Workbook

Sheet AP_Package_Summary
A1: Andhra Pradesh - size of data-centre incentive packages (sum of capped items in each GO)
A2: Sum of caps = upper bound of fiscal support over 10-20 yrs, nominal, undiscounted; uncapped items (land discount, some exemptions) are excluded, so true value is higher. Google: GO states an overall cap of Rs 22,002 cr, used instead of the sum.
A4: Project | B4: GO | C4: Site | D4: MW (per GO) | E4: Investment (Rs cr) | F4: Jobs | G4: Incentive caps (Rs cr) | H4: Caps as % of investment | I4: Caps per MW (Rs cr) | J4: of which power-related (Rs cr) | K4: Power-related share | L4: Notes
A5: Reliance Industries - Giga-scale AI DC + cable landing station | B5: G.O.Ms.30 (20-05-2026), land amended by G.O.Ms.52 (21-07-2026) | C5: Polipalli / Bhogapuram, Vizianagaram (854.97 ac) | E5: 108010 | G5: =SUMIFS(AP_Project_GOs!$F$5:$F$58,AP_Project_GOs!$A$5:$A$58,A5) -> 19101.53 | H5: =G5/E5 -> 0.17684964 | I5: =IF(D5="","n/a",G5/D5) -> n/a | J5: =SUMIFS(AP_Project_GOs!$F$5:$F$58,AP_Project_GOs!$A$5:$A$58,A5,AP_Project_GOs!$C$5:$C$58,"Power tariff")+SUMIFS(AP_Project_GOs!$F$5:$F$58,AP_Project_GOs!$A$5:$A$58,A5,AP_Project_GOs!$C$5:$C$58,"Transmission & wheeling")+SUMIFS(AP_Project_GOs!$F$5:$F$58,AP_Project_GOs!$A$5:$A$58,A5,AP_Project_GOs!$C$5:$C$58,"Electricity duty")+SUMIFS(AP_Project_GOs!$F$5:$F$58,AP_Project_GOs!$A$5:$A$58,A5,AP_Project_GOs!$C$5:$C$58,"Cross-subsidy surcharge")+SUMIFS(AP_Project_GOs!$F$5:$F$58,AP_Project_GOs!$A$5:$A$58,A5,AP_Project_GOs!$C$5:$C$58,"RE / green power charges")+SUMIFS(AP_Project_GOs!$F$5:$F$58,AP_Project_GOs!$A$5:$A$58,A5,AP_Project_GOs!$C$5:$C$58,"Grid / electrical infra") -> 8301.03 | K5: =J5/G5 -> 0.43457409 | L5: MW not stated in GO (1.5 GW only in civil-society registry). Jobs not committed in GO.
A6: Raiden Infotech (Google) - AI DC hub; Adani Infra / AdaniConneX / Airtel-Nxtra as notified partners | B6: G.O.Ms.40 (11-10-2025); partners G.O.Ms.66 (02-12-2025); stamp duty G.O.Ms.472 Rev (30-07-2026); sale terms G.O.Ms.213 I&C (20-08-2026) | C6: Tarluvada, Adavivaram-Mudasarlova, Rambilli (480 -> 601.4 ac) | D6: 1000 | E6: 87520 | G6: 22002 | H6: =G6/E6 -> 0.25139397 | I6: =IF(D6="","n/a",G6/D6) -> 22.002 | J6: =SUMIFS(AP_Project_GOs!$F$5:$F$58,AP_Project_GOs!$A$5:$A$58,A6,AP_Project_GOs!$C$5:$C$58,"Power tariff")+SUMIFS(AP_Project_GOs!$F$5:$F$58,AP_Project_GOs!$A$5:$A$58,A6,AP_Project_GOs!$C$5:$C$58,"Transmission & wheeling")+SUMIFS(AP_Project_GOs!$F$5:$F$58,AP_Project_GOs!$A$5:$A$58,A6,AP_Project_GOs!$C$5:$C$58,"Electricity duty")+SUMIFS(AP_Project_GOs!$F$5:$F$58,AP_Project_GOs!$A$5:$A$58,A6,AP_Project_GOs!$C$5:$C$58,"Cross-subsidy surcharge")+SUMIFS(AP_Project_GOs!$F$5:$F$58,AP_Project_GOs!$A$5:$A$58,A6,AP_Project_GOs!$C$5:$C$58,"RE / green power charges")+SUMIFS(AP_Project_GOs!$F$5:$F$58,AP_Project_GOs!$A$5:$A$58,A6,AP_Project_GOs!$C$5:$C$58,"Grid / electrical infra") -> 4800 | K6: =J6/G6 -> 0.21816199 | L6: GO 40 text not found online - items from PTI / tele.net quoting the GO; overall cap Rs 22,002 cr is quoted from the GO. GO 66, 472, 213 read in full (primary).
A7: ReNew AP Green Data Center Pvt Ltd | B7: G.O.Ms.55 (21-08-2026) | C7: Makavaripalem, Anakapalli (433.30 ac) | D7: 1000 | E7: 85200 | F7: 1880 | G7: =SUMIFS(AP_Project_GOs!$F$5:$F$58,AP_Project_GOs!$A$5:$A$58,A7) -> 14405 | H7: =G7/E7 -> 0.16907277 | I7: =IF(D7="","n/a",G7/D7) -> 14.405 | J7: =SUMIFS(AP_Project_GOs!$F$5:$F$58,AP_Project_GOs!$A$5:$A$58,A7,AP_Project_GOs!$C$5:$C$58,"Power tariff")+SUMIFS(AP_Project_GOs!$F$5:$F$58,AP_Project_GOs!$A$5:$A$58,A7,AP_Project_GOs!$C$5:$C$58,"Transmission & wheeling")+SUMIFS(AP_Project_GOs!$F$5:$F$58,AP_Project_GOs!$A$5:$A$58,A7,AP_Project_GOs!$C$5:$C$58,"Electricity duty")+SUMIFS(AP_Project_GOs!$F$5:$F$58,AP_Project_GOs!$A$5:$A$58,A7,AP_Project_GOs!$C$5:$C$58,"Cross-subsidy surcharge")+SUMIFS(AP_Project_GOs!$F$5:$F$58,AP_Project_GOs!$A$5:$A$58,A7,AP_Project_GOs!$C$5:$C$58,"RE / green power charges")+SUMIFS(AP_Project_GOs!$F$5:$F$58,AP_Project_GOs!$A$5:$A$58,A7,AP_Project_GOs!$C$5:$C$58,"Grid / electrical infra") -> 5700 | K7: =J7/G7 -> 0.39569594 | L7: Land at APIIC rate (no discount). Timeline 9 yrs 5 months.
A8: Data Centre Holdings India LLP (Colt DCS - RMZ) | B8: G.O.Ms.56 (21-08-2026) | C8: Jagnadhapuram, Anandapuram, Visakhapatnam (200 ac) | D8: 486 | E8: 58743 | F8: 1250 | G8: =SUMIFS(AP_Project_GOs!$F$5:$F$58,AP_Project_GOs!$A$5:$A$58,A8) -> 9966.22 | H8: =G8/E8 -> 0.169658 | I8: =IF(D8="","n/a",G8/D8) -> 20.506626 | J8: =SUMIFS(AP_Project_GOs!$F$5:$F$58,AP_Project_GOs!$A$5:$A$58,A8,AP_Project_GOs!$C$5:$C$58,"Power tariff")+SUMIFS(AP_Project_GOs!$F$5:$F$58,AP_Project_GOs!$A$5:$A$58,A8,AP_Project_GOs!$C$5:$C$58,"Transmission & wheeling")+SUMIFS(AP_Project_GOs!$F$5:$F$58,AP_Project_GOs!$A$5:$A$58,A8,AP_Project_GOs!$C$5:$C$58,"Electricity duty")+SUMIFS(AP_Project_GOs!$F$5:$F$58,AP_Project_GOs!$A$5:$A$58,A8,AP_Project_GOs!$C$5:$C$58,"Cross-subsidy surcharge")+SUMIFS(AP_Project_GOs!$F$5:$F$58,AP_Project_GOs!$A$5:$A$58,A8,AP_Project_GOs!$C$5:$C$58,"RE / green power charges")+SUMIFS(AP_Project_GOs!$F$5:$F$58,AP_Project_GOs!$A$5:$A$58,A8,AP_Project_GOs!$C$5:$C$58,"Grid / electrical infra") -> 6348.36 | K8: =J8/G8 -> 0.63698774 | L8: Timeline 10 yrs.
A9: AM AI Factory (Vizag) Pvt Ltd (AM Intelligence Labs) | B9: G.O.Ms.59 (22-08-2026) | C9: Amanam, Bheemunipatnam, Visakhapatnam | D9: 512 | E9: 31387 | F9: 1000 | G9: =SUMIFS(AP_Project_GOs!$F$5:$F$58,AP_Project_GOs!$A$5:$A$58,A9) -> 5176 | H9: =G9/E9 -> 0.16490904 | I9: =IF(D9="","n/a",G9/D9) -> 10.109375 | J9: =SUMIFS(AP_Project_GOs!$F$5:$F$58,AP_Project_GOs!$A$5:$A$58,A9,AP_Project_GOs!$C$5:$C$58,"Power tariff")+SUMIFS(AP_Project_GOs!$F$5:$F$58,AP_Project_GOs!$A$5:$A$58,A9,AP_Project_GOs!$C$5:$C$58,"Transmission & wheeling")+SUMIFS(AP_Project_GOs!$F$5:$F$58,AP_Project_GOs!$A$5:$A$58,A9,AP_Project_GOs!$C$5:$C$58,"Electricity duty")+SUMIFS(AP_Project_GOs!$F$5:$F$58,AP_Project_GOs!$A$5:$A$58,A9,AP_Project_GOs!$C$5:$C$58,"Cross-subsidy surcharge")+SUMIFS(AP_Project_GOs!$F$5:$F$58,AP_Project_GOs!$A$5:$A$58,A9,AP_Project_GOs!$C$5:$C$58,"RE / green power charges")+SUMIFS(AP_Project_GOs!$F$5:$F$58,AP_Project_GOs!$A$5:$A$58,A9,AP_Project_GOs!$C$5:$C$58,"Grid / electrical infra") -> 4340 | K9: =J9/G9 -> 0.83848532 | L9: No power-tariff subsidy, but CSS waiver capped at Rs 3,000 cr. Timeline 2 yrs 4 months.
A10: Total - 5 AP data-centre packages | D10: =SUM(D5:D9) -> 2998 | E10: =SUM(E5:E9) -> 370860 | F10: =SUM(F5:F9) -> 4130 | G10: =SUM(G5:G9) -> 70650.75 | H10: =G10/E10 -> 0.19050518 | J10: =SUM(J5:J9) -> 29489.39 | K10: =J10/G10 -> 0.4173967 | L10: MW total excludes Reliance (MW not in GO). Google power-related figure covers only the capped Rs 1/unit item.
A12: What the GOs show
A13: 1) AP has committed roughly Rs 70,000 cr of capped fiscal support across five DC projects (~3 GW with stated MW, plus Reliance) - about 18-25% of the stated investment.
A14: 2) Power is the core of every package: Rs 1/unit tariff discount (15 yrs), 100% transmission & wheeling waiver (20 yrs), 100% electricity duty waiver (15-20 yrs), plus CSS / RE-charge waivers. Power-related items are ~40-85% of the capped value (Google shows 22% only because its other power waivers have no reported cap).
A15: 3) Packages are bespoke, not formulaic: DCHI's power-tariff cap (Rs 4,800 cr for 486 MW) is ~2x ReNew's (Rs 2,500 cr for 1,000 MW); AM AI gets no tariff discount but a Rs 3,000 cr CSS waiver; Reliance gets a lower capital subsidy (6% vs 10%) but a Rs 5,000 cr transmission waiver.
A16: 4) Grid cost stays with the developer (APTRANSCO only 'facilitates') - except DCHI, which gets up to Rs 150 cr reimbursed for electrical infrastructure.
A17: 5) The GOs also hand over utility-style rights: DCHI gets power trading licence and deemed distribution licensee status facilitated; Reliance gets a captive solar park outside cross-subsidy surcharge.

Sheet AP_Project_GOs
A1: Andhra Pradesh - data-centre incentives granted in project Government Orders (tailor-made 'Mega project' packages under AP Data Center Policy 4.0)
A2: Caps are the maximum incentive (Rs crore) written in each GO; '-' = no cap stated. Mega projects (> Rs 5,000 cr and > 50 MW) get tailor-made packages. Approval chain: APEDB -> CCITEI -> SIPC -> SIPB -> GO. Tier A1 = GO read in full; A2 = press quoting the GO.
A4: Project | B4: GO | C4: Category | D4: Incentive (as written in GO) | E4: Period (yrs) | F4: Cap (Rs cr) | G4: MW | H4: Tier | I4: Source
A5: Reliance Industries - Giga-scale AI DC + cable landing station | B5: G.O.Ms.30 (20-05-2026), land amended by G.O.Ms.52 (21-07-2026) | C5: Land | D5: 25% discount on land value; company pays 75% of land cost to APIIC as acquisition starts; 1 acre for CLS | H5: A1 | I5: https://stopdirtydatacenters.org/media/resources/files/2026ITC_41827_MS30_E.pdf
A6: Reliance Industries - Giga-scale AI DC + cable landing station | B6: G.O.Ms.30 (20-05-2026), land amended by G.O.Ms.52 (21-07-2026) | C6: Stamp duty & registration | D6: 100% exemption | H6: A1 | I6: https://stopdirtydatacenters.org/media/resources/files/2026ITC_41827_MS30_E.pdf
A7: Reliance Industries - Giga-scale AI DC + cable landing station | B7: G.O.Ms.30 (20-05-2026), land amended by G.O.Ms.52 (21-07-2026) | C7: Capital subsidy | D7: 6% of investment in machinery & equipment, 10 equal instalments | E7: 10 | F7: 4500 | H7: A1 | I7: https://stopdirtydatacenters.org/media/resources/files/2026ITC_41827_MS30_E.pdf
A8: Reliance Industries - Giga-scale AI DC + cable landing station | B8: G.O.Ms.30 (20-05-2026), land amended by G.O.Ms.52 (21-07-2026) | C8: SGST reimbursement | D8: 100% net SGST on construction (10 yrs or till max capacity) | E8: 10 | F8: 2527.38 | H8: A1 | I8: https://stopdirtydatacenters.org/media/resources/files/2026ITC_41827_MS30_E.pdf
A9: Reliance Industries - Giga-scale AI DC + cable landing station | B9: G.O.Ms.30 (20-05-2026), land amended by G.O.Ms.52 (21-07-2026) | C9: SGST reimbursement | D9: 100% net SGST on leasing cost | E9: 10 | F9: 1800 | H9: A1 | I9: https://stopdirtydatacenters.org/media/resources/files/2026ITC_41827_MS30_E.pdf
A10: Reliance Industries - Giga-scale AI DC + cable landing station | B10: G.O.Ms.30 (20-05-2026), land amended by G.O.Ms.52 (21-07-2026) | C10: Water | D10: Water tariff subsidised 15% | E10: 10 | F10: 552.41 | H10: A1 | I10: https://stopdirtydatacenters.org/media/resources/files/2026ITC_41827_MS30_E.pdf
A11: Reliance Industries - Giga-scale AI DC + cable landing station | B11: G.O.Ms.30 (20-05-2026), land amended by G.O.Ms.52 (21-07-2026) | C11: Fibre / RoW | D11: OPGW fibre access at 30% discount (O&M +5% every 3 yrs) | E11: 20 | F11: 1220.71 | H11: A1 | I11: https://stopdirtydatacenters.org/media/resources/files/2026ITC_41827_MS30_E.pdf
A12: Reliance Industries - Giga-scale AI DC + cable landing station | B12: G.O.Ms.30 (20-05-2026), land amended by G.O.Ms.52 (21-07-2026) | C12: Fibre / RoW | D12: RoW cost of state entities waived | E12: 20 | F12: 200 | H12: A1 | I12: https://stopdirtydatacenters.org/media/resources/files/2026ITC_41827_MS30_E.pdf
A13: Reliance Industries - Giga-scale AI DC + cable landing station | B13: G.O.Ms.30 (20-05-2026), land amended by G.O.Ms.52 (21-07-2026) | C13: Power tariff | D13: Rs 1/unit discount on power | E13: 15 | F13: 3114.18 | H13: A1 | I13: https://stopdirtydatacenters.org/media/resources/files/2026ITC_41827_MS30_E.pdf
A14: Reliance Industries - Giga-scale AI DC + cable landing station | B14: G.O.Ms.30 (20-05-2026), land amended by G.O.Ms.52 (21-07-2026) | C14: Cross-subsidy surcharge | D14: CSS not levied on the captive solar park | E14: 20 | H14: A1 | I14: https://stopdirtydatacenters.org/media/resources/files/2026ITC_41827_MS30_E.pdf
A15: Reliance Industries - Giga-scale AI DC + cable landing station | B15: G.O.Ms.30 (20-05-2026), land amended by G.O.Ms.52 (21-07-2026) | C15: Transmission & wheeling | D15: 100% of transmission charges imposed by GoAP exempted | E15: 20 | F15: 5000 | H15: A1 | I15: https://stopdirtydatacenters.org/media/resources/files/2026ITC_41827_MS30_E.pdf
A16: Reliance Industries - Giga-scale AI DC + cable landing station | B16: G.O.Ms.30 (20-05-2026), land amended by G.O.Ms.52 (21-07-2026) | C16: Electricity duty | D16: 100% exemption | E16: 15 | F16: 186.85 | H16: A1 | I16: https://stopdirtydatacenters.org/media/resources/files/2026ITC_41827_MS30_E.pdf
A17: Reliance Industries - Giga-scale AI DC + cable landing station | B17: G.O.Ms.30 (20-05-2026), land amended by G.O.Ms.52 (21-07-2026) | C17: Non-fiscal | D17: Grid infra 'at-source waiver' - APTRANSCO facilitates infra to load end (proponent bears cost); single window; empowered nodal officer / steering committee; guaranteed water for 20 yrs + study of joint ownership of a desalination plant | H17: A1 | I17: https://stopdirtydatacenters.org/media/resources/files/2026ITC_41827_MS30_E.pdf
A18: Raiden Infotech (Google) - AI DC hub; Adani Infra / AdaniConneX / Airtel-Nxtra as notified partners | B18: G.O.Ms.40 (11-10-2025); partners G.O.Ms.66 (02-12-2025); stamp duty G.O.Ms.472 Rev (30-07-2026); sale terms G.O.Ms.213 I&C (20-08-2026) | C18: Land | D18: 25% discount on land (480 ac; later 601.4 ac allotted to Adani Infra SPVs); up to 15 ac for cable landing station | G18: 1000 | H18: A2 | I18: https://telanganatoday.com/googles-raiden-infotech-to-get-rs-22000-cr-incentives-from-andhra-for-vizag-data-centres
A19: Raiden Infotech (Google) - AI DC hub; Adani Infra / AdaniConneX / Airtel-Nxtra as notified partners | B19: G.O.Ms.40 (11-10-2025); partners G.O.Ms.66 (02-12-2025); stamp duty G.O.Ms.472 Rev (30-07-2026); sale terms G.O.Ms.213 I&C (20-08-2026) | C19: Stamp duty & registration | D19: 100% exemption (G.O.Ms.472: Rs 20.56 cr stamp duty + Rs 2.64 cr registration fee waived for the 3 Adani Infra SPVs) | F19: 23.2 | G19: 1000 | H19: A2 | I19: https://telanganatoday.com/googles-raiden-infotech-to-get-rs-22000-cr-incentives-from-andhra-for-vizag-data-centres
A20: Raiden Infotech (Google) - AI DC hub; Adani Infra / AdaniConneX / Airtel-Nxtra as notified partners | B20: G.O.Ms.40 (11-10-2025); partners G.O.Ms.66 (02-12-2025); stamp duty G.O.Ms.472 Rev (30-07-2026); sale terms G.O.Ms.213 I&C (20-08-2026) | C20: Capital subsidy | D20: 10% of plant & machinery, over 10 yrs (cap Rs 21.29 bn per tele.net) | E20: 10 | F20: 2129 | G20: 1000 | H20: A2 | I20: https://telanganatoday.com/googles-raiden-infotech-to-get-rs-22000-cr-incentives-from-andhra-for-vizag-data-centres
A21: Raiden Infotech (Google) - AI DC hub; Adani Infra / AdaniConneX / Airtel-Nxtra as notified partners | B21: G.O.Ms.40 (11-10-2025); partners G.O.Ms.66 (02-12-2025); stamp duty G.O.Ms.472 Rev (30-07-2026); sale terms G.O.Ms.213 I&C (20-08-2026) | C21: SGST reimbursement | D21: 100% net SGST on construction (cap Rs 2,245 cr per PTI); construction + leasing together Rs 3,990 cr per tele.net | E21: 10 | F21: 3990 | G21: 1000 | H21: A2 | I21: https://telanganatoday.com/googles-raiden-infotech-to-get-rs-22000-cr-incentives-from-andhra-for-vizag-data-centres
A22: Raiden Infotech (Google) - AI DC hub; Adani Infra / AdaniConneX / Airtel-Nxtra as notified partners | B22: G.O.Ms.40 (11-10-2025); partners G.O.Ms.66 (02-12-2025); stamp duty G.O.Ms.472 Rev (30-07-2026); sale terms G.O.Ms.213 I&C (20-08-2026) | C22: Power tariff | D22: Rs 1/unit discount for 10 yrs, +5 yrs on hitting investment & capacity milestones | E22: 15 | F22: 4800 | G22: 1000 | H22: A2 | I22: https://telanganatoday.com/googles-raiden-infotech-to-get-rs-22000-cr-incentives-from-andhra-for-vizag-data-centres
A23: Raiden Infotech (Google) - AI DC hub; Adani Infra / AdaniConneX / Airtel-Nxtra as notified partners | B23: G.O.Ms.40 (11-10-2025); partners G.O.Ms.66 (02-12-2025); stamp duty G.O.Ms.472 Rev (30-07-2026); sale terms G.O.Ms.213 I&C (20-08-2026) | C23: Electricity duty | D23: 100% exemption (15-20 yrs; cap not reported) | E23: 20 | G23: 1000 | H23: A2 | I23: https://telanganatoday.com/googles-raiden-infotech-to-get-rs-22000-cr-incentives-from-andhra-for-vizag-data-centres
A24: Raiden Infotech (Google) - AI DC hub; Adani Infra / AdaniConneX / Airtel-Nxtra as notified partners | B24: G.O.Ms.40 (11-10-2025); partners G.O.Ms.66 (02-12-2025); stamp duty G.O.Ms.472 Rev (30-07-2026); sale terms G.O.Ms.213 I&C (20-08-2026) | C24: Transmission & wheeling | D24: 100% exemption of transmission charges (cap not reported) | E24: 20 | G24: 1000 | H24: A2 | I24: https://telanganatoday.com/googles-raiden-infotech-to-get-rs-22000-cr-incentives-from-andhra-for-vizag-data-centres
A25: Raiden Infotech (Google) - AI DC hub; Adani Infra / AdaniConneX / Airtel-Nxtra as notified partners | B25: G.O.Ms.40 (11-10-2025); partners G.O.Ms.66 (02-12-2025); stamp duty G.O.Ms.472 Rev (30-07-2026); sale terms G.O.Ms.213 I&C (20-08-2026) | C25: Cross-subsidy surcharge | D25: RE cross-subsidy charges exempted (cap not reported) | E25: 20 | G25: 1000 | H25: A2 | I25: https://telanganatoday.com/googles-raiden-infotech-to-get-rs-22000-cr-incentives-from-andhra-for-vizag-data-centres
A26: Raiden Infotech (Google) - AI DC hub; Adani Infra / AdaniConneX / Airtel-Nxtra as notified partners | B26: G.O.Ms.40 (11-10-2025); partners G.O.Ms.66 (02-12-2025); stamp duty G.O.Ms.472 Rev (30-07-2026); sale terms G.O.Ms.213 I&C (20-08-2026) | C26: Water | D26: 25% water-tariff subsidy | E26: 10 | G26: 1000 | H26: A2 | I26: https://telanganatoday.com/googles-raiden-infotech-to-get-rs-22000-cr-incentives-from-andhra-for-vizag-data-centres
A27: Raiden Infotech (Google) - AI DC hub; Adani Infra / AdaniConneX / Airtel-Nxtra as notified partners | B27: G.O.Ms.40 (11-10-2025); partners G.O.Ms.66 (02-12-2025); stamp duty G.O.Ms.472 Rev (30-07-2026); sale terms G.O.Ms.213 I&C (20-08-2026) | C27: Overall cap | D27: SIPB: all listed incentives with an OVERALL CAP of Rs 22,002 cr (quoted from GO 40) | G27: 1000 | H27: A2 | I27: https://telanganatoday.com/googles-raiden-infotech-to-get-rs-22000-cr-incentives-from-andhra-for-vizag-data-centres
A28: Raiden Infotech (Google) - AI DC hub; Adani Infra / AdaniConneX / Airtel-Nxtra as notified partners | B28: G.O.Ms.40 (11-10-2025); partners G.O.Ms.66 (02-12-2025); stamp duty G.O.Ms.472 Rev (30-07-2026); sale terms G.O.Ms.213 I&C (20-08-2026) | C28: Non-fiscal | D28: Incentives extend to notified partners (Adani Infra, AdaniConneX, Adani Power, Airtel, Nxtra) within the overall ceiling (GO 66). Sale-agreement relaxations: ECB financing allowed, 30-day cure period, title warranties, liability for enhanced compensation capped at 10% of land cost; 5.84 ac GVMC land at endowment lease rates (3% of SRO value) (GO 213) | G28: 1000 | H28: A2 | I28: https://telanganatoday.com/googles-raiden-infotech-to-get-rs-22000-cr-incentives-from-andhra-for-vizag-data-centres
A29: ReNew AP Green Data Center Pvt Ltd | B29: G.O.Ms.55 (21-08-2026) | C29: Land | D29: 433.30 ac at APIIC rate (no discount); land cost includes roads & water pipeline | G29: 1000 | H29: A1 | I29: https://stopdirtydatacenters.org/media/resources/files/2026ITC_43622_MS55_E.pdf
A30: ReNew AP Green Data Center Pvt Ltd | B30: G.O.Ms.55 (21-08-2026) | C30: Stamp duty & registration | D30: 100% reimbursement | F30: 5 | G30: 1000 | H30: A1 | I30: https://stopdirtydatacenters.org/media/resources/files/2026ITC_43622_MS55_E.pdf
A31: ReNew AP Green Data Center Pvt Ltd | B31: G.O.Ms.55 (21-08-2026) | C31: Capital subsidy | D31: 10% of machinery & equipment, 10 equal annual instalments | E31: 10 | F31: 3700 | G31: 1000 | H31: A1 | I31: https://stopdirtydatacenters.org/media/resources/files/2026ITC_43622_MS55_E.pdf
A32: ReNew AP Green Data Center Pvt Ltd | B32: G.O.Ms.55 (21-08-2026) | C32: SGST reimbursement | D32: 100% net SGST on capital investment | E32: 10 | F32: 5000 | G32: 1000 | H32: A1 | I32: https://stopdirtydatacenters.org/media/resources/files/2026ITC_43622_MS55_E.pdf
A33: ReNew AP Green Data Center Pvt Ltd | B33: G.O.Ms.55 (21-08-2026) | C33: Power tariff | D33: Rs 1/unit discount | E33: 15 | F33: 2500 | G33: 1000 | H33: A1 | I33: https://stopdirtydatacenters.org/media/resources/files/2026ITC_43622_MS55_E.pdf
A34: ReNew AP Green Data Center Pvt Ltd | B34: G.O.Ms.55 (21-08-2026) | C34: Transmission & wheeling | D34: 100% exemption of transmission & wheeling charges | E34: 20 | F34: 3000 | G34: 1000 | H34: A1 | I34: https://stopdirtydatacenters.org/media/resources/files/2026ITC_43622_MS55_E.pdf
A35: ReNew AP Green Data Center Pvt Ltd | B35: G.O.Ms.55 (21-08-2026) | C35: Electricity duty | D35: 100% exemption | E35: 20 | F35: 200 | G35: 1000 | H35: A1 | I35: https://stopdirtydatacenters.org/media/resources/files/2026ITC_43622_MS55_E.pdf
A36: ReNew AP Green Data Center Pvt Ltd | B36: G.O.Ms.55 (21-08-2026) | C36: Non-fiscal | D36: FSI above 3 without extra charges; 'Mission Critical Infrastructure' status; assured water (APIIC rates); parking relaxation | G36: 1000 | H36: A1 | I36: https://stopdirtydatacenters.org/media/resources/files/2026ITC_43622_MS55_E.pdf
A37: Data Centre Holdings India LLP (Colt DCS - RMZ) | B37: G.O.Ms.56 (21-08-2026) | C37: Land | D37: 25% discount on APIIC cost | F37: 30 | G37: 486 | H37: A1 | I37: https://stopdirtydatacenters.org/media/resources/files/2026ITC_43620_MS56_E.pdf
A38: Data Centre Holdings India LLP (Colt DCS - RMZ) | B38: G.O.Ms.56 (21-08-2026) | C38: Stamp duty & registration | D38: 100% reimbursement of stamp duty | F38: 7 | G38: 486 | H38: A1 | I38: https://stopdirtydatacenters.org/media/resources/files/2026ITC_43620_MS56_E.pdf
A39: Data Centre Holdings India LLP (Colt DCS - RMZ) | B39: G.O.Ms.56 (21-08-2026) | C39: Capital subsidy | D39: 10% of machinery & equipment, 10 equal annual instalments | E39: 10 | F39: 1800 | G39: 486 | H39: A1 | I39: https://stopdirtydatacenters.org/media/resources/files/2026ITC_43620_MS56_E.pdf
A40: Data Centre Holdings India LLP (Colt DCS - RMZ) | B40: G.O.Ms.56 (21-08-2026) | C40: SGST reimbursement | D40: 100% net SGST on construction raw material (10 yrs or till max capacity) | E40: 10 | F40: 703.44 | G40: 486 | H40: A1 | I40: https://stopdirtydatacenters.org/media/resources/files/2026ITC_43620_MS56_E.pdf
A41: Data Centre Holdings India LLP (Colt DCS - RMZ) | B41: G.O.Ms.56 (21-08-2026) | C41: SGST reimbursement | D41: 100% net SGST on leasing cost (10 yrs or till max capacity) | E41: 10 | F41: 848 | G41: 486 | H41: A1 | I41: https://stopdirtydatacenters.org/media/resources/files/2026ITC_43620_MS56_E.pdf
...

Sheet Policy_Compare_AP_TG_MH
A1: Data-centre incentives by state policy - Andhra Pradesh vs Telangana vs Maharashtra
A2: AP column = what the 2026 project GOs actually grant (the base AP DC Policy 4.0, G.O.Ms.6 of 14-11-2024, is only available as a summary). Telangana = Data Centres Policy 2016 (no public project-level GOs found on the Telangana GO register). Maharashtra = IT/ITeS Policy 2023 + Integrated Green DC Park GR (09-10-2024) + amendment GR (09-06-2026) + Electricity Duty notification (22-06-2026).
A4: Incentive | B4: Andhra Pradesh (project GOs 2025-26) | C4: Telangana (DC Policy 2016) | D4: Maharashtra (IT/ITeS 2023 + Green DC Park GRs)
A5: Power tariff | B5: Rs 1/unit discount for 15 yrs (caps Rs 2,500-4,800 cr per project); Google: 10 yrs + 5 on milestones | C5: Power to eligible DCs 'at the cost of generation' (details left to operational guidelines) | D5: Industrial (not commercial) tariff from day one; Rs 1/unit subsidy for 5 yrs for new DCs outside Zone I [2023 policy, secondary]. Green DC parks: Rs 1/unit for 10 yrs (>= Rs 30,000 cr) or 20 yrs (>= Rs 60,000 cr) [GR 09-06-2026, single trade source]
A6: Electricity duty | B6: 100% exemption for 15-20 yrs (caps Rs 90-411 cr) | C6: Not specified in DC policy (IT/ITeS incentive GO applies) | D6: 20-yr exemption for new AND existing DC units; starts from commercial operation; no refunds of past duty; MSEDCL annual inspection [notification CEI-2025/CR-158/Energy-1, 22-06-2026 - summary]
A7: Transmission / wheeling | B7: 100% waiver of state transmission & wheeling charges for 20 yrs (caps Rs 1,250-5,000 cr) | C7: Not specified | D7: Not specified in public summaries
A8: Cross-subsidy surcharge / RE charges | B8: CSS waived 20 yrs (AM AI cap Rs 3,000 cr; Reliance captive solar); RE / carbon-free energy access charges waived 20 yrs (DCHI cap Rs 983 cr) | C8: RE under open access allowed up to 1/3 of load after paying DISCOM cost component; support for captive solar/wind + 'initial investment subsidy' | D8: Open access allowed incl. RE after paying DISCOM cost component; green parks must source >= 51% green power (cut from 100% in Jun-2026)
A9: Grid / supply reliability | B9: APTRANSCO facilitates grid infra (developer pays); DCHI gets up to Rs 150 cr reimbursed; priority green power allocation | C9: Dual power grid networks; exempt from statutory power cuts; subsidised backup power infra and DG fuel below market rate in the DC campus | D9: Exempt from statutory power cuts (24x7x365); infrastructure status
A10: Utility rights | B10: Power trading licence and deemed distribution licensee status 'facilitated' (DCHI) | C10: - | D10: -
A11: Land | B11: 25% discount on APIIC value (Google, Reliance, DCHI); ReNew at APIIC rate | C11: Subsidised land as decided by CCITI; DC campus earmarked by state | D11: MIDC DC parks earmarked with prior clearances; DCs allowed in any zone; MIDC green DC parks: no sub-letting charges
A12: Stamp duty & registration | B12: 100% exemption / reimbursement (caps Rs 5-23 cr) | C12: Not specified in DC policy | D12: 100% stamp duty exemption on land/premises purchase, lease, L&L for new DCs and expansion; 100% on first lease / sub-lease in green DC parks
A13: Capital / investment subsidy | B13: 10% of machinery & equipment over 10 yrs (Reliance 6%); caps Rs 300-4,500 cr | C13: Startups only (lease-rental, internet, R&D, patent support); tailor-made package for strategic projects | D13: Green parks >= Rs 60,000 cr: Industrial Promotion Subsidy = 75% of eligible fixed capital investment; 4% interest subsidy on term loans up to 10 yrs, max Rs 25 cr/yr [GR 09-06-2026, single trade source]
A14: SGST reimbursement | B14: 100% net SGST on construction and/or leasing for 10 yrs (caps Rs 490-5,000 cr) | C14: Not specified | D14: Not specified in public summaries
A15: Water | B15: Guaranteed water (APIIC / GVMC; Reliance 20 yrs + desalination study); tariff subsidy 15-25% for 10 yrs | C15: Continuous water supply for cooling in DC campus | D15: Not specified
... A20: Primary sources | B20: https://www.medianama.com/wp-content/uploads/2026/08/reliance_merged.pdf (GOs 52/55/56/59); https://stopdirtydatacenters.org/media/resources/files/2026ITC_41827_MS30_E.pdf (GO 30) | C20: https://www.telangana.gov.in/wp-content/uploads/2023/05/Telangana-Data-Centres-Policy.pdf | D20: https://powerpeakdigest.com/maharashtra-green-data-center-policy-expansion/ ; https://www.snrlaw.in/incentives-and-laws-for-data-centers-in-maharashtra/ ; https://teamleaseregtech.com/updates/article/57168/govt-of-maharashtra-issued-a-notification-regarding-electricity-duty-e/

Sheet Other_States
A1: Other states - data-centre policy incentives (secondary summaries; lower priority)
A3: State | B3: Policy | C3: Key incentives | D3: Tier | E3: Source
A4: Tamil Nadu | B4: TN Data Centre Policy 2021 (expired Apr-2026; no extension notified) | C4: DC parks; uninterrupted water; sub-lease without transfer charges; district-wise stamp duty concessions; land cost subsidy; power incentives; labour-law relaxations; single window. TN Energy Policy Note 2025-26: only 170.4 MVA connected to DCs statewide. | D4: D | E4: https://www.ahlawatassociates.com/blog/india-data-centre-policy-by-state
A5: Uttar Pradesh | B5: UP Data Centre Policy 2021 (amended 2022) | C5: 7% capital subsidy on fixed capital (up to Rs 20 cr); up to 60% interest subsidy for DC park developers; 100% stamp duty on first land transaction; 100% electricity duty waiver for 10 yrs; wheeling & transmission charge exemptions; essential service under ESMA. Dashboard: 29 MoUs, 644 MW proposed, 133 MW commercialised (Jun-2025). | D5: D | E5: https://uplc.up.gov.in/en/page/uttar-pradesh-data-center-policy
A6: Karnataka | B6: Karnataka Data Centre Policy 2022-27 | C6: Outside Bengaluru: 7% capital subsidy (excl. land & building), land subsidy, 100% stamp duty exemption; concessional industrial tariff; green-energy charge reimbursement; electricity duty exemption; dual power and open access; customised packages for large projects. | D6: D | E6: https://www.ahlawatassociates.com/blog/india-data-centre-policy-by-state
A7: Haryana | B7: Haryana State Data Centre Policy 2022 | C7: 100% stamp duty reimbursement on first sale/lease; long-term electricity duty exemption; power bill reimbursement; location-based SGST reimbursement; essential service; reduced industrial property tax; employment subsidies. | D7: D | E7: https://www.ahlawatassociates.com/blog/india-data-centre-policy-by-state
A8: Gujarat | B8: Gujarat IT/ITeS Policy 2022-27 | C8: DCs classed as 'Strategic Institutions' (greenfield only); job-linked PF reimbursements; 'Cloud Villages'; simplified fibre rules; faster agri-land conversion; DCs allowed in various zones. | D8: D | E8: https://www.ahlawatassociates.com/blog/india-data-centre-policy-by-state
A9: Odisha / West Bengal | B9: Odisha DC Policy 2021-22; WB DC Policy 2021 | C9: Capital subsidies, power-tariff concessions, stamp and electricity duty exemptions, single window (no item-level detail in summaries). Odisha approves mega DCs case-by-case via HLCA (e.g. Adani Naraj 1 GW, Sentraforge Puri). | D9: D | E9: https://assets.cushmanwakefield.com/-/media/cw/apac/india/insights/data-centre-policies-in-india-a-statewise-comparison.pdf?rev=6e0e167e39bf41f383b67eef232479f4
A10: Central (all states) | B10: Union Budget 2026-27 | C10: Long-dated tax holiday (to 2047) for foreign cloud companies serving global customers from Indian DCs. | D10: D | E10: https://www.snrlaw.in/indian-budget-2026-27-tax-incentives-for-data-centres/
A12: Tier D = law-firm / consultant summaries, not the policy text - verify before quoting figures.
