Workbook

Sheet README
B2: Hyperliquid Strategies Inc (NASDAQ: PURR) - HYPE token holdings time series
B3: Compiled 2026-08-27 09:45 UTC | CIK 0002078856 | Fiscal year end 30 June
B5: BOTTOM LINE
B6: There is NO dependable DAILY series of HSI's HYPE holdings in the public domain, and no
B7: continuous weekly series going back to inception. Anyone who tells you otherwise is either
B8: interpolating between disclosed points or reading a third-party tracker that is wrong.
B10: What does exist, and what this file contains:
B11: Tier 1 - 7 dated, company-disclosed observations from SEC filings (2 Dec 2025 - 15 Jul 2026).
B12: Three are exact to the token; four are rounded to 0.1m by the company.
B13: Tier 2 - 9 weekly observations from the company's own treasury dashboard (2 Jul - 20 Aug 2026).
B14: Company estimate, unaudited, and only 9 weeks are publicly retrievable (see caveat 3).
B15: Tier 3 - A full unit-level roll-forward from the 10-Q for Q2 and Q3 FY2026 - the only place
... B79: Blank cells are blank on purpose. Nothing in this file is interpolated.

Sheet Assumptions
A1: Assumptions and live inputs
A3: Input | B3: Value | C3: Unit | D3: Source / note
A4: HYPE spot price | B4: 82.88 | C4: USD | D4: CoinGecko simple/price api, 27-Aug-2026 09:45 UTC. Hyperliquid perp mid was $83.08 at the same moment. UPDATE BEFORE USE.
A5: PURR share price | C5: USD | D5: PURR close not independently retrieved - enter manually. Nasdaq close is the price of record; beware the Hyperliquid PURR spot token and the PURRDAT perp.
A6: Series A preferred, as-converted | B6: 26587647 | C6: shares | D6: hypestrat.xyz dashboard footnote 2, subject to blocker provisions.
A7: Data retrieved | B7: 2026-08-27 09:45 UTC | D7: All figures in this workbook were pulled at this timestamp.

Sheet Anchors_SEC
A1: Tier 1 - HYPE token holdings disclosed in SEC filings
A2: Every figure below is quoted or arithmetically reconciled from the filing named in column G. Nothing is estimated.
A4: As-of date | B4: HYPE tokens held | C4: Precision | D4: Delta vs prior | E4: Days elapsed | F4: Implied tokens/day | G4: Source document | H4: Verbatim basis
A5: 45993 | B5: 12517592 | C5: Exact | G5: 10-Q QE 31-Mar-2026, Note 3 digital asset roll-forward (accession 0001193125-26-212519) | H5: 'Contributions of HYPE digital assets from Rorschach Contributions 12,517,592'. Contributed in kind at closing, valued $580.5m at commitment ($46.37) but recognised at $411.3m.
A6: 46022 | B6: 12857533 | C6: Exact | D6: =B6-B5 -> 339941 | E6: =A6-A5 -> 29 | F6: =IFERROR(D6/E6,"") -> 11722.103 | G6: 10-Q QE 31-Dec-2025, Note 3 (accession 0001193125-26-045901); XBRL CryptoAssetNumberOfUnits | H6: 12,517,592 contributed + 321,224 purchased ($9.0m) + 18,717 staking receipts. Fair value $327.610m at $25.48.
A7: 46056 | B7: 17600000 | C7: Rounded 0.1m | D7: =B7-B6 -> 4742467 | E7: =A7-A6 -> 34 | F7: =IFERROR(D7/E7,"") -> 139484.32 | G7: 8-K 11-Feb-2026, Ex-99.1 'Treasury Strategy Progress (as of February 3, 2026)' | H7: 'Deployed $129.5 million to acquire ~5.0 million additional HYPE tokens, increasing total HYPE holdings to 17.6 million.' Note the implied 12.6m base does not tie to 12,517,592.
A8: 46112 | B8: 18826355 | C8: Exact | D8: =B8-B7 -> 1226355 | E8: =A8-A7 -> 56 | F8: =IFERROR(D8/E8,"") -> 21899.196 | G8: 10-Q QE 31-Mar-2026, Note 3 (accession 0001193125-26-212519) | H8: Balance, March 31, 2026 = 18,826,355 HYPE. Fair value $689.045m at $36.60. Separate $0.5m USDC brings total digital assets to $689.545m.
A9: 46141 | B9: 20000000 | C9: Rounded 0.1m | D9: =B9-B8 -> 1173645 | E9: =A9-A8 -> 29 | F9: =IFERROR(D9/E9,"") -> 40470.517 | G9: 8-K 7-May-2026, Ex-99.1 'Treasury Strategy Progress (as of April 29, 2026)' | H9: 'Materially increased treasury to 20.0 million HYPE tokens (as of April 29, 2026), with $103 million in cash remaining.'
A10: 46156 | B10: 20800000 | C10: Rounded 0.1m | D10: =B10-B9 -> 800000 | E10: =A10-A9 -> 15 | F10: =IFERROR(D10/E10,"") -> 53333.333 | G10: S-1 22-May-2026 (accession 0001193125-26-234992); repeated unchanged in S-1/A 16-Jun and 25-Jun | H10: 'As of May 14, 2026, the Company holds approximately 20.8 million HYPE tokens.' The June amendments did NOT refresh this date - it is stale in those documents.
A11: 46218 | B11: 29300000 | C11: Rounded 0.1m | D11: =B11-B10 -> 8500000 | E11: =A11-A10 -> 62 | F11: =IFERROR(D11/E11,"") -> 137096.77 | G11: S-1/A 21-Jul-2026 (accession 0001193125-26-309340) | H11: 'As of July 15, 2026, the Company holds approximately 29.3 million HYPE tokens.' Same filing: 21.2m staked to own validator (72.5%), 8.1m delegated to Anchorage (27.5%).
A12: Total 2-Dec-25 to 15-Jul-26 | B12: =B11-B5 -> 16782408 | C12: Net add | D12: =SUM(D6:D11) -> 16782408 | E12: =A11-A5 -> 225 | F12: =IFERROR(D12/E12,"") -> 74588.48 | G12: Cross-check: D column total must equal B column difference. | H12: =IF(B12=D12,"TIE","MISMATCH - INVESTIGATE") -> TIE
A14: Current market value of the 15-Jul-2026 position | B14: =B11*Assumptions!$B$4 -> 2428384000 | C14: USD | G14: Priced at the HYPE assumption on the Assumptions tab. Update that cell.

Sheet Weekly_Dashboard
A1: Tier 2 - Company treasury dashboard, weekly inputs
A2: Company estimates, unaudited. Only the 20-Aug row is published on the dashboard page; the rest come from the site's unauthenticated version-history feed. See README caveat 3.
A4: Page date (as published) | B4: Data as-of date (page date less 7d, per company note) | C4: HYPE held (m) | D4: WoW change (m) | E4: Shares, common + pref as-converted (m) | F4: WoW share change (m) | G4: Cash ($m) | H4: Cumulative treasury deployment ($m) | I4: WoW deployment ($m) | J4: Est. tax basis in HYPE ($m) | K4: WoW basis change ($m) | L4: Implied $ per incremental token | M4: Published (UTC) | N4: Note
A5: 46205 | B5: =A5-7 -> 46198 | C5: 29.26 | E5: 227.11 | G5: 149.4 | H5: 603.83 | J5: 1016.89 | M5: 2026-07-03 00:37
A6: 46212 | B6: =A6-7 -> 46205 | C6: 29.28 | D6: =C6-C5 -> 0.02 | E6: 227.11 | F6: =E6-E5 -> 0 | G6: 149.4 | H6: 603.83 | I6: =H6-H5 -> 0 | J6: 1018.18 | K6: =J6-J5 -> 1.29 | L6: =IFERROR(IF(D6=0,"",K6/D6),"") -> 64.5 | M6: 2026-07-09 11:26
A7: 46219 | B7: =A7-7 -> 46212 | C7: 29.28 | D7: =C7-C6 -> 0 | E7: 227.11 | F7: =E7-E6 -> 0 | G7: 149.4 | H7: 603.83 | I7: =H7-H6 -> 0 | J7: 1018.18 | K7: =J7-J6 -> 0 | L7: =IFERROR(IF(D7=0,"",K7/D7),"") | M7: 2026-07-16 12:10
A8: 46226 | B8: =A8-7 -> 46219 | C8: 29.28 | D8: =C8-C7 -> 0 | E8: 227.11 | F8: =E8-E7 -> 0 | G8: 149.4 | H8: 603.83 | I8: =H8-H7 -> 0 | J8: 1018.18 | K8: =J8-J7 -> 0 | L8: =IFERROR(IF(D8=0,"",K8/D8),"") | M8: 2026-07-23 06:49
A9: 46233 | B9: =A9-7 -> 46226 | C9: 29.28 | D9: =C9-C8 -> 0 | E9: 226.7 | F9: =E9-E8 -> -0.41 | G9: 146.56 | H9: 606.67 | I9: =H9-H8 -> 2.84 | J9: 1018.18 | K9: =J9-J8 -> 0 | L9: =IFERROR(IF(D9=0,"",K9/D9),"") | M9: 2026-07-30 15:02 | N9: Deployment rises, cash falls, share count falls, HYPE flat -> buyback, not accumulation.
A10: 46240 | B10: =A10-7 -> 46233 | C10: 29.28 | D10: =C10-C9 -> 0 | E10: 224.54 | F10: =E10-E9 -> -2.16 | G10: 132.88 | H10: 620.44 | I10: =H10-H9 -> 13.77 | J10: 1021.47 | K10: =J10-J9 -> 3.29 | L10: =IFERROR(IF(D10=0,"",K10/D10),"") | M10: 2026-08-06 10:30 | N10: Largest weekly deployment in the window; share count -2.16m. HYPE still flat.
A11: 46247 | B11: =A11-7 -> 46240 | C11: 29.28 | D11: =C11-C10 -> 0 | E11: 224.43 | F11: =E11-E10 -> -0.11 | G11: 132.62 | H11: 621.17 | I11: =H11-H10 -> 0.73 | J11: 1022.27 | K11: =J11-J10 -> 0.8 | L11: =IFERROR(IF(D11=0,"",K11/D11),"") | M11: 2026-08-13 11:56
A12: 46253 | B12: =A12-7 -> 46246 | C12: 29.28 | D12: =C12-C11 -> 0 | E12: 224.43 | F12: =E12-E11 -> 0 | G12: 132.62 | H12: 621.17 | I12: =H12-H11 -> 0 | J12: 1022.27 | K12: =J12-J11 -> 0 | L12: =IFERROR(IF(D12=0,"",K12/D12),"") | M12: 2026-08-20 01:14 | N12: SUPERSEDED - republished 13 hours later as the 20-Aug page. Shown for completeness; exclude from the series.
A13: 46254 | B13: =A13-7 -> 46247 | C13: 29.35 | D13: =C13-C12 -> 0.07 | E13: 224.43 | F13: =E13-E12 -> 0 | G13: 132.62 | H13: 621.17 | I13: =H13-H12 -> 0 | J13: 1023.07 | K13: =J13-J12 -> 0.8 | L13: =IFERROR(IF(D13=0,"",K13/D13),"") -> 11.428571 | M13: 2026-08-20 14:17 | N13: +0.07m HYPE and +$4.89m tax basis with NO change to cash or cumulative deployment. Most likely a periodic booking of staking rewards (implies c.$70/token), but the inputs are internally inconsistent as published. FLAGGED.
A14: Series summary (excl. superseded 19-Aug row) | C14: =C13 -> 29.35 | D14: =C13-C5 -> 0.09 | E14: =E13 -> 224.43 | F14: =E13-E5 -> -2.68 | G14: =G13 -> 132.62 | H14: =H13 -> 621.17 | I14: =H13-H5 -> 17.34 | J14: =J13 -> 1023.07 | K14: =J13-J5 -> 6.18 | N14: Over 7 weeks: HYPE +0.09m (+0.3%), shares -2.68m (-1.2%), cash -$16.8m, deployment +$17.3m.
A16: Derived: implied buyback price over 23-Jul to 13-Aug | C16: =IFERROR((H11-H8)/(E8-E11),"") -> 6.4701493 | D16: USD/share | E16: Cumulative deployment added divided by shares retired, over a window where HYPE held was unchanged. An inference, not a company disclosure.
A17: Derived: HYPE per 1,000 as-converted shares, latest | C17: =C13/E13*1000 -> 130.77574 | D17: HYPE / 1,000 sh | E17: Excludes warrant dilution. See README - this is the metric that matters for a DAT, not the raw token count.

Sheet Share_Count
A1: PURR share count - every dated observation
A2: Common shares OUTSTANDING (net of treasury) unless noted. Preferred is shown as-converted at a fixed 26,587,647. NOTHING IS INTERPOLATED - blank months are blank.
A3: Confirmed from the dashboard's own source code: its 'Basic Shares' input = common + preferred as-converted. Common is therefore derived as Basic x 1,000,000 less 26,587,647.
A5: As-of date | B5: Month | C5: Common shares outstanding | D5: Preferred, as-converted | E5: Common + preferred (as-converted) | F5: Change vs prior obs. | G5: Days since prior obs. | H5: Tier | I5: Month-end? | J5: Source | K5: Note
A6: 45996 | B6: Dec-25 | C6: 127025563 | D6: 26587647 | E6: =IF(C6="","",C6+D6) -> 153613210 | H6: 1 | I6: No | J6: 10-Q cover page (dei:EntityCommonStockSharesOutstanding), filed 8-Dec-25 | K6: First post-listing count. Treasury shares still nil at this date.
A7: 46022 | B7: Dec-25 | C7: 124093048 | D7: 26587647 | E7: =IF(C7="","",C7+D7) -> 150680695 | F7: =C7-C6 -> -2932515 | G7: =A7-A6 -> 26 | H7: 1 | I7: YES | J7: 10-Q QE 31-Dec-25, balance sheet | K7: Issued 127,034,605 less 2,941,557 treasury shares ($10.143m, avg $3.45). Buyback programme underway.
A8: 46053 | B8: Jan-26 | E8: =IF(C8="","",C8+D8) | H8: 1 | I8: NO DATA | J8: GAP - no filing or dashboard covers January | K8: Genuine hole. Do not interpolate across the Dec-Feb buyback.
A9: 46064 | B9: Feb-26 | C9: 123967508 | D9: 26587647 | E9: =IF(C9="","",C9+D9) -> 150555155 | F9: =C9-C7 -> -125540 | G9: =A9-A7 -> 42 | H9: 1 | I9: No | J9: 10-Q cover page, filed 11-Feb-26 | K9: Ties exactly: 124,093,048 less 125,540 = 123,967,508, and treasury rose by exactly 125,540 to 3,067,097. All Q3 FY26 buybacks were complete by this date.
A10: 46112 | B10: Mar-26 | C10: 124220108 | D10: 26587647 | E10: =IF(C10="","",C10+D10) -> 150807755 | F10: =C10-C9 -> 252600 | G10: =A10-A9 -> 48 | H10: 1 | I10: YES | J10: 10-Q QE 31-Mar-26, balance sheet | K10: Issued 127,287,205 less 3,067,097 treasury.
A11: 46142 | B11: Apr-26 | E11: =IF(C11="","",C11+D11) | H11: 1 | I11: NO DATA | J11: GAP - no filing or dashboard covers April | K11: Genuine hole, and it sits in the middle of the largest equity issuance window. Do not interpolate.
A12: 46149 | B12: May-26 | C12: 134621571 | D12: 26587647 | E12: =IF(C12="","",C12+D12) -> 161209218 | F12: =C12-C10 -> 10401463 | G12: =A12-A10 -> 37 | H12: 1 | I12: No | J12: 10-Q cover page, filed 8-May-26 | K12: +10.4m vs 31-Mar in five weeks - ATM issuance under the $1bn Chardan equity facility.
A13: 46161 | B13: May-26 | C13: 144447571 | D13: 26587647 | E13: =IF(C13="","",C13+D13) -> 171035218 | F13: =C13-C12 -> 9826000 | G13: =A13-A12 -> 12 | H13: 1 | I13: No | J13: S-1 filed 22-May-26 | K13: 'As of May 19, 2026, there were 144,447,571 shares... outstanding and 166,173 shares of Series A preferred'.
A14: 46188 | B14: Jun-26 | C14: 196553055 | D14: 26587647 | E14: =IF(C14="","",C14+D14) -> 223140702 | F14: =C14-C13 -> 52105484 | G14: =A14-A13 -> 27 | H14: 1 | I14: No | J14: S-1/A filed 16-Jun-26 (repeated unchanged in the 25-Jun amendment) | K14: +52.1m in four weeks. This is the peak issuance month.
A15: 46198 | B15: Jun-26 | C15: 200522353 | D15: 26587647 | E15: =IF(C15="","",C15+D15) -> 227110000 | F15: =C15-C14 -> 3969298 | G15: =A15-A14 -> 10 | H15: 2 | I15: ~ proxy | J15: Dashboard page dated 02-Jul-26, data as-of 25-Jun on the company's stated one-week lag | K15: Derived: 227.11m basic less 26,587,647 preferred. Precision is only +/-10,000 (basic is rounded to 0.01m).
A16: 46218 | B16: Jul-26 | C16: 200563691 | D16: 26587647 | E16: =IF(C16="","",C16+D16) -> 227151338 | F16: =C16-C15 -> 41338 | G16: =A16-A15 -> 20 | H16: 1 | I16: No | J16: S-1/A filed 21-Jul-26 | K16: Best mid-July anchor. A 13G/A filed 6-Aug cites 200,563,860 for the same date - a 169-share transcription difference. Use the S-1/A.
A17: 46226 | B17: Jul-26 | C17: 200112353 | D17: 26587647 | E17: =IF(C17="","",C17+D17) -> 226700000 | F17: =C17-C16 -> -451338 | G17: =A17-A16 -> 8 | H17: 2 | I17: No | J17: Dashboard page dated 30-Jul-26, data as-of 23-Jul | K17: First observed decline - buyback resumes.
A18: 46233 | B18: Jul-26 | C18: 197952353 | D18: 26587647 | E18: =IF(C18="","",C18+D18) -> 224540000 | F18: =C18-C17 -> -2160000 | G18: =A18-A17 -> 7 | H18: 2 | I18: ~ proxy | J18: Dashboard page dated 06-Aug-26, data as-of 30-Jul | K18: -2.16m in one week, the largest single-week retirement in the series.
A19: 46240 | B19: Aug-26 | C19: 197842353 | D19: 26587647 | E19: =IF(C19="","",C19+D19) -> 224430000 | F19: =C19-C18 -> -110000 | G19: =A19-A18 -> 7 | H19: 2 | I19: No | J19: Dashboard page dated 13-Aug-26, data as-of 06-Aug
A20: 46247 | B20: Aug-26 | C20: 197842353 | D20: 26587647 | E20: =IF(C20="","",C20+D20) -> 224430000 | F20: =C20-C19 -> 0 | G20: =A20-A19 -> 7 | H20: 2 | I20: LATEST | J20: Dashboard page dated 20-Aug-26, data as-of 13-Aug | K20: Most recent observation of any kind. Not yet in any SEC filing.
A22: Latest observed | C22: =LOOKUP(2,1/(C6:C20<>""),C6:C20) -> 197842353 | D22: 26587647 | E22: =C22+D22 -> 224430000 | F22: =C22-C7 -> 73749305 | J22: Change vs 31-Dec-25 in shares (col F); in per cent -> | K22: =IFERROR(C22/C7-1,"") -> 0.5943065
A23: HYPE per 1,000 as-converted shares, latest | C23: =Master_Series!B21/E22*1000 -> 130.77574 | D23: per 1,000 as-converted | E23: =Master_Series!B21/C22*1000 -> 148.35044 | F23: per 1,000 common | J23: Latest HYPE holdings divided by the latest share count. Both are 13-Aug-2026 dashboard estimates on the company's lag convention, so the numerator and denominator are at least date-consistent.
A25: FLAGS ON THIS SHEET
A26: 1. Two definitions in play. Cover-page counts (dei) and balance-sheet counts are both net of treasury, and they tie
A27: where they overlap. Dashboard counts are DERIVED from a figure rounded to 0.01m, so they carry +/-10,000 precision.
A28: 2. Dashboard vs registration statement disagree by ~41,000 shares on the same mid-July date (200,522,353 derived vs
A29: 200,563,691 stated). That is larger than the rounding band, so the two are not the same measure - the dashboard may
A30: exclude unvested restricted shares. Immaterial at 0.02%, but do not present them as the same series.
A31: 3. January and April 2026 have no observation of any kind. Both sit inside periods of real activity (a buyback and the
A32: largest issuance window respectively). Leave them blank in any chart.
A33: 4. Warrants do not reconcile between sources. The 10-Q lists Advisor Warrants 27,394,800 plus Sonnet warrants 2,426,481
A34: = 29,821,281, all antidilutive at the time. The dashboard lists five tranches totalling 28.63m at strikes of $6.25,
A35: $9.38, $12.50 and $18.75. I have NOT built a fully-diluted series because of this - if you need one, ask IR which
A36: schedule is current before you publish a number.
... A39: 6. The ~2.7m shares retired since mid-July are NOT yet in any SEC filing. They appear only in dashboard inputs.

Sheet Diluted_Shares
A1: PURR diluted share count - treasury stock method
A2: Diluted share count is PRICE-DEPENDENT. It is not a fact you can look up; it is a calculation that changes every day the stock moves. Everything below recalculates off the PURR price in each row.
A3: Method matches the company's own stated formula: each warrant adds (Share Price less Exercise) x Amount / Share Price, counted only when Exercise is below Share Price. The Advisor Warrants carry a cashless exercise provision, so treasury-stock method is the correct treatment and no cash proceeds arrive.
A5: A. INSTRUMENT INVENTORY (as of 31 March 2026 - the latest full disclosure)
A6: Instrument | B6: Warrant shares | C6: Exercise price | D6: Value (shares x strike) | J6: Source and note
A7: Advisor Warrants - tranche 1 of 3 | B7: 9131600 | C7: 9.375 | D7: =B7*C7 -> 85608750 | J7: S-1/A 21-Jul-26: 27,394,800 Advisor Warrants issued at Closing, exercisable 5 years, one third each at $9.375 / $12.50 / $18.75. Matches the dashboard's 'Sponsor 1.5x' tranche.
A8: Advisor Warrants - tranche 2 of 3 | B8: 9131600 | C8: 12.5 | D8: =B8*C8 -> 114145000 | J8: Dashboard 'Sponsor 2.0x'.
A9: Advisor Warrants - tranche 3 of 3 | B9: 9131600 | C9: 18.75 | D9: =B9*C9 -> 171217500 | J9: Dashboard 'Sponsor 3.0x'.
A10: 2025 Bridge Financing Warrants (200% coverage) | B10: 640000 | C10: 6.25 | D10: =B10*C10 -> 4000000 | J10: Strike and amount per the dashboard's warrant table only - not separately quantified in the filings. Part of the 2,426,481 non-Advisor block.
A11: 2025 PIPE Financing Warrants | B11: 600000 | C11: 6.25 | D11: =B11*C11 -> 3750000 | J11: Dashboard only, as above.
A12: Legacy warrant remainder - NOT IDENTIFIED | B12: 1186481 | C12: 30.92 | D12: =B12*C12 -> 36685993 | J12: PLUG. The filings give 29,821,281 total warrants at a weighted average strike of $13.93; the Advisor block accounts for 27,394,800 at an average of $13.5417. That leaves 2,426,481 at an implied average of $18.31. Net of the two dashboard tranches above, this residual is implied at ~$30.92. Deep out of the money on any current view, so it does not affect the diluted count - but the strike is DERIVED, not disclosed.
A13: Total warrants outstanding | B13: =SUM(B7:B12) -> 29821281 | C13: =D13/B13 -> 13.929893 | D13: =SUM(D7:D12) -> 4.1540724e+08 | J13: Weighted average strike in column C is calculated, and must equal the $13.93 disclosed in the S-1/A.
A14: TIE-OUT vs disclosure | B14: 29821281 | C14: 13.93 | D14: =B14*C14 -> 4.1541044e+08 | J14: =IF(AND(B13=B14,ABS(C13-C14)<0.01),"TIES on both share count and weighted average strike","DOES NOT TIE - INVESTIGATE") -> TIES on both share count and weighted average strike
A16: Memo - other potentially dilutive instruments
A17: Series A preferred, as-converted | B17: 26587647 | J17: Fixed conversion into 26,587,647 common. INCLUDED in the basic count throughout this workbook, per the company's own convention. Subject to blocker provisions, so the full amount may not be convertible at a point in time.
A18: Unvested RSUs, 2025 Equity Incentive Plan | B18: 747935 | J18: As of 31-Mar-26. EXCLUDED from the bridge below because the dashboard excludes them and the treasury-stock effect is small: the reported dilutive effect in Q3 FY26 was only 7,901 shares. Stale by five months and will have grown - 326,312 RSUs were granted in the nine months to March.
A19: Shares reserved for future issuance under the EIP | B19: 5783343 | J19: As of 31-Mar-26. EXCLUDED - reserved, not outstanding. Do not add these to a diluted count.
A21: B. DILUTED SHARE COUNT AT EACH DATED OBSERVATION
A22: As-of date | B22: PURR close ($) | C22: Common shares o/s | D22: Preferred as-converted | E22: Basic (common + preferred) | F22: Warrant dilution (TSM) | G22: Diluted shares | H22: Dilution vs basic (%) | I22: ITM tranches | J22: Source / note
A23: 45996 | B23: 3.68 | C23: 127025563 | D23: 26587647 | E23: =C23+D23 -> 153613210 | F23: =IF($B23>$C$7,($B23-$C$7)/$B23*$B$7,0)+IF($B23>$C$8,($B23-$C$8)/$B23*$B$8,0)+IF($B23>$C$9,($B23-$C$9)/$B23*$B$9,0)+IF($B23>$C$10,($B23-$C$10)/$B23*$B$10,0)+IF($B23>$C$11,($B23-$C$11)/$B23*$B$11,0)+IF($B23>$C$12,($B23-$C$12)/$B23*$B$12,0) -> 0 | G23: =E23+F23 -> 153613210 | H23: =IFERROR(G23/E23-1,"") -> 0 | I23: =IF($B23>$C$7,1,0)+IF($B23>$C$8,1,0)+IF($B23>$C$9,1,0)+IF($B23>$C$10,1,0)+IF($B23>$C$11,1,0)+IF($B23>$C$12,1,0) -> 0 | J23: 10-Q cover
A24: 46022 | B24: 3.56 | C24: 124093048 | D24: 26587647 | E24: =C24+D24 -> 150680695 | F24: =IF($B24>$C$7,($B24-$C$7)/$B24*$B$7,0)+IF($B24>$C$8,($B24-$C$8)/$B24*$B$8,0)+IF($B24>$C$9,($B24-$C$9)/$B24*$B$9,0)+IF($B24>$C$10,($B24-$C$10)/$B24*$B$10,0)+IF($B24>$C$11,($B24-$C$11)/$B24*$B$11,0)+IF($B24>$C$12,($B24-$C$12)/$B24*$B$12,0) -> 0 | G24: =E24+F24 -> 150680695 | H24: =IFERROR(G24/E24-1,"") -> 0 | I24: =IF($B24>$C$7,1,0)+IF($B24>$C$8,1,0)+IF($B24>$C$9,1,0)+IF($B24>$C$10,1,0)+IF($B24>$C$11,1,0)+IF($B24>$C$12,1,0) -> 0 | J24: 10-Q balance sheet
A25: 46064 | B25: 4.54 | C25: 123967508 | D25: 26587647 | E25: =C25+D25 -> 150555155 | F25: =IF($B25>$C$7,($B25-$C$7)/$B25*$B$7,0)+IF($B25>$C$8,($B25-$C$8)/$B25*$B$8,0)+IF($B25>$C$9,($B25-$C$9)/$B25*$B$9,0)+IF($B25>$C$10,($B25-$C$10)/$B25*$B$10,0)+IF($B25>$C$11,($B25-$C$11)/$B25*$B$11,0)+IF($B25>$C$12,($B25-$C$12)/$B25*$B$12,0) -> 0 | G25: =E25+F25 -> 150555155 | H25: =IFERROR(G25/E25-1,"") -> 0 | I25: =IF($B25>$C$7,1,0)+IF($B25>$C$8,1,0)+IF($B25>$C$9,1,0)+IF($B25>$C$10,1,0)+IF($B25>$C$11,1,0)+IF($B25>$C$12,1,0) -> 0 | J25: 10-Q cover
A26: 46112 | B26: 5.09 | C26: 124220108 | D26: 26587647 | E26: =C26+D26 -> 150807755 | F26: =IF($B26>$C$7,($B26-$C$7)/$B26*$B$7,0)+IF($B26>$C$8,($B26-$C$8)/$B26*$B$8,0)+IF($B26>$C$9,($B26-$C$9)/$B26*$B$9,0)+IF($B26>$C$10,($B26-$C$10)/$B26*$B$10,0)+IF($B26>$C$11,($B26-$C$11)/$B26*$B$11,0)+IF($B26>$C$12,($B26-$C$12)/$B26*$B$12,0) -> 0 | G26: =E26+F26 -> 150807755 | H26: =IFERROR(G26/E26-1,"") -> 0 | I26: =IF($B26>$C$7,1,0)+IF($B26>$C$8,1,0)+IF($B26>$C$9,1,0)+IF($B26>$C$10,1,0)+IF($B26>$C$11,1,0)+IF($B26>$C$12,1,0) -> 0 | J26: 10-Q balance sheet
A27: 46149 | B27: 6.55 | C27: 134621571 | D27: 26587647 | E27: =C27+D27 -> 161209218 | F27: =IF($B27>$C$7,($B27-$C$7)/$B27*$B$7,0)+IF($B27>$C$8,($B27-$C$8)/$B27*$B$8,0)+IF($B27>$C$9,($B27-$C$9)/$B27*$B$9,0)+IF($B27>$C$10,($B27-$C$10)/$B27*$B$10,0)+IF($B27>$C$11,($B27-$C$11)/$B27*$B$11,0)+IF($B27>$C$12,($B27-$C$12)/$B27*$B$12,0) -> 56793.893 | G27: =E27+F27 -> 1.6126601e+08 | H27: =IFERROR(G27/E27-1,"") -> 0.00035229929 | I27: =IF($B27>$C$7,1,0)+IF($B27>$C$8,1,0)+IF($B27>$C$9,1,0)+IF($B27>$C$10,1,0)+IF($B27>$C$11,1,0)+IF($B27>$C$12,1,0) -> 2 | J27: 10-Q cover
A28: 46161 | B28: 7.79 | C28: 144447571 | D28: 26587647 | E28: =C28+D28 -> 171035218 | F28: =IF($B28>$C$7,($B28-$C$7)/$B28*$B$7,0)+IF($B28>$C$8,($B28-$C$8)/$B28*$B$8,0)+IF($B28>$C$9,($B28-$C$9)/$B28*$B$9,0)+IF($B28>$C$10,($B28-$C$10)/$B28*$B$10,0)+IF($B28>$C$11,($B28-$C$11)/$B28*$B$11,0)+IF($B28>$C$12,($B28-$C$12)/$B28*$B$12,0) -> 245134.79 | G28: =E28+F28 -> 1.7128035e+08 | H28: =IFERROR(G28/E28-1,"") -> 0.0014332416 | I28: =IF($B28>$C$7,1,0)+IF($B28>$C$8,1,0)+IF($B28>$C$9,1,0)+IF($B28>$C$10,1,0)+IF($B28>$C$11,1,0)+IF($B28>$C$12,1,0) -> 2 | J28: S-1
A29: 46188 | B29: 9.34 | C29: 196553055 | D29: 26587647 | E29: =C29+D29 -> 223140702 | F29: =IF($B29>$C$7,($B29-$C$7)/$B29*$B$7,0)+IF($B29>$C$8,($B29-$C$8)/$B29*$B$8,0)+IF($B29>$C$9,($B29-$C$9)/$B29*$B$9,0)+IF($B29>$C$10,($B29-$C$10)/$B29*$B$10,0)+IF($B29>$C$11,($B29-$C$11)/$B29*$B$11,0)+IF($B29>$C$12,($B29-$C$12)/$B29*$B$12,0) -> 410235.55 | G29: =E29+F29 -> 2.2355094e+08 | H29: =IFERROR(G29/E29-1,"") -> 0.0018384613 | I29: =IF($B29>$C$7,1,0)+IF($B29>$C$8,1,0)+IF($B29>$C$9,1,0)+IF($B29>$C$10,1,0)+IF($B29>$C$11,1,0)+IF($B29>$C$12,1,0) -> 2 | J29: S-1/A. PURR closed 3.5 cents below the $9.375 strike - the first tranche was very nearly in the money.
A30: 46218 | B30: 7.61 | C30: 200563691 | D30: 26587647 | E30: =C30+D30 -> 227151338 | F30: =IF($B30>$C$7,($B30-$C$7)/$B30*$B$7,0)+IF($B30>$C$8,($B30-$C$8)/$B30*$B$8,0)+IF($B30>$C$9,($B30-$C$9)/$B30*$B$9,0)+IF($B30>$C$10,($B30-$C$10)/$B30*$B$10,0)+IF($B30>$C$11,($B30-$C$11)/$B30*$B$11,0)+IF($B30>$C$12,($B30-$C$12)/$B30*$B$12,0) -> 221603.15 | G30: =E30+F30 -> 2.2737294e+08 | H30: =IFERROR(G30/E30-1,"") -> 0.00097557494 | I30: =IF($B30>$C$7,1,0)+IF($B30>$C$8,1,0)+IF($B30>$C$9,1,0)+IF($B30>$C$10,1,0)+IF($B30>$C$11,1,0)+IF($B30>$C$12,1,0) -> 2 | J30: S-1/A
A31: 46226 | B31: 6.51 | C31: 200112353 | D31: 26587647 | E31: =C31+D31 -> 226700000 | F31: =IF($B31>$C$7,($B31-$C$7)/$B31*$B$7,0)+IF($B31>$C$8,($B31-$C$8)/$B31*$B$8,0)+IF($B31>$C$9,($B31-$C$9)/$B31*$B$9,0)+IF($B31>$C$10,($B31-$C$10)/$B31*$B$10,0)+IF($B31>$C$11,($B31-$C$11)/$B31*$B$11,0)+IF($B31>$C$12,($B31-$C$12)/$B31*$B$12,0) -> 49523.81 | G31: =E31+F31 -> 2.2674952e+08 | H31: =IFERROR(G31/E31-1,"") -> 0.00021845527 | I31: =IF($B31>$C$7,1,0)+IF($B31>$C$8,1,0)+IF($B31>$C$9,1,0)+IF($B31>$C$10,1,0)+IF($B31>$C$11,1,0)+IF($B31>$C$12,1,0) -> 2 | J31: Dashboard, data as-of
A32: 46233 | B32: 6.3 | C32: 197952353 | D32: 26587647 | E32: =C32+D32 -> 224540000 | F32: =IF($B32>$C$7,($B32-$C$7)/$B32*$B$7,0)+IF($B32>$C$8,($B32-$C$8)/$B32*$B$8,0)+IF($B32>$C$9,($B32-$C$9)/$B32*$B$9,0)+IF($B32>$C$10,($B32-$C$10)/$B32*$B$10,0)+IF($B32>$C$11,($B32-$C$11)/$B32*$B$11,0)+IF($B32>$C$12,($B32-$C$12)/$B32*$B$12,0) -> 9841.2698 | G32: =E32+F32 -> 2.2454984e+08 | H32: =IFERROR(G32/E32-1,"") -> 4.3828582e-05 | I32: =IF($B32>$C$7,1,0)+IF($B32>$C$8,1,0)+IF($B32>$C$9,1,0)+IF($B32>$C$10,1,0)+IF($B32>$C$11,1,0)+IF($B32>$C$12,1,0) -> 2 | J32: Dashboard, data as-of
A33: 46240 | B33: 6.67 | C33: 197842353 | D33: 26587647 | E33: =C33+D33 -> 224430000 | F33: =IF($B33>$C$7,($B33-$C$7)/$B33*$B$7,0)+IF($B33>$C$8,($B33-$C$8)/$B33*$B$8,0)+IF($B33>$C$9,($B33-$C$9)/$B33*$B$9,0)+IF($B33>$C$10,($B33-$C$10)/$B33*$B$10,0)+IF($B33>$C$11,($B33-$C$11)/$B33*$B$11,0)+IF($B33>$C$12,($B33-$C$12)/$B33*$B$12,0) -> 78080.96 | G33: =E33+F33 -> 2.2450808e+08 | H33: =IFERROR(G33/E33-1,"") -> 0.00034790785 | I33: =IF($B33>$C$7,1,0)+IF($B33>$C$8,1,0)+IF($B33>$C$9,1,0)+IF($B33>$C$10,1,0)+IF($B33>$C$11,1,0)+IF($B33>$C$12,1,0) -> 2 | J33: Dashboard, data as-of
A34: 46247 | B34: 6.82 | C34: 197842353 | D34: 26587647 | E34: =C34+D34 -> 224430000 | F34: =IF($B34>$C$7,($B34-$C$7)/$B34*$B$7,0)+IF($B34>$C$8,($B34-$C$8)/$B34*$B$8,0)+IF($B34>$C$9,($B34-$C$9)/$B34*$B$9,0)+IF($B34>$C$10,($B34-$C$10)/$B34*$B$10,0)+IF($B34>$C$11,($B34-$C$11)/$B34*$B$11,0)+IF($B34>$C$12,($B34-$C$12)/$B34*$B$12,0) -> 103636.36 | G34: =E34+F34 -> 2.2453364e+08 | H34: =IFERROR(G34/E34-1,"") -> 0.00046177589 | I34: =IF($B34>$C$7,1,0)+IF($B34>$C$8,1,0)+IF($B34>$C$9,1,0)+IF($B34>$C$10,1,0)+IF($B34>$C$11,1,0)+IF($B34>$C$12,1,0) -> 2 | J34: Dashboard, data as-of. Last date on which share count and price are both properly dated.
A35: 46260 | B35: 11.56 | C35: 197842353 | D35: 26587647 | E35: =C35+D35 -> 224430000 | F35: =IF($B35>$C$7,($B35-$C$7)/$B35*$B$7,0)+IF($B35>$C$8,($B35-$C$8)/$B35*$B$8,0)+IF($B35>$C$9,($B35-$C$9)/$B35*$B$9,0)+IF($B35>$C$10,($B35-$C$10)/$B35*$B$10,0)+IF($B35>$C$11,($B35-$C$11)/$B35*$B$11,0)+IF($B35>$C$12,($B35-$C$12)/$B35*$B$12,0) -> 2295583.6 | G35: =E35+F35 -> 2.2672558e+08 | H35: =IFERROR(G35/E35-1,"") -> 0.010228506 | I35: =IF($B35>$C$7,1,0)+IF($B35>$C$8,1,0)+IF($B35>$C$9,1,0)+IF($B35>$C$10,1,0)+IF($B35>$C$11,1,0)+IF($B35>$C$12,1,0) -> 3 | J35: MISMATCHED DATES: price is the 26-Aug close, share count is still the 13-Aug estimate. PURR rose 70% over those nine sessions and crossed the $9.375 strike. Shown because it is the only current view available, but the numerator and denominator are not date-consistent.
A37: C. SENSITIVITY - diluted shares at the 13-Aug-2026 basic count, across PURR prices
A38: PURR price | C38: Common shares o/s | D38: Preferred as-converted | E38: Basic (common + preferred) | F38: Warrant dilution (TSM) | G38: Diluted shares | H38: Dilution vs basic (%) | I38: ITM tranches | J38: Note
A39: 6.25 | C39: 197842353 | D39: 26587647 | E39: =C39+D39 -> 224430000 | F39: =IF($A39>$C$7,($A39-$C$7)/$A39*$B$7,0)+IF($A39>$C$8,($A39-$C$8)/$A39*$B$8,0)+IF($A39>$C$9,($A39-$C$9)/$A39*$B$9,0)+IF($A39>$C$10,($A39-$C$10)/$A39*$B$10,0)+IF($A39>$C$11,($A39-$C$11)/$A39*$B$11,0)+IF($A39>$C$12,($A39-$C$12)/$A39*$B$12,0) -> 0 | G39: =E39+F39 -> 224430000 | H39: =IFERROR(G39/E39-1,"") -> 0 | I39: =IF($A39>$C$7,1,0)+IF($A39>$C$8,1,0)+IF($A39>$C$9,1,0)+IF($A39>$C$10,1,0)+IF($A39>$C$11,1,0)+IF($A39>$C$12,1,0) -> 0 | J39: Below every strike - no dilution at all.
A40: 6.82 | C40: 197842353 | D40: 26587647 | E40: =C40+D40 -> 224430000 | F40: =IF($A40>$C$7,($A40-$C$7)/$A40*$B$7,0)+IF($A40>$C$8,($A40-$C$8)/$A40*$B$8,0)+IF($A40>$C$9,($A40-$C$9)/$A40*$B$9,0)+IF($A40>$C$10,($A40-$C$10)/$A40*$B$10,0)+IF($A40>$C$11,($A40-$C$11)/$A40*$B$11,0)+IF($A40>$C$12,($A40-$C$12)/$A40*$B$12,0) -> 103636.36 | G40: =E40+F40 -> 2.2453364e+08 | H40: =IFERROR(G40/E40-1,"") -> 0.00046177589 | I40: =IF($A40>$C$7,1,0)+IF($A40>$C$8,1,0)+IF($A40>$C$9,1,0)+IF($A40>$C$10,1,0)+IF($A40>$C$11,1,0)+IF($A40>$C$12,1,0) -> 2
A41: 9.375 | C41: 197842353 | D41: 26587647 | E41: =C41+D41 -> 224430000 | F41: =IF($A41>$C$7,($A41-$C$7)/$A41*$B$7,0)+IF($A41>$C$8,($A41-$C$8)/$A41*$B$8,0)+IF($A41>$C$9,($A41-$C$9)/$A41*$B$9,0)+IF($A41>$C$10,($A41-$C$10)/$A41*$B$10,0)+IF($A41>$C$11,($A41-$C$11)/$A41*$B$11,0)+IF($A41>$C$12,($A41-$C$12)/$A41*$B$12,0) -> 413333.33 | G41: =E41+F41 -> 2.2484333e+08 | H41: =IFERROR(G41/E41-1,"") -> 0.0018417027 | I41: =IF($A41>$C$7,1,0)+IF($A41>$C$8,1,0)+IF($A41>$C$9,1,0)+IF($A41>$C$10,1,0)+IF($A41>$C$11,1,0)+IF($A41>$C$12,1,0) -> 2 | J41: At the first Advisor strike. One cent higher and 9.13m warrants begin to count.
A42: 11.56 | C42: 197842353 | D42: 26587647 | E42: =C42+D42 -> 224430000 | F42: =IF($A42>$C$7,($A42-$C$7)/$A42*$B$7,0)+IF($A42>$C$8,($A42-$C$8)/$A42*$B$8,0)+IF($A42>$C$9,($A42-$C$9)/$A42*$B$9,0)+IF($A42>$C$10,($A42-$C$10)/$A42*$B$10,0)+IF($A42>$C$11,($A42-$C$11)/$A42*$B$11,0)+IF($A42>$C$12,($A42-$C$12)/$A42*$B$12,0) -> 2295583.6 | G42: =E42+F42 -> 2.2672558e+08 | H42: =IFERROR(G42/E42-1,"") -> 0.010228506 | I42: =IF($A42>$C$7,1,0)+IF($A42>$C$8,1,0)+IF($A42>$C$9,1,0)+IF($A42>$C$10,1,0)+IF($A42>$C$11,1,0)+IF($A42>$C$12,1,0) -> 3 | J42: Last close, 26-Aug-2026.
A43: 12.5 | C43: 197842353 | D43: 26587647 | E43: =C43+D43 -> 224430000 | F43: =IF($A43>$C$7,($A43-$C$7)/$A43*$B$7,0)+IF($A43>$C$8,($A43-$C$8)/$A43*$B$8,0)+IF($A43>$C$9,($A43-$C$9)/$A43*$B$9,0)+IF($A43>$C$10,($A43-$C$10)/$A43*$B$10,0)+IF($A43>$C$11,($A43-$C$11)/$A43*$B$11,0)+IF($A43>$C$12,($A43-$C$12)/$A43*$B$12,0) -> 2902900 | G43: =E43+F43 -> 227332900 | H43: =IFERROR(G43/E43-1,"") -> 0.012934545 | I43: =IF($A43>$C$7,1,0)+IF($A43>$C$8,1,0)+IF($A43>$C$9,1,0)+IF($A43>$C$10,1,0)+IF($A43>$C$11,1,0)+IF($A43>$C$12,1,0) -> 3 | J43: Second Advisor tranche starts to count here.
A44: 15 | C44: 197842353 | D44: 26587647 | E44: =C44+D44 -> 224430000 | F44: =IF($A44>$C$7,($A44-$C$7)/$A44*$B$7,0)+IF($A44>$C$8,($A44-$C$8)/$A44*$B$8,0)+IF($A44>$C$9,($A44-$C$9)/$A44*$B$9,0)+IF($A44>$C$10,($A44-$C$10)/$A44*$B$10,0)+IF($A44>$C$11,($A44-$C$11)/$A44*$B$11,0)+IF($A44>$C$12,($A44-$C$12)/$A44*$B$12,0) -> 5669616.7 | G44: =E44+F44 -> 2.3009962e+08 | H44: =IFERROR(G44/E44-1,"") -> 0.025262294 | I44: =IF($A44>$C$7,1,0)+IF($A44>$C$8,1,0)+IF($A44>$C$9,1,0)+IF($A44>$C$10,1,0)+IF($A44>$C$11,1,0)+IF($A44>$C$12,1,0) -> 4
...

Sheet Token_RollForward
A1: Tier 3 - Unit-level roll-forward, per 10-Q Note 3 (Digital Assets)
A2: Source: 10-Q for the quarter ended 31 March 2026, accession 0001193125-26-212519, Note 3. Dollar and unit tables reproduced side by side.
A4: Line | B4: HYPE tokens | C4: HYPE $000 | D4: Implied $/token | E4: Comment
A5: Balance, 30 June 2025 | B5: 0 | C5: 0 | D5: =IFERROR(IF(OR(B5="",B5=0),"",C5*1000/B5),"")
A6: Balance, 30 September 2025 | B6: 0 | C6: 0 | D6: =IFERROR(IF(OR(B6="",B6=0),"",C6*1000/B6),"")
A7: Contributions of HYPE from Rorschach Contributions | B7: 12517592 | C7: 580466 | D7: =IFERROR(IF(OR(B7="",B7=0),"",C7*1000/B7),"") -> 46.372018 | E7: Recognised at commitment-date fair value of $46.37. Actual closing-date value was $411.3m ($32.86), producing a $169.2m loss on contribution commitment.
A8: Purchases (quarter to 31 December 2025) | B8: 321224 | C8: 9000 | D8: =IFERROR(IF(OR(B8="",B8=0),"",C8*1000/B8),"") -> 28.017832 | E8: First open-market accumulation.
A9: Unrealized loss | C9: -93200 | D9: =IFERROR(IF(OR(B9="",B9=0),"",C9*1000/B9),"")
A10: Loss on HYPE contribution commitment | C10: -169156 | D10: =IFERROR(IF(OR(B10="",B10=0),"",C10*1000/B10),"")
A11: Receipt of HYPE from staking activities | B11: 18717 | C11: 500 | D11: =IFERROR(IF(OR(B11="",B11=0),"",C11*1000/B11),"") -> 26.713683 | E11: Non-cash. Adds tokens without deploying capital.
A12: Balance, 31 December 2025 | B12: 12857533 | C12: 327610 | D12: =IFERROR(IF(OR(B12="",B12=0),"",C12*1000/B12),"") -> 25.480005 | E12: Ties to XBRL CryptoAssetNumberOfUnits. Quarter-end HYPE $25.48.
A13: Purchases (quarter to 31 March 2026) | B13: 5884940 | C13: 160373 | D13: =IFERROR(IF(OR(B13="",B13=0),"",C13*1000/B13),"") -> 27.251425
A14: Unrealized gains | C14: 198435 | D14: =IFERROR(IF(OR(B14="",B14=0),"",C14*1000/B14),"")
A15: Receipt of HYPE from staking activities | B15: 83832 | C15: 2626 | D15: =IFERROR(IF(OR(B15="",B15=0),"",C15*1000/B15),"") -> 31.324554 | E15: 4.5x the prior quarter's staking receipts, on a larger staked base.
A16: Other receipts of HYPE | B16: 50 | C16: 1 | D16: =IFERROR(IF(OR(B16="",B16=0),"",C16*1000/B16),"") -> 20
A17: Balance, 31 March 2026 | B17: 18826355 | C17: 689045 | D17: =IFERROR(IF(OR(B17="",B17=0),"",C17*1000/B17),"") -> 36.600022 | E17: Quarter-end HYPE $36.60. A further $0.5m of USDC brings total digital assets to $689.545m.
A19: TIE-OUT: 12,857,533 + 5,884,940 + 83,832 + 50 | B19: =B12+B13+B15+B16 -> 18826355 | D19: =IF(B19=B17,"TIES to reported 31-Mar balance","DOES NOT TIE") -> TIES to reported 31-Mar balance
A21: Weighted average cash cost of tokens PURCHASED (Dec-25 + Q3 FY26) | B21: =B8+B13 -> 6206164 | C21: =C8+C13 -> 169373 | D21: =IFERROR(C21*1000/B21,"") -> 27.291093 | E21: This is the only defensible average cost figure. It EXCLUDES the 12.5m contributed tokens, which were never purchased. Do not blend the two.

Sheet Master_Series
A1: Merged observation series - every dated HYPE holdings datapoint, by source tier
A2: Sorted by as-of date. NOTHING IS INTERPOLATED. Gaps between rows are real gaps in disclosure and should be shown as such in any chart.
A4: As-of date | B4: HYPE tokens | C4: Tokens (m) | D4: Tier | E4: Precision | F4: Days since prior obs. | G4: Change vs prior (tokens) | H4: Implied tokens added per day | I4: Value at current HYPE ($m) | J4: Source
A5: 45993 | B5: 12517592 | C5: =IF(B5="","",B5/1000000) -> 12.517592 | D5: 1 | E5: Exact | I5: =IF(B5="","",B5*Assumptions!$B$4/1000000) -> 1037.458 | J5: 10-Q Q3 FY26 Note 3 (roll-forward)
A6: 46022 | B6: 12857533 | C6: =IF(B6="","",B6/1000000) -> 12.857533 | D6: 1 | E6: Exact | F6: =A6-A5 -> 29 | G6: =B6-B5 -> 339941 | H6: =IFERROR(G6/F6,"") -> 11722.103 | I6: =IF(B6="","",B6*Assumptions!$B$4/1000000) -> 1065.6323 | J6: 10-Q Q2 FY26 Note 3 / XBRL
A7: 46056 | B7: 17600000 | C7: =IF(B7="","",B7/1000000) -> 17.6 | D7: 1 | E7: Rounded 0.1m | F7: =A7-A6 -> 34 | G7: =B7-B6 -> 4742467 | H7: =IFERROR(G7/F7,"") -> 139484.32 | I7: =IF(B7="","",B7*Assumptions!$B$4/1000000) -> 1458.688 | J7: 8-K 11-Feb-26 Ex-99.1
A8: 46112 | B8: 18826355 | C8: =IF(B8="","",B8/1000000) -> 18.826355 | D8: 1 | E8: Exact | F8: =A8-A7 -> 56 | G8: =B8-B7 -> 1226355 | H8: =IFERROR(G8/F8,"") -> 21899.196 | I8: =IF(B8="","",B8*Assumptions!$B$4/1000000) -> 1560.3283 | J8: 10-Q Q3 FY26 Note 3
A9: 46141 | B9: 20000000 | C9: =IF(B9="","",B9/1000000) -> 20 | D9: 1 | E9: Rounded 0.1m | F9: =A9-A8 -> 29 | G9: =B9-B8 -> 1173645 | H9: =IFERROR(G9/F9,"") -> 40470.517 | I9: =IF(B9="","",B9*Assumptions!$B$4/1000000) -> 1657.6 | J9: 8-K 7-May-26 Ex-99.1
A10: 46156 | B10: 20800000 | C10: =IF(B10="","",B10/1000000) -> 20.8 | D10: 1 | E10: Rounded 0.1m | F10: =A10-A9 -> 15 | G10: =B10-B9 -> 800000 | H10: =IFERROR(G10/F10,"") -> 53333.333 | I10: =IF(B10="","",B10*Assumptions!$B$4/1000000) -> 1723.904 | J10: S-1 22-May-26
A11: 46198 | C11: =IF(B11="","",B11/1000000) | D11: 1 | E11: NOT DISCLOSED | I11: =IF(B11="","",B11*Assumptions!$B$4/1000000) | J11: GAP - S-1/A amendments of 16-Jun and 25-Jun did not refresh the holdings date
A12: 46203 | C12: =IF(B12="","",B12/1000000) | D12: 1 | E12: AWAITED | I12: =IF(B12="","",B12*Assumptions!$B$4/1000000) | J12: FY2026 10-K / earnings release - webcast 27-Aug-26 08:00 ET, not filed as at 09:45 UTC
A13: 46205 | B13: 29260000 | C13: =IF(B13="","",B13/1000000) -> 29.26 | D13: 2 | E13: Rounded 0.01m | F13: =A13-A10 -> 49 | G13: =B13-B10 -> 8460000 | H13: =IFERROR(G13/F13,"") -> 172653.06 | I13: =IF(B13="","",B13*Assumptions!$B$4/1000000) -> 2425.0688 | J13: Dashboard version history (page dated 02-Jul-26)
A14: 46212 | B14: 29280000 | C14: =IF(B14="","",B14/1000000) -> 29.28 | D14: 2 | E14: Rounded 0.01m | F14: =A14-A13 -> 7 | G14: =B14-B13 -> 20000 | H14: =IFERROR(G14/F14,"") -> 2857.1429 | I14: =IF(B14="","",B14*Assumptions!$B$4/1000000) -> 2426.7264 | J14: Dashboard version history
A15: 46218 | B15: 29300000 | C15: =IF(B15="","",B15/1000000) -> 29.3 | D15: 1 | E15: Rounded 0.1m | F15: =A15-A14 -> 6 | G15: =B15-B14 -> 20000 | H15: =IFERROR(G15/F15,"") -> 3333.3333 | I15: =IF(B15="","",B15*Assumptions!$B$4/1000000) -> 2428.384 | J15: S-1/A 21-Jul-26
A16: 46219 | B16: 29280000 | C16: =IF(B16="","",B16/1000000) -> 29.28 | D16: 2 | E16: Rounded 0.01m | F16: =A16-A15 -> 1 | G16: =B16-B15 -> -20000 | H16: =IFERROR(G16/F16,"") -> -20000 | I16: =IF(B16="","",B16*Assumptions!$B$4/1000000) -> 2426.7264 | J16: Dashboard version history. The apparent -20k vs the 15-Jul S-1/A figure is a rounding artefact of mixing a 0.1m-rounded disclosure with a 0.01m-rounded estimate - NOT a sale.
A17: 46226 | B17: 29280000 | C17: =IF(B17="","",B17/1000000) -> 29.28 | D17: 2 | E17: Rounded 0.01m | F17: =A17-A16 -> 7 | G17: =B17-B16 -> 0 | H17: =IFERROR(G17/F17,"") -> 0 | I17: =IF(B17="","",B17*Assumptions!$B$4/1000000) -> 2426.7264 | J17: Dashboard version history
A18: 46233 | B18: 29280000 | C18: =IF(B18="","",B18/1000000) -> 29.28 | D18: 2 | E18: Rounded 0.01m | F18: =A18-A17 -> 7 | G18: =B18-B17 -> 0 | H18: =IFERROR(G18/F18,"") -> 0 | I18: =IF(B18="","",B18*Assumptions!$B$4/1000000) -> 2426.7264 | J18: Dashboard version history
A19: 46240 | B19: 29280000 | C19: =IF(B19="","",B19/1000000) -> 29.28 | D19: 2 | E19: Rounded 0.01m | F19: =A19-A18 -> 7 | G19: =B19-B18 -> 0 | H19: =IFERROR(G19/F19,"") -> 0 | I19: =IF(B19="","",B19*Assumptions!$B$4/1000000) -> 2426.7264 | J19: Dashboard version history
A20: 46247 | B20: 29280000 | C20: =IF(B20="","",B20/1000000) -> 29.28 | D20: 2 | E20: Rounded 0.01m | F20: =A20-A19 -> 7 | G20: =B20-B19 -> 0 | H20: =IFERROR(G20/F20,"") -> 0 | I20: =IF(B20="","",B20*Assumptions!$B$4/1000000) -> 2426.7264 | J20: Dashboard version history
A21: 46254 | B21: 29350000 | C21: =IF(B21="","",B21/1000000) -> 29.35 | D21: 2 | E21: Rounded 0.01m | F21: =A21-A20 -> 7 | G21: =B21-B20 -> 70000 | H21: =IFERROR(G21/F21,"") -> 10000 | I21: =IF(B21="","",B21*Assumptions!$B$4/1000000) -> 2432.528 | J21: Dashboard, live (current published page)
A23: Latest observed holdings | B23: =LOOKUP(2,1/(B5:B21<>""),B5:B21) -> 29350000 | C23: =B23/1000000 -> 29.35 | I23: =B23*Assumptions!$B$4/1000000 -> 2432.528 | J23: Gap-aware LOOKUP - returns the last non-blank observation, not the last row.
A24: Growth, 2-Dec-25 to latest | B24: =B23-B5 -> 16832408 | C24: =IFERROR(B23/B5-1,"") -> 1.3447002 | J24: Multiple of the opening in-kind contribution.
A26: CHART GUIDANCE | B26: Plot Tier 1 as markers with a dashed connector; plot Tier 2 as a separate stepped series. Do not draw one continuous line through both - the two are different measurement bases (audited/disclosed vs weekly company estimate) and the 25-Jun and 30-Jun rows are genuine holes.

Sheet Third_Party_Check
A1: Third-party trackers - do not use
A2: Checked 27-Aug-2026. Both are materially wrong, in opposite directions.
A4: Source | B4: HYPE holdings shown | C4: Avg cost shown | D4: Total cost shown | E4: What is actually wrong | F4: Verdict
A5: CoinGecko treasuries | B5: 17,600,000 | C5: $7.36 | D5: $129.5m | E5: The 17.6m figure is the 3-Feb-2026 press release number, six months stale and 40% below the current position. The cost basis divides $129.5m (the cash spent on ~5.0m purchased tokens) by all 17.6m tokens, 12.5m of which were contributed in kind and cost the company nothing in cash. The stock price shown ($10.08) also did not match the market. | F5: Stale and methodologically wrong
A6: DefiLlama DAT page | B6: 16,890,000 | C6: $46.37 | D6: $783.15m | E6: Holdings figure does not correspond to any disclosed balance. $46.37 is the commitment-date valuation of the contributed tokens, not a purchase price - the tokens were actually recognised at $32.86 on the closing date. 'Total transactions: 2' and 'latest announcement 3-Dec-2025' show the feed stopped updating at listing. | F6: Stale and methodologically wrong
A7: Correct, per filings | B7: 29,350,000 (20-Aug-26 dashboard) / 18,826,355 (31-Mar-26 audited-period balance) | C7: See Token_RollForward | D7: n/a | E7: Cash cost only applies to purchased tokens. Contributed tokens must be carried separately or the average is meaningless. | F7: Use this

Sheet Source_Log
A1: Source log - every endpoint and document used
A3: # | B3: Source | C3: URL | D3: What it gave | E3: Access notes
A4: 1 | B4: SEC EDGAR submissions | C4: https://data.sec.gov/submissions/CIK0002078856.json | D4: Entity verification: name, CIK, ticker PURR, Nasdaq, full filing index | E4: Public. Confirms hypestrat.xyz is the genuine IR site.
A5: 2 | B5: 10-Q, QE 31-Mar-2026 | C5: https://www.sec.gov/Archives/edgar/data/2078856/000119312526212519/purr-20260331.htm | D5: Note 3 unit and dollar roll-forward; 31-Mar balance 18,826,355 | E5: Primary source. Highest reliability.
A6: 3 | B6: 10-Q, QE 31-Dec-2025 | C6: https://www.sec.gov/Archives/edgar/data/2078856/000119312526045901/purr-20251231.htm | D6: 31-Dec balance 12,857,533 | E6: Primary source.
A7: 4 | B7: XBRL company facts | C7: https://data.sec.gov/api/xbrl/companyfacts/CIK0002078856.json | D7: CryptoAssetNumberOfUnits, CryptoAssetFairValue, share counts | E7: Only 31-Dec-2025 units are XBRL-tagged; 31-Mar units are in the note text only.
A8: 5 | B8: 8-K 11-Feb-2026, Ex-99.1 | C8: https://www.sec.gov/Archives/edgar/data/2078856/000119312526045553/purr-ex99_1.htm | D8: 17.6m as of 3-Feb-2026; 150.6m FD shares | E8: Rounded figures.
A9: 6 | B9: 8-K 7-May-2026, Ex-99.1 | C9: https://www.sec.gov/Archives/edgar/data/2078856/000119312526212109/purr-ex99_1.htm | D9: 20.0m as of 29-Apr-2026; $216.0m deployed since inception | E9: Rounded figures.
A10: 7 | B10: S-1 22-May-2026 | C10: https://www.sec.gov/Archives/edgar/data/2078856/000119312526234992/d50758ds1.htm | D10: 20.8m as of 14-May-2026
A11: 8 | B11: S-1/A 21-Jul-2026 | C11: https://www.sec.gov/Archives/edgar/data/2078856/000119312526309340/d50758ds1a.htm | D11: 29.3m as of 15-Jul-2026; staking split 21.2m / 8.1m; $645m equity issued since 31-Mar | E11: Most recent primary disclosure.
A12: 9 | B12: HSI dashboard (live) | C12: https://hypestrat.xyz/api/dashboard-inputs | D12: Current week's inputs: 29.35m HYPE, effective 20-Aug-2026 | E12: Public JSON behind the published dashboard page.
A13: 10 | B13: HSI dashboard (archive) | C13: https://hypestrat.xyz/api/dashboard-history | D13: Eight prior weekly snapshots, 02-Jul to 19-Aug-2026 | E13: UNAUTHENTICATED admin version-history feed. Not IR-published. See README caveat 3. Retains ~8 snapshots only.
A14: 11 | B14: Hyperliquid /info API | C14: https://api.hyperliquid.xyz/info (type: validatorSummaries) | D14: HSI x Unit validator 0xd6a72f04b9868d5d6050376d5d7b729f47305cec, 23.1m total stake | E14: Contains third-party delegations - NOT a treasury proxy.
A15: 12 | B15: CoinGecko price API | C15: https://api.coingecko.com/api/v3/simple/price?ids=hyperliquid | D15: HYPE $82.88 at 09:45 UTC 27-Aug-2026 | E15: Cross-checked against Hyperliquid perp mid $83.08.
A16: 13 | B16: CoinGecko treasuries | C16: https://www.coingecko.com/en/treasuries/companies/hyperliquid-strategies-inc | D16: 17.6m HYPE, avg cost $7.36 | E16: WRONG - see Third_Party_Check.
A17: 14 | B17: DefiLlama DAT | C17: https://defillama.com/digital-asset-treasury/PURR | D17: 16.89m HYPE, avg cost $46.37 | E17: WRONG - see Third_Party_Check.
