Workbook

Sheet Assumptions
A1: Hyperliquid Master Model — Assumptions
A2: Edit yellow cells to flex the model. All Daily Master formulas reference these names.
A3: Parameter | B3: Value | C3: Format | D3: Source / Note | E3: Defined Name
A4: FEE STRUCTURE
A5: Base perp taker rate (tier 0) | B5: 0.00045 | C5: 0.0000% | D5: Source: Hyperliquid docs — tier 0 taker = 0.045% | E5: BaseTakerRate
A6: Base perp maker rate (tier 0) | B6: 0.00015 | C6: 0.0000% | D6: Source: Hyperliquid docs — tier 0 maker = 0.015% | E6: BaseMakerRate
A7: Empirical core perp blended bps (pre-HIP-3, vol-weighted) | B7: 2.897 | C7: 0.000 | D7: Derived from Dec 23 2024 - Oct 12 2025: total_perp_fees / core_volume × 10000 | E7: CoreBpsBlended
A8: Growth mode discount factor | B8: 0.1 | C8: 0.00% | D8: Source: Hyperliquid HIP-3 Growth Mode (Nov 19 2025): 90% reduction | E8: GrowthModeFactor
A10: HIP-3 DEPLOYER FEE SCALES (from Hyperliquid info API perpDexs)
A11: HIP-3 trader scale (deployerFeeScale=1, most dexes) | B11: 2 | C11: 0.0000 | D11: scaleIfHip3 = deployerFeeScale × 2 when ≥ 1 → trader pays 2x base | E11: HIP3TraderScale_Std
A12: Hyperliquid retained share on 50/50 dexes | B12: 0.5 | C12: 0.00% | D12: When deployerFeeScale ≥ 1, HL keeps 50%, deployer keeps 50% (= 1x base each) | E12: HL_Retained_50
A13: HyENA trader scale (deployerFeeScale=0.1111) | B13: 1.1111 | C13: 0.0000 | D13: HyENA-specific: 1 + 0.1111 — trader pays 1.111x base | E13: HIP3TraderScale_Hyna
A14: Hyperliquid retained share on HyENA | B14: 0.9 | C14: 0.0% | D14: On HyENA, HL gets 90%, deployer 10% | E14: HL_Retained_Hyna
A16: HLP REVENUE SHARE — pre Aug 31 2025 | B16: 0.03 | C16: 0.00% | D16: HLP gets 3% of perp+spot revenue. Source: DefiLlama adapter + empirical 3.0928% = 3/97 ratio | E16: HlpSharePre
A17: HLP REVENUE SHARE — post Aug 31 2025 | B17: 0.01 | C17: 0.00% | D17: HLP gets 1% of perp+spot revenue. Empirical 1.0101% = 1/99 ratio confirmed | E17: HlpSharePost
A18: HLP share change date | B18: 45900 | C18: yyyy-mm-dd | D18: Empirically determined transition date from DefiLlama data | E18: HlpChangeDate
A20: AF revenue share (post HLP cut) | B20: 0.99 | C20: 0.00% | D20: Source: Hyperliquid docs: 99% of (fees-builders) flows to AF | E20: AfShare
A22: KEY DATES
A23: HIP-3 LAUNCH | B23: 45943 | C23: yyyy-mm-dd | D23: HIP-3 mainnet launch | E23: Hip3LaunchDate
A24: HIP-3 Growth Mode launch | B24: 45980 | C24: yyyy-mm-dd | D24: Growth Mode feature available; per-asset opt-in over time | E24: GrowthModeDate
A25: HIP-4 LAUNCH | B25: 46144 | C25: yyyy-mm-dd | D25: HIP-4 outcome markets mainnet launch — zero fees initially | E25: Hip4LaunchDate
A26: HIP-4 fee rate (zero in testing) | B26: 0 | C26: 0.0000% | D26: Source: Hyperliquid HIP-4 docs: "Fees are currently zero for outcome markets for initial testing" | E26: Hip4Rate
A28: STAKING
A29: Staking APR formula coefficient | B29: 474 | C29: 0 | D29: Source: Hyperliquid docs. At 400M staked, APR ≈ 2.37%. Formula: APR(S) = AprCoef/sqrt(S) | E29: AprCoef

Sheet Daily Master
A1: Daily Master — formulas reference Assumptions sheet
A2: YELLOW cells = raw API data. BLUE text = formula. Every derived value is auditable.
A3: Yellow = raw DL/HP API data; Blue text = Excel formula. Builder codes = supplyside_perps − (perp_rev × hlp_pct/(1−hlp_pct)).
A4: Date | B4: Core perp volume ($) | C4: HIP-3 perp volume ($) | D4: Spot volume ($) | E4: Total perp volume ($) | F4: Total volume incl spot ($) | G4: HIP-3 vol share % | H4: DL Perps fees ($) [raw] | I4: DL Spot fees ($) [raw] | J4: DL HLP entity fees [DOUBLECOUNT - DO NOT ADD] | K4: Total fees [= H+I, do NOT add J] | L4: Modeled HL's slice from HIP-3 ($) | M4: Implied core fees [= H - L] ($) | N4: Implied core bps | O4: DL Perps revenue ($) [raw] | P4: DL Spot revenue ($) [raw] | Q4: Total revenue to AF ($) | R4: Effective HLP share % | S4: Formula HLP slice [= Q*R/(1-R)] ($) | T4: DL HLP slice (=fees_hlp) ($) | U4: HLP diff (formula − DL) ($) | V4: Builder codes (perp) [= Y - O*R/(1-R)] ($) | W4: Unit revenue (spot) [= Z - P*R/(1-R)] ($) | X4: Supplyside check [= S + V + W] ($) | Y4: DL supplyside_perps (raw) ($) | Z4: DL supplyside_spot (raw) ($) | AA4: DL Holders rev = AF buyback ($) | AB4: HYPE close ($) | AC4: HYPE VWAP proxy ($) | AD4: HYPE bought daily (#) | AE4: CHECK: K - Q - X (should=0) | AF4: CHECK: Q - AA (should=0) | AG4: HP daily total fees ($) | AH4: HP/DL revenue ratio | AI4: Total staked HYPE (#) | AJ4: Staking APR [= AprCoef/SQRT(AI)] | AK4: Daily HYPE issuance (#) [= AI*AJ/365] | AL4: Daily HYPE burned (#) [= AD] | AM4: Net daily HYPE chg (#) [= AK-AL] | AN4: HIP-3 live? | AO4: HIP-4 status | AP4: # HIP-3 assets active | AQ4: # w/ growth mode | AR4: Modeled HIP-3 deployer slice [INFO] ($)
A5: 45066 | B5: 1.4896434e+08 | C5: 0 | E5: =B5+C5 -> 1.4896434e+08 | F5: =E5+D5 -> 1.4896434e+08 | G5: =IFERROR(C5/E5,0) -> 0 | K5: =H5+I5 -> 0 | M5: =H5-L5 -> 0 | N5: =IFERROR(M5/B5*10000,0) -> 0 | Q5: =O5+P5 -> 0 | R5: =IF(A5<HlpChangeDate,HlpSharePre,HlpSharePost) -> 0.03 | S5: =Q5*R5/(1-R5) -> 0 | U5: =S5-T5 -> 0 | V5: =Y5-O5*R5/(1-R5) -> 0 | W5: =Z5-P5*R5/(1-R5) -> 0 | X5: =S5+V5+W5 -> 0 | AA5: 0 | AD5: =IFERROR(AA5/AC5,0) -> 0 | AE5: =K5-Q5-X5 -> 0 | AF5: =Q5-AA5 -> 0 | AH5: =IFERROR(AG5/Q5,0) -> 0 | AI5: 0 | AJ5: =IF(AI5>0,AprCoef/SQRT(AI5),0) -> 0 | AK5: =AI5*AJ5/365 -> 0 | AL5: =AD5 -> 0 | AM5: =AK5-AL5 -> 0 | AN5: =IF(A5>=Hip3LaunchDate,"YES","") | AO5: =IF(A5<Hip4LaunchDate,"pre-launch","live (zero-fee)") -> pre-launch
A6: 45067 | B6: 1.7817381e+08 | C6: 0 | E6: =B6+C6 -> 1.7817381e+08 | F6: =E6+D6 -> 1.7817381e+08 | G6: =IFERROR(C6/E6,0) -> 0 | K6: =H6+I6 -> 0 | M6: =H6-L6 -> 0 | N6: =IFERROR(M6/B6*10000,0) -> 0 | Q6: =O6+P6 -> 0 | R6: =IF(A6<HlpChangeDate,HlpSharePre,HlpSharePost) -> 0.03 | S6: =Q6*R6/(1-R6) -> 0 | U6: =S6-T6 -> 0 | V6: =Y6-O6*R6/(1-R6) -> 0 | W6: =Z6-P6*R6/(1-R6) -> 0 | X6: =S6+V6+W6 -> 0 | AA6: 0 | AD6: =IFERROR(AA6/AC6,0) -> 0 | AE6: =K6-Q6-X6 -> 0 | AF6: =Q6-AA6 -> 0 | AH6: =IFERROR(AG6/Q6,0) -> 0 | AI6: 0 | AJ6: =IF(AI6>0,AprCoef/SQRT(AI6),0) -> 0 | AK6: =AI6*AJ6/365 -> 0 | AL6: =AD6 -> 0 | AM6: =AK6-AL6 -> 0 | AN6: =IF(A6>=Hip3LaunchDate,"YES","") | AO6: =IF(A6<Hip4LaunchDate,"pre-launch","live (zero-fee)") -> pre-launch
A7: 45068 | B7: 2.0381289e+08 | C7: 0 | E7: =B7+C7 -> 2.0381289e+08 | F7: =E7+D7 -> 2.0381289e+08 | G7: =IFERROR(C7/E7,0) -> 0 | K7: =H7+I7 -> 0 | M7: =H7-L7 -> 0 | N7: =IFERROR(M7/B7*10000,0) -> 0 | Q7: =O7+P7 -> 0 | R7: =IF(A7<HlpChangeDate,HlpSharePre,HlpSharePost) -> 0.03 | S7: =Q7*R7/(1-R7) -> 0 | U7: =S7-T7 -> 0 | V7: =Y7-O7*R7/(1-R7) -> 0 | W7: =Z7-P7*R7/(1-R7) -> 0 | X7: =S7+V7+W7 -> 0 | AA7: 0 | AD7: =IFERROR(AA7/AC7,0) -> 0 | AE7: =K7-Q7-X7 -> 0 | AF7: =Q7-AA7 -> 0 | AH7: =IFERROR(AG7/Q7,0) -> 0 | AI7: 0 | AJ7: =IF(AI7>0,AprCoef/SQRT(AI7),0) -> 0 | AK7: =AI7*AJ7/365 -> 0 | AL7: =AD7 -> 0 | AM7: =AK7-AL7 -> 0 | AN7: =IF(A7>=Hip3LaunchDate,"YES","") | AO7: =IF(A7<Hip4LaunchDate,"pre-launch","live (zero-fee)") -> pre-launch
A8: 45069 | B8: 2.3846318e+08 | C8: 0 | E8: =B8+C8 -> 2.3846318e+08 | F8: =E8+D8 -> 2.3846318e+08 | G8: =IFERROR(C8/E8,0) -> 0 | K8: =H8+I8 -> 0 | M8: =H8-L8 -> 0 | N8: =IFERROR(M8/B8*10000,0) -> 0 | Q8: =O8+P8 -> 0 | R8: =IF(A8<HlpChangeDate,HlpSharePre,HlpSharePost) -> 0.03 | S8: =Q8*R8/(1-R8) -> 0 | U8: =S8-T8 -> 0 | V8: =Y8-O8*R8/(1-R8) -> 0 | W8: =Z8-P8*R8/(1-R8) -> 0 | X8: =S8+V8+W8 -> 0 | AA8: 0 | AD8: =IFERROR(AA8/AC8,0) -> 0 | AE8: =K8-Q8-X8 -> 0 | AF8: =Q8-AA8 -> 0 | AH8: =IFERROR(AG8/Q8,0) -> 0 | AI8: 0 | AJ8: =IF(AI8>0,AprCoef/SQRT(AI8),0) -> 0 | AK8: =AI8*AJ8/365 -> 0 | AL8: =AD8 -> 0 | AM8: =AK8-AL8 -> 0 | AN8: =IF(A8>=Hip3LaunchDate,"YES","") | AO8: =IF(A8<Hip4LaunchDate,"pre-launch","live (zero-fee)") -> pre-launch
A9: 45070 | B9: 4.6949197e+08 | C9: 0 | E9: =B9+C9 -> 4.6949197e+08 | F9: =E9+D9 -> 4.6949197e+08 | G9: =IFERROR(C9/E9,0) -> 0 | K9: =H9+I9 -> 0 | M9: =H9-L9 -> 0 | N9: =IFERROR(M9/B9*10000,0) -> 0 | Q9: =O9+P9 -> 0 | R9: =IF(A9<HlpChangeDate,HlpSharePre,HlpSharePost) -> 0.03 | S9: =Q9*R9/(1-R9) -> 0 | U9: =S9-T9 -> 0 | V9: =Y9-O9*R9/(1-R9) -> 0 | W9: =Z9-P9*R9/(1-R9) -> 0 | X9: =S9+V9+W9 -> 0 | AA9: 0 | AD9: =IFERROR(AA9/AC9,0) -> 0 | AE9: =K9-Q9-X9 -> 0 | AF9: =Q9-AA9 -> 0 | AH9: =IFERROR(AG9/Q9,0) -> 0 | AI9: 0 | AJ9: =IF(AI9>0,AprCoef/SQRT(AI9),0) -> 0 | AK9: =AI9*AJ9/365 -> 0 | AL9: =AD9 -> 0 | AM9: =AK9-AL9 -> 0 | AN9: =IF(A9>=Hip3LaunchDate,"YES","") | AO9: =IF(A9<Hip4LaunchDate,"pre-launch","live (zero-fee)") -> pre-launch
A10: 45071 | B10: 6.5181124e+08 | C10: 0 | E10: =B10+C10 -> 6.5181124e+08 | F10: =E10+D10 -> 6.5181124e+08 | G10: =IFERROR(C10/E10,0) -> 0 | K10: =H10+I10 -> 0 | M10: =H10-L10 -> 0 | N10: =IFERROR(M10/B10*10000,0) -> 0 | Q10: =O10+P10 -> 0 | R10: =IF(A10<HlpChangeDate,HlpSharePre,HlpSharePost) -> 0.03 | S10: =Q10*R10/(1-R10) -> 0 | U10: =S10-T10 -> 0 | V10: =Y10-O10*R10/(1-R10) -> 0 | W10: =Z10-P10*R10/(1-R10) -> 0 | X10: =S10+V10+W10 -> 0 | AA10: 0 | AD10: =IFERROR(AA10/AC10,0) -> 0 | AE10: =K10-Q10-X10 -> 0 | AF10: =Q10-AA10 -> 0 | AH10: =IFERROR(AG10/Q10,0) -> 0 | AI10: 0 | AJ10: =IF(AI10>0,AprCoef/SQRT(AI10),0) -> 0 | AK10: =AI10*AJ10/365 -> 0 | AL10: =AD10 -> 0 | AM10: =AK10-AL10 -> 0 | AN10: =IF(A10>=Hip3LaunchDate,"YES","") | AO10: =IF(A10<Hip4LaunchDate,"pre-launch","live (zero-fee)") -> pre-launch
A11: 45072 | B11: 6.3554324e+08 | C11: 0 | E11: =B11+C11 -> 6.3554324e+08 | F11: =E11+D11 -> 6.3554324e+08 | G11: =IFERROR(C11/E11,0) -> 0 | K11: =H11+I11 -> 0 | M11: =H11-L11 -> 0 | N11: =IFERROR(M11/B11*10000,0) -> 0 | Q11: =O11+P11 -> 0 | R11: =IF(A11<HlpChangeDate,HlpSharePre,HlpSharePost) -> 0.03 | S11: =Q11*R11/(1-R11) -> 0 | U11: =S11-T11 -> 0 | V11: =Y11-O11*R11/(1-R11) -> 0 | W11: =Z11-P11*R11/(1-R11) -> 0 | X11: =S11+V11+W11 -> 0 | AA11: 0 | AD11: =IFERROR(AA11/AC11,0) -> 0 | AE11: =K11-Q11-X11 -> 0 | AF11: =Q11-AA11 -> 0 | AH11: =IFERROR(AG11/Q11,0) -> 0 | AI11: 0 | AJ11: =IF(AI11>0,AprCoef/SQRT(AI11),0) -> 0 | AK11: =AI11*AJ11/365 -> 0 | AL11: =AD11 -> 0 | AM11: =AK11-AL11 -> 0 | AN11: =IF(A11>=Hip3LaunchDate,"YES","") | AO11: =IF(A11<Hip4LaunchDate,"pre-launch","live (zero-fee)") -> pre-launch
A12: 45073 | B12: 6.2926637e+08 | C12: 0 | E12: =B12+C12 -> 6.2926637e+08 | F12: =E12+D12 -> 6.2926637e+08 | G12: =IFERROR(C12/E12,0) -> 0 | K12: =H12+I12 -> 0 | M12: =H12-L12 -> 0 | N12: =IFERROR(M12/B12*10000,0) -> 0 | Q12: =O12+P12 -> 0 | R12: =IF(A12<HlpChangeDate,HlpSharePre,HlpSharePost) -> 0.03 | S12: =Q12*R12/(1-R12) -> 0 | U12: =S12-T12 -> 0 | V12: =Y12-O12*R12/(1-R12) -> 0 | W12: =Z12-P12*R12/(1-R12) -> 0 | X12: =S12+V12+W12 -> 0 | AA12: 0 | AD12: =IFERROR(AA12/AC12,0) -> 0 | AE12: =K12-Q12-X12 -> 0 | AF12: =Q12-AA12 -> 0 | AH12: =IFERROR(AG12/Q12,0) -> 0 | AI12: 0 | AJ12: =IF(AI12>0,AprCoef/SQRT(AI12),0) -> 0 | AK12: =AI12*AJ12/365 -> 0 | AL12: =AD12 -> 0 | AM12: =AK12-AL12 -> 0 | AN12: =IF(A12>=Hip3LaunchDate,"YES","") | AO12: =IF(A12<Hip4LaunchDate,"pre-launch","live (zero-fee)") -> pre-launch
A13: 45074 | B13: 1.0302869e+09 | C13: 0 | E13: =B13+C13 -> 1.0302869e+09 | F13: =E13+D13 -> 1.0302869e+09 | G13: =IFERROR(C13/E13,0) -> 0 | K13: =H13+I13 -> 0 | M13: =H13-L13 -> 0 | N13: =IFERROR(M13/B13*10000,0) -> 0 | Q13: =O13+P13 -> 0 | R13: =IF(A13<HlpChangeDate,HlpSharePre,HlpSharePost) -> 0.03 | S13: =Q13*R13/(1-R13) -> 0 | U13: =S13-T13 -> 0 | V13: =Y13-O13*R13/(1-R13) -> 0 | W13: =Z13-P13*R13/(1-R13) -> 0 | X13: =S13+V13+W13 -> 0 | AA13: 0 | AD13: =IFERROR(AA13/AC13,0) -> 0 | AE13: =K13-Q13-X13 -> 0 | AF13: =Q13-AA13 -> 0 | AH13: =IFERROR(AG13/Q13,0) -> 0 | AI13: 0 | AJ13: =IF(AI13>0,AprCoef/SQRT(AI13),0) -> 0 | AK13: =AI13*AJ13/365 -> 0 | AL13: =AD13 -> 0 | AM13: =AK13-AL13 -> 0 | AN13: =IF(A13>=Hip3LaunchDate,"YES","") | AO13: =IF(A13<Hip4LaunchDate,"pre-launch","live (zero-fee)") -> pre-launch
A14: 45075 | B14: 1.6653697e+09 | C14: 0 | E14: =B14+C14 -> 1.6653697e+09 | F14: =E14+D14 -> 1.6653697e+09 | G14: =IFERROR(C14/E14,0) -> 0 | K14: =H14+I14 -> 0 | M14: =H14-L14 -> 0 | N14: =IFERROR(M14/B14*10000,0) -> 0 | Q14: =O14+P14 -> 0 | R14: =IF(A14<HlpChangeDate,HlpSharePre,HlpSharePost) -> 0.03 | S14: =Q14*R14/(1-R14) -> 0 | U14: =S14-T14 -> 0 | V14: =Y14-O14*R14/(1-R14) -> 0 | W14: =Z14-P14*R14/(1-R14) -> 0 | X14: =S14+V14+W14 -> 0 | AA14: 0 | AD14: =IFERROR(AA14/AC14,0) -> 0 | AE14: =K14-Q14-X14 -> 0 | AF14: =Q14-AA14 -> 0 | AH14: =IFERROR(AG14/Q14,0) -> 0 | AI14: 0 | AJ14: =IF(AI14>0,AprCoef/SQRT(AI14),0) -> 0 | AK14: =AI14*AJ14/365 -> 0 | AL14: =AD14 -> 0 | AM14: =AK14-AL14 -> 0 | AN14: =IF(A14>=Hip3LaunchDate,"YES","") | AO14: =IF(A14<Hip4LaunchDate,"pre-launch","live (zero-fee)") -> pre-launch
A15: 45076 | B15: 7.9048504e+08 | C15: 0 | E15: =B15+C15 -> 7.9048504e+08 | F15: =E15+D15 -> 7.9048504e+08 | G15: =IFERROR(C15/E15,0) -> 0 | K15: =H15+I15 -> 0 | M15: =H15-L15 -> 0 | N15: =IFERROR(M15/B15*10000,0) -> 0 | Q15: =O15+P15 -> 0 | R15: =IF(A15<HlpChangeDate,HlpSharePre,HlpSharePost) -> 0.03 | S15: =Q15*R15/(1-R15) -> 0 | U15: =S15-T15 -> 0 | V15: =Y15-O15*R15/(1-R15) -> 0 | W15: =Z15-P15*R15/(1-R15) -> 0 | X15: =S15+V15+W15 -> 0 | AA15: 0 | AD15: =IFERROR(AA15/AC15,0) -> 0 | AE15: =K15-Q15-X15 -> 0 | AF15: =Q15-AA15 -> 0 | AH15: =IFERROR(AG15/Q15,0) -> 0 | AI15: 0 | AJ15: =IF(AI15>0,AprCoef/SQRT(AI15),0) -> 0 | AK15: =AI15*AJ15/365 -> 0 | AL15: =AD15 -> 0 | AM15: =AK15-AL15 -> 0 | AN15: =IF(A15>=Hip3LaunchDate,"YES","") | AO15: =IF(A15<Hip4LaunchDate,"pre-launch","live (zero-fee)") -> pre-launch
A16: 45077 | B16: 6.9786168e+08 | C16: 0 | E16: =B16+C16 -> 6.9786168e+08 | F16: =E16+D16 -> 6.9786168e+08 | G16: =IFERROR(C16/E16,0) -> 0 | K16: =H16+I16 -> 0 | M16: =H16-L16 -> 0 | N16: =IFERROR(M16/B16*10000,0) -> 0 | Q16: =O16+P16 -> 0 | R16: =IF(A16<HlpChangeDate,HlpSharePre,HlpSharePost) -> 0.03 | S16: =Q16*R16/(1-R16) -> 0 | U16: =S16-T16 -> 0 | V16: =Y16-O16*R16/(1-R16) -> 0 | W16: =Z16-P16*R16/(1-R16) -> 0 | X16: =S16+V16+W16 -> 0 | AA16: 0 | AD16: =IFERROR(AA16/AC16,0) -> 0 | AE16: =K16-Q16-X16 -> 0 | AF16: =Q16-AA16 -> 0 | AH16: =IFERROR(AG16/Q16,0) -> 0 | AI16: 0 | AJ16: =IF(AI16>0,AprCoef/SQRT(AI16),0) -> 0 | AK16: =AI16*AJ16/365 -> 0 | AL16: =AD16 -> 0 | AM16: =AK16-AL16 -> 0 | AN16: =IF(A16>=Hip3LaunchDate,"YES","") | AO16: =IF(A16<Hip4LaunchDate,"pre-launch","live (zero-fee)") -> pre-launch
... A492: 45553 | B492: 1.3098399e+09 | C492: 0 | E492: =B492+C492 -> 1.3098399e+09 | F492: =E492+D492 -> 1.3098399e+09 | G492: =IFERROR(C492/E492,0) -> 0 | K492: =H492+I492 -> 0 | M492: =H492-L492 -> 0 | N492: =IFERROR(M492/B492*10000,0) -> 0 | Q492: =O492+P492 -> 0 | R492: =IF(A492<HlpChangeDate,HlpSharePre,HlpSharePost) -> 0.03 | S492: =Q492*R492/(1-R492) -> 0 | U492: =S492-T492 -> 0 | V492: =Y492-O492*R492/(1-R492) -> 0 | W492: =Z492-P492*R492/(1-R492) -> 0 | X492: =S492+V492+W492 -> 0 | AA492: 0 | AD492: =IFERROR(AA492/AC492,0) -> 0 | AE492: =K492-Q492-X492 -> 0 | AF492: =Q492-AA492 -> 0 | AH492: =IFERROR(AG492/Q492,0) -> 0 | AI492: 0 | AJ492: =IF(AI492>0,AprCoef/SQRT(AI492),0) -> 0 | AK492: =AI492*AJ492/365 -> 0 | AL492: =AD492 -> 0 | AM492: =AK492-AL492 -> 0 | AN492: =IF(A492>=Hip3LaunchDate,"YES","") | AO492: =IF(A492<Hip4LaunchDate,"pre-launch","live (zero-fee)") -> pre-launch
A493: 45554 | B493: 1.7619522e+09 | C493: 0 | D493: 3260099 | E493: =B493+C493 -> 1.7619522e+09 | F493: =E493+D493 -> 1.7652123e+09 | G493: =IFERROR(C493/E493,0) -> 0 | K493: =H493+I493 -> 0 | M493: =H493-L493 -> 0 | N493: =IFERROR(M493/B493*10000,0) -> 0 | Q493: =O493+P493 -> 0 | R493: =IF(A493<HlpChangeDate,HlpSharePre,HlpSharePost) -> 0.03 | S493: =Q493*R493/(1-R493) -> 0 | U493: =S493-T493 -> 0 | V493: =Y493-O493*R493/(1-R493) -> 0 | W493: =Z493-P493*R493/(1-R493) -> 0 | X493: =S493+V493+W493 -> 0 | AA493: 0 | AD493: =IFERROR(AA493/AC493,0) -> 0 | AE493: =K493-Q493-X493 -> 0 | AF493: =Q493-AA493 -> 0 | AH493: =IFERROR(AG493/Q493,0) -> 0 | AI493: 0 | AJ493: =IF(AI493>0,AprCoef/SQRT(AI493),0) -> 0 | AK493: =AI493*AJ493/365 -> 0 | AL493: =AD493 -> 0 | AM493: =AK493-AL493 -> 0 | AN493: =IF(A493>=Hip3LaunchDate,"YES","") | AO493: =IF(A493<Hip4LaunchDate,"pre-launch","live (zero-fee)") -> pre-launch
A494: 45555 | B494: 1.1603466e+09 | C494: 0 | D494: 4801770 | E494: =B494+C494 -> 1.1603466e+09 | F494: =E494+D494 -> 1.1651484e+09 | G494: =IFERROR(C494/E494,0) -> 0 | K494: =H494+I494 -> 0 | M494: =H494-L494 -> 0 | N494: =IFERROR(M494/B494*10000,0) -> 0 | Q494: =O494+P494 -> 0 | R494: =IF(A494<HlpChangeDate,HlpSharePre,HlpSharePost) -> 0.03 | S494: =Q494*R494/(1-R494) -> 0 | U494: =S494-T494 -> 0 | V494: =Y494-O494*R494/(1-R494) -> 0 | W494: =Z494-P494*R494/(1-R494) -> 0 | X494: =S494+V494+W494 -> 0 | AA494: 0 | AD494: =IFERROR(AA494/AC494,0) -> 0 | AE494: =K494-Q494-X494 -> 0 | AF494: =Q494-AA494 -> 0 | AH494: =IFERROR(AG494/Q494,0) -> 0 | AI494: 0 | AJ494: =IF(AI494>0,AprCoef/SQRT(AI494),0) -> 0 | AK494: =AI494*AJ494/365 -> 0 | AL494: =AD494 -> 0 | AM494: =AK494-AL494 -> 0 | AN494: =IF(A494>=Hip3LaunchDate,"YES","") | AO494: =IF(A494<Hip4LaunchDate,"pre-launch","live (zero-fee)") -> pre-launch
A495: 45556 | B495: 4.5167684e+08 | C495: 0 | D495: 4983173 | E495: =B495+C495 -> 4.5167684e+08 | F495: =E495+D495 -> 4.5666001e+08 | G495: =IFERROR(C495/E495,0) -> 0 | K495: =H495+I495 -> 0 | M495: =H495-L495 -> 0 | N495: =IFERROR(M495/B495*10000,0) -> 0 | Q495: =O495+P495 -> 0 | R495: =IF(A495<HlpChangeDate,HlpSharePre,HlpSharePost) -> 0.03 | S495: =Q495*R495/(1-R495) -> 0 | U495: =S495-T495 -> 0 | V495: =Y495-O495*R495/(1-R495) -> 0 | W495: =Z495-P495*R495/(1-R495) -> 0 | X495: =S495+V495+W495 -> 0 | AA495: 0 | AD495: =IFERROR(AA495/AC495,0) -> 0 | AE495: =K495-Q495-X495 -> 0 | AF495: =Q495-AA495 -> 0 | AH495: =IFERROR(AG495/Q495,0) -> 0 | AI495: 0 | AJ495: =IF(AI495>0,AprCoef/SQRT(AI495),0) -> 0 | AK495: =AI495*AJ495/365 -> 0 | AL495: =AD495 -> 0 | AM495: =AK495-AL495 -> 0 | AN495: =IF(A495>=Hip3LaunchDate,"YES","") | AO495: =IF(A495<Hip4LaunchDate,"pre-launch","live (zero-fee)") -> pre-launch
A496: 45557 | B496: 6.6972587e+08 | C496: 0 | D496: 4441106 | E496: =B496+C496 -> 6.6972587e+08 | F496: =E496+D496 -> 6.7416697e+08 | G496: =IFERROR(C496/E496,0) -> 0 | K496: =H496+I496 -> 0 | M496: =H496-L496 -> 0 | N496: =IFERROR(M496/B496*10000,0) -> 0 | Q496: =O496+P496 -> 0 | R496: =IF(A496<HlpChangeDate,HlpSharePre,HlpSharePost) -> 0.03 | S496: =Q496*R496/(1-R496) -> 0 | U496: =S496-T496 -> 0 | V496: =Y496-O496*R496/(1-R496) -> 0 | W496: =Z496-P496*R496/(1-R496) -> 0 | X496: =S496+V496+W496 -> 0 | AA496: 0 | AD496: =IFERROR(AA496/AC496,0) -> 0 | AE496: =K496-Q496-X496 -> 0 | AF496: =Q496-AA496 -> 0 | AH496: =IFERROR(AG496/Q496,0) -> 0 | AI496: 0 | AJ496: =IF(AI496>0,AprCoef/SQRT(AI496),0) -> 0 | AK496: =AI496*AJ496/365 -> 0 | AL496: =AD496 -> 0 | AM496: =AK496-AL496 -> 0 | AN496: =IF(A496>=Hip3LaunchDate,"YES","") | AO496: =IF(A496<Hip4LaunchDate,"pre-launch","live (zero-fee)") -> pre-launch
A497: 45558 | B497: 1.4264579e+09 | C497: 0 | D497: 9787031 | E497: =B497+C497 -> 1.4264579e+09 | F497: =E497+D497 -> 1.4362449e+09 | G497: =IFERROR(C497/E497,0) -> 0 | K497: =H497+I497 -> 0 | M497: =H497-L497 -> 0 | N497: =IFERROR(M497/B497*10000,0) -> 0 | Q497: =O497+P497 -> 0 | R497: =IF(A497<HlpChangeDate,HlpSharePre,HlpSharePost) -> 0.03 | S497: =Q497*R497/(1-R497) -> 0 | U497: =S497-T497 -> 0 | V497: =Y497-O497*R497/(1-R497) -> 0 | W497: =Z497-P497*R497/(1-R497) -> 0 | X497: =S497+V497+W497 -> 0 | AA497: 0 | AD497: =IFERROR(AA497/AC497,0) -> 0 | AE497: =K497-Q497-X497 -> 0 | AF497: =Q497-AA497 -> 0 | AH497: =IFERROR(AG497/Q497,0) -> 0 | AI497: 0 | AJ497: =IF(AI497>0,AprCoef/SQRT(AI497),0) -> 0 | AK497: =AI497*AJ497/365 -> 0 | AL497: =AD497 -> 0 | AM497: =AK497-AL497 -> 0 | AN497: =IF(A497>=Hip3LaunchDate,"YES","") | AO497: =IF(A497<Hip4LaunchDate,"pre-launch","live (zero-fee)") -> pre-launch
A498: 45559 | B498: 1.2194153e+09 | C498: 0 | D498: 4003448 | E498: =B498+C498 -> 1.2194153e+09 | F498: =E498+D498 -> 1.2234187e+09 | G498: =IFERROR(C498/E498,0) -> 0 | K498: =H498+I498 -> 0 | M498: =H498-L498 -> 0 | N498: =IFERROR(M498/B498*10000,0) -> 0 | Q498: =O498+P498 -> 0 | R498: =IF(A498<HlpChangeDate,HlpSharePre,HlpSharePost) -> 0.03 | S498: =Q498*R498/(1-R498) -> 0 | U498: =S498-T498 -> 0 | V498: =Y498-O498*R498/(1-R498) -> 0 | W498: =Z498-P498*R498/(1-R498) -> 0 | X498: =S498+V498+W498 -> 0 | AA498: 0 | AD498: =IFERROR(AA498/AC498,0) -> 0 | AE498: =K498-Q498-X498 -> 0 | AF498: =Q498-AA498 -> 0 | AH498: =IFERROR(AG498/Q498,0) -> 0 | AI498: 0 | AJ498: =IF(AI498>0,AprCoef/SQRT(AI498),0) -> 0 | AK498: =AI498*AJ498/365 -> 0 | AL498: =AD498 -> 0 | AM498: =AK498-AL498 -> 0 | AN498: =IF(A498>=Hip3LaunchDate,"YES","") | AO498: =IF(A498<Hip4LaunchDate,"pre-launch","live (zero-fee)") -> pre-launch
A499: 45560 | B499: 1.206077e+09 | C499: 0 | D499: 4050062 | E499: =B499+C499 -> 1.206077e+09 | F499: =E499+D499 -> 1.2101271e+09 | G499: =IFERROR(C499/E499,0) -> 0 | K499: =H499+I499 -> 0 | M499: =H499-L499 -> 0 | N499: =IFERROR(M499/B499*10000,0) -> 0 | Q499: =O499+P499 -> 0 | R499: =IF(A499<HlpChangeDate,HlpSharePre,HlpSharePost) -> 0.03 | S499: =Q499*R499/(1-R499) -> 0 | U499: =S499-T499 -> 0 | V499: =Y499-O499*R499/(1-R499) -> 0 | W499: =Z499-P499*R499/(1-R499) -> 0 | X499: =S499+V499+W499 -> 0 | AA499: 0 | AD499: =IFERROR(AA499/AC499,0) -> 0 | AE499: =K499-Q499-X499 -> 0 | AF499: =Q499-AA499 -> 0 | AH499: =IFERROR(AG499/Q499,0) -> 0 | AI499: 0 | AJ499: =IF(AI499>0,AprCoef/SQRT(AI499),0) -> 0 | AK499: =AI499*AJ499/365 -> 0 | AL499: =AD499 -> 0 | AM499: =AK499-AL499 -> 0 | AN499: =IF(A499>=Hip3LaunchDate,"YES","") | AO499: =IF(A499<Hip4LaunchDate,"pre-launch","live (zero-fee)") -> pre-launch
A500: 45561 | B500: 1.6520725e+09 | C500: 0 | D500: 2720909 | E500: =B500+C500 -> 1.6520725e+09 | F500: =E500+D500 -> 1.6547934e+09 | G500: =IFERROR(C500/E500,0) -> 0 | K500: =H500+I500 -> 0 | M500: =H500-L500 -> 0 | N500: =IFERROR(M500/B500*10000,0) -> 0 | Q500: =O500+P500 -> 0 | R500: =IF(A500<HlpChangeDate,HlpSharePre,HlpSharePost) -> 0.03 | S500: =Q500*R500/(1-R500) -> 0 | U500: =S500-T500 -> 0 | V500: =Y500-O500*R500/(1-R500) -> 0 | W500: =Z500-P500*R500/(1-R500) -> 0 | X500: =S500+V500+W500 -> 0 | AA500: 0 | AD500: =IFERROR(AA500/AC500,0) -> 0 | AE500: =K500-Q500-X500 -> 0 | AF500: =Q500-AA500 -> 0 | AH500: =IFERROR(AG500/Q500,0) -> 0 | AI500: 0 | AJ500: =IF(AI500>0,AprCoef/SQRT(AI500),0) -> 0 | AK500: =AI500*AJ500/365 -> 0 | AL500: =AD500 -> 0 | AM500: =AK500-AL500 -> 0 | AN500: =IF(A500>=Hip3LaunchDate,"YES","") | AO500: =IF(A500<Hip4LaunchDate,"pre-launch","live (zero-fee)") -> pre-launch
A501: 45562 | B501: 1.3608713e+09 | C501: 0 | D501: 3014452 | E501: =B501+C501 -> 1.3608713e+09 | F501: =E501+D501 -> 1.3638857e+09 | G501: =IFERROR(C501/E501,0) -> 0 | K501: =H501+I501 -> 0 | M501: =H501-L501 -> 0 | N501: =IFERROR(M501/B501*10000,0) -> 0 | Q501: =O501+P501 -> 0 | R501: =IF(A501<HlpChangeDate,HlpSharePre,HlpSharePost) -> 0.03 | S501: =Q501*R501/(1-R501) -> 0 | U501: =S501-T501 -> 0 | V501: =Y501-O501*R501/(1-R501) -> 0 | W501: =Z501-P501*R501/(1-R501) -> 0 | X501: =S501+V501+W501 -> 0 | AA501: 0 | AD501: =IFERROR(AA501/AC501,0) -> 0 | AE501: =K501-Q501-X501 -> 0 | AF501: =Q501-AA501 -> 0 | AH501: =IFERROR(AG501/Q501,0) -> 0 | AI501: 0 | AJ501: =IF(AI501>0,AprCoef/SQRT(AI501),0) -> 0 | AK501: =AI501*AJ501/365 -> 0 | AL501: =AD501 -> 0 | AM501: =AK501-AL501 -> 0 | AN501: =IF(A501>=Hip3LaunchDate,"YES","") | AO501: =IF(A501<Hip4LaunchDate,"pre-launch","live (zero-fee)") -> pre-launch
A502: 45563 | B502: 6.2587922e+08 | C502: 0 | D502: 2447124 | E502: =B502+C502 -> 6.2587922e+08 | F502: =E502+D502 -> 6.2832635e+08 | G502: =IFERROR(C502/E502,0) -> 0 | K502: =H502+I502 -> 0 | M502: =H502-L502 -> 0 | N502: =IFERROR(M502/B502*10000,0) -> 0 | Q502: =O502+P502 -> 0 | R502: =IF(A502<HlpChangeDate,HlpSharePre,HlpSharePost) -> 0.03 | S502: =Q502*R502/(1-R502) -> 0 | U502: =S502-T502 -> 0 | V502: =Y502-O502*R502/(1-R502) -> 0 | W502: =Z502-P502*R502/(1-R502) -> 0 | X502: =S502+V502+W502 -> 0 | AA502: 0 | AD502: =IFERROR(AA502/AC502,0) -> 0 | AE502: =K502-Q502-X502 -> 0 | AF502: =Q502-AA502 -> 0 | AH502: =IFERROR(AG502/Q502,0) -> 0 | AI502: 0 | AJ502: =IF(AI502>0,AprCoef/SQRT(AI502),0) -> 0 | AK502: =AI502*AJ502/365 -> 0 | AL502: =AD502 -> 0 | AM502: =AK502-AL502 -> 0 | AN502: =IF(A502>=Hip3LaunchDate,"YES","") | AO502: =IF(A502<Hip4LaunchDate,"pre-launch","live (zero-fee)") -> pre-launch
A503: 45564 | B503: 5.6653266e+08 | C503: 0 | D503: 1971820 | E503: =B503+C503 -> 5.6653266e+08 | F503: =E503+D503 -> 5.6850448e+08 | G503: =IFERROR(C503/E503,0) -> 0 | K503: =H503+I503 -> 0 | M503: =H503-L503 -> 0 | N503: =IFERROR(M503/B503*10000,0) -> 0 | Q503: =O503+P503 -> 0 | R503: =IF(A503<HlpChangeDate,HlpSharePre,HlpSharePost) -> 0.03 | S503: =Q503*R503/(1-R503) -> 0 | U503: =S503-T503 -> 0 | V503: =Y503-O503*R503/(1-R503) -> 0 | W503: =Z503-P503*R503/(1-R503) -> 0 | X503: =S503+V503+W503 -> 0 | AA503: 0 | AD503: =IFERROR(AA503/AC503,0) -> 0 | AE503: =K503-Q503-X503 -> 0 | AF503: =Q503-AA503 -> 0 | AH503: =IFERROR(AG503/Q503,0) -> 0 | AI503: 0 | AJ503: =IF(AI503>0,AprCoef/SQRT(AI503),0) -> 0 | AK503: =AI503*AJ503/365 -> 0 | AL503: =AD503 -> 0 | AM503: =AK503-AL503 -> 0 | AN503: =IF(A503>=Hip3LaunchDate,"YES","") | AO503: =IF(A503<Hip4LaunchDate,"pre-launch","live (zero-fee)") -> pre-launch
A504: 45565 | B504: 1.4412132e+09 | C504: 0 | D504: 2992524 | E504: =B504+C504 -> 1.4412132e+09 | F504: =E504+D504 -> 1.4442057e+09 | G504: =IFERROR(C504/E504,0) -> 0 | K504: =H504+I504 -> 0 | M504: =H504-L504 -> 0 | N504: =IFERROR(M504/B504*10000,0) -> 0 | Q504: =O504+P504 -> 0 | R504: =IF(A504<HlpChangeDate,HlpSharePre,HlpSharePost) -> 0.03 | S504: =Q504*R504/(1-R504) -> 0 | U504: =S504-T504 -> 0 | V504: =Y504-O504*R504/(1-R504) -> 0 | W504: =Z504-P504*R504/(1-R504) -> 0 | X504: =S504+V504+W504 -> 0 | AA504: 0 | AD504: =IFERROR(AA504/AC504,0) -> 0 | AE504: =K504-Q504-X504 -> 0 | AF504: =Q504-AA504 -> 0 | AH504: =IFERROR(AG504/Q504,0) -> 0 | AI504: 0 | AJ504: =IF(AI504>0,AprCoef/SQRT(AI504),0) -> 0 | AK504: =AI504*AJ504/365 -> 0 | AL504: =AD504 -> 0 | AM504: =AK504-AL504 -> 0 | AN504: =IF(A504>=Hip3LaunchDate,"YES","") | AO504: =IF(A504<Hip4LaunchDate,"pre-launch","live (zero-fee)") -> pre-launch
... A559: 45620 | B559: 2.2105278e+09 | C559: 0 | D559: 2473310 | E559: =B559+C559 -> 2.2105278e+09 | F559: =E559+D559 -> 2.2130012e+09 | G559: =IFERROR(C559/E559,0) -> 0 | K559: =H559+I559 -> 0 | M559: =H559-L559 -> 0 | N559: =IFERROR(M559/B559*10000,0) -> 0 | Q559: =O559+P559 -> 0 | R559: =IF(A559<HlpChangeDate,HlpSharePre,HlpSharePost) -> 0.03 | S559: =Q559*R559/(1-R559) -> 0 | U559: =S559-T559 -> 0 | V559: =Y559-O559*R559/(1-R559) -> 0 | W559: =Z559-P559*R559/(1-R559) -> 0 | X559: =S559+V559+W559 -> 0 | AA559: 0 | AD559: =IFERROR(AA559/AC559,0) -> 0 | AE559: =K559-Q559-X559 -> 0 | AF559: =Q559-AA559 -> 0 | AH559: =IFERROR(AG559/Q559,0) -> 0 | AI559: 0 | AJ559: =IF(AI559>0,AprCoef/SQRT(AI559),0) -> 0 | AK559: =AI559*AJ559/365 -> 0 | AL559: =AD559 -> 0 | AM559: =AK559-AL559 -> 0 | AN559: =IF(A559>=Hip3LaunchDate,"YES","") | AO559: =IF(A559<Hip4LaunchDate,"pre-launch","live (zero-fee)") -> pre-launch
A560: 45621 | B560: 3.2691508e+09 | C560: 0 | D560: 5628946 | E560: =B560+C560 -> 3.2691508e+09 | F560: =E560+D560 -> 3.2747798e+09 | G560: =IFERROR(C560/E560,0) -> 0 | K560: =H560+I560 -> 0 | M560: =H560-L560 -> 0 | N560: =IFERROR(M560/B560*10000,0) -> 0 | Q560: =O560+P560 -> 0 | R560: =IF(A560<HlpChangeDate,HlpSharePre,HlpSharePost) -> 0.03 | S560: =Q560*R560/(1-R560) -> 0 | U560: =S560-T560 -> 0 | V560: =Y560-O560*R560/(1-R560) -> 0 | W560: =Z560-P560*R560/(1-R560) -> 0 | X560: =S560+V560+W560 -> 0 | AA560: 0 | AD560: =IFERROR(AA560/AC560,0) -> 0 | AE560: =K560-Q560-X560 -> 0 | AF560: =Q560-AA560 -> 0 | AG560: 4585090.2 | AH560: =IFERROR(AG560/Q560,0) -> 0 | AI560: 0 | AJ560: =IF(AI560>0,AprCoef/SQRT(AI560),0) -> 0 | AK560: =AI560*AJ560/365 -> 0 | AL560: =AD560 -> 0 | AM560: =AK560-AL560 -> 0 | AN560: =IF(A560>=Hip3LaunchDate,"YES","") | AO560: =IF(A560<Hip4LaunchDate,"pre-launch","live (zero-fee)") -> pre-launch
A561: 45622 | B561: 3.3938162e+09 | C561: 0 | D561: 7041832 | E561: =B561+C561 -> 3.3938162e+09 | F561: =E561+D561 -> 3.4008581e+09 | G561: =IFERROR(C561/E561,0) -> 0 | K561: =H561+I561 -> 0 | M561: =H561-L561 -> 0 | N561: =IFERROR(M561/B561*10000,0) -> 0 | Q561: =O561+P561 -> 0 | R561: =IF(A561<HlpChangeDate,HlpSharePre,HlpSharePost) -> 0.03 | S561: =Q561*R561/(1-R561) -> 0 | U561: =S561-T561 -> 0 | V561: =Y561-O561*R561/(1-R561) -> 0 | W561: =Z561-P561*R561/(1-R561) -> 0 | X561: =S561+V561+W561 -> 0 | AA561: 0 | AD561: =IFERROR(AA561/AC561,0) -> 0 | AE561: =K561-Q561-X561 -> 0 | AF561: =Q561-AA561 -> 0 | AH561: =IFERROR(AG561/Q561,0) -> 0 | AI561: 0 | AJ561: =IF(AI561>0,AprCoef/SQRT(AI561),0) -> 0 | AK561: =AI561*AJ561/365 -> 0 | AL561: =AD561 -> 0 | AM561: =AK561-AL561 -> 0 | AN561: =IF(A561>=Hip3LaunchDate,"YES","") | AO561: =IF(A561<Hip4LaunchDate,"pre-launch","live (zero-fee)") -> pre-launch
A562: 45623 | B562: 2.2108559e+09 | C562: 0 | D562: 4131241 | E562: =B562+C562 -> 2.2108559e+09 | F562: =E562+D562 -> 2.2149872e+09 | G562: =IFERROR(C562/E562,0) -> 0 | K562: =H562+I562 -> 0 | M562: =H562-L562 -> 0 | N562: =IFERROR(M562/B562*10000,0) -> 0 | Q562: =O562+P562 -> 0 | R562: =IF(A562<HlpChangeDate,HlpSharePre,HlpSharePost) -> 0.03 | S562: =Q562*R562/(1-R562) -> 0 | U562: =S562-T562 -> 0 | V562: =Y562-O562*R562/(1-R562) -> 0 | W562: =Z562-P562*R562/(1-R562) -> 0 | X562: =S562+V562+W562 -> 0 | AA562: 0 | AD562: =IFERROR(AA562/AC562,0) -> 0 | AE562: =K562-Q562-X562 -> 0 | AF562: =Q562-AA562 -> 0 | AH562: =IFERROR(AG562/Q562,0) -> 0 | AI562: 0 | AJ562: =IF(AI562>0,AprCoef/SQRT(AI562),0) -> 0 | AK562: =AI562*AJ562/365 -> 0 | AL562: =AD562 -> 0 | AM562: =AK562-AL562 -> 0 | AN562: =IF(A562>=Hip3LaunchDate,"YES","") | AO562: =IF(A562<Hip4LaunchDate,"pre-launch","live (zero-fee)") -> pre-launch
A563: 45624 | B563: 1.7653393e+09 | C563: 0 | D563: 19036485 | E563: =B563+C563 -> 1.7653393e+09 | F563: =E563+D563 -> 1.7843758e+09 | G563: =IFERROR(C563/E563,0) -> 0 | K563: =H563+I563 -> 0 | M563: =H563-L563 -> 0 | N563: =IFERROR(M563/B563*10000,0) -> 0 | Q563: =O563+P563 -> 0 | R563: =IF(A563<HlpChangeDate,HlpSharePre,HlpSharePost) -> 0.03 | S563: =Q563*R563/(1-R563) -> 0 | U563: =S563-T563 -> 0 | V563: =Y563-O563*R563/(1-R563) -> 0 | W563: =Z563-P563*R563/(1-R563) -> 0 | X563: =S563+V563+W563 -> 0 | AA563: 0 | AD563: =IFERROR(AA563/AC563,0) -> 0 | AE563: =K563-Q563-X563 -> 0 | AF563: =Q563-AA563 -> 0 | AH563: =IFERROR(AG563/Q563,0) -> 0 | AI563: 0 | AJ563: =IF(AI563>0,AprCoef/SQRT(AI563),0) -> 0 | AK563: =AI563*AJ563/365 -> 0 | AL563: =AD563 -> 0 | AM563: =AK563-AL563 -> 0 | AN563: =IF(A563>=Hip3LaunchDate,"YES","") | AO563: =IF(A563<Hip4LaunchDate,"pre-launch","live (zero-fee)") -> pre-launch
A564: 45625 | B564: 1.8146872e+09 | C564: 0 | D564: 951196324 | E564: =B564+C564 -> 1.8146872e+09 | F564: =E564+D564 -> 2.7658836e+09 | G564: =IFERROR(C564/E564,0) -> 0 | K564: =H564+I564 -> 0 | M564: =H564-L564 -> 0 | N564: =IFERROR(M564/B564*10000,0) -> 0 | Q564: =O564+P564 -> 0 | R564: =IF(A564<HlpChangeDate,HlpSharePre,HlpSharePost) -> 0.03 | S564: =Q564*R564/(1-R564) -> 0 | U564: =S564-T564 -> 0 | V564: =Y564-O564*R564/(1-R564) -> 0 | W564: =Z564-P564*R564/(1-R564) -> 0 | X564: =S564+V564+W564 -> 0 | AA564: 0 | AB564: 6.252 | AC564: 4.2155 | AD564: =IFERROR(AA564/AC564,0) -> 0 | AE564: =K564-Q564-X564 -> 0 | AF564: =Q564-AA564 -> 0 | AG564: 2497425.1 | AH564: =IFERROR(AG564/Q564,0) -> 0 | AI564: 0 | AJ564: =IF(AI564>0,AprCoef/SQRT(AI564),0) -> 0 | AK564: =AI564*AJ564/365 -> 0 | AL564: =AD564 -> 0 | AM564: =AK564-AL564 -> 0 | AN564: =IF(A564>=Hip3LaunchDate,"YES","") | AO564: =IF(A564<Hip4LaunchDate,"pre-launch","live (zero-fee)") -> pre-launch
A565: 45626 | B565: 1.9278396e+09 | C565: 0 | D565: 460835741 | E565: =B565+C565 -> 1.9278396e+09 | F565: =E565+D565 -> 2.3886754e+09 | G565: =IFERROR(C565/E565,0) -> 0 | K565: =H565+I565 -> 0 | M565: =H565-L565 -> 0 | N565: =IFERROR(M565/B565*10000,0) -> 0 | Q565: =O565+P565 -> 0 | R565: =IF(A565<HlpChangeDate,HlpSharePre,HlpSharePost) -> 0.03 | S565: =Q565*R565/(1-R565) -> 0 | U565: =S565-T565 -> 0 | V565: =Y565-O565*R565/(1-R565) -> 0 | W565: =Z565-P565*R565/(1-R565) -> 0 | X565: =S565+V565+W565 -> 0 | AA565: 0 | AB565: 8.4985 | AC565: 7.454675 | AD565: =IFERROR(AA565/AC565,0) -> 0 | AE565: =K565-Q565-X565 -> 0 | AF565: =Q565-AA565 -> 0 | AH565: =IFERROR(AG565/Q565,0) -> 0 | AI565: 0 | AJ565: =IF(AI565>0,AprCoef/SQRT(AI565),0) -> 0 | AK565: =AI565*AJ565/365 -> 0 | AL565: =AD565 -> 0 | AM565: =AK565-AL565 -> 0 | AN565: =IF(A565>=Hip3LaunchDate,"YES","") | AO565: =IF(A565<Hip4LaunchDate,"pre-launch","live (zero-fee)") -> pre-launch
A566: 45627 | B566: 2.2309523e+09 | C566: 0 | D566: 382137710 | E566: =B566+C566 -> 2.2309523e+09 | F566: =E566+D566 -> 2.61309e+09 | G566: =IFERROR(C566/E566,0) -> 0 | K566: =H566+I566 -> 0 | M566: =H566-L566 -> 0 | N566: =IFERROR(M566/B566*10000,0) -> 0 | Q566: =O566+P566 -> 0 | R566: =IF(A566<HlpChangeDate,HlpSharePre,HlpSharePost) -> 0.03 | S566: =Q566*R566/(1-R566) -> 0 | U566: =S566-T566 -> 0 | V566: =Y566-O566*R566/(1-R566) -> 0 | W566: =Z566-P566*R566/(1-R566) -> 0 | X566: =S566+V566+W566 -> 0 | AA566: 0 | AB566: 9.4686 | AC566: 8.98335 | AD566: =IFERROR(AA566/AC566,0) -> 0 | AE566: =K566-Q566-X566 -> 0 | AF566: =Q566-AA566 -> 0 | AH566: =IFERROR(AG566/Q566,0) -> 0 | AI566: 0 | AJ566: =IF(AI566>0,AprCoef/SQRT(AI566),0) -> 0 | AK566: =AI566*AJ566/365 -> 0 | AL566: =AD566 -> 0 | AM566: =AK566-AL566 -> 0 | AN566: =IF(A566>=Hip3LaunchDate,"YES","") | AO566: =IF(A566<Hip4LaunchDate,"pre-launch","live (zero-fee)") -> pre-launch
A567: 45628 | B567: 5.3331258e+09 | C567: 0 | D567: 320571512 | E567: =B567+C567 -> 5.3331258e+09 | F567: =E567+D567 -> 5.6536974e+09 | G567: =IFERROR(C567/E567,0) -> 0 | K567: =H567+I567 -> 0 | M567: =H567-L567 -> 0 | N567: =IFERROR(M567/B567*10000,0) -> 0 | Q567: =O567+P567 -> 0 | R567: =IF(A567<HlpChangeDate,HlpSharePre,HlpSharePost) -> 0.03 | S567: =Q567*R567/(1-R567) -> 0 | U567: =S567-T567 -> 0 | V567: =Y567-O567*R567/(1-R567) -> 0 | W567: =Z567-P567*R567/(1-R567) -> 0 | X567: =S567+V567+W567 -> 0 | AA567: 0 | AB567: 8.4277 | AC567: 8.68185 | AD567: =IFERROR(AA567/AC567,0) -> 0 | AE567: =K567-Q567-X567 -> 0 | AF567: =Q567-AA567 -> 0 | AG567: 2313969.7 | AH567: =IFERROR(AG567/Q567,0) -> 0 | AI567: 0 | AJ567: =IF(AI567>0,AprCoef/SQRT(AI567),0) -> 0 | AK567: =AI567*AJ567/365 -> 0 | AL567: =AD567 -> 0 | AM567: =AK567-AL567 -> 0 | AN567: =IF(A567>=Hip3LaunchDate,"YES","") | AO567: =IF(A567<Hip4LaunchDate,"pre-launch","live (zero-fee)") -> pre-launch
A568: 45629 | B568: 4.8819819e+09 | C568: 0 | D568: 302890343 | E568: =B568+C568 -> 4.8819819e+09 | F568: =E568+D568 -> 5.1848722e+09 | G568: =IFERROR(C568/E568,0) -> 0 | K568: =H568+I568 -> 0 | M568: =H568-L568 -> 0 | N568: =IFERROR(M568/B568*10000,0) -> 0 | Q568: =O568+P568 -> 0 | R568: =IF(A568<HlpChangeDate,HlpSharePre,HlpSharePost) -> 0.03 | S568: =Q568*R568/(1-R568) -> 0 | U568: =S568-T568 -> 0 | V568: =Y568-O568*R568/(1-R568) -> 0 | W568: =Z568-P568*R568/(1-R568) -> 0 | X568: =S568+V568+W568 -> 0 | AA568: 0 | AB568: 11.082 | AC568: 9.76005 | AD568: =IFERROR(AA568/AC568,0) -> 0 | AE568: =K568-Q568-X568 -> 0 | AF568: =Q568-AA568 -> 0 | AH568: =IFERROR(AG568/Q568,0) -> 0 | AI568: 0 | AJ568: =IF(AI568>0,AprCoef/SQRT(AI568),0) -> 0 | AK568: =AI568*AJ568/365 -> 0 | AL568: =AD568 -> 0 | AM568: =AK568-AL568 -> 0 | AN568: =IF(A568>=Hip3LaunchDate,"YES","") | AO568: =IF(A568<Hip4LaunchDate,"pre-launch","live (zero-fee)") -> pre-launch
A569: 45630 | B569: 6.2259185e+09 | C569: 0 | D569: 318696984 | E569: =B569+C569 -> 6.2259185e+09 | F569: =E569+D569 -> 6.5446155e+09 | G569: =IFERROR(C569/E569,0) -> 0 | K569: =H569+I569 -> 0 | M569: =H569-L569 -> 0 | N569: =IFERROR(M569/B569*10000,0) -> 0 | Q569: =O569+P569 -> 0 | R569: =IF(A569<HlpChangeDate,HlpSharePre,HlpSharePost) -> 0.03 | S569: =Q569*R569/(1-R569) -> 0 | U569: =S569-T569 -> 0 | V569: =Y569-O569*R569/(1-R569) -> 0 | W569: =Z569-P569*R569/(1-R569) -> 0 | X569: =S569+V569+W569 -> 0 | AA569: 0 | AB569: 11.403 | AC569: 11.6015 | AD569: =IFERROR(AA569/AC569,0) -> 0 | AE569: =K569-Q569-X569 -> 0 | AF569: =Q569-AA569 -> 0 | AH569: =IFERROR(AG569/Q569,0) -> 0 | AI569: 0 | AJ569: =IF(AI569>0,AprCoef/SQRT(AI569),0) -> 0 | AK569: =AI569*AJ569/365 -> 0 | AL569: =AD569 -> 0 | AM569: =AK569-AL569 -> 0 | AN569: =IF(A569>=Hip3LaunchDate,"YES","") | AO569: =IF(A569<Hip4LaunchDate,"pre-launch","live (zero-fee)") -> pre-launch
...

Sheet HIP-3 Model
A1: HIP-3 Per-Asset Fee Model — Hyperliquid's slice only (matches DL Perps)
A2: Hyperliquid's slice on any HIP-3 market = base × growthModeFactor × 1 (HL always keeps the equivalent of 1x base, regardless of deployerFeeScale).
A3: Note: This sheet shows what enters DL Hyperliquid Perps fees from HIP-3. The deployer's slice is tracked SEPARATELY in DL (e.g. tradeXYZ, Felix, etc.) and is NOT in Hyperliquid totals.
A5: Asset | B5: Dex | C5: deployerFeeScale | D5: scaleIfHip3 | E5: HL retained share | F5: Deployer share | G5: growthMode | H5: gmChangeDate | I5: HL slice bps (GM on) | J5: HL slice bps (GM off) | K5: Deployer slice bps (GM on, info)
A6: abcd:USA500 | B6: abcd | C6: 1 | D6: 2 | E6: 0.5 | F6: 0.5 | G6: N/A | I6: =CoreBpsBlended*GrowthModeFactor*D6*E6 -> 0.2897 | J6: =CoreBpsBlended*D6*E6 -> 2.897 | K6: =CoreBpsBlended*GrowthModeFactor*D6*F6 -> 0.2897
A7: cash:AMZN | B7: cash | C7: 1 | D7: 2 | E7: 0.5 | F7: 0.5 | G7: enabled | H7: 46049 | I7: =CoreBpsBlended*GrowthModeFactor*D7*E7 -> 0.2897 | J7: =CoreBpsBlended*D7*E7 -> 2.897 | K7: =CoreBpsBlended*GrowthModeFactor*D7*F7 -> 0.2897
A8: cash:BTC | B8: cash | C8: 1 | D8: 2 | E8: 0.5 | F8: 0.5 | G8: N/A | I8: =CoreBpsBlended*GrowthModeFactor*D8*E8 -> 0.2897 | J8: =CoreBpsBlended*D8*E8 -> 2.897 | K8: =CoreBpsBlended*GrowthModeFactor*D8*F8 -> 0.2897
A9: cash:CAR | B9: cash | C9: 1 | D9: 2 | E9: 0.5 | F9: 0.5 | G9: enabled | H9: 46141 | I9: =CoreBpsBlended*GrowthModeFactor*D9*E9 -> 0.2897 | J9: =CoreBpsBlended*D9*E9 -> 2.897 | K9: =CoreBpsBlended*GrowthModeFactor*D9*F9 -> 0.2897
A10: cash:ETH | B10: cash | C10: 1 | D10: 2 | E10: 0.5 | F10: 0.5 | G10: N/A | I10: =CoreBpsBlended*GrowthModeFactor*D10*E10 -> 0.2897 | J10: =CoreBpsBlended*D10*E10 -> 2.897 | K10: =CoreBpsBlended*GrowthModeFactor*D10*F10 -> 0.2897
A11: cash:EWY | B11: cash | C11: 1 | D11: 2 | E11: 0.5 | F11: 0.5 | G11: enabled | H11: 46079 | I11: =CoreBpsBlended*GrowthModeFactor*D11*E11 -> 0.2897 | J11: =CoreBpsBlended*D11*E11 -> 2.897 | K11: =CoreBpsBlended*GrowthModeFactor*D11*F11 -> 0.2897
A12: cash:GOLD | B12: cash | C12: 1 | D12: 2 | E12: 0.5 | F12: 0.5 | G12: N/A | I12: =CoreBpsBlended*GrowthModeFactor*D12*E12 -> 0.2897 | J12: =CoreBpsBlended*D12*E12 -> 2.897 | K12: =CoreBpsBlended*GrowthModeFactor*D12*F12 -> 0.2897
A13: cash:GOOGL | B13: cash | C13: 1 | D13: 2 | E13: 0.5 | F13: 0.5 | G13: enabled | H13: 46049 | I13: =CoreBpsBlended*GrowthModeFactor*D13*E13 -> 0.2897 | J13: =CoreBpsBlended*D13*E13 -> 2.897 | K13: =CoreBpsBlended*GrowthModeFactor*D13*F13 -> 0.2897
A14: cash:HOOD | B14: cash | C14: 1 | D14: 2 | E14: 0.5 | F14: 0.5 | G14: enabled | H14: 46049 | I14: =CoreBpsBlended*GrowthModeFactor*D14*E14 -> 0.2897 | J14: =CoreBpsBlended*D14*E14 -> 2.897 | K14: =CoreBpsBlended*GrowthModeFactor*D14*F14 -> 0.2897
A15: cash:INTC | B15: cash | C15: 1 | D15: 2 | E15: 0.5 | F15: 0.5 | G15: enabled | H15: 46049 | I15: =CoreBpsBlended*GrowthModeFactor*D15*E15 -> 0.2897 | J15: =CoreBpsBlended*D15*E15 -> 2.897 | K15: =CoreBpsBlended*GrowthModeFactor*D15*F15 -> 0.2897
A16: cash:KWEB | B16: cash | C16: 1 | D16: 2 | E16: 0.5 | F16: 0.5 | G16: enabled | H16: 46099 | I16: =CoreBpsBlended*GrowthModeFactor*D16*E16 -> 0.2897 | J16: =CoreBpsBlended*D16*E16 -> 2.897 | K16: =CoreBpsBlended*GrowthModeFactor*D16*F16 -> 0.2897
A17: cash:META | B17: cash | C17: 1 | D17: 2 | E17: 0.5 | F17: 0.5 | G17: enabled | H17: 46049 | I17: =CoreBpsBlended*GrowthModeFactor*D17*E17 -> 0.2897 | J17: =CoreBpsBlended*D17*E17 -> 2.897 | K17: =CoreBpsBlended*GrowthModeFactor*D17*F17 -> 0.2897
A18: cash:MSFT | B18: cash | C18: 1 | D18: 2 | E18: 0.5 | F18: 0.5 | G18: enabled | H18: 46049 | I18: =CoreBpsBlended*GrowthModeFactor*D18*E18 -> 0.2897 | J18: =CoreBpsBlended*D18*E18 -> 2.897 | K18: =CoreBpsBlended*GrowthModeFactor*D18*F18 -> 0.2897
A19: cash:NVDA | B19: cash | C19: 1 | D19: 2 | E19: 0.5 | F19: 0.5 | G19: enabled | H19: 46045 | I19: =CoreBpsBlended*GrowthModeFactor*D19*E19 -> 0.2897 | J19: =CoreBpsBlended*D19*E19 -> 2.897 | K19: =CoreBpsBlended*GrowthModeFactor*D19*F19 -> 0.2897
A20: cash:SILVER | B20: cash | C20: 1 | D20: 2 | E20: 0.5 | F20: 0.5 | G20: enabled | H20: 46059 | I20: =CoreBpsBlended*GrowthModeFactor*D20*E20 -> 0.2897 | J20: =CoreBpsBlended*D20*E20 -> 2.897 | K20: =CoreBpsBlended*GrowthModeFactor*D20*F20 -> 0.2897
A21: cash:TSLA | B21: cash | C21: 1 | D21: 2 | E21: 0.5 | F21: 0.5 | G21: enabled | H21: 46044 | I21: =CoreBpsBlended*GrowthModeFactor*D21*E21 -> 0.2897 | J21: =CoreBpsBlended*D21*E21 -> 2.897 | K21: =CoreBpsBlended*GrowthModeFactor*D21*F21 -> 0.2897
A22: cash:USA500 | B22: cash | C22: 1 | D22: 2 | E22: 0.5 | F22: 0.5 | G22: enabled | H22: 46042 | I22: =CoreBpsBlended*GrowthModeFactor*D22*E22 -> 0.2897 | J22: =CoreBpsBlended*D22*E22 -> 2.897 | K22: =CoreBpsBlended*GrowthModeFactor*D22*F22 -> 0.2897
A23: cash:WTI | B23: cash | C23: 1 | D23: 2 | E23: 0.5 | F23: 0.5 | G23: enabled | H23: 46092 | I23: =CoreBpsBlended*GrowthModeFactor*D23*E23 -> 0.2897 | J23: =CoreBpsBlended*D23*E23 -> 2.897 | K23: =CoreBpsBlended*GrowthModeFactor*D23*F23 -> 0.2897
A24: flx:BTC | B24: flx | C24: 1 | D24: 2 | E24: 0.5 | F24: 0.5 | G24: N/A | I24: =CoreBpsBlended*GrowthModeFactor*D24*E24 -> 0.2897 | J24: =CoreBpsBlended*D24*E24 -> 2.897 | K24: =CoreBpsBlended*GrowthModeFactor*D24*F24 -> 0.2897
A25: flx:COIN | B25: flx | C25: 1 | D25: 2 | E25: 0.5 | F25: 0.5 | G25: enabled | H25: 45985 | I25: =CoreBpsBlended*GrowthModeFactor*D25*E25 -> 0.2897 | J25: =CoreBpsBlended*D25*E25 -> 2.897 | K25: =CoreBpsBlended*GrowthModeFactor*D25*F25 -> 0.2897
A26: flx:COPPER | B26: flx | C26: 1 | D26: 2 | E26: 0.5 | F26: 0.5 | G26: enabled | H26: 46051 | I26: =CoreBpsBlended*GrowthModeFactor*D26*E26 -> 0.2897 | J26: =CoreBpsBlended*D26*E26 -> 2.897 | K26: =CoreBpsBlended*GrowthModeFactor*D26*F26 -> 0.2897
A27: flx:CRCL | B27: flx | C27: 1 | D27: 2 | E27: 0.5 | F27: 0.5 | G27: enabled | H27: 45985 | I27: =CoreBpsBlended*GrowthModeFactor*D27*E27 -> 0.2897 | J27: =CoreBpsBlended*D27*E27 -> 2.897 | K27: =CoreBpsBlended*GrowthModeFactor*D27*F27 -> 0.2897
A28: flx:GAS | B28: flx | C28: 1 | D28: 2 | E28: 0.5 | F28: 0.5 | G28: enabled | H28: 46112 | I28: =CoreBpsBlended*GrowthModeFactor*D28*E28 -> 0.2897 | J28: =CoreBpsBlended*D28*E28 -> 2.897 | K28: =CoreBpsBlended*GrowthModeFactor*D28*F28 -> 0.2897
A29: flx:GOLD | B29: flx | C29: 1 | D29: 2 | E29: 0.5 | F29: 0.5 | G29: N/A | I29: =CoreBpsBlended*GrowthModeFactor*D29*E29 -> 0.2897 | J29: =CoreBpsBlended*D29*E29 -> 2.897 | K29: =CoreBpsBlended*GrowthModeFactor*D29*F29 -> 0.2897
A30: flx:NVDA | B30: flx | C30: 1 | D30: 2 | E30: 0.5 | F30: 0.5 | G30: enabled | H30: 46089 | I30: =CoreBpsBlended*GrowthModeFactor*D30*E30 -> 0.2897 | J30: =CoreBpsBlended*D30*E30 -> 2.897 | K30: =CoreBpsBlended*GrowthModeFactor*D30*F30 -> 0.2897
A31: flx:OIL | B31: flx | C31: 1 | D31: 2 | E31: 0.5 | F31: 0.5 | G31: enabled | H31: 46051 | I31: =CoreBpsBlended*GrowthModeFactor*D31*E31 -> 0.2897 | J31: =CoreBpsBlended*D31*E31 -> 2.897 | K31: =CoreBpsBlended*GrowthModeFactor*D31*F31 -> 0.2897
A32: flx:PALLADIUM | B32: flx | C32: 1 | D32: 2 | E32: 0.5 | F32: 0.5 | G32: enabled | H32: 46051 | I32: =CoreBpsBlended*GrowthModeFactor*D32*E32 -> 0.2897 | J32: =CoreBpsBlended*D32*E32 -> 2.897 | K32: =CoreBpsBlended*GrowthModeFactor*D32*F32 -> 0.2897
A33: flx:PLATINUM | B33: flx | C33: 1 | D33: 2 | E33: 0.5 | F33: 0.5 | G33: enabled | H33: 46051 | I33: =CoreBpsBlended*GrowthModeFactor*D33*E33 -> 0.2897 | J33: =CoreBpsBlended*D33*E33 -> 2.897 | K33: =CoreBpsBlended*GrowthModeFactor*D33*F33 -> 0.2897
A34: flx:SILVER | B34: flx | C34: 1 | D34: 2 | E34: 0.5 | F34: 0.5 | G34: enabled | H34: 46051 | I34: =CoreBpsBlended*GrowthModeFactor*D34*E34 -> 0.2897 | J34: =CoreBpsBlended*D34*E34 -> 2.897 | K34: =CoreBpsBlended*GrowthModeFactor*D34*F34 -> 0.2897
A35: flx:TSLA | B35: flx | C35: 1 | D35: 2 | E35: 0.5 | F35: 0.5 | G35: enabled | H35: 45985 | I35: =CoreBpsBlended*GrowthModeFactor*D35*E35 -> 0.2897 | J35: =CoreBpsBlended*D35*E35 -> 2.897 | K35: =CoreBpsBlended*GrowthModeFactor*D35*F35 -> 0.2897
A36: flx:USA100 | B36: flx | C36: 1 | D36: 2 | E36: 0.5 | F36: 0.5 | G36: enabled | H36: 46111 | I36: =CoreBpsBlended*GrowthModeFactor*D36*E36 -> 0.2897 | J36: =CoreBpsBlended*D36*E36 -> 2.897 | K36: =CoreBpsBlended*GrowthModeFactor*D36*F36 -> 0.2897
A37: flx:USA500 | B37: flx | C37: 1 | D37: 2 | E37: 0.5 | F37: 0.5 | G37: enabled | H37: 46091 | I37: =CoreBpsBlended*GrowthModeFactor*D37*E37 -> 0.2897 | J37: =CoreBpsBlended*D37*E37 -> 2.897 | K37: =CoreBpsBlended*GrowthModeFactor*D37*F37 -> 0.2897
A38: flx:USDE | B38: flx | C38: 1 | D38: 2 | E38: 0.5 | F38: 0.5 | G38: N/A | I38: =CoreBpsBlended*GrowthModeFactor*D38*E38 -> 0.2897 | J38: =CoreBpsBlended*D38*E38 -> 2.897 | K38: =CoreBpsBlended*GrowthModeFactor*D38*F38 -> 0.2897
A39: flx:XMR | B39: flx | C39: 1 | D39: 2 | E39: 0.5 | F39: 0.5 | G39: N/A | I39: =CoreBpsBlended*GrowthModeFactor*D39*E39 -> 0.2897 | J39: =CoreBpsBlended*D39*E39 -> 2.897 | K39: =CoreBpsBlended*GrowthModeFactor*D39*F39 -> 0.2897
A40: hyna:1000PEPE | B40: hyna | C40: 0.1111 | D40: 1.1111 | E40: 0.900009 | F40: 0.099991 | G40: N/A | I40: =CoreBpsBlended*GrowthModeFactor*D40*E40 -> 0.2897 | J40: =CoreBpsBlended*D40*E40 -> 2.897 | K40: =CoreBpsBlended*GrowthModeFactor*D40*F40 -> 0.03218567
A41: hyna:ADA | B41: hyna | C41: 0.1111 | D41: 1.1111 | E41: 0.900009 | F41: 0.099991 | G41: N/A | I41: =CoreBpsBlended*GrowthModeFactor*D41*E41 -> 0.2897 | J41: =CoreBpsBlended*D41*E41 -> 2.897 | K41: =CoreBpsBlended*GrowthModeFactor*D41*F41 -> 0.03218567
...

Sheet HIP-3 by Category
A1: HIP-3 Daily — Volume & Modeled HL Slice by Asset Category
A2: Volume from Hyperliquid info API candleSnapshot per asset; HL slice modeled per growth-mode-aware formula.
A4: VOLUME BY CATEGORY ($)
A5: Date | B5: Agriculture | C5: Bonds | D5: Crypto | E5: Energy | F5: Equities — Crypto-related | G5: Equities — Single Name | H5: Equity Indices/ETF | I5: FX | J5: Industrial Metals | K5: Pre-IPO / Private | L5: Precious Metals | M5: Total HIP-3
A6: 45943 | B6: 0 | C6: 0 | D6: 0 | E6: 0 | F6: 0 | G6: 0 | H6: 24137313 | I6: 0 | J6: 0 | K6: 0 | L6: 0 | M6: =SUM(B6:L6) -> 24137313
A7: 45944 | B7: 0 | C7: 0 | D7: 0 | E7: 0 | F7: 0 | G7: 0 | H7: 21893628 | I7: 0 | J7: 0 | K7: 0 | L7: 0 | M7: =SUM(B7:L7) -> 21893628
A8: 45945 | B8: 0 | C8: 0 | D8: 0 | E8: 0 | F8: 0 | G8: 0 | H8: 20602638 | I8: 0 | J8: 0 | K8: 0 | L8: 0 | M8: =SUM(B8:L8) -> 20602638
A9: 45946 | B9: 0 | C9: 0 | D9: 0 | E9: 0 | F9: 0 | G9: 0 | H9: 19139744 | I9: 0 | J9: 0 | K9: 0 | L9: 0 | M9: =SUM(B9:L9) -> 19139744
A10: 45947 | B10: 0 | C10: 0 | D10: 0 | E10: 0 | F10: 0 | G10: 0 | H10: 15100795 | I10: 0 | J10: 0 | K10: 0 | L10: 0 | M10: =SUM(B10:L10) -> 15100795
A11: 45948 | B11: 0 | C11: 0 | D11: 0 | E11: 0 | F11: 0 | G11: 0 | H11: 6243638.8 | I11: 0 | J11: 0 | K11: 0 | L11: 0 | M11: =SUM(B11:L11) -> 6243638.8
A12: 45949 | B12: 0 | C12: 0 | D12: 0 | E12: 0 | F12: 0 | G12: 0 | H12: 7838676.4 | I12: 0 | J12: 0 | K12: 0 | L12: 0 | M12: =SUM(B12:L12) -> 7838676.4
A13: 45950 | B13: 0 | C13: 0 | D13: 0 | E13: 0 | F13: 0 | G13: 0 | H13: 10597513 | I13: 0 | J13: 0 | K13: 0 | L13: 0 | M13: =SUM(B13:L13) -> 10597513
A14: 45951 | B14: 0 | C14: 0 | D14: 0 | E14: 0 | F14: 0 | G14: 0 | H14: 23304373 | I14: 0 | J14: 0 | K14: 0 | L14: 0 | M14: =SUM(B14:L14) -> 23304373
A15: 45952 | B15: 0 | C15: 0 | D15: 0 | E15: 0 | F15: 0 | G15: 0 | H15: 36702797 | I15: 0 | J15: 0 | K15: 0 | L15: 0 | M15: =SUM(B15:L15) -> 36702797
A16: 45953 | B16: 0 | C16: 0 | D16: 0 | E16: 0 | F16: 0 | G16: 0 | H16: 30181937 | I16: 0 | J16: 0 | K16: 0 | L16: 0 | M16: =SUM(B16:L16) -> 30181937
A17: 45954 | B17: 0 | C17: 0 | D17: 0 | E17: 0 | F17: 0 | G17: 0 | H17: 27291720 | I17: 0 | J17: 0 | K17: 0 | L17: 0 | M17: =SUM(B17:L17) -> 27291720
... A225: 46162 | B225: 87327.911 | C225: 9993.4427 | D225: 2115097.8 | E225: 39845360 | F225: 2922661.3 | G225: 46698955 | H225: 99407571 | I225: 414539.84 | J225: 608633.1 | K225: 896499.64 | L225: 52653089 | M225: =SUM(B225:L225) -> 2.4565973e+08
A228: MODELED HL SLICE BY CATEGORY ($)
A229: Date | B229: Agriculture | C229: Bonds | D229: Crypto | E229: Energy | F229: Equities — Crypto-related | G229: Equities — Single Name | H229: Equity Indices/ETF | I229: FX | J229: Industrial Metals | K229: Pre-IPO / Private | L229: Precious Metals | M229: Total HL HIP-3 Slice
A230: 45943 | B230: 0 | C230: 0 | D230: 0 | E230: 0 | F230: 0 | G230: 0 | H230: 6992.5795 | I230: 0 | J230: 0 | K230: 0 | L230: 0 | M230: =SUM(B230:L230) -> 6992.5795
A231: 45944 | B231: 0 | C231: 0 | D231: 0 | E231: 0 | F231: 0 | G231: 0 | H231: 6342.584 | I231: 0 | J231: 0 | K231: 0 | L231: 0 | M231: =SUM(B231:L231) -> 6342.584
A232: 45945 | B232: 0 | C232: 0 | D232: 0 | E232: 0 | F232: 0 | G232: 0 | H232: 5968.5843 | I232: 0 | J232: 0 | K232: 0 | L232: 0 | M232: =SUM(B232:L232) -> 5968.5843
A233: 45946 | B233: 0 | C233: 0 | D233: 0 | E233: 0 | F233: 0 | G233: 0 | H233: 5544.7837 | I233: 0 | J233: 0 | K233: 0 | L233: 0 | M233: =SUM(B233:L233) -> 5544.7837
A234: 45947 | B234: 0 | C234: 0 | D234: 0 | E234: 0 | F234: 0 | G234: 0 | H234: 4374.7005 | I234: 0 | J234: 0 | K234: 0 | L234: 0 | M234: =SUM(B234:L234) -> 4374.7005
A235: 45948 | B235: 0 | C235: 0 | D235: 0 | E235: 0 | F235: 0 | G235: 0 | H235: 1808.7822 | I235: 0 | J235: 0 | K235: 0 | L235: 0 | M235: =SUM(B235:L235) -> 1808.7822
A236: 45949 | B236: 0 | C236: 0 | D236: 0 | E236: 0 | F236: 0 | G236: 0 | H236: 2270.8645 | I236: 0 | J236: 0 | K236: 0 | L236: 0 | M236: =SUM(B236:L236) -> 2270.8645
A237: 45950 | B237: 0 | C237: 0 | D237: 0 | E237: 0 | F237: 0 | G237: 0 | H237: 3070.0995 | I237: 0 | J237: 0 | K237: 0 | L237: 0 | M237: =SUM(B237:L237) -> 3070.0995
A238: 45951 | B238: 0 | C238: 0 | D238: 0 | E238: 0 | F238: 0 | G238: 0 | H238: 6751.2769 | I238: 0 | J238: 0 | K238: 0 | L238: 0 | M238: =SUM(B238:L238) -> 6751.2769
A239: 45952 | B239: 0 | C239: 0 | D239: 0 | E239: 0 | F239: 0 | G239: 0 | H239: 10632.8 | I239: 0 | J239: 0 | K239: 0 | L239: 0 | M239: =SUM(B239:L239) -> 10632.8
A240: 45953 | B240: 0 | C240: 0 | D240: 0 | E240: 0 | F240: 0 | G240: 0 | H240: 8743.7071 | I240: 0 | J240: 0 | K240: 0 | L240: 0 | M240: =SUM(B240:L240) -> 8743.7071
A241: 45954 | B241: 0 | C241: 0 | D241: 0 | E241: 0 | F241: 0 | G241: 0 | H241: 7906.4112 | I241: 0 | J241: 0 | K241: 0 | L241: 0 | M241: =SUM(B241:L241) -> 7906.4112
... A449: 46162 | B449: 2.5298896 | C449: 0.28951003 | D449: 336.80203 | E449: 1154.3201 | F449: 195.09318 | G449: 1352.8687 | H449: 2879.8373 | I449: 12.009219 | J449: 17.632101 | K449: 64.08414 | L449: 4368.8672 | M449: =SUM(B449:L449) -> 10384.333

Sheet Reconciliation
A1: Reconciliation & Cross-Source Checks (formula-driven)
A4: --- DEFILLAMA COVERAGE ---
A5: First date with DefiLlama fees | B5: ='Daily Master'!A588 -> 45649
A6: Last date with DefiLlama fees | B6: ='Daily Master'!A1100 -> 46161
A7: Number of days | B7: =1100-588+1 -> 513
A9: --- PERPS IDENTITY: Perp fees = Perp rev + Perp supplyside ---
A10: Cum perp fees ($) | B10: =SUM('Daily Master'!H588:H1100) -> 1204675054
A11: Cum perp revenue ($) | B11: =SUM('Daily Master'!O588:O1100) -> 1117945937
A12: Cum perp supplyside ($) | B12: =SUM('Daily Master'!Y588:Y1100) -> 86729113
A13: Diff (fees − rev − supply) | B13: =SUM('Daily Master'!H588:H1100)-SUM('Daily Master'!O588:O1100)-SUM('Daily Master'!Y588:Y1100) -> 4
A15: --- SPOT IDENTITY: Spot fees = Spot rev + Spot supplyside ---
A16: Cum spot fees ($) | B16: =SUM('Daily Master'!I588:I1100) -> 56270819
A17: Cum spot revenue ($) | B17: =SUM('Daily Master'!P588:P1100) -> 43695138
A18: Cum spot supplyside ($) | B18: =SUM('Daily Master'!Z588:Z1100) -> 12575680
A19: Diff (fees − rev − supply) | B19: =SUM('Daily Master'!I588:I1100)-SUM('Daily Master'!P588:P1100)-SUM('Daily Master'!Z588:Z1100) -> 1
A21: --- CORE IDENTITY: Total fees = Revenue + Supplyside ---
A22: Sum of daily identity diffs | B22: =SUM('Daily Master'!AE588:AE1100) -> 5
A23: -> Should be ≈ 0 (integer rounding only)
A25: --- AF BUYBACK = HOLDERS REVENUE ---
A26: Sum of (revenue − buyback) diffs | B26: =SUM('Daily Master'!AF588:AF1100) -> 0
A27: -> Should be 0 (same DL metric)
A29: --- HLP FORMULA vs DL ---
A30: Cum formula HLP slice ($) | B30: =SUM('Daily Master'!S588:S1100) -> 22746844
A31: Cum DL reported HLP slice ($) | B31: =SUM('Daily Master'!T588:T1100) -> 22189875
A32: Diff ($) | B32: =SUM('Daily Master'!S588:S1100)-SUM('Daily Master'!T588:T1100) -> 556968.68
A33: -> Small diff explained by gaps in DL HLP coverage on early dates
A35: --- SUPPLYSIDE BREAKDOWN ---
A36: Cum DL total supplyside ($) | B36: =SUM('Daily Master'!Y588:Y1100)+SUM('Daily Master'!Z588:Z1100) -> 99304793
A37: Cum HLP depositors slice | B37: =SUM('Daily Master'!T588:T1100) -> 22189875
A38: Cum Builder Code Distribution (perp) [FROM FORMULA] | B38: =SUM('Daily Master'!V588:V1100) -> 64744542
A39: Cum Unit Revenue (spot) [FROM FORMULA] | B39: =SUM('Daily Master'!W588:W1100) -> 11813407
A40: Check sum: HLP + Builders + Unit | B40: =SUM('Daily Master'!T588:T1100)+SUM('Daily Master'!V588:V1100)+SUM('Daily Master'!W588:W1100) -> 98747824
A41: Diff to total supplyside (should ≈ 0) | B41: =(SUM('Daily Master'!Y588:Y1100)+SUM('Daily Master'!Z588:Z1100))-(SUM('Daily Master'!T588:T1100)+SUM('Daily Master'!V588:V1100)+SUM('Daily Master'!W588:W1100)) -> 556968.68
A43: --- BUILDER CODES CROSS-CHECK ---
A44: Cum builder codes (derived from DL) | B44: =SUM('Daily Master'!V588:V1100) -> 64744542
A45: Cross-ref: Dwellir blog (Jan 2026) reported $40M+ since launch
A46: Cross-ref: Hyperdash (Jan 2026): "top builders incl Based/Phantom/PVP earned $31M+"
A47: Builder codes as % of perp fees | B47: =SUM('Daily Master'!V588:V1100)/SUM('Daily Master'!H588:H1100) -> 0.053744403
A49: --- HYPURRSCAN CROSS-CHECK ---
A50: Cum DL revenue | B50: =SUM('Daily Master'!Q588:Q1100) -> 1161641075
...

Sheet Sources & Methodology
A1: Sources & Methodology — v3 (CORRECTED)
A3: CORRECTIONS FROM v2
A4: 1. DL Hyperliquid Perps fees does NOT include the HIP-3 deployer's 50% slice. Only Hyperliquid's 1x retained slice is in there. The deployer's slice is tracked SEPARATELY in DefiLlama as individual protocols (tradeXYZ, Felix, Ventuals, HyENA, etc.).
A5: 2. The Perps supplyside line breaks down into: HLP slice + Builder Code Distribution (NOT HIP-3 deployer fees).
A6: 3. The Spot supplyside line breaks down into: HLP slice + Unit Protocol Revenue.
A7: 4. Builder codes (third-party frontend kickbacks like Phantom, Hyperdash, PVP.trade) are now broken out as a dedicated column.
A9: PRIMARY SOURCES
A10: 21Shares Dune query 6874521 (existing user file) | B10: Daily core + HIP-3 perp volume; cross-checked vs Hyperliquid info API (matches within 0.03%)
A11: DefiLlama Fees API | B11: https://api.llama.fi/summary/fees/hyperliquid?dataType={dailyFees|dailyRevenue|dailyHoldersRevenue|dailySupplySideRevenue}
A12: DefiLlama DEX volume | B12: https://api.llama.fi/summary/dexs/hyperliquid?dataType=dailyVolume — spot orderbook volume
A13: Hyperliquid Info API — perpDexs | B13: POST /info {"type":"perpDexs"} — HIP-3 dex list with deployerFeeScale
A14: Hyperliquid Info API — meta per dex | B14: POST /info {"type":"meta","dex":"<name>"} — per-asset growthMode + lastGrowthModeChangeTime
A15: Hyperliquid Info API — candleSnapshot | B15: Per-asset daily candles for HIP-3; HYPE/USDC spot price
A16: Hypurrscan API | B16: https://api.hypurrscan.io/fees — independent on-chain cumulative fees for cross-check
A17: Hyperliquid Fees doc | B17: https://hyperliquid.gitbook.io/hyperliquid-docs/trading/fees
A18: Hyperliquid Builder Codes doc | B18: https://hyperliquid.gitbook.io/hyperliquid-docs/trading/builder-codes
A19: Hyperliquid HIP-3 doc | B19: https://hyperliquid.gitbook.io/hyperliquid-docs/hyperliquid-improvement-proposals-hips/hip-3
A20: Hyperliquid HIP-4 doc | B20: https://hyperliquid.gitbook.io/hyperliquid-docs/hyperliquid-improvement-proposals-hips/hip-4-outcome-markets
A21: DefiLlama adapter source | B21: https://github.com/DefiLlama/dimension-adapters/blob/master/fees/hyperliquid-hlp.ts — flagged `doublecounted: true`
A23: CORRECTED FEE FLOW
A24: FOR CORE PERP MARKETS:
A25: trader_fee = base_taker_rate (tier-adjusted, often discounted by staking/referrals)
A26: Of that fee: builder_code (0-10 bps cap) → frontend if user opted in
A27: remainder × hlp_pct → HLP depositors (1% post Aug 31 2025, 3% before)
A28: remainder × (1 − hlp_pct) → AF (~99% to HYPE buybacks)
A30: FOR HIP-3 PERP MARKETS:
A31: trader_fee = base × scaleIfHip3 × growthModeFactor (0.1× if GM enabled)
A32: scaleIfHip3 = 2.0 for deployers with deployerFeeScale=1 (trade.xyz, Felix, Ventuals, Kinetiq, dreamcash, Paragon)
A33: = 1.111 for HyENA (deployerFeeScale=0.1111)
A34: Of that fee:
A35: Deployer (trade.xyz etc.) keeps: 50% (or 10% for HyENA)
... A106: 5. Hypurrscan vs DefiLlama daily fees agree to ~92% on median (snapshot-timing noise, not methodology disagreement).
