Workbook

Sheet Inputs
A1: HYPE per 1000 shares — inputs and derived flows (v2)
A2: AMBER = input. Overwrite columns D, E, F and (optionally) G. Do not link to the model — paste values.
A3: Placeholder series is constructed at mNAV = 1.00 to demonstrate that acquisitions and dilution offset exactly. Replace before use.
A5: Assumptions
A6: % of HYPE staked | B6: 1 | C6: Set 100% if the model stakes the whole balance
A7: Annual staking yield | B7: 0.019757 | C7: (1+q)^4-1. Only used if column G is blank
A8: Quarterly staking rate | B8: =(1+B7)^0.25-1 -> 0.0049030718
A10: # | B10: Period | C10: Date | D10: Total HYPE (m) | E10: FD shares (m) | F10: HYPE price ($) | G10: Purchases (m) — optional | H10: HYPE / 1000 sh | I10: NAV / 1000 sh ($) | J10: Δ HYPE (m) | K10: Δ shares (m) | L10: Staking est. (m) | M10: Acquisitions used (m) | N10: Staking used (m) | O10: ln(1+acq/open) | P10: Acq % of open HYPE | Q10: Shares issued % of open | R10: mNAV proxy | S10: Check
A11: 0 | B11: Dec-25 | C11: 46022 | D11: 12.86 | E11: 150.7 | F11: 25.48 | H11: =D11/E11*1000 -> 85.335103 | I11: =H11*F11 -> 2174.3384 | J11: — | K11: — | L11: — | M11: — | N11: — | O11: — | P11: — | Q11: — | R11: — | S11: —
A12: 1 | B12: Mar-26 | C12: 46112 | D12: 13.3261 | E12: 155.4235 | F12: 27.407 | G12: 0.4031 | H12: =D12/E12*1000 -> 85.740573 | I12: =H12*F12 -> 2349.8919 | J12: =D12-D11 -> 0.4661 | K12: =E12-E11 -> 4.7235 | L12: =D11*$B$6*$B$8 -> 0.063053504 | M12: =IF(G12="",J12-L12,G12) -> 0.4031 | N12: =J12-M12 -> 0.063 | O12: =LN(1+M12/D11) -> 0.030864024 | P12: =M12/D11 -> 0.031345257 | Q12: =K12/E11 -> 0.031343729 | R12: =IFERROR(P12/Q12,"n/a") -> 1.0000487 | S12: =IF(ROUND(M12+N12-J12,6)=0,"ok","CHECK") -> ok
A13: 2 | B13: Jun-26 | C13: 46203 | D13: 13.8091 | E13: 160.295 | F13: 29.4797 | G13: 0.4177 | H13: =D13/E13*1000 -> 86.14804 | I13: =H13*F13 -> 2539.6184 | J13: =D13-D12 -> 0.483 | K13: =E13-E12 -> 4.8715 | L13: =D12*$B$6*$B$8 -> 0.065338825 | M13: =IF(G13="",J13-L13,G13) -> 0.4177 | N13: =J13-M13 -> 0.0653 | O13: =LN(1+M13/D12) -> 0.030863295 | P13: =M13/D12 -> 0.031344504 | Q13: =K13/E12 -> 0.031343394 | R13: =IFERROR(P13/Q13,"n/a") -> 1.0000354 | S13: =IF(ROUND(M13+N13-J13,6)=0,"ok","CHECK") -> ok
A14: 3 | B14: Sep-26 | C14: 46295 | D14: 14.3096 | E14: 165.3192 | F14: 31.7092 | G14: 0.4328 | H14: =D14/E14*1000 -> 86.557399 | I14: =H14*F14 -> 2744.6659 | J14: =D14-D13 -> 0.5005 | K14: =E14-E13 -> 5.0242 | L14: =D13*$B$6*$B$8 -> 0.067707009 | M14: =IF(G14="",J14-L14,G14) -> 0.4328 | N14: =J14-M14 -> 0.0677 | O14: =LN(1+M14/D13) -> 0.030860529 | P14: =M14/D13 -> 0.031341652 | Q14: =K14/E13 -> 0.03134346 | R14: =IFERROR(P14/Q14,"n/a") -> 0.99994229 | S14: =IF(ROUND(M14+N14-J14,6)=0,"ok","CHECK") -> ok
A15: 4 | B15: Dec-26 | C15: 46387 | D15: 14.8282 | E15: 170.5009 | F15: 34.1073 | G15: 0.4485 | H15: =D15/E15*1000 -> 86.968456 | I15: =H15*F15 -> 2966.2592 | J15: =D15-D14 -> 0.5186 | K15: =E15-E14 -> 5.1817 | L15: =D14*$B$6*$B$8 -> 0.070160996 | M15: =IF(G15="",J15-L15,G15) -> 0.4485 | N15: =J15-M15 -> 0.0701 | O15: =LN(1+M15/D14) -> 0.030861444 | P15: =M15/D14 -> 0.031342595 | Q15: =K15/E14 -> 0.031343607 | R15: =IFERROR(P15/Q15,"n/a") -> 0.99996773 | S15: =IF(ROUND(M15+N15-J15,6)=0,"ok","CHECK") -> ok
A16: 5 | B16: Mar-27 | C16: 46477 | D16: 15.3656 | E16: 175.8449 | F16: 36.6867 | G16: 0.4648 | H16: =D16/E16*1000 -> 87.38155 | I16: =H16*F16 -> 3205.7407 | J16: =D16-D15 -> 0.5374 | K16: =E16-E15 -> 5.344 | L16: =D15*$B$6*$B$8 -> 0.072703729 | M16: =IF(G16="",J16-L16,G16) -> 0.4648 | N16: =J16-M16 -> 0.0726 | O16: =LN(1+M16/D15) -> 0.030864434 | P16: =M16/D15 -> 0.031345679 | Q16: =K16/E15 -> 0.031342943 | R16: =IFERROR(P16/Q16,"n/a") -> 1.0000873 | S16: =IF(ROUND(M16+N16-J16,6)=0,"ok","CHECK") -> ok
A17: 6 | B17: Jun-27 | C17: 46568 | D17: 15.9225 | E17: 181.3565 | F17: 39.4612 | G17: 0.4816 | H17: =D17/E17*1000 -> 87.796688 | I17: =H17*F17 -> 3464.5627 | J17: =D17-D16 -> 0.5569 | K17: =E17-E16 -> 5.5116 | L17: =D16*$B$6*$B$8 -> 0.07533864 | M17: =IF(G17="",J17-L17,G17) -> 0.4816 | N17: =J17-M17 -> 0.0753 | O17: =LN(1+M17/D16) -> 0.030861584 | P17: =M17/D16 -> 0.03134274 | Q17: =K17/E16 -> 0.031343531 | R17: =IFERROR(P17/Q17,"n/a") -> 0.99997477 | S17: =IF(ROUND(M17+N17-J17,6)=0,"ok","CHECK") -> ok
A18: 7 | B18: Sep-27 | C18: 46660 | D18: 16.4996 | E18: 187.0409 | F18: 42.4456 | G18: 0.4991 | H18: =D18/E18*1000 -> 88.213861 | I18: =H18*F18 -> 3744.2903 | J18: =D18-D17 -> 0.5771 | K18: =E18-E17 -> 5.6844 | L18: =D17*$B$6*$B$8 -> 0.078069161 | M18: =IF(G18="",J18-L18,G18) -> 0.4991 | N18: =J18-M18 -> 0.078 | O18: =LN(1+M18/D17) -> 0.030864338 | P18: =M18/D17 -> 0.03134558 | Q18: =K18/E17 -> 0.03134379 | R18: =IFERROR(P18/Q18,"n/a") -> 1.0000571 | S18: =IF(ROUND(M18+N18-J18,6)=0,"ok","CHECK") -> ok
A19: 8 | B19: Dec-27 | C19: 46752 | D19: 17.0976 | E19: 192.9034 | F19: 45.6556 | G19: 0.5172 | H19: =D19/E19*1000 -> 88.632963 | I19: =H19*F19 -> 4046.5911 | J19: =D19-D18 -> 0.598 | K19: =E19-E18 -> 5.8625 | L19: =D18*$B$6*$B$8 -> 0.080898724 | M19: =IF(G19="",J19-L19,G19) -> 0.5172 | N19: =J19-M19 -> 0.0808 | O19: =LN(1+M19/D18) -> 0.030864953 | P19: =M19/D18 -> 0.031346214 | Q19: =K19/E18 -> 0.031343412 | R19: =IFERROR(P19/Q19,"n/a") -> 1.0000894 | S19: =IF(ROUND(M19+N19-J19,6)=0,"ok","CHECK") -> ok
A20: 9 | B20: Mar-28 | C20: 46843 | D20: 17.7173 | E20: 198.9497 | F20: 49.1084 | G20: 0.5359 | H20: =D20/E20*1000 -> 89.054168 | I20: =H20*F20 -> 4373.3077 | J20: =D20-D19 -> 0.6197 | K20: =E20-E19 -> 6.0463 | L20: =D19*$B$6*$B$8 -> 0.083830761 | M20: =IF(G20="",J20-L20,G20) -> 0.5359 | N20: =J20-M20 -> 0.0838 | O20: =LN(1+M20/D19) -> 0.030862399 | P20: =M20/D19 -> 0.03134358 | Q20: =K20/E19 -> 0.031343667 | R20: =IFERROR(P20/Q20,"n/a") -> 0.99999723 | S20: =IF(ROUND(M20+N20-J20,6)=0,"ok","CHECK") -> ok
A21: 10 | B21: Jun-28 | C21: 46934 | D21: 18.3594 | E21: 205.1854 | F21: 52.8223 | G21: 0.5553 | H21: =D21/E21*1000 -> 89.477127 | I21: =H21*F21 -> 4726.3876 | J21: =D21-D20 -> 0.6421 | K21: =E21-E20 -> 6.2357 | L21: =D20*$B$6*$B$8 -> 0.086869194 | M21: =IF(G21="",J21-L21,G21) -> 0.5553 | N21: =J21-M21 -> 0.0868 | O21: =LN(1+M21/D20) -> 0.030861107 | P21: =M21/D20 -> 0.031342247 | Q21: =K21/E20 -> 0.031343098 | R21: =IFERROR(P21/Q21,"n/a") -> 0.99997285 | S21: =IF(ROUND(M21+N21-J21,6)=0,"ok","CHECK") -> ok
A22: 11 | B22: Sep-28 | C22: 47026 | D22: 19.0248 | E22: 211.6167 | F22: 56.8172 | G22: 0.5754 | H22: =D22/E22*1000 -> 89.902167 | I22: =H22*F22 -> 5107.9894 | J22: =D22-D21 -> 0.6654 | K22: =E22-E21 -> 6.4313 | L22: =D21*$B$6*$B$8 -> 0.090017457 | M22: =IF(G22="",J22-L22,G22) -> 0.5754 | N22: =J22-M22 -> 0.09 | O22: =LN(1+M22/D21) -> 0.030859794 | P22: =M22/D21 -> 0.031340893 | Q22: =K22/E21 -> 0.031343848 | R22: =IFERROR(P22/Q22,"n/a") -> 0.99990574 | S22: =IF(ROUND(M22+N22-J22,6)=0,"ok","CHECK") -> ok
A23: 12 | B23: Dec-28 | C23: 47118 | D23: 19.7144 | E23: 218.2495 | F23: 61.1141 | G23: 0.5963 | H23: =D23/E23*1000 -> 90.329646 | I23: =H23*F23 -> 5520.415 | J23: =D23-D22 -> 0.6896 | K23: =E23-E22 -> 6.6328 | L23: =D22*$B$6*$B$8 -> 0.093279961 | M23: =IF(G23="",J23-L23,G23) -> 0.5963 | N23: =J23-M23 -> 0.0933 | O23: =LN(1+M23/D22) -> 0.030862127 | P23: =M23/D22 -> 0.031343299 | Q23: =K23/E22 -> 0.031343462 | R23: =IFERROR(P23/Q23,"n/a") -> 0.99999481 | S23: =IF(ROUND(M23+N23-J23,6)=0,"ok","CHECK") -> ok
... A51: 40 | B51: Dec-35 | C51: 49674 | D51: 53.4212 | E51: 517.9006 | F51: 470.6224 | G51: 1.6158 | H51: =D51/E51*1000 -> 103.14952 | I51: =H51*F51 -> 48544.476 | J51: =D51-D50 -> 1.8685 | K51: =E51-E50 -> 15.7395 | L51: =D50*$B$6*$B$8 -> 0.25276659 | M51: =IF(G51="",J51-L51,G51) -> 1.6158 | N51: =J51-M51 -> 0.2527 | O51: =LN(1+M51/D50) -> 0.03086153 | P51: =M51/D50 -> 0.031342684 | Q51: =K51/E50 -> 0.031343527 | R51: =IFERROR(P51/Q51,"n/a") -> 0.99997311 | S51: =IF(ROUND(M51+N51-J51,6)=0,"ok","CHECK") -> ok
A53: Column G (Purchases) is the preferred input. If supplied, acquisitions are taken directly from the model and staking becomes the residual — this is what makes Method B exact.
A54: If column G is left blank, staking is estimated from the assumptions above and acquisitions fall out as the residual. That reverses which line carries any error.
A55: mNAV proxy (column R) = acquisitions as % of opening HYPE, divided by shares issued as % of opening shares. A value of 1.000 means issuance is exactly at NAV and acquisitions must offset dilution exactly.
A56: A value below 1.000 means shares were issued below NAV, or some issuance did not fund HYPE purchases (ESOP, warrants). Above 1.000 means issuance at a premium — accretive.

Sheet Attribution
A1: CAGR attribution — HYPE per 1000 shares (v2)
A2: Two allocation methods shown side by side. Method A is the v1 weighted split; Method B is the corrected sequential split.
A4: Period
A5: Start | B5: Dec-25
A6: End | B6: Jun-35
A7: Start date | B7: =INDEX(Inputs!$C$11:$C$51,MATCH($B$5,Inputs!$B$11:$B$51,0)) -> 46022
A8: End date | B8: =INDEX(Inputs!$C$11:$C$51,MATCH($B$6,Inputs!$B$11:$B$51,0)) -> 49490
A9: Years (from dates) | B9: =((YEAR(B8)-YEAR(B7))*12+MONTH(B8)-MONTH(B7))/12 -> 9.5
A10: Quarters | B10: =B9*4 -> 38
A11: Years (legacy, row index) | B11: =(INDEX(Inputs!$A$11:$A$51,MATCH($B$6,Inputs!$B$11:$B$51,0))-INDEX(Inputs!$A$11:$A$51,MATCH($B$5,Inputs!$B$11:$B$51,0)))/4 -> 9.5
A12: Index vs date check | B12: =IF(ROUND(B9-B11,6)=0,"agree","MISMATCH — index column is out of step") -> agree
A14: Levels
B15: Start | C15: End
A16: HYPE held (m) | B16: =INDEX(Inputs!$D$11:$D$51,MATCH($B$5,Inputs!$B$11:$B$51,0)) -> 12.86 | C16: =INDEX(Inputs!$D$11:$D$51,MATCH($B$6,Inputs!$B$11:$B$51,0)) -> 49.7496
A17: FD shares (m) | B17: =INDEX(Inputs!$E$11:$E$51,MATCH($B$5,Inputs!$B$11:$B$51,0)) -> 150.7 | C17: =INDEX(Inputs!$E$11:$E$51,MATCH($B$6,Inputs!$B$11:$B$51,0)) -> 486.9
A18: HYPE price ($) | B18: =INDEX(Inputs!$F$11:$F$51,MATCH($B$5,Inputs!$B$11:$B$51,0)) -> 25.48 | C18: =INDEX(Inputs!$F$11:$F$51,MATCH($B$6,Inputs!$B$11:$B$51,0)) -> 406.77
A19: HYPE / 1000 sh | B19: =INDEX(Inputs!$H$11:$H$51,MATCH($B$5,Inputs!$B$11:$B$51,0)) -> 85.335103 | C19: =INDEX(Inputs!$H$11:$H$51,MATCH($B$6,Inputs!$B$11:$B$51,0)) -> 102.17622
A20: NAV / 1000 sh ($) | B20: =INDEX(Inputs!$I$11:$I$51,MATCH($B$5,Inputs!$B$11:$B$51,0)) -> 2174.3384 | C20: =INDEX(Inputs!$I$11:$I$51,MATCH($B$6,Inputs!$B$11:$B$51,0)) -> 41562.22
A22: Log growth rates (annualised, continuously compounded)
A23: r_HYPE | B23: =LN(C16/B16)/$B$9 -> 0.1424085
A24: r_Shares | B24: =LN(C17/B17)/$B$9 -> 0.12344923
A25: r_Price | B25: =LN(C18/B18)/$B$9 -> 0.29161622
A26: r_HPS (= r_HYPE − r_Shares) | B26: =B23-B24 -> 0.018959268
A27: r_NAV (= r_HPS + r_Price) | B27: =B26+B25 -> 0.31057549
A29: Headline CAGRs — two formulas, must agree
B30: EXP(r)−1 | C30: RRI | D30: (End/Start)^(1/n)−1 | E30: Agree?
A31: HYPE per 1000 shares | B31: =EXP(B26)-1 -> 0.019140136 | C31: =_xlfn.RRI($B$9,B19,C19) -> 0.019140136 | D31: =(C19/B19)^(1/$B$9)-1 -> 0.019140136 | E31: =IF(AND(ROUND(B31-C31,8)=0,ROUND(B31-D31,8)=0),"yes","NO") -> yes
A32: NAV per 1000 shares | B32: =EXP(B27)-1 -> 0.36420997 | C32: =_xlfn.RRI($B$9,B20,C20) -> 0.36420997 | D32: =(C20/B20)^(1/$B$9)-1 -> 0.36420997 | E32: =IF(AND(ROUND(B32-C32,8)=0,ROUND(B32-D32,8)=0),"yes","NO") -> yes
A33: RRI is the annually-compounded rate. All three columns must agree by construction; if they do not, the period length is wrong. RRI is written as _xlfn.RRI so Excel resolves it — it will display as RRI.
A35: Source of HYPE added over the window
A36: Cumulative acquisitions (m) | B36: =SUMIFS(Inputs!$M$11:$M$51,Inputs!$A$11:$A$51,">"&INDEX(Inputs!$A$11:$A$51,MATCH($B$5,Inputs!$B$11:$B$51,0)),Inputs!$A$11:$A$51,"<="&INDEX(Inputs!$A$11:$A$51,MATCH($B$6,Inputs!$B$11:$B$51,0))) -> 31.9025
A37: Cumulative staking (m) | B37: =SUMIFS(Inputs!$N$11:$N$51,Inputs!$A$11:$A$51,">"&INDEX(Inputs!$A$11:$A$51,MATCH($B$5,Inputs!$B$11:$B$51,0)),Inputs!$A$11:$A$51,"<="&INDEX(Inputs!$A$11:$A$51,MATCH($B$6,Inputs!$B$11:$B$51,0))) -> 4.9871
A38: Total added (m) | B38: =B36+B37 -> 36.8896
A39: Weight — acquisitions | B39: =IFERROR(B36/B38,0) -> 0.86481014
A40: Weight — staking | B40: =IFERROR(B37/B38,0) -> 0.13518986
A41: Σ ln(1+acq/open) | B41: =SUMIFS(Inputs!$O$11:$O$51,Inputs!$A$11:$A$51,">"&INDEX(Inputs!$A$11:$A$51,MATCH($B$5,Inputs!$B$11:$B$51,0)),Inputs!$A$11:$A$51,"<="&INDEX(Inputs!$A$11:$A$51,MATCH($B$6,Inputs!$B$11:$B$51,0))) -> 1.1727742
A42: r_acq (sequential) | B42: =B41/$B$9 -> 0.12344992
A44: Method A — weighted split (as built in v1)
A45: Driver | B45: Log contribution | C45: CAGR contribution
A46: New HYPE acquired | B46: =$B$39*$B$23 -> 0.12315631 | C46: =IFERROR(B46/$B$26*$B$31,0) -> 0.1243312
...

Sheet Method
A1: Method, the v1→v2 changes, and caveats
A3: The identity | B3: HYPE per 1000 shares = 1000 x HYPE held / fully diluted shares. Growth in the ratio equals growth in the numerator less growth in the denominator. Dilution is a subtraction, not an adjustment, and is usually the largest single line.
A4: Why logs | B4: Percentage growth rates multiply; log rates add. r_HPS = r_HYPE - r_Shares is an exact identity. Each driver's log contribution is rescaled by CAGR / r_total so the parts sum to the reported CAGR with no balancing plug.
A5: EXP(r)-1 vs RRI | B5: A log rate is continuously compounded; a CAGR is annually compounded. EXP(r)-1 converts between them and must equal RRI(years, start, end). Both are shown with an agreement check. If they disagree, the period length is wrong — that is the single most common error here.
A6: FIX in v2 — period length | B6: v1 derived Years from the row-index column, which silently breaks when real data is pasted in or rows are inserted. v2 derives Years from the date column using whole months, and reports the legacy index-based figure alongside with a mismatch flag. In the v1 build this understated the period by two quarters and overstated NAV CAGR by roughly 2.7pp.
A7: FIX in v2 — allocation | B7: Method A (v1) splits r_HYPE by each source's share of cumulative tokens added. Because acquisitions and staking compound on each other, that static weighting misallocates the cross-term and can make acquisitions and dilution fail to offset even when issuance is exactly at NAV. Method B instead sums ln(1 + acquisitions / opening balance) period by period, and takes staking as the residual. Both sum to r_HYPE; Method B is exact.
A8: The mNAV test | B8: If shares are issued at NAV, cash raised buys tokens in exact proportion to shares issued, so r_acq must equal r_Shares and acquisitions must offset dilution exactly. Column R on Inputs tests this per period; the diagnostics block tests it over the window. A reading of 1.000 with a non-zero gap in Method A is proof the gap is a method artefact.
A9: Which method to report | B9: Report Method B. Keep Method A visible only to reconcile against earlier drafts. Method B's gross-versus-dilution comparison is exact; its internal split of acquisitions and staking still assumes purchases settle before staking accrues within each quarter, which matches the model's row ordering.
A10: Price is not in the HPS metric | B10: HYPE per 1000 shares is a token count and is unaffected by price. Price enters only the NAV attribution, as a fourth driver. Keep the two decompositions separate.
A11: Sub-periods | B11: A ten-year CAGR conceals phases. Acquisitions are typically front-loaded while staking compounds later, so run shorter windows by changing the start and end labels and check whether the mix shifts.
A12: Placeholder data | B12: Columns D, E, F and G on Inputs are a constructed series at mNAV = 1.00, present only to demonstrate that the two methods behave as described. They are not estimates and must be replaced.
