Workbook

Sheet Inputs
A1: HYPE per 1000 shares — input data and derived flows
A2: AMBER cells are inputs — overwrite columns B, C, D with your model. Everything else is calculated.
A4: Assumptions
A5: % of HYPE staked | B5: 0.8 | C5: Set to 0% if you supply acquisitions directly in column J
A6: Annual staking yield | B6: 0.023 | C6: Validator reward rate, net of commission
A7: Quarterly staking rate | B7: =(1+B6)^0.25-1 -> 0.0057010613
A9: # | B9: Period | C9: Total HYPE (m) | D9: FD shares (m) | E9: HYPE price ($) | F9: HYPE / 1000 sh | G9: NAV / 1000 sh ($) | H9: Δ HYPE (m) | I9: Staking (m) | J9: Acq. override (m) | K9: Acquisitions (m) | L9: Check
A10: 0 | B10: Dec-25 | C10: 12.6 | D10: 300 | E10: 40 | F10: =C10/D10*1000 -> 42 | G10: =F10*E10 -> 1680 | H10: — | I10: — | K10: — | L10: —
A11: 1 | B11: Mar-26 | C11: 12.8177 | D11: 302.5342 | E11: 41.5327 | F11: =C11/D11*1000 -> 42.367772 | G11: =F11*E11 -> 1759.648 | H11: =C11-C10 -> 0.2177 | I11: =C10*$B$5*$B$7 -> 0.057466698 | K11: =IF(J11="",H11-I11,J11) -> 0.1602333 | L11: =IF(ROUND(I11+K11-H11,6)=0,"ok","check") -> ok
A12: 2 | B12: Jun-26 | C12: 13.0391 | D12: 305.0898 | E12: 43.1242 | F12: =C12/D12*1000 -> 42.738564 | G12: =F12*E12 -> 1843.0664 | H12: =C12-C11 -> 0.2214 | I12: =C11*$B$5*$B$7 -> 0.058459595 | K12: =IF(J12="",H12-I12,J12) -> 0.16294041 | L12: =IF(ROUND(I12+K12-H12,6)=0,"ok","check") -> ok
A13: 3 | B13: Sep-26 | C13: 13.2644 | D13: 307.667 | E13: 44.7766 | F13: =C13/D13*1000 -> 43.112846 | G13: =F13*E13 -> 1930.4467 | H13: =C13-C12 -> 0.2253 | I13: =C12*$B$5*$B$7 -> 0.059469367 | K13: =IF(J13="",H13-I13,J13) -> 0.16583063 | L13: =IF(ROUND(I13+K13-H13,6)=0,"ok","check") -> ok
A14: 4 | B14: Dec-26 | C14: 13.4936 | D14: 310.2659 | E14: 46.4923 | F14: =C14/D14*1000 -> 43.490438 | G14: =F14*E14 -> 2021.9705 | H14: =C14-C13 -> 0.2292 | I14: =C13*$B$5*$B$7 -> 0.060496926 | K14: =IF(J14="",H14-I14,J14) -> 0.16870307 | L14: =IF(ROUND(I14+K14-H14,6)=0,"ok","check") -> ok
A15: 5 | B15: Mar-27 | C15: 13.7267 | D15: 312.8868 | E15: 48.2738 | F15: =C15/D15*1000 -> 43.871138 | G15: =F15*E15 -> 2117.8265 | H15: =C15-C14 -> 0.2331 | I15: =C14*$B$5*$B$7 -> 0.061542272 | K15: =IF(J15="",H15-I15,J15) -> 0.17155773 | L15: =IF(ROUND(I15+K15-H15,6)=0,"ok","check") -> ok
A16: 6 | B16: Jun-27 | C16: 13.9639 | D16: 315.5299 | E16: 50.1236 | F16: =C16/D16*1000 -> 44.255394 | G16: =F16*E16 -> 2218.2397 | H16: =C16-C15 -> 0.2372 | I16: =C15*$B$5*$B$7 -> 0.062605406 | K16: =IF(J16="",H16-I16,J16) -> 0.17459459 | L16: =IF(ROUND(I16+K16-H16,6)=0,"ok","check") -> ok
A17: 7 | B17: Sep-27 | C17: 14.2051 | D17: 318.1952 | E17: 52.0442 | F17: =C17/D17*1000 -> 44.642722 | G17: =F17*E17 -> 2323.3948 | H17: =C17-C16 -> 0.2412 | I17: =C16*$B$5*$B$7 -> 0.06368724 | K17: =IF(J17="",H17-I17,J17) -> 0.17751276 | L17: =IF(ROUND(I17+K17-H17,6)=0,"ok","check") -> ok
A18: 8 | B18: Dec-27 | C18: 14.4506 | D18: 320.8831 | E18: 54.0384 | F18: =C18/D18*1000 -> 45.033846 | G18: =F18*E18 -> 2433.557 | H18: =C18-C17 -> 0.2455 | I18: =C17*$B$5*$B$7 -> 0.064787317 | K18: =IF(J18="",H18-I18,J18) -> 0.18071268 | L18: =IF(ROUND(I18+K18-H18,6)=0,"ok","check") -> ok
A19: 9 | B19: Mar-28 | C19: 14.7002 | D19: 323.5937 | E19: 56.109 | F19: =C19/D19*1000 -> 45.427955 | G19: =F19*E19 -> 2548.9171 | H19: =C19-C18 -> 0.2496 | I19: =C18*$B$5*$B$7 -> 0.065907005 | K19: =IF(J19="",H19-I19,J19) -> 0.18369299 | L19: =IF(ROUND(I19+K19-H19,6)=0,"ok","check") -> ok
A20: 10 | B20: Jun-28 | C20: 14.9542 | D20: 326.3272 | E20: 58.259 | F20: =C20/D20*1000 -> 45.825785 | G20: =F20*E20 -> 2669.7644 | H20: =C20-C19 -> 0.254 | I20: =C19*$B$5*$B$7 -> 0.067045393 | K20: =IF(J20="",H20-I20,J20) -> 0.18695461 | L20: =IF(ROUND(I20+K20-H20,6)=0,"ok","check") -> ok
A21: 11 | B21: Sep-28 | C21: 15.2126 | D21: 329.0838 | E21: 60.4914 | F21: =C21/D21*1000 -> 46.227131 | G21: =F21*E21 -> 2796.3439 | H21: =C21-C20 -> 0.2584 | I21: =C20*$B$5*$B$7 -> 0.068203849 | K21: =IF(J21="",H21-I21,J21) -> 0.19019615 | L21: =IF(ROUND(I21+K21-H21,6)=0,"ok","check") -> ok
A22: 12 | B22: Dec-28 | C22: 15.4754 | D22: 331.8636 | E22: 62.8093 | F22: =C22/D22*1000 -> 46.631809 | G22: =F22*E22 -> 2928.9113 | H22: =C22-C21 -> 0.2628 | I22: =C21*$B$5*$B$7 -> 0.069382372 | K22: =IF(J22="",H22-I22,J22) -> 0.19341763 | L22: =IF(ROUND(I22+K22-H22,6)=0,"ok","check") -> ok
... A50: 40 | B50: Dec-35 | C50: 25 | D50: 420 | E50: 180 | F50: =C50/D50*1000 -> 59.52381 | G50: =F50*E50 -> 10714.286 | H50: =C50-C49 -> 0.4246 | I50: =C49*$B$5*$B$7 -> 0.11208469 | K50: =IF(J50="",H50-I50,J50) -> 0.31251531 | L50: =IF(ROUND(I50+K50-H50,6)=0,"ok","check") -> ok
A52: Note: staking is modelled as prior-period HYPE balance x %staked x quarterly rate. Acquisitions are the residual. If your model already carries an acquisitions schedule, enter it in column J and staking becomes the residual instead — set the yield to 0% to switch off the estimate.
A53: Note: a negative acquisitions figure means HYPE was sold in that quarter. That is meaningful, not an error.
A54: Note: placeholder series in columns C, D, E are illustrative only and must be replaced before use.

Sheet Attribution
A1: CAGR attribution — HYPE per 1000 shares
A2: Log-based decomposition. Contributions are rescaled to sum exactly to the reported CAGR.
A4: Period
A5: Start | B5: Dec-25
A6: End | B6: Dec-35
A7: Start index | B7: =MATCH(B5,Inputs!$B$10:$B$50,0)-1 -> 0
A8: End index | B8: =MATCH(B6,Inputs!$B$10:$B$50,0)-1 -> 40
A9: Years | B9: =(B8-B7)/4 -> 10
A11: Levels
B12: Start | C12: End
A13: HYPE held (m) | B13: =INDEX(Inputs!$C$10:$C$50,MATCH($B$5,Inputs!$B$10:$B$50,0)) -> 12.6 | C13: =INDEX(Inputs!$C$10:$C$50,MATCH($B$6,Inputs!$B$10:$B$50,0)) -> 25
A14: FD shares (m) | B14: =INDEX(Inputs!$D$10:$D$50,MATCH($B$5,Inputs!$B$10:$B$50,0)) -> 300 | C14: =INDEX(Inputs!$D$10:$D$50,MATCH($B$6,Inputs!$B$10:$B$50,0)) -> 420
A15: HYPE price ($) | B15: =INDEX(Inputs!$E$10:$E$50,MATCH($B$5,Inputs!$B$10:$B$50,0)) -> 40 | C15: =INDEX(Inputs!$E$10:$E$50,MATCH($B$6,Inputs!$B$10:$B$50,0)) -> 180
A16: HYPE / 1000 sh | B16: =INDEX(Inputs!$F$10:$F$50,MATCH($B$5,Inputs!$B$10:$B$50,0)) -> 42 | C16: =INDEX(Inputs!$F$10:$F$50,MATCH($B$6,Inputs!$B$10:$B$50,0)) -> 59.52381
A17: NAV / 1000 sh ($) | B17: =INDEX(Inputs!$G$10:$G$50,MATCH($B$5,Inputs!$B$10:$B$50,0)) -> 1680 | C17: =INDEX(Inputs!$G$10:$G$50,MATCH($B$6,Inputs!$B$10:$B$50,0)) -> 10714.286
A19: Log growth rates (annualised)
A20: r_HYPE | B20: =LN(C13/B13)/$B$9 -> 0.068517901
A21: r_Shares | B21: =LN(C14/B14)/$B$9 -> 0.033647224
A22: r_Price | B22: =LN(C15/B15)/$B$9 -> 0.15040774
A23: r_HPS (= r_HYPE - r_Shares) | B23: =B20-B21 -> 0.034870677
A24: r_NAV (= r_HPS + r_Price) | B24: =B23+B22 -> 0.18527842
A26: Headline CAGRs
A27: HYPE per 1000 shares | B27: =EXP(B23)-1 -> 0.035485788
A28: NAV per 1000 shares | B28: =EXP(B24)-1 -> 0.20355348
A30: Source of HYPE added over the window
A31: Cumulative staking (m) | B31: =SUMIFS(Inputs!$I$10:$I$50,Inputs!$A$10:$A$50,">"&$B$7,Inputs!$A$10:$A$50,"<="&$B$8) -> 3.2733939
A32: Cumulative acquisitions (m) | B32: =SUMIFS(Inputs!$K$10:$K$50,Inputs!$A$10:$A$50,">"&$B$7,Inputs!$A$10:$A$50,"<="&$B$8) -> 9.1266061
A33: Total added (m) | B33: =B31+B32 -> 12.4
A34: Weight — staking | B34: =IFERROR(B31/B33,0) -> 0.26398338
A35: Weight — acquisitions | B35: =IFERROR(B32/B33,0) -> 0.73601662
A37: Attribution — HYPE per 1000 shares CAGR
A38: Driver | B38: Log contribution | C38: CAGR contribution (pp)
A39: New HYPE acquired | B39: =$B$35*$B$20 -> 0.050430314 | C39: =IFERROR(B39/$B$23*$B$27,0) -> 0.051319894
A40: Staking rewards | B40: =$B$34*$B$20 -> 0.018087587 | C40: =IFERROR(B40/$B$23*$B$27,0) -> 0.018406648
A41: Share dilution | B41: =-$B$21 -> -0.033647224 | C41: =IFERROR(B41/$B$23*$B$27,0) -> -0.034240753
A42: Total | B42: =SUM(B39:B41) -> 0.034870677 | C42: =SUM(C39:C41) -> 0.035485788
A43: Tie to headline | C43: =IF(ROUND(C42-B27,8)=0,"ties","does not tie") -> ties
A45: Attribution — NAV per 1000 shares CAGR
A46: Driver | B46: Log contribution | C46: CAGR contribution (pp)
A47: New HYPE acquired | B47: =$B$35*$B$20 -> 0.050430314 | C47: =IFERROR(B47/$B$24*$B$28,0) -> 0.055404544
...

Sheet Method
A1: Method and caveats
A3: The identity | B3: HYPE per 1000 shares = 1000 x HYPE held / fully diluted shares. Growth in the ratio equals growth in the numerator less growth in the denominator. Dilution is a subtraction, not an adjustment, and is usually the largest single driver.
A4: Why logs | B4: Percentage contributions do not add. Continuously compounded (log) growth rates do, exactly: r_HPS = r_HYPE - r_Shares. Each driver's log contribution is then rescaled by CAGR / r_total so the pieces sum to the reported CAGR without a balancing plug.
A5: Splitting the numerator | B5: r_HYPE is apportioned between acquisitions and staking by each source's share of cumulative HYPE added over the window. This assumes the mix is broadly stable through the period. If acquisitions are heavily front- or back-loaded, run the attribution on sub-periods instead of one ten-year window.
A6: Staking estimate | B6: Modelled as prior-quarter balance x % staked x quarterly rate, where the quarterly rate is (1+annual)^0.25-1. Acquisitions fall out as the residual. If the model carries an explicit acquisitions schedule, enter it in column J of Inputs; staking then becomes the residual. Set the yield to zero to disable the estimate.
A7: Price is not in the HPS metric | B7: HYPE per 1000 shares is a unit count and is unaffected by price. Price enters only the NAV per 1000 shares attribution, as a fourth driver. Keep the two decompositions separate — combining them is the most common error in this analysis.
A8: Negative acquisitions | B8: A negative residual means HYPE was sold in that quarter, or that the staking assumption is too high. Check column L before concluding the former.
A9: Sub-period analysis | B9: Change the start and end period on the Attribution sheet to run any window. A ten-year CAGR can conceal very different phases; consider reporting Dec-25 to Dec-30 and Dec-30 to Dec-35 separately.
A10: Placeholder data | B10: Columns C, D and E of the Inputs sheet are illustrative smooth series, not estimates. They must be replaced with your model output before any figure here is used.
