Workbook

Sheet Daily 
A1: HYPERLIQUID (HYPE) — DAILY . Volumes -> Gross Fees -> Fee→Revenue bridge (−HLP, −Unit, −HIP-3/HIP-4 deployer; builder is on-top) -> Revenue per segment (sum = HyperCore = hyperscreener) -> + HyperEVM + Auction = Total Revenue. Then AF/supply & OTS. Daily 2024-11-30 → 2026-09-19. Hover headers for source. blue=ASXN/primary source · black=formula · green=derived, cross-check or SECONDARY-SOURCE fill · amber shading=NOT ASXN (spot volume: DefiLlama fill; revenue: DefiLlama pre-2025-03-20; categories: pre-2025-11-27 backfill) (revenue: DefiLlama pre-2025-03-20; team unlocks & the two supply-split columns: held flat after 2026-09-06).
B2: VOLUME ($) | F2: HIP-3 VOLUME BY CATEGORY ($) | N2: GROSS FEES ($) [user-paid] | S2: FEE → REVENUE BRIDGE [deductions, $] | AC2: REVENUE TO HYPERCORE ($) | AJ2: IMPLIED TAKE-RATE (bps) | AN2: OTHER REVENUE ($) | AQ2: ASSISTANCE FUND & SUPPLY | AZ2: OTS (Hyperliquid Strategies basis)
A3: Date | B3: Core Crypto Perp Vol ($) | C3: HIP-3 Perp Vol ($) | D3: Spot Vol ($) | E3: HIP-4 Vol ($) | F3: HIP-3 Commodities ($) | G3: HIP-3 Crypto ($) | H3: HIP-3 FX ($) | I3: HIP-3 Indices ($) | J3: HIP-3 Pre-IPO ($) | K3: HIP-3 Equities ($) | L3: HIP-3 Cat Total ($) | M3: Pro-rate Factor Applied | N3: Core Crypto Perp Fees ($) | O3: HIP-3 Gross Fees ($) | P3: Spot Fees incl Unit ($) | Q3: HIP-4 Fees ($) | R3: Total Gross Fees ($) | S3: HLP Rate | T3: (-) HLP on Core Perp ($) | U3: (-) HLP on HIP-3 ($) | V3: (-) HLP on Spot ($) | W3: (-) HLP on HIP-4 ($) | X3: (-) Unit Protocol Fees ($) | Y3: (-) HIP-3 Deployer Fees ($) | Z3: (-) HIP-4 Deployer Fees ($) | AA3: Total Deductions ($) | AB3: Builder Code Fees [on-top, not deducted] ($) | AC3: Core Crypto Perp Revenue ($) | AD3: HIP-3 Revenue ($) | AE3: Spot Revenue ($) | AF3: HIP-4 Revenue ($) | AG3: = HyperCore Revenue (model) ($) | AH3: HyperCore Revenue ($) | AI3: Accrual less Buyback ($) | AJ3: Core Perp Take-Rate (bps) | AK3: HIP-3 Take-Rate (bps) | AL3: Spot Take-Rate (bps) | AM3: HIP-4 Take-Rate (bps) | AN3: HyperEVM Burn ($) | AO3: Auction Burn ($) | AP3: Total Revenue ($) | AQ3: Revenue -> AF ($) | AR3: Buyback HYPE | AS3: Buyback Avg Price ($) | AT3: AF HYPE Balance | AU3: Staking Emissions (HYPE) | AV3: Fee Burn (HYPE) | AW3: Team Tokens Unlocked (HYPE) | AX3: HYPE Staked (M) | AY3: Implied Staking Yield | AZ3: (-) Future Emissions & CR (HYPE) | BA3: (-) Hyper Foundation (HYPE) | BB3: (-) Assistance Fund (HYPE) | BC3: (-) Community Grants (HYPE) | BD3: (-) HC&EVM Fee Burns (HYPE) | BE3: = OTS (HYPE) | BF3: Core Contributors Locked (M) | BG3: Circulating Token Supply (M) | BH3: OTS Value ($)
A4: 45626 | B4: 1927839627 | D4: 460835741 | S4: 0.03 | AJ4: =IF(OR(B4="",B4=0,N4=""),"",N4/B4*10000) | AK4: =IF(OR(C4="",C4=0),"",O4/C4*10000) | AL4: =IF(OR(D4="",D4=0),"",P4/D4*10000) -> 0 | AM4: =IF(OR(E4="",E4=0),"",Q4/E4*10000) | AT4: 8714980.2 | AU4: 0 | AV4: 32364.464 | AY4: =IF(OR(AX4="",AX4=0,AU4=""),"",AU4*365/(AX4*1000000)) | AZ4: 0 | BA4: 60480066 | BB4: 8714980.2 | BC4: 2971324 | BD4: =1000000000-999967635.536+0 -> 32364.464 | BE4: =1000000000-AZ4-BA4-BB4-BC4-BD4 -> 9.2780127e+08 | BF4: 238 | BG4: =BE4/1000000-BF4 -> 689.80127 | BH4: =BE4*8.64 -> 8.0162029e+09
A5: 45627 | B5: 2230952304 | D5: 382137710 | S5: 0.03 | AJ5: =IF(OR(B5="",B5=0,N5=""),"",N5/B5*10000) | AK5: =IF(OR(C5="",C5=0),"",O5/C5*10000) | AL5: =IF(OR(D5="",D5=0),"",P5/D5*10000) -> 0 | AM5: =IF(OR(E5="",E5=0),"",Q5/E5*10000) | AT5: 9336088.4 | AU5: 0 | AV5: 10604.896 | AY5: =IF(OR(AX5="",AX5=0,AU5=""),"",AU5*365/(AX5*1000000)) | AZ5: 0 | BA5: 60480066 | BB5: 9336088.4 | BC5: 2971324 | BD5: =1000000000-999957030.64+0 -> 42969.36 | BE5: =1000000000-AZ5-BA5-BB5-BC5-BD5 -> 9.2716955e+08 | BF5: 238 | BG5: =BE5/1000000-BF5 -> 689.16955 | BH5: =BE5*8.9 -> 8.251809e+09
A6: 45628 | B6: 5333125841 | D6: 320571512 | S6: 0.03 | AJ6: =IF(OR(B6="",B6=0,N6=""),"",N6/B6*10000) | AK6: =IF(OR(C6="",C6=0),"",O6/C6*10000) | AL6: =IF(OR(D6="",D6=0),"",P6/D6*10000) -> 0 | AM6: =IF(OR(E6="",E6=0),"",Q6/E6*10000) | AT6: 9336088.4 | AU6: 0 | AV6: 2916.6523 | AY6: =IF(OR(AX6="",AX6=0,AU6=""),"",AU6*365/(AX6*1000000)) | AZ6: 0 | BA6: 60480066 | BB6: 9336088.4 | BC6: 2971324 | BD6: =1000000000-999954113.9877+0 -> 45886.012 | BE6: =1000000000-AZ6-BA6-BB6-BC6-BD6 -> 9.2716664e+08 | BF6: 238 | BG6: =BE6/1000000-BF6 -> 689.16664 | BH6: =BE6*8.66 -> 8.0292631e+09
A7: 45629 | B7: 4881981857 | D7: 302890343 | S7: 0.03 | AJ7: =IF(OR(B7="",B7=0,N7=""),"",N7/B7*10000) | AK7: =IF(OR(C7="",C7=0),"",O7/C7*10000) | AL7: =IF(OR(D7="",D7=0),"",P7/D7*10000) -> 0 | AM7: =IF(OR(E7="",E7=0),"",Q7/E7*10000) | AT7: 9933598.1 | AU7: 0 | AV7: 3632.1998 | AY7: =IF(OR(AX7="",AX7=0,AU7=""),"",AU7*365/(AX7*1000000)) | AZ7: 0 | BA7: 60480066 | BB7: 9933598.1 | BC7: 2971324 | BD7: =1000000000-999950481.7879+0 -> 49518.212 | BE7: =1000000000-AZ7-BA7-BB7-BC7-BD7 -> 9.2656549e+08 | BF7: 238 | BG7: =BE7/1000000-BF7 -> 688.56549 | BH7: =BE7*8.96 -> 8.3020268e+09
A8: 45630 | B8: 6225918535 | D8: 318696984 | S8: 0.03 | AJ8: =IF(OR(B8="",B8=0,N8=""),"",N8/B8*10000) | AK8: =IF(OR(C8="",C8=0),"",O8/C8*10000) | AL8: =IF(OR(D8="",D8=0),"",P8/D8*10000) -> 0 | AM8: =IF(OR(E8="",E8=0),"",Q8/E8*10000) | AT8: 10009960 | AU8: 0 | AV8: 3743.7999 | AY8: =IF(OR(AX8="",AX8=0,AU8=""),"",AU8*365/(AX8*1000000)) | AZ8: 0 | BA8: 60480066 | BB8: 10009960 | BC8: 2971324 | BD8: =1000000000-999946737.988+0 -> 53262.012 | BE8: =1000000000-AZ8-BA8-BB8-BC8-BD8 -> 9.2648539e+08 | BF8: 238 | BG8: =BE8/1000000-BF8 -> 688.48539 | BH8: =BE8*11.08 -> 1.0265458e+10
A9: 45631 | B9: 9789562819 | D9: 323114172 | S9: 0.03 | AJ9: =IF(OR(B9="",B9=0,N9=""),"",N9/B9*10000) | AK9: =IF(OR(C9="",C9=0),"",O9/C9*10000) | AL9: =IF(OR(D9="",D9=0),"",P9/D9*10000) -> 0 | AM9: =IF(OR(E9="",E9=0),"",Q9/E9*10000) | AT9: 10009960 | AU9: 0 | AV9: 4041.2964 | AY9: =IF(OR(AX9="",AX9=0,AU9=""),"",AU9*365/(AX9*1000000)) | AZ9: 0 | BA9: 60480066 | BB9: 10009960 | BC9: 2971324 | BD9: =1000000000-999942696.6916+0 -> 57303.308 | BE9: =1000000000-AZ9-BA9-BB9-BC9-BD9 -> 9.2648135e+08 | BF9: 238 | BG9: =BE9/1000000-BF9 -> 688.48135 | BH9: =BE9*11.4 -> 1.0561887e+10
A10: 45632 | B10: 7811474440 | D10: 218646771 | S10: 0.03 | AJ10: =IF(OR(B10="",B10=0,N10=""),"",N10/B10*10000) | AK10: =IF(OR(C10="",C10=0),"",O10/C10*10000) | AL10: =IF(OR(D10="",D10=0),"",P10/D10*10000) -> 0 | AM10: =IF(OR(E10="",E10=0),"",Q10/E10*10000) | AT10: 10428491 | AU10: 0 | AV10: 3472.5047 | AY10: =IF(OR(AX10="",AX10=0,AU10=""),"",AU10*365/(AX10*1000000)) | AZ10: 0 | BA10: 60480066 | BB10: 10428491 | BC10: 2971324 | BD10: =1000000000-999939224.1869+0 -> 60775.813 | BE10: =1000000000-AZ10-BA10-BB10-BC10-BD10 -> 9.2605934e+08 | BF10: 238 | BG10: =BE10/1000000-BF10 -> 688.05934 | BH10: =BE10*12.69 -> 1.1751693e+10
A11: 45633 | B11: 2862437941 | D11: 182104753 | S11: 0.03 | AJ11: =IF(OR(B11="",B11=0,N11=""),"",N11/B11*10000) | AK11: =IF(OR(C11="",C11=0),"",O11/C11*10000) | AL11: =IF(OR(D11="",D11=0),"",P11/D11*10000) -> 0 | AM11: =IF(OR(E11="",E11=0),"",Q11/E11*10000) | AT11: 10428491 | AU11: 0 | AV11: 2255.2254 | AY11: =IF(OR(AX11="",AX11=0,AU11=""),"",AU11*365/(AX11*1000000)) | AZ11: 0 | BA11: 60480066 | BB11: 10428491 | BC11: 2971324 | BD11: =1000000000-999936968.9615+0 -> 63031.038 | BE11: =1000000000-AZ11-BA11-BB11-BC11-BD11 -> 9.2605709e+08 | BF11: 238 | BG11: =BE11/1000000-BF11 -> 688.05709 | BH11: =BE11*13.83 -> 1.280737e+10
A12: 45634 | B12: 3252798818 | D12: 136064768 | S12: 0.03 | AJ12: =IF(OR(B12="",B12=0,N12=""),"",N12/B12*10000) | AK12: =IF(OR(C12="",C12=0),"",O12/C12*10000) | AL12: =IF(OR(D12="",D12=0),"",P12/D12*10000) -> 0 | AM12: =IF(OR(E12="",E12=0),"",Q12/E12*10000) | AT12: 10428491 | AU12: 0 | AV12: 1897.8347 | AY12: =IF(OR(AX12="",AX12=0,AU12=""),"",AU12*365/(AX12*1000000)) | AZ12: 0 | BA12: 60480066 | BB12: 10428491 | BC12: 2971324 | BD12: =1000000000-999935071.1268+0 -> 64928.873 | BE12: =1000000000-AZ12-BA12-BB12-BC12-BD12 -> 9.2605519e+08 | BF12: 238 | BG12: =BE12/1000000-BF12 -> 688.05519 | BH12: =BE12*14.12 -> 1.3075899e+10
A13: 45635 | B13: 5306358932 | D13: 270676721 | S13: 0.03 | AJ13: =IF(OR(B13="",B13=0,N13=""),"",N13/B13*10000) | AK13: =IF(OR(C13="",C13=0),"",O13/C13*10000) | AL13: =IF(OR(D13="",D13=0),"",P13/D13*10000) -> 0 | AM13: =IF(OR(E13="",E13=0),"",Q13/E13*10000) | AT13: 10654299 | AU13: 0 | AV13: 1284.1908 | AY13: =IF(OR(AX13="",AX13=0,AU13=""),"",AU13*365/(AX13*1000000)) | AZ13: 0 | BA13: 60480066 | BB13: 10654299 | BC13: 2971324 | BD13: =1000000000-999933786.9361+0 -> 66213.064 | BE13: =1000000000-AZ13-BA13-BB13-BC13-BD13 -> 9.258281e+08 | BF13: 238 | BG13: =BE13/1000000-BF13 -> 687.8281 | BH13: =BE13*14.02 -> 1.298011e+10
A14: 45636 | B14: 10009953607 | D14: 208129108 | S14: 0.03 | AJ14: =IF(OR(B14="",B14=0,N14=""),"",N14/B14*10000) | AK14: =IF(OR(C14="",C14=0),"",O14/C14*10000) | AL14: =IF(OR(D14="",D14=0),"",P14/D14*10000) -> 0 | AM14: =IF(OR(E14="",E14=0),"",Q14/E14*10000) | AT14: 10654299 | AU14: 0 | AV14: 2527.2104 | AY14: =IF(OR(AX14="",AX14=0,AU14=""),"",AU14*365/(AX14*1000000)) | AZ14: 0 | BA14: 60480066 | BB14: 10654299 | BC14: 2971324 | BD14: =1000000000-999931259.7256+0 -> 68740.274 | BE14: =1000000000-AZ14-BA14-BB14-BC14-BD14 -> 9.2582557e+08 | BF14: 238 | BG14: =BE14/1000000-BF14 -> 687.82557 | BH14: =BE14*13.54 -> 1.2535678e+10
A15: 45637 | B15: 3979399218 | D15: 211797447 | S15: 0.03 | AJ15: =IF(OR(B15="",B15=0,N15=""),"",N15/B15*10000) | AK15: =IF(OR(C15="",C15=0),"",O15/C15*10000) | AL15: =IF(OR(D15="",D15=0),"",P15/D15*10000) -> 0 | AM15: =IF(OR(E15="",E15=0),"",Q15/E15*10000) | AT15: 10654299 | AU15: 0 | AV15: 2003.998 | AY15: =IF(OR(AX15="",AX15=0,AU15=""),"",AU15*365/(AX15*1000000)) | AZ15: 0 | BA15: 60480066 | BB15: 10654299 | BC15: 2971324 | BD15: =1000000000-999929255.7277+0 -> 70744.272 | BE15: =1000000000-AZ15-BA15-BB15-BC15-BD15 -> 9.2582357e+08 | BF15: 238 | BG15: =BE15/1000000-BF15 -> 687.82357 | BH15: =BE15*13.56 -> 1.2554168e+10
A16: 45638 | B16: 4839045908 | D16: 324908474 | S16: 0.03 | AJ16: =IF(OR(B16="",B16=0,N16=""),"",N16/B16*10000) | AK16: =IF(OR(C16="",C16=0),"",O16/C16*10000) | AL16: =IF(OR(D16="",D16=0),"",P16/D16*10000) -> 0 | AM16: =IF(OR(E16="",E16=0),"",Q16/E16*10000) | AT16: 10654299 | AU16: 0 | AV16: 1932.7073 | AY16: =IF(OR(AX16="",AX16=0,AU16=""),"",AU16*365/(AX16*1000000)) | AZ16: 0 | BA16: 60480066 | BB16: 10654299 | BC16: 2971324 | BD16: =1000000000-999927323.0204+0 -> 72676.98 | BE16: =1000000000-AZ16-BA16-BB16-BC16-BD16 -> 9.2582163e+08 | BF16: 238 | BG16: =BE16/1000000-BF16 -> 687.82163 | BH16: =BE16*16.11 -> 1.4914987e+10
A17: 45639 | B17: 4253319332 | D17: 334237923 | S17: 0.03 | AJ17: =IF(OR(B17="",B17=0,N17=""),"",N17/B17*10000) | AK17: =IF(OR(C17="",C17=0),"",O17/C17*10000) | AL17: =IF(OR(D17="",D17=0),"",P17/D17*10000) -> 0 | AM17: =IF(OR(E17="",E17=0),"",Q17/E17*10000) | AT17: 10662922 | AU17: 0 | AV17: 2435.2699 | AY17: =IF(OR(AX17="",AX17=0,AU17=""),"",AU17*365/(AX17*1000000)) | AZ17: 0 | BA17: 60480066 | BB17: 10662922 | BC17: 2971324 | BD17: =1000000000-999924887.7505+0 -> 75112.25 | BE17: =1000000000-AZ17-BA17-BB17-BC17-BD17 -> 9.2581058e+08 | BF17: 238 | BG17: =BE17/1000000-BF17 -> 687.81058 | BH17: =BE17*18.04 -> 1.6701623e+10
A18: 45640 | B18: 3170522123 | D18: 546075604 | S18: 0.03 | AJ18: =IF(OR(B18="",B18=0,N18=""),"",N18/B18*10000) | AK18: =IF(OR(C18="",C18=0),"",O18/C18*10000) | AL18: =IF(OR(D18="",D18=0),"",P18/D18*10000) -> 0 | AM18: =IF(OR(E18="",E18=0),"",Q18/E18*10000) | AT18: 10761181 | AU18: 0 | AV18: 1602.2514 | AY18: =IF(OR(AX18="",AX18=0,AU18=""),"",AU18*365/(AX18*1000000)) | AZ18: 0 | BA18: 60480066 | BB18: 10761181 | BC18: 2971324 | BD18: =1000000000-999923285.4991+0 -> 76714.501 | BE18: =1000000000-AZ18-BA18-BB18-BC18-BD18 -> 9.2571071e+08 | BF18: 238 | BG18: =BE18/1000000-BF18 -> 687.71071 | BH18: =BE18*19.49 -> 1.8042102e+10
A19: 45641 | B19: 3786628959 | D19: 517821521 | S19: 0.03 | AJ19: =IF(OR(B19="",B19=0,N19=""),"",N19/B19*10000) | AK19: =IF(OR(C19="",C19=0),"",O19/C19*10000) | AL19: =IF(OR(D19="",D19=0),"",P19/D19*10000) -> 0 | AM19: =IF(OR(E19="",E19=0),"",Q19/E19*10000) | AT19: 10761181 | AU19: 0 | AV19: 2857.882 | AY19: =IF(OR(AX19="",AX19=0,AU19=""),"",AU19*365/(AX19*1000000)) | AZ19: 0 | BA19: 60480066 | BB19: 10761181 | BC19: 2971324 | BD19: =1000000000-999920427.6171+0 -> 79572.383 | BE19: =1000000000-AZ19-BA19-BB19-BC19-BD19 -> 9.2570786e+08 | BF19: 238 | BG19: =BE19/1000000-BF19 -> 687.70786 | BH19: =BE19*24.15 -> 2.2355845e+10
A20: 45642 | B20: 6267294833 | D20: 552491542 | S20: 0.03 | AJ20: =IF(OR(B20="",B20=0,N20=""),"",N20/B20*10000) | AK20: =IF(OR(C20="",C20=0),"",O20/C20*10000) | AL20: =IF(OR(D20="",D20=0),"",P20/D20*10000) -> 0 | AM20: =IF(OR(E20="",E20=0),"",Q20/E20*10000) | AT20: 10761181 | AU20: 0 | AV20: 2419.5935 | AY20: =IF(OR(AX20="",AX20=0,AU20=""),"",AU20*365/(AX20*1000000)) | AZ20: 0 | BA20: 60480066 | BB20: 10761181 | BC20: 2971324 | BD20: =1000000000-999918008.0235+0 -> 81991.977 | BE20: =1000000000-AZ20-BA20-BB20-BC20-BD20 -> 9.2570544e+08 | BF20: 238 | BG20: =BE20/1000000-BF20 -> 687.70544 | BH20: =BE20*23.88 -> 2.2105846e+10
A21: 45643 | B21: 5593864857 | D21: 533018011 | S21: 0.03 | AJ21: =IF(OR(B21="",B21=0,N21=""),"",N21/B21*10000) | AK21: =IF(OR(C21="",C21=0),"",O21/C21*10000) | AL21: =IF(OR(D21="",D21=0),"",P21/D21*10000) -> 0 | AM21: =IF(OR(E21="",E21=0),"",Q21/E21*10000) | AT21: 10789059 | AU21: 0 | AV21: 2278.9176 | AY21: =IF(OR(AX21="",AX21=0,AU21=""),"",AU21*365/(AX21*1000000)) | AZ21: 0 | BA21: 60480066 | BB21: 10789059 | BC21: 2971324 | BD21: =1000000000-999915729.1059+0 -> 84270.894 | BE21: =1000000000-AZ21-BA21-BB21-BC21-BD21 -> 9.2567528e+08 | BF21: 238 | BG21: =BE21/1000000-BF21 -> 687.67528 | BH21: =BE21*27.24 -> 2.5215395e+10
A22: 45644 | B22: 8540539048 | D22: 472394527 | S22: 0.03 | AJ22: =IF(OR(B22="",B22=0,N22=""),"",N22/B22*10000) | AK22: =IF(OR(C22="",C22=0),"",O22/C22*10000) | AL22: =IF(OR(D22="",D22=0),"",P22/D22*10000) -> 0 | AM22: =IF(OR(E22="",E22=0),"",Q22/E22*10000) | AT22: 10927485 | AU22: 0 | AV22: 2263.4293 | AY22: =IF(OR(AX22="",AX22=0,AU22=""),"",AU22*365/(AX22*1000000)) | AZ22: 0 | BA22: 60480066 | BB22: 10927485 | BC22: 2971324 | BD22: =1000000000-999913465.6766+0 -> 86534.323 | BE22: =1000000000-AZ22-BA22-BB22-BC22-BD22 -> 9.2553459e+08 | BF22: 238 | BG22: =BE22/1000000-BF22 -> 687.53459 | BH22: =BE22*25.57 -> 2.3665919e+10
A23: 45645 | B23: 11512982470 | D23: 564194362 | S23: 0.03 | AJ23: =IF(OR(B23="",B23=0,N23=""),"",N23/B23*10000) | AK23: =IF(OR(C23="",C23=0),"",O23/C23*10000) | AL23: =IF(OR(D23="",D23=0),"",P23/D23*10000) -> 0 | AM23: =IF(OR(E23="",E23=0),"",Q23/E23*10000) | AT23: 11039806 | AU23: 0 | AV23: 2427.0823 | AY23: =IF(OR(AX23="",AX23=0,AU23=""),"",AU23*365/(AX23*1000000)) | AZ23: 0 | BA23: 60480066 | BB23: 11039806 | BC23: 2971324 | BD23: =1000000000-999911038.5943+0 -> 88961.406 | BE23: =1000000000-AZ23-BA23-BB23-BC23-BD23 -> 9.2541984e+08 | BF23: 238 | BG23: =BE23/1000000-BF23 -> 687.41984 | BH23: =BE23*23.22 -> 2.1488249e+10
A24: 45646 | B24: 9878521131 | D24: 703781781 | S24: 0.03 | AJ24: =IF(OR(B24="",B24=0,N24=""),"",N24/B24*10000) | AK24: =IF(OR(C24="",C24=0),"",O24/C24*10000) | AL24: =IF(OR(D24="",D24=0),"",P24/D24*10000) -> 0 | AM24: =IF(OR(E24="",E24=0),"",Q24/E24*10000) | AT24: 11180484 | AU24: 0 | AV24: 2863.6836 | AY24: =IF(OR(AX24="",AX24=0,AU24=""),"",AU24*365/(AX24*1000000)) | AZ24: 0 | BA24: 60480066 | BB24: 11180484 | BC24: 2971324 | BD24: =1000000000-999908174.9107+0 -> 91825.089 | BE24: =1000000000-AZ24-BA24-BB24-BC24-BD24 -> 9.252763e+08 | BF24: 238 | BG24: =BE24/1000000-BF24 -> 687.2763 | BH24: =BE24*24.92 -> 2.3057885e+10
A25: 45647 | B25: 5203028237 | D25: 527191283 | S25: 0.03 | AJ25: =IF(OR(B25="",B25=0,N25=""),"",N25/B25*10000) | AK25: =IF(OR(C25="",C25=0),"",O25/C25*10000) | AL25: =IF(OR(D25="",D25=0),"",P25/D25*10000) -> 0 | AM25: =IF(OR(E25="",E25=0),"",Q25/E25*10000) | AT25: 11244814 | AU25: 0 | AV25: 3033.9608 | AY25: =IF(OR(AX25="",AX25=0,AU25=""),"",AU25*365/(AX25*1000000)) | AZ25: 0 | BA25: 60480066 | BB25: 11244814 | BC25: 2971324 | BD25: =1000000000-999905140.9499+0 -> 94859.05 | BE25: =1000000000-AZ25-BA25-BB25-BC25-BD25 -> 9.2520894e+08 | BF25: 238 | BG25: =BE25/1000000-BF25 -> 687.20894 | BH25: =BE25*29.74 -> 2.7515714e+10
A26: 45648 | B26: 4686731738 | D26: 471634786 | S26: 0.03 | AJ26: =IF(OR(B26="",B26=0,N26=""),"",N26/B26*10000) | AK26: =IF(OR(C26="",C26=0),"",O26/C26*10000) | AL26: =IF(OR(D26="",D26=0),"",P26/D26*10000) -> 0 | AM26: =IF(OR(E26="",E26=0),"",Q26/E26*10000) | AT26: 11290999 | AU26: 0 | AV26: 2044.5791 | AY26: =IF(OR(AX26="",AX26=0,AU26=""),"",AU26*365/(AX26*1000000)) | AZ26: 0 | BA26: 60480066 | BB26: 11290999 | BC26: 2971324 | BD26: =1000000000-999903096.3708+0 -> 96903.629 | BE26: =1000000000-AZ26-BA26-BB26-BC26-BD26 -> 9.2516071e+08 | BF26: 238 | BG26: =BE26/1000000-BF26 -> 687.16071 | BH26: =BE26*32.02 -> 2.9623646e+10
A27: 45649 | B27: 6168463522 | D27: 375034673 | P27: 96254 | R27: =N27+O27+P27+N(Q27) -> 96254 | S27: 0.03 | T27: =N(AC27)*S27 -> 0 | U27: =N(AD27)*S27 -> 0 | V27: =N(AE27)*S27 -> 2887.62 | W27: =IF(Q27="","",N(AF27)*S27) | X27: 0 | AA27: =T27+U27+V27+N(W27)+X27+Y27+N(Z27) -> 2887.62 | AD27: =O27-Y27 -> 0 | AE27: =P27-X27 -> 96254 | AF27: =IF(Q27="","",Q27-Z27) | AG27: =AC27+AD27+AE27+N(AF27) -> 96254 | AH27: 1424462 | AI27: =AG27-AH27 -> -1328208 | AJ27: =IF(OR(B27="",B27=0,N27=""),"",N27/B27*10000) | AK27: =IF(OR(C27="",C27=0),"",O27/C27*10000) | AL27: =IF(OR(D27="",D27=0),"",P27/D27*10000) -> 2.566536 | AM27: =IF(OR(E27="",E27=0),"",Q27/E27*10000) | AN27: 0 | AO27: 0 | AP27: =AH27+AN27+AO27 -> 1424462 | AQ27: =AH27 -> 1424462 | AR27: 55522.13 | AS27: 28.47 | AT27: 11346521 | AU27: 0 | AV27: 2041.5641 | AY27: =IF(OR(AX27="",AX27=0,AU27=""),"",AU27*365/(AX27*1000000)) | AZ27: 0 | BA27: 60480066 | BB27: 11346521 | BC27: 2971324 | BD27: =1000000000-999901054.8066+0 -> 98945.193 | BE27: =1000000000-AZ27-BA27-BB27-BC27-BD27 -> 9.2510314e+08 | BF27: 238 | BG27: =BE27/1000000-BF27 -> 687.10314 | BH27: =BE27*28.47 -> 2.6337686e+10
A28: 45650 | B28: 4401565233 | D28: 319403848 | P28: 47315 | R28: =N28+O28+P28+N(Q28) -> 47315 | S28: 0.03 | T28: =N(AC28)*S28 -> 0 | U28: =N(AD28)*S28 -> 0 | V28: =N(AE28)*S28 -> 1419.45 | W28: =IF(Q28="","",N(AF28)*S28) | X28: 0 | AA28: =T28+U28+V28+N(W28)+X28+Y28+N(Z28) -> 1419.45 | AD28: =O28-Y28 -> 0 | AE28: =P28-X28 -> 47315 | AF28: =IF(Q28="","",Q28-Z28) | AG28: =AC28+AD28+AE28+N(AF28) -> 47315 | AH28: 1303665 | AI28: =AG28-AH28 -> -1256350 | AJ28: =IF(OR(B28="",B28=0,N28=""),"",N28/B28*10000) | AK28: =IF(OR(C28="",C28=0),"",O28/C28*10000) | AL28: =IF(OR(D28="",D28=0),"",P28/D28*10000) -> 1.4813535 | AM28: =IF(OR(E28="",E28=0),"",Q28/E28*10000) | AN28: 0 | AO28: 0 | AP28: =AH28+AN28+AO28 -> 1303665 | AQ28: =AH28 -> 1303665 | AR28: 49941.64 | AS28: 28.6 | AT28: 11396463 | AU28: 0 | AV28: 3190.5125 | AY28: =IF(OR(AX28="",AX28=0,AU28=""),"",AU28*365/(AX28*1000000)) | AZ28: 0 | BA28: 60480066 | BB28: 11396463 | BC28: 2971324 | BD28: =1000000000-999897864.2941+0 -> 102135.71 | BE28: =1000000000-AZ28-BA28-BB28-BC28-BD28 -> 9.2505001e+08 | BF28: 238 | BG28: =BE28/1000000-BF28 -> 687.05001 | BH28: =BE28*28.6 -> 2.645643e+10
A29: 45651 | B29: 3090026720 | D29: 310480616 | P29: 43561 | R29: =N29+O29+P29+N(Q29) -> 43561 | S29: 0.03 | T29: =N(AC29)*S29 -> 0 | U29: =N(AD29)*S29 -> 0 | V29: =N(AE29)*S29 -> 1306.83 | W29: =IF(Q29="","",N(AF29)*S29) | X29: 0 | AA29: =T29+U29+V29+N(W29)+X29+Y29+N(Z29) -> 1306.83 | AD29: =O29-Y29 -> 0 | AE29: =P29-X29 -> 43561 | AF29: =IF(Q29="","",Q29-Z29) | AG29: =AC29+AD29+AE29+N(AF29) -> 43561 | AH29: 1014518 | AI29: =AG29-AH29 -> -970957 | AJ29: =IF(OR(B29="",B29=0,N29=""),"",N29/B29*10000) | AK29: =IF(OR(C29="",C29=0),"",O29/C29*10000) | AL29: =IF(OR(D29="",D29=0),"",P29/D29*10000) -> 1.4030183 | AM29: =IF(OR(E29="",E29=0),"",Q29/E29*10000) | AN29: 0 | AO29: 0 | AP29: =AH29+AN29+AO29 -> 1014518 | AQ29: =AH29 -> 1014518 | AR29: 42906.81 | AS29: 29.78 | AT29: 11439370 | AU29: 0 | AV29: 1832.8323 | AY29: =IF(OR(AX29="",AX29=0,AU29=""),"",AU29*365/(AX29*1000000)) | AZ29: 0 | BA29: 60480066 | BB29: 11439370 | BC29: 2971324 | BD29: =1000000000-999896031.4618+0 -> 103968.54 | BE29: =1000000000-AZ29-BA29-BB29-BC29-BD29 -> 9.2500527e+08 | BF29: 238 | BG29: =BE29/1000000-BF29 -> 687.00527 | BH29: =BE29*29.78 -> 2.7546657e+10
A30: 45652 | B30: 3897465234 | D30: 214091088 | P30: 44254 | R30: =N30+O30+P30+N(Q30) -> 44254 | S30: 0.03 | T30: =N(AC30)*S30 -> 0 | U30: =N(AD30)*S30 -> 0 | V30: =N(AE30)*S30 -> 1327.62 | W30: =IF(Q30="","",N(AF30)*S30) | X30: 0 | AA30: =T30+U30+V30+N(W30)+X30+Y30+N(Z30) -> 1327.62 | AD30: =O30-Y30 -> 0 | AE30: =P30-X30 -> 44254 | AF30: =IF(Q30="","",Q30-Z30) | AG30: =AC30+AD30+AE30+N(AF30) -> 44254 | AH30: 1273897 | AI30: =AG30-AH30 -> -1229643 | AJ30: =IF(OR(B30="",B30=0,N30=""),"",N30/B30*10000) | AK30: =IF(OR(C30="",C30=0),"",O30/C30*10000) | AL30: =IF(OR(D30="",D30=0),"",P30/D30*10000) -> 2.0670641 | AM30: =IF(OR(E30="",E30=0),"",Q30/E30*10000) | AN30: 0 | AO30: 0 | AP30: =AH30+AN30+AO30 -> 1273897 | AQ30: =AH30 -> 1273897 | AR30: 28772.87 | AS30: 26.55 | AT30: 11468143 | AU30: 0 | AV30: 1373.0965 | AY30: =IF(OR(AX30="",AX30=0,AU30=""),"",AU30*365/(AX30*1000000)) | AZ30: 0 | BA30: 60480066 | BB30: 11468143 | BC30: 2971324 | BD30: =1000000000-999894658.3653+0 -> 105341.63 | BE30: =1000000000-AZ30-BA30-BB30-BC30-BD30 -> 9.2497513e+08 | BF30: 238 | BG30: =BE30/1000000-BF30 -> 686.97513 | BH30: =BE30*26.55 -> 2.455809e+10
A31: 45653 | B31: 3889473141 | D31: 216391282 | P31: 28523 | R31: =N31+O31+P31+N(Q31) -> 28523 | S31: 0.03 | T31: =N(AC31)*S31 -> 0 | U31: =N(AD31)*S31 -> 0 | V31: =N(AE31)*S31 -> 855.69 | W31: =IF(Q31="","",N(AF31)*S31) | X31: 0 | AA31: =T31+U31+V31+N(W31)+X31+Y31+N(Z31) -> 855.69 | AD31: =O31-Y31 -> 0 | AE31: =P31-X31 -> 28523 | AF31: =IF(Q31="","",Q31-Z31) | AG31: =AC31+AD31+AE31+N(AF31) -> 28523 | AH31: 1258520 | AI31: =AG31-AH31 -> -1229997 | AJ31: =IF(OR(B31="",B31=0,N31=""),"",N31/B31*10000) | AK31: =IF(OR(C31="",C31=0),"",O31/C31*10000) | AL31: =IF(OR(D31="",D31=0),"",P31/D31*10000) -> 1.3181215 | AM31: =IF(OR(E31="",E31=0),"",Q31/E31*10000) | AN31: 0 | AO31: 0 | AP31: =AH31+AN31+AO31 -> 1258520 | AQ31: =AH31 -> 1258520 | AR31: 45393.95 | AS31: 27.22 | AT31: 11513537 | AU31: 0 | AV31: 1476.4802 | AY31: =IF(OR(AX31="",AX31=0,AU31=""),"",AU31*365/(AX31*1000000)) | AZ31: 0 | BA31: 60480066 | BB31: 11513537 | BC31: 2971324 | BD31: =1000000000-999893181.8852+0 -> 106818.11 | BE31: =1000000000-AZ31-BA31-BB31-BC31-BD31 -> 9.2492826e+08 | BF31: 238 | BG31: =BE31/1000000-BF31 -> 686.92826 | BH31: =BE31*27.22 -> 2.5176547e+10
A32: 45654 | B32: 2077191362 | D32: 212391739 | P32: 28430 | R32: =N32+O32+P32+N(Q32) -> 28430 | S32: 0.03 | T32: =N(AC32)*S32 -> 0 | U32: =N(AD32)*S32 -> 0 | V32: =N(AE32)*S32 -> 852.9 | W32: =IF(Q32="","",N(AF32)*S32) | X32: 0 | AA32: =T32+U32+V32+N(W32)+X32+Y32+N(Z32) -> 852.9 | AD32: =O32-Y32 -> 0 | AE32: =P32-X32 -> 28430 | AF32: =IF(Q32="","",Q32-Z32) | AG32: =AC32+AD32+AE32+N(AF32) -> 28430 | AH32: 949315 | AI32: =AG32-AH32 -> -920885 | AJ32: =IF(OR(B32="",B32=0,N32=""),"",N32/B32*10000) | AK32: =IF(OR(C32="",C32=0),"",O32/C32*10000) | AL32: =IF(OR(D32="",D32=0),"",P32/D32*10000) -> 1.3385643 | AM32: =IF(OR(E32="",E32=0),"",Q32/E32*10000) | AN32: 0 | AO32: 0 | AP32: =AH32+AN32+AO32 -> 949315 | AQ32: =AH32 -> 949315 | AR32: 46697.63 | AS32: 27.11 | AT32: 11560234 | AU32: 0 | AV32: 1019.7076 | AX32: 301.00122 | AY32: =IF(OR(AX32="",AX32=0,AU32=""),"",AU32*365/(AX32*1000000)) -> 0 | AZ32: 0 | BA32: 60480066 | BB32: 11560234 | BC32: 2971324 | BD32: =1000000000-999892162.1776+0 -> 107837.82 | BE32: =1000000000-AZ32-BA32-BB32-BC32-BD32 -> 9.2488054e+08 | BF32: 238 | BG32: =BE32/1000000-BF32 -> 686.88054 | BH32: =BE32*27.11 -> 2.5073511e+10
A33: 45655 | B33: 1965931600 | D33: 342862746 | P33: 31496 | R33: =N33+O33+P33+N(Q33) -> 31496 | S33: 0.03 | T33: =N(AC33)*S33 -> 0 | U33: =N(AD33)*S33 -> 0 | V33: =N(AE33)*S33 -> 944.88 | W33: =IF(Q33="","",N(AF33)*S33) | X33: 0 | AA33: =T33+U33+V33+N(W33)+X33+Y33+N(Z33) -> 944.88 | AD33: =O33-Y33 -> 0 | AE33: =P33-X33 -> 31496 | AF33: =IF(Q33="","",Q33-Z33) | AG33: =AC33+AD33+AE33+N(AF33) -> 31496 | AH33: 471167 | AI33: =AG33-AH33 -> -439671 | AJ33: =IF(OR(B33="",B33=0,N33=""),"",N33/B33*10000) | AK33: =IF(OR(C33="",C33=0),"",O33/C33*10000) | AL33: =IF(OR(D33="",D33=0),"",P33/D33*10000) -> 0.91861832 | AM33: =IF(OR(E33="",E33=0),"",Q33/E33*10000) | AN33: 0 | AO33: 0 | AP33: =AH33+AN33+AO33 -> 471167 | AQ33: =AH33 -> 471167 | AR33: 33952.54 | AS33: 29.26 | AT33: 11594187 | AU33: 0 | AV33: 774.4857 | AX33: 301.02439 | AY33: =IF(OR(AX33="",AX33=0,AU33=""),"",AU33*365/(AX33*1000000)) -> 0 | AZ33: 4.2805004e+08 | BA33: 60480066 | BB33: 11594187 | BC33: 2971324 | BD33: =1000000000-999891387.692+0 -> 108612.31 | BE33: =1000000000-AZ33-BA33-BB33-BC33-BD33 -> 4.9679578e+08 | BF33: 238 | BG33: =BE33/1000000-BF33 -> 258.79578 | BH33: =BE33*29.26 -> 1.4536244e+10
A34: 45656 | B34: 4697171102 | D34: 267028183 | P34: 49113 | R34: =N34+O34+P34+N(Q34) -> 49113 | S34: 0.03 | T34: =N(AC34)*S34 -> 0 | U34: =N(AD34)*S34 -> 0 | V34: =N(AE34)*S34 -> 1473.39 | W34: =IF(Q34="","",N(AF34)*S34) | X34: 0 | AA34: =T34+U34+V34+N(W34)+X34+Y34+N(Z34) -> 1473.39 | AD34: =O34-Y34 -> 0 | AE34: =P34-X34 -> 49113 | AF34: =IF(Q34="","",Q34-Z34) | AG34: =AC34+AD34+AE34+N(AF34) -> 49113 | AH34: 1486794 | AI34: =AG34-AH34 -> -1437681 | AJ34: =IF(OR(B34="",B34=0,N34=""),"",N34/B34*10000) | AK34: =IF(OR(C34="",C34=0),"",O34/C34*10000) | AL34: =IF(OR(D34="",D34=0),"",P34/D34*10000) -> 1.8392441 | AM34: =IF(OR(E34="",E34=0),"",Q34/E34*10000) | AN34: 0 | AO34: 0 | AP34: =AH34+AN34+AO34 -> 1486794 | AQ34: =AH34 -> 1486794 | AR34: 32031.98 | AS34: 27.44 | AT34: 11626219 | AU34: 22225.362 | AV34: 611.8805 | AX34: 301.10728 | AY34: =IF(OR(AX34="",AX34=0,AU34=""),"",AU34*365/(AX34*1000000)) -> 0.026941419 | AZ34: 4.2802781e+08 | BA34: 60480066 | BB34: 11626219 | BC34: 2971324 | BD34: =1000000000-999890775.8115+0 -> 109224.19 | BE34: =1000000000-AZ34-BA34-BB34-BC34-BD34 -> 4.9678536e+08 | BF34: 238 | BG34: =BE34/1000000-BF34 -> 258.78536 | BH34: =BE34*27.44 -> 1.363179e+10
A35: 45657 | B35: 3450514508 | D35: 225503235 | P35: 42962 | R35: =N35+O35+P35+N(Q35) -> 42962 | S35: 0.03 | T35: =N(AC35)*S35 -> 0 | U35: =N(AD35)*S35 -> 0 | V35: =N(AE35)*S35 -> 1288.86 | W35: =IF(Q35="","",N(AF35)*S35) | X35: 0 | AA35: =T35+U35+V35+N(W35)+X35+Y35+N(Z35) -> 1288.86 | AD35: =O35-Y35 -> 0 | AE35: =P35-X35 -> 42962 | AF35: =IF(Q35="","",Q35-Z35) | AG35: =AC35+AD35+AE35+N(AF35) -> 42962 | AH35: 1327977 | AI35: =AG35-AH35 -> -1285015 | AJ35: =IF(OR(B35="",B35=0,N35=""),"",N35/B35*10000) | AK35: =IF(OR(C35="",C35=0),"",O35/C35*10000) | AL35: =IF(OR(D35="",D35=0),"",P35/D35*10000) -> 1.9051611 | AM35: =IF(OR(E35="",E35=0),"",Q35/E35*10000) | AN35: 0 | AO35: 0 | AP35: =AH35+AN35+AO35 -> 1327977 | AQ35: =AH35 -> 1327977 | AR35: 44578.73 | AS35: 26.95 | AT35: 11670797 | AU35: 23028.588 | AV35: 870.4787 | AX35: 352.79856 | AY35: =IF(OR(AX35="",AX35=0,AU35=""),"",AU35*365/(AX35*1000000)) -> 0.023825026 | AZ35: 4.2800478e+08 | BA35: 60480066 | BB35: 11670797 | BC35: 2971324 | BD35: =1000000000-999889905.3328+0 -> 110094.67 | BE35: =1000000000-AZ35-BA35-BB35-BC35-BD35 -> 4.9676294e+08 | BF35: 238 | BG35: =BE35/1000000-BF35 -> 258.76294 | BH35: =BE35*26.95 -> 1.3387761e+10
A36: 45658 | B36: 2157256818 | D36: 256438336 | P36: 30141 | R36: =N36+O36+P36+N(Q36) -> 30141 | S36: 0.03 | T36: =N(AC36)*S36 -> 0 | U36: =N(AD36)*S36 -> 0 | V36: =N(AE36)*S36 -> 904.23 | W36: =IF(Q36="","",N(AF36)*S36) | X36: 0 | AA36: =T36+U36+V36+N(W36)+X36+Y36+N(Z36) -> 904.23 | AD36: =O36-Y36 -> 0 | AE36: =P36-X36 -> 30141 | AF36: =IF(Q36="","",Q36-Z36) | AG36: =AC36+AD36+AE36+N(AF36) -> 30141 | AH36: 498037 | AI36: =AG36-AH36 -> -467896 | AJ36: =IF(OR(B36="",B36=0,N36=""),"",N36/B36*10000) | AK36: =IF(OR(C36="",C36=0),"",O36/C36*10000) | AL36: =IF(OR(D36="",D36=0),"",P36/D36*10000) -> 1.1753703 | AM36: =IF(OR(E36="",E36=0),"",Q36/E36*10000) | AN36: 0 | AO36: 0 | AP36: =AH36+AN36+AO36 -> 498037 | AQ36: =AH36 -> 498037 | AR36: 48753.47 | AS36: 24 | AT36: 11719551 | AU36: 24499.354 | AV36: 941.1022 | AX36: 372.98553 | AY36: =IF(OR(AX36="",AX36=0,AU36=""),"",AU36*365/(AX36*1000000)) -> 0.023974828 | AZ36: 4.2798028e+08 | BA36: 60480066 | BB36: 11719551 | BC36: 2971324 | BD36: =1000000000-999888964.2307+0 -> 111035.77 | BE36: =1000000000-AZ36-BA36-BB36-BC36-BD36 -> 4.9673774e+08 | BF36: 238 | BG36: =BE36/1000000-BF36 -> 258.73774 | BH36: =BE36*24 -> 1.1921706e+10
A37: 45659 | B37: 3645816159 | D37: 267239456 | P37: 41666 | R37: =N37+O37+P37+N(Q37) -> 41666 | S37: 0.03 | T37: =N(AC37)*S37 -> 0 | U37: =N(AD37)*S37 -> 0 | V37: =N(AE37)*S37 -> 1249.98 | W37: =IF(Q37="","",N(AF37)*S37) | X37: 0 | AA37: =T37+U37+V37+N(W37)+X37+Y37+N(Z37) -> 1249.98 | AD37: =O37-Y37 -> 0 | AE37: =P37-X37 -> 41666 | AF37: =IF(Q37="","",Q37-Z37) | AG37: =AC37+AD37+AE37+N(AF37) -> 41666 | AH37: 1270220 | AI37: =AG37-AH37 -> -1228554 | AJ37: =IF(OR(B37="",B37=0,N37=""),"",N37/B37*10000) | AK37: =IF(OR(C37="",C37=0),"",O37/C37*10000) | AL37: =IF(OR(D37="",D37=0),"",P37/D37*10000) -> 1.5591261 | AM37: =IF(OR(E37="",E37=0),"",Q37/E37*10000) | AN37: 0 | AO37: 0 | AP37: =AH37+AN37+AO37 -> 1270220 | AQ37: =AH37 -> 1270220 | AR37: 37230.03 | AS37: 26.31 | AT37: 11756781 | AU37: 24851.902 | AV37: 920.9016 | AX37: 380.75278 | AY37: =IF(OR(AX37="",AX37=0,AU37=""),"",AU37*365/(AX37*1000000)) -> 0.023823711 | AZ37: 4.2795543e+08 | BA37: 60480066 | BB37: 11756781 | BC37: 2971324 | BD37: =1000000000-999888043.3291+0 -> 111956.67 | BE37: =1000000000-AZ37-BA37-BB37-BC37-BD37 -> 4.9672444e+08 | BF37: 238 | BG37: =BE37/1000000-BF37 -> 258.72444 | BH37: =BE37*26.31 -> 1.306882e+10
A38: 45660 | B38: 3573160271 | D38: 176550030 | P38: 37005 | R38: =N38+O38+P38+N(Q38) -> 37005 | S38: 0.03 | T38: =N(AC38)*S38 -> 0 | U38: =N(AD38)*S38 -> 0 | V38: =N(AE38)*S38 -> 1110.15 | W38: =IF(Q38="","",N(AF38)*S38) | X38: 0 | AA38: =T38+U38+V38+N(W38)+X38+Y38+N(Z38) -> 1110.15 | AD38: =O38-Y38 -> 0 | AE38: =P38-X38 -> 37005 | AF38: =IF(Q38="","",Q38-Z38) | AG38: =AC38+AD38+AE38+N(AF38) -> 37005 | AH38: 1369500 | AI38: =AG38-AH38 -> -1332495 | AJ38: =IF(OR(B38="",B38=0,N38=""),"",N38/B38*10000) | AK38: =IF(OR(C38="",C38=0),"",O38/C38*10000) | AL38: =IF(OR(D38="",D38=0),"",P38/D38*10000) -> 2.0960064 | AM38: =IF(OR(E38="",E38=0),"",Q38/E38*10000) | AN38: 0 | AO38: 0 | AP38: =AH38+AN38+AO38 -> 1369500 | AQ38: =AH38 -> 1369500 | AR38: 55732.01 | AS38: 23.15 | AT38: 11812513 | AU38: 25219.868 | AV38: 905.5316 | AX38: 390.38936 | AY38: =IF(OR(AX38="",AX38=0,AU38=""),"",AU38*365/(AX38*1000000)) -> 0.023579669 | AZ38: 4.2793021e+08 | BA38: 60480066 | BB38: 11812513 | BC38: 2971324 | BD38: =1000000000-999887137.7975+0 -> 112862.2 | BE38: =1000000000-AZ38-BA38-BB38-BC38-BD38 -> 4.9669302e+08 | BF38: 238 | BG38: =BE38/1000000-BF38 -> 258.69302 | BH38: =BE38*23.15 -> 1.1498444e+10
A39: 45661 | B39: 2506267603 | D39: 119410641 | P39: 25377 | R39: =N39+O39+P39+N(Q39) -> 25377 | S39: 0.03 | T39: =N(AC39)*S39 -> 0 | U39: =N(AD39)*S39 -> 0 | V39: =N(AE39)*S39 -> 761.31 | W39: =IF(Q39="","",N(AF39)*S39) | X39: 0 | AA39: =T39+U39+V39+N(W39)+X39+Y39+N(Z39) -> 761.31 | AD39: =O39-Y39 -> 0 | AE39: =P39-X39 -> 25377 | AF39: =IF(Q39="","",Q39-Z39) | AG39: =AC39+AD39+AE39+N(AF39) -> 25377 | AH39: 1042972 | AI39: =AG39-AH39 -> -1017595 | AJ39: =IF(OR(B39="",B39=0,N39=""),"",N39/B39*10000) | AK39: =IF(OR(C39="",C39=0),"",O39/C39*10000) | AL39: =IF(OR(D39="",D39=0),"",P39/D39*10000) -> 2.1251875 | AM39: =IF(OR(E39="",E39=0),"",Q39/E39*10000) | AN39: 0 | AO39: 0 | AP39: =AH39+AN39+AO39 -> 1042972 | AQ39: =AH39 -> 1042972 | AR39: 34281.41 | AS39: 24.43 | AT39: 11846794 | AU39: 25452.778 | AV39: 1232.8801 | AX39: 395.40416 | AY39: =IF(OR(AX39="",AX39=0,AU39=""),"",AU39*365/(AX39*1000000)) -> 0.023495615 | AZ39: 4.2790476e+08 | BA39: 60480066 | BB39: 11846794 | BC39: 2971324 | BD39: =1000000000-999885904.9174+0 -> 114095.08 | BE39: =1000000000-AZ39-BA39-BB39-BC39-BD39 -> 4.9668296e+08 | BF39: 238 | BG39: =BE39/1000000-BF39 -> 258.68296 | BH39: =BE39*24.43 -> 1.2133965e+10
A40: 45662 | B40: 2149149006 | D40: 174388254 | P40: 19262 | R40: =N40+O40+P40+N(Q40) -> 19262 | S40: 0.03 | T40: =N(AC40)*S40 -> 0 | U40: =N(AD40)*S40 -> 0 | V40: =N(AE40)*S40 -> 577.86 | W40: =IF(Q40="","",N(AF40)*S40) | X40: 0 | AA40: =T40+U40+V40+N(W40)+X40+Y40+N(Z40) -> 577.86 | AD40: =O40-Y40 -> 0 | AE40: =P40-X40 -> 19262 | AF40: =IF(Q40="","",Q40-Z40) | AG40: =AC40+AD40+AE40+N(AF40) -> 19262 | AH40: 985187 | AI40: =AG40-AH40 -> -965925 | AJ40: =IF(OR(B40="",B40=0,N40=""),"",N40/B40*10000) | AK40: =IF(OR(C40="",C40=0),"",O40/C40*10000) | AL40: =IF(OR(D40="",D40=0),"",P40/D40*10000) -> 1.1045469 | AM40: =IF(OR(E40="",E40=0),"",Q40/E40*10000) | AN40: 0 | AO40: 0 | AP40: =AH40+AN40+AO40 -> 985187 | AQ40: =AH40 -> 985187 | AR40: 42553.47 | AS40: 25.02 | AT40: 11889348 | AU40: 25665.111 | AV40: 617.3145 | AX40: 401.89251 | AY40: =IF(OR(AX40="",AX40=0,AU40=""),"",AU40*365/(AX40*1000000)) -> 0.023309132 | AZ40: 4.2787909e+08 | BA40: 60480066 | BB40: 11889348 | BC40: 2971324 | BD40: =1000000000-999885287.603+0 -> 114712.4 | BE40: =1000000000-AZ40-BA40-BB40-BC40-BD40 -> 4.9666546e+08 | BF40: 238 | BG40: =BE40/1000000-BF40 -> 258.66546 | BH40: =BE40*25.02 -> 1.242657e+10
...

Sheet Quarterly 
A1: HYPERLIQUID (HYPE) — QUARTERLY. Same columns as Daily. Flows summed (SUMIFS); stocks/rates at period-end; OTS at quarter-end.
D2: VOLUME ($) | H2: HIP-3 VOLUME BY CATEGORY ($) | P2: GROSS FEES ($) [user-paid] | U2: FEE → REVENUE BRIDGE [deductions, $] | AE2: REVENUE TO HYPERCORE ($) | AL2: IMPLIED TAKE-RATE (bps) | AP2: OTHER REVENUE ($) | AS2: ASSISTANCE FUND & SUPPLY | BB2: OTS (Hyperliquid Strategies basis)
A3: Quarter | B3: Start | C3: End | D3: Core Crypto Perp Vol ($) | E3: HIP-3 Perp Vol ($) | F3: Spot Vol ($) | G3: HIP-4 Vol ($) | H3: HIP-3 Commodities ($) | I3: HIP-3 Crypto ($) | J3: HIP-3 FX ($) | K3: HIP-3 Indices ($) | L3: HIP-3 Pre-IPO ($) | M3: HIP-3 Equities ($) | N3: HIP-3 Cat Total ($) | O3: Pro-rate Factor Applied | P3: Core Crypto Perp Fees ($) | Q3: HIP-3 Gross Fees ($) | R3: Spot Fees incl Unit ($) | S3: HIP-4 Fees ($) | T3: Total Gross Fees ($) | U3: HLP Rate | V3: (-) HLP on Core Perp ($) | W3: (-) HLP on HIP-3 ($) | X3: (-) HLP on Spot ($) | Y3: (-) HLP on HIP-4 ($) | Z3: (-) Unit Protocol Fees ($) | AA3: (-) HIP-3 Deployer Fees ($) | AB3: (-) HIP-4 Deployer Fees ($) | AC3: Total Deductions ($) | AD3: Builder Code Fees [on-top, not deducted] ($) | AE3: Core Crypto Perp Revenue ($) | AF3: HIP-3 Revenue ($) | AG3: Spot Revenue ($) | AH3: HIP-4 Revenue ($) | AI3: = HyperCore Revenue (model) ($) | AJ3: HyperCore Revenue ($) | AK3: Accrual less Buyback ($) | AL3: Core Perp Take-Rate (bps) | AM3: HIP-3 Take-Rate (bps) | AN3: Spot Take-Rate (bps) | AO3: HIP-4 Take-Rate (bps) | AP3: HyperEVM Burn ($) | AQ3: Auction Burn ($) | AR3: Total Revenue ($) | AS3: Revenue -> AF ($) | AT3: Buyback HYPE | AU3: Buyback Avg Price ($) | AV3: AF HYPE Balance | AW3: Staking Emissions (HYPE) | AX3: Fee Burn (HYPE) | AY3: Team Tokens Unlocked (HYPE) | AZ3: HYPE Staked (M) | BA3: Implied Staking Yield | BB3: (-) Future Emissions & CR (HYPE) | BC3: (-) Hyper Foundation (HYPE) | BD3: (-) Assistance Fund (HYPE) | BE3: (-) Community Grants (HYPE) | BF3: (-) HC&EVM Fee Burns (HYPE) | BG3: = OTS (HYPE) | BH3: Core Contributors Locked (M) | BI3: Circulating Token Supply (M) | BJ3: OTS Value ($)
A4: Q4 2024 (Nov-Dec) | B4: 45626 | C4: 45657 | D4: =SUMIFS('Daily '!$B$4:$B$662,'Daily '!$A$4:$A$662,">="&$B4,'Daily '!$A$4:$A$662,"<="&$C4) -> 164982084997 | E4: =SUMIFS('Daily '!$C$4:$C$662,'Daily '!$A$4:$A$662,">="&$B4,'Daily '!$A$4:$A$662,"<="&$C4) -> 0 | F4: =SUMIFS('Daily '!$D$4:$D$662,'Daily '!$A$4:$A$662,">="&$B4,'Daily '!$A$4:$A$662,"<="&$C4) -> 11366603254 | G4: =SUMIFS('Daily '!$E$4:$E$662,'Daily '!$A$4:$A$662,">="&$B4,'Daily '!$A$4:$A$662,"<="&$C4) -> 0 | H4: =SUMIFS('Daily '!$F$4:$F$662,'Daily '!$A$4:$A$662,">="&$B4,'Daily '!$A$4:$A$662,"<="&$C4) -> 0 | I4: =SUMIFS('Daily '!$G$4:$G$662,'Daily '!$A$4:$A$662,">="&$B4,'Daily '!$A$4:$A$662,"<="&$C4) -> 0 | J4: =SUMIFS('Daily '!$H$4:$H$662,'Daily '!$A$4:$A$662,">="&$B4,'Daily '!$A$4:$A$662,"<="&$C4) -> 0 | K4: =SUMIFS('Daily '!$I$4:$I$662,'Daily '!$A$4:$A$662,">="&$B4,'Daily '!$A$4:$A$662,"<="&$C4) -> 0 | L4: =SUMIFS('Daily '!$J$4:$J$662,'Daily '!$A$4:$A$662,">="&$B4,'Daily '!$A$4:$A$662,"<="&$C4) -> 0 | M4: =SUMIFS('Daily '!$K$4:$K$662,'Daily '!$A$4:$A$662,">="&$B4,'Daily '!$A$4:$A$662,"<="&$C4) -> 0 | N4: =SUMIFS('Daily '!$L$4:$L$662,'Daily '!$A$4:$A$662,">="&$B4,'Daily '!$A$4:$A$662,"<="&$C4) -> 0 | O4: =IF(E4=0,"",N4/E4) | P4: =SUMIFS('Daily '!$N$4:$N$662,'Daily '!$A$4:$A$662,">="&$B4,'Daily '!$A$4:$A$662,"<="&$C4) -> 0 | Q4: =SUMIFS('Daily '!$O$4:$O$662,'Daily '!$A$4:$A$662,">="&$B4,'Daily '!$A$4:$A$662,"<="&$C4) -> 0 | R4: =SUMIFS('Daily '!$P$4:$P$662,'Daily '!$A$4:$A$662,">="&$B4,'Daily '!$A$4:$A$662,"<="&$C4) -> 411908 | S4: =SUMIFS('Daily '!$Q$4:$Q$662,'Daily '!$A$4:$A$662,">="&$B4,'Daily '!$A$4:$A$662,"<="&$C4) -> 0 | T4: =SUMIFS('Daily '!$R$4:$R$662,'Daily '!$A$4:$A$662,">="&$B4,'Daily '!$A$4:$A$662,"<="&$C4) -> 411908 | V4: =SUMIFS('Daily '!$T$4:$T$662,'Daily '!$A$4:$A$662,">="&$B4,'Daily '!$A$4:$A$662,"<="&$C4) -> 0 | W4: =SUMIFS('Daily '!$U$4:$U$662,'Daily '!$A$4:$A$662,">="&$B4,'Daily '!$A$4:$A$662,"<="&$C4) -> 0 | X4: =SUMIFS('Daily '!$V$4:$V$662,'Daily '!$A$4:$A$662,">="&$B4,'Daily '!$A$4:$A$662,"<="&$C4) -> 12357.24 | Y4: =SUMIFS('Daily '!$W$4:$W$662,'Daily '!$A$4:$A$662,">="&$B4,'Daily '!$A$4:$A$662,"<="&$C4) -> 0 | Z4: =SUMIFS('Daily '!$X$4:$X$662,'Daily '!$A$4:$A$662,">="&$B4,'Daily '!$A$4:$A$662,"<="&$C4) -> 0 | AA4: =SUMIFS('Daily '!$Y$4:$Y$662,'Daily '!$A$4:$A$662,">="&$B4,'Daily '!$A$4:$A$662,"<="&$C4) -> 0 | AB4: =SUMIFS('Daily '!$Z$4:$Z$662,'Daily '!$A$4:$A$662,">="&$B4,'Daily '!$A$4:$A$662,"<="&$C4) -> 0 | AC4: =SUMIFS('Daily '!$AA$4:$AA$662,'Daily '!$A$4:$A$662,">="&$B4,'Daily '!$A$4:$A$662,"<="&$C4) -> 12357.24 | AD4: =SUMIFS('Daily '!$AB$4:$AB$662,'Daily '!$A$4:$A$662,">="&$B4,'Daily '!$A$4:$A$662,"<="&$C4) -> 0 | AE4: =SUMIFS('Daily '!$AC$4:$AC$662,'Daily '!$A$4:$A$662,">="&$B4,'Daily '!$A$4:$A$662,"<="&$C4) -> 0 | AF4: =SUMIFS('Daily '!$AD$4:$AD$662,'Daily '!$A$4:$A$662,">="&$B4,'Daily '!$A$4:$A$662,"<="&$C4) -> 0 | AG4: =SUMIFS('Daily '!$AE$4:$AE$662,'Daily '!$A$4:$A$662,">="&$B4,'Daily '!$A$4:$A$662,"<="&$C4) -> 411908 | AH4: =SUMIFS('Daily '!$AF$4:$AF$662,'Daily '!$A$4:$A$662,">="&$B4,'Daily '!$A$4:$A$662,"<="&$C4) -> 0 | AI4: =SUMIFS('Daily '!$AG$4:$AG$662,'Daily '!$A$4:$A$662,">="&$B4,'Daily '!$A$4:$A$662,"<="&$C4) -> 411908 | AJ4: =SUMIFS('Daily '!$AH$4:$AH$662,'Daily '!$A$4:$A$662,">="&$B4,'Daily '!$A$4:$A$662,"<="&$C4) -> 10510315 | AK4: =AI4-AJ4 -> -10098407 | AL4: =IF(D4=0,"",P4/D4*10000) -> 0 | AM4: =IF(E4=0,"",Q4/E4*10000) | AN4: =IF(F4=0,"",R4/F4*10000) -> 0.36238443 | AO4: =IF(G4=0,"",S4/G4*10000) | AP4: =SUMIFS('Daily '!$AN$4:$AN$662,'Daily '!$A$4:$A$662,">="&$B4,'Daily '!$A$4:$A$662,"<="&$C4) -> 0 | AQ4: =SUMIFS('Daily '!$AO$4:$AO$662,'Daily '!$A$4:$A$662,">="&$B4,'Daily '!$A$4:$A$662,"<="&$C4) -> 0 | AR4: =SUMIFS('Daily '!$AP$4:$AP$662,'Daily '!$A$4:$A$662,">="&$B4,'Daily '!$A$4:$A$662,"<="&$C4) -> 10510315 | AS4: =SUMIFS('Daily '!$AQ$4:$AQ$662,'Daily '!$A$4:$A$662,">="&$B4,'Daily '!$A$4:$A$662,"<="&$C4) -> 10510315 | AT4: =SUMIFS('Daily '!$AR$4:$AR$662,'Daily '!$A$4:$A$662,">="&$B4,'Daily '!$A$4:$A$662,"<="&$C4) -> 379798.28 | AU4: =IF(AT4=0,"",AS4/AT4) -> 27.673414 | AV4: 11670797 | AW4: =SUMIFS('Daily '!$AU$4:$AU$662,'Daily '!$A$4:$A$662,">="&$B4,'Daily '!$A$4:$A$662,"<="&$C4) -> 45253.951 | AX4: =SUMIFS('Daily '!$AV$4:$AV$662,'Daily '!$A$4:$A$662,">="&$B4,'Daily '!$A$4:$A$662,"<="&$C4) -> 110094.67 | AY4: =SUMIFS('Daily '!$AW$4:$AW$662,'Daily '!$A$4:$A$662,">="&$B4,'Daily '!$A$4:$A$662,"<="&$C4) -> 0 | AZ4: 352.7986 | BA4: 0.0127 | BB4: 4.2800478e+08 | BC4: 60480066 | BD4: 11670797 | BE4: 2971324 | BF4: 110094.67 | BG4: 4.9676294e+08 | BH4: 238 | BI4: 258.7629 | BJ4: 1.3387761e+10
A5: Q1 2025 | B5: 45658 | C5: 45747 | D5: =SUMIFS('Daily '!$B$4:$B$662,'Daily '!$A$4:$A$662,">="&$B5,'Daily '!$A$4:$A$662,"<="&$C5) -> 554802601520 | E5: =SUMIFS('Daily '!$C$4:$C$662,'Daily '!$A$4:$A$662,">="&$B5,'Daily '!$A$4:$A$662,"<="&$C5) -> 0 | F5: =SUMIFS('Daily '!$D$4:$D$662,'Daily '!$A$4:$A$662,">="&$B5,'Daily '!$A$4:$A$662,"<="&$C5) -> 15849231942 | G5: =SUMIFS('Daily '!$E$4:$E$662,'Daily '!$A$4:$A$662,">="&$B5,'Daily '!$A$4:$A$662,"<="&$C5) -> 0 | H5: =SUMIFS('Daily '!$F$4:$F$662,'Daily '!$A$4:$A$662,">="&$B5,'Daily '!$A$4:$A$662,"<="&$C5) -> 0 | I5: =SUMIFS('Daily '!$G$4:$G$662,'Daily '!$A$4:$A$662,">="&$B5,'Daily '!$A$4:$A$662,"<="&$C5) -> 0 | J5: =SUMIFS('Daily '!$H$4:$H$662,'Daily '!$A$4:$A$662,">="&$B5,'Daily '!$A$4:$A$662,"<="&$C5) -> 0 | K5: =SUMIFS('Daily '!$I$4:$I$662,'Daily '!$A$4:$A$662,">="&$B5,'Daily '!$A$4:$A$662,"<="&$C5) -> 0 | L5: =SUMIFS('Daily '!$J$4:$J$662,'Daily '!$A$4:$A$662,">="&$B5,'Daily '!$A$4:$A$662,"<="&$C5) -> 0 | M5: =SUMIFS('Daily '!$K$4:$K$662,'Daily '!$A$4:$A$662,">="&$B5,'Daily '!$A$4:$A$662,"<="&$C5) -> 0 | N5: =SUMIFS('Daily '!$L$4:$L$662,'Daily '!$A$4:$A$662,">="&$B5,'Daily '!$A$4:$A$662,"<="&$C5) -> 0 | O5: =IF(E5=0,"",N5/E5) | P5: =SUMIFS('Daily '!$N$4:$N$662,'Daily '!$A$4:$A$662,">="&$B5,'Daily '!$A$4:$A$662,"<="&$C5) -> 0 | Q5: =SUMIFS('Daily '!$O$4:$O$662,'Daily '!$A$4:$A$662,">="&$B5,'Daily '!$A$4:$A$662,"<="&$C5) -> 0 | R5: =SUMIFS('Daily '!$P$4:$P$662,'Daily '!$A$4:$A$662,">="&$B5,'Daily '!$A$4:$A$662,"<="&$C5) -> 2254941 | S5: =SUMIFS('Daily '!$Q$4:$Q$662,'Daily '!$A$4:$A$662,">="&$B5,'Daily '!$A$4:$A$662,"<="&$C5) -> 0 | T5: =SUMIFS('Daily '!$R$4:$R$662,'Daily '!$A$4:$A$662,">="&$B5,'Daily '!$A$4:$A$662,"<="&$C5) -> 2254941 | V5: =SUMIFS('Daily '!$T$4:$T$662,'Daily '!$A$4:$A$662,">="&$B5,'Daily '!$A$4:$A$662,"<="&$C5) -> 0 | W5: =SUMIFS('Daily '!$U$4:$U$662,'Daily '!$A$4:$A$662,">="&$B5,'Daily '!$A$4:$A$662,"<="&$C5) -> 0 | X5: =SUMIFS('Daily '!$V$4:$V$662,'Daily '!$A$4:$A$662,">="&$B5,'Daily '!$A$4:$A$662,"<="&$C5) -> 67648.23 | Y5: =SUMIFS('Daily '!$W$4:$W$662,'Daily '!$A$4:$A$662,">="&$B5,'Daily '!$A$4:$A$662,"<="&$C5) -> 0 | Z5: =SUMIFS('Daily '!$X$4:$X$662,'Daily '!$A$4:$A$662,">="&$B5,'Daily '!$A$4:$A$662,"<="&$C5) -> 0 | AA5: =SUMIFS('Daily '!$Y$4:$Y$662,'Daily '!$A$4:$A$662,">="&$B5,'Daily '!$A$4:$A$662,"<="&$C5) -> 0 | AB5: =SUMIFS('Daily '!$Z$4:$Z$662,'Daily '!$A$4:$A$662,">="&$B5,'Daily '!$A$4:$A$662,"<="&$C5) -> 0 | AC5: =SUMIFS('Daily '!$AA$4:$AA$662,'Daily '!$A$4:$A$662,">="&$B5,'Daily '!$A$4:$A$662,"<="&$C5) -> 67648.23 | AD5: =SUMIFS('Daily '!$AB$4:$AB$662,'Daily '!$A$4:$A$662,">="&$B5,'Daily '!$A$4:$A$662,"<="&$C5) -> 0 | AE5: =SUMIFS('Daily '!$AC$4:$AC$662,'Daily '!$A$4:$A$662,">="&$B5,'Daily '!$A$4:$A$662,"<="&$C5) -> 0 | AF5: =SUMIFS('Daily '!$AD$4:$AD$662,'Daily '!$A$4:$A$662,">="&$B5,'Daily '!$A$4:$A$662,"<="&$C5) -> 0 | AG5: =SUMIFS('Daily '!$AE$4:$AE$662,'Daily '!$A$4:$A$662,">="&$B5,'Daily '!$A$4:$A$662,"<="&$C5) -> 2254941 | AH5: =SUMIFS('Daily '!$AF$4:$AF$662,'Daily '!$A$4:$A$662,">="&$B5,'Daily '!$A$4:$A$662,"<="&$C5) -> 0 | AI5: =SUMIFS('Daily '!$AG$4:$AG$662,'Daily '!$A$4:$A$662,">="&$B5,'Daily '!$A$4:$A$662,"<="&$C5) -> 2254941 | AJ5: =SUMIFS('Daily '!$AH$4:$AH$662,'Daily '!$A$4:$A$662,">="&$B5,'Daily '!$A$4:$A$662,"<="&$C5) -> 1.3201762e+08 | AK5: =AI5-AJ5 -> -1.2976268e+08 | AL5: =IF(D5=0,"",P5/D5*10000) -> 0 | AM5: =IF(E5=0,"",Q5/E5*10000) | AN5: =IF(F5=0,"",R5/F5*10000) -> 1.4227447 | AO5: =IF(G5=0,"",S5/G5*10000) | AP5: =SUMIFS('Daily '!$AN$4:$AN$662,'Daily '!$A$4:$A$662,">="&$B5,'Daily '!$A$4:$A$662,"<="&$C5) -> 5738.4519 | AQ5: =SUMIFS('Daily '!$AO$4:$AO$662,'Daily '!$A$4:$A$662,">="&$B5,'Daily '!$A$4:$A$662,"<="&$C5) -> 495900.76 | AR5: =SUMIFS('Daily '!$AP$4:$AP$662,'Daily '!$A$4:$A$662,">="&$B5,'Daily '!$A$4:$A$662,"<="&$C5) -> 1.3251926e+08 | AS5: =SUMIFS('Daily '!$AQ$4:$AQ$662,'Daily '!$A$4:$A$662,">="&$B5,'Daily '!$A$4:$A$662,"<="&$C5) -> 1.3201762e+08 | AT5: =SUMIFS('Daily '!$AR$4:$AR$662,'Daily '!$A$4:$A$662,">="&$B5,'Daily '!$A$4:$A$662,"<="&$C5) -> 6676117 | AU5: =IF(AT5=0,"",AS5/AT5) -> 19.774611 | AV5: 18407964 | AW5: =SUMIFS('Daily '!$AU$4:$AU$662,'Daily '!$A$4:$A$662,">="&$B5,'Daily '!$A$4:$A$662,"<="&$C5) -> 2370516.1 | AX5: =SUMIFS('Daily '!$AV$4:$AV$662,'Daily '!$A$4:$A$662,">="&$B5,'Daily '!$A$4:$A$662,"<="&$C5) -> 84921.753 | AY5: =SUMIFS('Daily '!$AW$4:$AW$662,'Daily '!$A$4:$A$662,">="&$B5,'Daily '!$A$4:$A$662,"<="&$C5) -> 0 | AZ5: 421.3321 | BA5: 0.0228 | BB5: 4.2563427e+08 | BC5: 60480066 | BD5: 18407964 | BE5: 2971324 | BF5: 195393.45 | BG5: 4.9231099e+08 | BH5: 238 | BI5: 254.311 | BJ5: 6.1440411e+09
A6: Q2 2025 | B6: 45748 | C6: 45838 | D6: =SUMIFS('Daily '!$B$4:$B$662,'Daily '!$A$4:$A$662,">="&$B6,'Daily '!$A$4:$A$662,"<="&$C6) -> 654128076158 | E6: =SUMIFS('Daily '!$C$4:$C$662,'Daily '!$A$4:$A$662,">="&$B6,'Daily '!$A$4:$A$662,"<="&$C6) -> 0 | F6: =SUMIFS('Daily '!$D$4:$D$662,'Daily '!$A$4:$A$662,">="&$B6,'Daily '!$A$4:$A$662,"<="&$C6) -> 22001354657 | G6: =SUMIFS('Daily '!$E$4:$E$662,'Daily '!$A$4:$A$662,">="&$B6,'Daily '!$A$4:$A$662,"<="&$C6) -> 0 | H6: =SUMIFS('Daily '!$F$4:$F$662,'Daily '!$A$4:$A$662,">="&$B6,'Daily '!$A$4:$A$662,"<="&$C6) -> 0 | I6: =SUMIFS('Daily '!$G$4:$G$662,'Daily '!$A$4:$A$662,">="&$B6,'Daily '!$A$4:$A$662,"<="&$C6) -> 0 | J6: =SUMIFS('Daily '!$H$4:$H$662,'Daily '!$A$4:$A$662,">="&$B6,'Daily '!$A$4:$A$662,"<="&$C6) -> 0 | K6: =SUMIFS('Daily '!$I$4:$I$662,'Daily '!$A$4:$A$662,">="&$B6,'Daily '!$A$4:$A$662,"<="&$C6) -> 0 | L6: =SUMIFS('Daily '!$J$4:$J$662,'Daily '!$A$4:$A$662,">="&$B6,'Daily '!$A$4:$A$662,"<="&$C6) -> 0 | M6: =SUMIFS('Daily '!$K$4:$K$662,'Daily '!$A$4:$A$662,">="&$B6,'Daily '!$A$4:$A$662,"<="&$C6) -> 0 | N6: =SUMIFS('Daily '!$L$4:$L$662,'Daily '!$A$4:$A$662,">="&$B6,'Daily '!$A$4:$A$662,"<="&$C6) -> 0 | O6: =IF(E6=0,"",N6/E6) | P6: =SUMIFS('Daily '!$N$4:$N$662,'Daily '!$A$4:$A$662,">="&$B6,'Daily '!$A$4:$A$662,"<="&$C6) -> 0 | Q6: =SUMIFS('Daily '!$O$4:$O$662,'Daily '!$A$4:$A$662,">="&$B6,'Daily '!$A$4:$A$662,"<="&$C6) -> 0 | R6: =SUMIFS('Daily '!$P$4:$P$662,'Daily '!$A$4:$A$662,">="&$B6,'Daily '!$A$4:$A$662,"<="&$C6) -> 4388223 | S6: =SUMIFS('Daily '!$Q$4:$Q$662,'Daily '!$A$4:$A$662,">="&$B6,'Daily '!$A$4:$A$662,"<="&$C6) -> 0 | T6: =SUMIFS('Daily '!$R$4:$R$662,'Daily '!$A$4:$A$662,">="&$B6,'Daily '!$A$4:$A$662,"<="&$C6) -> 4388223 | V6: =SUMIFS('Daily '!$T$4:$T$662,'Daily '!$A$4:$A$662,">="&$B6,'Daily '!$A$4:$A$662,"<="&$C6) -> 0 | W6: =SUMIFS('Daily '!$U$4:$U$662,'Daily '!$A$4:$A$662,">="&$B6,'Daily '!$A$4:$A$662,"<="&$C6) -> 0 | X6: =SUMIFS('Daily '!$V$4:$V$662,'Daily '!$A$4:$A$662,">="&$B6,'Daily '!$A$4:$A$662,"<="&$C6) -> 105865.83 | Y6: =SUMIFS('Daily '!$W$4:$W$662,'Daily '!$A$4:$A$662,">="&$B6,'Daily '!$A$4:$A$662,"<="&$C6) -> 0 | Z6: =SUMIFS('Daily '!$X$4:$X$662,'Daily '!$A$4:$A$662,">="&$B6,'Daily '!$A$4:$A$662,"<="&$C6) -> 859362 | AA6: =SUMIFS('Daily '!$Y$4:$Y$662,'Daily '!$A$4:$A$662,">="&$B6,'Daily '!$A$4:$A$662,"<="&$C6) -> 0 | AB6: =SUMIFS('Daily '!$Z$4:$Z$662,'Daily '!$A$4:$A$662,">="&$B6,'Daily '!$A$4:$A$662,"<="&$C6) -> 0 | AC6: =SUMIFS('Daily '!$AA$4:$AA$662,'Daily '!$A$4:$A$662,">="&$B6,'Daily '!$A$4:$A$662,"<="&$C6) -> 965227.83 | AD6: =SUMIFS('Daily '!$AB$4:$AB$662,'Daily '!$A$4:$A$662,">="&$B6,'Daily '!$A$4:$A$662,"<="&$C6) -> 0 | AE6: =SUMIFS('Daily '!$AC$4:$AC$662,'Daily '!$A$4:$A$662,">="&$B6,'Daily '!$A$4:$A$662,"<="&$C6) -> 0 | AF6: =SUMIFS('Daily '!$AD$4:$AD$662,'Daily '!$A$4:$A$662,">="&$B6,'Daily '!$A$4:$A$662,"<="&$C6) -> 0 | AG6: =SUMIFS('Daily '!$AE$4:$AE$662,'Daily '!$A$4:$A$662,">="&$B6,'Daily '!$A$4:$A$662,"<="&$C6) -> 3528861 | AH6: =SUMIFS('Daily '!$AF$4:$AF$662,'Daily '!$A$4:$A$662,">="&$B6,'Daily '!$A$4:$A$662,"<="&$C6) -> 0 | AI6: =SUMIFS('Daily '!$AG$4:$AG$662,'Daily '!$A$4:$A$662,">="&$B6,'Daily '!$A$4:$A$662,"<="&$C6) -> 3528861 | AJ6: =SUMIFS('Daily '!$AH$4:$AH$662,'Daily '!$A$4:$A$662,">="&$B6,'Daily '!$A$4:$A$662,"<="&$C6) -> 1.7479522e+08 | AK6: =AI6-AJ6 -> -1.7126636e+08 | AL6: =IF(D6=0,"",P6/D6*10000) -> 0 | AM6: =IF(E6=0,"",Q6/E6*10000) | AN6: =IF(F6=0,"",R6/F6*10000) -> 1.994524 | AO6: =IF(G6=0,"",S6/G6*10000) | AP6: =SUMIFS('Daily '!$AN$4:$AN$662,'Daily '!$A$4:$A$662,">="&$B6,'Daily '!$A$4:$A$662,"<="&$C6) -> 1503329.4 | AQ6: =SUMIFS('Daily '!$AO$4:$AO$662,'Daily '!$A$4:$A$662,">="&$B6,'Daily '!$A$4:$A$662,"<="&$C6) -> 1946562.9 | AR6: =SUMIFS('Daily '!$AP$4:$AP$662,'Daily '!$A$4:$A$662,">="&$B6,'Daily '!$A$4:$A$662,"<="&$C6) -> 1.7824512e+08 | AS6: =SUMIFS('Daily '!$AQ$4:$AQ$662,'Daily '!$A$4:$A$662,">="&$B6,'Daily '!$A$4:$A$662,"<="&$C6) -> 1.7479522e+08 | AT6: =SUMIFS('Daily '!$AR$4:$AR$662,'Daily '!$A$4:$A$662,">="&$B6,'Daily '!$A$4:$A$662,"<="&$C6) -> 7100912 | AU6: =IF(AT6=0,"",AS6/AT6) -> 24.615884 | AV6: 25508876 | AW6: =SUMIFS('Daily '!$AU$4:$AU$662,'Daily '!$A$4:$A$662,">="&$B6,'Daily '!$A$4:$A$662,"<="&$C6) -> 2361973 | AX6: =SUMIFS('Daily '!$AV$4:$AV$662,'Daily '!$A$4:$A$662,">="&$B6,'Daily '!$A$4:$A$662,"<="&$C6) -> 113573.92 | AY6: =SUMIFS('Daily '!$AW$4:$AW$662,'Daily '!$A$4:$A$662,">="&$B6,'Daily '!$A$4:$A$662,"<="&$C6) -> 0 | AZ6: 422.0714 | BA6: 0.0226 | BB6: 4.2324595e+08 | BC6: 60480066 | BD6: 25508876 | BE6: 2971324 | BF6: 355352.02 | BG6: 4.8743843e+08 | BH6: 238 | BI6: 249.4384 | BJ6: 1.9268441e+10
A7: Q3 2025 | B7: 45839 | C7: 45930 | D7: =SUMIFS('Daily '!$B$4:$B$662,'Daily '!$A$4:$A$662,">="&$B7,'Daily '!$A$4:$A$662,"<="&$C7) -> 995759179915 | E7: =SUMIFS('Daily '!$C$4:$C$662,'Daily '!$A$4:$A$662,">="&$B7,'Daily '!$A$4:$A$662,"<="&$C7) -> 0 | F7: =SUMIFS('Daily '!$D$4:$D$662,'Daily '!$A$4:$A$662,">="&$B7,'Daily '!$A$4:$A$662,"<="&$C7) -> 57404523609 | G7: =SUMIFS('Daily '!$E$4:$E$662,'Daily '!$A$4:$A$662,">="&$B7,'Daily '!$A$4:$A$662,"<="&$C7) -> 0 | H7: =SUMIFS('Daily '!$F$4:$F$662,'Daily '!$A$4:$A$662,">="&$B7,'Daily '!$A$4:$A$662,"<="&$C7) -> 0 | I7: =SUMIFS('Daily '!$G$4:$G$662,'Daily '!$A$4:$A$662,">="&$B7,'Daily '!$A$4:$A$662,"<="&$C7) -> 0 | J7: =SUMIFS('Daily '!$H$4:$H$662,'Daily '!$A$4:$A$662,">="&$B7,'Daily '!$A$4:$A$662,"<="&$C7) -> 0 | K7: =SUMIFS('Daily '!$I$4:$I$662,'Daily '!$A$4:$A$662,">="&$B7,'Daily '!$A$4:$A$662,"<="&$C7) -> 0 | L7: =SUMIFS('Daily '!$J$4:$J$662,'Daily '!$A$4:$A$662,">="&$B7,'Daily '!$A$4:$A$662,"<="&$C7) -> 0 | M7: =SUMIFS('Daily '!$K$4:$K$662,'Daily '!$A$4:$A$662,">="&$B7,'Daily '!$A$4:$A$662,"<="&$C7) -> 0 | N7: =SUMIFS('Daily '!$L$4:$L$662,'Daily '!$A$4:$A$662,">="&$B7,'Daily '!$A$4:$A$662,"<="&$C7) -> 0 | O7: =IF(E7=0,"",N7/E7) | P7: =SUMIFS('Daily '!$N$4:$N$662,'Daily '!$A$4:$A$662,">="&$B7,'Daily '!$A$4:$A$662,"<="&$C7) -> 1.3916399e+08 | Q7: =SUMIFS('Daily '!$O$4:$O$662,'Daily '!$A$4:$A$662,">="&$B7,'Daily '!$A$4:$A$662,"<="&$C7) -> 0 | R7: =SUMIFS('Daily '!$P$4:$P$662,'Daily '!$A$4:$A$662,">="&$B7,'Daily '!$A$4:$A$662,"<="&$C7) -> 23134792 | S7: =SUMIFS('Daily '!$Q$4:$Q$662,'Daily '!$A$4:$A$662,">="&$B7,'Daily '!$A$4:$A$662,"<="&$C7) -> 0 | T7: =SUMIFS('Daily '!$R$4:$R$662,'Daily '!$A$4:$A$662,">="&$B7,'Daily '!$A$4:$A$662,"<="&$C7) -> 1.6229878e+08 | V7: =SUMIFS('Daily '!$T$4:$T$662,'Daily '!$A$4:$A$662,">="&$B7,'Daily '!$A$4:$A$662,"<="&$C7) -> 2405724.6 | W7: =SUMIFS('Daily '!$U$4:$U$662,'Daily '!$A$4:$A$662,">="&$B7,'Daily '!$A$4:$A$662,"<="&$C7) -> 0 | X7: =SUMIFS('Daily '!$V$4:$V$662,'Daily '!$A$4:$A$662,">="&$B7,'Daily '!$A$4:$A$662,"<="&$C7) -> 330416.3 | Y7: =SUMIFS('Daily '!$W$4:$W$662,'Daily '!$A$4:$A$662,">="&$B7,'Daily '!$A$4:$A$662,"<="&$C7) -> 0 | Z7: =SUMIFS('Daily '!$X$4:$X$662,'Daily '!$A$4:$A$662,">="&$B7,'Daily '!$A$4:$A$662,"<="&$C7) -> 5109814.7 | AA7: =SUMIFS('Daily '!$Y$4:$Y$662,'Daily '!$A$4:$A$662,">="&$B7,'Daily '!$A$4:$A$662,"<="&$C7) -> 0 | AB7: =SUMIFS('Daily '!$Z$4:$Z$662,'Daily '!$A$4:$A$662,">="&$B7,'Daily '!$A$4:$A$662,"<="&$C7) -> 0 | AC7: =SUMIFS('Daily '!$AA$4:$AA$662,'Daily '!$A$4:$A$662,">="&$B7,'Daily '!$A$4:$A$662,"<="&$C7) -> 7845955.6 | AD7: =SUMIFS('Daily '!$AB$4:$AB$662,'Daily '!$A$4:$A$662,">="&$B7,'Daily '!$A$4:$A$662,"<="&$C7) -> 5727519.2 | AE7: =SUMIFS('Daily '!$AC$4:$AC$662,'Daily '!$A$4:$A$662,">="&$B7,'Daily '!$A$4:$A$662,"<="&$C7) -> 1.3916399e+08 | AF7: =SUMIFS('Daily '!$AD$4:$AD$662,'Daily '!$A$4:$A$662,">="&$B7,'Daily '!$A$4:$A$662,"<="&$C7) -> 0 | AG7: =SUMIFS('Daily '!$AE$4:$AE$662,'Daily '!$A$4:$A$662,">="&$B7,'Daily '!$A$4:$A$662,"<="&$C7) -> 18024977 | AH7: =SUMIFS('Daily '!$AF$4:$AF$662,'Daily '!$A$4:$A$662,">="&$B7,'Daily '!$A$4:$A$662,"<="&$C7) -> 0 | AI7: =SUMIFS('Daily '!$AG$4:$AG$662,'Daily '!$A$4:$A$662,">="&$B7,'Daily '!$A$4:$A$662,"<="&$C7) -> 1.5718897e+08 | AJ7: =SUMIFS('Daily '!$AH$4:$AH$662,'Daily '!$A$4:$A$662,">="&$B7,'Daily '!$A$4:$A$662,"<="&$C7) -> 2.8087817e+08 | AK7: =AI7-AJ7 -> -1.236892e+08 | AL7: =IF(D7=0,"",P7/D7*10000) -> 1.3975668 | AM7: =IF(E7=0,"",Q7/E7*10000) | AN7: =IF(F7=0,"",R7/F7*10000) -> 4.0301339 | AO7: =IF(G7=0,"",S7/G7*10000) | AP7: =SUMIFS('Daily '!$AN$4:$AN$662,'Daily '!$A$4:$A$662,">="&$B7,'Daily '!$A$4:$A$662,"<="&$C7) -> 2690642.4 | AQ7: =SUMIFS('Daily '!$AO$4:$AO$662,'Daily '!$A$4:$A$662,">="&$B7,'Daily '!$A$4:$A$662,"<="&$C7) -> 2080362.6 | AR7: =SUMIFS('Daily '!$AP$4:$AP$662,'Daily '!$A$4:$A$662,">="&$B7,'Daily '!$A$4:$A$662,"<="&$C7) -> 2.8564918e+08 | AS7: =SUMIFS('Daily '!$AQ$4:$AQ$662,'Daily '!$A$4:$A$662,">="&$B7,'Daily '!$A$4:$A$662,"<="&$C7) -> 2.8087817e+08 | AT7: =SUMIFS('Daily '!$AR$4:$AR$662,'Daily '!$A$4:$A$662,">="&$B7,'Daily '!$A$4:$A$662,"<="&$C7) -> 6219840.7 | AU7: =IF(AT7=0,"",AS7/AT7) -> 45.158419 | AV7: 31785059 | AW7: =SUMIFS('Daily '!$AU$4:$AU$662,'Daily '!$A$4:$A$662,">="&$B7,'Daily '!$A$4:$A$662,"<="&$C7) -> 2421595.6 | AX7: =SUMIFS('Daily '!$AV$4:$AV$662,'Daily '!$A$4:$A$662,">="&$B7,'Daily '!$A$4:$A$662,"<="&$C7) -> 115837.35 | AY7: =SUMIFS('Daily '!$AW$4:$AW$662,'Daily '!$A$4:$A$662,">="&$B7,'Daily '!$A$4:$A$662,"<="&$C7) -> 0 | AZ7: 425.4931 | BA7: 0.0224 | BB7: 4.2082436e+08 | BC7: 60480066 | BD7: 31785059 | BE7: 2971324 | BF7: 529777.17 | BG7: 4.8340942e+08 | BH7: 238 | BI7: 245.4094 | BJ7: 2.2290008e+10
A8: Q4 2025 | B8: 45931 | C8: 46022 | D8: =SUMIFS('Daily '!$B$4:$B$662,'Daily '!$A$4:$A$662,">="&$B8,'Daily '!$A$4:$A$662,"<="&$C8) -> 736416007436 | E8: =SUMIFS('Daily '!$C$4:$C$662,'Daily '!$A$4:$A$662,">="&$B8,'Daily '!$A$4:$A$662,"<="&$C8) -> 1.3083575e+10 | F8: =SUMIFS('Daily '!$D$4:$D$662,'Daily '!$A$4:$A$662,">="&$B8,'Daily '!$A$4:$A$662,"<="&$C8) -> 26372740554 | G8: =SUMIFS('Daily '!$E$4:$E$662,'Daily '!$A$4:$A$662,">="&$B8,'Daily '!$A$4:$A$662,"<="&$C8) -> 0 | H8: =SUMIFS('Daily '!$F$4:$F$662,'Daily '!$A$4:$A$662,">="&$B8,'Daily '!$A$4:$A$662,"<="&$C8) -> 3.055227e+08 | I8: =SUMIFS('Daily '!$G$4:$G$662,'Daily '!$A$4:$A$662,">="&$B8,'Daily '!$A$4:$A$662,"<="&$C8) -> 3.2960552e+08 | J8: =SUMIFS('Daily '!$H$4:$H$662,'Daily '!$A$4:$A$662,">="&$B8,'Daily '!$A$4:$A$662,"<="&$C8) -> 6085282.8 | K8: =SUMIFS('Daily '!$I$4:$I$662,'Daily '!$A$4:$A$662,">="&$B8,'Daily '!$A$4:$A$662,"<="&$C8) -> 8.3893562e+09 | L8: =SUMIFS('Daily '!$J$4:$J$662,'Daily '!$A$4:$A$662,">="&$B8,'Daily '!$A$4:$A$662,"<="&$C8) -> 51147216 | M8: =SUMIFS('Daily '!$K$4:$K$662,'Daily '!$A$4:$A$662,">="&$B8,'Daily '!$A$4:$A$662,"<="&$C8) -> 4.0018584e+09 | N8: =SUMIFS('Daily '!$L$4:$L$662,'Daily '!$A$4:$A$662,">="&$B8,'Daily '!$A$4:$A$662,"<="&$C8) -> 1.3083575e+10 | O8: =IF(E8=0,"",N8/E8) -> 1 | P8: =SUMIFS('Daily '!$N$4:$N$662,'Daily '!$A$4:$A$662,">="&$B8,'Daily '!$A$4:$A$662,"<="&$C8) -> 2.2700903e+08 | Q8: =SUMIFS('Daily '!$O$4:$O$662,'Daily '!$A$4:$A$662,">="&$B8,'Daily '!$A$4:$A$662,"<="&$C8) -> 4594926.6 | R8: =SUMIFS('Daily '!$P$4:$P$662,'Daily '!$A$4:$A$662,">="&$B8,'Daily '!$A$4:$A$662,"<="&$C8) -> 14039425 | S8: =SUMIFS('Daily '!$Q$4:$Q$662,'Daily '!$A$4:$A$662,">="&$B8,'Daily '!$A$4:$A$662,"<="&$C8) -> 0 | T8: =SUMIFS('Daily '!$R$4:$R$662,'Daily '!$A$4:$A$662,">="&$B8,'Daily '!$A$4:$A$662,"<="&$C8) -> 2.4564339e+08 | V8: =SUMIFS('Daily '!$T$4:$T$662,'Daily '!$A$4:$A$662,">="&$B8,'Daily '!$A$4:$A$662,"<="&$C8) -> 2270090.3 | W8: =SUMIFS('Daily '!$U$4:$U$662,'Daily '!$A$4:$A$662,">="&$B8,'Daily '!$A$4:$A$662,"<="&$C8) -> 22974.633 | X8: =SUMIFS('Daily '!$V$4:$V$662,'Daily '!$A$4:$A$662,">="&$B8,'Daily '!$A$4:$A$662,"<="&$C8) -> 113707.77 | Y8: =SUMIFS('Daily '!$W$4:$W$662,'Daily '!$A$4:$A$662,">="&$B8,'Daily '!$A$4:$A$662,"<="&$C8) -> 0 | Z8: =SUMIFS('Daily '!$X$4:$X$662,'Daily '!$A$4:$A$662,">="&$B8,'Daily '!$A$4:$A$662,"<="&$C8) -> 2668648.4 | AA8: =SUMIFS('Daily '!$Y$4:$Y$662,'Daily '!$A$4:$A$662,">="&$B8,'Daily '!$A$4:$A$662,"<="&$C8) -> 2297463.3 | AB8: =SUMIFS('Daily '!$Z$4:$Z$662,'Daily '!$A$4:$A$662,">="&$B8,'Daily '!$A$4:$A$662,"<="&$C8) -> 0 | AC8: =SUMIFS('Daily '!$AA$4:$AA$662,'Daily '!$A$4:$A$662,">="&$B8,'Daily '!$A$4:$A$662,"<="&$C8) -> 7372884.4 | AD8: =SUMIFS('Daily '!$AB$4:$AB$662,'Daily '!$A$4:$A$662,">="&$B8,'Daily '!$A$4:$A$662,"<="&$C8) -> 19494286 | AE8: =SUMIFS('Daily '!$AC$4:$AC$662,'Daily '!$A$4:$A$662,">="&$B8,'Daily '!$A$4:$A$662,"<="&$C8) -> 2.2700903e+08 | AF8: =SUMIFS('Daily '!$AD$4:$AD$662,'Daily '!$A$4:$A$662,">="&$B8,'Daily '!$A$4:$A$662,"<="&$C8) -> 2297463.3 | AG8: =SUMIFS('Daily '!$AE$4:$AE$662,'Daily '!$A$4:$A$662,">="&$B8,'Daily '!$A$4:$A$662,"<="&$C8) -> 11370777 | AH8: =SUMIFS('Daily '!$AF$4:$AF$662,'Daily '!$A$4:$A$662,">="&$B8,'Daily '!$A$4:$A$662,"<="&$C8) -> 0 | AI8: =SUMIFS('Daily '!$AG$4:$AG$662,'Daily '!$A$4:$A$662,">="&$B8,'Daily '!$A$4:$A$662,"<="&$C8) -> 2.4067727e+08 | AJ8: =SUMIFS('Daily '!$AH$4:$AH$662,'Daily '!$A$4:$A$662,">="&$B8,'Daily '!$A$4:$A$662,"<="&$C8) -> 2.2166534e+08 | AK8: =AI8-AJ8 -> 19011935 | AL8: =IF(D8=0,"",P8/D8*10000) -> 3.0826195 | AM8: =IF(E8=0,"",Q8/E8*10000) -> 3.5119809 | AN8: =IF(F8=0,"",R8/F8*10000) -> 5.3234608 | AO8: =IF(G8=0,"",S8/G8*10000) | AP8: =SUMIFS('Daily '!$AN$4:$AN$662,'Daily '!$A$4:$A$662,">="&$B8,'Daily '!$A$4:$A$662,"<="&$C8) -> 3261330.8 | AQ8: =SUMIFS('Daily '!$AO$4:$AO$662,'Daily '!$A$4:$A$662,">="&$B8,'Daily '!$A$4:$A$662,"<="&$C8) -> 854091.95 | AR8: =SUMIFS('Daily '!$AP$4:$AP$662,'Daily '!$A$4:$A$662,">="&$B8,'Daily '!$A$4:$A$662,"<="&$C8) -> 2.2578076e+08 | AS8: =SUMIFS('Daily '!$AQ$4:$AQ$662,'Daily '!$A$4:$A$662,">="&$B8,'Daily '!$A$4:$A$662,"<="&$C8) -> 2.2166534e+08 | AT8: =SUMIFS('Daily '!$AR$4:$AR$662,'Daily '!$A$4:$A$662,">="&$B8,'Daily '!$A$4:$A$662,"<="&$C8) -> 6069597.7 | AU8: =IF(AT8=0,"",AS8/AT8) -> 36.520598 | AV8: 37855112 | AW8: =SUMIFS('Daily '!$AU$4:$AU$662,'Daily '!$A$4:$A$662,">="&$B8,'Daily '!$A$4:$A$662,"<="&$C8) -> 2380114.6 | AX8: =SUMIFS('Daily '!$AV$4:$AV$662,'Daily '!$A$4:$A$662,">="&$B8,'Daily '!$A$4:$A$662,"<="&$C8) -> 122406.05 | AY8: =SUMIFS('Daily '!$AW$4:$AW$662,'Daily '!$A$4:$A$662,">="&$B8,'Daily '!$A$4:$A$662,"<="&$C8) -> 1745746 | AZ8: 432.3217 | BA8: 0.0223 | BB8: 4.1841903e+08 | BC8: 60480066 | BD8: 37855112 | BE8: 2971324 | BF8: 744540.86 | BG8: 4.7952993e+08 | BH8: 236.2543 | BI8: 243.2757 | BJ8: 1.2400644e+10
