Workbook

Sheet Daily Breakdown
B1: VOLUME ($) | E1: FEES — 21Shares proxy ($) | J1: HIP-3 SPLIT — retained / 1x basis ($) | L1: HIP-3 SPLIT — total / 2x basis ($) | N1: REVENUE — DefiLlama ($) | O1: CROSS-CHECK — DefiLlama ($) | Q1: FLAGS
A2: Date | B2: Core volume | C2: HIP-3 volume | D2: Total volume | E2: Core+HIP3 fee proxy | F2: HyperEVM fees | G2: Total fees (21S) | H2: HIP-3 vol share % | I2: Core vol share % | J2: HIP-3 fees (retained 1x) | K2: Core fees (retained basis) | L2: HIP-3 fees (total 2x) | M2: Core fees (2x basis) | N2: Revenue (DefiLlama) | O2: Total fees (DefiLlama) | P2: 21S vs DL fee diff % | Q2: Row source | R2: Day status
A3: 2023-05-20 | B3: 1.4896434e+08 | C3: 0 | D3: 1.4896434e+08 | E3: 55116.81 | F3: 0 | G3: =E3+F3 -> 55116.81 | H3: =IF(D3=0,0,C3/D3) -> 0 | I3: =IF(D3=0,0,B3/D3) -> 1 | J3: =E3*H3 -> 0 | K3: =E3*I3 -> 55116.81 | L3: 0 | M3: 55116.81 | Q3: historical_core_plus_hip3 | R3: complete
A4: 2023-05-21 | B4: 1.7817381e+08 | C4: 0 | D4: 1.7817381e+08 | E4: 65924.31 | F4: 0 | G4: =E4+F4 -> 65924.31 | H4: =IF(D4=0,0,C4/D4) -> 0 | I4: =IF(D4=0,0,B4/D4) -> 1 | J4: =E4*H4 -> 0 | K4: =E4*I4 -> 65924.31 | L4: 0 | M4: 65924.31 | Q4: historical_core_plus_hip3 | R4: complete
A5: 2023-05-22 | B5: 2.0381289e+08 | C5: 0 | D5: 2.0381289e+08 | E5: 75410.77 | F5: 0 | G5: =E5+F5 -> 75410.77 | H5: =IF(D5=0,0,C5/D5) -> 0 | I5: =IF(D5=0,0,B5/D5) -> 1 | J5: =E5*H5 -> 0 | K5: =E5*I5 -> 75410.77 | L5: 0 | M5: 75410.77 | Q5: historical_core_plus_hip3 | R5: complete
A6: 2023-05-23 | B6: 2.3846318e+08 | C6: 0 | D6: 2.3846318e+08 | E6: 88231.38 | F6: 0 | G6: =E6+F6 -> 88231.38 | H6: =IF(D6=0,0,C6/D6) -> 0 | I6: =IF(D6=0,0,B6/D6) -> 1 | J6: =E6*H6 -> 0 | K6: =E6*I6 -> 88231.38 | L6: 0 | M6: 88231.38 | Q6: historical_core_plus_hip3 | R6: complete
A7: 2023-05-24 | B7: 4.6949197e+08 | C7: 0 | D7: 4.6949197e+08 | E7: 173712.03 | F7: 0 | G7: =E7+F7 -> 173712.03 | H7: =IF(D7=0,0,C7/D7) -> 0 | I7: =IF(D7=0,0,B7/D7) -> 1 | J7: =E7*H7 -> 0 | K7: =E7*I7 -> 173712.03 | L7: 0 | M7: 173712.03 | Q7: historical_core_plus_hip3 | R7: complete
A8: 2023-05-25 | B8: 6.5181124e+08 | C8: 0 | D8: 6.5181124e+08 | E8: 241170.16 | F8: 0 | G8: =E8+F8 -> 241170.16 | H8: =IF(D8=0,0,C8/D8) -> 0 | I8: =IF(D8=0,0,B8/D8) -> 1 | J8: =E8*H8 -> 0 | K8: =E8*I8 -> 241170.16 | L8: 0 | M8: 241170.16 | Q8: historical_core_plus_hip3 | R8: complete
A9: 2023-05-26 | B9: 6.3554324e+08 | C9: 0 | D9: 6.3554324e+08 | E9: 235151 | F9: 0 | G9: =E9+F9 -> 235151 | H9: =IF(D9=0,0,C9/D9) -> 0 | I9: =IF(D9=0,0,B9/D9) -> 1 | J9: =E9*H9 -> 0 | K9: =E9*I9 -> 235151 | L9: 0 | M9: 235151 | Q9: historical_core_plus_hip3 | R9: complete
A10: 2023-05-27 | B10: 6.2926637e+08 | C10: 0 | D10: 6.2926637e+08 | E10: 232828.56 | F10: 0 | G10: =E10+F10 -> 232828.56 | H10: =IF(D10=0,0,C10/D10) -> 0 | I10: =IF(D10=0,0,B10/D10) -> 1 | J10: =E10*H10 -> 0 | K10: =E10*I10 -> 232828.56 | L10: 0 | M10: 232828.56 | Q10: historical_core_plus_hip3 | R10: complete
A11: 2023-05-28 | B11: 1.0302869e+09 | C11: 0 | D11: 1.0302869e+09 | E11: 381206.16 | F11: 0 | G11: =E11+F11 -> 381206.16 | H11: =IF(D11=0,0,C11/D11) -> 0 | I11: =IF(D11=0,0,B11/D11) -> 1 | J11: =E11*H11 -> 0 | K11: =E11*I11 -> 381206.16 | L11: 0 | M11: 381206.16 | Q11: historical_core_plus_hip3 | R11: complete
A12: 2023-05-29 | B12: 1.6653697e+09 | C12: 0 | D12: 1.6653697e+09 | E12: 616186.81 | F12: 0 | G12: =E12+F12 -> 616186.81 | H12: =IF(D12=0,0,C12/D12) -> 0 | I12: =IF(D12=0,0,B12/D12) -> 1 | J12: =E12*H12 -> 0 | K12: =E12*I12 -> 616186.81 | L12: 0 | M12: 616186.81 | Q12: historical_core_plus_hip3 | R12: complete
A13: 2023-05-30 | B13: 7.9048504e+08 | C13: 0 | D13: 7.9048504e+08 | E13: 292479.47 | F13: 0 | G13: =E13+F13 -> 292479.47 | H13: =IF(D13=0,0,C13/D13) -> 0 | I13: =IF(D13=0,0,B13/D13) -> 1 | J13: =E13*H13 -> 0 | K13: =E13*I13 -> 292479.47 | L13: 0 | M13: 292479.47 | Q13: historical_core_plus_hip3 | R13: complete
A14: 2023-05-31 | B14: 6.9786168e+08 | C14: 0 | D14: 6.9786168e+08 | E14: 258208.82 | F14: 0 | G14: =E14+F14 -> 258208.82 | H14: =IF(D14=0,0,C14/D14) -> 0 | I14: =IF(D14=0,0,B14/D14) -> 1 | J14: =E14*H14 -> 0 | K14: =E14*I14 -> 258208.82 | L14: 0 | M14: 258208.82 | Q14: historical_core_plus_hip3 | R14: complete
... A585: 2024-12-22 | B585: 4.6867317e+09 | C585: 0 | D585: 4.6867317e+09 | E585: 1734090.7 | F585: 0 | G585: =E585+F585 -> 1734090.7 | H585: =IF(D585=0,0,C585/D585) -> 0 | I585: =IF(D585=0,0,B585/D585) -> 1 | J585: =E585*H585 -> 0 | K585: =E585*I585 -> 1734090.7 | L585: 0 | M585: 1734090.7 | Q585: historical_core_plus_hip3 | R585: complete
A586: 2024-12-23 | B586: 6.1684635e+09 | C586: 0 | D586: 6.1684635e+09 | E586: 2282331.5 | F586: 0 | G586: =E586+F586 -> 2282331.5 | H586: =IF(D586=0,0,C586/D586) -> 0 | I586: =IF(D586=0,0,B586/D586) -> 1 | J586: =E586*H586 -> 0 | K586: =E586*I586 -> 2282331.5 | L586: 0 | M586: 2282331.5 | N586: 1424462 | O586: 1468518 | P586: =IF(O586=0,"",(G586-O586)/O586) -> 0.55417332 | Q586: historical_core_plus_hip3 | R586: complete
A587: 2024-12-24 | B587: 4.4015652e+09 | C587: 0 | D587: 4.4015652e+09 | E587: 1628579.1 | F587: 0 | G587: =E587+F587 -> 1628579.1 | H587: =IF(D587=0,0,C587/D587) -> 0 | I587: =IF(D587=0,0,B587/D587) -> 1 | J587: =E587*H587 -> 0 | K587: =E587*I587 -> 1628579.1 | L587: 0 | M587: 1628579.1 | N587: 1303665 | O587: 1384305 | P587: =IF(O587=0,"",(G587-O587)/O587) -> 0.17645977 | Q587: historical_core_plus_hip3 | R587: complete
A588: 2024-12-25 | B588: 3.0900267e+09 | C588: 0 | D588: 3.0900267e+09 | E588: 1143309.9 | F588: 0 | G588: =E588+F588 -> 1143309.9 | H588: =IF(D588=0,0,C588/D588) -> 0 | I588: =IF(D588=0,0,B588/D588) -> 1 | J588: =E588*H588 -> 0 | K588: =E588*I588 -> 1143309.9 | L588: 0 | M588: 1143309.9 | N588: 1014518 | O588: 1077272 | P588: =IF(O588=0,"",(G588-O588)/O588) -> 0.061301036 | Q588: historical_core_plus_hip3 | R588: complete
A589: 2024-12-26 | B589: 3.8974652e+09 | C589: 0 | D589: 3.8974652e+09 | E589: 1442062.1 | F589: 0 | G589: =E589+F589 -> 1442062.1 | H589: =IF(D589=0,0,C589/D589) -> 0 | I589: =IF(D589=0,0,B589/D589) -> 1 | J589: =E589*H589 -> 0 | K589: =E589*I589 -> 1442062.1 | L589: 0 | M589: 1442062.1 | N589: 1273897 | O589: 1352695 | P589: =IF(O589=0,"",(G589-O589)/O589) -> 0.066065994 | Q589: historical_core_plus_hip3 | R589: complete
A590: 2024-12-27 | B590: 3.8894731e+09 | C590: 0 | D590: 3.8894731e+09 | E590: 1439105.1 | F590: 0 | G590: =E590+F590 -> 1439105.1 | H590: =IF(D590=0,0,C590/D590) -> 0 | I590: =IF(D590=0,0,B590/D590) -> 1 | J590: =E590*H590 -> 0 | K590: =E590*I590 -> 1439105.1 | L590: 0 | M590: 1439105.1 | N590: 1258520 | O590: 1336367 | P590: =IF(O590=0,"",(G590-O590)/O590) -> 0.076878627 | Q590: historical_core_plus_hip3 | R590: complete
A591: 2024-12-28 | B591: 2.0771914e+09 | C591: 0 | D591: 2.0771914e+09 | E591: 768560.8 | F591: 0 | G591: =E591+F591 -> 768560.8 | H591: =IF(D591=0,0,C591/D591) -> 0 | I591: =IF(D591=0,0,B591/D591) -> 1 | J591: =E591*H591 -> 0 | K591: =E591*I591 -> 768560.8 | L591: 0 | M591: 768560.8 | N591: 949315 | O591: 1008036 | P591: =IF(O591=0,"",(G591-O591)/O591) -> -0.23756612 | Q591: historical_core_plus_hip3 | R591: complete
A592: 2024-12-29 | B592: 1.9659316e+09 | C592: 0 | D592: 1.9659316e+09 | E592: 727394.69 | F592: 0 | G592: =E592+F592 -> 727394.69 | H592: =IF(D592=0,0,C592/D592) -> 0 | I592: =IF(D592=0,0,B592/D592) -> 1 | J592: =E592*H592 -> 0 | K592: =E592*I592 -> 727394.69 | L592: 0 | M592: 727394.69 | N592: 471167 | O592: 500152 | P592: =IF(O592=0,"",(G592-O592)/O592) -> 0.45434726 | Q592: historical_core_plus_hip3 | R592: complete
A593: 2024-12-30 | B593: 4.6971711e+09 | C593: 0 | D593: 4.6971711e+09 | E593: 1737953.3 | F593: 0 | G593: =E593+F593 -> 1737953.3 | H593: =IF(D593=0,0,C593/D593) -> 0 | I593: =IF(D593=0,0,B593/D593) -> 1 | J593: =E593*H593 -> 0 | K593: =E593*I593 -> 1737953.3 | L593: 0 | M593: 1737953.3 | N593: 1486794 | O593: 1578682 | P593: =IF(O593=0,"",(G593-O593)/O593) -> 0.10088879 | Q593: historical_core_plus_hip3 | R593: complete
A594: 2024-12-31 | B594: 3.4505145e+09 | C594: 0 | D594: 3.4505145e+09 | E594: 1276690.4 | F594: 0 | G594: =E594+F594 -> 1276690.4 | H594: =IF(D594=0,0,C594/D594) -> 0 | I594: =IF(D594=0,0,B594/D594) -> 1 | J594: =E594*H594 -> 0 | K594: =E594*I594 -> 1276690.4 | L594: 0 | M594: 1276690.4 | N594: 1327977 | O594: 1410195 | P594: =IF(O594=0,"",(G594-O594)/O594) -> -0.094671042 | Q594: historical_core_plus_hip3 | R594: complete
A595: 2025-01-01 | B595: 2.1572568e+09 | C595: 0 | D595: 2.1572568e+09 | E595: 798185.02 | F595: 0 | G595: =E595+F595 -> 798185.02 | H595: =IF(D595=0,0,C595/D595) -> 0 | I595: =IF(D595=0,0,B595/D595) -> 1 | J595: =E595*H595 -> 0 | K595: =E595*I595 -> 798185.02 | L595: 0 | M595: 798185.02 | N595: 498037 | O595: 528836 | P595: =IF(O595=0,"",(G595-O595)/O595) -> 0.50932429 | Q595: historical_core_plus_hip3 | R595: complete
A596: 2025-01-02 | B596: 3.6458162e+09 | C596: 0 | D596: 3.6458162e+09 | E596: 1348952 | F596: 0 | G596: =E596+F596 -> 1348952 | H596: =IF(D596=0,0,C596/D596) -> 0 | I596: =IF(D596=0,0,B596/D596) -> 1 | J596: =E596*H596 -> 0 | K596: =E596*I596 -> 1348952 | L596: 0 | M596: 1348952 | N596: 1270220 | O596: 1348961 | P596: =IF(O596=0,"",(G596-O596)/O596) -> -6.6866277e-06 | Q596: historical_core_plus_hip3 | R596: complete
A597: 2025-01-03 | B597: 3.5731603e+09 | C597: 0 | D597: 3.5731603e+09 | E597: 1322069.3 | F597: 0 | G597: =E597+F597 -> 1322069.3 | H597: =IF(D597=0,0,C597/D597) -> 0 | I597: =IF(D597=0,0,B597/D597) -> 1 | J597: =E597*H597 -> 0 | K597: =E597*I597 -> 1322069.3 | L597: 0 | M597: 1322069.3 | N597: 1369500 | O597: 1454092 | P597: =IF(O597=0,"",(G597-O597)/O597) -> -0.090793911 | Q597: historical_core_plus_hip3 | R597: complete
... A605: 2025-01-11 | B605: 1.9752201e+09 | C605: 0 | D605: 1.9752201e+09 | E605: 730831.44 | F605: 0 | G605: =E605+F605 -> 730831.44 | H605: =IF(D605=0,0,C605/D605) -> 0 | I605: =IF(D605=0,0,B605/D605) -> 1 | J605: =E605*H605 -> 0 | K605: =E605*I605 -> 730831.44 | L605: 0 | M605: 730831.44 | N605: 458402 | O605: 486756 | P605: =IF(O605=0,"",(G605-O605)/O605) -> 0.50143283 | Q605: historical_core_plus_hip3 | R605: complete
A606: 2025-01-12 | B606: 1.8688233e+09 | C606: 0 | D606: 1.8688233e+09 | E606: 691464.63 | F606: 0 | G606: =E606+F606 -> 691464.63 | H606: =IF(D606=0,0,C606/D606) -> 0 | I606: =IF(D606=0,0,B606/D606) -> 1 | J606: =E606*H606 -> 0 | K606: =E606*I606 -> 691464.63 | L606: 0 | M606: 691464.63 | Q606: historical_core_plus_hip3 | R606: complete
A607: 2025-01-13 | B607: 7.6148894e+09 | C607: 0 | D607: 7.6148894e+09 | E607: 2817509.1 | F607: 0 | G607: =E607+F607 -> 2817509.1 | H607: =IF(D607=0,0,C607/D607) -> 0 | I607: =IF(D607=0,0,B607/D607) -> 1 | J607: =E607*H607 -> 0 | K607: =E607*I607 -> 2817509.1 | L607: 0 | M607: 2817509.1 | Q607: historical_core_plus_hip3 | R607: complete
A608: 2025-01-14 | B608: 4.1645346e+09 | C608: 0 | D608: 4.1645346e+09 | E608: 1540877.8 | F608: 0 | G608: =E608+F608 -> 1540877.8 | H608: =IF(D608=0,0,C608/D608) -> 0 | I608: =IF(D608=0,0,B608/D608) -> 1 | J608: =E608*H608 -> 0 | K608: =E608*I608 -> 1540877.8 | L608: 0 | M608: 1540877.8 | N608: 1230157 | O608: 1306397 | P608: =IF(O608=0,"",(G608-O608)/O608) -> 0.17948664 | Q608: historical_core_plus_hip3 | R608: complete
A609: 2025-01-15 | B609: 5.3154076e+09 | C609: 0 | D609: 5.3154076e+09 | E609: 1966700.8 | F609: 0 | G609: =E609+F609 -> 1966700.8 | H609: =IF(D609=0,0,C609/D609) -> 0 | I609: =IF(D609=0,0,B609/D609) -> 1 | J609: =E609*H609 -> 0 | K609: =E609*I609 -> 1966700.8 | L609: 0 | M609: 1966700.8 | N609: 1231497 | O609: 1307385 | P609: =IF(O609=0,"",(G609-O609)/O609) -> 0.50430118 | Q609: historical_core_plus_hip3 | R609: complete
A610: 2025-01-16 | B610: 5.7136112e+09 | C610: 0 | D610: 5.7136112e+09 | E610: 2114036.2 | F610: 0 | G610: =E610+F610 -> 2114036.2 | H610: =IF(D610=0,0,C610/D610) -> 0 | I610: =IF(D610=0,0,B610/D610) -> 1 | J610: =E610*H610 -> 0 | K610: =E610*I610 -> 2114036.2 | L610: 0 | M610: 2114036.2 | N610: 1644992 | O610: 1747030 | P610: =IF(O610=0,"",(G610-O610)/O610) -> 0.21007433 | Q610: historical_core_plus_hip3 | R610: complete
A611: 2025-01-17 | B611: 5.4612772e+09 | C611: 0 | D611: 5.4612772e+09 | E611: 2020672.6 | F611: 0 | G611: =E611+F611 -> 2020672.6 | H611: =IF(D611=0,0,C611/D611) -> 0 | I611: =IF(D611=0,0,B611/D611) -> 1 | J611: =E611*H611 -> 0 | K611: =E611*I611 -> 2020672.6 | L611: 0 | M611: 2020672.6 | N611: 1647338 | O611: 1749236 | P611: =IF(O611=0,"",(G611-O611)/O611) -> 0.15517436 | Q611: historical_core_plus_hip3 | R611: complete
A612: 2025-01-18 | B612: 9.6789601e+09 | C612: 0 | D612: 9.6789601e+09 | E612: 3581215.2 | F612: 0 | G612: =E612+F612 -> 3581215.2 | H612: =IF(D612=0,0,C612/D612) -> 0 | I612: =IF(D612=0,0,B612/D612) -> 1 | J612: =E612*H612 -> 0 | K612: =E612*I612 -> 3581215.2 | L612: 0 | M612: 3581215.2 | N612: 2754660 | O612: 2924730 | P612: =IF(O612=0,"",(G612-O612)/O612) -> 0.22446012 | Q612: historical_core_plus_hip3 | R612: complete
A613: 2025-01-19 | B613: 1.775022e+10 | C613: 0 | D613: 1.775022e+10 | E613: 6567581.2 | F613: 0 | G613: =E613+F613 -> 6567581.2 | H613: =IF(D613=0,0,C613/D613) -> 0 | I613: =IF(D613=0,0,B613/D613) -> 1 | J613: =E613*H613 -> 0 | K613: =E613*I613 -> 6567581.2 | L613: 0 | M613: 6567581.2 | N613: 4182537 | O613: 4440262 | P613: =IF(O613=0,"",(G613-O613)/O613) -> 0.47909768 | Q613: historical_core_plus_hip3 | R613: complete
A614: 2025-01-20 | B614: 1.6339005e+10 | C614: 0 | D614: 1.6339005e+10 | E614: 6045431.8 | F614: 0 | G614: =E614+F614 -> 6045431.8 | H614: =IF(D614=0,0,C614/D614) -> 0 | I614: =IF(D614=0,0,B614/D614) -> 1 | J614: =E614*H614 -> 0 | K614: =E614*I614 -> 6045431.8 | L614: 0 | M614: 6045431.8 | N614: 3956440 | O614: 4201737 | P614: =IF(O614=0,"",(G614-O614)/O614) -> 0.43879349 | Q614: historical_core_plus_hip3 | R614: complete
A615: 2025-01-21 | B615: 8.3419449e+09 | C615: 0 | D615: 8.3419449e+09 | E615: 3086519.6 | F615: 0 | G615: =E615+F615 -> 3086519.6 | H615: =IF(D615=0,0,C615/D615) -> 0 | I615: =IF(D615=0,0,B615/D615) -> 1 | J615: =E615*H615 -> 0 | K615: =E615*I615 -> 3086519.6 | L615: 0 | M615: 3086519.6 | N615: 2003967 | O615: 2128663 | P615: =IF(O615=0,"",(G615-O615)/O615) -> 0.4499804 | Q615: historical_core_plus_hip3 | R615: complete
A616: 2025-01-22 | B616: 5.2815512e+09 | C616: 0 | D616: 5.2815512e+09 | E616: 1954173.9 | F616: 0 | G616: =E616+F616 -> 1954173.9 | H616: =IF(D616=0,0,C616/D616) -> 0 | I616: =IF(D616=0,0,B616/D616) -> 1 | J616: =E616*H616 -> 0 | K616: =E616*I616 -> 1954173.9 | L616: 0 | M616: 1954173.9 | N616: 1392360 | O616: 1478487 | P616: =IF(O616=0,"",(G616-O616)/O616) -> 0.321739 | Q616: historical_core_plus_hip3 | R616: complete
A617: 2025-01-23 | B617: 1.1321581e+10 | C617: 0 | D617: 1.1321581e+10 | E617: 4188984.9 | F617: 0 | G617: =E617+F617 -> 4188984.9 | H617: =IF(D617=0,0,C617/D617) -> 0 | I617: =IF(D617=0,0,B617/D617) -> 1 | J617: =E617*H617 -> 0 | K617: =E617*I617 -> 4188984.9 | L617: 0 | M617: 4188984.9 | N617: 2736794 | O617: 2906080 | P617: =IF(O617=0,"",(G617-O617)/O617) -> 0.44145547 | Q617: historical_core_plus_hip3 | R617: complete
...

Sheet Monthly Summary
A1: Month | B1: Core volume | C1: HIP-3 volume | D1: Total volume | E1: Total fees (21S) | F1: HIP-3 fees (retained 1x) | G1: HIP-3 fees (total 2x) | H1: HyperEVM fees | I1: Revenue (DefiLlama) | J1: Total fees (DefiLlama)
A2: 2023-05 | B2: =SUM('Daily Breakdown'!B3:B14) -> 7.3395304e+09 | C2: =SUM('Daily Breakdown'!C3:C14) -> 0 | D2: =SUM('Daily Breakdown'!D3:D14) -> 7.3395304e+09 | E2: =SUM('Daily Breakdown'!G3:G14) -> 2715626.3 | F2: =SUM('Daily Breakdown'!J3:J14) -> 0 | G2: =SUM('Daily Breakdown'!L3:L14) -> 0 | H2: =SUM('Daily Breakdown'!F3:F14) -> 0 | I2: =SUM('Daily Breakdown'!N3:N14) -> 0 | J2: =SUM('Daily Breakdown'!O3:O14) -> 0
A3: 2023-06 | B3: =SUM('Daily Breakdown'!B15:B44) -> 1.9381923e+10 | C3: =SUM('Daily Breakdown'!C15:C44) -> 0 | D3: =SUM('Daily Breakdown'!D15:D44) -> 1.9381923e+10 | E3: =SUM('Daily Breakdown'!G15:G44) -> 7171311.4 | F3: =SUM('Daily Breakdown'!J15:J44) -> 0 | G3: =SUM('Daily Breakdown'!L15:L44) -> 0 | H3: =SUM('Daily Breakdown'!F15:F44) -> 0 | I3: =SUM('Daily Breakdown'!N15:N44) -> 0 | J3: =SUM('Daily Breakdown'!O15:O44) -> 0
A4: 2023-07 | B4: =SUM('Daily Breakdown'!B45:B75) -> 1.4160942e+09 | C4: =SUM('Daily Breakdown'!C45:C75) -> 0 | D4: =SUM('Daily Breakdown'!D45:D75) -> 1.4160942e+09 | E4: =SUM('Daily Breakdown'!G45:G75) -> 523954.85 | F4: =SUM('Daily Breakdown'!J45:J75) -> 0 | G4: =SUM('Daily Breakdown'!L45:L75) -> 0 | H4: =SUM('Daily Breakdown'!F45:F75) -> 0 | I4: =SUM('Daily Breakdown'!N45:N75) -> 0 | J4: =SUM('Daily Breakdown'!O45:O75) -> 0
A5: 2023-08 | B5: =SUM('Daily Breakdown'!B76:B106) -> 1.9316452e+09 | C5: =SUM('Daily Breakdown'!C76:C106) -> 0 | D5: =SUM('Daily Breakdown'!D76:D106) -> 1.9316452e+09 | E5: =SUM('Daily Breakdown'!G76:G106) -> 714708.71 | F5: =SUM('Daily Breakdown'!J76:J106) -> 0 | G5: =SUM('Daily Breakdown'!L76:L106) -> 0 | H5: =SUM('Daily Breakdown'!F76:F106) -> 0 | I5: =SUM('Daily Breakdown'!N76:N106) -> 0 | J5: =SUM('Daily Breakdown'!O76:O106) -> 0
A6: 2023-09 | B6: =SUM('Daily Breakdown'!B107:B136) -> 1.3682478e+09 | C6: =SUM('Daily Breakdown'!C107:C136) -> 0 | D6: =SUM('Daily Breakdown'!D107:D136) -> 1.3682478e+09 | E6: =SUM('Daily Breakdown'!G107:G136) -> 506251.68 | F6: =SUM('Daily Breakdown'!J107:J136) -> 0 | G6: =SUM('Daily Breakdown'!L107:L136) -> 0 | H6: =SUM('Daily Breakdown'!F107:F136) -> 0 | I6: =SUM('Daily Breakdown'!N107:N136) -> 0 | J6: =SUM('Daily Breakdown'!O107:O136) -> 0
A7: 2023-10 | B7: =SUM('Daily Breakdown'!B137:B167) -> 1.6466526e+09 | C7: =SUM('Daily Breakdown'!C137:C167) -> 0 | D7: =SUM('Daily Breakdown'!D137:D167) -> 1.6466526e+09 | E7: =SUM('Daily Breakdown'!G137:G167) -> 609261.47 | F7: =SUM('Daily Breakdown'!J137:J167) -> 0 | G7: =SUM('Daily Breakdown'!L137:L167) -> 0 | H7: =SUM('Daily Breakdown'!F137:F167) -> 0 | I7: =SUM('Daily Breakdown'!N137:N167) -> 0 | J7: =SUM('Daily Breakdown'!O137:O167) -> 0
A8: 2023-11 | B8: =SUM('Daily Breakdown'!B168:B197) -> 3.9474931e+09 | C8: =SUM('Daily Breakdown'!C168:C197) -> 0 | D8: =SUM('Daily Breakdown'!D168:D197) -> 3.9474931e+09 | E8: =SUM('Daily Breakdown'!G168:G197) -> 1460572.4 | F8: =SUM('Daily Breakdown'!J168:J197) -> 0 | G8: =SUM('Daily Breakdown'!L168:L197) -> 0 | H8: =SUM('Daily Breakdown'!F168:F197) -> 0 | I8: =SUM('Daily Breakdown'!N168:N197) -> 0 | J8: =SUM('Daily Breakdown'!O168:O197) -> 0
A9: 2023-12 | B9: =SUM('Daily Breakdown'!B198:B228) -> 1.0181166e+10 | C9: =SUM('Daily Breakdown'!C198:C228) -> 0 | D9: =SUM('Daily Breakdown'!D198:D228) -> 1.0181166e+10 | E9: =SUM('Daily Breakdown'!G198:G228) -> 3767031.5 | F9: =SUM('Daily Breakdown'!J198:J228) -> 0 | G9: =SUM('Daily Breakdown'!L198:L228) -> 0 | H9: =SUM('Daily Breakdown'!F198:F228) -> 0 | I9: =SUM('Daily Breakdown'!N198:N228) -> 0 | J9: =SUM('Daily Breakdown'!O198:O228) -> 0
A10: 2024-01 | B10: =SUM('Daily Breakdown'!B229:B259) -> 1.7411821e+10 | C10: =SUM('Daily Breakdown'!C229:C259) -> 0 | D10: =SUM('Daily Breakdown'!D229:D259) -> 1.7411821e+10 | E10: =SUM('Daily Breakdown'!G229:G259) -> 6442373.8 | F10: =SUM('Daily Breakdown'!J229:J259) -> 0 | G10: =SUM('Daily Breakdown'!L229:L259) -> 0 | H10: =SUM('Daily Breakdown'!F229:F259) -> 0 | I10: =SUM('Daily Breakdown'!N229:N259) -> 0 | J10: =SUM('Daily Breakdown'!O229:O259) -> 0
A11: 2024-02 | B11: =SUM('Daily Breakdown'!B260:B288) -> 3.3043241e+10 | C11: =SUM('Daily Breakdown'!C260:C288) -> 0 | D11: =SUM('Daily Breakdown'!D260:D288) -> 3.3043241e+10 | E11: =SUM('Daily Breakdown'!G260:G288) -> 12225999 | F11: =SUM('Daily Breakdown'!J260:J288) -> 0 | G11: =SUM('Daily Breakdown'!L260:L288) -> 0 | H11: =SUM('Daily Breakdown'!F260:F288) -> 0 | I11: =SUM('Daily Breakdown'!N260:N288) -> 0 | J11: =SUM('Daily Breakdown'!O260:O288) -> 0
A12: 2024-03 | B12: =SUM('Daily Breakdown'!B289:B319) -> 5.2343861e+10 | C12: =SUM('Daily Breakdown'!C289:C319) -> 0 | D12: =SUM('Daily Breakdown'!D289:D319) -> 5.2343861e+10 | E12: =SUM('Daily Breakdown'!G289:G319) -> 19367228 | F12: =SUM('Daily Breakdown'!J289:J319) -> 0 | G12: =SUM('Daily Breakdown'!L289:L319) -> 0 | H12: =SUM('Daily Breakdown'!F289:F319) -> 0 | I12: =SUM('Daily Breakdown'!N289:N319) -> 0 | J12: =SUM('Daily Breakdown'!O289:O319) -> 0
A13: 2024-04 | B13: =SUM('Daily Breakdown'!B320:B349) -> 4.4816013e+10 | C13: =SUM('Daily Breakdown'!C320:C349) -> 0 | D13: =SUM('Daily Breakdown'!D320:D349) -> 4.4816013e+10 | E13: =SUM('Daily Breakdown'!G320:G349) -> 16581925 | F13: =SUM('Daily Breakdown'!J320:J349) -> 0 | G13: =SUM('Daily Breakdown'!L320:L349) -> 0 | H13: =SUM('Daily Breakdown'!F320:F349) -> 0 | I13: =SUM('Daily Breakdown'!N320:N349) -> 0 | J13: =SUM('Daily Breakdown'!O320:O349) -> 0
A14: 2024-05 | B14: =SUM('Daily Breakdown'!B350:B380) -> 2.6186164e+10 | C14: =SUM('Daily Breakdown'!C350:C380) -> 0 | D14: =SUM('Daily Breakdown'!D350:D380) -> 2.6186164e+10 | E14: =SUM('Daily Breakdown'!G350:G380) -> 9688880.4 | F14: =SUM('Daily Breakdown'!J350:J380) -> 0 | G14: =SUM('Daily Breakdown'!L350:L380) -> 0 | H14: =SUM('Daily Breakdown'!F350:F380) -> 0 | I14: =SUM('Daily Breakdown'!N350:N380) -> 0 | J14: =SUM('Daily Breakdown'!O350:O380) -> 0
A15: 2024-06 | B15: =SUM('Daily Breakdown'!B381:B410) -> 2.5939755e+10 | C15: =SUM('Daily Breakdown'!C381:C410) -> 0 | D15: =SUM('Daily Breakdown'!D381:D410) -> 2.5939755e+10 | E15: =SUM('Daily Breakdown'!G381:G410) -> 9597709.3 | F15: =SUM('Daily Breakdown'!J381:J410) -> 0 | G15: =SUM('Daily Breakdown'!L381:L410) -> 0 | H15: =SUM('Daily Breakdown'!F381:F410) -> 0 | I15: =SUM('Daily Breakdown'!N381:N410) -> 0 | J15: =SUM('Daily Breakdown'!O381:O410) -> 0
A16: 2024-07 | B16: =SUM('Daily Breakdown'!B411:B441) -> 3.31262e+10 | C16: =SUM('Daily Breakdown'!C411:C441) -> 0 | D16: =SUM('Daily Breakdown'!D411:D441) -> 3.31262e+10 | E16: =SUM('Daily Breakdown'!G411:G441) -> 12256694 | F16: =SUM('Daily Breakdown'!J411:J441) -> 0 | G16: =SUM('Daily Breakdown'!L411:L441) -> 0 | H16: =SUM('Daily Breakdown'!F411:F441) -> 0 | I16: =SUM('Daily Breakdown'!N411:N441) -> 0 | J16: =SUM('Daily Breakdown'!O411:O441) -> 0
A17: 2024-08 | B17: =SUM('Daily Breakdown'!B442:B472) -> 3.5157295e+10 | C17: =SUM('Daily Breakdown'!C442:C472) -> 0 | D17: =SUM('Daily Breakdown'!D442:D472) -> 3.5157295e+10 | E17: =SUM('Daily Breakdown'!G442:G472) -> 13008199 | F17: =SUM('Daily Breakdown'!J442:J472) -> 0 | G17: =SUM('Daily Breakdown'!L442:L472) -> 0 | H17: =SUM('Daily Breakdown'!F442:F472) -> 0 | I17: =SUM('Daily Breakdown'!N442:N472) -> 0 | J17: =SUM('Daily Breakdown'!O442:O472) -> 0
A18: 2024-09 | B18: =SUM('Daily Breakdown'!B473:B502) -> 2.9680392e+10 | C18: =SUM('Daily Breakdown'!C473:C502) -> 0 | D18: =SUM('Daily Breakdown'!D473:D502) -> 2.9680392e+10 | E18: =SUM('Daily Breakdown'!G473:G502) -> 10981745 | F18: =SUM('Daily Breakdown'!J473:J502) -> 0 | G18: =SUM('Daily Breakdown'!L473:L502) -> 0 | H18: =SUM('Daily Breakdown'!F473:F502) -> 0 | I18: =SUM('Daily Breakdown'!N473:N502) -> 0 | J18: =SUM('Daily Breakdown'!O473:O502) -> 0
A19: 2024-10 | B19: =SUM('Daily Breakdown'!B503:B533) -> 3.5869893e+10 | C19: =SUM('Daily Breakdown'!C503:C533) -> 0 | D19: =SUM('Daily Breakdown'!D503:D533) -> 3.5869893e+10 | E19: =SUM('Daily Breakdown'!G503:G533) -> 13271860 | F19: =SUM('Daily Breakdown'!J503:J533) -> 0 | G19: =SUM('Daily Breakdown'!L503:L533) -> 0 | H19: =SUM('Daily Breakdown'!F503:F533) -> 0 | I19: =SUM('Daily Breakdown'!N503:N533) -> 0 | J19: =SUM('Daily Breakdown'!O503:O533) -> 0
A20: 2024-11 | B20: =SUM('Daily Breakdown'!B534:B563) -> 7.3441019e+10 | C20: =SUM('Daily Breakdown'!C534:C563) -> 0 | D20: =SUM('Daily Breakdown'!D534:D563) -> 7.3441019e+10 | E20: =SUM('Daily Breakdown'!G534:G563) -> 27173177 | F20: =SUM('Daily Breakdown'!J534:J563) -> 0 | G20: =SUM('Daily Breakdown'!L534:L563) -> 0 | H20: =SUM('Daily Breakdown'!F534:F563) -> 0 | I20: =SUM('Daily Breakdown'!N534:N563) -> 0 | J20: =SUM('Daily Breakdown'!O534:O563) -> 0
A21: 2024-12 | B21: =SUM('Daily Breakdown'!B564:B594) -> 1.6305425e+11 | C21: =SUM('Daily Breakdown'!C564:C594) -> 0 | D21: =SUM('Daily Breakdown'!D564:D594) -> 1.6305425e+11 | E21: =SUM('Daily Breakdown'!G564:G594) -> 60330071 | F21: =SUM('Daily Breakdown'!J564:J594) -> 0 | G21: =SUM('Daily Breakdown'!L564:L594) -> 0 | H21: =SUM('Daily Breakdown'!F564:F594) -> 0 | I21: =SUM('Daily Breakdown'!N564:N594) -> 10510315 | J21: =SUM('Daily Breakdown'!O564:O594) -> 11116222
A22: 2025-01 | B22: =SUM('Daily Breakdown'!B595:B625) -> 1.9497818e+11 | C22: =SUM('Daily Breakdown'!C595:C625) -> 0 | D22: =SUM('Daily Breakdown'!D595:D625) -> 1.9497818e+11 | E22: =SUM('Daily Breakdown'!G595:G625) -> 72141925 | F22: =SUM('Daily Breakdown'!J595:J625) -> 0 | G22: =SUM('Daily Breakdown'!L595:L625) -> 0 | H22: =SUM('Daily Breakdown'!F595:F625) -> 0 | I22: =SUM('Daily Breakdown'!N595:N625) -> 49126542 | J22: =SUM('Daily Breakdown'!O595:O625) -> 52165603
A23: 2025-02 | B23: =SUM('Daily Breakdown'!B626:B653) -> 1.8943457e+11 | C23: =SUM('Daily Breakdown'!C626:C653) -> 0 | D23: =SUM('Daily Breakdown'!D626:D653) -> 1.8943457e+11 | E23: =SUM('Daily Breakdown'!G626:G653) -> 70211919 | F23: =SUM('Daily Breakdown'!J626:J653) -> 0 | G23: =SUM('Daily Breakdown'!L626:L653) -> 0 | H23: =SUM('Daily Breakdown'!F626:F653) -> 121127.18 | I23: =SUM('Daily Breakdown'!N626:N653) -> 44206582 | J23: =SUM('Daily Breakdown'!O626:O653) -> 46585009
A24: 2025-03 | B24: =SUM('Daily Breakdown'!B654:B684) -> 1.7038985e+11 | C24: =SUM('Daily Breakdown'!C654:C684) -> 0 | D24: =SUM('Daily Breakdown'!D654:D684) -> 1.7038985e+11 | E24: =SUM('Daily Breakdown'!G654:G684) -> 63086570 | F24: =SUM('Daily Breakdown'!J654:J684) -> 0 | G24: =SUM('Daily Breakdown'!L654:L684) -> 0 | H24: =SUM('Daily Breakdown'!F654:F684) -> 42323.51 | I24: =SUM('Daily Breakdown'!N654:N684) -> 38687274 | J24: =SUM('Daily Breakdown'!O654:O684) -> 40923469
A25: 2025-04 | B25: =SUM('Daily Breakdown'!B685:B714) -> 1.8768774e+11 | C25: =SUM('Daily Breakdown'!C685:C714) -> 0 | D25: =SUM('Daily Breakdown'!D685:D714) -> 1.8768774e+11 | E25: =SUM('Daily Breakdown'!G685:G714) -> 69535156 | F25: =SUM('Daily Breakdown'!J685:J714) -> 0 | G25: =SUM('Daily Breakdown'!L685:L714) -> 0 | H25: =SUM('Daily Breakdown'!F685:F714) -> 90693.97 | I25: =SUM('Daily Breakdown'!N685:N714) -> 41660180 | J25: =SUM('Daily Breakdown'!O685:O714) -> 44237098
A26: 2025-05 | B26: =SUM('Daily Breakdown'!B715:B745) -> 2.4914248e+11 | C26: =SUM('Daily Breakdown'!C715:C745) -> 0 | D26: =SUM('Daily Breakdown'!D715:D745) -> 2.4914248e+11 | E26: =SUM('Daily Breakdown'!G715:G745) -> 93185250 | F26: =SUM('Daily Breakdown'!J715:J745) -> 0 | G26: =SUM('Daily Breakdown'!L715:L745) -> 0 | H26: =SUM('Daily Breakdown'!F715:F745) -> 1002530.9 | I26: =SUM('Daily Breakdown'!N715:N745) -> 68727160 | J26: =SUM('Daily Breakdown'!O715:O745) -> 72978325
A27: 2025-06 | B27: =SUM('Daily Breakdown'!B746:B775) -> 2.1729786e+11 | C27: =SUM('Daily Breakdown'!C746:C775) -> 0 | D27: =SUM('Daily Breakdown'!D746:D775) -> 2.1729786e+11 | E27: =SUM('Daily Breakdown'!G746:G775) -> 80967589 | F27: =SUM('Daily Breakdown'!J746:J775) -> 0 | G27: =SUM('Daily Breakdown'!L746:L775) -> 0 | H27: =SUM('Daily Breakdown'!F746:F775) -> 567381.67 | I27: =SUM('Daily Breakdown'!N746:N775) -> 59460178 | J27: =SUM('Daily Breakdown'!O746:O775) -> 63138126
A28: 2025-07 | B28: =SUM('Daily Breakdown'!B776:B806) -> 3.202451e+11 | C28: =SUM('Daily Breakdown'!C776:C806) -> 0 | D28: =SUM('Daily Breakdown'!D776:D806) -> 3.202451e+11 | E28: =SUM('Daily Breakdown'!G776:G806) -> 1.1916598e+08 | F28: =SUM('Daily Breakdown'!J776:J806) -> 0 | G28: =SUM('Daily Breakdown'!L776:L806) -> 0 | H28: =SUM('Daily Breakdown'!F776:F806) -> 675294.26 | I28: =SUM('Daily Breakdown'!N776:N806) -> 90799094 | J28: =SUM('Daily Breakdown'!O776:O806) -> 96415361
A29: 2025-08 | B29: =SUM('Daily Breakdown'!B807:B837) -> 4.005557e+11 | C29: =SUM('Daily Breakdown'!C807:C837) -> 0 | D29: =SUM('Daily Breakdown'!D807:D837) -> 4.005557e+11 | E29: =SUM('Daily Breakdown'!G807:G837) -> 1.4908709e+08 | F29: =SUM('Daily Breakdown'!J807:J837) -> 0 | G29: =SUM('Daily Breakdown'!L807:L837) -> 0 | H29: =SUM('Daily Breakdown'!F807:F837) -> 881484.21 | I29: =SUM('Daily Breakdown'!N807:N837) -> 127728272 | J29: =SUM('Daily Breakdown'!O807:O837) -> 145395806
A30: 2025-09 | B30: =SUM('Daily Breakdown'!B838:B867) -> 2.7495838e+11 | C30: =SUM('Daily Breakdown'!C838:C867) -> 0 | D30: =SUM('Daily Breakdown'!D838:D867) -> 2.7495838e+11 | E30: =SUM('Daily Breakdown'!G838:G867) -> 1.0323584e+08 | F30: =SUM('Daily Breakdown'!J838:J867) -> 0 | G30: =SUM('Daily Breakdown'!L838:L867) -> 0 | H30: =SUM('Daily Breakdown'!F838:F867) -> 1501235.6 | I30: =SUM('Daily Breakdown'!N838:N867) -> 98239623 | J30: =SUM('Daily Breakdown'!O838:O867) -> 113136362
A31: 2025-10 | B31: =SUM('Daily Breakdown'!B868:B898) -> 3.1883729e+11 | C31: =SUM('Daily Breakdown'!C868:C898) -> 7.5564086e+08 | D31: =SUM('Daily Breakdown'!D868:D898) -> 3.1959293e+11 | E31: =SUM('Daily Breakdown'!G868:G898) -> 1.2019284e+08 | F31: =SUM('Daily Breakdown'!J868:J898) -> 279587.12 | G31: =SUM('Daily Breakdown'!L868:L898) -> 555309.91 | H31: =SUM('Daily Breakdown'!F868:F898) -> 1943452.4 | I31: =SUM('Daily Breakdown'!N868:N898) -> 104550047 | J31: =SUM('Daily Breakdown'!O868:O898) -> 117061228
A32: 2025-11 | B32: =SUM('Daily Breakdown'!B899:B928) -> 2.4936946e+11 | C32: =SUM('Daily Breakdown'!C899:C928) -> 4.2113124e+09 | D32: =SUM('Daily Breakdown'!D899:D928) -> 2.5358078e+11 | E32: =SUM('Daily Breakdown'!G899:G928) -> 94987044 | F32: =SUM('Daily Breakdown'!J899:J928) -> 1558185.6 | G32: =SUM('Daily Breakdown'!L899:L928) -> 3018211.9 | H32: =SUM('Daily Breakdown'!F899:F928) -> 1162157.4 | I32: =SUM('Daily Breakdown'!N899:N928) -> 89878614 | J32: =SUM('Daily Breakdown'!O899:O928) -> 100711740
A33: 2025-12 | B33: =SUM('Daily Breakdown'!B929:B959) -> 1.6455138e+11 | C33: =SUM('Daily Breakdown'!C929:C959) -> 8.1310232e+09 | D33: =SUM('Daily Breakdown'!D929:D959) -> 1.726824e+11 | E33: =SUM('Daily Breakdown'!G929:G959) -> 64594583 | F33: =SUM('Daily Breakdown'!J929:J959) -> 3008478.6 | G33: =SUM('Daily Breakdown'!L929:L959) -> 5722118.5 | H33: =SUM('Daily Breakdown'!F929:F959) -> 702094.42 | I33: =SUM('Daily Breakdown'!N929:N959) -> 60628332 | J33: =SUM('Daily Breakdown'!O929:O959) -> 68765847
A34: 2026-01 | B34: =SUM('Daily Breakdown'!B960:B990) -> 1.8832788e+11 | C34: =SUM('Daily Breakdown'!C960:C990) -> 2.497972e+10 | D34: =SUM('Daily Breakdown'!D960:D990) -> 2.133076e+11 | E34: =SUM('Daily Breakdown'!G960:G990) -> 79541393 | F34: =SUM('Daily Breakdown'!J960:J990) -> 9242496.4 | G34: =SUM('Daily Breakdown'!L960:L990) -> 15705633 | H34: =SUM('Daily Breakdown'!F960:F990) -> 617579.87 | I34: =SUM('Daily Breakdown'!N960:N990) -> 68792903 | J34: =SUM('Daily Breakdown'!O960:O990) -> 76558259
A35: 2026-02 | B35: =SUM('Daily Breakdown'!B991:B1018) -> 1.6608249e+11 | C35: =SUM('Daily Breakdown'!C991:C1018) -> 4.0443835e+10 | D35: =SUM('Daily Breakdown'!D991:D1018) -> 2.0652633e+11 | E35: =SUM('Daily Breakdown'!G991:G1018) -> 77160582 | F35: =SUM('Daily Breakdown'!J991:J1018) -> 14964219 | G35: =SUM('Daily Breakdown'!L991:L1018) -> 24616417 | H35: =SUM('Daily Breakdown'!F991:F1018) -> 745839.68 | I35: =SUM('Daily Breakdown'!N991:N1018) -> 62064961 | J35: =SUM('Daily Breakdown'!O991:O1018) -> 69276165
A36: 2026-03 | B36: =SUM('Daily Breakdown'!B1019:B1049) -> 1.45768e+11 | C36: =SUM('Daily Breakdown'!C1019:C1049) -> 6.8661613e+10 | D36: =SUM('Daily Breakdown'!D1019:D1049) -> 2.1442961e+11 | E36: =SUM('Daily Breakdown'!G1019:G1049) -> 79829481 | F36: =SUM('Daily Breakdown'!J1019:J1049) -> 25404797 | G36: =SUM('Daily Breakdown'!L1019:L1049) -> 37966438 | H36: =SUM('Daily Breakdown'!F1019:F1049) -> 490523.5 | I36: =SUM('Daily Breakdown'!N1019:N1049) -> 61400023 | J36: =SUM('Daily Breakdown'!O1019:O1049) -> 69123186
A37: 2026-04 | B37: =SUM('Daily Breakdown'!B1050:B1079) -> 1.219444e+11 | C37: =SUM('Daily Breakdown'!C1050:C1079) -> 6.5070104e+10 | D37: =SUM('Daily Breakdown'!D1050:D1079) -> 1.870145e+11 | E37: =SUM('Daily Breakdown'!G1050:G1079) -> 69453874 | F37: =SUM('Daily Breakdown'!J1050:J1079) -> 24075938 | G37: =SUM('Daily Breakdown'!L1050:L1079) -> 35334751 | H37: =SUM('Daily Breakdown'!F1050:F1079) -> 258509.46 | I37: =SUM('Daily Breakdown'!N1050:N1079) -> 52216846 | J37: =SUM('Daily Breakdown'!O1050:O1079) -> 58772635
A38: 2026-05 | B38: =SUM('Daily Breakdown'!B1080:B1097) -> 76033314215 | C38: =SUM('Daily Breakdown'!C1080:C1097) -> 3.7160085e+10 | D38: =SUM('Daily Breakdown'!D1080:D1097) -> 1.131934e+11 | E38: =SUM('Daily Breakdown'!G1080:G1097) -> 42177330 | F38: =SUM('Daily Breakdown'!J1080:J1097) -> 13749231 | G38: =SUM('Daily Breakdown'!L1080:L1097) -> 20368317 | H38: =SUM('Daily Breakdown'!F1080:F1097) -> 295772.61 | I38: =SUM('Daily Breakdown'!N1080:N1097) -> 31448582 | J38: =SUM('Daily Breakdown'!O1080:O1097) -> 35102304
A39: TOTAL | B39: =SUM(B2:B38) -> 4.2528867e+12 | C39: =SUM(C2:C38) -> 2.4941333e+11 | D39: =SUM(D2:D38) -> 4.5023001e+12 | E39: =SUM(E2:E38) -> 1.676949e+09 | F39: =SUM(F2:F38) -> 92282933 | G39: =SUM(G2:G38) -> 1.432872e+08 | H39: =SUM(H2:H38) -> 11098001 | I39: =SUM(I2:I38) -> 1160125528 | J39: =SUM(J2:J38) -> 1281462745

Sheet Reconciliation
A1: Reconciliation & Validation Checks
A3: Check | B3: Result
A4: Daily rows (21Shares) | B4: =COUNTA('Daily Breakdown'!A3:A1097) -> 1095
A5: Date range | B5: 2023-05-20 to 2026-05-18
A6: First day with HIP-3 volume | B6: 2025-10-13
A7: Partial / rolling-snapshot rows (excluded from clean totals) | B7: 1 (2026-05-18)
A9: INTERNAL CONSISTENCY
A10: Total fees (21S) sum | B10: =SUM('Daily Breakdown'!G3:G1097) -> 1.676949e+09
A11: proxy + HyperEVM sum | B11: =SUM('Daily Breakdown'!E3:E1097)+SUM('Daily Breakdown'!F3:F1097) -> 1.676949e+09
A12: difference (should be 0) | B12: =B10-B11 -> 0
A13: HIP-3 retained + Core retained sum | B13: =SUM('Daily Breakdown'!J3:J1097)+SUM('Daily Breakdown'!K3:K1097) -> 1.665851e+09
A14: vs fee proxy sum (should match) | B14: =SUM('Daily Breakdown'!E3:E1097) -> 1.665851e+09
A15: difference (should be 0) | B15: =B13-B14 -> 3.695488e-05
A16: HIP-3 total(2x) + Core(2x) sum | B16: =SUM('Daily Breakdown'!L3:L1097)+SUM('Daily Breakdown'!M3:M1097) -> 1.665851e+09
A17: vs fee proxy sum (should match) | B17: =SUM('Daily Breakdown'!E3:E1097) -> 1.665851e+09
A18: difference (should be 0) | B18: =B16-B17 -> 0.0099999905
A20: CROSS-SOURCE (overlap period 2024-12-23 to 2026-05-18)
A21: 21Shares total fees (proxy), overlap | B21: =SUMPRODUCT(('Daily Breakdown'!O3:O1097<>"")*'Daily Breakdown'!G3:G1097) -> 1.4533598e+09
A22: DefiLlama total fees, overlap | B22: =SUM('Daily Breakdown'!O3:O1097) -> 1281462745
A23: ratio 21S / DL | B23: =B21/B22 -> 1.1341413
A24: DefiLlama total revenue, overlap | B24: =SUM('Daily Breakdown'!N3:N1097) -> 1160125528
A25: implied revenue/fee ratio (DL) | B25: =B24/B22 -> 0.9053135

Sheet Notes & Methodology
A1: Hyperliquid — Fees & Revenue Breakdown by Category
A3: SOURCES
A4: 21Shares | B4: Dune query 6874521 'Hyperliquid Daily Fees (Core + HIP-3 Trading Proxy + HyperEVM)'.
B5: Provides daily core vs HIP-3 VOLUME split, a blended trading-fee PROXY, and HyperEVM fees.
A6: DefiLlama | B6: api.llama.fi/summary/fees/hyperliquid — daily fees and daily revenue. Used for revenue
B7: and as an independent cross-check on the 21Shares fee proxy. Retrieved 2026-05-19.
A9: KEY METHODOLOGY POINTS
A10: Fee proxy | B10: 21Shares 'total fees' is a PROXY: a flat fee rate applied to trading volume, NOT actual
B11: collected fees. It will not exactly equal DefiLlama's on-chain fees. Treat as an estimate.
A12: HIP-3 split | B12: The 21Shares proxy is blended across core + HIP-3. It is split here by volume share.
B13: Two bases are shown because HIP-3 markets charge ~2x the standard fee rate:
A14: retained / 1x | B14: Proxy apportioned by RAW volume share. Equals HIP-3 fees on a core-equivalent rate
B15: Equals the portion retained by Hyperliquid (HL keeps ~half of the 2x HIP-3 fee).
A16: total / 2x | B16: Proxy apportioned by 2x-weighted HIP-3 volume. Approximates TOTAL HIP-3 fees paid by
B17: users (incl. the HIP-3 builder/deployer's half). Use for gross user-paid fee figures.
A18: Revenue | B18: Hyperliquid protocol revenue (Assistance Fund HYPE buybacks, ~97-99% of perp/spot
B19: fees; 1-3% to HLP). Sourced from DefiLlama; the 21Shares query has no revenue series.
A20: HIP-3 start | B20: HIP-3 volume first appears 2025-10-13 in the data. Earlier rows are core-only.
A21: Partial day | B21: 2026-05-18 is flagged 'rolling_24h_snapshot' (live API), not a completed day.
B22: It is highlighted yellow on the Daily Breakdown tab; exclude it from clean period totals.
A24: CAVEATS
B25: 21Shares fees are volume-derived estimates; DefiLlama fees are on-chain actuals. A gap
B26: between them is expected, not an error. The Reconciliation tab shows the ratio.
B27: The HIP-3 2x split is an approximation: it assumes a uniform 2x multiple and uniform
B28: rate across markets. Actual per-market HIP-3 fee scales vary (deployers set 0-300%).
