Workbook
Name AfShare: Assumptions!$B$18
Name AprCoef: Assumptions!$B$25
Name BaseMakerRate: Assumptions!$B$6
Name BaseTakerRate: Assumptions!$B$5
Name CoreBpsBlended: Assumptions!$B$7
Name GrowthModeDate: Assumptions!$B$21
Name GrowthModeFactor: Assumptions!$B$8
Name HIP3DeployerShare_50: Assumptions!$B$10
Name HIP3DeployerShare_Hyna: Assumptions!$B$12
Name Hip3LaunchDate: Assumptions!$B$20
Name HIP3TraderScale_50: Assumptions!$B$9
Name HIP3TraderScale_Hyna: Assumptions!$B$11
Name Hip4LaunchDate: Assumptions!$B$22
Name Hip4Rate: Assumptions!$B$23
Name HlpChangeDate: Assumptions!$B$16
Name HlpSharePost: Assumptions!$B$15
Name HlpSharePre: Assumptions!$B$14

Sheet Assumptions
A1: Hyperliquid Master Model — Assumptions
A2: Edit yellow cells to flex the model. All Daily Master formulas reference these names.
A3: Parameter | B3: Value | C3: Format | D3: Source / Note | E3: Defined Name
A4: FEE FLOW (from Hyperliquid docs)
A5: Base perp taker rate (tier 0) | B5: 0.00045 | C5: 0.0000% | D5: Source: Hyperliquid docs > Trading > Fees: tier 0 taker = 0.045% | E5: BaseTakerRate
A6: Base perp maker rate (tier 0) | B6: 0.00015 | C6: 0.0000% | D6: Source: Hyperliquid docs > Trading > Fees: tier 0 maker = 0.015% | E6: BaseMakerRate
A7: Empirical blended core bps (vol-weighted, pre-HIP-3) | B7: 2.897 | C7: 0.000 | D7: Derived from Dec 23 2024 - Oct 12 2025 data: total_perp_fees / total_perp_volume × 10000 | E7: CoreBpsBlended
A8: Growth mode discount factor | B8: 0.1 | C8: 0.0% | D8: Source: Hyperliquid HIP-3 Growth Mode (Nov 19 2025): 90% fee reduction | E8: GrowthModeFactor
A9: HIP-3 trader scale (deployerFeeScale=1, most dexes) | B9: 2 | C9: 0.00 | D9: Source: Hyperliquid fee formula: scaleIfHip3 = deployerFeeScale × 2 when ≥ 1 | E9: HIP3TraderScale_50
A10: HIP-3 deployer share (50/50 case) | B10: 0.5 | C10: 0.0% | D10: Source: Hyperliquid fee formula: deployerShare = 0.5 when deployerFeeScale ≥ 1 | E10: HIP3DeployerShare_50
A11: HyENA trader scale (deployerFeeScale=0.1111) | B11: 1.1111 | C11: 0.0000 | D11: HyENA-specific: 1 + 0.1111 | E11: HIP3TraderScale_Hyna
A12: HyENA deployer share | B12: 0.1 | C12: 0.0% | D12: 0.1111 / (1 + 0.1111) | E12: HIP3DeployerShare_Hyna
A14: HLP REVENUE SHARE — pre Aug 30 2025 | B14: 0.03 | C14: 0.0% | D14: Source: Hyperliquid Fees docs + DefiLlama HLP adapter notes | E14: HlpSharePre
A15: HLP REVENUE SHARE — post Aug 30 2025 | B15: 0.01 | C15: 0.0% | D15: Source: Hyperliquid Fees docs + DefiLlama HLP adapter notes | E15: HlpSharePost
A16: HLP share change date | B16: 45900 | C16: yyyy-mm-dd | D16: Source: empirical observation from DefiLlama data — HLP_fee/revenue ratio dropped from 3.0928% (= 3/97) to 1.0101% (= 1/99) on 2025-08-31 | E16: HlpChangeDate
A18: AF REVENUE SHARE (post HLP cut) | B18: 0.99 | C18: 0.0% | D18: Source: Hyperliquid docs: 99% of fees go to AF for HYPE buybacks (excluding builders/Unit/deployers) | E18: AfShare
... A25: STAKING — APR formula coefficient | B25: 474 | C25: 0 | D25: Source: Hyperliquid docs: at 400M staked, APR ≈ 2.37%. Formula: APR(S) = 474/sqrt(S) | E25: AprCoef

Sheet Daily Master
A1: Daily Master — formulas reference Assumptions sheet
A2: Yellow cells are raw API data. Blue text = formula. All HLP/buyback splits computed dynamically from Assumptions.
A3: Yellow = raw API data; Blue text = Excel formula. Hover over cells for details.
A4: Date | B4: Core perp volume ($) | C4: HIP-3 perp volume ($) | D4: Spot volume ($) | E4: Total perp volume ($) | F4: Total volume incl spot ($) | G4: HIP-3 vol share % | H4: DL Perps fees ($) [raw API] | I4: DL Spot fees ($) [raw API] | J4: DL HLP fees [doublecounted] ($) | K4: Total fees (corrected, Perps+Spot) ($) | L4: Modeled HIP-3 gross fees ($) | M4: Modeled HIP-3 protocol fees ($) | N4: Modeled HIP-3 deployer fees ($) | O4: Implied core fees (Perps - modeled HIP-3 gross) ($) | P4: Implied core bps | Q4: DL Perps revenue (raw API) ($) | R4: DL Spot revenue (raw API) ($) | S4: Total revenue to AF ($) | T4: Effective HLP share % | U4: Implied HLP slice via formula ($) | V4: DL HLP slice (from supplyside_hlp) ($) | W4: HLP slice diff (formula - DL) ($) | X4: DL supplyside total (Y+Z) ($) | Y4: supplyside_perps_usd | Z4: supplyside_spot_usd | AA4: Builders + Unit fees ($) [= X-V] | AB4: DL Holders revenue = AF buyback ($) | AC4: HYPE close price ($) | AD4: HYPE VWAP proxy ($) | AE4: HYPE bought daily (#) | AF4: CHECK: fees=rev+supplyside (=K-S-X) | AG4: CHECK: rev=buyback (=S-AB) | AH4: HP daily total fees ($, indep on-chain) | AI4: HP/DL revenue ratio | AJ4: Total staked HYPE (#) | AK4: Staking APR formula = AprCoef/sqrt(staked) | AL4: Daily HYPE issuance to stakers (#) | AM4: Daily HYPE burned via AF (#) | AN4: Net daily HYPE supply change (#) | AO4: HIP-3 live? | AP4: HIP-4 status | AQ4: # HIP-3 assets active | AR4: # w/ growth mode active
A5: 45066 | B5: 1.4896434e+08 | C5: 0 | E5: =B5+C5 -> 1.4896434e+08 | F5: =E5+D5 -> 1.4896434e+08 | G5: =IFERROR(C5/E5,0) -> 0 | K5: =H5+I5 -> 0 | O5: =IF(H5=0,0,H5-L5) -> 0 | P5: =IF(B5=0,0,O5/B5*10000) -> 0 | S5: =Q5+R5 -> 0 | T5: =IF(A5<HlpChangeDate,HlpSharePre,HlpSharePost) -> 0.03 | U5: =S5*T5/(1-T5) -> 0 | W5: =U5-V5 -> 0 | X5: =Y5+Z5 -> 0 | AA5: =X5-V5 -> 0 | AB5: 0 | AE5: =IFERROR(AB5/AD5,0) -> 0 | AF5: =K5-S5-X5 -> 0 | AG5: =S5-AB5 -> 0 | AI5: =IFERROR(AH5/S5,0) -> 0 | AJ5: 0 | AK5: =IF(AJ5>0,AprCoef/SQRT(AJ5),0) -> 0 | AL5: =AJ5*AK5/365 -> 0 | AM5: =AE5 -> 0 | AN5: =AL5-AM5 -> 0 | AO5: =IF(A5>=Hip3LaunchDate,"YES","") | AP5: =IF(A5<Hip4LaunchDate,"pre-launch","live (zero-fee)") -> pre-launch
A6: 45067 | B6: 1.7817381e+08 | C6: 0 | E6: =B6+C6 -> 1.7817381e+08 | F6: =E6+D6 -> 1.7817381e+08 | G6: =IFERROR(C6/E6,0) -> 0 | K6: =H6+I6 -> 0 | O6: =IF(H6=0,0,H6-L6) -> 0 | P6: =IF(B6=0,0,O6/B6*10000) -> 0 | S6: =Q6+R6 -> 0 | T6: =IF(A6<HlpChangeDate,HlpSharePre,HlpSharePost) -> 0.03 | U6: =S6*T6/(1-T6) -> 0 | W6: =U6-V6 -> 0 | X6: =Y6+Z6 -> 0 | AA6: =X6-V6 -> 0 | AB6: 0 | AE6: =IFERROR(AB6/AD6,0) -> 0 | AF6: =K6-S6-X6 -> 0 | AG6: =S6-AB6 -> 0 | AI6: =IFERROR(AH6/S6,0) -> 0 | AJ6: 0 | AK6: =IF(AJ6>0,AprCoef/SQRT(AJ6),0) -> 0 | AL6: =AJ6*AK6/365 -> 0 | AM6: =AE6 -> 0 | AN6: =AL6-AM6 -> 0 | AO6: =IF(A6>=Hip3LaunchDate,"YES","") | AP6: =IF(A6<Hip4LaunchDate,"pre-launch","live (zero-fee)") -> pre-launch
A7: 45068 | B7: 2.0381289e+08 | C7: 0 | E7: =B7+C7 -> 2.0381289e+08 | F7: =E7+D7 -> 2.0381289e+08 | G7: =IFERROR(C7/E7,0) -> 0 | K7: =H7+I7 -> 0 | O7: =IF(H7=0,0,H7-L7) -> 0 | P7: =IF(B7=0,0,O7/B7*10000) -> 0 | S7: =Q7+R7 -> 0 | T7: =IF(A7<HlpChangeDate,HlpSharePre,HlpSharePost) -> 0.03 | U7: =S7*T7/(1-T7) -> 0 | W7: =U7-V7 -> 0 | X7: =Y7+Z7 -> 0 | AA7: =X7-V7 -> 0 | AB7: 0 | AE7: =IFERROR(AB7/AD7,0) -> 0 | AF7: =K7-S7-X7 -> 0 | AG7: =S7-AB7 -> 0 | AI7: =IFERROR(AH7/S7,0) -> 0 | AJ7: 0 | AK7: =IF(AJ7>0,AprCoef/SQRT(AJ7),0) -> 0 | AL7: =AJ7*AK7/365 -> 0 | AM7: =AE7 -> 0 | AN7: =AL7-AM7 -> 0 | AO7: =IF(A7>=Hip3LaunchDate,"YES","") | AP7: =IF(A7<Hip4LaunchDate,"pre-launch","live (zero-fee)") -> pre-launch
A8: 45069 | B8: 2.3846318e+08 | C8: 0 | E8: =B8+C8 -> 2.3846318e+08 | F8: =E8+D8 -> 2.3846318e+08 | G8: =IFERROR(C8/E8,0) -> 0 | K8: =H8+I8 -> 0 | O8: =IF(H8=0,0,H8-L8) -> 0 | P8: =IF(B8=0,0,O8/B8*10000) -> 0 | S8: =Q8+R8 -> 0 | T8: =IF(A8<HlpChangeDate,HlpSharePre,HlpSharePost) -> 0.03 | U8: =S8*T8/(1-T8) -> 0 | W8: =U8-V8 -> 0 | X8: =Y8+Z8 -> 0 | AA8: =X8-V8 -> 0 | AB8: 0 | AE8: =IFERROR(AB8/AD8,0) -> 0 | AF8: =K8-S8-X8 -> 0 | AG8: =S8-AB8 -> 0 | AI8: =IFERROR(AH8/S8,0) -> 0 | AJ8: 0 | AK8: =IF(AJ8>0,AprCoef/SQRT(AJ8),0) -> 0 | AL8: =AJ8*AK8/365 -> 0 | AM8: =AE8 -> 0 | AN8: =AL8-AM8 -> 0 | AO8: =IF(A8>=Hip3LaunchDate,"YES","") | AP8: =IF(A8<Hip4LaunchDate,"pre-launch","live (zero-fee)") -> pre-launch
A9: 45070 | B9: 4.6949197e+08 | C9: 0 | E9: =B9+C9 -> 4.6949197e+08 | F9: =E9+D9 -> 4.6949197e+08 | G9: =IFERROR(C9/E9,0) -> 0 | K9: =H9+I9 -> 0 | O9: =IF(H9=0,0,H9-L9) -> 0 | P9: =IF(B9=0,0,O9/B9*10000) -> 0 | S9: =Q9+R9 -> 0 | T9: =IF(A9<HlpChangeDate,HlpSharePre,HlpSharePost) -> 0.03 | U9: =S9*T9/(1-T9) -> 0 | W9: =U9-V9 -> 0 | X9: =Y9+Z9 -> 0 | AA9: =X9-V9 -> 0 | AB9: 0 | AE9: =IFERROR(AB9/AD9,0) -> 0 | AF9: =K9-S9-X9 -> 0 | AG9: =S9-AB9 -> 0 | AI9: =IFERROR(AH9/S9,0) -> 0 | AJ9: 0 | AK9: =IF(AJ9>0,AprCoef/SQRT(AJ9),0) -> 0 | AL9: =AJ9*AK9/365 -> 0 | AM9: =AE9 -> 0 | AN9: =AL9-AM9 -> 0 | AO9: =IF(A9>=Hip3LaunchDate,"YES","") | AP9: =IF(A9<Hip4LaunchDate,"pre-launch","live (zero-fee)") -> pre-launch
A10: 45071 | B10: 6.5181124e+08 | C10: 0 | E10: =B10+C10 -> 6.5181124e+08 | F10: =E10+D10 -> 6.5181124e+08 | G10: =IFERROR(C10/E10,0) -> 0 | K10: =H10+I10 -> 0 | O10: =IF(H10=0,0,H10-L10) -> 0 | P10: =IF(B10=0,0,O10/B10*10000) -> 0 | S10: =Q10+R10 -> 0 | T10: =IF(A10<HlpChangeDate,HlpSharePre,HlpSharePost) -> 0.03 | U10: =S10*T10/(1-T10) -> 0 | W10: =U10-V10 -> 0 | X10: =Y10+Z10 -> 0 | AA10: =X10-V10 -> 0 | AB10: 0 | AE10: =IFERROR(AB10/AD10,0) -> 0 | AF10: =K10-S10-X10 -> 0 | AG10: =S10-AB10 -> 0 | AI10: =IFERROR(AH10/S10,0) -> 0 | AJ10: 0 | AK10: =IF(AJ10>0,AprCoef/SQRT(AJ10),0) -> 0 | AL10: =AJ10*AK10/365 -> 0 | AM10: =AE10 -> 0 | AN10: =AL10-AM10 -> 0 | AO10: =IF(A10>=Hip3LaunchDate,"YES","") | AP10: =IF(A10<Hip4LaunchDate,"pre-launch","live (zero-fee)") -> pre-launch
A11: 45072 | B11: 6.3554324e+08 | C11: 0 | E11: =B11+C11 -> 6.3554324e+08 | F11: =E11+D11 -> 6.3554324e+08 | G11: =IFERROR(C11/E11,0) -> 0 | K11: =H11+I11 -> 0 | O11: =IF(H11=0,0,H11-L11) -> 0 | P11: =IF(B11=0,0,O11/B11*10000) -> 0 | S11: =Q11+R11 -> 0 | T11: =IF(A11<HlpChangeDate,HlpSharePre,HlpSharePost) -> 0.03 | U11: =S11*T11/(1-T11) -> 0 | W11: =U11-V11 -> 0 | X11: =Y11+Z11 -> 0 | AA11: =X11-V11 -> 0 | AB11: 0 | AE11: =IFERROR(AB11/AD11,0) -> 0 | AF11: =K11-S11-X11 -> 0 | AG11: =S11-AB11 -> 0 | AI11: =IFERROR(AH11/S11,0) -> 0 | AJ11: 0 | AK11: =IF(AJ11>0,AprCoef/SQRT(AJ11),0) -> 0 | AL11: =AJ11*AK11/365 -> 0 | AM11: =AE11 -> 0 | AN11: =AL11-AM11 -> 0 | AO11: =IF(A11>=Hip3LaunchDate,"YES","") | AP11: =IF(A11<Hip4LaunchDate,"pre-launch","live (zero-fee)") -> pre-launch
A12: 45073 | B12: 6.2926637e+08 | C12: 0 | E12: =B12+C12 -> 6.2926637e+08 | F12: =E12+D12 -> 6.2926637e+08 | G12: =IFERROR(C12/E12,0) -> 0 | K12: =H12+I12 -> 0 | O12: =IF(H12=0,0,H12-L12) -> 0 | P12: =IF(B12=0,0,O12/B12*10000) -> 0 | S12: =Q12+R12 -> 0 | T12: =IF(A12<HlpChangeDate,HlpSharePre,HlpSharePost) -> 0.03 | U12: =S12*T12/(1-T12) -> 0 | W12: =U12-V12 -> 0 | X12: =Y12+Z12 -> 0 | AA12: =X12-V12 -> 0 | AB12: 0 | AE12: =IFERROR(AB12/AD12,0) -> 0 | AF12: =K12-S12-X12 -> 0 | AG12: =S12-AB12 -> 0 | AI12: =IFERROR(AH12/S12,0) -> 0 | AJ12: 0 | AK12: =IF(AJ12>0,AprCoef/SQRT(AJ12),0) -> 0 | AL12: =AJ12*AK12/365 -> 0 | AM12: =AE12 -> 0 | AN12: =AL12-AM12 -> 0 | AO12: =IF(A12>=Hip3LaunchDate,"YES","") | AP12: =IF(A12<Hip4LaunchDate,"pre-launch","live (zero-fee)") -> pre-launch
A13: 45074 | B13: 1.0302869e+09 | C13: 0 | E13: =B13+C13 -> 1.0302869e+09 | F13: =E13+D13 -> 1.0302869e+09 | G13: =IFERROR(C13/E13,0) -> 0 | K13: =H13+I13 -> 0 | O13: =IF(H13=0,0,H13-L13) -> 0 | P13: =IF(B13=0,0,O13/B13*10000) -> 0 | S13: =Q13+R13 -> 0 | T13: =IF(A13<HlpChangeDate,HlpSharePre,HlpSharePost) -> 0.03 | U13: =S13*T13/(1-T13) -> 0 | W13: =U13-V13 -> 0 | X13: =Y13+Z13 -> 0 | AA13: =X13-V13 -> 0 | AB13: 0 | AE13: =IFERROR(AB13/AD13,0) -> 0 | AF13: =K13-S13-X13 -> 0 | AG13: =S13-AB13 -> 0 | AI13: =IFERROR(AH13/S13,0) -> 0 | AJ13: 0 | AK13: =IF(AJ13>0,AprCoef/SQRT(AJ13),0) -> 0 | AL13: =AJ13*AK13/365 -> 0 | AM13: =AE13 -> 0 | AN13: =AL13-AM13 -> 0 | AO13: =IF(A13>=Hip3LaunchDate,"YES","") | AP13: =IF(A13<Hip4LaunchDate,"pre-launch","live (zero-fee)") -> pre-launch
A14: 45075 | B14: 1.6653697e+09 | C14: 0 | E14: =B14+C14 -> 1.6653697e+09 | F14: =E14+D14 -> 1.6653697e+09 | G14: =IFERROR(C14/E14,0) -> 0 | K14: =H14+I14 -> 0 | O14: =IF(H14=0,0,H14-L14) -> 0 | P14: =IF(B14=0,0,O14/B14*10000) -> 0 | S14: =Q14+R14 -> 0 | T14: =IF(A14<HlpChangeDate,HlpSharePre,HlpSharePost) -> 0.03 | U14: =S14*T14/(1-T14) -> 0 | W14: =U14-V14 -> 0 | X14: =Y14+Z14 -> 0 | AA14: =X14-V14 -> 0 | AB14: 0 | AE14: =IFERROR(AB14/AD14,0) -> 0 | AF14: =K14-S14-X14 -> 0 | AG14: =S14-AB14 -> 0 | AI14: =IFERROR(AH14/S14,0) -> 0 | AJ14: 0 | AK14: =IF(AJ14>0,AprCoef/SQRT(AJ14),0) -> 0 | AL14: =AJ14*AK14/365 -> 0 | AM14: =AE14 -> 0 | AN14: =AL14-AM14 -> 0 | AO14: =IF(A14>=Hip3LaunchDate,"YES","") | AP14: =IF(A14<Hip4LaunchDate,"pre-launch","live (zero-fee)") -> pre-launch
A15: 45076 | B15: 7.9048504e+08 | C15: 0 | E15: =B15+C15 -> 7.9048504e+08 | F15: =E15+D15 -> 7.9048504e+08 | G15: =IFERROR(C15/E15,0) -> 0 | K15: =H15+I15 -> 0 | O15: =IF(H15=0,0,H15-L15) -> 0 | P15: =IF(B15=0,0,O15/B15*10000) -> 0 | S15: =Q15+R15 -> 0 | T15: =IF(A15<HlpChangeDate,HlpSharePre,HlpSharePost) -> 0.03 | U15: =S15*T15/(1-T15) -> 0 | W15: =U15-V15 -> 0 | X15: =Y15+Z15 -> 0 | AA15: =X15-V15 -> 0 | AB15: 0 | AE15: =IFERROR(AB15/AD15,0) -> 0 | AF15: =K15-S15-X15 -> 0 | AG15: =S15-AB15 -> 0 | AI15: =IFERROR(AH15/S15,0) -> 0 | AJ15: 0 | AK15: =IF(AJ15>0,AprCoef/SQRT(AJ15),0) -> 0 | AL15: =AJ15*AK15/365 -> 0 | AM15: =AE15 -> 0 | AN15: =AL15-AM15 -> 0 | AO15: =IF(A15>=Hip3LaunchDate,"YES","") | AP15: =IF(A15<Hip4LaunchDate,"pre-launch","live (zero-fee)") -> pre-launch
A16: 45077 | B16: 6.9786168e+08 | C16: 0 | E16: =B16+C16 -> 6.9786168e+08 | F16: =E16+D16 -> 6.9786168e+08 | G16: =IFERROR(C16/E16,0) -> 0 | K16: =H16+I16 -> 0 | O16: =IF(H16=0,0,H16-L16) -> 0 | P16: =IF(B16=0,0,O16/B16*10000) -> 0 | S16: =Q16+R16 -> 0 | T16: =IF(A16<HlpChangeDate,HlpSharePre,HlpSharePost) -> 0.03 | U16: =S16*T16/(1-T16) -> 0 | W16: =U16-V16 -> 0 | X16: =Y16+Z16 -> 0 | AA16: =X16-V16 -> 0 | AB16: 0 | AE16: =IFERROR(AB16/AD16,0) -> 0 | AF16: =K16-S16-X16 -> 0 | AG16: =S16-AB16 -> 0 | AI16: =IFERROR(AH16/S16,0) -> 0 | AJ16: 0 | AK16: =IF(AJ16>0,AprCoef/SQRT(AJ16),0) -> 0 | AL16: =AJ16*AK16/365 -> 0 | AM16: =AE16 -> 0 | AN16: =AL16-AM16 -> 0 | AO16: =IF(A16>=Hip3LaunchDate,"YES","") | AP16: =IF(A16<Hip4LaunchDate,"pre-launch","live (zero-fee)") -> pre-launch
... A492: 45553 | B492: 1.3098399e+09 | C492: 0 | E492: =B492+C492 -> 1.3098399e+09 | F492: =E492+D492 -> 1.3098399e+09 | G492: =IFERROR(C492/E492,0) -> 0 | K492: =H492+I492 -> 0 | O492: =IF(H492=0,0,H492-L492) -> 0 | P492: =IF(B492=0,0,O492/B492*10000) -> 0 | S492: =Q492+R492 -> 0 | T492: =IF(A492<HlpChangeDate,HlpSharePre,HlpSharePost) -> 0.03 | U492: =S492*T492/(1-T492) -> 0 | W492: =U492-V492 -> 0 | X492: =Y492+Z492 -> 0 | AA492: =X492-V492 -> 0 | AB492: 0 | AE492: =IFERROR(AB492/AD492,0) -> 0 | AF492: =K492-S492-X492 -> 0 | AG492: =S492-AB492 -> 0 | AI492: =IFERROR(AH492/S492,0) -> 0 | AJ492: 0 | AK492: =IF(AJ492>0,AprCoef/SQRT(AJ492),0) -> 0 | AL492: =AJ492*AK492/365 -> 0 | AM492: =AE492 -> 0 | AN492: =AL492-AM492 -> 0 | AO492: =IF(A492>=Hip3LaunchDate,"YES","") | AP492: =IF(A492<Hip4LaunchDate,"pre-launch","live (zero-fee)") -> pre-launch
A493: 45554 | B493: 1.7619522e+09 | C493: 0 | D493: 3260099 | E493: =B493+C493 -> 1.7619522e+09 | F493: =E493+D493 -> 1.7652123e+09 | G493: =IFERROR(C493/E493,0) -> 0 | K493: =H493+I493 -> 0 | O493: =IF(H493=0,0,H493-L493) -> 0 | P493: =IF(B493=0,0,O493/B493*10000) -> 0 | S493: =Q493+R493 -> 0 | T493: =IF(A493<HlpChangeDate,HlpSharePre,HlpSharePost) -> 0.03 | U493: =S493*T493/(1-T493) -> 0 | W493: =U493-V493 -> 0 | X493: =Y493+Z493 -> 0 | AA493: =X493-V493 -> 0 | AB493: 0 | AE493: =IFERROR(AB493/AD493,0) -> 0 | AF493: =K493-S493-X493 -> 0 | AG493: =S493-AB493 -> 0 | AI493: =IFERROR(AH493/S493,0) -> 0 | AJ493: 0 | AK493: =IF(AJ493>0,AprCoef/SQRT(AJ493),0) -> 0 | AL493: =AJ493*AK493/365 -> 0 | AM493: =AE493 -> 0 | AN493: =AL493-AM493 -> 0 | AO493: =IF(A493>=Hip3LaunchDate,"YES","") | AP493: =IF(A493<Hip4LaunchDate,"pre-launch","live (zero-fee)") -> pre-launch
A494: 45555 | B494: 1.1603466e+09 | C494: 0 | D494: 4801770 | E494: =B494+C494 -> 1.1603466e+09 | F494: =E494+D494 -> 1.1651484e+09 | G494: =IFERROR(C494/E494,0) -> 0 | K494: =H494+I494 -> 0 | O494: =IF(H494=0,0,H494-L494) -> 0 | P494: =IF(B494=0,0,O494/B494*10000) -> 0 | S494: =Q494+R494 -> 0 | T494: =IF(A494<HlpChangeDate,HlpSharePre,HlpSharePost) -> 0.03 | U494: =S494*T494/(1-T494) -> 0 | W494: =U494-V494 -> 0 | X494: =Y494+Z494 -> 0 | AA494: =X494-V494 -> 0 | AB494: 0 | AE494: =IFERROR(AB494/AD494,0) -> 0 | AF494: =K494-S494-X494 -> 0 | AG494: =S494-AB494 -> 0 | AI494: =IFERROR(AH494/S494,0) -> 0 | AJ494: 0 | AK494: =IF(AJ494>0,AprCoef/SQRT(AJ494),0) -> 0 | AL494: =AJ494*AK494/365 -> 0 | AM494: =AE494 -> 0 | AN494: =AL494-AM494 -> 0 | AO494: =IF(A494>=Hip3LaunchDate,"YES","") | AP494: =IF(A494<Hip4LaunchDate,"pre-launch","live (zero-fee)") -> pre-launch
A495: 45556 | B495: 4.5167684e+08 | C495: 0 | D495: 4983173 | E495: =B495+C495 -> 4.5167684e+08 | F495: =E495+D495 -> 4.5666001e+08 | G495: =IFERROR(C495/E495,0) -> 0 | K495: =H495+I495 -> 0 | O495: =IF(H495=0,0,H495-L495) -> 0 | P495: =IF(B495=0,0,O495/B495*10000) -> 0 | S495: =Q495+R495 -> 0 | T495: =IF(A495<HlpChangeDate,HlpSharePre,HlpSharePost) -> 0.03 | U495: =S495*T495/(1-T495) -> 0 | W495: =U495-V495 -> 0 | X495: =Y495+Z495 -> 0 | AA495: =X495-V495 -> 0 | AB495: 0 | AE495: =IFERROR(AB495/AD495,0) -> 0 | AF495: =K495-S495-X495 -> 0 | AG495: =S495-AB495 -> 0 | AI495: =IFERROR(AH495/S495,0) -> 0 | AJ495: 0 | AK495: =IF(AJ495>0,AprCoef/SQRT(AJ495),0) -> 0 | AL495: =AJ495*AK495/365 -> 0 | AM495: =AE495 -> 0 | AN495: =AL495-AM495 -> 0 | AO495: =IF(A495>=Hip3LaunchDate,"YES","") | AP495: =IF(A495<Hip4LaunchDate,"pre-launch","live (zero-fee)") -> pre-launch
A496: 45557 | B496: 6.6972587e+08 | C496: 0 | D496: 4441106 | E496: =B496+C496 -> 6.6972587e+08 | F496: =E496+D496 -> 6.7416697e+08 | G496: =IFERROR(C496/E496,0) -> 0 | K496: =H496+I496 -> 0 | O496: =IF(H496=0,0,H496-L496) -> 0 | P496: =IF(B496=0,0,O496/B496*10000) -> 0 | S496: =Q496+R496 -> 0 | T496: =IF(A496<HlpChangeDate,HlpSharePre,HlpSharePost) -> 0.03 | U496: =S496*T496/(1-T496) -> 0 | W496: =U496-V496 -> 0 | X496: =Y496+Z496 -> 0 | AA496: =X496-V496 -> 0 | AB496: 0 | AE496: =IFERROR(AB496/AD496,0) -> 0 | AF496: =K496-S496-X496 -> 0 | AG496: =S496-AB496 -> 0 | AI496: =IFERROR(AH496/S496,0) -> 0 | AJ496: 0 | AK496: =IF(AJ496>0,AprCoef/SQRT(AJ496),0) -> 0 | AL496: =AJ496*AK496/365 -> 0 | AM496: =AE496 -> 0 | AN496: =AL496-AM496 -> 0 | AO496: =IF(A496>=Hip3LaunchDate,"YES","") | AP496: =IF(A496<Hip4LaunchDate,"pre-launch","live (zero-fee)") -> pre-launch
A497: 45558 | B497: 1.4264579e+09 | C497: 0 | D497: 9787031 | E497: =B497+C497 -> 1.4264579e+09 | F497: =E497+D497 -> 1.4362449e+09 | G497: =IFERROR(C497/E497,0) -> 0 | K497: =H497+I497 -> 0 | O497: =IF(H497=0,0,H497-L497) -> 0 | P497: =IF(B497=0,0,O497/B497*10000) -> 0 | S497: =Q497+R497 -> 0 | T497: =IF(A497<HlpChangeDate,HlpSharePre,HlpSharePost) -> 0.03 | U497: =S497*T497/(1-T497) -> 0 | W497: =U497-V497 -> 0 | X497: =Y497+Z497 -> 0 | AA497: =X497-V497 -> 0 | AB497: 0 | AE497: =IFERROR(AB497/AD497,0) -> 0 | AF497: =K497-S497-X497 -> 0 | AG497: =S497-AB497 -> 0 | AI497: =IFERROR(AH497/S497,0) -> 0 | AJ497: 0 | AK497: =IF(AJ497>0,AprCoef/SQRT(AJ497),0) -> 0 | AL497: =AJ497*AK497/365 -> 0 | AM497: =AE497 -> 0 | AN497: =AL497-AM497 -> 0 | AO497: =IF(A497>=Hip3LaunchDate,"YES","") | AP497: =IF(A497<Hip4LaunchDate,"pre-launch","live (zero-fee)") -> pre-launch
A498: 45559 | B498: 1.2194153e+09 | C498: 0 | D498: 4003448 | E498: =B498+C498 -> 1.2194153e+09 | F498: =E498+D498 -> 1.2234187e+09 | G498: =IFERROR(C498/E498,0) -> 0 | K498: =H498+I498 -> 0 | O498: =IF(H498=0,0,H498-L498) -> 0 | P498: =IF(B498=0,0,O498/B498*10000) -> 0 | S498: =Q498+R498 -> 0 | T498: =IF(A498<HlpChangeDate,HlpSharePre,HlpSharePost) -> 0.03 | U498: =S498*T498/(1-T498) -> 0 | W498: =U498-V498 -> 0 | X498: =Y498+Z498 -> 0 | AA498: =X498-V498 -> 0 | AB498: 0 | AE498: =IFERROR(AB498/AD498,0) -> 0 | AF498: =K498-S498-X498 -> 0 | AG498: =S498-AB498 -> 0 | AI498: =IFERROR(AH498/S498,0) -> 0 | AJ498: 0 | AK498: =IF(AJ498>0,AprCoef/SQRT(AJ498),0) -> 0 | AL498: =AJ498*AK498/365 -> 0 | AM498: =AE498 -> 0 | AN498: =AL498-AM498 -> 0 | AO498: =IF(A498>=Hip3LaunchDate,"YES","") | AP498: =IF(A498<Hip4LaunchDate,"pre-launch","live (zero-fee)") -> pre-launch
A499: 45560 | B499: 1.206077e+09 | C499: 0 | D499: 4050062 | E499: =B499+C499 -> 1.206077e+09 | F499: =E499+D499 -> 1.2101271e+09 | G499: =IFERROR(C499/E499,0) -> 0 | K499: =H499+I499 -> 0 | O499: =IF(H499=0,0,H499-L499) -> 0 | P499: =IF(B499=0,0,O499/B499*10000) -> 0 | S499: =Q499+R499 -> 0 | T499: =IF(A499<HlpChangeDate,HlpSharePre,HlpSharePost) -> 0.03 | U499: =S499*T499/(1-T499) -> 0 | W499: =U499-V499 -> 0 | X499: =Y499+Z499 -> 0 | AA499: =X499-V499 -> 0 | AB499: 0 | AE499: =IFERROR(AB499/AD499,0) -> 0 | AF499: =K499-S499-X499 -> 0 | AG499: =S499-AB499 -> 0 | AI499: =IFERROR(AH499/S499,0) -> 0 | AJ499: 0 | AK499: =IF(AJ499>0,AprCoef/SQRT(AJ499),0) -> 0 | AL499: =AJ499*AK499/365 -> 0 | AM499: =AE499 -> 0 | AN499: =AL499-AM499 -> 0 | AO499: =IF(A499>=Hip3LaunchDate,"YES","") | AP499: =IF(A499<Hip4LaunchDate,"pre-launch","live (zero-fee)") -> pre-launch
A500: 45561 | B500: 1.6520725e+09 | C500: 0 | D500: 2720909 | E500: =B500+C500 -> 1.6520725e+09 | F500: =E500+D500 -> 1.6547934e+09 | G500: =IFERROR(C500/E500,0) -> 0 | K500: =H500+I500 -> 0 | O500: =IF(H500=0,0,H500-L500) -> 0 | P500: =IF(B500=0,0,O500/B500*10000) -> 0 | S500: =Q500+R500 -> 0 | T500: =IF(A500<HlpChangeDate,HlpSharePre,HlpSharePost) -> 0.03 | U500: =S500*T500/(1-T500) -> 0 | W500: =U500-V500 -> 0 | X500: =Y500+Z500 -> 0 | AA500: =X500-V500 -> 0 | AB500: 0 | AE500: =IFERROR(AB500/AD500,0) -> 0 | AF500: =K500-S500-X500 -> 0 | AG500: =S500-AB500 -> 0 | AI500: =IFERROR(AH500/S500,0) -> 0 | AJ500: 0 | AK500: =IF(AJ500>0,AprCoef/SQRT(AJ500),0) -> 0 | AL500: =AJ500*AK500/365 -> 0 | AM500: =AE500 -> 0 | AN500: =AL500-AM500 -> 0 | AO500: =IF(A500>=Hip3LaunchDate,"YES","") | AP500: =IF(A500<Hip4LaunchDate,"pre-launch","live (zero-fee)") -> pre-launch
A501: 45562 | B501: 1.3608713e+09 | C501: 0 | D501: 3014452 | E501: =B501+C501 -> 1.3608713e+09 | F501: =E501+D501 -> 1.3638857e+09 | G501: =IFERROR(C501/E501,0) -> 0 | K501: =H501+I501 -> 0 | O501: =IF(H501=0,0,H501-L501) -> 0 | P501: =IF(B501=0,0,O501/B501*10000) -> 0 | S501: =Q501+R501 -> 0 | T501: =IF(A501<HlpChangeDate,HlpSharePre,HlpSharePost) -> 0.03 | U501: =S501*T501/(1-T501) -> 0 | W501: =U501-V501 -> 0 | X501: =Y501+Z501 -> 0 | AA501: =X501-V501 -> 0 | AB501: 0 | AE501: =IFERROR(AB501/AD501,0) -> 0 | AF501: =K501-S501-X501 -> 0 | AG501: =S501-AB501 -> 0 | AI501: =IFERROR(AH501/S501,0) -> 0 | AJ501: 0 | AK501: =IF(AJ501>0,AprCoef/SQRT(AJ501),0) -> 0 | AL501: =AJ501*AK501/365 -> 0 | AM501: =AE501 -> 0 | AN501: =AL501-AM501 -> 0 | AO501: =IF(A501>=Hip3LaunchDate,"YES","") | AP501: =IF(A501<Hip4LaunchDate,"pre-launch","live (zero-fee)") -> pre-launch
A502: 45563 | B502: 6.2587922e+08 | C502: 0 | D502: 2447124 | E502: =B502+C502 -> 6.2587922e+08 | F502: =E502+D502 -> 6.2832635e+08 | G502: =IFERROR(C502/E502,0) -> 0 | K502: =H502+I502 -> 0 | O502: =IF(H502=0,0,H502-L502) -> 0 | P502: =IF(B502=0,0,O502/B502*10000) -> 0 | S502: =Q502+R502 -> 0 | T502: =IF(A502<HlpChangeDate,HlpSharePre,HlpSharePost) -> 0.03 | U502: =S502*T502/(1-T502) -> 0 | W502: =U502-V502 -> 0 | X502: =Y502+Z502 -> 0 | AA502: =X502-V502 -> 0 | AB502: 0 | AE502: =IFERROR(AB502/AD502,0) -> 0 | AF502: =K502-S502-X502 -> 0 | AG502: =S502-AB502 -> 0 | AI502: =IFERROR(AH502/S502,0) -> 0 | AJ502: 0 | AK502: =IF(AJ502>0,AprCoef/SQRT(AJ502),0) -> 0 | AL502: =AJ502*AK502/365 -> 0 | AM502: =AE502 -> 0 | AN502: =AL502-AM502 -> 0 | AO502: =IF(A502>=Hip3LaunchDate,"YES","") | AP502: =IF(A502<Hip4LaunchDate,"pre-launch","live (zero-fee)") -> pre-launch
A503: 45564 | B503: 5.6653266e+08 | C503: 0 | D503: 1971820 | E503: =B503+C503 -> 5.6653266e+08 | F503: =E503+D503 -> 5.6850448e+08 | G503: =IFERROR(C503/E503,0) -> 0 | K503: =H503+I503 -> 0 | O503: =IF(H503=0,0,H503-L503) -> 0 | P503: =IF(B503=0,0,O503/B503*10000) -> 0 | S503: =Q503+R503 -> 0 | T503: =IF(A503<HlpChangeDate,HlpSharePre,HlpSharePost) -> 0.03 | U503: =S503*T503/(1-T503) -> 0 | W503: =U503-V503 -> 0 | X503: =Y503+Z503 -> 0 | AA503: =X503-V503 -> 0 | AB503: 0 | AE503: =IFERROR(AB503/AD503,0) -> 0 | AF503: =K503-S503-X503 -> 0 | AG503: =S503-AB503 -> 0 | AI503: =IFERROR(AH503/S503,0) -> 0 | AJ503: 0 | AK503: =IF(AJ503>0,AprCoef/SQRT(AJ503),0) -> 0 | AL503: =AJ503*AK503/365 -> 0 | AM503: =AE503 -> 0 | AN503: =AL503-AM503 -> 0 | AO503: =IF(A503>=Hip3LaunchDate,"YES","") | AP503: =IF(A503<Hip4LaunchDate,"pre-launch","live (zero-fee)") -> pre-launch
A504: 45565 | B504: 1.4412132e+09 | C504: 0 | D504: 2992524 | E504: =B504+C504 -> 1.4412132e+09 | F504: =E504+D504 -> 1.4442057e+09 | G504: =IFERROR(C504/E504,0) -> 0 | K504: =H504+I504 -> 0 | O504: =IF(H504=0,0,H504-L504) -> 0 | P504: =IF(B504=0,0,O504/B504*10000) -> 0 | S504: =Q504+R504 -> 0 | T504: =IF(A504<HlpChangeDate,HlpSharePre,HlpSharePost) -> 0.03 | U504: =S504*T504/(1-T504) -> 0 | W504: =U504-V504 -> 0 | X504: =Y504+Z504 -> 0 | AA504: =X504-V504 -> 0 | AB504: 0 | AE504: =IFERROR(AB504/AD504,0) -> 0 | AF504: =K504-S504-X504 -> 0 | AG504: =S504-AB504 -> 0 | AI504: =IFERROR(AH504/S504,0) -> 0 | AJ504: 0 | AK504: =IF(AJ504>0,AprCoef/SQRT(AJ504),0) -> 0 | AL504: =AJ504*AK504/365 -> 0 | AM504: =AE504 -> 0 | AN504: =AL504-AM504 -> 0 | AO504: =IF(A504>=Hip3LaunchDate,"YES","") | AP504: =IF(A504<Hip4LaunchDate,"pre-launch","live (zero-fee)") -> pre-launch
... A559: 45620 | B559: 2.2105278e+09 | C559: 0 | D559: 2473310 | E559: =B559+C559 -> 2.2105278e+09 | F559: =E559+D559 -> 2.2130012e+09 | G559: =IFERROR(C559/E559,0) -> 0 | K559: =H559+I559 -> 0 | O559: =IF(H559=0,0,H559-L559) -> 0 | P559: =IF(B559=0,0,O559/B559*10000) -> 0 | S559: =Q559+R559 -> 0 | T559: =IF(A559<HlpChangeDate,HlpSharePre,HlpSharePost) -> 0.03 | U559: =S559*T559/(1-T559) -> 0 | W559: =U559-V559 -> 0 | X559: =Y559+Z559 -> 0 | AA559: =X559-V559 -> 0 | AB559: 0 | AE559: =IFERROR(AB559/AD559,0) -> 0 | AF559: =K559-S559-X559 -> 0 | AG559: =S559-AB559 -> 0 | AI559: =IFERROR(AH559/S559,0) -> 0 | AJ559: 0 | AK559: =IF(AJ559>0,AprCoef/SQRT(AJ559),0) -> 0 | AL559: =AJ559*AK559/365 -> 0 | AM559: =AE559 -> 0 | AN559: =AL559-AM559 -> 0 | AO559: =IF(A559>=Hip3LaunchDate,"YES","") | AP559: =IF(A559<Hip4LaunchDate,"pre-launch","live (zero-fee)") -> pre-launch
A560: 45621 | B560: 3.2691508e+09 | C560: 0 | D560: 5628946 | E560: =B560+C560 -> 3.2691508e+09 | F560: =E560+D560 -> 3.2747798e+09 | G560: =IFERROR(C560/E560,0) -> 0 | K560: =H560+I560 -> 0 | O560: =IF(H560=0,0,H560-L560) -> 0 | P560: =IF(B560=0,0,O560/B560*10000) -> 0 | S560: =Q560+R560 -> 0 | T560: =IF(A560<HlpChangeDate,HlpSharePre,HlpSharePost) -> 0.03 | U560: =S560*T560/(1-T560) -> 0 | W560: =U560-V560 -> 0 | X560: =Y560+Z560 -> 0 | AA560: =X560-V560 -> 0 | AB560: 0 | AE560: =IFERROR(AB560/AD560,0) -> 0 | AF560: =K560-S560-X560 -> 0 | AG560: =S560-AB560 -> 0 | AH560: 4585090.2 | AI560: =IFERROR(AH560/S560,0) -> 0 | AJ560: 0 | AK560: =IF(AJ560>0,AprCoef/SQRT(AJ560),0) -> 0 | AL560: =AJ560*AK560/365 -> 0 | AM560: =AE560 -> 0 | AN560: =AL560-AM560 -> 0 | AO560: =IF(A560>=Hip3LaunchDate,"YES","") | AP560: =IF(A560<Hip4LaunchDate,"pre-launch","live (zero-fee)") -> pre-launch
A561: 45622 | B561: 3.3938162e+09 | C561: 0 | D561: 7041832 | E561: =B561+C561 -> 3.3938162e+09 | F561: =E561+D561 -> 3.4008581e+09 | G561: =IFERROR(C561/E561,0) -> 0 | K561: =H561+I561 -> 0 | O561: =IF(H561=0,0,H561-L561) -> 0 | P561: =IF(B561=0,0,O561/B561*10000) -> 0 | S561: =Q561+R561 -> 0 | T561: =IF(A561<HlpChangeDate,HlpSharePre,HlpSharePost) -> 0.03 | U561: =S561*T561/(1-T561) -> 0 | W561: =U561-V561 -> 0 | X561: =Y561+Z561 -> 0 | AA561: =X561-V561 -> 0 | AB561: 0 | AE561: =IFERROR(AB561/AD561,0) -> 0 | AF561: =K561-S561-X561 -> 0 | AG561: =S561-AB561 -> 0 | AI561: =IFERROR(AH561/S561,0) -> 0 | AJ561: 0 | AK561: =IF(AJ561>0,AprCoef/SQRT(AJ561),0) -> 0 | AL561: =AJ561*AK561/365 -> 0 | AM561: =AE561 -> 0 | AN561: =AL561-AM561 -> 0 | AO561: =IF(A561>=Hip3LaunchDate,"YES","") | AP561: =IF(A561<Hip4LaunchDate,"pre-launch","live (zero-fee)") -> pre-launch
A562: 45623 | B562: 2.2108559e+09 | C562: 0 | D562: 4131241 | E562: =B562+C562 -> 2.2108559e+09 | F562: =E562+D562 -> 2.2149872e+09 | G562: =IFERROR(C562/E562,0) -> 0 | K562: =H562+I562 -> 0 | O562: =IF(H562=0,0,H562-L562) -> 0 | P562: =IF(B562=0,0,O562/B562*10000) -> 0 | S562: =Q562+R562 -> 0 | T562: =IF(A562<HlpChangeDate,HlpSharePre,HlpSharePost) -> 0.03 | U562: =S562*T562/(1-T562) -> 0 | W562: =U562-V562 -> 0 | X562: =Y562+Z562 -> 0 | AA562: =X562-V562 -> 0 | AB562: 0 | AE562: =IFERROR(AB562/AD562,0) -> 0 | AF562: =K562-S562-X562 -> 0 | AG562: =S562-AB562 -> 0 | AI562: =IFERROR(AH562/S562,0) -> 0 | AJ562: 0 | AK562: =IF(AJ562>0,AprCoef/SQRT(AJ562),0) -> 0 | AL562: =AJ562*AK562/365 -> 0 | AM562: =AE562 -> 0 | AN562: =AL562-AM562 -> 0 | AO562: =IF(A562>=Hip3LaunchDate,"YES","") | AP562: =IF(A562<Hip4LaunchDate,"pre-launch","live (zero-fee)") -> pre-launch
A563: 45624 | B563: 1.7653393e+09 | C563: 0 | D563: 19036485 | E563: =B563+C563 -> 1.7653393e+09 | F563: =E563+D563 -> 1.7843758e+09 | G563: =IFERROR(C563/E563,0) -> 0 | K563: =H563+I563 -> 0 | O563: =IF(H563=0,0,H563-L563) -> 0 | P563: =IF(B563=0,0,O563/B563*10000) -> 0 | S563: =Q563+R563 -> 0 | T563: =IF(A563<HlpChangeDate,HlpSharePre,HlpSharePost) -> 0.03 | U563: =S563*T563/(1-T563) -> 0 | W563: =U563-V563 -> 0 | X563: =Y563+Z563 -> 0 | AA563: =X563-V563 -> 0 | AB563: 0 | AE563: =IFERROR(AB563/AD563,0) -> 0 | AF563: =K563-S563-X563 -> 0 | AG563: =S563-AB563 -> 0 | AI563: =IFERROR(AH563/S563,0) -> 0 | AJ563: 0 | AK563: =IF(AJ563>0,AprCoef/SQRT(AJ563),0) -> 0 | AL563: =AJ563*AK563/365 -> 0 | AM563: =AE563 -> 0 | AN563: =AL563-AM563 -> 0 | AO563: =IF(A563>=Hip3LaunchDate,"YES","") | AP563: =IF(A563<Hip4LaunchDate,"pre-launch","live (zero-fee)") -> pre-launch
A564: 45625 | B564: 1.8146872e+09 | C564: 0 | D564: 951196324 | E564: =B564+C564 -> 1.8146872e+09 | F564: =E564+D564 -> 2.7658836e+09 | G564: =IFERROR(C564/E564,0) -> 0 | K564: =H564+I564 -> 0 | O564: =IF(H564=0,0,H564-L564) -> 0 | P564: =IF(B564=0,0,O564/B564*10000) -> 0 | S564: =Q564+R564 -> 0 | T564: =IF(A564<HlpChangeDate,HlpSharePre,HlpSharePost) -> 0.03 | U564: =S564*T564/(1-T564) -> 0 | W564: =U564-V564 -> 0 | X564: =Y564+Z564 -> 0 | AA564: =X564-V564 -> 0 | AB564: 0 | AC564: 6.252 | AD564: 4.2155 | AE564: =IFERROR(AB564/AD564,0) -> 0 | AF564: =K564-S564-X564 -> 0 | AG564: =S564-AB564 -> 0 | AH564: 2497425.1 | AI564: =IFERROR(AH564/S564,0) -> 0 | AJ564: 0 | AK564: =IF(AJ564>0,AprCoef/SQRT(AJ564),0) -> 0 | AL564: =AJ564*AK564/365 -> 0 | AM564: =AE564 -> 0 | AN564: =AL564-AM564 -> 0 | AO564: =IF(A564>=Hip3LaunchDate,"YES","") | AP564: =IF(A564<Hip4LaunchDate,"pre-launch","live (zero-fee)") -> pre-launch
A565: 45626 | B565: 1.9278396e+09 | C565: 0 | D565: 460835741 | E565: =B565+C565 -> 1.9278396e+09 | F565: =E565+D565 -> 2.3886754e+09 | G565: =IFERROR(C565/E565,0) -> 0 | K565: =H565+I565 -> 0 | O565: =IF(H565=0,0,H565-L565) -> 0 | P565: =IF(B565=0,0,O565/B565*10000) -> 0 | S565: =Q565+R565 -> 0 | T565: =IF(A565<HlpChangeDate,HlpSharePre,HlpSharePost) -> 0.03 | U565: =S565*T565/(1-T565) -> 0 | W565: =U565-V565 -> 0 | X565: =Y565+Z565 -> 0 | AA565: =X565-V565 -> 0 | AB565: 0 | AC565: 8.4985 | AD565: 7.454675 | AE565: =IFERROR(AB565/AD565,0) -> 0 | AF565: =K565-S565-X565 -> 0 | AG565: =S565-AB565 -> 0 | AI565: =IFERROR(AH565/S565,0) -> 0 | AJ565: 0 | AK565: =IF(AJ565>0,AprCoef/SQRT(AJ565),0) -> 0 | AL565: =AJ565*AK565/365 -> 0 | AM565: =AE565 -> 0 | AN565: =AL565-AM565 -> 0 | AO565: =IF(A565>=Hip3LaunchDate,"YES","") | AP565: =IF(A565<Hip4LaunchDate,"pre-launch","live (zero-fee)") -> pre-launch
A566: 45627 | B566: 2.2309523e+09 | C566: 0 | D566: 382137710 | E566: =B566+C566 -> 2.2309523e+09 | F566: =E566+D566 -> 2.61309e+09 | G566: =IFERROR(C566/E566,0) -> 0 | K566: =H566+I566 -> 0 | O566: =IF(H566=0,0,H566-L566) -> 0 | P566: =IF(B566=0,0,O566/B566*10000) -> 0 | S566: =Q566+R566 -> 0 | T566: =IF(A566<HlpChangeDate,HlpSharePre,HlpSharePost) -> 0.03 | U566: =S566*T566/(1-T566) -> 0 | W566: =U566-V566 -> 0 | X566: =Y566+Z566 -> 0 | AA566: =X566-V566 -> 0 | AB566: 0 | AC566: 9.4686 | AD566: 8.98335 | AE566: =IFERROR(AB566/AD566,0) -> 0 | AF566: =K566-S566-X566 -> 0 | AG566: =S566-AB566 -> 0 | AI566: =IFERROR(AH566/S566,0) -> 0 | AJ566: 0 | AK566: =IF(AJ566>0,AprCoef/SQRT(AJ566),0) -> 0 | AL566: =AJ566*AK566/365 -> 0 | AM566: =AE566 -> 0 | AN566: =AL566-AM566 -> 0 | AO566: =IF(A566>=Hip3LaunchDate,"YES","") | AP566: =IF(A566<Hip4LaunchDate,"pre-launch","live (zero-fee)") -> pre-launch
A567: 45628 | B567: 5.3331258e+09 | C567: 0 | D567: 320571512 | E567: =B567+C567 -> 5.3331258e+09 | F567: =E567+D567 -> 5.6536974e+09 | G567: =IFERROR(C567/E567,0) -> 0 | K567: =H567+I567 -> 0 | O567: =IF(H567=0,0,H567-L567) -> 0 | P567: =IF(B567=0,0,O567/B567*10000) -> 0 | S567: =Q567+R567 -> 0 | T567: =IF(A567<HlpChangeDate,HlpSharePre,HlpSharePost) -> 0.03 | U567: =S567*T567/(1-T567) -> 0 | W567: =U567-V567 -> 0 | X567: =Y567+Z567 -> 0 | AA567: =X567-V567 -> 0 | AB567: 0 | AC567: 8.4277 | AD567: 8.68185 | AE567: =IFERROR(AB567/AD567,0) -> 0 | AF567: =K567-S567-X567 -> 0 | AG567: =S567-AB567 -> 0 | AH567: 2313969.7 | AI567: =IFERROR(AH567/S567,0) -> 0 | AJ567: 0 | AK567: =IF(AJ567>0,AprCoef/SQRT(AJ567),0) -> 0 | AL567: =AJ567*AK567/365 -> 0 | AM567: =AE567 -> 0 | AN567: =AL567-AM567 -> 0 | AO567: =IF(A567>=Hip3LaunchDate,"YES","") | AP567: =IF(A567<Hip4LaunchDate,"pre-launch","live (zero-fee)") -> pre-launch
A568: 45629 | B568: 4.8819819e+09 | C568: 0 | D568: 302890343 | E568: =B568+C568 -> 4.8819819e+09 | F568: =E568+D568 -> 5.1848722e+09 | G568: =IFERROR(C568/E568,0) -> 0 | K568: =H568+I568 -> 0 | O568: =IF(H568=0,0,H568-L568) -> 0 | P568: =IF(B568=0,0,O568/B568*10000) -> 0 | S568: =Q568+R568 -> 0 | T568: =IF(A568<HlpChangeDate,HlpSharePre,HlpSharePost) -> 0.03 | U568: =S568*T568/(1-T568) -> 0 | W568: =U568-V568 -> 0 | X568: =Y568+Z568 -> 0 | AA568: =X568-V568 -> 0 | AB568: 0 | AC568: 11.082 | AD568: 9.76005 | AE568: =IFERROR(AB568/AD568,0) -> 0 | AF568: =K568-S568-X568 -> 0 | AG568: =S568-AB568 -> 0 | AI568: =IFERROR(AH568/S568,0) -> 0 | AJ568: 0 | AK568: =IF(AJ568>0,AprCoef/SQRT(AJ568),0) -> 0 | AL568: =AJ568*AK568/365 -> 0 | AM568: =AE568 -> 0 | AN568: =AL568-AM568 -> 0 | AO568: =IF(A568>=Hip3LaunchDate,"YES","") | AP568: =IF(A568<Hip4LaunchDate,"pre-launch","live (zero-fee)") -> pre-launch
A569: 45630 | B569: 6.2259185e+09 | C569: 0 | D569: 318696984 | E569: =B569+C569 -> 6.2259185e+09 | F569: =E569+D569 -> 6.5446155e+09 | G569: =IFERROR(C569/E569,0) -> 0 | K569: =H569+I569 -> 0 | O569: =IF(H569=0,0,H569-L569) -> 0 | P569: =IF(B569=0,0,O569/B569*10000) -> 0 | S569: =Q569+R569 -> 0 | T569: =IF(A569<HlpChangeDate,HlpSharePre,HlpSharePost) -> 0.03 | U569: =S569*T569/(1-T569) -> 0 | W569: =U569-V569 -> 0 | X569: =Y569+Z569 -> 0 | AA569: =X569-V569 -> 0 | AB569: 0 | AC569: 11.403 | AD569: 11.6015 | AE569: =IFERROR(AB569/AD569,0) -> 0 | AF569: =K569-S569-X569 -> 0 | AG569: =S569-AB569 -> 0 | AI569: =IFERROR(AH569/S569,0) -> 0 | AJ569: 0 | AK569: =IF(AJ569>0,AprCoef/SQRT(AJ569),0) -> 0 | AL569: =AJ569*AK569/365 -> 0 | AM569: =AE569 -> 0 | AN569: =AL569-AM569 -> 0 | AO569: =IF(A569>=Hip3LaunchDate,"YES","") | AP569: =IF(A569<Hip4LaunchDate,"pre-launch","live (zero-fee)") -> pre-launch
...

Sheet HIP-3 Model
A1: HIP-3 Per-Asset Fee Model
A2: Formula: effective_bps = CoreBpsBlended × scaleIfHip3 × growthModeFactor. Gross fee $ = vol × bps/10000.
A4: PER-ASSET METADATA (snapshot from Hyperliquid info API)
A5: Asset | B5: Dex | C5: deployerFeeScale | D5: scaleIfHip3 | E5: deployerShare | F5: growthModeFinal | G5: gmChangeDate | H5: Effective bps (if GM active) | I5: Effective bps (if GM inactive)
A6: abcd:USA500 | B6: abcd | C6: 1 | D6: 2 | E6: 0.5 | F6: N/A | H6: =CoreBpsBlended*D6*GrowthModeFactor -> 0.5794 | I6: =CoreBpsBlended*D6 -> 5.794
A7: cash:AMZN | B7: cash | C7: 1 | D7: 2 | E7: 0.5 | F7: enabled | G7: 46049 | H7: =CoreBpsBlended*D7*GrowthModeFactor -> 0.5794 | I7: =CoreBpsBlended*D7 -> 5.794
A8: cash:BTC | B8: cash | C8: 1 | D8: 2 | E8: 0.5 | F8: N/A | H8: =CoreBpsBlended*D8*GrowthModeFactor -> 0.5794 | I8: =CoreBpsBlended*D8 -> 5.794
A9: cash:CAR | B9: cash | C9: 1 | D9: 2 | E9: 0.5 | F9: enabled | G9: 46141 | H9: =CoreBpsBlended*D9*GrowthModeFactor -> 0.5794 | I9: =CoreBpsBlended*D9 -> 5.794
A10: cash:ETH | B10: cash | C10: 1 | D10: 2 | E10: 0.5 | F10: N/A | H10: =CoreBpsBlended*D10*GrowthModeFactor -> 0.5794 | I10: =CoreBpsBlended*D10 -> 5.794
A11: cash:EWY | B11: cash | C11: 1 | D11: 2 | E11: 0.5 | F11: enabled | G11: 46079 | H11: =CoreBpsBlended*D11*GrowthModeFactor -> 0.5794 | I11: =CoreBpsBlended*D11 -> 5.794
A12: cash:GOLD | B12: cash | C12: 1 | D12: 2 | E12: 0.5 | F12: N/A | H12: =CoreBpsBlended*D12*GrowthModeFactor -> 0.5794 | I12: =CoreBpsBlended*D12 -> 5.794
A13: cash:GOOGL | B13: cash | C13: 1 | D13: 2 | E13: 0.5 | F13: enabled | G13: 46049 | H13: =CoreBpsBlended*D13*GrowthModeFactor -> 0.5794 | I13: =CoreBpsBlended*D13 -> 5.794
A14: cash:HOOD | B14: cash | C14: 1 | D14: 2 | E14: 0.5 | F14: enabled | G14: 46049 | H14: =CoreBpsBlended*D14*GrowthModeFactor -> 0.5794 | I14: =CoreBpsBlended*D14 -> 5.794
A15: cash:INTC | B15: cash | C15: 1 | D15: 2 | E15: 0.5 | F15: enabled | G15: 46049 | H15: =CoreBpsBlended*D15*GrowthModeFactor -> 0.5794 | I15: =CoreBpsBlended*D15 -> 5.794
A16: cash:KWEB | B16: cash | C16: 1 | D16: 2 | E16: 0.5 | F16: enabled | G16: 46099 | H16: =CoreBpsBlended*D16*GrowthModeFactor -> 0.5794 | I16: =CoreBpsBlended*D16 -> 5.794
A17: cash:META | B17: cash | C17: 1 | D17: 2 | E17: 0.5 | F17: enabled | G17: 46049 | H17: =CoreBpsBlended*D17*GrowthModeFactor -> 0.5794 | I17: =CoreBpsBlended*D17 -> 5.794
A18: cash:MSFT | B18: cash | C18: 1 | D18: 2 | E18: 0.5 | F18: enabled | G18: 46049 | H18: =CoreBpsBlended*D18*GrowthModeFactor -> 0.5794 | I18: =CoreBpsBlended*D18 -> 5.794
A19: cash:NVDA | B19: cash | C19: 1 | D19: 2 | E19: 0.5 | F19: enabled | G19: 46045 | H19: =CoreBpsBlended*D19*GrowthModeFactor -> 0.5794 | I19: =CoreBpsBlended*D19 -> 5.794
A20: cash:SILVER | B20: cash | C20: 1 | D20: 2 | E20: 0.5 | F20: enabled | G20: 46059 | H20: =CoreBpsBlended*D20*GrowthModeFactor -> 0.5794 | I20: =CoreBpsBlended*D20 -> 5.794
A21: cash:TSLA | B21: cash | C21: 1 | D21: 2 | E21: 0.5 | F21: enabled | G21: 46044 | H21: =CoreBpsBlended*D21*GrowthModeFactor -> 0.5794 | I21: =CoreBpsBlended*D21 -> 5.794
A22: cash:USA500 | B22: cash | C22: 1 | D22: 2 | E22: 0.5 | F22: enabled | G22: 46042 | H22: =CoreBpsBlended*D22*GrowthModeFactor -> 0.5794 | I22: =CoreBpsBlended*D22 -> 5.794
A23: cash:WTI | B23: cash | C23: 1 | D23: 2 | E23: 0.5 | F23: enabled | G23: 46092 | H23: =CoreBpsBlended*D23*GrowthModeFactor -> 0.5794 | I23: =CoreBpsBlended*D23 -> 5.794
A24: flx:BTC | B24: flx | C24: 1 | D24: 2 | E24: 0.5 | F24: N/A | H24: =CoreBpsBlended*D24*GrowthModeFactor -> 0.5794 | I24: =CoreBpsBlended*D24 -> 5.794
A25: flx:COIN | B25: flx | C25: 1 | D25: 2 | E25: 0.5 | F25: enabled | G25: 45985 | H25: =CoreBpsBlended*D25*GrowthModeFactor -> 0.5794 | I25: =CoreBpsBlended*D25 -> 5.794
A26: flx:COPPER | B26: flx | C26: 1 | D26: 2 | E26: 0.5 | F26: enabled | G26: 46051 | H26: =CoreBpsBlended*D26*GrowthModeFactor -> 0.5794 | I26: =CoreBpsBlended*D26 -> 5.794
A27: flx:CRCL | B27: flx | C27: 1 | D27: 2 | E27: 0.5 | F27: enabled | G27: 45985 | H27: =CoreBpsBlended*D27*GrowthModeFactor -> 0.5794 | I27: =CoreBpsBlended*D27 -> 5.794
A28: flx:GAS | B28: flx | C28: 1 | D28: 2 | E28: 0.5 | F28: enabled | G28: 46112 | H28: =CoreBpsBlended*D28*GrowthModeFactor -> 0.5794 | I28: =CoreBpsBlended*D28 -> 5.794
A29: flx:GOLD | B29: flx | C29: 1 | D29: 2 | E29: 0.5 | F29: N/A | H29: =CoreBpsBlended*D29*GrowthModeFactor -> 0.5794 | I29: =CoreBpsBlended*D29 -> 5.794
A30: flx:NVDA | B30: flx | C30: 1 | D30: 2 | E30: 0.5 | F30: enabled | G30: 46089 | H30: =CoreBpsBlended*D30*GrowthModeFactor -> 0.5794 | I30: =CoreBpsBlended*D30 -> 5.794
A31: flx:OIL | B31: flx | C31: 1 | D31: 2 | E31: 0.5 | F31: enabled | G31: 46051 | H31: =CoreBpsBlended*D31*GrowthModeFactor -> 0.5794 | I31: =CoreBpsBlended*D31 -> 5.794
A32: flx:PALLADIUM | B32: flx | C32: 1 | D32: 2 | E32: 0.5 | F32: enabled | G32: 46051 | H32: =CoreBpsBlended*D32*GrowthModeFactor -> 0.5794 | I32: =CoreBpsBlended*D32 -> 5.794
A33: flx:PLATINUM | B33: flx | C33: 1 | D33: 2 | E33: 0.5 | F33: enabled | G33: 46051 | H33: =CoreBpsBlended*D33*GrowthModeFactor -> 0.5794 | I33: =CoreBpsBlended*D33 -> 5.794
A34: flx:SILVER | B34: flx | C34: 1 | D34: 2 | E34: 0.5 | F34: enabled | G34: 46051 | H34: =CoreBpsBlended*D34*GrowthModeFactor -> 0.5794 | I34: =CoreBpsBlended*D34 -> 5.794
A35: flx:TSLA | B35: flx | C35: 1 | D35: 2 | E35: 0.5 | F35: enabled | G35: 45985 | H35: =CoreBpsBlended*D35*GrowthModeFactor -> 0.5794 | I35: =CoreBpsBlended*D35 -> 5.794
A36: flx:USA100 | B36: flx | C36: 1 | D36: 2 | E36: 0.5 | F36: enabled | G36: 46111 | H36: =CoreBpsBlended*D36*GrowthModeFactor -> 0.5794 | I36: =CoreBpsBlended*D36 -> 5.794
A37: flx:USA500 | B37: flx | C37: 1 | D37: 2 | E37: 0.5 | F37: enabled | G37: 46091 | H37: =CoreBpsBlended*D37*GrowthModeFactor -> 0.5794 | I37: =CoreBpsBlended*D37 -> 5.794
A38: flx:USDE | B38: flx | C38: 1 | D38: 2 | E38: 0.5 | F38: N/A | H38: =CoreBpsBlended*D38*GrowthModeFactor -> 0.5794 | I38: =CoreBpsBlended*D38 -> 5.794
A39: flx:XMR | B39: flx | C39: 1 | D39: 2 | E39: 0.5 | F39: N/A | H39: =CoreBpsBlended*D39*GrowthModeFactor -> 0.5794 | I39: =CoreBpsBlended*D39 -> 5.794
A40: hyna:1000PEPE | B40: hyna | C40: 0.1111 | D40: 1.1111 | E40: 0.099991 | F40: N/A | H40: =CoreBpsBlended*D40*GrowthModeFactor -> 0.32188567 | I40: =CoreBpsBlended*D40 -> 3.2188567
A41: hyna:ADA | B41: hyna | C41: 0.1111 | D41: 1.1111 | E41: 0.099991 | F41: N/A | H41: =CoreBpsBlended*D41*GrowthModeFactor -> 0.32188567 | I41: =CoreBpsBlended*D41 -> 3.2188567
...

Sheet HIP-3 by Category
A1: HIP-3 Daily — Volume & Modeled Fees by Asset Category
A2: Volume from Hyperliquid info API candleSnapshot per asset, aggregated by category.
A3: Fees modeled per-asset using growth-mode-aware formula; aggregated to category. See HIP-3 Model sheet.
A5: VOLUME BY CATEGORY ($)
A6: Date | B6: Agriculture | C6: Bonds | D6: Crypto | E6: Energy | F6: Equities — Crypto-related | G6: Equities — Single Name | H6: Equity Indices/ETF | I6: FX | J6: Industrial Metals | K6: Pre-IPO / Private | L6: Precious Metals | M6: Total HIP-3
A7: 45943 | B7: 0 | C7: 0 | D7: 0 | E7: 0 | F7: 0 | G7: 0 | H7: 24137313 | I7: 0 | J7: 0 | K7: 0 | L7: 0 | M7: =SUM(B7:L7) -> 24137313
A8: 45944 | B8: 0 | C8: 0 | D8: 0 | E8: 0 | F8: 0 | G8: 0 | H8: 21893628 | I8: 0 | J8: 0 | K8: 0 | L8: 0 | M8: =SUM(B8:L8) -> 21893628
A9: 45945 | B9: 0 | C9: 0 | D9: 0 | E9: 0 | F9: 0 | G9: 0 | H9: 20602638 | I9: 0 | J9: 0 | K9: 0 | L9: 0 | M9: =SUM(B9:L9) -> 20602638
A10: 45946 | B10: 0 | C10: 0 | D10: 0 | E10: 0 | F10: 0 | G10: 0 | H10: 19139744 | I10: 0 | J10: 0 | K10: 0 | L10: 0 | M10: =SUM(B10:L10) -> 19139744
A11: 45947 | B11: 0 | C11: 0 | D11: 0 | E11: 0 | F11: 0 | G11: 0 | H11: 15100795 | I11: 0 | J11: 0 | K11: 0 | L11: 0 | M11: =SUM(B11:L11) -> 15100795
A12: 45948 | B12: 0 | C12: 0 | D12: 0 | E12: 0 | F12: 0 | G12: 0 | H12: 6243638.8 | I12: 0 | J12: 0 | K12: 0 | L12: 0 | M12: =SUM(B12:L12) -> 6243638.8
A13: 45949 | B13: 0 | C13: 0 | D13: 0 | E13: 0 | F13: 0 | G13: 0 | H13: 7838676.4 | I13: 0 | J13: 0 | K13: 0 | L13: 0 | M13: =SUM(B13:L13) -> 7838676.4
A14: 45950 | B14: 0 | C14: 0 | D14: 0 | E14: 0 | F14: 0 | G14: 0 | H14: 10597513 | I14: 0 | J14: 0 | K14: 0 | L14: 0 | M14: =SUM(B14:L14) -> 10597513
A15: 45951 | B15: 0 | C15: 0 | D15: 0 | E15: 0 | F15: 0 | G15: 0 | H15: 23304373 | I15: 0 | J15: 0 | K15: 0 | L15: 0 | M15: =SUM(B15:L15) -> 23304373
A16: 45952 | B16: 0 | C16: 0 | D16: 0 | E16: 0 | F16: 0 | G16: 0 | H16: 36702797 | I16: 0 | J16: 0 | K16: 0 | L16: 0 | M16: =SUM(B16:L16) -> 36702797
A17: 45953 | B17: 0 | C17: 0 | D17: 0 | E17: 0 | F17: 0 | G17: 0 | H17: 30181937 | I17: 0 | J17: 0 | K17: 0 | L17: 0 | M17: =SUM(B17:L17) -> 30181937
A18: 45954 | B18: 0 | C18: 0 | D18: 0 | E18: 0 | F18: 0 | G18: 0 | H18: 27291720 | I18: 0 | J18: 0 | K18: 0 | L18: 0 | M18: =SUM(B18:L18) -> 27291720
... A226: 46162 | B226: 87327.911 | C226: 9993.4427 | D226: 2115097.8 | E226: 39845360 | F226: 2922661.3 | G226: 46698955 | H226: 99407571 | I226: 414539.84 | J226: 608633.1 | K226: 896499.64 | L226: 52653089 | M226: =SUM(B226:L226) -> 2.4565973e+08
A229: MODELED PROTOCOL FEES BY CATEGORY ($)
A230: Date | B230: Agriculture | C230: Bonds | D230: Crypto | E230: Energy | F230: Equities — Crypto-related | G230: Equities — Single Name | H230: Equity Indices/ETF | I230: FX | J230: Industrial Metals | K230: Pre-IPO / Private | L230: Precious Metals | M230: Total HIP-3 Protocol Fees
A231: 45943 | B231: 0 | C231: 0 | D231: 0 | E231: 0 | F231: 0 | G231: 0 | H231: 6830.8595 | I231: 0 | J231: 0 | K231: 0 | L231: 0 | M231: =SUM(B231:L231) -> 6830.8595
A232: 45944 | B232: 0 | C232: 0 | D232: 0 | E232: 0 | F232: 0 | G232: 0 | H232: 6195.8967 | I232: 0 | J232: 0 | K232: 0 | L232: 0 | M232: =SUM(B232:L232) -> 6195.8967
A233: 45945 | B233: 0 | C233: 0 | D233: 0 | E233: 0 | F233: 0 | G233: 0 | H233: 5830.5466 | I233: 0 | J233: 0 | K233: 0 | L233: 0 | M233: =SUM(B233:L233) -> 5830.5466
A234: 45946 | B234: 0 | C234: 0 | D234: 0 | E234: 0 | F234: 0 | G234: 0 | H234: 5416.5475 | I234: 0 | J234: 0 | K234: 0 | L234: 0 | M234: =SUM(B234:L234) -> 5416.5475
A235: 45947 | B235: 0 | C235: 0 | D235: 0 | E235: 0 | F235: 0 | G235: 0 | H235: 4273.5251 | I235: 0 | J235: 0 | K235: 0 | L235: 0 | M235: =SUM(B235:L235) -> 4273.5251
A236: 45948 | B236: 0 | C236: 0 | D236: 0 | E236: 0 | F236: 0 | G236: 0 | H236: 1766.9498 | I236: 0 | J236: 0 | K236: 0 | L236: 0 | M236: =SUM(B236:L236) -> 1766.9498
A237: 45949 | B237: 0 | C237: 0 | D237: 0 | E237: 0 | F237: 0 | G237: 0 | H237: 2218.3454 | I237: 0 | J237: 0 | K237: 0 | L237: 0 | M237: =SUM(B237:L237) -> 2218.3454
A238: 45950 | B238: 0 | C238: 0 | D238: 0 | E238: 0 | F238: 0 | G238: 0 | H238: 2999.0962 | I238: 0 | J238: 0 | K238: 0 | L238: 0 | M238: =SUM(B238:L238) -> 2999.0962
A239: 45951 | B239: 0 | C239: 0 | D239: 0 | E239: 0 | F239: 0 | G239: 0 | H239: 6595.1376 | I239: 0 | J239: 0 | K239: 0 | L239: 0 | M239: =SUM(B239:L239) -> 6595.1376
A240: 45952 | B240: 0 | C240: 0 | D240: 0 | E240: 0 | F240: 0 | G240: 0 | H240: 10386.891 | I240: 0 | J240: 0 | K240: 0 | L240: 0 | M240: =SUM(B240:L240) -> 10386.891
A241: 45953 | B241: 0 | C241: 0 | D241: 0 | E241: 0 | F241: 0 | G241: 0 | H241: 8541.4881 | I241: 0 | J241: 0 | K241: 0 | L241: 0 | M241: =SUM(B241:L241) -> 8541.4881
A242: 45954 | B242: 0 | C242: 0 | D242: 0 | E242: 0 | F242: 0 | G242: 0 | H242: 7723.5566 | I242: 0 | J242: 0 | K242: 0 | L242: 0 | M242: =SUM(B242:L242) -> 7723.5566
... A450: 46162 | B450: 2.4713799 | C450: 0.28281443 | D450: 329.01269 | E450: 1127.6237 | F450: 190.58119 | G450: 1321.5804 | H450: 2813.2342 | I450: 11.731477 | J450: 17.224317 | K450: 62.602042 | L450: 4267.8267 | M450: =SUM(B450:L450) -> 10144.171

Sheet Reconciliation
A1: Reconciliation & Cross-Source Checks
A2: All values computed via formulas referencing Daily Master sheet. Identity diffs near $0 = clean reconciliation.
A4: --- DEFILLAMA COVERAGE ---
A5: First date with DefiLlama fees | B5: ='Daily Master'!A588 -> 45649
A6: Last date with DefiLlama fees | B6: ='Daily Master'!A1100 -> 46161
A7: Number of days covered | B7: =(1100-588+1) -> 513
A9: --- CORE IDENTITY: fees = revenue + supplyside ---
A10: Sum of identity diffs across all days | B10: =SUM('Daily Master'!AF588:AF1100) -> 5
A11: Max abs identity diff | B11: =SUMPRODUCT(MAX(ABS('Daily Master'!AF588:AF1100))) -> #VALUE!
A12: Average abs identity diff | B12: =SUMPRODUCT(ABS('Daily Master'!AF588:AF1100))/(1100-588+1) -> 0.46978558
A13: -> Should be near 0 (integer rounding only)
A15: --- AF BUYBACK = HOLDERS REVENUE IDENTITY ---
A16: Sum of rev-buyback diffs | B16: =SUM('Daily Master'!AG588:AG1100) -> 0
A17: Max abs diff | B17: =SUMPRODUCT(MAX(ABS('Daily Master'!AG588:AG1100))) -> #VALUE!
A18: -> Should be exactly 0 (same metric)
A20: --- HLP SHARE FORMULA vs DEFILLAMA ---
A21: Sum of formula HLP slice ($) | B21: =SUM('Daily Master'!U588:U1100) -> 22746844
A22: Sum of DL reported HLP slice ($) | B22: =SUM('Daily Master'!V588:V1100) -> 22189875
A23: Diff ($) | B23: =SUM('Daily Master'!W588:W1100) -> 556968.68
A24: Max abs daily diff ($) | B24: =SUMPRODUCT(MAX(ABS('Daily Master'!W588:W1100))) -> #VALUE!
A25: -> Formula uses 3% pre-Aug30 / 1% post; should match DL closely
A27: --- HYPURRSCAN CROSS-CHECK ---
A28: Cum. DL revenue ($) | B28: =SUM('Daily Master'!S588:S1100) -> 1161641075
A29: Cum. HP total fees ($) | B29: =SUM('Daily Master'!AH588:AH1100) -> 1.0682216e+09
A30: HP/DL revenue ratio | B30: =SUM('Daily Master'!AH588:AH1100)/SUM('Daily Master'!S588:S1100) -> 0.91957971
A32: --- CUMULATIVE FEE BREAKDOWN ---
A33: Cum. total gross fees (Perps+Spot) | B33: =SUM('Daily Master'!K588:K1100) -> 1260945873
A34: Cum. revenue to AF | B34: =SUM('Daily Master'!S588:S1100) -> 1161641075
A35: Cum. HLP depositors share | B35: =SUM('Daily Master'!V588:V1100) -> 22189875
A36: Cum. Builders + Unit share | B36: =SUM('Daily Master'!AA588:AA1100) -> 77114918
A37: Check sum: revenue + HLP + builders+unit | B37: =SUM('Daily Master'!S588:S1100)+SUM('Daily Master'!V588:V1100)+SUM('Daily Master'!AA588:AA1100) -> 1260945868
A38: Diff to total fees (should ~ 0) | B38: =SUM('Daily Master'!K588:K1100)-(SUM('Daily Master'!S588:S1100)+SUM('Daily Master'!V588:V1100)+SUM('Daily Master'!AA588:AA1100)) -> 5
A40: --- MODELED HIP-3 vs IMPLIED HIP-3 ---
A41: Cum. modeled HIP-3 protocol fees | B41: =SUM('Daily Master'!M588:M1100) -> 12473867
A42: Cum. modeled HIP-3 deployer fees | B42: =SUM('Daily Master'!N588:N1100) -> 11522443
A43: Cum. modeled HIP-3 gross fees | B43: =SUM('Daily Master'!L588:L1100) -> 23996311
A44: Cum. implied core fees (DL Perps - modeled HIP-3 gross) | B44: =SUM('Daily Master'!O588:O1100) -> 1.1806787e+09
A45: -> Model imperfect (fee tiers vary). Best-effort estimate.
A47: --- BUYBACKS ---
A48: Cum. HYPE bought daily (#) | B48: =SUM('Daily Master'!AE588:AE1100) -> 36433808
...

Sheet Sources & Methodology
A1: Sources & Methodology
A3: PRIMARY SOURCES
A4: Existing user file (21Shares Dune query 6874521) | B4: Daily core & HIP-3 perp volume + 21Shares fee proxy
A5: DefiLlama Fees API | B5: https://api.llama.fi/summary/fees/hyperliquid?dataType=dailyFees / dailyRevenue / dailyHoldersRevenue / dailySupplySideRevenue
A6: DefiLlama DEX volume | B6: https://api.llama.fi/summary/dexs/hyperliquid?dataType=dailyVolume — spot orderbook volume
A7: Hyperliquid Info API — perpDexs | B7: POST https://api.hyperliquid.xyz/info {"type":"perpDexs"} — HIP-3 dex list + deployerFeeScale per dex
A8: Hyperliquid Info API — meta per dex | B8: POST .../info {"type":"meta","dex":"<name>"} — per-asset growthMode + lastGrowthModeChangeTime
A9: Hyperliquid Info API — candleSnapshot | B9: Per-asset daily candles for HIP-3 assets AND HYPE/USDC spot price (@107)
A10: Hyperliquid Info API — validatorSummaries | B10: Current total HYPE staked, predicted APR
A11: Hypurrscan Fees API | B11: https://api.hypurrscan.io/fees — independent cumulative on-chain fees (cross-check)
A12: Hyperliquid Fees doc | B12: https://hyperliquid.gitbook.io/hyperliquid-docs/trading/fees — fee schedule, tiers, formula
A13: Hyperliquid HIP-3 doc | B13: https://hyperliquid.gitbook.io/hyperliquid-docs/hyperliquid-improvement-proposals-hips/hip-3
A14: Hyperliquid HIP-4 doc | B14: https://hyperliquid.gitbook.io/hyperliquid-docs/hyperliquid-improvement-proposals-hips/hip-4-outcome-markets
A15: Hyperliquid Staking doc | B15: https://hyperliquid.gitbook.io/hyperliquid-docs/hypercore/staking — APR formula
A17: HIP-3 FEE MECHANICS — THE CORRECTED PICTURE
A18: Per the official Hyperliquid fee formula in docs:
A19: scaleIfHip3 = (deployerFeeScale × 2) if deployerFeeScale ≥ 1
A20: = (deployerFeeScale + 1) if deployerFeeScale < 1
A21: deployerShare = 0.5 if deployerFeeScale ≥ 1
A22: = deployerFeeScale / (1 + deployerFeeScale) if < 1
A23: trader pays: base_taker × scaleIfHip3 × growthModeScale × (1 - referralDiscount)
A24: growthModeScale = 0.1 if growth mode enabled on that asset, else 1.0
A26: SNAPSHOT (as of May 20, 2026) FROM HYPERLIQUID INFO API:
A27: trade.xyz (xyz): deployerFeeScale=1.0 → trader pays 2x base, 50/50 split
A28: Felix (flx): deployerFeeScale=1.0 → trader pays 2x base, 50/50 split
A29: Ventuals (vntl): deployerFeeScale=1.0 → trader pays 2x base, 50/50 split
... A75: Only one market (daily BTC binary outcome) initially live.
