Workbook

Sheet README
A1: India Data Centre Power - Public-Document Dataset (v3 - multi-state)
A3: Compiled | B3: 19-Oct-2026, from publicly available documents. v2 adds a Maharashtra permit sweep: all 2025-26 SEIAA/SEAC agendas (266 docs), OCR of 66 scanned SEIAA minutes, all MPCB Consent Appraisal Committee reports (132 docs), MERC Case 88/2026, and Parliament answers on DC power demand.
A4: What changed in v3 | B4: Added AP, Telangana, Tamil Nadu, Karnataka, UP, Odisha. New CTU_Bulk_Register sheet: every bulk-consumer (>=50 MW) application for direct central-grid access, classified for data-centre use. New States_Evidence sheet: GOs, ECs, grid sanctions and state dashboards outside Maharashtra. 18 new project rows.
A5: What changed in v2 | B5: New MH_Permits sheet (45 permit records with connected load, DG sets, capital investment). 14 new permit-backed projects (Google x2, AWS Thane & Powai, Microsoft/AdaniConneX Pune, Iron Mountain MUM-3, Chandivali DC, MAHAPREIT, etc.). MERC Ambernath order and Rajya Sabha answers now read in full (tier A1). Lodha/Ambernath, CapitaLand, Digital Edge, STT, Yotta, AirTrunk rows enriched.
A6: Purpose | B6: Test whether planned data-centre power in India (especially Navi Mumbai) is materially higher than press announcements suggest, using government, regulator, utility, permit and company-filing evidence.
A7: Sheets | B7: Projects - one row per campus/project. Grid_Power - transmission, substation, utility and regulatory evidence. CTU_Bulk_Register - CTUIL national grid-access register (bulk consumers). States_Evidence - non-Maharashtra GOs/ECs/grid evidence. MH_Permits - Maharashtra environmental clearances and pollution-board consents for data centres, with power data. Govt_Aggregates - official and operator-level totals. Summary - formula-driven roll-ups and gap check. To_Pull - primary documents still to retrieve. Sources - every link used.
A8: Units | B8: IT MW = critical IT load. 'Grid / facility power' is quoted as the source states it (MW or MVA); facility power is typically 1.3-1.6x IT load. Investment in Rs crore.
A9: Include in totals | B9: 'N' marks rows excluded from Summary sums to avoid double counting (e.g., tenants inside a park; umbrella MoUs; potential-only site capacity). Change the flag to re-cut totals.
A10: Read in source? | B10: 'Y' = the figure was checked in the primary document itself during compilation. 'N' = taken from a report of that document; verify before external use.
A11: Highlighting | B11: Yellow rows = Navi Mumbai / MMR focus.
A12: Caveat | B12: Sources often conflict (IT vs facility MW, campus potential vs build). Conflicts are noted per row. MoU/LoI capacity is intent, not committed build.
A14: Evidence tiers
A15: A1 | B15: Government / regulator / utility document - retrieved and read for this dataset
A16: A2 | B16: Government / regulator action (GO, MoU, LoI, permit application, regulatory order) - reported; primary document not yet retrieved
A17: B | B17: Statutory company disclosure - exchange filing, investor presentation, DRHP, credit-rating rationale
A18: C | B18: Company announcement / company website
A19: D | B19: Third-party only - press, aggregator, research house

Sheet Summary
A1: Summary - tracked IT MW (Projects sheet, rows with Include = Y)
A2: All figures are formulas over the Projects sheet; edit Projects and these update.
A4: State | B4: A1 | C4: A2 | D4: B | E4: C | F4: D | G4: Total planned IT MW | H4: Operational IT MW | I4: UC / contracted IT MW
A5: Maharashtra | B5: =SUMIFS(Projects!$J$2:$J$293,Projects!$B$2:$B$293,$A5,Projects!$O$2:$O$293,"A1",Projects!$W$2:$W$293,"Y") -> 3372 | C5: =SUMIFS(Projects!$J$2:$J$293,Projects!$B$2:$B$293,$A5,Projects!$O$2:$O$293,"A2",Projects!$W$2:$W$293,"Y") -> 4250 | D5: =SUMIFS(Projects!$J$2:$J$293,Projects!$B$2:$B$293,$A5,Projects!$O$2:$O$293,"B",Projects!$W$2:$W$293,"Y") -> 244 | E5: =SUMIFS(Projects!$J$2:$J$293,Projects!$B$2:$B$293,$A5,Projects!$O$2:$O$293,"C",Projects!$W$2:$W$293,"Y") -> 3216 | F5: =SUMIFS(Projects!$J$2:$J$293,Projects!$B$2:$B$293,$A5,Projects!$O$2:$O$293,"D",Projects!$W$2:$W$293,"Y") -> 165.5 | G5: =SUM(B5:F5) -> 11247.5 | H5: =SUMIFS(Projects!$H$2:$H$293,Projects!$B$2:$B$293,$A5,Projects!$W$2:$W$293,"Y") -> 472.2 | I5: =SUMIFS(Projects!$I$2:$I$293,Projects!$B$2:$B$293,$A5,Projects!$W$2:$W$293,"Y") -> 2454.1
A6: Andhra Pradesh | B6: =SUMIFS(Projects!$J$2:$J$293,Projects!$B$2:$B$293,$A6,Projects!$O$2:$O$293,"A1",Projects!$W$2:$W$293,"Y") -> 1000 | C6: =SUMIFS(Projects!$J$2:$J$293,Projects!$B$2:$B$293,$A6,Projects!$O$2:$O$293,"A2",Projects!$W$2:$W$293,"Y") -> 4148 | D6: =SUMIFS(Projects!$J$2:$J$293,Projects!$B$2:$B$293,$A6,Projects!$O$2:$O$293,"B",Projects!$W$2:$W$293,"Y") -> 0 | E6: =SUMIFS(Projects!$J$2:$J$293,Projects!$B$2:$B$293,$A6,Projects!$O$2:$O$293,"C",Projects!$W$2:$W$293,"Y") -> 0 | F6: =SUMIFS(Projects!$J$2:$J$293,Projects!$B$2:$B$293,$A6,Projects!$O$2:$O$293,"D",Projects!$W$2:$W$293,"Y") -> 0 | G6: =SUM(B6:F6) -> 5148 | H6: =SUMIFS(Projects!$H$2:$H$293,Projects!$B$2:$B$293,$A6,Projects!$W$2:$W$293,"Y") -> 0 | I6: =SUMIFS(Projects!$I$2:$I$293,Projects!$B$2:$B$293,$A6,Projects!$W$2:$W$293,"Y") -> 0
A7: Telangana | B7: =SUMIFS(Projects!$J$2:$J$293,Projects!$B$2:$B$293,$A7,Projects!$O$2:$O$293,"A1",Projects!$W$2:$W$293,"Y") -> 0 | C7: =SUMIFS(Projects!$J$2:$J$293,Projects!$B$2:$B$293,$A7,Projects!$O$2:$O$293,"A2",Projects!$W$2:$W$293,"Y") -> 1000 | D7: =SUMIFS(Projects!$J$2:$J$293,Projects!$B$2:$B$293,$A7,Projects!$O$2:$O$293,"B",Projects!$W$2:$W$293,"Y") -> 406 | E7: =SUMIFS(Projects!$J$2:$J$293,Projects!$B$2:$B$293,$A7,Projects!$O$2:$O$293,"C",Projects!$W$2:$W$293,"Y") -> 2200 | F7: =SUMIFS(Projects!$J$2:$J$293,Projects!$B$2:$B$293,$A7,Projects!$O$2:$O$293,"D",Projects!$W$2:$W$293,"Y") -> 0 | G7: =SUM(B7:F7) -> 3606 | H7: =SUMIFS(Projects!$H$2:$H$293,Projects!$B$2:$B$293,$A7,Projects!$W$2:$W$293,"Y") -> 19.2 | I7: =SUMIFS(Projects!$I$2:$I$293,Projects!$B$2:$B$293,$A7,Projects!$W$2:$W$293,"Y") -> 100
A8: Tamil Nadu | B8: =SUMIFS(Projects!$J$2:$J$293,Projects!$B$2:$B$293,$A8,Projects!$O$2:$O$293,"A1",Projects!$W$2:$W$293,"Y") -> 70 | C8: =SUMIFS(Projects!$J$2:$J$293,Projects!$B$2:$B$293,$A8,Projects!$O$2:$O$293,"A2",Projects!$W$2:$W$293,"Y") -> 0 | D8: =SUMIFS(Projects!$J$2:$J$293,Projects!$B$2:$B$293,$A8,Projects!$O$2:$O$293,"B",Projects!$W$2:$W$293,"Y") -> 33 | E8: =SUMIFS(Projects!$J$2:$J$293,Projects!$B$2:$B$293,$A8,Projects!$O$2:$O$293,"C",Projects!$W$2:$W$293,"Y") -> 200 | F8: =SUMIFS(Projects!$J$2:$J$293,Projects!$B$2:$B$293,$A8,Projects!$O$2:$O$293,"D",Projects!$W$2:$W$293,"Y") -> 145 | G8: =SUM(B8:F8) -> 448 | H8: =SUMIFS(Projects!$H$2:$H$293,Projects!$B$2:$B$293,$A8,Projects!$W$2:$W$293,"Y") -> 86.1 | I8: =SUMIFS(Projects!$I$2:$I$293,Projects!$B$2:$B$293,$A8,Projects!$W$2:$W$293,"Y") -> 34
A9: Uttar Pradesh | B9: =SUMIFS(Projects!$J$2:$J$293,Projects!$B$2:$B$293,$A9,Projects!$O$2:$O$293,"A1",Projects!$W$2:$W$293,"Y") -> 0 | C9: =SUMIFS(Projects!$J$2:$J$293,Projects!$B$2:$B$293,$A9,Projects!$O$2:$O$293,"A2",Projects!$W$2:$W$293,"Y") -> 370 | D9: =SUMIFS(Projects!$J$2:$J$293,Projects!$B$2:$B$293,$A9,Projects!$O$2:$O$293,"B",Projects!$W$2:$W$293,"Y") -> 50 | E9: =SUMIFS(Projects!$J$2:$J$293,Projects!$B$2:$B$293,$A9,Projects!$O$2:$O$293,"C",Projects!$W$2:$W$293,"Y") -> 52.8 | F9: =SUMIFS(Projects!$J$2:$J$293,Projects!$B$2:$B$293,$A9,Projects!$O$2:$O$293,"D",Projects!$W$2:$W$293,"Y") -> 0 | G9: =SUM(B9:F9) -> 472.8 | H9: =SUMIFS(Projects!$H$2:$H$293,Projects!$B$2:$B$293,$A9,Projects!$W$2:$W$293,"Y") -> 10 | I9: =SUMIFS(Projects!$I$2:$I$293,Projects!$B$2:$B$293,$A9,Projects!$W$2:$W$293,"Y") -> 40
A10: Gujarat | B10: =SUMIFS(Projects!$J$2:$J$293,Projects!$B$2:$B$293,$A10,Projects!$O$2:$O$293,"A1",Projects!$W$2:$W$293,"Y") -> 0 | C10: =SUMIFS(Projects!$J$2:$J$293,Projects!$B$2:$B$293,$A10,Projects!$O$2:$O$293,"A2",Projects!$W$2:$W$293,"Y") -> 0 | D10: =SUMIFS(Projects!$J$2:$J$293,Projects!$B$2:$B$293,$A10,Projects!$O$2:$O$293,"B",Projects!$W$2:$W$293,"Y") -> 0 | E10: =SUMIFS(Projects!$J$2:$J$293,Projects!$B$2:$B$293,$A10,Projects!$O$2:$O$293,"C",Projects!$W$2:$W$293,"Y") -> 168 | F10: =SUMIFS(Projects!$J$2:$J$293,Projects!$B$2:$B$293,$A10,Projects!$O$2:$O$293,"D",Projects!$W$2:$W$293,"Y") -> 0 | G10: =SUM(B10:F10) -> 168 | H10: =SUMIFS(Projects!$H$2:$H$293,Projects!$B$2:$B$293,$A10,Projects!$W$2:$W$293,"Y") -> 0 | I10: =SUMIFS(Projects!$I$2:$I$293,Projects!$B$2:$B$293,$A10,Projects!$W$2:$W$293,"Y") -> 168
A11: Odisha | B11: =SUMIFS(Projects!$J$2:$J$293,Projects!$B$2:$B$293,$A11,Projects!$O$2:$O$293,"A1",Projects!$W$2:$W$293,"Y") -> 0 | C11: =SUMIFS(Projects!$J$2:$J$293,Projects!$B$2:$B$293,$A11,Projects!$O$2:$O$293,"A2",Projects!$W$2:$W$293,"Y") -> 1120 | D11: =SUMIFS(Projects!$J$2:$J$293,Projects!$B$2:$B$293,$A11,Projects!$O$2:$O$293,"B",Projects!$W$2:$W$293,"Y") -> 0 | E11: =SUMIFS(Projects!$J$2:$J$293,Projects!$B$2:$B$293,$A11,Projects!$O$2:$O$293,"C",Projects!$W$2:$W$293,"Y") -> 0 | F11: =SUMIFS(Projects!$J$2:$J$293,Projects!$B$2:$B$293,$A11,Projects!$O$2:$O$293,"D",Projects!$W$2:$W$293,"Y") -> 0 | G11: =SUM(B11:F11) -> 1120 | H11: =SUMIFS(Projects!$H$2:$H$293,Projects!$B$2:$B$293,$A11,Projects!$W$2:$W$293,"Y") -> 0 | I11: =SUMIFS(Projects!$I$2:$I$293,Projects!$B$2:$B$293,$A11,Projects!$W$2:$W$293,"Y") -> 0
A12: West Bengal | B12: =SUMIFS(Projects!$J$2:$J$293,Projects!$B$2:$B$293,$A12,Projects!$O$2:$O$293,"A1",Projects!$W$2:$W$293,"Y") -> 0 | C12: =SUMIFS(Projects!$J$2:$J$293,Projects!$B$2:$B$293,$A12,Projects!$O$2:$O$293,"A2",Projects!$W$2:$W$293,"Y") -> 0 | D12: =SUMIFS(Projects!$J$2:$J$293,Projects!$B$2:$B$293,$A12,Projects!$O$2:$O$293,"B",Projects!$W$2:$W$293,"Y") -> 0 | E12: =SUMIFS(Projects!$J$2:$J$293,Projects!$B$2:$B$293,$A12,Projects!$O$2:$O$293,"C",Projects!$W$2:$W$293,"Y") -> 40 | F12: =SUMIFS(Projects!$J$2:$J$293,Projects!$B$2:$B$293,$A12,Projects!$O$2:$O$293,"D",Projects!$W$2:$W$293,"Y") -> 250 | G12: =SUM(B12:F12) -> 290 | H12: =SUMIFS(Projects!$H$2:$H$293,Projects!$B$2:$B$293,$A12,Projects!$W$2:$W$293,"Y") -> 0 | I12: =SUMIFS(Projects!$I$2:$I$293,Projects!$B$2:$B$293,$A12,Projects!$W$2:$W$293,"Y") -> 0
A13: Haryana | B13: =SUMIFS(Projects!$J$2:$J$293,Projects!$B$2:$B$293,$A13,Projects!$O$2:$O$293,"A1",Projects!$W$2:$W$293,"Y") -> 0 | C13: =SUMIFS(Projects!$J$2:$J$293,Projects!$B$2:$B$293,$A13,Projects!$O$2:$O$293,"A2",Projects!$W$2:$W$293,"Y") -> 0 | D13: =SUMIFS(Projects!$J$2:$J$293,Projects!$B$2:$B$293,$A13,Projects!$O$2:$O$293,"B",Projects!$W$2:$W$293,"Y") -> 307 | E13: =SUMIFS(Projects!$J$2:$J$293,Projects!$B$2:$B$293,$A13,Projects!$O$2:$O$293,"C",Projects!$W$2:$W$293,"Y") -> 0 | F13: =SUMIFS(Projects!$J$2:$J$293,Projects!$B$2:$B$293,$A13,Projects!$O$2:$O$293,"D",Projects!$W$2:$W$293,"Y") -> 0 | G13: =SUM(B13:F13) -> 307 | H13: =SUMIFS(Projects!$H$2:$H$293,Projects!$B$2:$B$293,$A13,Projects!$W$2:$W$293,"Y") -> 28 | I13: =SUMIFS(Projects!$I$2:$I$293,Projects!$B$2:$B$293,$A13,Projects!$W$2:$W$293,"Y") -> 35
A14: Karnataka | B14: =SUMIFS(Projects!$J$2:$J$293,Projects!$B$2:$B$293,$A14,Projects!$O$2:$O$293,"A1",Projects!$W$2:$W$293,"Y") -> 120 | C14: =SUMIFS(Projects!$J$2:$J$293,Projects!$B$2:$B$293,$A14,Projects!$O$2:$O$293,"A2",Projects!$W$2:$W$293,"Y") -> 500 | D14: =SUMIFS(Projects!$J$2:$J$293,Projects!$B$2:$B$293,$A14,Projects!$O$2:$O$293,"B",Projects!$W$2:$W$293,"Y") -> 0 | E14: =SUMIFS(Projects!$J$2:$J$293,Projects!$B$2:$B$293,$A14,Projects!$O$2:$O$293,"C",Projects!$W$2:$W$293,"Y") -> 0 | F14: =SUMIFS(Projects!$J$2:$J$293,Projects!$B$2:$B$293,$A14,Projects!$O$2:$O$293,"D",Projects!$W$2:$W$293,"Y") -> 0 | G14: =SUM(B14:F14) -> 620 | H14: =SUMIFS(Projects!$H$2:$H$293,Projects!$B$2:$B$293,$A14,Projects!$W$2:$W$293,"Y") -> 0 | I14: =SUMIFS(Projects!$I$2:$I$293,Projects!$B$2:$B$293,$A14,Projects!$W$2:$W$293,"Y") -> 0
A15: All India (tracked) | B15: =SUM(B5:B14) -> 4562 | C15: =SUM(C5:C14) -> 11388 | D15: =SUM(D5:D14) -> 1040 | E15: =SUM(E5:E14) -> 5876.8 | F15: =SUM(F5:F14) -> 560.5 | G15: =SUM(G5:G14) -> 23427.3 | H15: =SUM(H5:H14) -> 615.5 | I15: =SUM(I5:I14) -> 2831.1
A17: Maharashtra by cluster (Include = Y)
A18: Cluster | B18: Total planned IT MW | C18: Operational IT MW | D18: UC / contracted IT MW | E18: Of which tier A1/A2/B
A19: Navi Mumbai - Taloja/Panvel | B19: =SUMIFS(Projects!$J$2:$J$293,Projects!$C$2:$C$293,$A19,Projects!$W$2:$W$293,"Y") -> 1480 | C19: =SUMIFS(Projects!$H$2:$H$293,Projects!$C$2:$C$293,$A19,Projects!$W$2:$W$293,"Y") -> 52 | D19: =SUMIFS(Projects!$I$2:$I$293,Projects!$C$2:$C$293,$A19,Projects!$W$2:$W$293,"Y") -> 292 | E19: =SUMIFS(Projects!$J$2:$J$293,Projects!$C$2:$C$293,$A19,Projects!$W$2:$W$293,"Y",Projects!$O$2:$O$293,"A1")+SUMIFS(Projects!$J$2:$J$293,Projects!$C$2:$C$293,$A19,Projects!$W$2:$W$293,"Y",Projects!$O$2:$O$293,"A2")+SUMIFS(Projects!$J$2:$J$293,Projects!$C$2:$C$293,$A19,Projects!$W$2:$W$293,"Y",Projects!$O$2:$O$293,"B") -> 750
A20: Maharashtra - multiple | B20: =SUMIFS(Projects!$J$2:$J$293,Projects!$C$2:$C$293,$A20,Projects!$W$2:$W$293,"Y") -> 0 | C20: =SUMIFS(Projects!$H$2:$H$293,Projects!$C$2:$C$293,$A20,Projects!$W$2:$W$293,"Y") -> 0 | D20: =SUMIFS(Projects!$I$2:$I$293,Projects!$C$2:$C$293,$A20,Projects!$W$2:$W$293,"Y") -> 0 | E20: =SUMIFS(Projects!$J$2:$J$293,Projects!$C$2:$C$293,$A20,Projects!$W$2:$W$293,"Y",Projects!$O$2:$O$293,"A1")+SUMIFS(Projects!$J$2:$J$293,Projects!$C$2:$C$293,$A20,Projects!$W$2:$W$293,"Y",Projects!$O$2:$O$293,"A2")+SUMIFS(Projects!$J$2:$J$293,Projects!$C$2:$C$293,$A20,Projects!$W$2:$W$293,"Y",Projects!$O$2:$O$293,"B") -> 0
A21: MMR - Palava/Ambernath/Taloja edge | B21: =SUMIFS(Projects!$J$2:$J$293,Projects!$C$2:$C$293,$A21,Projects!$W$2:$W$293,"Y") -> 2500 | C21: =SUMIFS(Projects!$H$2:$H$293,Projects!$C$2:$C$293,$A21,Projects!$W$2:$W$293,"Y") -> 0 | D21: =SUMIFS(Projects!$I$2:$I$293,Projects!$C$2:$C$293,$A21,Projects!$W$2:$W$293,"Y") -> 1450 | E21: =SUMIFS(Projects!$J$2:$J$293,Projects!$C$2:$C$293,$A21,Projects!$W$2:$W$293,"Y",Projects!$O$2:$O$293,"A1")+SUMIFS(Projects!$J$2:$J$293,Projects!$C$2:$C$293,$A21,Projects!$W$2:$W$293,"Y",Projects!$O$2:$O$293,"A2")+SUMIFS(Projects!$J$2:$J$293,Projects!$C$2:$C$293,$A21,Projects!$W$2:$W$293,"Y",Projects!$O$2:$O$293,"B") -> 2500
A22: MMR - Raigad/Pen | B22: =SUMIFS(Projects!$J$2:$J$293,Projects!$C$2:$C$293,$A22,Projects!$W$2:$W$293,"Y") -> 3000 | C22: =SUMIFS(Projects!$H$2:$H$293,Projects!$C$2:$C$293,$A22,Projects!$W$2:$W$293,"Y") -> 0 | D22: =SUMIFS(Projects!$I$2:$I$293,Projects!$C$2:$C$293,$A22,Projects!$W$2:$W$293,"Y") -> 0 | E22: =SUMIFS(Projects!$J$2:$J$293,Projects!$C$2:$C$293,$A22,Projects!$W$2:$W$293,"Y",Projects!$O$2:$O$293,"A1")+SUMIFS(Projects!$J$2:$J$293,Projects!$C$2:$C$293,$A22,Projects!$W$2:$W$293,"Y",Projects!$O$2:$O$293,"A2")+SUMIFS(Projects!$J$2:$J$293,Projects!$C$2:$C$293,$A22,Projects!$W$2:$W$293,"Y",Projects!$O$2:$O$293,"B") -> 3000
A23: Navi Mumbai - TTC/Thane-Belapur | B23: =SUMIFS(Projects!$J$2:$J$293,Projects!$C$2:$C$293,$A23,Projects!$W$2:$W$293,"Y") -> 2794 | C23: =SUMIFS(Projects!$H$2:$H$293,Projects!$C$2:$C$293,$A23,Projects!$W$2:$W$293,"Y") -> 397 | D23: =SUMIFS(Projects!$I$2:$I$293,Projects!$C$2:$C$293,$A23,Projects!$W$2:$W$293,"Y") -> 697 | E23: =SUMIFS(Projects!$J$2:$J$293,Projects!$C$2:$C$293,$A23,Projects!$W$2:$W$293,"Y",Projects!$O$2:$O$293,"A1")+SUMIFS(Projects!$J$2:$J$293,Projects!$C$2:$C$293,$A23,Projects!$W$2:$W$293,"Y",Projects!$O$2:$O$293,"A2")+SUMIFS(Projects!$J$2:$J$293,Projects!$C$2:$C$293,$A23,Projects!$W$2:$W$293,"Y",Projects!$O$2:$O$293,"B") -> 548
A24: Navi Mumbai - unspecified | B24: =SUMIFS(Projects!$J$2:$J$293,Projects!$C$2:$C$293,$A24,Projects!$W$2:$W$293,"Y") -> 245.5 | C24: =SUMIFS(Projects!$H$2:$H$293,Projects!$C$2:$C$293,$A24,Projects!$W$2:$W$293,"Y") -> 0 | D24: =SUMIFS(Projects!$I$2:$I$293,Projects!$C$2:$C$293,$A24,Projects!$W$2:$W$293,"Y") -> 5.5 | E24: =SUMIFS(Projects!$J$2:$J$293,Projects!$C$2:$C$293,$A24,Projects!$W$2:$W$293,"Y",Projects!$O$2:$O$293,"A1")+SUMIFS(Projects!$J$2:$J$293,Projects!$C$2:$C$293,$A24,Projects!$W$2:$W$293,"Y",Projects!$O$2:$O$293,"A2")+SUMIFS(Projects!$J$2:$J$293,Projects!$C$2:$C$293,$A24,Projects!$W$2:$W$293,"Y",Projects!$O$2:$O$293,"B") -> 0
A25: Maharashtra - unspecified | B25: =SUMIFS(Projects!$J$2:$J$293,Projects!$C$2:$C$293,$A25,Projects!$W$2:$W$293,"Y") -> 700 | C25: =SUMIFS(Projects!$H$2:$H$293,Projects!$C$2:$C$293,$A25,Projects!$W$2:$W$293,"Y") -> 0 | D25: =SUMIFS(Projects!$I$2:$I$293,Projects!$C$2:$C$293,$A25,Projects!$W$2:$W$293,"Y") -> 0 | E25: =SUMIFS(Projects!$J$2:$J$293,Projects!$C$2:$C$293,$A25,Projects!$W$2:$W$293,"Y",Projects!$O$2:$O$293,"A1")+SUMIFS(Projects!$J$2:$J$293,Projects!$C$2:$C$293,$A25,Projects!$W$2:$W$293,"Y",Projects!$O$2:$O$293,"A2")+SUMIFS(Projects!$J$2:$J$293,Projects!$C$2:$C$293,$A25,Projects!$W$2:$W$293,"Y",Projects!$O$2:$O$293,"B") -> 700
A26: MMR - Thane | B26: =SUMIFS(Projects!$J$2:$J$293,Projects!$C$2:$C$293,$A26,Projects!$W$2:$W$293,"Y") -> 272 | C26: =SUMIFS(Projects!$H$2:$H$293,Projects!$C$2:$C$293,$A26,Projects!$W$2:$W$293,"Y") -> 0 | D26: =SUMIFS(Projects!$I$2:$I$293,Projects!$C$2:$C$293,$A26,Projects!$W$2:$W$293,"Y") -> 0 | E26: =SUMIFS(Projects!$J$2:$J$293,Projects!$C$2:$C$293,$A26,Projects!$W$2:$W$293,"Y",Projects!$O$2:$O$293,"A1")+SUMIFS(Projects!$J$2:$J$293,Projects!$C$2:$C$293,$A26,Projects!$W$2:$W$293,"Y",Projects!$O$2:$O$293,"A2")+SUMIFS(Projects!$J$2:$J$293,Projects!$C$2:$C$293,$A26,Projects!$W$2:$W$293,"Y",Projects!$O$2:$O$293,"B") -> 272
A27: Mumbai (island/suburbs) | B27: =SUMIFS(Projects!$J$2:$J$293,Projects!$C$2:$C$293,$A27,Projects!$W$2:$W$293,"Y") -> 0 | C27: =SUMIFS(Projects!$H$2:$H$293,Projects!$C$2:$C$293,$A27,Projects!$W$2:$W$293,"Y") -> 0 | D27: =SUMIFS(Projects!$I$2:$I$293,Projects!$C$2:$C$293,$A27,Projects!$W$2:$W$293,"Y") -> 0 | E27: =SUMIFS(Projects!$J$2:$J$293,Projects!$C$2:$C$293,$A27,Projects!$W$2:$W$293,"Y",Projects!$O$2:$O$293,"A1")+SUMIFS(Projects!$J$2:$J$293,Projects!$C$2:$C$293,$A27,Projects!$W$2:$W$293,"Y",Projects!$O$2:$O$293,"A2")+SUMIFS(Projects!$J$2:$J$293,Projects!$C$2:$C$293,$A27,Projects!$W$2:$W$293,"Y",Projects!$O$2:$O$293,"B") -> 0
A28: Pune | B28: =SUMIFS(Projects!$J$2:$J$293,Projects!$C$2:$C$293,$A28,Projects!$W$2:$W$293,"Y") -> 256 | C28: =SUMIFS(Projects!$H$2:$H$293,Projects!$C$2:$C$293,$A28,Projects!$W$2:$W$293,"Y") -> 23.2 | D28: =SUMIFS(Projects!$I$2:$I$293,Projects!$C$2:$C$293,$A28,Projects!$W$2:$W$293,"Y") -> 9.6 | E28: =SUMIFS(Projects!$J$2:$J$293,Projects!$C$2:$C$293,$A28,Projects!$W$2:$W$293,"Y",Projects!$O$2:$O$293,"A1")+SUMIFS(Projects!$J$2:$J$293,Projects!$C$2:$C$293,$A28,Projects!$W$2:$W$293,"Y",Projects!$O$2:$O$293,"A2")+SUMIFS(Projects!$J$2:$J$293,Projects!$C$2:$C$293,$A28,Projects!$W$2:$W$293,"Y",Projects!$O$2:$O$293,"B") -> 96
A29: Maharashtra total | B29: =SUM(B19:B28) -> 11247.5 | C29: =SUM(C19:C28) -> 472.2 | D29: =SUM(D19:D28) -> 2454.1 | E29: =SUM(E19:E28) -> 7866
A31: Gap check - official totals vs. what this dataset can name
A32: Comparison | B32: Official / govt figure (MW) | C32: Tracked here (MW) | D32: Unnamed gap (MW) | E32: Tracked as % of official
A33: India: CEA projected additional DC demand by FY32 vs all tracked planned IT MW | B33: =Govt_Aggregates!$E$2 -> 26300 | C33: =G15 -> 23427.3 | D33: =B33-C33 -> 2872.7 | E33: =IF(B33=0,"-",C33/B33) -> 0.89077186
A34: Maharashtra: Industries/MIDC 44-project IT capacity vs tracked Maharashtra | B34: =Govt_Aggregates!$E$12 -> 23800 | C34: =B29 -> 11247.5 | D34: =B34-C34 -> 12552.5 | E34: =IF(B34=0,"-",C34/B34) -> 0.47258403
A35: Navi Mumbai Hub + Taloja Corridor (MIDC) vs tracked Navi Mumbai clusters | B35: =Govt_Aggregates!$E$15+Govt_Aggregates!$E$16 -> 7810 | C35: =B19+B23+B24 -> 4519.5 | D35: =B35-C35 -> 3290.5 | E35: =IF(B35=0,"-",C35/B35) -> 0.57868118
A36: Andhra Pradesh: 16 projects IT load (APTRANSCO) vs tracked AP | B36: =Govt_Aggregates!$E$18 -> 9100 | C36: =G6 -> 5148 | D36: =B36-C36 -> 3952 | E36: =IF(B36=0,"-",C36/B36) -> 0.56571429
A37: India installed today (MeitY) vs tracked operational IT MW | B37: =Govt_Aggregates!$E$6 -> 1575 | C37: =H15 -> 615.5 | D37: =B37-C37 -> 959.5 | E37: =IF(B37=0,"-",C37/B37) -> 0.39079365
A39: Reading the gap: a positive 'Unnamed gap' means government/utility documents point to more capacity than can be tied to named projects in this first pass - consistent with the client view.
A40: Tracked operational MW is far below MeitY's 1,575 MW because this pass focuses on new/large campuses, not the full installed base.
A41: Navi Mumbai cluster rows exclude Palava/Ambernath and Raigad-Pen (separate clusters); MIDC's 'Navi Mumbai Hub' definition is not published, so the comparison is indicative.
A43: Permit evidence - Maharashtra (MH_Permits sheet)
A44: Connected load in SEIAA/SEAC permit records (MW) | B44: =MH_Permits!M49 -> 644.622
A45: DG back-up in permit records (MVA) | B45: =MH_Permits!M50 -> 886.9
...

Sheet Projects
A1: ID | B1: State | C1: Cluster | D1: Micro-location | E1: Developer / operator | F1: Partner / tenant | G1: Project / campus | H1: IT MW - operational | I1: IT MW - under construction / contracted | J1: IT MW - total planned (campus) | K1: Grid / facility power (as stated) | L1: Investment (Rs crore) | M1: Status | N1: Timeline | O1: Evidence tier | P1: Source type | Q1: Primary source | R1: Link 1 | S1: Link 2 | T1: Source date | U1: Key data point (as stated in source) | V1: Read in source document? (Y/N) | W1: Include in totals (Y/N) | X1: Notes / conflicts / double-count | Y1: Navi Mumbai / MMR focus
A2: P001 | B2: Maharashtra | C2: Navi Mumbai - Taloja/Panvel | D2: Taloja campus | E2: AdaniConneX (Adani Ent.-EdgeConneX 50:50 JV) | F2: CoreWeave (sole tenant) | G2: AdaniConneX Taloja - CoreWeave AI campus | I2: 240 | J2: 480 | K2: 3 x 80 MW buildings; DLC GPU halls | M2: Contracted / under development | N2: First phase mid-2028 | O2: C | P2: Company press release | Q2: CoreWeave investor release: CoreWeave enters India with AdaniConneX | R2: https://investors.coreweave.com/news/news-details/2026/CoreWeave-Enters-India-Expanding-AI-Cloud-Platform-With-AdaniConneX/default.aspx | S2: https://inc42.com/buzz/coreweave-enters-india-partners-adaniconnex-for-240-mw-data-centre-capacity/ | T2: 2026-10-06 | U2: 240 MW across three 80 MW buildings at Taloja; option for further 240 MW (480 MW total) | V2: N | W2: Y | X2: Overlaps with AdaniConneX 'Navi Mumbai 110 MW' (30 + 80 MW buildings) in Adani Ent. Q1 FY27 deck - the 80 MW building is likely the first CoreWeave building. Counted here, not in the AEL row. | Y2: Y
A3: P002 | B3: Maharashtra | C3: Navi Mumbai - Taloja/Panvel | D3: Navi Mumbai | E3: AdaniConneX | F3: - | G3: AdaniConneX Navi Mumbai (per AEL filing) | H3: 0 | I3: 110 | J3: 110 | M3: Under construction | N3: - | O3: B | P3: Investor presentation (exchange filing) | Q3: Adani Enterprises Q1 FY27 earnings presentation, slide 15 | R3: https://www.adanienterprises.com/-/media/Project/Enterprises/Investors/Investor-Downloads/Results-Presentations/AEL_Investor_Presentation.pdf | T3: 2026-07 | U3: 'Navi Mumbai - Execution started for 2 buildings - 30 & 80* MW'; total 110 MW; *80 MW revised down from 136 MW | V3: Y | W3: N | X3: Excluded from totals to avoid double counting with CoreWeave 240 MW row. | Y3: Y
A4: P003 | B4: Maharashtra | C4: Navi Mumbai - Taloja/Panvel | D4: Navi Mumbai site (aggregator) | E4: AdaniConneX | F4: - | G4: AdaniConneX 'Navi' site - potential IT load | J4: 1000 | M4: Planned (potential) | N4: RFS Dec 2026 onwards | O4: D | P4: Aggregator listing | Q4: datacenters.com listing | R4: https://www.datacenters.com/adaniconnex-navi | T4: n.d. | U4: 1,000 MW potential IT load | V4: N | W4: N | X4: Potential site capacity only; shown for reference. Adani's 2024 Maharashtra MoU (1 GW, Rs 50,000 cr) is the umbrella commitment. | Y4: Y
A5: P004 | B5: Maharashtra | C5: Maharashtra - multiple | D5: Mumbai/Navi Mumbai & Pune | E5: Adani Group | F5: - | G5: Adani Maharashtra hyperscale MoU (Davos 2024) | J5: 1000 | L5: 50000 | M5: MoU | N5: 10 years | O5: A2 | P5: State MoU (reported) | Q5: Adani newsroom: Govt of Maharashtra MoU | R5: https://www.adani.com/newsroom/media-releases/government-of-maharashtra | T5: 2024-01 | U5: MoU for 1 GW hyperscale data infrastructure, Rs 50,000 crore over 10 years | V5: N | W5: N | X5: Umbrella MoU; AdaniConneX Navi Mumbai / Pune rows sit within it. | Y5: Y
A6: P005 | B6: Maharashtra | C6: MMR - Palava/Ambernath/Taloja edge | D6: Asode & Burdul villages (near Taloja; ex-Lodha land) | E6: Amazon Data Services India (AWS) | F6: - | G6: AWS Taloja/Palava data centre campus | J6: 473 | K6: 473 MW electricity requirement (per SEIAA application as reported) | L6: 4000 | M6: EC application filed with SEIAA | N6: Groundbreaking Mar 2026 | O6: A2 | P6: SEIAA environmental clearance application (reported) | Q6: Blitz India Media report on SEIAA application | R6: https://blitzindiamedia.com/west/amazon-taloja-data-center-environmental-clearance-seiaa-2026/ | S6: https://www.datacenterdynamics.com/en/news/aws-plans-430m-data-center-in-navi-mumbai-india/ | T6: 2026-04-28 | U6: 48.85 acres (197,692 sq m); BUA 393,938 sq m; 6 buildings (4 x 7-storey DCs); 473 MW; ~Rs 4,000 cr; land bought Nov-2024 from Macrotech (Lodha) for Rs 450 cr | V6: N | W6: N | X6: Land was bought from Lodha (Macrotech) -> sits inside/adjacent to Lodha Palava DC park; excluded to avoid double count with Lodha park row. Pull PARIVESH proposal for DG/power annexure. 473 MW figure appears to be facility power, not IT. | Y6: Y
A7: P006 | B7: Maharashtra | C7: MMR - Palava/Ambernath/Taloja edge | D7: Palava City, Thane/Raigad (approx. 370-400 acres) | E7: Lodha Developers (Macrotech) | F7: AWS, STT GDC, Digital Edge (land buyers) | G7: Lodha Green Integrated Data Centre Park, Palava | I7: 1450 | J7: 2500 | K7: MERC Case 88/2026: 400/220 kV GIS Ambernath S/S, 4 x 500 MVA ICT (DDF, Lodha-funded); STU connectivity granted ~1,450 MW (AWS, STT) + ~1,500 MW under process = 2,950 MW by 2028 | L7: 130000 | M7: MERC order 01-Jun-2026; STU connectivity granted; land being sold | N7: Substation & DC load by 2028 | O7: A1 | P7: MERC order (read) + State MoUs | Q7: MERC order in Case No. 88 of 2026 & IA 78 of 2026 (01-06-2026) | R7: https://merc.gov.in/wp-content/uploads/2026/06/Order-88-of-2026.pdf | S7: https://www.saurenergy.com/solar-energy-news/maharashtra-approves-transmission-infrastructure-for-13-lakh-crore-data-centre-park-11902218 | T7: 2026-06-01 | U7: Order para 7.6: 'STU has already granted grid connectivity to Amazon Web Services (AWS) and ST Telemedia Global Data Centres (STT), while the connectivity application of another Data Center is under process'; para 7.15: ~1450 MW granted, ~1500 MW under consideration, 2950 MW by 2028 | V7: Y | W7: Y | X7: 'UC/contracted' column holds the ~1,450 MW of grid connectivity granted per the MERC order. Capacity cited as 2 / 2.5 / 3 GW across sources. Tenants AWS (473 MW), Digital Edge (~270 MW) and STT (24 acres) are inside this total. | Y7: Y
A8: P007 | B8: Maharashtra | C8: MMR - Palava/Ambernath/Taloja edge | D8: Palava (~30 acres) | E8: Digital Edge India (Digital Edge-NIIF JV) | F8: - | G8: Digital Edge second Mumbai campus (Palava) | J8: 270 | M8: Land acquired | N8: - | O8: D | P8: Press | Q8: W.Media: Palava land deal points to Digital Edge's second India DC | R8: https://w.media/palava-land-deal-points-to-digital-edges-second-india-data-center/ | S8: https://finimize.com/content/lodha-confirms-palava-land-sale-to-data-center-builder | T8: 2026-07 | U8: ~30 acres bought at ~Rs 42 cr/acre; ~270 MW reported (not confirmed by Lodha) | V8: N | W8: N | X8: Inside Lodha park - excluded from totals. | Y8: Y
A9: P008 | B9: Maharashtra | C9: MMR - Palava/Ambernath/Taloja edge | D9: Palava (24+ acres) | E9: STT GDC India | F9: - | G9: STT GDC Palava land | L9: 500 | M9: Land acquired | N9: - | O9: D | P9: Press / Wikipedia | Q9: Data centre industry in India (Wikipedia, citing press) | R9: https://en.wikipedia.org/wiki/Data_centre_industry_in_India | T9: 2025-09 | U9: 24+ acres for ~Rs 500 cr | V9: N | W9: N | X9: Inside Lodha park; MW not disclosed. | Y9: Y
A10: P009 | B10: Maharashtra | C10: MMR - Raigad/Pen | D10: Raigad Pen Growth Centre ('Orange City'), Pen taluka | E10: AirTrunk (Blackstone/CPP) | F10: - | G10: AirTrunk Raigad mega-campus | J10: 3000 | L10: 200000 | M10: Letter of Intent for land allotment | N10: - | O10: A2 | P10: State LoI (announced by CM) | Q10: ANI: Maharashtra issues LoI to AirTrunk for Rs 2 lakh crore DC project in Raigad | R10: https://www.aninews.in/news/business/maharashtra-issues-letter-of-intent-to-airtrunk-for-rs-2-lakh-crore-data-centre-project-in-raigad20260601123602/ | S10: https://techcrunch.com/2026/06/05/airtrunk-commits-30b-to-build-5gw-of-ai-data-centers-in-india/ | T10: 2026-06-01 | U10: 3 GW IT capacity, Rs 2 lakh crore (~US$21bn); part of AirTrunk's US$30bn / 5 GW India plan | V10: N | W10: Y | X10: MMRDA secured 216 acres for Raigad-Pen Growth Centre (MMRDA PR 17/2026). Unverified aggregator reports of Mapletree (100 acres) also at Raigad-Pen. | Y10: Y
A11: P010 | B11: Maharashtra | C11: Navi Mumbai - TTC/Thane-Belapur | D11: Mahape | E11: NTT Global Data Centers | F11: - | G11: NTT NAV2 campus | J11: 336 | K11: 500 MW campus power | M11: Planned / under development | N11: - | O11: C | P11: Company announcement (via DCD) | Q11: DCD: NTT announces 500MW NAV2 data center in Navi Mumbai | R11: https://www.datacenterdynamics.com/en/news/ntt-announces-500mw-nav2-data-center-in-navi-mumbai-india/ | S11: https://www.globaldatacenterhub.com/p/the-new-center-of-gravity-inside | T11: 2026 | U11: 500 MW power; 336 MW IT across three facilities | V11: N | W11: Y | X11: ICRA (2025) puts NTT GDC India total at ~280 MW; capex Rs 1,200-1,500 cr/yr FY26-28. | Y11: Y
A12: P011 | B12: Maharashtra | C12: Navi Mumbai - TTC/Thane-Belapur | D12: Mahape (NAV1A) | E12: NTT Global Data Centers | F12: - | G12: NTT NAV1A | H12: 30 | J12: 30 | M12: Operational | N12: - | O12: C | P12: Company website | Q12: NTT Navi Mumbai data center page | R12: https://services.global.ntt/en-us/services-and-products/global-data-centers/global-locations/india/navi-mumbai-data-center | T12: n.d. | U12: 37,000 m2; 5,000 racks; 30 MW IT | V12: N | W12: Y | Y12: Y
A13: P012 | B13: Maharashtra | C13: Navi Mumbai - TTC/Thane-Belapur | D13: Plot IT-07, TTC Industrial Area, Mahape | E13: Nxtra Data Ltd (Bharti Airtel) | F13: - | G13: Nxtra Mahape DC-02 expansion | K13: Not in cover pages - see EC annexure on PARIVESH | M13: Environmental clearance granted (expansion) | N13: - | O13: A1 | P13: SEIAA Maharashtra environmental clearance | Q13: EC letter, proposal SIA/MH/INFRA2/490756/2025, EC id EC24C3802MH5926451N | R13: https://assets.airtel.in/nxtra/pdf/EC_Environmental_Clearance_Certificate_Nxtra%20Mahape_DC-02_25.11.25.pdf | T13: 2025-11-21 | U13: EC for expansion of IT/ITeS (datacenter) unit; SEIAA meeting 14/10/2025; Category B2, item 8(a) | V13: Y | W13: N | X13: MW not yet extracted (scanned PDF; salient features in Annexure). Nxtra Mumbai page lists Mahape hyperscale sites at 4/7/18/42 MW IT. Nxtra group: ~250-300 MW, target 1 GW. | Y13: Y
A14: P013 | B14: Maharashtra | C14: Navi Mumbai - TTC/Thane-Belapur | D14: Survey 238/2, Kalwa / Ghansoli, Thane-Belapur Rd | E14: Digital Edge DC (India) | F14: NIIF | G14: Digital Edge BOM campus (BOM1-BOM3) | H14: 40 | I14: 48 | J14: 400 | K14: 83 MW solar PPA (Hexa) | M14: BOM1 operational; BOM2 topped out; BOM3 started | N14: - | O14: A1 | P14: SEIAA EC + company | Q14: SEIAA EC letter, proposal SIA/MH/INFRA2/449922/2023, EC id EC24B039MH149609 | R14: https://www.digitaledgedc.com/wp-content/uploads/2025/07/EC-Letter-Data-Center.pdf | S14: https://www.digitaledgedc.com/digital-edge-india/ | T14: 2024-02-08 | U14: EC granted for 'BOM' data center (Cat B, 8(b)); company: 400 MW Navi Mumbai campus, ~47 acres; BOM2 48.4 MW | V14: Y | W14: Y | X14: Campus sized at 300 / 350 / 400 MW in different company materials. MPCB CTE 0000195775 (3rd CAC 2024-25) for 'BOM 2 & BOM 3', Dighe S.No. 47/2-49/2: plot 172,354 m2, BUA 390,772 m2, 8 buildings, CI Rs 3,000 cr (EC dated 08-02-2024 matches this EC). CTO 0000225726 issued 03-04-2025. See MH_Permits. | Y14: Y
A15: P014 | B15: Maharashtra | C15: Navi Mumbai - TTC/Thane-Belapur | D15: TTC Rabale (Plot R-847) | E15: Sify Infinit Spaces | F15: - | G15: Sify Rabale hyperscale campus | H15: 85 | I15: 40 | J15: 377 | M15: 5 towers live; 7 more planned | N15: - | O15: C | P15: Company website / IR deck | Q15: Sify Rabale campus page | R15: https://www.sifytechnologies.com/data-center/rabale-data-center/ | S15: https://sifyinfinitspaces.com/wp-content/uploads/2025/07/Sify-Infinit-Spaces-IR-2025.pdf | T15: 2025-26 | U15: Designed for 377+ MW IT across 12 towers (earlier 240+ MW); 2022 factsheet: 5 towers / 85 MW | V15: N | W15: Y | X15: IFC SLL (Jun-2026) for two new DCs in Navi Mumbai + Chennai totalling 103 MW. DRHP (Oct-2025): 188 MW built IT India-wide. | Y15: Y
A16: P015 | B16: Maharashtra | C16: Navi Mumbai - Taloja/Panvel | D16: Panvel (Hiranandani Fortune City) | E16: Yotta Infrastructure (Hiranandani) | F16: - | G16: Yotta NM1 / NM2 DC park | H16: 52 | I16: 52 | J16: 250 | M16: NM1 operational; NM2 operational/fit-out | N16: - | O16: C | P16: Company website | Q16: Yotta NM1 page | R16: https://colocation.yotta.com/data-center/nm1-datacenter-mumbai-region-maharashtra/ | S16: https://dcpulse.com/project/yotta-nm2-navi-mumbai-datacenter | T16: 2026 | U16: NM1 52 MW IT; park 5 buildings ~210-250 MW; 'scalable to 1 GW' | V16: N | W16: Y | X16: NM2 cited at 52 or 65 MW. REALITY CHECK: CRISIL rationale (15-Apr-2025) on NMDC Data Centre Pvt Ltd (Hiranandani/Yotta SPV for NM1) shows ~13.1 MW colocation operational, rising to ~17.2 MW by FY27, rest for Shakti Cloud GPUs; holds captive discom licence. MPCB renewal 0000223122 (May-2025) covers Bhokarpada (Panvel) AND Talegaon Panshil (Khalapur) - a second site. | Y16: Y
A17: P016 | B17: Maharashtra | C17: Navi Mumbai - TTC/Thane-Belapur | D17: Mahape | E17: CtrlS Datacenters | F17: - | G17: CtrlS Mumbai DC1-DC7 | H17: 119 | I17: 95 | J17: 700 | M17: DC1-DC5 operational; DC6-DC7 upcoming | N17: - | O17: C | P17: Company website | Q17: CtrlS homepage / Mumbai visit page | R17: https://www.ctrls.com/ | S17: https://www.ctrls.com/dc-visit-mumbai/ | T17: 2025-26 | U17: DC1/2 40 MW, DC3 10, DC4 36.8, DC5 32; DC6+DC7 95 MW upcoming; campus '13 buildings, 700 MW IT' | V17: N | W17: Y | X17: 700 MW is a marketing claim. | Y17: Y
A18: P017 | B18: Maharashtra | C18: Navi Mumbai - TTC/Thane-Belapur | D18: Mahape (11.5 acres) + new TTC parcel | E18: STT GDC India | F18: - | G18: STT Navi Mumbai campus | H18: 53 | I18: 80 | J18: 133 | K18: Dual 220 kV & 400 kV substation feed | M18: 2 x 40 MW buildings due 2026 | N18: 2026 | O18: C | P18: Company website / brochure | Q18: STT GDC Mumbai locations page | R18: https://www.sttelemediagdc.com/in-en/locations/mumbai | S18: https://www.communicationstoday.co.in/stt-gdc-india-buys-navi-mumbai-land-for-%E2%82%B9282-crore-data-centre-project/ | T18: 2024-26 | U18: Total 133 MW after 3 new buildings; separate TTC land parcel bought May/Jun 2026 for Rs 282 cr (MW not disclosed) | V18: N | W18: Y | X18: Operational figure derived (133 minus 80 under construction). MPCB: CTE 0000175818 (Dec-2023) & CTO part 0000209776 for Gen-50/1, TTC Khairane; consent amended to REMOVE 31 x 2,000 kVA DG sets (13th CAC 2024-25). STU also granted STT grid connectivity at Ambernath (MERC Case 88/2026). | Y18: Y
A19: P018 | B19: Maharashtra | C19: Navi Mumbai - TTC/Thane-Belapur | D19: Airoli (MU1) & Navi Mumbai (MU2, 10 acres) | E19: Princeton Digital Group | F19: - | G19: PDG MU1 expansion + MU2 | H19: 48 | I19: 100 | J19: 220 | M19: MU1 phase-1 of 100 MW expansion UC; MU2 construction Apr 2026 | N19: - | O19: C | P19: Company (via DCD) | Q19: DCD: PDG breaks ground on latest Mumbai data center | R19: https://www.datacenterdynamics.com/en/news/pdg-breaks-ground-on-latest-mumbai-data-center/ | S19: https://www.datacentermap.com/india/navi-mumbai/princeton-digital-mu2/ | T19: 2026-04 | U19: MU2 120 MW IT; MU1 100 MW expansion | V19: N | W19: Y | X19: 48 MW operational = MU1 launch (DCD). | Y19: Y
A20: P019 | B20: Maharashtra | C20: Navi Mumbai - TTC/Thane-Belapur | D20: Airoli | E20: CapitaLand Investment | F20: - | G20: CapitaLand Data Centre Navi Mumbai 1 (+NM2) | I20: 108 | J20: 108 | K20: 108 MW power; on-site 220 kV GIS | M20: Under development | N20: Q4 2026 (first phase) | O20: C | P20: Company website | Q20: CapitaLand DC Navi Mumbai 1 listing | R20: https://www.capitaland.com/en/find-a-property/global-property-listing/data-centres/capitaland-s-datacentrenavimumbai1.html | T20: 2026 | U20: 108 MW; MPCB Consent to Establish listed among project documents | V20: N | W20: Y | X20: Some listings: 37 MW IT for first phase. CapitaLand's local SPV is Datascape Realty Pvt Ltd (Digha, TTC plots 14/2, 15 & 37): MPCB CTE 0000155369 CI Rs 3,211.9 cr; CTO (part) 0000231516 issued 09-02-2025; SEIAA EC proposal SIA/MH/INFRA2/466218/2024. See MH_Permits. | Y20: Y
A21: P020 | B21: Maharashtra | C21: Navi Mumbai - TTC/Thane-Belapur | D21: Mahape (5.4 ha) / Airoli | E21: AirTrunk (ex-Lumina CloudInfra) | F21: - | G21: AirTrunk BOM1 + BOM2 | I21: 62 | J21: 182 | K21: Dedicated 220 kV substations | M21: BOM1 under build (ex-Lumina, 60 MW Airoli); BOM2 planned | N21: - | O21: C | P21: Company website | Q21: AirTrunk BOM2 page | R21: https://airtrunk.com/location/bom2-mumbai/ | S21: https://www.datacenterdynamics.com/en/news/apac-data-center-firm-airtrunk-enters-india-acquires-lumina-cloudinfra/ | T21: 2026 | U21: BOM2 120+ MW, 5.4 ha, 220 kV S/S, PUE<1.4; BOM1 62+ MW, 2.4 ha | V21: N | W21: Y | X21: Lumina's Airoli SPV is Gramercy Techpark Pvt Ltd (Plot 7 & 7A, TTC Airoli): MPCB CTE 0000145905 - plot 24,350 m2, BUA 86,044 m2, CI Rs 1,495 cr; CTO (part) 13-05-2025; SEIAA EC expansion SIA/MH/INFRA2/484959/2024 (Oct/Nov-2025 agendas). | Y21: Y
A22: P021 | B22: Maharashtra | C22: Navi Mumbai - TTC/Thane-Belapur | D22: Thane-Belapur belt (15.4 acres) | E22: Data Center Holdings India LLP (Colt DCS-RMZ 50:50) | F22: - | G22: Colt DCS Navi Mumbai campus (Mumbai 1-3) | H22: 22 | I22: 64 | J22: 148 | K22: 220 kV GIS on campus | L22: 2016 | M22: Ph-1 22 MW (4 MW live Jul-2023); Mumbai 3 64 MW UC, fully pre-let | N22: - | O22: B | P22: Credit rating rationale | Q22: ICRA rationale - Data Center Holdings India LLP (Rs 1,440 cr TL, A-) | R22: https://www.icra.in/Rating/ShowRationalReportFilePdf/141442 | S22: https://indianinfrastructure.com/2026/10/16/colt-dcs-and-rmz-begin-construction-of-third-data-centre-in-mumbai/ | T22: 2026-03-09 | U22: ICRA: 142 MW expected across 3 phases; Ph-1 cost Rs 2,016 cr (71:29 D/E); 82% of Ph-1 unleased (Sep-2025). Oct-2026: Mumbai 3 (64 MW) started => campus 86 MW, 148 MW potential | V22: Y | W22: Y | X22: Same LLP received AP GO for 486 MW Vizag campus (see AP rows). | Y22: Y
A23: P022 | B23: Maharashtra | C23: Navi Mumbai - TTC/Thane-Belapur | D23: Navi Mumbai | E23: L&T-Vyoma | F23: - | G23: L&T Vyoma Navi Mumbai AI DC | I23: 40 | J23: 100 | M23: Under construction | N23: - | O23: C | P23: Company press release | Q23: L&T press release 21-Jan-2026 | R23: https://www.larsentoubro.com/pressreleases/2026/2026-01-21-larsen-toubro-vyoma-breaks-ground-on-40-mw-green-ai-ready-data-centre-in-navi-mumbai | T23: 2026-01-21 | U23: 40 MW phase-1 of 100 MW campus; direct-to-chip liquid cooling | V23: N | W23: Y | X23: Site is Plot EL-200, TTC Mahape: SEIAA EC proposal SIA/MH/INFRA2/517940/2025 (309th agenda, Oct-2025). | Y23: Y
A24: P023 | B24: Maharashtra | C24: Navi Mumbai - TTC/Thane-Belapur | D24: Rabale | E24: ESR | F24: - | G24: ESR Rabale DC | I24: 60 | J24: 60 | K24: Facility load up to 60 MW | M24: Under construction | N24: - | O24: D | P24: Press | Q24: CRN Asia: ESR enters India DC market with 60 MW facility | R24: https://www.crnasia.com/india/news/2026/esr-enters-india-data-centre-market-with-60-mw-facility-in-mumbai | T24: 2026 | U24: 60 MW facility load | V24: N | W24: Y | X24: Facility load, not IT load. | Y24: Y
A25: P024 | B25: Maharashtra | C25: Navi Mumbai - unspecified | D25: Navi Mumbai (29 acres, freehold) | E25: Zerra (AGPDC Global Holdings) | F25: - | G25: Zerra Navi Mumbai campus | J25: 240 | K25: 220 kV / 300 MVA + 100 kV / 40 MVA substations | M25: Construction commenced; power & pre-construction approvals received | N25: Oct 2026 start | O25: C | P25: Company website | Q25: Zerra Navi Mumbai project page | R25: https://zerradc.com/projects/navi-mumbai/ | T25: 2026-10 | U25: 240 MW IT; two independent substations; 'initial development consents received' | V25: N | W25: Y | X25: Relatively unknown developer; no press coverage found - an example of capacity not in mainstream announcements. | Y25: Y
A26: P025 | B26: Maharashtra | C26: Navi Mumbai - Taloja/Panvel | D26: Taloja | E26: Prestige Group | F26: - | G26: Prestige Taloja data centre | L26: 5000 | M26: State MoU | N26: Construction from 2026 | O26: A2 | P26: State MoU (reported) | Q26: DCD: Maharashtra partners with Prestige for Navi Mumbai DC | R26: https://www.datacenterdynamics.com/en/news/maharashtra-state-govt-partners-with-prestige-to-develop-data-center-in/ | T26: 2025-08 | U26: Rs 5,000 cr of Rs 12,500 cr MoU earmarked for DC at Taloja; 1,200 jobs | V26: N | W26: N | X26: MW not disclosed. | Y26: Y
A27: P026 | B27: Maharashtra | C27: Navi Mumbai - Taloja/Panvel | D27: Panvel, Khalapur, Taloja, Bhokharpada | E27: ReNew (ReNew Wind Energy) | F27: - | G27: ReNew Green Integrated DC Park (MMR) | J27: 750 | K27: Min. 51% green power | L27: 70000 | M27: State MoU | N27: Phased from 2028 | O27: A2 | P27: State MoU (reported) | Q27: Business Standard: ReNew signs MoU for Rs 70,000 cr green DC park | R27: https://www.business-standard.com/industry/news/renew-signs-mou-with-maharashtra-for-70-000-crore-green-data-centre-park-126100801226_1.html | S27: https://indianinfrastructure.com/2026/10/13/renew-signs-rs-700-billion-mou-with-maharashtra-government-to-develop-green-integrated-data-centre-park-in-mmr/ | T27: 2026-10-08 | U27: 750 MW, Rs 70,000 cr, multiple MMR sites | V27: N | W27: Y | Y27: Y
A28: P027 | B28: Maharashtra | C28: Maharashtra - unspecified | D28: Not disclosed | E28: Trentar Pvt Ltd (Dorf Ketal Group) | F28: - | G28: Trentar Green Integrated Hyperscale DC Park | J28: 500 | K28: Min. 51% RE + storage | L28: 30000 | M28: State LoI + MoU | N28: - | O28: A2 | P28: State LoI/MoU (company release) | Q28: PR Newswire: Trentar signs Rs 30,000 cr MoU | R28: https://www.prnewswire.com/in/news-releases/trentar-signs-30-000-crore-3-3-bn-mou-with-maharashtra-for-500-mw-green-integrated-data-center-park-302899623.html | T28: 2026-10-06 | U28: 500 MW; LoI received from state | V28: N | W28: Y | X28: Location not disclosed. | Y28: Y
A29: P028 | B29: Maharashtra | C29: Navi Mumbai - unspecified | D29: Navi Mumbai | E29: Avisirah Technologies | F29: - | G29: Avisirah Navi Mumbai DC | I29: 5.5 | J29: 5.5 | L29: 75 | M29: Financed | N29: - | O29: D | P29: Press | Q29: PropNewsTime: Avisirah raises Rs 75 cr | R29: https://propnewstime.com/latestnewsstories/MzY3MDg=/avisirah-raises-inr-75-crore-for-navi-mumbai-data-centre | T29: 2026 | U29: ~5.5 MW IT; Rs 75 cr loan | V29: N | W29: Y | X29: Small/enterprise example. | Y29: Y
A30: P029 | B30: Maharashtra | C30: Navi Mumbai - TTC/Thane-Belapur | D30: Plot D-31 & D-32, TTC Turbhe (EverYondr 'Mumbai 1') | E30: Amanthin Info Parks Pvt Ltd (EverYondr = Everstone + Yondr) | F30: Raiden Infotech India (Google) - 28-yr lease, ~3.81 lakh sq ft, Rs 8.83 cr/month (registered Oct-2022) | G30: Google / EverYondr Turbhe data centre | K30: Form-1A: connected load 103,367 kW; demand 108,807 kVA; 4 x 220/22 kV 60 MVA transformers; 58 x 2,200 kVA DG sets | M30: Under construction (target 2025-27) | N30: - | O30: A1 | P30: SEAC-II Form-1A (EC application) | Q30: Form 1A - Data Center by Amanthin Info Parks Pvt Ltd, Plot D-31 & D-32, TTC Turbhe | R30: https://environmentclearance.nic.in/DownloadPfdFile.aspx?FileName=Kwy+a1Xl%2FGHp2kMbJYBd8GPrFSz%2FNzzr1mrm87hA6RfsBvasy5U%2FhwjR4PRxBwwupD8Lw8MExL5FqtSFZLEOTQ%3D%3D&FilePath=93ZZBm8LWEXfg+HAlQix2fE2t8z%2FpgnoBhDlYdZCxzXTbTpOQqzWjBW0IF63rxBVcDlG0LKdfbGNs0Ou%2FTEvAA%3D%3D | S30: https://housing.com/news/google-rents-data-centre-space-in-navi-mumbai-midc/ | T30: n.d. (c.2022-23) | U30: Plot 39,980 m2; BUA 55,432 m2; ~103 MW connected load; 127.6 MVA of DG back-up | V30: Y | W30: N | X30: ~103 MW facility load => roughly 65-75 MW IT (assumes PUE 1.4-1.6) - IT MW left blank because not stated. Google's presence in Navi Mumbai is barely covered in the press. | Y30: Y
A31: P030 | B31: Maharashtra | C31: Navi Mumbai - TTC/Thane-Belapur | D31: GEN-2/1/A/1, D-Block, TTC Turbhe (ex-Gramercy Trade 'Gold Craft' plot) | E31: Raiden Infotech India Pvt Ltd (Google) | F31: - | G31: Google (Raiden) Turbhe data centre - own plot | K31: Not in agenda - see EC file | L31: 1895 | M31: MPCB Consent to Establish granted 26-08-2025; SEIAA EC proposal listed Oct-2025 | N31: - | O31: A1 | P31: MPCB CAC + SEIAA agenda | Q31: MPCB 5th CAC 2025-26 Action Taken Report (consent 0000249841); SEIAA 310th agenda (SIA/MH/INFRA2/531703/2025) | R31: https://mpcb.gov.in/en/cac-meetings | S31: https://www.ecmpcb.in/login/download_ec_document/ODY2MDg5MDRCMzNGNDNCN0JEMTFBNDUzNEI4MjlGNEQucGRm | T31: 2025-08-26 | U31: CTE approved for Raiden (Google) at Turbhe; same plot previously had CTE for 'Gold Craft by Gramercy Trade Industries' with CI Rs 1,895 cr (14th CAC 2023-24) | V31: Y | W31: N | X31: Investment shown is the earlier Gramercy CTE CI on the same plot - indicative only. Second Google site in Navi Mumbai. | Y31: Y
A32: P031 | B32: Maharashtra | C32: MMR - Thane | D32: Balkum & Majiwada villages, Thane (54.73 acres; ex-Kalpataru land) | E32: Amazon Data Services India (AWS) | F32: - | G32: AWS Thane (Balkum-Majiwada) campus | J32: 272 | L32: 7203 | M32: MPCB CTE granted 14-12-2023; SEIAA EC proposal SIA/MH/INFRA2/477127/2024 on agendas Nov-2024 & Sep-2025 | N32: - | O32: A1 | P32: MPCB CAC + SEIAA agendas | Q32: MPCB 16th CAC 2023-24 index & ATR (consent 0000178616); SEIAA 304th agenda | R32: https://mpcb.gov.in/en/cac-meetings | S32: https://www.ecmpcb.in/login/download_ec_document/RTE1NjUyREEwNzhCNEQ1MzkwRTZDQUVFOTNEQUIyRjYucGRm | T32: 2023-12-14 | U32: MPCB: 'Data Center by Amazon ... Balkum & Majiwada', CI Rs 7,203.29 cr, CTE approved. EC application (per public post of the filing): 54.73 acres, 272 MW total IT load | V32: Y | W32: Y | X32: 272 MW IT is from a social-media summary of the EC filing (https://x.com/cbdhage/status/1762797367529480646) - verify in EC file. Local political opposition (NCP-SP 'Out of Thane' campaign). | Y32: Y
A33: P032 | B33: Maharashtra | C33: Mumbai (island/suburbs) | D33: CTS 86 pt, Paspoli & CTS 115 pt Tungwa, Powai | E33: Amazon Data Services India (AWS) | F33: - | G33: AWS Powai data centre | L33: 2627 | M33: MPCB CTE granted 11-02-2025 (earlier SCN Dec-2023); SEIAA EC proposal SIA/MH/INFRA2/416132/2023 | N33: - | O33: A1 | P33: MPCB CAC | Q33: MPCB 15th CAC 2024-25 ATR (consent 0000217236) | R33: https://mpcb.gov.in/en/cac-meetings | T33: 2025-02-11 | U33: CI Rs 2,626.63 cr; CTE approved | V33: Y | W33: N | X33: MW not disclosed in CAC record. | Y33: N
A34: P033 | B34: Maharashtra | C34: Navi Mumbai - TTC/Thane-Belapur | D34: Plot ES-05, TTC Mahape | E34: Bearys Properties & Developments (build-to-suit; NTT NAV1A/1B developer) | F34: NTT (likely) | G34: Bearys ES-05 Mahape data centre | M34: SEIAA EC proposal Oct-2025 | N34: - | O34: A1 | P34: SEIAA agenda | Q34: SEIAA additional agenda, 310th meeting (SIA/MH/INFRA2/533354/2025) | R34: https://www.ecmpcb.in/login/download_ec_document/QjJCMzlBQzg5M0MzNDZERjg1NDQxQTZGN0YzQzE0MjMucGRm | S34: https://bearysgroup.com/wp-content/uploads/2024/01/Bearys-Data-Centre-e-brochure.pdf | T34: 2025-10-29 | U34: New EC application for data centre at ES-05 Mahape | V34: Y | W34: N | X34: Tenant not confirmed. | Y34: Y
A35: P034 | B35: Maharashtra | C35: Navi Mumbai - Taloja/Panvel | D35: S.No./Gut 39, 42, 49, Bhokarpada, Panvel | E35: Larsen & Toubro Ltd | F35: - | G35: L&T Bhokarpada data centre + residential | M35: SEIAA EC proposal (Sep & Dec-2025 agendas) | N35: - | O35: A1 | P35: SEIAA agendas | Q35: SEIAA 304th & 313th agendas (SIA/MH/INFRA2/502320/2024) | R35: https://www.ecmpcb.in/login/download_ec_document/MzMzQzM2MDM3QkQ5NEYxQUIyOTNEMjAyNEE2NUNFODgucGRm | T35: 2025-12-02 | U35: 'Proposed Data Centre and Residential development with retail and commercial components', Bhokarpada | V35: Y | W35: N | X35: Separate from L&T-Vyoma Mahape (EL-200, SIA/MH/INFRA2/517940/2025). Bhokarpada also hosts Yotta/Hiranandani and is a ReNew park site. | Y35: Y
A36: P035 | B36: Maharashtra | C36: Navi Mumbai - TTC/Thane-Belapur | D36: Plot A-GEN-4, TTC Rabale / Ghansoli | E36: Support Properties Pvt Ltd (K Raheja Corp group) for AdaniConneX ('ACXNMI-01') | F36: - | G36: AdaniConneX NMI-01 Rabale | M36: MPCB CTE 21-02-2024; SEIAA EC expansion proposal Oct-2025 | N36: - | O36: A1 | P36: MPCB CAC + SEIAA agenda | Q36: SEIAA 308th agenda (SIA/MH/INFRA2/509611/2024); MPCB 21st CAC 2023-24 (0000185134) | R36: https://www.ecmpcb.in/login/download_ec_document/MjMyMTI2NEMzMjYzNDM5M0IxRTJDRDY5MENBNDZFODcucGRm | S36: https://www.scribd.com/document/1014690774/Adaniconnex-Navi-Mumbai | T36: 2025-10-03 | U36: 'Expansion in EC for Proposed Data Center Project ACXNMI-01' | V36: Y | W36: N | X36: 'ACX' project code = AdaniConneX (inference). A Scribd document describes ACXNMI-02 as 3 buildings / 400 MW IT. Overlaps AdaniConneX rows above - excluded. | Y36: Y
A37: P036 | B37: Maharashtra | C37: Navi Mumbai - TTC/Thane-Belapur | D37: Plot R-978, Sector 8, Rabale MIDC | E37: Gargantuan Industrial Space Solutions Pvt Ltd | F37: Unknown | G37: Gargantuan Rabale data centre expansion | M37: SEIAA EC expansion proposal Oct-2025 | N37: - | O37: A1 | P37: SEIAA agenda | Q37: SEIAA 310th agenda (SIA/MH/INFRA2/496938/2024) | R37: https://www.ecmpcb.in/login/download_ec_document/ODY2MDg5MDRCMzNGNDNCN0JEMTFBNDUzNEI4MjlGNEQucGRm | T37: 2025-10-26 | U37: 'Proposed expansion in Data Centre [IT/ITeS] Project' | V37: Y | W37: N | X37: Owner/tenant not identified - candidate 'unannounced' project; check MCA filings. | Y37: Y
A38: P037 | B38: Maharashtra | C38: Navi Mumbai - TTC/Thane-Belapur | D38: IT-5 Airoli Knowledge Park (Gigaplex) & Gen 2/1/D-F Juinagar (Newfound) | E38: K Raheja Corp / Mindspace REIT SPVs (Gigaplex Estate; Newfound Properties & Leasing) | F38: - | G38: Data-centre buildings inside K Raheja IT parks | L38: 174 | M38: Gigaplex Bldg 8 (DC) CTO applied 2025-26; Newfound Bldg 5A (DC) CTO Part-I granted (17th CAC 2024-25) | N38: - | O38: A1 | P38: MPCB CAC + SEIAA agendas | Q38: MPCB 4th CAC 2025-26 index (0000232277) & 17th CAC 2024-25 ATR (0000227513); SEIAA 309th/310th/318th agendas | R38: https://mpcb.gov.in/en/cac-meetings | S38: https://environmentclearance.nic.in/writereaddata/FormB/agenda/2801202685869228318FinalAgenda.pdf | T38: 2025-26 | U38: Gigaplex Bldg 8 (Data Centre) CI Rs 173.99 cr; Newfound Bldg 5A data centre BUA 32,971 m2 | V38: Y | W38: N | X38: Powered-shell DC buildings leased to hyperscalers (tenants not disclosed). | Y38: Y
A39: P038 | B39: Maharashtra | C39: Navi Mumbai - TTC/Thane-Belapur | D39: TTC Rabale | E39: Web Werks India (Iron Mountain) | F39: - | G39: Web Werks / Iron Mountain Rabale | M39: MPCB CTE 28-09-2024 | N39: - | O39: A1 | P39: MPCB CAC | Q39: MPCB 6th CAC 2024-25 ATR (0000215272) | R39: https://mpcb.gov.in/en/cac-meetings | T39: 2024-09-28 | U39: CTE approved | V39: Y | W39: N | X39: MW not stated. | Y39: Y
A40: P039 | B40: Maharashtra | C40: Navi Mumbai - TTC/Thane-Belapur | D40: Plot 13, Kalwa Industrial Area, Digha | E40: Bridge Data Centres (Mumbai) LLP | F40: - | G40: Bridge Data Centres Mumbai | L40: 599 | M40: Operating (CTO renewals 2024, 2025) | N40: - | O40: A1 | P40: MPCB CAC | Q40: MPCB 15th CAC 2023-24 index (0000171036); 13th CAC 2024-25 ATR | R40: https://mpcb.gov.in/en/cac-meetings | T40: 2025-02-09 | U40: CI Rs 598.52 cr | V40: Y | W40: N | X40: Operator rarely in Indian press. | Y40: Y
...

Sheet Grid_Power
A1: ID | B1: State | C1: Utility / body | D1: Asset / item | E1: Voltage / capacity | F1: Data-centre link | G1: Status / date in plan | H1: Evidence tier | I1: Source | J1: Link | K1: Source date | L1: Read in source? (Y/N) | M1: Notes | N1: Navi Mumbai / MMR focus
A2: G001 | B2: Maharashtra | C2: MSETCL (State Transmission Utility) | D2: New 765/400/220 kV Mahape substation (Navi Mumbai) | E2: 4 x 1500 MVA 765/400 kV ICT (6,000 MVA) + 4 x 500 MVA 400/220 kV ICT (2,000 MVA); 765 kV D/C Mahape-Padghe (PG) 120 km; 240 MVAr reactor | F2: Scheme 'Type' = 'Data Center'; '400 kV connectivity to Datacenter Consumers' and '220 kV connectivity to Datacenter Consumers' | G2: Padghe line 2026-27; Apta line 2028-29 | H2: A1 | I2: MSETCL STU Five-Year Plan 2024-25 to 2033-34, Annexure-E 'New Corridor Schemes', row 4 (PDF p.36) | J2: https://www.mahatransco.in/uploads/docs/STU%20Plan%202024-25%20to%202033-24.pdf | K2: 2024-25 | L2: Y | M2: Strongest single piece of evidence: the STU is planning a dedicated 765 kV node with up to ~6 GVA purely for data-centre consumers at Mahape. | N2: Y
A3: G002 | B3: Maharashtra | C3: MSETCL | D3: 400 kV Hinjewadi bays - data-centre connectivity (Pune) | E3: 2 x 400 kV bays at Hinjewadi | F3: '400 kV connectivity to Datacenter Consumers' | G3: Plan period | H3: A1 | I3: MSETCL STU Plan 2024-34, Annexure-E (PDF p.38) | J3: https://www.mahatransco.in/uploads/docs/STU%20Plan%202024-25%20to%202033-24.pdf | K3: 2024-25 | L3: Y | M3: Pune data-centre load explicitly planned. | N3: N
A4: G003 | B4: Maharashtra | C4: MSETCL | D4: Vashi-zone new EHV substations (Taloja/Panvel/Uran belt) | E4: 400/220 kV Kalwa-II GIS (2x500 MVA); 220 kV Panchanand/Taloja (BR sanctioned); 220 kV Rohinjan (Taloja) NEW; 220 kV Palaspe; 220 kV Uran (Dronagiri) NEW; Panvel-II GIS (WIP) | F4: Not labelled as DC, but sit in the Taloja/Panvel data-centre corridor | G4: 2024-34 | H4: A1 | I4: MSETCL STU Plan 2024-34, Vashi zone table (PDF p.25) | J4: https://www.mahatransco.in/uploads/docs/STU%20Plan%202024-25%20to%202033-24.pdf | K4: 2024-25 | L4: Y | M4: Cross-check which DC campuses these serve via MSETCL/MSEDCL HT connection lists. | N4: Y
A5: G004 | B5: Maharashtra | C5: MERC / MSETCL (STU) / Lodha | D5: 400/220 kV GIS Ambernath (Palava) substation - Dedicated Distribution Facility | E5: 4 x 500 MVA 400/220 kV ICT + line bays, bus reactor, LILO; Lodha-funded capex & lifetime O&M | F5: STU has granted connectivity to AWS and STT; another DC application under process; ~1,450 MW granted + ~1,500 MW under consideration = 2,950 MW expected on grid by 2028; feeds from ISTS 400 kV Padghe(PG)-Navi Mumbai(PG) and Padghe-Kharghar | G5: Order 01-06-2026; TBCB annulled Apr-2026; Empowered Committee 12-05-2026 | H5: A1 | I5: MERC order, Case No. 88 of 2026 & IA No. 78 of 2026 | J5: https://merc.gov.in/wp-content/uploads/2026/06/Order-88-of-2026.pdf | K5: 2026-06-01 | L5: Y | M5: Read in full. Order says global DC clients could move elsewhere if power is late - regulator treats DC load as committed. | N5: Y
A6: G005 | B6: Maharashtra | C6: Bajel Projects (EPC) - client undisclosed | D6: 400/220/33 kV GIS substation for a Mumbai data-centre project | E6: Rs 300-400 cr EPC; 24 months | F6: Dedicated EHV substation for an unnamed domestic DC developer | G6: Order Jun-2026 | H6: B | I6: SEBI Reg. 30 disclosure (via Business Standard) | J6: https://www.business-standard.com/markets/capital-market-news/bajel-projects-gains-on-bagging-mega-order-for-gis-substation-in-mumbai-126060300276_1.html | K6: 2026-06-03 | L6: N | M6: 400 kV + timing suggests the Lodha Ambernath DDF; unconfirmed. | N6: Y
A7: G006 | B7: Maharashtra | C7: Tata Power (Mumbai licensee) | D7: Data-centre opportunity pipeline | E7: ~2.8 GW: ~430 MW distribution load; 1,236 MW transmission-linked; 1,150 MW green energy | F7: 18 operators, 29 active workstreams; Rs 15,000 cr Mumbai grid plan; 400 kV ring | G7: Oct-2026 | H7: B | I7: Tata Power release (via TaxGuru / Trade Brains) | J7: https://taxguru.in/finance/business/tata-power-expands-data-centre-opportunities-with-2-8-gw-pipeline.html | K7: 2026-10-14 | L7: N | M7: Pipeline, not contracts. Get the exchange filing/investor deck. | N7: Y
A8: G007 | B8: Maharashtra | C8: AEML (Adani Electricity Mumbai) | D8: Distribution demand projection incl. data centres | E8: 50 MW (FY23) -> 638 MW by 2027; 354 MW of the increase from proposed DCs | F8: Proposed DCs in AEML licence area | G8: MERC filing (reported) | H8: A2 | I8: TechPolicy.Press citing AEML filing | J8: https://www.techpolicy.press/mumbais-data-center-dreams-run-on-coal-and-inequality/ | K8: 2025-26 | L8: N | M8: Identify the exact MERC case. | N8: Y
A9: G008 | B9: Maharashtra | C9: AEML (transmission) | D9: Transmission licence amendment petition | E9: Mumbai peak 4,306 MW (FY25) -> ~6,000 MW (FY30); DCs/EVs/infra ~800 MW | F9: DC load cited as a driver | G9: MERC petition | H9: A2 | I9: EQ Mag summary of AEML petition | J9: https://www.eqmagpro.com/petition-for-application-of-adani-electricity-mumbai-infra-limited-for-the-first-amendment-of-transmission-licence-eq/ | K9: 2026 | L9: N | N9: Y
A10: G009 | B10: Maharashtra | C10: MSEDCL | D10: Grid capacity allocated to DCs in Navi Mumbai cluster | E10: ~6 GW | F10: Committed + under-construction capacity said to be approaching this ceiling; new builds moving to Panvel/Taloja/Rasayani | G10: 2026 | H10: D | I10: Structure Research Mumbai+Pune report 2026 (abstract) | J10: https://www.structureresearch.net/product/mumbai-pune-dcai-report-2026-data-centre-colocation-hyperscale-cloud-ai-interconnection/ | K10: 2026 | L10: N | M10: High-value claim; try to corroborate via MSEDCL / RTI. | N10: Y
A11: G010 | B11: Maharashtra | C11: CTUIL / POWERGRID | D11: 400/220 kV Navi Mumbai (PG) substation - drawal margin | E11: 2 x 315 MVA | F11: 'No margins for drawal of power exist at existing 400/220kV Navi Mumbai S/s' (bulk-consumer GNA diverted to Murbad/Pune) | G11: 26th CMETS-WR, 28.02.2024 | H11: A1 | I11: CTUIL minutes, 26th CMETS-WR | J11: https://www.ctuil.in/uploads/ists_consultation_meeting/minutes/171076102952Minutes%20of%2026th%20CMETS-WR_final.pdf | K11: 2024-02-28 | L11: Y | M11: Grid constraint in Navi Mumbai. | N11: Y
A12: G011 | B12: Maharashtra | C12: CTUIL / POWERGRID | D12: Additional ISTS feed to Navi Mumbai 400/220 kV S/S | E12: Padghe-Kharghar / Vikhroli 400 kV LILO at Navi Mumbai GIS; LILO of Apta-Taloja/Kalwa 220 kV | F12: Mumbai corridor demand expected to rise to 4,000-4,200 MW; jack-bus/line-trap upgrades and SPS at Navi Mumbai (PG) | G12: Common system Mar-26 (29th); upgrade discussed 02.02.2026 (41st) | H12: A1 | I12: CTUIL minutes, 29th & 41st CMETS-WR | J12: https://www.ctuil.in/uploads/ists_consultation_meeting/minutes/17718323234441st%20WR%20CMETS%20MOM.pdf | K12: 2026-02-02 | L12: Y | N12: Y
A13: G012 | B13: Gujarat | C13: CTUIL | D13: Reliance Industries - ISTS GNA as 'bulk consumer' at Jam Khambhaliya | E13: 300 MW (from 01-12-2027), 600 MW (from 01-12-2028), 350 MW (from 01-06-2029) | F13: Purpose not stated; timing/location coincides with the Jamnagar AI DC build-out | G13: 41st CMETS-WR, 02.02.2026 | H13: A1 | I13: CTUIL minutes, 41st CMETS-WR (applications 2200002406-08, dated 09-09-2025) | J13: https://www.ctuil.in/uploads/ists_consultation_meeting/minutes/17718323234441st%20WR%20CMETS%20MOM.pdf | K13: 2026-02-02 | L13: Y | M13: Possible DC load - NOT confirmed. Total 1,250 MW. | N13: N
