Workbook

Sheet Chart_Data
A1: Maharashtra data-centre power by group - verifiable MW, EXCLUDING CTUIL (no double counting)
A2: Every number is a SUMIFS on MH_Master_List: column S (verifiable MW) for rows of that group (col Z), excluding rows whose primary record (col B) is 'CTUIL', split by stage (col V). Each project appears in exactly one row of MH_Master_List, so groups cannot double count. Facility (grid) MW, not IT MW.
A4: Group | B4: Grid sanctioned / approved (SLDC, MERC) | C4: Grid under consideration (MERC) | D4: Permit only (EC connected load) | E4: MoU / LoI / EOI (not yet on grid) | F4: TOTAL excl. CTUIL (MW) | G4: of which realised today (SLDC) | H4: Callout text (MoU / LoI items) | I4: Rows in MH_Master_List | J4: Note
A5: Blackstone / AirTrunk | B5: =SUMIFS(MH_Master_List!$S$5:$S$61,MH_Master_List!$Z$5:$Z$61,$A5,MH_Master_List!$B$5:$B$61,"<>CTUIL",MH_Master_List!$V$5:$V$61,"1*")+SUMIFS(MH_Master_List!$S$5:$S$61,MH_Master_List!$Z$5:$Z$61,$A5,MH_Master_List!$B$5:$B$61,"<>CTUIL",MH_Master_List!$V$5:$V$61,"2*") -> 900 | C5: =SUMIFS(MH_Master_List!$S$5:$S$61,MH_Master_List!$Z$5:$Z$61,$A5,MH_Master_List!$B$5:$B$61,"<>CTUIL",MH_Master_List!$V$5:$V$61,"3*") -> 0 | D5: =SUMIFS(MH_Master_List!$S$5:$S$61,MH_Master_List!$Z$5:$Z$61,$A5,MH_Master_List!$B$5:$B$61,"<>CTUIL",MH_Master_List!$V$5:$V$61,"4*") -> 0 | E5: =SUMIFS(MH_Master_List!$S$5:$S$61,MH_Master_List!$Z$5:$Z$61,$A5,MH_Master_List!$B$5:$B$61,"<>CTUIL",MH_Master_List!$V$5:$V$61,"5*") -> 3000 | F5: =SUM(B5:E5) -> 3900 | G5: =SUMIFS(MH_Master_List!$I$5:$I$61,MH_Master_List!$Z$5:$Z$61,$A5,MH_Master_List!$B$5:$B$61,"<>CTUIL") -> 35 | H5: AirTrunk - Raigad-Pen Growth Centre: 3,000 MW, State Letter of Intent for land (Jun-2026) (MH50) | I5: MH02, MH25, MH26, MH27, MH50 | J5: Gramercy SPVs mapped to Blackstone/AirTrunk by inference (BOM1 = Gramercy Techpark)
A6: Ambernath park (MERC add-on) | B6: =SUMIFS(MH_Master_List!$S$5:$S$61,MH_Master_List!$Z$5:$Z$61,$A6,MH_Master_List!$B$5:$B$61,"<>CTUIL",MH_Master_List!$V$5:$V$61,"1*")+SUMIFS(MH_Master_List!$S$5:$S$61,MH_Master_List!$Z$5:$Z$61,$A6,MH_Master_List!$B$5:$B$61,"<>CTUIL",MH_Master_List!$V$5:$V$61,"2*") -> 525 | C6: =SUMIFS(MH_Master_List!$S$5:$S$61,MH_Master_List!$Z$5:$Z$61,$A6,MH_Master_List!$B$5:$B$61,"<>CTUIL",MH_Master_List!$V$5:$V$61,"3*") -> 1500 | D6: =SUMIFS(MH_Master_List!$S$5:$S$61,MH_Master_List!$Z$5:$Z$61,$A6,MH_Master_List!$B$5:$B$61,"<>CTUIL",MH_Master_List!$V$5:$V$61,"4*") -> 0 | E6: =SUMIFS(MH_Master_List!$S$5:$S$61,MH_Master_List!$Z$5:$Z$61,$A6,MH_Master_List!$B$5:$B$61,"<>CTUIL",MH_Master_List!$V$5:$V$61,"5*") -> 0 | F6: =SUM(B6:E6) -> 2025 | G6: =SUMIFS(MH_Master_List!$I$5:$I$61,MH_Master_List!$Z$5:$Z$61,$A6,MH_Master_List!$B$5:$B$61,"<>CTUIL") -> 0 | I6: MH21, MH39 | J6: MERC Case 88/2026: 1,450 MW granted (vs 925 in SLDC for AWS + STT, shown in their bars) + 1,500 MW under consideration; tenant split not disclosed
A7: AWS (Amazon) | B7: =SUMIFS(MH_Master_List!$S$5:$S$61,MH_Master_List!$Z$5:$Z$61,$A7,MH_Master_List!$B$5:$B$61,"<>CTUIL",MH_Master_List!$V$5:$V$61,"1*")+SUMIFS(MH_Master_List!$S$5:$S$61,MH_Master_List!$Z$5:$Z$61,$A7,MH_Master_List!$B$5:$B$61,"<>CTUIL",MH_Master_List!$V$5:$V$61,"2*") -> 850 | C7: =SUMIFS(MH_Master_List!$S$5:$S$61,MH_Master_List!$Z$5:$Z$61,$A7,MH_Master_List!$B$5:$B$61,"<>CTUIL",MH_Master_List!$V$5:$V$61,"3*") -> 0 | D7: =SUMIFS(MH_Master_List!$S$5:$S$61,MH_Master_List!$Z$5:$Z$61,$A7,MH_Master_List!$B$5:$B$61,"<>CTUIL",MH_Master_List!$V$5:$V$61,"4*") -> 0 | E7: =SUMIFS(MH_Master_List!$S$5:$S$61,MH_Master_List!$Z$5:$Z$61,$A7,MH_Master_List!$B$5:$B$61,"<>CTUIL",MH_Master_List!$V$5:$V$61,"5*") -> 0 | F7: =SUM(B7:E7) -> 850 | G7: =SUMIFS(MH_Master_List!$I$5:$I$61,MH_Master_List!$Z$5:$Z$61,$A7,MH_Master_List!$B$5:$B$61,"<>CTUIL") -> 0 | I7: MH20, MH23, MH38 | J7: Powai 225, Thane 150, Ambernath 475 (SLDC)
A8: STT GDC | B8: =SUMIFS(MH_Master_List!$S$5:$S$61,MH_Master_List!$Z$5:$Z$61,$A8,MH_Master_List!$B$5:$B$61,"<>CTUIL",MH_Master_List!$V$5:$V$61,"1*")+SUMIFS(MH_Master_List!$S$5:$S$61,MH_Master_List!$Z$5:$Z$61,$A8,MH_Master_List!$B$5:$B$61,"<>CTUIL",MH_Master_List!$V$5:$V$61,"2*") -> 770 | C8: =SUMIFS(MH_Master_List!$S$5:$S$61,MH_Master_List!$Z$5:$Z$61,$A8,MH_Master_List!$B$5:$B$61,"<>CTUIL",MH_Master_List!$V$5:$V$61,"3*") -> 0 | D8: =SUMIFS(MH_Master_List!$S$5:$S$61,MH_Master_List!$Z$5:$Z$61,$A8,MH_Master_List!$B$5:$B$61,"<>CTUIL",MH_Master_List!$V$5:$V$61,"4*") -> 0 | E8: =SUMIFS(MH_Master_List!$S$5:$S$61,MH_Master_List!$Z$5:$Z$61,$A8,MH_Master_List!$B$5:$B$61,"<>CTUIL",MH_Master_List!$V$5:$V$61,"5*") -> 0 | F8: =SUM(B8:E8) -> 770 | G8: =SUMIFS(MH_Master_List!$I$5:$I$61,MH_Master_List!$Z$5:$Z$61,$A8,MH_Master_List!$B$5:$B$61,"<>CTUIL") -> 97 | I8: MH13, MH19, MH22, MH33 | J8: Navi Mumbai 40 + 80, Ambernath 450, Pune 200 (SLDC)
A9: ReNew | B9: =SUMIFS(MH_Master_List!$S$5:$S$61,MH_Master_List!$Z$5:$Z$61,$A9,MH_Master_List!$B$5:$B$61,"<>CTUIL",MH_Master_List!$V$5:$V$61,"1*")+SUMIFS(MH_Master_List!$S$5:$S$61,MH_Master_List!$Z$5:$Z$61,$A9,MH_Master_List!$B$5:$B$61,"<>CTUIL",MH_Master_List!$V$5:$V$61,"2*") -> 0 | C9: =SUMIFS(MH_Master_List!$S$5:$S$61,MH_Master_List!$Z$5:$Z$61,$A9,MH_Master_List!$B$5:$B$61,"<>CTUIL",MH_Master_List!$V$5:$V$61,"3*") -> 0 | D9: =SUMIFS(MH_Master_List!$S$5:$S$61,MH_Master_List!$Z$5:$Z$61,$A9,MH_Master_List!$B$5:$B$61,"<>CTUIL",MH_Master_List!$V$5:$V$61,"4*") -> 0 | E9: =SUMIFS(MH_Master_List!$S$5:$S$61,MH_Master_List!$Z$5:$Z$61,$A9,MH_Master_List!$B$5:$B$61,"<>CTUIL",MH_Master_List!$V$5:$V$61,"5*") -> 750 | F9: =SUM(B9:E9) -> 750 | G9: =SUMIFS(MH_Master_List!$I$5:$I$61,MH_Master_List!$Z$5:$Z$61,$A9,MH_Master_List!$B$5:$B$61,"<>CTUIL") -> 0 | H9: ReNew Wind Energy - MMR green DC park: 750 MW, State MoU Oct-2026 (MH51) | I9: MH51
A10: NTT | B10: =SUMIFS(MH_Master_List!$S$5:$S$61,MH_Master_List!$Z$5:$Z$61,$A10,MH_Master_List!$B$5:$B$61,"<>CTUIL",MH_Master_List!$V$5:$V$61,"1*")+SUMIFS(MH_Master_List!$S$5:$S$61,MH_Master_List!$Z$5:$Z$61,$A10,MH_Master_List!$B$5:$B$61,"<>CTUIL",MH_Master_List!$V$5:$V$61,"2*") -> 665 | C10: =SUMIFS(MH_Master_List!$S$5:$S$61,MH_Master_List!$Z$5:$Z$61,$A10,MH_Master_List!$B$5:$B$61,"<>CTUIL",MH_Master_List!$V$5:$V$61,"3*") -> 0 | D10: =SUMIFS(MH_Master_List!$S$5:$S$61,MH_Master_List!$Z$5:$Z$61,$A10,MH_Master_List!$B$5:$B$61,"<>CTUIL",MH_Master_List!$V$5:$V$61,"4*") -> 0 | E10: =SUMIFS(MH_Master_List!$S$5:$S$61,MH_Master_List!$Z$5:$Z$61,$A10,MH_Master_List!$B$5:$B$61,"<>CTUIL",MH_Master_List!$V$5:$V$61,"5*") -> 0 | F10: =SUM(B10:E10) -> 665 | G10: =SUMIFS(MH_Master_List!$I$5:$I$61,MH_Master_List!$Z$5:$Z$61,$A10,MH_Master_List!$B$5:$B$61,"<>CTUIL") -> 90 | I10: MH10, MH11, MH12
A11: CtrlS | B11: =SUMIFS(MH_Master_List!$S$5:$S$61,MH_Master_List!$Z$5:$Z$61,$A11,MH_Master_List!$B$5:$B$61,"<>CTUIL",MH_Master_List!$V$5:$V$61,"1*")+SUMIFS(MH_Master_List!$S$5:$S$61,MH_Master_List!$Z$5:$Z$61,$A11,MH_Master_List!$B$5:$B$61,"<>CTUIL",MH_Master_List!$V$5:$V$61,"2*") -> 585 | C11: =SUMIFS(MH_Master_List!$S$5:$S$61,MH_Master_List!$Z$5:$Z$61,$A11,MH_Master_List!$B$5:$B$61,"<>CTUIL",MH_Master_List!$V$5:$V$61,"3*") -> 0 | D11: =SUMIFS(MH_Master_List!$S$5:$S$61,MH_Master_List!$Z$5:$Z$61,$A11,MH_Master_List!$B$5:$B$61,"<>CTUIL",MH_Master_List!$V$5:$V$61,"4*") -> 0 | E11: =SUMIFS(MH_Master_List!$S$5:$S$61,MH_Master_List!$Z$5:$Z$61,$A11,MH_Master_List!$B$5:$B$61,"<>CTUIL",MH_Master_List!$V$5:$V$61,"5*") -> 0 | F11: =SUM(B11:E11) -> 585 | G11: =SUMIFS(MH_Master_List!$I$5:$I$61,MH_Master_List!$Z$5:$Z$61,$A11,MH_Master_List!$B$5:$B$61,"<>CTUIL") -> 70 | I11: MH06, MH28
A12: K Raheja Corp / Mindspace | B12: =SUMIFS(MH_Master_List!$S$5:$S$61,MH_Master_List!$Z$5:$Z$61,$A12,MH_Master_List!$B$5:$B$61,"<>CTUIL",MH_Master_List!$V$5:$V$61,"1*")+SUMIFS(MH_Master_List!$S$5:$S$61,MH_Master_List!$Z$5:$Z$61,$A12,MH_Master_List!$B$5:$B$61,"<>CTUIL",MH_Master_List!$V$5:$V$61,"2*") -> 535 | C12: =SUMIFS(MH_Master_List!$S$5:$S$61,MH_Master_List!$Z$5:$Z$61,$A12,MH_Master_List!$B$5:$B$61,"<>CTUIL",MH_Master_List!$V$5:$V$61,"3*") -> 0 | D12: =SUMIFS(MH_Master_List!$S$5:$S$61,MH_Master_List!$Z$5:$Z$61,$A12,MH_Master_List!$B$5:$B$61,"<>CTUIL",MH_Master_List!$V$5:$V$61,"4*") -> 0 | E12: =SUMIFS(MH_Master_List!$S$5:$S$61,MH_Master_List!$Z$5:$Z$61,$A12,MH_Master_List!$B$5:$B$61,"<>CTUIL",MH_Master_List!$V$5:$V$61,"5*") -> 0 | F12: =SUM(B12:E12) -> 535 | G12: =SUMIFS(MH_Master_List!$I$5:$I$61,MH_Master_List!$Z$5:$Z$61,$A12,MH_Master_List!$B$5:$B$61,"<>CTUIL") -> 71 | I12: MH08, MH09
A13: Trentar (Dorf Ketal) | B13: =SUMIFS(MH_Master_List!$S$5:$S$61,MH_Master_List!$Z$5:$Z$61,$A13,MH_Master_List!$B$5:$B$61,"<>CTUIL",MH_Master_List!$V$5:$V$61,"1*")+SUMIFS(MH_Master_List!$S$5:$S$61,MH_Master_List!$Z$5:$Z$61,$A13,MH_Master_List!$B$5:$B$61,"<>CTUIL",MH_Master_List!$V$5:$V$61,"2*") -> 0 | C13: =SUMIFS(MH_Master_List!$S$5:$S$61,MH_Master_List!$Z$5:$Z$61,$A13,MH_Master_List!$B$5:$B$61,"<>CTUIL",MH_Master_List!$V$5:$V$61,"3*") -> 0 | D13: =SUMIFS(MH_Master_List!$S$5:$S$61,MH_Master_List!$Z$5:$Z$61,$A13,MH_Master_List!$B$5:$B$61,"<>CTUIL",MH_Master_List!$V$5:$V$61,"4*") -> 0 | E13: =SUMIFS(MH_Master_List!$S$5:$S$61,MH_Master_List!$Z$5:$Z$61,$A13,MH_Master_List!$B$5:$B$61,"<>CTUIL",MH_Master_List!$V$5:$V$61,"5*") -> 500 | F13: =SUM(B13:E13) -> 500 | G13: =SUMIFS(MH_Master_List!$I$5:$I$61,MH_Master_List!$Z$5:$Z$61,$A13,MH_Master_List!$B$5:$B$61,"<>CTUIL") -> 0 | H13: Trentar Pvt Ltd - Location not disclosed: 500 MW, State LoI + MoU Oct-2026 (MH49) | I13: MH49
A14: Google | B14: =SUMIFS(MH_Master_List!$S$5:$S$61,MH_Master_List!$Z$5:$Z$61,$A14,MH_Master_List!$B$5:$B$61,"<>CTUIL",MH_Master_List!$V$5:$V$61,"1*")+SUMIFS(MH_Master_List!$S$5:$S$61,MH_Master_List!$Z$5:$Z$61,$A14,MH_Master_List!$B$5:$B$61,"<>CTUIL",MH_Master_List!$V$5:$V$61,"2*") -> 320 | C14: =SUMIFS(MH_Master_List!$S$5:$S$61,MH_Master_List!$Z$5:$Z$61,$A14,MH_Master_List!$B$5:$B$61,"<>CTUIL",MH_Master_List!$V$5:$V$61,"3*") -> 0 | D14: =SUMIFS(MH_Master_List!$S$5:$S$61,MH_Master_List!$Z$5:$Z$61,$A14,MH_Master_List!$B$5:$B$61,"<>CTUIL",MH_Master_List!$V$5:$V$61,"4*") -> 0 | E14: =SUMIFS(MH_Master_List!$S$5:$S$61,MH_Master_List!$Z$5:$Z$61,$A14,MH_Master_List!$B$5:$B$61,"<>CTUIL",MH_Master_List!$V$5:$V$61,"5*") -> 0 | F14: =SUM(B14:E14) -> 320 | G14: =SUMIFS(MH_Master_List!$I$5:$I$61,MH_Master_List!$Z$5:$Z$61,$A14,MH_Master_List!$B$5:$B$61,"<>CTUIL") -> 0 | I14: MH30, MH31
A15: Adani Group | B15: =SUMIFS(MH_Master_List!$S$5:$S$61,MH_Master_List!$Z$5:$Z$61,$A15,MH_Master_List!$B$5:$B$61,"<>CTUIL",MH_Master_List!$V$5:$V$61,"1*")+SUMIFS(MH_Master_List!$S$5:$S$61,MH_Master_List!$Z$5:$Z$61,$A15,MH_Master_List!$B$5:$B$61,"<>CTUIL",MH_Master_List!$V$5:$V$61,"2*") -> 229 | C15: =SUMIFS(MH_Master_List!$S$5:$S$61,MH_Master_List!$Z$5:$Z$61,$A15,MH_Master_List!$B$5:$B$61,"<>CTUIL",MH_Master_List!$V$5:$V$61,"3*") -> 0 | D15: =SUMIFS(MH_Master_List!$S$5:$S$61,MH_Master_List!$Z$5:$Z$61,$A15,MH_Master_List!$B$5:$B$61,"<>CTUIL",MH_Master_List!$V$5:$V$61,"4*") -> 0 | E15: =SUMIFS(MH_Master_List!$S$5:$S$61,MH_Master_List!$Z$5:$Z$61,$A15,MH_Master_List!$B$5:$B$61,"<>CTUIL",MH_Master_List!$V$5:$V$61,"5*") -> 0 | F15: =SUM(B15:E15) -> 229 | G15: =SUMIFS(MH_Master_List!$I$5:$I$61,MH_Master_List!$Z$5:$Z$61,$A15,MH_Master_List!$B$5:$B$61,"<>CTUIL") -> 16 | I15: MH16, MH37 | J15: Only the two ex-Microsoft Pune sites; Adani's other MH power (Support Properties 1,468, Adani Infra 500) is CTUIL and excluded
A16: Digital Edge | B16: =SUMIFS(MH_Master_List!$S$5:$S$61,MH_Master_List!$Z$5:$Z$61,$A16,MH_Master_List!$B$5:$B$61,"<>CTUIL",MH_Master_List!$V$5:$V$61,"1*")+SUMIFS(MH_Master_List!$S$5:$S$61,MH_Master_List!$Z$5:$Z$61,$A16,MH_Master_List!$B$5:$B$61,"<>CTUIL",MH_Master_List!$V$5:$V$61,"2*") -> 225 | C16: =SUMIFS(MH_Master_List!$S$5:$S$61,MH_Master_List!$Z$5:$Z$61,$A16,MH_Master_List!$B$5:$B$61,"<>CTUIL",MH_Master_List!$V$5:$V$61,"3*") -> 0 | D16: =SUMIFS(MH_Master_List!$S$5:$S$61,MH_Master_List!$Z$5:$Z$61,$A16,MH_Master_List!$B$5:$B$61,"<>CTUIL",MH_Master_List!$V$5:$V$61,"4*") -> 0 | E16: =SUMIFS(MH_Master_List!$S$5:$S$61,MH_Master_List!$Z$5:$Z$61,$A16,MH_Master_List!$B$5:$B$61,"<>CTUIL",MH_Master_List!$V$5:$V$61,"5*") -> 0 | F16: =SUM(B16:E16) -> 225 | G16: =SUMIFS(MH_Master_List!$I$5:$I$61,MH_Master_List!$Z$5:$Z$61,$A16,MH_Master_List!$B$5:$B$61,"<>CTUIL") -> 25 | I16: MH07, MH29
A17: Bharti Airtel (Nxtra) | B17: =SUMIFS(MH_Master_List!$S$5:$S$61,MH_Master_List!$Z$5:$Z$61,$A17,MH_Master_List!$B$5:$B$61,"<>CTUIL",MH_Master_List!$V$5:$V$61,"1*")+SUMIFS(MH_Master_List!$S$5:$S$61,MH_Master_List!$Z$5:$Z$61,$A17,MH_Master_List!$B$5:$B$61,"<>CTUIL",MH_Master_List!$V$5:$V$61,"2*") -> 221 | C17: =SUMIFS(MH_Master_List!$S$5:$S$61,MH_Master_List!$Z$5:$Z$61,$A17,MH_Master_List!$B$5:$B$61,"<>CTUIL",MH_Master_List!$V$5:$V$61,"3*") -> 0 | D17: =SUMIFS(MH_Master_List!$S$5:$S$61,MH_Master_List!$Z$5:$Z$61,$A17,MH_Master_List!$B$5:$B$61,"<>CTUIL",MH_Master_List!$V$5:$V$61,"4*") -> 0 | E17: =SUMIFS(MH_Master_List!$S$5:$S$61,MH_Master_List!$Z$5:$Z$61,$A17,MH_Master_List!$B$5:$B$61,"<>CTUIL",MH_Master_List!$V$5:$V$61,"5*") -> 0 | F17: =SUM(B17:E17) -> 221 | G17: =SUMIFS(MH_Master_List!$I$5:$I$61,MH_Master_List!$Z$5:$Z$61,$A17,MH_Master_List!$B$5:$B$61,"<>CTUIL") -> 121 | I17: MH01, MH17, MH18
A18: MAHAPREIT (state) | B18: =SUMIFS(MH_Master_List!$S$5:$S$61,MH_Master_List!$Z$5:$Z$61,$A18,MH_Master_List!$B$5:$B$61,"<>CTUIL",MH_Master_List!$V$5:$V$61,"1*")+SUMIFS(MH_Master_List!$S$5:$S$61,MH_Master_List!$Z$5:$Z$61,$A18,MH_Master_List!$B$5:$B$61,"<>CTUIL",MH_Master_List!$V$5:$V$61,"2*") -> 0 | C18: =SUMIFS(MH_Master_List!$S$5:$S$61,MH_Master_List!$Z$5:$Z$61,$A18,MH_Master_List!$B$5:$B$61,"<>CTUIL",MH_Master_List!$V$5:$V$61,"3*") -> 0 | D18: =SUMIFS(MH_Master_List!$S$5:$S$61,MH_Master_List!$Z$5:$Z$61,$A18,MH_Master_List!$B$5:$B$61,"<>CTUIL",MH_Master_List!$V$5:$V$61,"4*") -> 0 | E18: =SUMIFS(MH_Master_List!$S$5:$S$61,MH_Master_List!$Z$5:$Z$61,$A18,MH_Master_List!$B$5:$B$61,"<>CTUIL",MH_Master_List!$V$5:$V$61,"5*") -> 200 | F18: =SUM(B18:E18) -> 200 | G18: =SUMIFS(MH_Master_List!$I$5:$I$61,MH_Master_List!$Z$5:$Z$61,$A18,MH_Master_List!$B$5:$B$61,"<>CTUIL") -> 0 | H18: MAHAPREIT - State DC project: 200 MW, EOI stage (MH48) | I18: MH48
A19: Sify | B19: =SUMIFS(MH_Master_List!$S$5:$S$61,MH_Master_List!$Z$5:$Z$61,$A19,MH_Master_List!$B$5:$B$61,"<>CTUIL",MH_Master_List!$V$5:$V$61,"1*")+SUMIFS(MH_Master_List!$S$5:$S$61,MH_Master_List!$Z$5:$Z$61,$A19,MH_Master_List!$B$5:$B$61,"<>CTUIL",MH_Master_List!$V$5:$V$61,"2*") -> 160 | C19: =SUMIFS(MH_Master_List!$S$5:$S$61,MH_Master_List!$Z$5:$Z$61,$A19,MH_Master_List!$B$5:$B$61,"<>CTUIL",MH_Master_List!$V$5:$V$61,"3*") -> 0 | D19: =SUMIFS(MH_Master_List!$S$5:$S$61,MH_Master_List!$Z$5:$Z$61,$A19,MH_Master_List!$B$5:$B$61,"<>CTUIL",MH_Master_List!$V$5:$V$61,"4*") -> 0 | E19: =SUMIFS(MH_Master_List!$S$5:$S$61,MH_Master_List!$Z$5:$Z$61,$A19,MH_Master_List!$B$5:$B$61,"<>CTUIL",MH_Master_List!$V$5:$V$61,"5*") -> 0 | F19: =SUM(B19:E19) -> 160 | G19: =SUMIFS(MH_Master_List!$I$5:$I$61,MH_Master_List!$Z$5:$Z$61,$A19,MH_Master_List!$B$5:$B$61,"<>CTUIL") -> 100 | I19: MH14, MH15
A20: CapitaLand | B20: =SUMIFS(MH_Master_List!$S$5:$S$61,MH_Master_List!$Z$5:$Z$61,$A20,MH_Master_List!$B$5:$B$61,"<>CTUIL",MH_Master_List!$V$5:$V$61,"1*")+SUMIFS(MH_Master_List!$S$5:$S$61,MH_Master_List!$Z$5:$Z$61,$A20,MH_Master_List!$B$5:$B$61,"<>CTUIL",MH_Master_List!$V$5:$V$61,"2*") -> 120 | C20: =SUMIFS(MH_Master_List!$S$5:$S$61,MH_Master_List!$Z$5:$Z$61,$A20,MH_Master_List!$B$5:$B$61,"<>CTUIL",MH_Master_List!$V$5:$V$61,"3*") -> 0 | D20: =SUMIFS(MH_Master_List!$S$5:$S$61,MH_Master_List!$Z$5:$Z$61,$A20,MH_Master_List!$B$5:$B$61,"<>CTUIL",MH_Master_List!$V$5:$V$61,"4*") -> 0 | E20: =SUMIFS(MH_Master_List!$S$5:$S$61,MH_Master_List!$Z$5:$Z$61,$A20,MH_Master_List!$B$5:$B$61,"<>CTUIL",MH_Master_List!$V$5:$V$61,"5*") -> 0 | F20: =SUM(B20:E20) -> 120 | G20: =SUMIFS(MH_Master_List!$I$5:$I$61,MH_Master_List!$Z$5:$Z$61,$A20,MH_Master_List!$B$5:$B$61,"<>CTUIL") -> 18 | I20: MH04
A21: Iron Mountain (Web Werks) | B21: =SUMIFS(MH_Master_List!$S$5:$S$61,MH_Master_List!$Z$5:$Z$61,$A21,MH_Master_List!$B$5:$B$61,"<>CTUIL",MH_Master_List!$V$5:$V$61,"1*")+SUMIFS(MH_Master_List!$S$5:$S$61,MH_Master_List!$Z$5:$Z$61,$A21,MH_Master_List!$B$5:$B$61,"<>CTUIL",MH_Master_List!$V$5:$V$61,"2*") -> 120 | C21: =SUMIFS(MH_Master_List!$S$5:$S$61,MH_Master_List!$Z$5:$Z$61,$A21,MH_Master_List!$B$5:$B$61,"<>CTUIL",MH_Master_List!$V$5:$V$61,"3*") -> 0 | D21: =SUMIFS(MH_Master_List!$S$5:$S$61,MH_Master_List!$Z$5:$Z$61,$A21,MH_Master_List!$B$5:$B$61,"<>CTUIL",MH_Master_List!$V$5:$V$61,"4*") -> 0 | E21: =SUMIFS(MH_Master_List!$S$5:$S$61,MH_Master_List!$Z$5:$Z$61,$A21,MH_Master_List!$B$5:$B$61,"<>CTUIL",MH_Master_List!$V$5:$V$61,"5*") -> 0 | F21: =SUM(B21:E21) -> 120 | G21: =SUMIFS(MH_Master_List!$I$5:$I$61,MH_Master_List!$Z$5:$Z$61,$A21,MH_Master_List!$B$5:$B$61,"<>CTUIL") -> 0 | I21: MH32
A22: Unidentified (Chandivali) | B22: =SUMIFS(MH_Master_List!$S$5:$S$61,MH_Master_List!$Z$5:$Z$61,$A22,MH_Master_List!$B$5:$B$61,"<>CTUIL",MH_Master_List!$V$5:$V$61,"1*")+SUMIFS(MH_Master_List!$S$5:$S$61,MH_Master_List!$Z$5:$Z$61,$A22,MH_Master_List!$B$5:$B$61,"<>CTUIL",MH_Master_List!$V$5:$V$61,"2*") -> 0 | C22: =SUMIFS(MH_Master_List!$S$5:$S$61,MH_Master_List!$Z$5:$Z$61,$A22,MH_Master_List!$B$5:$B$61,"<>CTUIL",MH_Master_List!$V$5:$V$61,"3*") -> 0 | D22: =SUMIFS(MH_Master_List!$S$5:$S$61,MH_Master_List!$Z$5:$Z$61,$A22,MH_Master_List!$B$5:$B$61,"<>CTUIL",MH_Master_List!$V$5:$V$61,"4*") -> 113.9 | E22: =SUMIFS(MH_Master_List!$S$5:$S$61,MH_Master_List!$Z$5:$Z$61,$A22,MH_Master_List!$B$5:$B$61,"<>CTUIL",MH_Master_List!$V$5:$V$61,"5*") -> 0 | F22: =SUM(B22:E22) -> 113.9 | G22: =SUMIFS(MH_Master_List!$I$5:$I$61,MH_Master_List!$Z$5:$Z$61,$A22,MH_Master_List!$B$5:$B$61,"<>CTUIL") -> 0 | I22: MH43
A23: Unidentified ('IMCC') | B23: =SUMIFS(MH_Master_List!$S$5:$S$61,MH_Master_List!$Z$5:$Z$61,$A23,MH_Master_List!$B$5:$B$61,"<>CTUIL",MH_Master_List!$V$5:$V$61,"1*")+SUMIFS(MH_Master_List!$S$5:$S$61,MH_Master_List!$Z$5:$Z$61,$A23,MH_Master_List!$B$5:$B$61,"<>CTUIL",MH_Master_List!$V$5:$V$61,"2*") -> 106 | C23: =SUMIFS(MH_Master_List!$S$5:$S$61,MH_Master_List!$Z$5:$Z$61,$A23,MH_Master_List!$B$5:$B$61,"<>CTUIL",MH_Master_List!$V$5:$V$61,"3*") -> 0 | D23: =SUMIFS(MH_Master_List!$S$5:$S$61,MH_Master_List!$Z$5:$Z$61,$A23,MH_Master_List!$B$5:$B$61,"<>CTUIL",MH_Master_List!$V$5:$V$61,"4*") -> 0 | E23: =SUMIFS(MH_Master_List!$S$5:$S$61,MH_Master_List!$Z$5:$Z$61,$A23,MH_Master_List!$B$5:$B$61,"<>CTUIL",MH_Master_List!$V$5:$V$61,"5*") -> 0 | F23: =SUM(B23:E23) -> 106 | G23: =SUMIFS(MH_Master_List!$I$5:$I$61,MH_Master_List!$Z$5:$Z$61,$A23,MH_Master_List!$B$5:$B$61,"<>CTUIL") -> 0 | I23: MH34
A24: Colt DCS - RMZ | B24: =SUMIFS(MH_Master_List!$S$5:$S$61,MH_Master_List!$Z$5:$Z$61,$A24,MH_Master_List!$B$5:$B$61,"<>CTUIL",MH_Master_List!$V$5:$V$61,"1*")+SUMIFS(MH_Master_List!$S$5:$S$61,MH_Master_List!$Z$5:$Z$61,$A24,MH_Master_List!$B$5:$B$61,"<>CTUIL",MH_Master_List!$V$5:$V$61,"2*") -> 60 | C24: =SUMIFS(MH_Master_List!$S$5:$S$61,MH_Master_List!$Z$5:$Z$61,$A24,MH_Master_List!$B$5:$B$61,"<>CTUIL",MH_Master_List!$V$5:$V$61,"3*") -> 0 | D24: =SUMIFS(MH_Master_List!$S$5:$S$61,MH_Master_List!$Z$5:$Z$61,$A24,MH_Master_List!$B$5:$B$61,"<>CTUIL",MH_Master_List!$V$5:$V$61,"4*") -> 0 | E24: =SUMIFS(MH_Master_List!$S$5:$S$61,MH_Master_List!$Z$5:$Z$61,$A24,MH_Master_List!$B$5:$B$61,"<>CTUIL",MH_Master_List!$V$5:$V$61,"5*") -> 0 | F24: =SUM(B24:E24) -> 60 | G24: =SUMIFS(MH_Master_List!$I$5:$I$61,MH_Master_List!$Z$5:$Z$61,$A24,MH_Master_List!$B$5:$B$61,"<>CTUIL") -> 10 | I24: MH05
A25: Yotta (Hiranandani) | B25: =SUMIFS(MH_Master_List!$S$5:$S$61,MH_Master_List!$Z$5:$Z$61,$A25,MH_Master_List!$B$5:$B$61,"<>CTUIL",MH_Master_List!$V$5:$V$61,"1*")+SUMIFS(MH_Master_List!$S$5:$S$61,MH_Master_List!$Z$5:$Z$61,$A25,MH_Master_List!$B$5:$B$61,"<>CTUIL",MH_Master_List!$V$5:$V$61,"2*") -> 52 | C25: =SUMIFS(MH_Master_List!$S$5:$S$61,MH_Master_List!$Z$5:$Z$61,$A25,MH_Master_List!$B$5:$B$61,"<>CTUIL",MH_Master_List!$V$5:$V$61,"3*") -> 0 | D25: =SUMIFS(MH_Master_List!$S$5:$S$61,MH_Master_List!$Z$5:$Z$61,$A25,MH_Master_List!$B$5:$B$61,"<>CTUIL",MH_Master_List!$V$5:$V$61,"4*") -> 0 | E25: =SUMIFS(MH_Master_List!$S$5:$S$61,MH_Master_List!$Z$5:$Z$61,$A25,MH_Master_List!$B$5:$B$61,"<>CTUIL",MH_Master_List!$V$5:$V$61,"5*") -> 0 | F25: =SUM(B25:E25) -> 52 | G25: =SUMIFS(MH_Master_List!$I$5:$I$61,MH_Master_List!$Z$5:$Z$61,$A25,MH_Master_List!$B$5:$B$61,"<>CTUIL") -> 0 | I25: MH36
A26: Unidentified ('Innovative') | B26: =SUMIFS(MH_Master_List!$S$5:$S$61,MH_Master_List!$Z$5:$Z$61,$A26,MH_Master_List!$B$5:$B$61,"<>CTUIL",MH_Master_List!$V$5:$V$61,"1*")+SUMIFS(MH_Master_List!$S$5:$S$61,MH_Master_List!$Z$5:$Z$61,$A26,MH_Master_List!$B$5:$B$61,"<>CTUIL",MH_Master_List!$V$5:$V$61,"2*") -> 50 | C26: =SUMIFS(MH_Master_List!$S$5:$S$61,MH_Master_List!$Z$5:$Z$61,$A26,MH_Master_List!$B$5:$B$61,"<>CTUIL",MH_Master_List!$V$5:$V$61,"3*") -> 0 | D26: =SUMIFS(MH_Master_List!$S$5:$S$61,MH_Master_List!$Z$5:$Z$61,$A26,MH_Master_List!$B$5:$B$61,"<>CTUIL",MH_Master_List!$V$5:$V$61,"4*") -> 0 | E26: =SUMIFS(MH_Master_List!$S$5:$S$61,MH_Master_List!$Z$5:$Z$61,$A26,MH_Master_List!$B$5:$B$61,"<>CTUIL",MH_Master_List!$V$5:$V$61,"5*") -> 0 | F26: =SUM(B26:E26) -> 50 | G26: =SUMIFS(MH_Master_List!$I$5:$I$61,MH_Master_List!$Z$5:$Z$61,$A26,MH_Master_List!$B$5:$B$61,"<>CTUIL") -> 0 | I26: MH35
A27: Bridge Data Centres | B27: =SUMIFS(MH_Master_List!$S$5:$S$61,MH_Master_List!$Z$5:$Z$61,$A27,MH_Master_List!$B$5:$B$61,"<>CTUIL",MH_Master_List!$V$5:$V$61,"1*")+SUMIFS(MH_Master_List!$S$5:$S$61,MH_Master_List!$Z$5:$Z$61,$A27,MH_Master_List!$B$5:$B$61,"<>CTUIL",MH_Master_List!$V$5:$V$61,"2*") -> 32 | C27: =SUMIFS(MH_Master_List!$S$5:$S$61,MH_Master_List!$Z$5:$Z$61,$A27,MH_Master_List!$B$5:$B$61,"<>CTUIL",MH_Master_List!$V$5:$V$61,"3*") -> 0 | D27: =SUMIFS(MH_Master_List!$S$5:$S$61,MH_Master_List!$Z$5:$Z$61,$A27,MH_Master_List!$B$5:$B$61,"<>CTUIL",MH_Master_List!$V$5:$V$61,"4*") -> 0 | E27: =SUMIFS(MH_Master_List!$S$5:$S$61,MH_Master_List!$Z$5:$Z$61,$A27,MH_Master_List!$B$5:$B$61,"<>CTUIL",MH_Master_List!$V$5:$V$61,"5*") -> 0 | F27: =SUM(B27:E27) -> 32 | G27: =SUMIFS(MH_Master_List!$I$5:$I$61,MH_Master_List!$Z$5:$Z$61,$A27,MH_Master_List!$B$5:$B$61,"<>CTUIL") -> 32 | I27: MH03
A28: TOTAL | B28: =SUM(B5:B27) -> 6525 | C28: =SUM(C5:C27) -> 1500 | D28: =SUM(D5:D27) -> 113.9 | E28: =SUM(E5:E27) -> 4450 | F28: =SUM(F5:F27) -> 12588.9 | G28: =SUM(G5:G27) -> 685
A30: Check: all verifiable MW in MH_Master_List excl. CTUIL | B30: =SUMIFS(MH_Master_List!$S$5:$S$61,MH_Master_List!$B$5:$B$61,"<>CTUIL") -> 12588.9
A31: Difference (must be 0) | B31: =F28-B30 -> 0
A32: For reference: CTUIL rows excluded (MW) | B32: =SUMIFS(MH_Master_List!$S$5:$S$61,MH_Master_List!$B$5:$B$61,"CTUIL") -> 2068
A33: For reference: total incl. CTUIL | B33: =SUM(MH_Master_List!$S$5:$S$61) -> 14656.9
A35: Not in the chart: rows with no verifiable MW (company / press claims only: PDG 270, Zerra 240, L&T Vyoma 100, ESR 60, TCC 60, Avisirah 5.5; permit records without MW).
A36: Grey 'Permit only' = Chandivali 113.9 MW connected load in SEIAA EC minutes (no grid record yet).

Sheet MH_Master_List
A1: Maharashtra data centres - combined master list (SLDC grid + CTUIL + MERC + permits + our dataset), one row per project
A2: Verifiable MW = figure found in an official record, in priority order: SLDC/STU sanctioned load (Dec-2025) > CTUIL GNA (approved + under process) > other official (MERC order, EC/SEIAA connected load, state GO/LoI/MoU/EOI). Company / press figures are shown separately and NOT counted as verifiable. Grid MW (SLDC, CTUIL, MERC) and connected-load MW are facility power, not IT MW (IT is roughly 55-65% of facility load per SLDC).
A4: ID | B4: Primary record | C4: Group | D4: Company / SPV (as filed) | E4: Site / location | F4: Cluster | G4: Grid connection | H4: SLDC sanctioned (MW) | I4: SLDC realised (MW) | J4: SLDC avg load 3 m (MW) | K4: CTUIL approved (MW) | L4: CTUIL under process (MW) | M4: Other official (MW) | N4: Other official basis | O4: Other official tier | P4: Company / press (MW) | Q4: Company / press basis & tier | R4: Permits (EC / MPCB) | S4: VERIFIABLE MW | T4: Verifiable source | U4: Indicative MW (incl. unverified) | V4: Stage | W4: Primary source | X4: Other source | Y4: Notes | Z4: Chart group
A5: MH01 | B5: SLDC | C5: Bharti Airtel (Nxtra) | D5: M/s. Nxtra | E5: TTC, Mahape | F5: Navi Mumbai - TTC | G5: LILO on 220 kV Kalwa-Tiffil line | H5: 35 | I5: 35 | J5: 2.28 | R5: SEIAA EC (expansion) - Granted (M022); MPCB CTE expansion (Feb-25); CTO part (Jun-25) - Approved (M023) | S5: =IF(N(H5)>0,H5,IF(N(K5)+N(L5)>0,N(K5)+N(L5),IF(AND(N(M5)>0,OR(O5="A1",O5="A2")),M5,0))) -> 35 | T5: =IF(N(H5)>0,"SLDC",IF(N(K5)+N(L5)>0,"CTUIL",IF(S5>0,"Other official",IF(N(P5)>0,"Unverified","No MW")))) -> SLDC | U5: =IF(S5>0,S5,N(P5)) -> 35 | V5: 1 Grid sanctioned - partly live | W5: https://mahasldc.in/assets/public-ui/files/Data_Centre.pdf#page=23 | X5: https://assets.airtel.in/nxtra/pdf/EC_Environmental_Clearance_Certificate_Nxtra%20Mahape_DC-02_25.11.25.pdf | Y5: SLDC MMR #8. Not in our MH state data (Airtel Nxtra) | Z5: Bharti Airtel (Nxtra)
A6: MH02 | B6: SLDC | C6: Blackstone / AirTrunk (Gramercy SPVs) - inferred | D6: M/s Estela Hindustan Unilever (Gramercy Techpark) | E6: TTC MIDC, Airoli | F6: Navi Mumbai - TTC | G6: LILO on 220 kV Kalwa-Taloja-Panchanand | H6: 90 | I6: 35 | J6: 5 | P6: 62 | Q6: IT MW - tier D | R6: MPCB Consent to Establish - Approved (M024); MPCB / SEIAA CTO (part); EC expansion - Approved / on agenda (M025) | S6: =IF(N(H6)>0,H6,IF(N(K6)+N(L6)>0,N(K6)+N(L6),IF(AND(N(M6)>0,OR(O6="A1",O6="A2")),M6,0))) -> 90 | T6: =IF(N(H6)>0,"SLDC",IF(N(K6)+N(L6)>0,"CTUIL",IF(S6>0,"Other official",IF(N(P6)>0,"Unverified","No MW")))) -> SLDC | U6: =IF(S6>0,S6,N(P6)) -> 90 | V6: 1 Grid sanctioned - partly live | W6: https://mahasldc.in/assets/public-ui/files/Data_Centre.pdf#page=24 | X6: https://mpcb.gov.in/sites/default/files/inline-files/Minutes%20of%2015th%20CAC%20Establish%20Booklet%20no%2065.pdf | Y6: SLDC MMR #13. Official grid figure (90 MW) replaces directory-sourced 62 MW | Z6: Blackstone / AirTrunk
A7: MH03 | B7: SLDC | C7: Bridge Data Centres | D7: M/s. Bridge Data Centre | E7: Dighi MIDC, Navi Mumbai | F7: Navi Mumbai - TTC | G7: LILO on 100 kV Kalwa-Mukund ckt-1 | H7: 32 | I7: 32 | J7: 10.93 | R7: MPCB CTO renewal - Approved (M040) | S7: =IF(N(H7)>0,H7,IF(N(K7)+N(L7)>0,N(K7)+N(L7),IF(AND(N(M7)>0,OR(O7="A1",O7="A2")),M7,0))) -> 32 | T7: =IF(N(H7)>0,"SLDC",IF(N(K7)+N(L7)>0,"CTUIL",IF(S7>0,"Other official",IF(N(P7)>0,"Unverified","No MW")))) -> SLDC | U7: =IF(S7>0,S7,N(P7)) -> 32 | V7: 1 Grid sanctioned - partly live | W7: https://mahasldc.in/assets/public-ui/files/Data_Centre.pdf#page=26 | X7: https://mpcb.gov.in/sites/default/files/inline-files/Index_Of_15th_CAC_Meeting.pdf | Y7: SLDC MMR #29. Not in our data; operating (avg ~11 MW) | Z7: Bridge Data Centres
A8: MH04 | B8: SLDC | C8: CapitaLand | D8: M/s. Datascape | E8: TTC, Dighe | F8: Navi Mumbai - TTC | G8: LILO on 220 kV Kalwa-Bapgaon | H8: 120 | I8: 18 | J8: 9 | M8: 135 | N8: EC / Form-1A connected load | O8: A1 | P8: 135 | Q8: Connected MW - tier A1 | R8: SEIAA EC (expansion) - Discussed (M005); MPCB Consent to Establish - Listed (M006); MPCB Consent to 1st Operate (part) - Approved (M007) | S8: =IF(N(H8)>0,H8,IF(N(K8)+N(L8)>0,N(K8)+N(L8),IF(AND(N(M8)>0,OR(O8="A1",O8="A2")),M8,0))) -> 120 | T8: =IF(N(H8)>0,"SLDC",IF(N(K8)+N(L8)>0,"CTUIL",IF(S8>0,"Other official",IF(N(P8)>0,"Unverified","No MW")))) -> SLDC | U8: =IF(S8>0,S8,N(P8)) -> 120 | V8: 1 Grid sanctioned - partly live | W8: https://mahasldc.in/assets/public-ui/files/Data_Centre.pdf#page=24 | X8: https://environmentclearance.nic.in/writereaddata/FormB/agenda/1509202585756580%28740114%29MINUTESOF301DAY-4TABLEITEM-Copy.pdf | Y8: SLDC MMR #17. | Z8: CapitaLand
A9: MH05 | B9: SLDC | C9: Colt DCS - RMZ | D9: M/s. Data Centre Holding | E9: Kalwa Industrial Area, Dighe, Airoli | F9: Navi Mumbai - TTC | G9: LILO on 220 kV Kalwa-Colourchem | H9: 60 | I9: 10 | J9: 1.2 | P9: 148 | Q9: IT MW - tier C | R9: MPCB CTO / renewal - Approved (M039) | S9: =IF(N(H9)>0,H9,IF(N(K9)+N(L9)>0,N(K9)+N(L9),IF(AND(N(M9)>0,OR(O9="A1",O9="A2")),M9,0))) -> 60 | T9: =IF(N(H9)>0,"SLDC",IF(N(K9)+N(L9)>0,"CTUIL",IF(S9>0,"Other official",IF(N(P9)>0,"Unverified","No MW")))) -> SLDC | U9: =IF(S9>0,S9,N(P9)) -> 60 | V9: 1 Grid sanctioned - partly live | W9: https://mahasldc.in/assets/public-ui/files/Data_Centre.pdf#page=24 | X9: https://indianinfrastructure.com/2026/10/16/colt-dcs-and-rmz-begin-construction-of-third-data-centre-in-mumbai/ | Y9: SLDC MMR #16. SLDC sanction only 60 MW so far vs 148 MW campus potential | Z9: Colt DCS - RMZ
A10: MH06 | B10: SLDC | C10: CtrlS | D10: M/s CTRLS | E10: TTC MIDC, Mahape | F10: Navi Mumbai - TTC | G10: LILO on ckt-I of 220 kV Kharghar-Borivali D/C | H10: 295 | I10: 70 | J10: 43 | P10: 214 | Q10: IT MW - tier A1 | R10: MPCB CTE for expansion - Approved (M038) | S10: =IF(N(H10)>0,H10,IF(N(K10)+N(L10)>0,N(K10)+N(L10),IF(AND(N(M10)>0,OR(O10="A1",O10="A2")),M10,0))) -> 295 | T10: =IF(N(H10)>0,"SLDC",IF(N(K10)+N(L10)>0,"CTUIL",IF(S10>0,"Other official",IF(N(P10)>0,"Unverified","No MW")))) -> SLDC | U10: =IF(S10>0,S10,N(P10)) -> 295 | V10: 1 Grid sanctioned - partly live | W10: https://mahasldc.in/assets/public-ui/files/Data_Centre.pdf#page=22 | X10: https://www.ctrls.com/ | Y10: SLDC MMR #3. SLDC: 295 MW sanctioned + 290 MW 'CtrlS New' (#24) = 585 MW grid vs our 214 IT MW. Site visit: 70 MW live, avg 42-45 MW | Z10: CtrlS
A11: MH07 | B11: SLDC | C11: Digital Edge | D11: M/s. Digital Edge (AGP) | E11: Mukund Ltd, Kalwa & Digha | F11: Navi Mumbai - TTC | G11: LILO on 100 kV Kalwa-BDC-Mukund I & II | H11: 35 | I11: 25 | J11: 0.97 | R11: MPCB Consent to 1st Operate - Approved (M020) | S11: =IF(N(H11)>0,H11,IF(N(K11)+N(L11)>0,N(K11)+N(L11),IF(AND(N(M11)>0,OR(O11="A1",O11="A2")),M11,0))) -> 35 | T11: =IF(N(H11)>0,"SLDC",IF(N(K11)+N(L11)>0,"CTUIL",IF(S11>0,"Other official",IF(N(P11)>0,"Unverified","No MW")))) -> SLDC | U11: =IF(S11>0,S11,N(P11)) -> 35 | V11: 1 Grid sanctioned - partly live | W11: https://mahasldc.in/assets/public-ui/files/Data_Centre.pdf#page=26 | X11: https://mpcb.gov.in/sites/default/files/inline-files/Action_Taken_Report_of_17th_CAC_Booklet_no_17_2024-25.pdf | Y11: SLDC MMR #27. SLDC: Digital Edge #27 + #28 = 225 MW grid vs 350 MW campus | Z11: Digital Edge
A12: MH08 | B12: SLDC | C12: K Raheja Corp / Mindspace | D12: M/s Newfound | E12: TTC Industrial Area, Thane, Navi Mumbai | F12: Navi Mumbai - TTC | G12: LILO on 220 kV Kharghar-Sonkhar line | H12: 250 | I12: 36 | J12: 0.42 | R12: SEIAA / MPCB CTO Part-I for Bldg 5A (Data Centre) - Approved (M033) | S12: =IF(N(H12)>0,H12,IF(N(K12)+N(L12)>0,N(K12)+N(L12),IF(AND(N(M12)>0,OR(O12="A1",O12="A2")),M12,0))) -> 250 | T12: =IF(N(H12)>0,"SLDC",IF(N(K12)+N(L12)>0,"CTUIL",IF(S12>0,"Other official",IF(N(P12)>0,"Unverified","No MW")))) -> SLDC | U12: =IF(S12>0,S12,N(P12)) -> 250 | V12: 1 Grid sanctioned - partly live | W12: https://mahasldc.in/assets/public-ui/files/Data_Centre.pdf#page=22 | X12: https://mpcb.gov.in/sites/default/files/inline-files/Action_Taken_Report_of_17th_CAC_Booklet_no_17_2024-25.pdf | Y12: SLDC MMR #4. Not in state data; 250 MW sanctioned to 2034 | Z12: K Raheja Corp / Mindspace
A13: MH09 | B13: SLDC | C13: K Raheja Corp / Mindspace | D13: M/s Gigaplex | E13: Airoli Knowledge Park, Airoli | F13: Navi Mumbai - TTC | G13: LILO on 220 kV Kalwa-Bapgaon | H13: 285 | I13: 35 | J13: 7 | R13: SEIAA / MPCB CTO application; EC amendment - Listed (M034) | S13: =IF(N(H13)>0,H13,IF(N(K13)+N(L13)>0,N(K13)+N(L13),IF(AND(N(M13)>0,OR(O13="A1",O13="A2")),M13,0))) -> 285 | T13: =IF(N(H13)>0,"SLDC",IF(N(K13)+N(L13)>0,"CTUIL",IF(S13>0,"Other official",IF(N(P13)>0,"Unverified","No MW")))) -> SLDC | U13: =IF(S13>0,S13,N(P13)) -> 285 | V13: 1 Grid sanctioned - partly live | W13: https://mahasldc.in/assets/public-ui/files/Data_Centre.pdf#page=22 | X13: https://mpcb.gov.in/sites/default/files/inline-files/Index_of_4th_CAC_Meeting_of_2025-26.pdf | Y13: SLDC MMR #5. Not in state data; 285 MW sanctioned to 2031 | Z13: K Raheja Corp / Mindspace
A14: MH10 | B14: SLDC | C14: NTT | D14: M/s Netmagic | E14: TTC, Mahape | F14: Navi Mumbai - TTC | G14: LILO on ckt-1 of 220 kV Kharghar-Borivali D/C | H14: 90 | I14: 25 | J14: 23.19 | S14: =IF(N(H14)>0,H14,IF(N(K14)+N(L14)>0,N(K14)+N(L14),IF(AND(N(M14)>0,OR(O14="A1",O14="A2")),M14,0))) -> 90 | T14: =IF(N(H14)>0,"SLDC",IF(N(K14)+N(L14)>0,"CTUIL",IF(S14>0,"Other official",IF(N(P14)>0,"Unverified","No MW")))) -> SLDC | U14: =IF(S14>0,S14,N(P14)) -> 90 | V14: 1 Grid sanctioned - partly live | W14: https://mahasldc.in/assets/public-ui/files/Data_Centre.pdf#page=23 | Y14: SLDC MMR #6. SLDC: NTT sites #6 + #9 + #18 = 665 MW grid | Z14: NTT
A15: MH11 | B15: SLDC | C15: NTT | D15: M/s. Estela Mukund (NTT Global) | E15: Bhola Nagar, Kalwa | F15: Navi Mumbai - TTC | G15: Interim LILO on 220 kV Kalwa-Bapgaon; final LILO on 400 kV Kalwa-Padghe | H15: 500 | I15: 50 | J15: 14 | P15: 366 | Q15: IT MW - tier C | R15: MPCB CTO; renewal (part) - Approved (M036) | S15: =IF(N(H15)>0,H15,IF(N(K15)+N(L15)>0,N(K15)+N(L15),IF(AND(N(M15)>0,OR(O15="A1",O15="A2")),M15,0))) -> 500 | T15: =IF(N(H15)>0,"SLDC",IF(N(K15)+N(L15)>0,"CTUIL",IF(S15>0,"Other official",IF(N(P15)>0,"Unverified","No MW")))) -> SLDC | U15: =IF(S15>0,S15,N(P15)) -> 500 | V15: 1 Grid sanctioned - partly live | W15: https://mahasldc.in/assets/public-ui/files/Data_Centre.pdf#page=23 | X15: https://www.datacenterdynamics.com/en/news/ntt-announces-500mw-nav2-data-center-in-navi-mumbai-india/ | Y15: SLDC MMR #9. NAV2 = 500 MW facility; our IT figure is consistent | Z15: NTT
A16: MH12 | B16: SLDC | C16: NTT | D16: M/s. NTT Global DC-13 | E16: TTC, Bhola Nagar, Kalwa | F16: Navi Mumbai - TTC | G16: LILO on 220 kV Kalwa-Bapgaon at 220 kV GIS of NTT NAV2 (DC-13) | H16: 75 | I16: 15 | J16: 5 | S16: =IF(N(H16)>0,H16,IF(N(K16)+N(L16)>0,N(K16)+N(L16),IF(AND(N(M16)>0,OR(O16="A1",O16="A2")),M16,0))) -> 75 | T16: =IF(N(H16)>0,"SLDC",IF(N(K16)+N(L16)>0,"CTUIL",IF(S16>0,"Other official",IF(N(P16)>0,"Unverified","No MW")))) -> SLDC | U16: =IF(S16>0,S16,N(P16)) -> 75 | V16: 1 Grid sanctioned - partly live | W16: https://mahasldc.in/assets/public-ui/files/Data_Centre.pdf#page=24 | Y16: SLDC MMR #18. | Z16: NTT
A17: MH13 | B17: SLDC | C17: STT GDC | D17: M/s. STT Global | E17: TTC MIDC, Khairane | F17: Navi Mumbai - TTC | G17: LILO on 220 kV Mahape-Tiffil | H17: 80 | I17: 40 | J17: 5 | P17: 133 | Q17: IT MW - tier A1 | R17: MPCB CTE; CTO (part); amendment - Approved (M035) | S17: =IF(N(H17)>0,H17,IF(N(K17)+N(L17)>0,N(K17)+N(L17),IF(AND(N(M17)>0,OR(O17="A1",O17="A2")),M17,0))) -> 80 | T17: =IF(N(H17)>0,"SLDC",IF(N(K17)+N(L17)>0,"CTUIL",IF(S17>0,"Other official",IF(N(P17)>0,"Unverified","No MW")))) -> SLDC | U17: =IF(S17>0,S17,N(P17)) -> 80 | V17: 1 Grid sanctioned - partly live | W17: https://mahasldc.in/assets/public-ui/files/Data_Centre.pdf#page=24 | X17: https://www.sttelemediagdc.com/in-en/locations/mumbai | Y17: SLDC MMR #14. | Z17: STT GDC
A18: MH14 | B18: SLDC | C18: Sify | D18: M/s Print House (Sify Infinit Spaces) | E18: TTC, Rabale | F18: Navi Mumbai - TTC | G18: LILO on 220 kV Apta-Kalwa | H18: 90 | I18: 30 | J18: 14 | P18: 377 | Q18: IT MW - tier A1 | R18: SEIAA / MPCB EC expansion; CTE expansion - Approved / on agenda (M028) | S18: =IF(N(H18)>0,H18,IF(N(K18)+N(L18)>0,N(K18)+N(L18),IF(AND(N(M18)>0,OR(O18="A1",O18="A2")),M18,0))) -> 90 | T18: =IF(N(H18)>0,"SLDC",IF(N(K18)+N(L18)>0,"CTUIL",IF(S18>0,"Other official",IF(N(P18)>0,"Unverified","No MW")))) -> SLDC | U18: =IF(S18>0,S18,N(P18)) -> 90 | V18: 1 Grid sanctioned - partly live | W18: https://mahasldc.in/assets/public-ui/files/Data_Centre.pdf#page=23 | X18: https://www.sifytechnologies.com/data-center/rabale-data-center/ | Y18: SLDC MMR #12. SLDC: Sify #12 + #30 = 160 MW grid vs 377 MW company campus figure | Z18: Sify
A19: MH15 | B19: SLDC | C19: Sify | D19: M/s. Sify Technologies Ltd | E19: TTC, Rabale | F19: Navi Mumbai - TTC | G19: LILO of 100 kV Reliable-Standard Alkali | H19: 70 | I19: 70 | S19: =IF(N(H19)>0,H19,IF(N(K19)+N(L19)>0,N(K19)+N(L19),IF(AND(N(M19)>0,OR(O19="A1",O19="A2")),M19,0))) -> 70 | T19: =IF(N(H19)>0,"SLDC",IF(N(K19)+N(L19)>0,"CTUIL",IF(S19>0,"Other official",IF(N(P19)>0,"Unverified","No MW")))) -> SLDC | U19: =IF(S19>0,S19,N(P19)) -> 70 | V19: 1 Grid sanctioned - partly live | W19: https://mahasldc.in/assets/public-ui/files/Data_Centre.pdf#page=26 | Y19: SLDC MMR #30. | Z19: Sify
A20: MH16 | B20: SLDC | C20: Adani Group (ex-Microsoft site) - inferred | D20: M/s Microsoft Corporation India Ltd (Pimpri-Chinchwad) | E20: Pimpri Chinchwad, Pune | F20: Pune | G20: 220 kV D/C UG cable from 220 kV Bhosari-I S/s (4 km) | H20: 155 | I20: 16 | J20: 0 | R20: MPCB Consent to Establish - Approved (M017); SEIAA EC - On agenda (M018) | S20: =IF(N(H20)>0,H20,IF(N(K20)+N(L20)>0,N(K20)+N(L20),IF(AND(N(M20)>0,OR(O20="A1",O20="A2")),M20,0))) -> 155 | T20: =IF(N(H20)>0,"SLDC",IF(N(K20)+N(L20)>0,"CTUIL",IF(S20>0,"Other official",IF(N(P20)>0,"Unverified","No MW")))) -> SLDC | U20: =IF(S20>0,S20,N(P20)) -> 155 | V20: 1 Grid sanctioned - partly live | W20: https://mahasldc.in/assets/public-ui/files/Data_Centre.pdf#page=26 | X20: https://mpcb.gov.in/sites/default/files/inline-files/Minutes%20of%2015th%20CAC%20Establish%20Booklet%20no%2065.pdf | Y20: SLDC PMR #2. First MW figure for this site: 155 MW (cumulative schedule to Jan-2030) | Z20: Adani Group
A21: MH17 | B21: SLDC | C21: Bharti Airtel (Nxtra) | D21: M/s NXTRA Data Ltd-1 | E21: MIDC Plot 13/104, Hinjewadi Ph-3, Pune | F21: Pune | G21: 2 x 220 kV lines from 400 kV Hinjewadi Ph-III | H21: 36 | I21: 36 | J21: 16.88 | S21: =IF(N(H21)>0,H21,IF(N(K21)+N(L21)>0,N(K21)+N(L21),IF(AND(N(M21)>0,OR(O21="A1",O21="A2")),M21,0))) -> 36 | T21: =IF(N(H21)>0,"SLDC",IF(N(K21)+N(L21)>0,"CTUIL",IF(S21>0,"Other official",IF(N(P21)>0,"Unverified","No MW")))) -> SLDC | U21: =IF(S21>0,S21,N(P21)) -> 36 | V21: 1 Grid sanctioned - partly live | W21: https://mahasldc.in/assets/public-ui/files/Data_Centre.pdf#page=27 | Y21: SLDC PMR #4. Not in our data | Z21: Bharti Airtel (Nxtra)
A22: MH18 | B22: SLDC | C22: Bharti Airtel (Nxtra) | D22: M/s NXTRA Data Ltd-2 | E22: Hinjewadi Ph-3, Mann, Pune | F22: Pune | G22: 220 kV UG D/C from 400/220 kV Hinjewadi Ph-III | H22: 150 | I22: 50 | J22: 5.02 | R22: MPCB CTE expansion; CTO (part) - Approved (after SCN) (M043) | S22: =IF(N(H22)>0,H22,IF(N(K22)+N(L22)>0,N(K22)+N(L22),IF(AND(N(M22)>0,OR(O22="A1",O22="A2")),M22,0))) -> 150 | T22: =IF(N(H22)>0,"SLDC",IF(N(K22)+N(L22)>0,"CTUIL",IF(S22>0,"Other official",IF(N(P22)>0,"Unverified","No MW")))) -> SLDC | U22: =IF(S22>0,S22,N(P22)) -> 150 | V22: 1 Grid sanctioned - partly live | W22: https://mahasldc.in/assets/public-ui/files/Data_Centre.pdf#page=27 | X22: https://mpcb.gov.in/sites/default/files/inline-files/Action_Taken_Report_of_16th_CAC_Booklet_no._16_%281%29.pdf | Y22: SLDC PMR #5. Not in our data | Z22: Bharti Airtel (Nxtra)
A23: MH19 | B23: SLDC | C23: STT GDC | D23: M/s. STT Global Data Centres India Pvt Ltd | E23: Alandi Road, VSNL Old Colony, Dighi, Pune | F23: Pune | G23: 220 kV VSNL-STT Global ckt-I & II | H23: 200 | I23: 57 | J23: 41.63 | S23: =IF(N(H23)>0,H23,IF(N(K23)+N(L23)>0,N(K23)+N(L23),IF(AND(N(M23)>0,OR(O23="A1",O23="A2")),M23,0))) -> 200 | T23: =IF(N(H23)>0,"SLDC",IF(N(K23)+N(L23)>0,"CTUIL",IF(S23>0,"Other official",IF(N(P23)>0,"Unverified","No MW")))) -> SLDC | U23: =IF(S23>0,S23,N(P23)) -> 200 | V23: 1 Grid sanctioned - partly live | W23: https://mahasldc.in/assets/public-ui/files/Data_Centre.pdf#page=27 | Y23: SLDC PMR #3. Not in our MH data: 100 MW existing + 100 MW additional; avg load ~42 MW | Z23: STT GDC
A24: MH20 | B24: SLDC | C24: AWS (Amazon) | D24: M/s. Amazon, Ambernath | E24: Narhen, Usatane, Burdul & Asode, Ambernath | F24: Ambernath (Lodha Palava park) | G24: 220 kV D/C from 220 kV Lodha switching station (proposed MSETCL) | H24: 475 | S24: =IF(N(H24)>0,H24,IF(N(K24)+N(L24)>0,N(K24)+N(L24),IF(AND(N(M24)>0,OR(O24="A1",O24="A2")),M24,0))) -> 475 | T24: =IF(N(H24)>0,"SLDC",IF(N(K24)+N(L24)>0,"CTUIL",IF(S24>0,"Other official",IF(N(P24)>0,"Unverified","No MW")))) -> SLDC | U24: =IF(S24>0,S24,N(P24)) -> 475 | V24: 2 Grid sanctioned / approved - not yet live | W24: https://mahasldc.in/assets/public-ui/files/Data_Centre.pdf#page=25 | Y24: SLDC MMR #22. Dec-2025: AWS 475 + STT 450 = 925 MW; MERC order (Jun-2026) later raised the park to ~1,450 MW granted. Phase schedule in report sums to 450 | Z24: AWS (Amazon)
A25: MH21 | B25: MERC | C25: Lodha park (AWS, STT + 1 more) | D25: Maharashtra STU - Ambernath 400/220 kV (Lodha-funded) | E25: Ambernath (Palava) - increase in STU grant Dec-25 -> Jun-26 | F25: Ambernath (Lodha Palava park) | G25: 400/220 kV Ambernath S/s (TBCB annulled; STU to build) | M25: 525 | N25: Derived: MERC 1,450 MW granted (Jun-2026) less SLDC 925 MW (AWS 475 + STT 450, Dec-2025) | O25: A1 | S25: =IF(N(H25)>0,H25,IF(N(K25)+N(L25)>0,N(K25)+N(L25),IF(AND(N(M25)>0,OR(O25="A1",O25="A2")),M25,0))) -> 525 | T25: =IF(N(H25)>0,"SLDC",IF(N(K25)+N(L25)>0,"CTUIL",IF(S25>0,"Other official",IF(N(P25)>0,"Unverified","No MW")))) -> Other official | U25: =IF(S25>0,S25,N(P25)) -> 525 | V25: 2 Grid sanctioned / approved - not yet live | W25: https://merc.gov.in/wp-content/uploads/2026/06/Order-88-of-2026.pdf | Y25: MERC Case 88/2026 para 7.15. AWS Ambernath EC filing (473 MW) sits inside this park - not added separately | Z25: Ambernath park (MERC add-on)
A26: MH22 | B26: SLDC | C26: STT GDC | D26: M/s. STT Global, Ambernath | E26: Narhen, Usatane, Burdul & Asode, Ambernath | F26: Ambernath (Lodha Palava park) | G26: 220 kV D/C from 220 kV Lodha switching station (proposed MSETCL) | H26: 450 | S26: =IF(N(H26)>0,H26,IF(N(K26)+N(L26)>0,N(K26)+N(L26),IF(AND(N(M26)>0,OR(O26="A1",O26="A2")),M26,0))) -> 450 | T26: =IF(N(H26)>0,"SLDC",IF(N(K26)+N(L26)>0,"CTUIL",IF(S26>0,"Other official",IF(N(P26)>0,"Unverified","No MW")))) -> SLDC | U26: =IF(S26>0,S26,N(P26)) -> 450 | V26: 2 Grid sanctioned / approved - not yet live | W26: https://mahasldc.in/assets/public-ui/files/Data_Centre.pdf#page=25 | Y26: SLDC MMR #23. | Z26: STT GDC
A27: MH23 | B27: SLDC | C27: AWS (Amazon) | D27: Amazon Data Services Pvt Ltd, Mumbai | E27: Tungwa, Powai (Kurla) | F27: Mumbai city | G27: LILO on 220 kV Salsette-Sahar & Salsette-Saki | H27: 225 | M27: 77 | N27: EC / Form-1A connected load | O27: A1 | P27: 77 | Q27: Connected MW - tier A1 | R27: SEIAA EC - Discussed (M010); MPCB Consent to Establish - Approved (M011) | S27: =IF(N(H27)>0,H27,IF(N(K27)+N(L27)>0,N(K27)+N(L27),IF(AND(N(M27)>0,OR(O27="A1",O27="A2")),M27,0))) -> 225 | T27: =IF(N(H27)>0,"SLDC",IF(N(K27)+N(L27)>0,"CTUIL",IF(S27>0,"Other official",IF(N(P27)>0,"Unverified","No MW")))) -> SLDC | U27: =IF(S27>0,S27,N(P27)) -> 225 | V27: 2 Grid sanctioned / approved - not yet live | W27: https://mahasldc.in/assets/public-ui/files/Data_Centre.pdf#page=24 | X27: https://environmentclearance.nic.in/writereaddata/FormB/agenda/1509202585756580%28740114%29MINUTESOF301DAY-4TABLEITEM-Copy.pdf | Y27: SLDC MMR #19. Grid sanction 225 MW vs 77 MW in the EC - EC covers only the first building(s) | Z27: AWS (Amazon)
A28: MH24 | B28: CTUIL | C28: Adani Group (AdaniConneX) | D28: Support Properties Pvt Ltd ('ACXNMI-01') | E28: A-GEN-4 TTC Rabale / Ghansoli; 400 kV POWERGRID Navi Mumbai (GIS) | F28: Navi Mumbai - TTC | G28: ISTS - 400 kV PG Navi Mumbai (GIS) | K28: 1468 | R28: SEIAA / MPCB EC expansion; CTE (Feb-24) - On agenda / approved (M027) | S28: =IF(N(H28)>0,H28,IF(N(K28)+N(L28)>0,N(K28)+N(L28),IF(AND(N(M28)>0,OR(O28="A1",O28="A2")),M28,0))) -> 1468 | T28: =IF(N(H28)>0,"SLDC",IF(N(K28)+N(L28)>0,"CTUIL",IF(S28>0,"Other official",IF(N(P28)>0,"Unverified","No MW")))) -> CTUIL | U28: =IF(S28>0,S28,N(P28)) -> 1468 | V28: 2 Grid sanctioned / approved - not yet live | W28: https://ctuil.in/nswsapi/gna | X28: https://www.ecmpcb.in/login/download_ec_document/MjMyMTI2NEMzMjYzNDM5M0IxRTJDRDY5MENBNDZFODcucGRm | Y28: 17 GNA applications (13 x 50 + 418 + 74 + 174 + 152) approved; AdaniConneX subsidiary since 2023. Not in SLDC (ISTS, not STU) | Z28: Adani Group
A29: MH25 | B29: SLDC | C29: Blackstone / AirTrunk (Gramercy SPVs) - inferred | D29: M/s Estela Coromandal (Gramercy Infopark Pvt Ltd) | E29: TTC, Mavli, Ghansoli | F29: Navi Mumbai - TTC | G29: Interim LILO on 220 kV Kharghar-Borivali; final LILO on 400 kV Kalwa-Kharghar | H29: 480 | S29: =IF(N(H29)>0,H29,IF(N(K29)+N(L29)>0,N(K29)+N(L29),IF(AND(N(M29)>0,OR(O29="A1",O29="A2")),M29,0))) -> 480 | T29: =IF(N(H29)>0,"SLDC",IF(N(K29)+N(L29)>0,"CTUIL",IF(S29>0,"Other official",IF(N(P29)>0,"Unverified","No MW")))) -> SLDC | U29: =IF(S29>0,S29,N(P29)) -> 480 | V29: 2 Grid sanctioned / approved - not yet live | W29: https://mahasldc.in/assets/public-ui/files/Data_Centre.pdf#page=23 | Y29: SLDC MMR #11. Largest new item: 480 MW (Mar-2028 to Nov-2031); needs a 400 kV LILO | Z29: Blackstone / AirTrunk
A30: MH26 | B30: SLDC | C30: Blackstone / AirTrunk (Gramercy SPVs) - inferred | D30: M/s. Gramercy Business Hub Pvt Ltd | E30: TTC, Mahape | F30: Navi Mumbai - TTC | G30: 220 kV Gramercy switching station; LILO on 220 kV Kharghar-Netmagic | H30: 150 | P30: 120 | Q30: IT MW - tier C | R30: MPCB Consent to Establish - Approved (M026) | S30: =IF(N(H30)>0,H30,IF(N(K30)+N(L30)>0,N(K30)+N(L30),IF(AND(N(M30)>0,OR(O30="A1",O30="A2")),M30,0))) -> 150 | T30: =IF(N(H30)>0,"SLDC",IF(N(K30)+N(L30)>0,"CTUIL",IF(S30>0,"Other official",IF(N(P30)>0,"Unverified","No MW")))) -> SLDC | U30: =IF(S30>0,S30,N(P30)) -> 150 | V30: 2 Grid sanctioned / approved - not yet live | W30: https://mahasldc.in/assets/public-ui/files/Data_Centre.pdf#page=25 | X30: https://airtrunk.com/location/bom2-mumbai/ | Y30: SLDC MMR #25. Likely AirTrunk BOM2 (Mahape) | Z30: Blackstone / AirTrunk
A31: MH27 | B31: SLDC | C31: Blackstone / AirTrunk (Gramercy SPVs) - inferred | D31: M/s. Gramercy Infra Realty Pvt Ltd | E31: Plot IT-1, IT-2, Knowledge Park, Navi Mumbai | F31: Navi Mumbai - TTC | G31: TFR awaited from field office | H31: 180 | S31: =IF(N(H31)>0,H31,IF(N(K31)+N(L31)>0,N(K31)+N(L31),IF(AND(N(M31)>0,OR(O31="A1",O31="A2")),M31,0))) -> 180 | T31: =IF(N(H31)>0,"SLDC",IF(N(K31)+N(L31)>0,"CTUIL",IF(S31>0,"Other official",IF(N(P31)>0,"Unverified","No MW")))) -> SLDC | U31: =IF(S31>0,S31,N(P31)) -> 180 | V31: 2 Grid sanctioned / approved - not yet live | W31: https://mahasldc.in/assets/public-ui/files/Data_Centre.pdf#page=25 | Y31: SLDC MMR #26. Not in our data; connectivity still at feasibility (TFR awaited) | Z31: Blackstone / AirTrunk
A32: MH28 | B32: SLDC | C32: CtrlS | D32: M/s. CTRLS New | E32: TTC MIDC, Mahape | F32: Navi Mumbai - TTC | G32: 220 kV Mahape-CtrlS GIS D/C UG cable (1 km) | H32: 290 | S32: =IF(N(H32)>0,H32,IF(N(K32)+N(L32)>0,N(K32)+N(L32),IF(AND(N(M32)>0,OR(O32="A1",O32="A2")),M32,0))) -> 290 | T32: =IF(N(H32)>0,"SLDC",IF(N(K32)+N(L32)>0,"CTUIL",IF(S32>0,"Other official",IF(N(P32)>0,"Unverified","No MW")))) -> SLDC | U32: =IF(S32>0,S32,N(P32)) -> 290 | V32: 2 Grid sanctioned / approved - not yet live | W32: https://mahasldc.in/assets/public-ui/files/Data_Centre.pdf#page=25 | Y32: SLDC MMR #24. Second CtrlS GIS substation, +290 MW | Z32: CtrlS
A33: MH29 | B33: SLDC | C33: Digital Edge | D33: M/s. Digital Edge | E33: Dighe, Thane Belapur Road | F33: Navi Mumbai - TTC | G33: LILO of 220 kV DCHI-Colourchem | H33: 190 | P33: 350 | Q33: IT MW - tier C | R33: MPCB Consent to Establish - Approved (M019); SEIAA EC - Granted (M021) | S33: =IF(N(H33)>0,H33,IF(N(K33)+N(L33)>0,N(K33)+N(L33),IF(AND(N(M33)>0,OR(O33="A1",O33="A2")),M33,0))) -> 190 | T33: =IF(N(H33)>0,"SLDC",IF(N(K33)+N(L33)>0,"CTUIL",IF(S33>0,"Other official",IF(N(P33)>0,"Unverified","No MW")))) -> SLDC | U33: =IF(S33>0,S33,N(P33)) -> 190 | V33: 2 Grid sanctioned / approved - not yet live | W33: https://mahasldc.in/assets/public-ui/files/Data_Centre.pdf#page=26 | X33: https://www.digitaledgedc.com/products-services/data-centers/india/ | Y33: SLDC MMR #28. | Z33: Digital Edge
A34: MH30 | B34: SLDC | C34: Google | D34: M/s Amantin (Greenscape) | E34: TTC, Turbhe | F34: Navi Mumbai - TTC | G34: LILO on 220 kV Kalwa-Tiffil at proposed 220 kV S/s | H34: 130 | M34: 103.367 | N34: EC / Form-1A connected load | O34: A1 | P34: 103.4 | Q34: Connected MW - tier A1 | R34: SEAC-II EC application - n/a (M001) | S34: =IF(N(H34)>0,H34,IF(N(K34)+N(L34)>0,N(K34)+N(L34),IF(AND(N(M34)>0,OR(O34="A1",O34="A2")),M34,0))) -> 130 | T34: =IF(N(H34)>0,"SLDC",IF(N(K34)+N(L34)>0,"CTUIL",IF(S34>0,"Other official",IF(N(P34)>0,"Unverified","No MW")))) -> SLDC | U34: =IF(S34>0,S34,N(P34)) -> 130 | V34: 2 Grid sanctioned / approved - not yet live | W34: https://mahasldc.in/assets/public-ui/files/Data_Centre.pdf#page=23 | X34: https://environmentclearance.nic.in/DownloadPfdFile.aspx?FileName=Kwy+a1Xl%2FGHp2kMbJYBd8GPrFSz%2FNzzr1mrm87hA6RfsBvasy5U%2FhwjR4PRxBwwupD8Lw8MExL5FqtSFZLEOTQ%3D%3D&FilePath=93ZZBm8LWEXfg+HAlQix2fE2t8z%2FpgnoBhDlYdZCxzXTbTpOQqzWjBW0IF63rxBVcDlG0LKdfbGNs0Ou%2FTEvAA%3D%3D | Y34: SLDC MMR #10. SLDC 130 MW grid vs 103.4 MW connected load in EC filing | Z34: Google
A35: MH31 | B35: SLDC | C35: Google | D35: M/s. Raiden InfoTech India (P) Ltd | E35: Turbhe MIDC, TTC | F35: Navi Mumbai - TTC | G35: LILO on 220 kV Kharghar-Sonkhar | H35: 190 | Q35: n/a - tier A1 | R35: MPCB Consent to Establish - Approved (M002); SEIAA EC application - On agenda (M003) | S35: =IF(N(H35)>0,H35,IF(N(K35)+N(L35)>0,N(K35)+N(L35),IF(AND(N(M35)>0,OR(O35="A1",O35="A2")),M35,0))) -> 190 | T35: =IF(N(H35)>0,"SLDC",IF(N(K35)+N(L35)>0,"CTUIL",IF(S35>0,"Other official",IF(N(P35)>0,"Unverified","No MW")))) -> SLDC | U35: =IF(S35>0,S35,N(P35)) -> 190 | V35: 2 Grid sanctioned / approved - not yet live | W35: https://mahasldc.in/assets/public-ui/files/Data_Centre.pdf#page=25 | X35: https://mpcb.gov.in/sites/default/files/inline-files/Action_Taken_report_of_5th_CAC_Booklet_no_5_0.pdf | Y35: SLDC MMR #21. First MW figure for Google's own Navi Mumbai site: 190 MW, May-2026 to May-2031 | Z35: Google
A36: MH32 | B36: SLDC | C36: Iron Mountain (Web Werks) | D36: M/s. Web Werks | E36: TTC, Rabale | F36: Navi Mumbai - TTC | G36: LILO on 220 kV Kalwa-Siemens at proposed 220 kV GIS | H36: 120 | M36: 140 | N36: EC / Form-1A connected load | O36: A1 | P36: 140 | Q36: Connected MW - tier A1 | R36: SEIAA EC (new DC buildings) - Discussed (M008); MPCB Consent to Establish - Approved (M009) | S36: =IF(N(H36)>0,H36,IF(N(K36)+N(L36)>0,N(K36)+N(L36),IF(AND(N(M36)>0,OR(O36="A1",O36="A2")),M36,0))) -> 120 | T36: =IF(N(H36)>0,"SLDC",IF(N(K36)+N(L36)>0,"CTUIL",IF(S36>0,"Other official",IF(N(P36)>0,"Unverified","No MW")))) -> SLDC | U36: =IF(S36>0,S36,N(P36)) -> 120 | V36: 2 Grid sanctioned / approved - not yet live | W36: https://mahasldc.in/assets/public-ui/files/Data_Centre.pdf#page=24 | X36: https://environmentclearance.nic.in/writereaddata/FormB/agenda/1509202585756580%28740114%29MINUTESOF301DAY-4TABLEITEM-Copy.pdf | Y36: SLDC MMR #15. | Z36: Iron Mountain (Web Werks)
A37: MH33 | B37: SLDC | C37: STT GDC | D37: M/s. ST Telemedia | E37: Thane Belapur Road | F37: Navi Mumbai - TTC | G37: LILO on 220 kV Mahape-Tiffil line | H37: 40 | S37: =IF(N(H37)>0,H37,IF(N(K37)+N(L37)>0,N(K37)+N(L37),IF(AND(N(M37)>0,OR(O37="A1",O37="A2")),M37,0))) -> 40 | T37: =IF(N(H37)>0,"SLDC",IF(N(K37)+N(L37)>0,"CTUIL",IF(S37>0,"Other official",IF(N(P37)>0,"Unverified","No MW")))) -> SLDC | U37: =IF(S37>0,S37,N(P37)) -> 40 | V37: 2 Grid sanctioned / approved - not yet live | W37: https://mahasldc.in/assets/public-ui/files/Data_Centre.pdf#page=22 | Y37: SLDC MMR #1. SLDC grid sanction for the two STT Navi Mumbai sites = 120 MW | Z37: STT GDC
A38: MH34 | B38: SLDC | C38: Unidentified ('IMCC') | D38: M/s IMCC | E38: TTC MIDC Zone-A, Ghansoli | F38: Navi Mumbai - TTC | G38: LILO on ckt-I of 220 kV Kharghar-Borivali D/C | H38: 106 | S38: =IF(N(H38)>0,H38,IF(N(K38)+N(L38)>0,N(K38)+N(L38),IF(AND(N(M38)>0,OR(O38="A1",O38="A2")),M38,0))) -> 106 | T38: =IF(N(H38)>0,"SLDC",IF(N(K38)+N(L38)>0,"CTUIL",IF(S38>0,"Other official",IF(N(P38)>0,"Unverified","No MW")))) -> SLDC | U38: =IF(S38>0,S38,N(P38)) -> 106 | V38: 2 Grid sanctioned / approved - not yet live | W38: https://mahasldc.in/assets/public-ui/files/Data_Centre.pdf#page=23 | Y38: SLDC MMR #7. Not in our data; sponsor to be identified | Z38: Unidentified ('IMCC')
A39: MH35 | B39: SLDC | C39: Unidentified ('Innovative') | D39: M/s. Innovative | E39: Khairane MIDC, Navi Mumbai | F39: Navi Mumbai - TTC | G39: LILO on 220 kV Mahape-Tiffil ckt of Kalwa-Siemens-Mahape-Tiffil line | H39: 50 | S39: =IF(N(H39)>0,H39,IF(N(K39)+N(L39)>0,N(K39)+N(L39),IF(AND(N(M39)>0,OR(O39="A1",O39="A2")),M39,0))) -> 50 | T39: =IF(N(H39)>0,"SLDC",IF(N(K39)+N(L39)>0,"CTUIL",IF(S39>0,"Other official",IF(N(P39)>0,"Unverified","No MW")))) -> SLDC | U39: =IF(S39>0,S39,N(P39)) -> 50 | V39: 2 Grid sanctioned / approved - not yet live | W39: https://mahasldc.in/assets/public-ui/files/Data_Centre.pdf#page=22 | Y39: SLDC MMR #2. Not in our data; sponsor to be identified | Z39: Unidentified ('Innovative')
A40: MH36 | B40: SLDC | C40: Yotta (Hiranandani) | D40: Yotta Data Services | E40: Hiranandani Fortune City, Panvel | F40: Panvel / Raigad | G40: - | H40: 52 | P40: 52 | Q40: IT MW - tier C | R40: MPCB Renewal of consent - Approved (M041) | S40: =IF(N(H40)>0,H40,IF(N(K40)+N(L40)>0,N(K40)+N(L40),IF(AND(N(M40)>0,OR(O40="A1",O40="A2")),M40,0))) -> 52 | T40: =IF(N(H40)>0,"SLDC",IF(N(K40)+N(L40)>0,"CTUIL",IF(S40>0,"Other official",IF(N(P40)>0,"Unverified","No MW")))) -> SLDC | U40: =IF(S40>0,S40,N(P40)) -> 52 | V40: 2 Grid sanctioned / approved - not yet live | W40: https://mahasldc.in/assets/public-ui/files/Data_Centre.pdf#page=26 | X40: https://colocation.yotta.com/data-center/nm1-datacenter-mumbai-region-maharashtra/ | Y40: SLDC MMR #31. Exact match | Z40: Yotta (Hiranandani)
A41: MH37 | B41: SLDC | C41: Adani Group (ex-Microsoft site) | D41: M/s Microsoft Corporation India Ltd (Bhosari) | E41: Bhosari, Pimpri Industrial Area, Pune | F41: Pune | G41: 220 kV D/C UG cable from 220 kV Century Enka S/s (2 km) | H41: 74 | M41: 75.4 | N41: EC / Form-1A connected load | O41: A1 | P41: 75.4 | Q41: Connected MW - tier A1 | R41: SEIAA EC (expansion) - Referred back to SEAC-III (M015); MPCB Consent to Establish - Approved (M016) | S41: =IF(N(H41)>0,H41,IF(N(K41)+N(L41)>0,N(K41)+N(L41),IF(AND(N(M41)>0,OR(O41="A1",O41="A2")),M41,0))) -> 74 | T41: =IF(N(H41)>0,"SLDC",IF(N(K41)+N(L41)>0,"CTUIL",IF(S41>0,"Other official",IF(N(P41)>0,"Unverified","No MW")))) -> SLDC | U41: =IF(S41>0,S41,N(P41)) -> 74 | V41: 2 Grid sanctioned / approved - not yet live | W41: https://mahasldc.in/assets/public-ui/files/Data_Centre.pdf#page=26 | X41: https://environmentclearance.nic.in/writereaddata/FormB/agenda/2302202697285484%28921161%29MINUTESOF319DAY-5PART-B.pdf | Y41: SLDC PMR #1. 74 MW grid = 75.4 MW EC. Schedule in report is cumulative (16.1 -> 74); converted to annual increments | Z41: Adani Group
...
