Workbook

Sheet MH_Master_Summary
A1: Maharashtra data centres - verifiable pipeline (combined list)
A2: Built from MH_Master_List. Verifiable = MW in an official record (SLDC / CTUIL / MERC / SEIAA / state GO-LoI-MoU). Facility (grid) MW, not IT MW.
A4: By stage | B4: Projects | C4: Verifiable MW | D4: Indicative MW | E4: Share of verifiable | F4: What it is
A5: 1 Grid sanctioned - partly live | B5: =COUNTIFS(MH_Master_List!$V$5:$V$61,A5) -> 19 | C5: =SUMIFS(MH_Master_List!$S$5:$S$61,MH_Master_List!$V$5:$V$61,A5) -> 2648 | D5: =SUMIFS(MH_Master_List!$U$5:$U$61,MH_Master_List!$V$5:$V$61,A5) -> 2648 | E5: =C5/C$11 -> 0.18066576 | F5: STU sanction with load already realised (SLDC)
A6: 2 Grid sanctioned / approved - not yet live | B6: =COUNTIFS(MH_Master_List!$V$5:$V$61,A6) -> 19 | C6: =SUMIFS(MH_Master_List!$S$5:$S$61,MH_Master_List!$V$5:$V$61,A6) -> 5345 | D6: =SUMIFS(MH_Master_List!$U$5:$U$61,MH_Master_List!$V$5:$V$61,A6) -> 5345 | E6: =C6/C$11 -> 0.36467466 | F6: STU sanction / CTUIL approval / MERC grant, not yet drawing
A7: 3 Grid applied / under consideration | B7: =COUNTIFS(MH_Master_List!$V$5:$V$61,A7) -> 3 | C7: =SUMIFS(MH_Master_List!$S$5:$S$61,MH_Master_List!$V$5:$V$61,A7) -> 2100 | D7: =SUMIFS(MH_Master_List!$U$5:$U$61,MH_Master_List!$V$5:$V$61,A7) -> 2100 | E7: =C7/C$11 -> 0.14327723 | F7: CTUIL GNA under process; MERC 'under consideration'
A8: 4 Permit only (no grid record) | B8: =COUNTIFS(MH_Master_List!$V$5:$V$61,A8) -> 6 | C8: =SUMIFS(MH_Master_List!$S$5:$S$61,MH_Master_List!$V$5:$V$61,A8) -> 113.9 | D8: =SUMIFS(MH_Master_List!$U$5:$U$61,MH_Master_List!$V$5:$V$61,A8) -> 113.9 | E8: =C8/C$11 -> 0.0077710839 | F8: EC / MPCB record but no grid record (often MW not disclosed)
A9: 5 MoU / LoI / EOI | B9: =COUNTIFS(MH_Master_List!$V$5:$V$61,A9) -> 4 | C9: =SUMIFS(MH_Master_List!$S$5:$S$61,MH_Master_List!$V$5:$V$61,A9) -> 4450 | D9: =SUMIFS(MH_Master_List!$U$5:$U$61,MH_Master_List!$V$5:$V$61,A9) -> 4450 | E9: =C9/C$11 -> 0.30361127 | F9: State MoU / LoI / EOI (government action, early stage)
A10: 6 Company claim / announced only | B10: =COUNTIFS(MH_Master_List!$V$5:$V$61,A10) -> 6 | C10: =SUMIFS(MH_Master_List!$S$5:$S$61,MH_Master_List!$V$5:$V$61,A10) -> 0 | D10: =SUMIFS(MH_Master_List!$U$5:$U$61,MH_Master_List!$V$5:$V$61,A10) -> 735.5 | E10: =C10/C$11 -> 0 | F10: Only company or press figure - not counted as verifiable
A11: Total | B11: =SUM(B5:B10) -> 57 | C11: =SUM(C5:C10) -> 14656.9 | D11: =SUM(D5:D10) -> 15392.4 | E11: =C11/C11 -> 1
A13: Key measures | B13: MW | F13: Note
A14: Grid-sanctioned / approved (stages 1-2) - firmest verifiable | B14: =C5+C6 -> 7993 | F14: SLDC sanctions + CTUIL approved (Support Properties) + MERC Ambernath increase
A15: Plus: grid applications pending (stage 3) | B15: =C7 -> 2100 | F15: CTUIL under process + MERC 1,500 MW under consideration
A16: Grid pipeline, stages 1-3 (sum of the two rows above) | B16: =B14+B15 -> 10093 | F16: Official grid-level DC pipeline in Maharashtra
A17: Plus: State MoU / LoI / EOI (stage 5) | B17: =C9 -> 4450 | F17: AirTrunk Pen 3 GW, ReNew 750, Trentar 500, MAHAPREIT 200
A18: Realised so far (SLDC, Dec-2025) | B18: =SUM(MH_Master_List!$I$5:$I$61) -> 685 | F18: Final connectivity granted / load realised
A19: Actually drawn - avg last 3 months (SLDC, 18 DCs) | B19: =SUM(MH_Master_List!$J$5:$J$61) -> 204.52 | F19: Metered average load
A20: Unverified extra (company / press only) | B20: =SUMIFS(MH_Master_List!$U$5:$U$61,MH_Master_List!$T$5:$T$61,"Unverified") -> 735.5 | F20: PDG, L&T Vyoma, Zerra, ESR, TCC, Avisirah
A22: By group | B22: Projects | C22: Verifiable MW | D22: Indicative MW | E22: SLDC realised | F22: Main sites
A23: Bharti Airtel (Nxtra) | B23: =COUNTIFS(MH_Master_List!$Z$5:$Z$61,A23) -> 3 | C23: =SUMIFS(MH_Master_List!$S$5:$S$61,MH_Master_List!$Z$5:$Z$61,A23) -> 221 | D23: =SUMIFS(MH_Master_List!$U$5:$U$61,MH_Master_List!$Z$5:$Z$61,A23) -> 221 | E23: =SUMIFS(MH_Master_List!$I$5:$I$61,MH_Master_List!$Z$5:$Z$61,A23) -> 121 | F23: Navi Mumbai - TTC, Pune
A24: Blackstone / AirTrunk | B24: =COUNTIFS(MH_Master_List!$Z$5:$Z$61,A24) -> 5 | C24: =SUMIFS(MH_Master_List!$S$5:$S$61,MH_Master_List!$Z$5:$Z$61,A24) -> 3900 | D24: =SUMIFS(MH_Master_List!$U$5:$U$61,MH_Master_List!$Z$5:$Z$61,A24) -> 3900 | E24: =SUMIFS(MH_Master_List!$I$5:$I$61,MH_Master_List!$Z$5:$Z$61,A24) -> 35 | F24: Navi Mumbai - TTC, Panvel / Raigad
A25: Bridge Data Centres | B25: =COUNTIFS(MH_Master_List!$Z$5:$Z$61,A25) -> 1 | C25: =SUMIFS(MH_Master_List!$S$5:$S$61,MH_Master_List!$Z$5:$Z$61,A25) -> 32 | D25: =SUMIFS(MH_Master_List!$U$5:$U$61,MH_Master_List!$Z$5:$Z$61,A25) -> 32 | E25: =SUMIFS(MH_Master_List!$I$5:$I$61,MH_Master_List!$Z$5:$Z$61,A25) -> 32 | F25: Navi Mumbai - TTC
A26: CapitaLand | B26: =COUNTIFS(MH_Master_List!$Z$5:$Z$61,A26) -> 1 | C26: =SUMIFS(MH_Master_List!$S$5:$S$61,MH_Master_List!$Z$5:$Z$61,A26) -> 120 | D26: =SUMIFS(MH_Master_List!$U$5:$U$61,MH_Master_List!$Z$5:$Z$61,A26) -> 120 | E26: =SUMIFS(MH_Master_List!$I$5:$I$61,MH_Master_List!$Z$5:$Z$61,A26) -> 18 | F26: Navi Mumbai - TTC
A27: Colt DCS - RMZ | B27: =COUNTIFS(MH_Master_List!$Z$5:$Z$61,A27) -> 1 | C27: =SUMIFS(MH_Master_List!$S$5:$S$61,MH_Master_List!$Z$5:$Z$61,A27) -> 60 | D27: =SUMIFS(MH_Master_List!$U$5:$U$61,MH_Master_List!$Z$5:$Z$61,A27) -> 60 | E27: =SUMIFS(MH_Master_List!$I$5:$I$61,MH_Master_List!$Z$5:$Z$61,A27) -> 10 | F27: Navi Mumbai - TTC
A28: CtrlS | B28: =COUNTIFS(MH_Master_List!$Z$5:$Z$61,A28) -> 2 | C28: =SUMIFS(MH_Master_List!$S$5:$S$61,MH_Master_List!$Z$5:$Z$61,A28) -> 585 | D28: =SUMIFS(MH_Master_List!$U$5:$U$61,MH_Master_List!$Z$5:$Z$61,A28) -> 585 | E28: =SUMIFS(MH_Master_List!$I$5:$I$61,MH_Master_List!$Z$5:$Z$61,A28) -> 70 | F28: Navi Mumbai - TTC
A29: Digital Edge | B29: =COUNTIFS(MH_Master_List!$Z$5:$Z$61,A29) -> 2 | C29: =SUMIFS(MH_Master_List!$S$5:$S$61,MH_Master_List!$Z$5:$Z$61,A29) -> 225 | D29: =SUMIFS(MH_Master_List!$U$5:$U$61,MH_Master_List!$Z$5:$Z$61,A29) -> 225 | E29: =SUMIFS(MH_Master_List!$I$5:$I$61,MH_Master_List!$Z$5:$Z$61,A29) -> 25 | F29: Navi Mumbai - TTC
A30: K Raheja Corp / Mindspace | B30: =COUNTIFS(MH_Master_List!$Z$5:$Z$61,A30) -> 2 | C30: =SUMIFS(MH_Master_List!$S$5:$S$61,MH_Master_List!$Z$5:$Z$61,A30) -> 535 | D30: =SUMIFS(MH_Master_List!$U$5:$U$61,MH_Master_List!$Z$5:$Z$61,A30) -> 535 | E30: =SUMIFS(MH_Master_List!$I$5:$I$61,MH_Master_List!$Z$5:$Z$61,A30) -> 71 | F30: Navi Mumbai - TTC
A31: NTT | B31: =COUNTIFS(MH_Master_List!$Z$5:$Z$61,A31) -> 5 | C31: =SUMIFS(MH_Master_List!$S$5:$S$61,MH_Master_List!$Z$5:$Z$61,A31) -> 665 | D31: =SUMIFS(MH_Master_List!$U$5:$U$61,MH_Master_List!$Z$5:$Z$61,A31) -> 665 | E31: =SUMIFS(MH_Master_List!$I$5:$I$61,MH_Master_List!$Z$5:$Z$61,A31) -> 90 | F31: Mumbai city, Navi Mumbai - TTC
A32: STT GDC | B32: =COUNTIFS(MH_Master_List!$Z$5:$Z$61,A32) -> 4 | C32: =SUMIFS(MH_Master_List!$S$5:$S$61,MH_Master_List!$Z$5:$Z$61,A32) -> 770 | D32: =SUMIFS(MH_Master_List!$U$5:$U$61,MH_Master_List!$Z$5:$Z$61,A32) -> 770 | E32: =SUMIFS(MH_Master_List!$I$5:$I$61,MH_Master_List!$Z$5:$Z$61,A32) -> 97 | F32: Ambernath (Lodha Palava park), Navi Mumbai - TTC, Pune
A33: Sify | B33: =COUNTIFS(MH_Master_List!$Z$5:$Z$61,A33) -> 2 | C33: =SUMIFS(MH_Master_List!$S$5:$S$61,MH_Master_List!$Z$5:$Z$61,A33) -> 160 | D33: =SUMIFS(MH_Master_List!$U$5:$U$61,MH_Master_List!$Z$5:$Z$61,A33) -> 160 | E33: =SUMIFS(MH_Master_List!$I$5:$I$61,MH_Master_List!$Z$5:$Z$61,A33) -> 100 | F33: Navi Mumbai - TTC
A34: Adani Group | B34: =COUNTIFS(MH_Master_List!$Z$5:$Z$61,A34) -> 4 | C34: =SUMIFS(MH_Master_List!$S$5:$S$61,MH_Master_List!$Z$5:$Z$61,A34) -> 2197 | D34: =SUMIFS(MH_Master_List!$U$5:$U$61,MH_Master_List!$Z$5:$Z$61,A34) -> 2197 | E34: =SUMIFS(MH_Master_List!$I$5:$I$61,MH_Master_List!$Z$5:$Z$61,A34) -> 16 | F34: Navi Mumbai - TTC, Panvel / Raigad, Pune
... A53: TCC Concept / NES Data | B53: =COUNTIFS(MH_Master_List!$Z$5:$Z$61,A53) -> 1 | C53: =SUMIFS(MH_Master_List!$S$5:$S$61,MH_Master_List!$Z$5:$Z$61,A53) -> 0 | D53: =SUMIFS(MH_Master_List!$U$5:$U$61,MH_Master_List!$Z$5:$Z$61,A53) -> 60 | E53: =SUMIFS(MH_Master_List!$I$5:$I$61,MH_Master_List!$Z$5:$Z$61,A53) -> 0 | F53: Pune
A55: By cluster | B55: Projects | C55: Verifiable MW | D55: Indicative MW | E55: SLDC realised
A56: Ambernath (Lodha Palava park) | B56: =COUNTIFS(MH_Master_List!$F$5:$F$61,A56) -> 4 | C56: =SUMIFS(MH_Master_List!$S$5:$S$61,MH_Master_List!$F$5:$F$61,A56) -> 2950 | D56: =SUMIFS(MH_Master_List!$U$5:$U$61,MH_Master_List!$F$5:$F$61,A56) -> 2950 | E56: =SUMIFS(MH_Master_List!$I$5:$I$61,MH_Master_List!$F$5:$F$61,A56) -> 0
A57: Mumbai city | B57: =COUNTIFS(MH_Master_List!$F$5:$F$61,A57) -> 3 | C57: =SUMIFS(MH_Master_List!$S$5:$S$61,MH_Master_List!$F$5:$F$61,A57) -> 338.9 | D57: =SUMIFS(MH_Master_List!$U$5:$U$61,MH_Master_List!$F$5:$F$61,A57) -> 338.9 | E57: =SUMIFS(MH_Master_List!$I$5:$I$61,MH_Master_List!$F$5:$F$61,A57) -> 0
A58: Navi Mumbai - TTC | B58: =COUNTIFS(MH_Master_List!$F$5:$F$61,A58) -> 34 | C58: =SUMIFS(MH_Master_List!$S$5:$S$61,MH_Master_List!$F$5:$F$61,A58) -> 5501 | D58: =SUMIFS(MH_Master_List!$U$5:$U$61,MH_Master_List!$F$5:$F$61,A58) -> 6176.5 | E58: =SUMIFS(MH_Master_List!$I$5:$I$61,MH_Master_List!$F$5:$F$61,A58) -> 526
A59: Not disclosed | B59: =COUNTIFS(MH_Master_List!$F$5:$F$61,A59) -> 2 | C59: =SUMIFS(MH_Master_List!$S$5:$S$61,MH_Master_List!$F$5:$F$61,A59) -> 700 | D59: =SUMIFS(MH_Master_List!$U$5:$U$61,MH_Master_List!$F$5:$F$61,A59) -> 700 | E59: =SUMIFS(MH_Master_List!$I$5:$I$61,MH_Master_List!$F$5:$F$61,A59) -> 0
A60: Panvel / Raigad | B60: =COUNTIFS(MH_Master_List!$F$5:$F$61,A60) -> 6 | C60: =SUMIFS(MH_Master_List!$S$5:$S$61,MH_Master_List!$F$5:$F$61,A60) -> 4302 | D60: =SUMIFS(MH_Master_List!$U$5:$U$61,MH_Master_List!$F$5:$F$61,A60) -> 4302 | E60: =SUMIFS(MH_Master_List!$I$5:$I$61,MH_Master_List!$F$5:$F$61,A60) -> 0
A61: Pune | B61: =COUNTIFS(MH_Master_List!$F$5:$F$61,A61) -> 7 | C61: =SUMIFS(MH_Master_List!$S$5:$S$61,MH_Master_List!$F$5:$F$61,A61) -> 715 | D61: =SUMIFS(MH_Master_List!$U$5:$U$61,MH_Master_List!$F$5:$F$61,A61) -> 775 | E61: =SUMIFS(MH_Master_List!$I$5:$I$61,MH_Master_List!$F$5:$F$61,A61) -> 159
A62: Thane | B62: =COUNTIFS(MH_Master_List!$F$5:$F$61,A62) -> 1 | C62: =SUMIFS(MH_Master_List!$S$5:$S$61,MH_Master_List!$F$5:$F$61,A62) -> 150 | D62: =SUMIFS(MH_Master_List!$U$5:$U$61,MH_Master_List!$F$5:$F$61,A62) -> 150 | E62: =SUMIFS(MH_Master_List!$I$5:$I$61,MH_Master_List!$F$5:$F$61,A62) -> 0
...

Sheet MH_Master_List
A1: Maharashtra data centres - combined master list (SLDC grid + CTUIL + MERC + permits + our dataset), one row per project
A2: Verifiable MW = figure found in an official record, in priority order: SLDC/STU sanctioned load (Dec-2025) > CTUIL GNA (approved + under process) > other official (MERC order, EC/SEIAA connected load, state GO/LoI/MoU/EOI). Company / press figures are shown separately and NOT counted as verifiable. Grid MW (SLDC, CTUIL, MERC) and connected-load MW are facility power, not IT MW (IT is roughly 55-65% of facility load per SLDC).
A4: ID | B4: Primary record | C4: Group | D4: Company / SPV (as filed) | E4: Site / location | F4: Cluster | G4: Grid connection | H4: SLDC sanctioned (MW) | I4: SLDC realised (MW) | J4: SLDC avg load 3 m (MW) | K4: CTUIL approved (MW) | L4: CTUIL under process (MW) | M4: Other official (MW) | N4: Other official basis | O4: Other official tier | P4: Company / press (MW) | Q4: Company / press basis & tier | R4: Permits (EC / MPCB) | S4: VERIFIABLE MW | T4: Verifiable source | U4: Indicative MW (incl. unverified) | V4: Stage | W4: Primary source | X4: Other source | Y4: Notes | Z4: Group key
A5: MH01 | B5: SLDC | C5: Bharti Airtel (Nxtra) | D5: M/s. Nxtra | E5: TTC, Mahape | F5: Navi Mumbai - TTC | G5: LILO on 220 kV Kalwa-Tiffil line | H5: 35 | I5: 35 | J5: 2.28 | R5: SEIAA EC (expansion) - Granted (M022); MPCB CTE expansion (Feb-25); CTO part (Jun-25) - Approved (M023) | S5: =IF(N(H5)>0,H5,IF(N(K5)+N(L5)>0,N(K5)+N(L5),IF(AND(N(M5)>0,OR(O5="A1",O5="A2")),M5,0))) -> 35 | T5: =IF(N(H5)>0,"SLDC",IF(N(K5)+N(L5)>0,"CTUIL",IF(S5>0,"Other official",IF(N(P5)>0,"Unverified","No MW")))) -> SLDC | U5: =IF(S5>0,S5,N(P5)) -> 35 | V5: 1 Grid sanctioned - partly live | W5: https://mahasldc.in/assets/public-ui/files/Data_Centre.pdf#page=23 | X5: https://assets.airtel.in/nxtra/pdf/EC_Environmental_Clearance_Certificate_Nxtra%20Mahape_DC-02_25.11.25.pdf | Y5: SLDC MMR #8. Not in our MH state data (Airtel Nxtra) | Z5: Bharti Airtel (Nxtra)
A6: MH02 | B6: SLDC | C6: Blackstone / AirTrunk (Gramercy SPVs) - inferred | D6: M/s Estela Hindustan Unilever (Gramercy Techpark) | E6: TTC MIDC, Airoli | F6: Navi Mumbai - TTC | G6: LILO on 220 kV Kalwa-Taloja-Panchanand | H6: 90 | I6: 35 | J6: 5 | P6: 62 | Q6: IT MW - tier D | R6: MPCB Consent to Establish - Approved (M024); MPCB / SEIAA CTO (part); EC expansion - Approved / on agenda (M025) | S6: =IF(N(H6)>0,H6,IF(N(K6)+N(L6)>0,N(K6)+N(L6),IF(AND(N(M6)>0,OR(O6="A1",O6="A2")),M6,0))) -> 90 | T6: =IF(N(H6)>0,"SLDC",IF(N(K6)+N(L6)>0,"CTUIL",IF(S6>0,"Other official",IF(N(P6)>0,"Unverified","No MW")))) -> SLDC | U6: =IF(S6>0,S6,N(P6)) -> 90 | V6: 1 Grid sanctioned - partly live | W6: https://mahasldc.in/assets/public-ui/files/Data_Centre.pdf#page=24 | X6: https://mpcb.gov.in/sites/default/files/inline-files/Minutes%20of%2015th%20CAC%20Establish%20Booklet%20no%2065.pdf | Y6: SLDC MMR #13. Official grid figure (90 MW) replaces directory-sourced 62 MW | Z6: Blackstone / AirTrunk
A7: MH03 | B7: SLDC | C7: Bridge Data Centres | D7: M/s. Bridge Data Centre | E7: Dighi MIDC, Navi Mumbai | F7: Navi Mumbai - TTC | G7: LILO on 100 kV Kalwa-Mukund ckt-1 | H7: 32 | I7: 32 | J7: 10.93 | R7: MPCB CTO renewal - Approved (M040) | S7: =IF(N(H7)>0,H7,IF(N(K7)+N(L7)>0,N(K7)+N(L7),IF(AND(N(M7)>0,OR(O7="A1",O7="A2")),M7,0))) -> 32 | T7: =IF(N(H7)>0,"SLDC",IF(N(K7)+N(L7)>0,"CTUIL",IF(S7>0,"Other official",IF(N(P7)>0,"Unverified","No MW")))) -> SLDC | U7: =IF(S7>0,S7,N(P7)) -> 32 | V7: 1 Grid sanctioned - partly live | W7: https://mahasldc.in/assets/public-ui/files/Data_Centre.pdf#page=26 | X7: https://mpcb.gov.in/sites/default/files/inline-files/Index_Of_15th_CAC_Meeting.pdf | Y7: SLDC MMR #29. Not in our data; operating (avg ~11 MW) | Z7: Bridge Data Centres
A8: MH04 | B8: SLDC | C8: CapitaLand | D8: M/s. Datascape | E8: TTC, Dighe | F8: Navi Mumbai - TTC | G8: LILO on 220 kV Kalwa-Bapgaon | H8: 120 | I8: 18 | J8: 9 | M8: 135 | N8: EC / Form-1A connected load | O8: A1 | P8: 135 | Q8: Connected MW - tier A1 | R8: SEIAA EC (expansion) - Discussed (M005); MPCB Consent to Establish - Listed (M006); MPCB Consent to 1st Operate (part) - Approved (M007) | S8: =IF(N(H8)>0,H8,IF(N(K8)+N(L8)>0,N(K8)+N(L8),IF(AND(N(M8)>0,OR(O8="A1",O8="A2")),M8,0))) -> 120 | T8: =IF(N(H8)>0,"SLDC",IF(N(K8)+N(L8)>0,"CTUIL",IF(S8>0,"Other official",IF(N(P8)>0,"Unverified","No MW")))) -> SLDC | U8: =IF(S8>0,S8,N(P8)) -> 120 | V8: 1 Grid sanctioned - partly live | W8: https://mahasldc.in/assets/public-ui/files/Data_Centre.pdf#page=24 | X8: https://environmentclearance.nic.in/writereaddata/FormB/agenda/1509202585756580%28740114%29MINUTESOF301DAY-4TABLEITEM-Copy.pdf | Y8: SLDC MMR #17. | Z8: CapitaLand
A9: MH05 | B9: SLDC | C9: Colt DCS - RMZ | D9: M/s. Data Centre Holding | E9: Kalwa Industrial Area, Dighe, Airoli | F9: Navi Mumbai - TTC | G9: LILO on 220 kV Kalwa-Colourchem | H9: 60 | I9: 10 | J9: 1.2 | P9: 148 | Q9: IT MW - tier C | R9: MPCB CTO / renewal - Approved (M039) | S9: =IF(N(H9)>0,H9,IF(N(K9)+N(L9)>0,N(K9)+N(L9),IF(AND(N(M9)>0,OR(O9="A1",O9="A2")),M9,0))) -> 60 | T9: =IF(N(H9)>0,"SLDC",IF(N(K9)+N(L9)>0,"CTUIL",IF(S9>0,"Other official",IF(N(P9)>0,"Unverified","No MW")))) -> SLDC | U9: =IF(S9>0,S9,N(P9)) -> 60 | V9: 1 Grid sanctioned - partly live | W9: https://mahasldc.in/assets/public-ui/files/Data_Centre.pdf#page=24 | X9: https://indianinfrastructure.com/2026/10/16/colt-dcs-and-rmz-begin-construction-of-third-data-centre-in-mumbai/ | Y9: SLDC MMR #16. SLDC sanction only 60 MW so far vs 148 MW campus potential | Z9: Colt DCS - RMZ
A10: MH06 | B10: SLDC | C10: CtrlS | D10: M/s CTRLS | E10: TTC MIDC, Mahape | F10: Navi Mumbai - TTC | G10: LILO on ckt-I of 220 kV Kharghar-Borivali D/C | H10: 295 | I10: 70 | J10: 43 | P10: 214 | Q10: IT MW - tier A1 | R10: MPCB CTE for expansion - Approved (M038) | S10: =IF(N(H10)>0,H10,IF(N(K10)+N(L10)>0,N(K10)+N(L10),IF(AND(N(M10)>0,OR(O10="A1",O10="A2")),M10,0))) -> 295 | T10: =IF(N(H10)>0,"SLDC",IF(N(K10)+N(L10)>0,"CTUIL",IF(S10>0,"Other official",IF(N(P10)>0,"Unverified","No MW")))) -> SLDC | U10: =IF(S10>0,S10,N(P10)) -> 295 | V10: 1 Grid sanctioned - partly live | W10: https://mahasldc.in/assets/public-ui/files/Data_Centre.pdf#page=22 | X10: https://www.ctrls.com/ | Y10: SLDC MMR #3. SLDC: 295 MW sanctioned + 290 MW 'CtrlS New' (#24) = 585 MW grid vs our 214 IT MW. Site visit: 70 MW live, avg 42-45 MW | Z10: CtrlS
A11: MH07 | B11: SLDC | C11: Digital Edge | D11: M/s. Digital Edge (AGP) | E11: Mukund Ltd, Kalwa & Digha | F11: Navi Mumbai - TTC | G11: LILO on 100 kV Kalwa-BDC-Mukund I & II | H11: 35 | I11: 25 | J11: 0.97 | R11: MPCB Consent to 1st Operate - Approved (M020) | S11: =IF(N(H11)>0,H11,IF(N(K11)+N(L11)>0,N(K11)+N(L11),IF(AND(N(M11)>0,OR(O11="A1",O11="A2")),M11,0))) -> 35 | T11: =IF(N(H11)>0,"SLDC",IF(N(K11)+N(L11)>0,"CTUIL",IF(S11>0,"Other official",IF(N(P11)>0,"Unverified","No MW")))) -> SLDC | U11: =IF(S11>0,S11,N(P11)) -> 35 | V11: 1 Grid sanctioned - partly live | W11: https://mahasldc.in/assets/public-ui/files/Data_Centre.pdf#page=26 | X11: https://mpcb.gov.in/sites/default/files/inline-files/Action_Taken_Report_of_17th_CAC_Booklet_no_17_2024-25.pdf | Y11: SLDC MMR #27. SLDC: Digital Edge #27 + #28 = 225 MW grid vs 350 MW campus | Z11: Digital Edge
A12: MH08 | B12: SLDC | C12: K Raheja Corp / Mindspace | D12: M/s Newfound | E12: TTC Industrial Area, Thane, Navi Mumbai | F12: Navi Mumbai - TTC | G12: LILO on 220 kV Kharghar-Sonkhar line | H12: 250 | I12: 36 | J12: 0.42 | R12: SEIAA / MPCB CTO Part-I for Bldg 5A (Data Centre) - Approved (M033) | S12: =IF(N(H12)>0,H12,IF(N(K12)+N(L12)>0,N(K12)+N(L12),IF(AND(N(M12)>0,OR(O12="A1",O12="A2")),M12,0))) -> 250 | T12: =IF(N(H12)>0,"SLDC",IF(N(K12)+N(L12)>0,"CTUIL",IF(S12>0,"Other official",IF(N(P12)>0,"Unverified","No MW")))) -> SLDC | U12: =IF(S12>0,S12,N(P12)) -> 250 | V12: 1 Grid sanctioned - partly live | W12: https://mahasldc.in/assets/public-ui/files/Data_Centre.pdf#page=22 | X12: https://mpcb.gov.in/sites/default/files/inline-files/Action_Taken_Report_of_17th_CAC_Booklet_no_17_2024-25.pdf | Y12: SLDC MMR #4. Not in state data; 250 MW sanctioned to 2034 | Z12: K Raheja Corp / Mindspace
A13: MH09 | B13: SLDC | C13: K Raheja Corp / Mindspace | D13: M/s Gigaplex | E13: Airoli Knowledge Park, Airoli | F13: Navi Mumbai - TTC | G13: LILO on 220 kV Kalwa-Bapgaon | H13: 285 | I13: 35 | J13: 7 | R13: SEIAA / MPCB CTO application; EC amendment - Listed (M034) | S13: =IF(N(H13)>0,H13,IF(N(K13)+N(L13)>0,N(K13)+N(L13),IF(AND(N(M13)>0,OR(O13="A1",O13="A2")),M13,0))) -> 285 | T13: =IF(N(H13)>0,"SLDC",IF(N(K13)+N(L13)>0,"CTUIL",IF(S13>0,"Other official",IF(N(P13)>0,"Unverified","No MW")))) -> SLDC | U13: =IF(S13>0,S13,N(P13)) -> 285 | V13: 1 Grid sanctioned - partly live | W13: https://mahasldc.in/assets/public-ui/files/Data_Centre.pdf#page=22 | X13: https://mpcb.gov.in/sites/default/files/inline-files/Index_of_4th_CAC_Meeting_of_2025-26.pdf | Y13: SLDC MMR #5. Not in state data; 285 MW sanctioned to 2031 | Z13: K Raheja Corp / Mindspace
A14: MH10 | B14: SLDC | C14: NTT | D14: M/s Netmagic | E14: TTC, Mahape | F14: Navi Mumbai - TTC | G14: LILO on ckt-1 of 220 kV Kharghar-Borivali D/C | H14: 90 | I14: 25 | J14: 23.19 | S14: =IF(N(H14)>0,H14,IF(N(K14)+N(L14)>0,N(K14)+N(L14),IF(AND(N(M14)>0,OR(O14="A1",O14="A2")),M14,0))) -> 90 | T14: =IF(N(H14)>0,"SLDC",IF(N(K14)+N(L14)>0,"CTUIL",IF(S14>0,"Other official",IF(N(P14)>0,"Unverified","No MW")))) -> SLDC | U14: =IF(S14>0,S14,N(P14)) -> 90 | V14: 1 Grid sanctioned - partly live | W14: https://mahasldc.in/assets/public-ui/files/Data_Centre.pdf#page=23 | Y14: SLDC MMR #6. SLDC: NTT sites #6 + #9 + #18 = 665 MW grid | Z14: NTT
A15: MH11 | B15: SLDC | C15: NTT | D15: M/s. Estela Mukund (NTT Global) | E15: Bhola Nagar, Kalwa | F15: Navi Mumbai - TTC | G15: Interim LILO on 220 kV Kalwa-Bapgaon; final LILO on 400 kV Kalwa-Padghe | H15: 500 | I15: 50 | J15: 14 | P15: 366 | Q15: IT MW - tier C | R15: MPCB CTO; renewal (part) - Approved (M036) | S15: =IF(N(H15)>0,H15,IF(N(K15)+N(L15)>0,N(K15)+N(L15),IF(AND(N(M15)>0,OR(O15="A1",O15="A2")),M15,0))) -> 500 | T15: =IF(N(H15)>0,"SLDC",IF(N(K15)+N(L15)>0,"CTUIL",IF(S15>0,"Other official",IF(N(P15)>0,"Unverified","No MW")))) -> SLDC | U15: =IF(S15>0,S15,N(P15)) -> 500 | V15: 1 Grid sanctioned - partly live | W15: https://mahasldc.in/assets/public-ui/files/Data_Centre.pdf#page=23 | X15: https://www.datacenterdynamics.com/en/news/ntt-announces-500mw-nav2-data-center-in-navi-mumbai-india/ | Y15: SLDC MMR #9. NAV2 = 500 MW facility; our IT figure is consistent | Z15: NTT
A16: MH12 | B16: SLDC | C16: NTT | D16: M/s. NTT Global DC-13 | E16: TTC, Bhola Nagar, Kalwa | F16: Navi Mumbai - TTC | G16: LILO on 220 kV Kalwa-Bapgaon at 220 kV GIS of NTT NAV2 (DC-13) | H16: 75 | I16: 15 | J16: 5 | S16: =IF(N(H16)>0,H16,IF(N(K16)+N(L16)>0,N(K16)+N(L16),IF(AND(N(M16)>0,OR(O16="A1",O16="A2")),M16,0))) -> 75 | T16: =IF(N(H16)>0,"SLDC",IF(N(K16)+N(L16)>0,"CTUIL",IF(S16>0,"Other official",IF(N(P16)>0,"Unverified","No MW")))) -> SLDC | U16: =IF(S16>0,S16,N(P16)) -> 75 | V16: 1 Grid sanctioned - partly live | W16: https://mahasldc.in/assets/public-ui/files/Data_Centre.pdf#page=24 | Y16: SLDC MMR #18. | Z16: NTT
A17: MH13 | B17: SLDC | C17: STT GDC | D17: M/s. STT Global | E17: TTC MIDC, Khairane | F17: Navi Mumbai - TTC | G17: LILO on 220 kV Mahape-Tiffil | H17: 80 | I17: 40 | J17: 5 | P17: 133 | Q17: IT MW - tier A1 | R17: MPCB CTE; CTO (part); amendment - Approved (M035) | S17: =IF(N(H17)>0,H17,IF(N(K17)+N(L17)>0,N(K17)+N(L17),IF(AND(N(M17)>0,OR(O17="A1",O17="A2")),M17,0))) -> 80 | T17: =IF(N(H17)>0,"SLDC",IF(N(K17)+N(L17)>0,"CTUIL",IF(S17>0,"Other official",IF(N(P17)>0,"Unverified","No MW")))) -> SLDC | U17: =IF(S17>0,S17,N(P17)) -> 80 | V17: 1 Grid sanctioned - partly live | W17: https://mahasldc.in/assets/public-ui/files/Data_Centre.pdf#page=24 | X17: https://www.sttelemediagdc.com/in-en/locations/mumbai | Y17: SLDC MMR #14. | Z17: STT GDC
A18: MH14 | B18: SLDC | C18: Sify | D18: M/s Print House (Sify Infinit Spaces) | E18: TTC, Rabale | F18: Navi Mumbai - TTC | G18: LILO on 220 kV Apta-Kalwa | H18: 90 | I18: 30 | J18: 14 | P18: 377 | Q18: IT MW - tier A1 | R18: SEIAA / MPCB EC expansion; CTE expansion - Approved / on agenda (M028) | S18: =IF(N(H18)>0,H18,IF(N(K18)+N(L18)>0,N(K18)+N(L18),IF(AND(N(M18)>0,OR(O18="A1",O18="A2")),M18,0))) -> 90 | T18: =IF(N(H18)>0,"SLDC",IF(N(K18)+N(L18)>0,"CTUIL",IF(S18>0,"Other official",IF(N(P18)>0,"Unverified","No MW")))) -> SLDC | U18: =IF(S18>0,S18,N(P18)) -> 90 | V18: 1 Grid sanctioned - partly live | W18: https://mahasldc.in/assets/public-ui/files/Data_Centre.pdf#page=23 | X18: https://www.sifytechnologies.com/data-center/rabale-data-center/ | Y18: SLDC MMR #12. SLDC: Sify #12 + #30 = 160 MW grid vs 377 MW company campus figure | Z18: Sify
A19: MH15 | B19: SLDC | C19: Sify | D19: M/s. Sify Technologies Ltd | E19: TTC, Rabale | F19: Navi Mumbai - TTC | G19: LILO of 100 kV Reliable-Standard Alkali | H19: 70 | I19: 70 | S19: =IF(N(H19)>0,H19,IF(N(K19)+N(L19)>0,N(K19)+N(L19),IF(AND(N(M19)>0,OR(O19="A1",O19="A2")),M19,0))) -> 70 | T19: =IF(N(H19)>0,"SLDC",IF(N(K19)+N(L19)>0,"CTUIL",IF(S19>0,"Other official",IF(N(P19)>0,"Unverified","No MW")))) -> SLDC | U19: =IF(S19>0,S19,N(P19)) -> 70 | V19: 1 Grid sanctioned - partly live | W19: https://mahasldc.in/assets/public-ui/files/Data_Centre.pdf#page=26 | Y19: SLDC MMR #30. | Z19: Sify
A20: MH16 | B20: SLDC | C20: Adani Group (ex-Microsoft site) - inferred | D20: M/s Microsoft Corporation India Ltd (Pimpri-Chinchwad) | E20: Pimpri Chinchwad, Pune | F20: Pune | G20: 220 kV D/C UG cable from 220 kV Bhosari-I S/s (4 km) | H20: 155 | I20: 16 | J20: 0 | R20: MPCB Consent to Establish - Approved (M017); SEIAA EC - On agenda (M018) | S20: =IF(N(H20)>0,H20,IF(N(K20)+N(L20)>0,N(K20)+N(L20),IF(AND(N(M20)>0,OR(O20="A1",O20="A2")),M20,0))) -> 155 | T20: =IF(N(H20)>0,"SLDC",IF(N(K20)+N(L20)>0,"CTUIL",IF(S20>0,"Other official",IF(N(P20)>0,"Unverified","No MW")))) -> SLDC | U20: =IF(S20>0,S20,N(P20)) -> 155 | V20: 1 Grid sanctioned - partly live | W20: https://mahasldc.in/assets/public-ui/files/Data_Centre.pdf#page=26 | X20: https://mpcb.gov.in/sites/default/files/inline-files/Minutes%20of%2015th%20CAC%20Establish%20Booklet%20no%2065.pdf | Y20: SLDC PMR #2. First MW figure for this site: 155 MW (cumulative schedule to Jan-2030) | Z20: Adani Group
A21: MH17 | B21: SLDC | C21: Bharti Airtel (Nxtra) | D21: M/s NXTRA Data Ltd-1 | E21: MIDC Plot 13/104, Hinjewadi Ph-3, Pune | F21: Pune | G21: 2 x 220 kV lines from 400 kV Hinjewadi Ph-III | H21: 36 | I21: 36 | J21: 16.88 | S21: =IF(N(H21)>0,H21,IF(N(K21)+N(L21)>0,N(K21)+N(L21),IF(AND(N(M21)>0,OR(O21="A1",O21="A2")),M21,0))) -> 36 | T21: =IF(N(H21)>0,"SLDC",IF(N(K21)+N(L21)>0,"CTUIL",IF(S21>0,"Other official",IF(N(P21)>0,"Unverified","No MW")))) -> SLDC | U21: =IF(S21>0,S21,N(P21)) -> 36 | V21: 1 Grid sanctioned - partly live | W21: https://mahasldc.in/assets/public-ui/files/Data_Centre.pdf#page=27 | Y21: SLDC PMR #4. Not in our data | Z21: Bharti Airtel (Nxtra)
A22: MH18 | B22: SLDC | C22: Bharti Airtel (Nxtra) | D22: M/s NXTRA Data Ltd-2 | E22: Hinjewadi Ph-3, Mann, Pune | F22: Pune | G22: 220 kV UG D/C from 400/220 kV Hinjewadi Ph-III | H22: 150 | I22: 50 | J22: 5.02 | R22: MPCB CTE expansion; CTO (part) - Approved (after SCN) (M043) | S22: =IF(N(H22)>0,H22,IF(N(K22)+N(L22)>0,N(K22)+N(L22),IF(AND(N(M22)>0,OR(O22="A1",O22="A2")),M22,0))) -> 150 | T22: =IF(N(H22)>0,"SLDC",IF(N(K22)+N(L22)>0,"CTUIL",IF(S22>0,"Other official",IF(N(P22)>0,"Unverified","No MW")))) -> SLDC | U22: =IF(S22>0,S22,N(P22)) -> 150 | V22: 1 Grid sanctioned - partly live | W22: https://mahasldc.in/assets/public-ui/files/Data_Centre.pdf#page=27 | X22: https://mpcb.gov.in/sites/default/files/inline-files/Action_Taken_Report_of_16th_CAC_Booklet_no._16_%281%29.pdf | Y22: SLDC PMR #5. Not in our data | Z22: Bharti Airtel (Nxtra)
A23: MH19 | B23: SLDC | C23: STT GDC | D23: M/s. STT Global Data Centres India Pvt Ltd | E23: Alandi Road, VSNL Old Colony, Dighi, Pune | F23: Pune | G23: 220 kV VSNL-STT Global ckt-I & II | H23: 200 | I23: 57 | J23: 41.63 | S23: =IF(N(H23)>0,H23,IF(N(K23)+N(L23)>0,N(K23)+N(L23),IF(AND(N(M23)>0,OR(O23="A1",O23="A2")),M23,0))) -> 200 | T23: =IF(N(H23)>0,"SLDC",IF(N(K23)+N(L23)>0,"CTUIL",IF(S23>0,"Other official",IF(N(P23)>0,"Unverified","No MW")))) -> SLDC | U23: =IF(S23>0,S23,N(P23)) -> 200 | V23: 1 Grid sanctioned - partly live | W23: https://mahasldc.in/assets/public-ui/files/Data_Centre.pdf#page=27 | Y23: SLDC PMR #3. Not in our MH data: 100 MW existing + 100 MW additional; avg load ~42 MW | Z23: STT GDC
A24: MH20 | B24: SLDC | C24: AWS (Amazon) | D24: M/s. Amazon, Ambernath | E24: Narhen, Usatane, Burdul & Asode, Ambernath | F24: Ambernath (Lodha Palava park) | G24: 220 kV D/C from 220 kV Lodha switching station (proposed MSETCL) | H24: 475 | S24: =IF(N(H24)>0,H24,IF(N(K24)+N(L24)>0,N(K24)+N(L24),IF(AND(N(M24)>0,OR(O24="A1",O24="A2")),M24,0))) -> 475 | T24: =IF(N(H24)>0,"SLDC",IF(N(K24)+N(L24)>0,"CTUIL",IF(S24>0,"Other official",IF(N(P24)>0,"Unverified","No MW")))) -> SLDC | U24: =IF(S24>0,S24,N(P24)) -> 475 | V24: 2 Grid sanctioned / approved - not yet live | W24: https://mahasldc.in/assets/public-ui/files/Data_Centre.pdf#page=25 | Y24: SLDC MMR #22. Dec-2025: AWS 475 + STT 450 = 925 MW; MERC order (Jun-2026) later raised the park to ~1,450 MW granted. Phase schedule in report sums to 450 | Z24: AWS (Amazon)
A25: MH21 | B25: MERC | C25: Lodha park (AWS, STT + 1 more) | D25: Maharashtra STU - Ambernath 400/220 kV (Lodha-funded) | E25: Ambernath (Palava) - increase in STU grant Dec-25 -> Jun-26 | F25: Ambernath (Lodha Palava park) | G25: 400/220 kV Ambernath S/s (TBCB annulled; STU to build) | M25: 525 | N25: Derived: MERC 1,450 MW granted (Jun-2026) less SLDC 925 MW (AWS 475 + STT 450, Dec-2025) | O25: A1 | S25: =IF(N(H25)>0,H25,IF(N(K25)+N(L25)>0,N(K25)+N(L25),IF(AND(N(M25)>0,OR(O25="A1",O25="A2")),M25,0))) -> 525 | T25: =IF(N(H25)>0,"SLDC",IF(N(K25)+N(L25)>0,"CTUIL",IF(S25>0,"Other official",IF(N(P25)>0,"Unverified","No MW")))) -> Other official | U25: =IF(S25>0,S25,N(P25)) -> 525 | V25: 2 Grid sanctioned / approved - not yet live | W25: https://merc.gov.in/wp-content/uploads/2026/06/Order-88-of-2026.pdf | Y25: MERC Case 88/2026 para 7.15. AWS Ambernath EC filing (473 MW) sits inside this park - not added separately | Z25: Lodha park (AWS, STT + 1 more)
A26: MH22 | B26: SLDC | C26: STT GDC | D26: M/s. STT Global, Ambernath | E26: Narhen, Usatane, Burdul & Asode, Ambernath | F26: Ambernath (Lodha Palava park) | G26: 220 kV D/C from 220 kV Lodha switching station (proposed MSETCL) | H26: 450 | S26: =IF(N(H26)>0,H26,IF(N(K26)+N(L26)>0,N(K26)+N(L26),IF(AND(N(M26)>0,OR(O26="A1",O26="A2")),M26,0))) -> 450 | T26: =IF(N(H26)>0,"SLDC",IF(N(K26)+N(L26)>0,"CTUIL",IF(S26>0,"Other official",IF(N(P26)>0,"Unverified","No MW")))) -> SLDC | U26: =IF(S26>0,S26,N(P26)) -> 450 | V26: 2 Grid sanctioned / approved - not yet live | W26: https://mahasldc.in/assets/public-ui/files/Data_Centre.pdf#page=25 | Y26: SLDC MMR #23. | Z26: STT GDC
A27: MH23 | B27: SLDC | C27: AWS (Amazon) | D27: Amazon Data Services Pvt Ltd, Mumbai | E27: Tungwa, Powai (Kurla) | F27: Mumbai city | G27: LILO on 220 kV Salsette-Sahar & Salsette-Saki | H27: 225 | M27: 77 | N27: EC / Form-1A connected load | O27: A1 | P27: 77 | Q27: Connected MW - tier A1 | R27: SEIAA EC - Discussed (M010); MPCB Consent to Establish - Approved (M011) | S27: =IF(N(H27)>0,H27,IF(N(K27)+N(L27)>0,N(K27)+N(L27),IF(AND(N(M27)>0,OR(O27="A1",O27="A2")),M27,0))) -> 225 | T27: =IF(N(H27)>0,"SLDC",IF(N(K27)+N(L27)>0,"CTUIL",IF(S27>0,"Other official",IF(N(P27)>0,"Unverified","No MW")))) -> SLDC | U27: =IF(S27>0,S27,N(P27)) -> 225 | V27: 2 Grid sanctioned / approved - not yet live | W27: https://mahasldc.in/assets/public-ui/files/Data_Centre.pdf#page=24 | X27: https://environmentclearance.nic.in/writereaddata/FormB/agenda/1509202585756580%28740114%29MINUTESOF301DAY-4TABLEITEM-Copy.pdf | Y27: SLDC MMR #19. Grid sanction 225 MW vs 77 MW in the EC - EC covers only the first building(s) | Z27: AWS (Amazon)
A28: MH24 | B28: CTUIL | C28: Adani Group (AdaniConneX) | D28: Support Properties Pvt Ltd ('ACXNMI-01') | E28: A-GEN-4 TTC Rabale / Ghansoli; 400 kV POWERGRID Navi Mumbai (GIS) | F28: Navi Mumbai - TTC | G28: ISTS - 400 kV PG Navi Mumbai (GIS) | K28: 1468 | R28: SEIAA / MPCB EC expansion; CTE (Feb-24) - On agenda / approved (M027) | S28: =IF(N(H28)>0,H28,IF(N(K28)+N(L28)>0,N(K28)+N(L28),IF(AND(N(M28)>0,OR(O28="A1",O28="A2")),M28,0))) -> 1468 | T28: =IF(N(H28)>0,"SLDC",IF(N(K28)+N(L28)>0,"CTUIL",IF(S28>0,"Other official",IF(N(P28)>0,"Unverified","No MW")))) -> CTUIL | U28: =IF(S28>0,S28,N(P28)) -> 1468 | V28: 2 Grid sanctioned / approved - not yet live | W28: https://ctuil.in/nswsapi/gna | X28: https://www.ecmpcb.in/login/download_ec_document/MjMyMTI2NEMzMjYzNDM5M0IxRTJDRDY5MENBNDZFODcucGRm | Y28: 17 GNA applications (13 x 50 + 418 + 74 + 174 + 152) approved; AdaniConneX subsidiary since 2023. Not in SLDC (ISTS, not STU) | Z28: Adani Group
A29: MH25 | B29: SLDC | C29: Blackstone / AirTrunk (Gramercy SPVs) - inferred | D29: M/s Estela Coromandal (Gramercy Infopark Pvt Ltd) | E29: TTC, Mavli, Ghansoli | F29: Navi Mumbai - TTC | G29: Interim LILO on 220 kV Kharghar-Borivali; final LILO on 400 kV Kalwa-Kharghar | H29: 480 | S29: =IF(N(H29)>0,H29,IF(N(K29)+N(L29)>0,N(K29)+N(L29),IF(AND(N(M29)>0,OR(O29="A1",O29="A2")),M29,0))) -> 480 | T29: =IF(N(H29)>0,"SLDC",IF(N(K29)+N(L29)>0,"CTUIL",IF(S29>0,"Other official",IF(N(P29)>0,"Unverified","No MW")))) -> SLDC | U29: =IF(S29>0,S29,N(P29)) -> 480 | V29: 2 Grid sanctioned / approved - not yet live | W29: https://mahasldc.in/assets/public-ui/files/Data_Centre.pdf#page=23 | Y29: SLDC MMR #11. Largest new item: 480 MW (Mar-2028 to Nov-2031); needs a 400 kV LILO | Z29: Blackstone / AirTrunk
A30: MH26 | B30: SLDC | C30: Blackstone / AirTrunk (Gramercy SPVs) - inferred | D30: M/s. Gramercy Business Hub Pvt Ltd | E30: TTC, Mahape | F30: Navi Mumbai - TTC | G30: 220 kV Gramercy switching station; LILO on 220 kV Kharghar-Netmagic | H30: 150 | P30: 120 | Q30: IT MW - tier C | R30: MPCB Consent to Establish - Approved (M026) | S30: =IF(N(H30)>0,H30,IF(N(K30)+N(L30)>0,N(K30)+N(L30),IF(AND(N(M30)>0,OR(O30="A1",O30="A2")),M30,0))) -> 150 | T30: =IF(N(H30)>0,"SLDC",IF(N(K30)+N(L30)>0,"CTUIL",IF(S30>0,"Other official",IF(N(P30)>0,"Unverified","No MW")))) -> SLDC | U30: =IF(S30>0,S30,N(P30)) -> 150 | V30: 2 Grid sanctioned / approved - not yet live | W30: https://mahasldc.in/assets/public-ui/files/Data_Centre.pdf#page=25 | X30: https://airtrunk.com/location/bom2-mumbai/ | Y30: SLDC MMR #25. Likely AirTrunk BOM2 (Mahape) | Z30: Blackstone / AirTrunk
A31: MH27 | B31: SLDC | C31: Blackstone / AirTrunk (Gramercy SPVs) - inferred | D31: M/s. Gramercy Infra Realty Pvt Ltd | E31: Plot IT-1, IT-2, Knowledge Park, Navi Mumbai | F31: Navi Mumbai - TTC | G31: TFR awaited from field office | H31: 180 | S31: =IF(N(H31)>0,H31,IF(N(K31)+N(L31)>0,N(K31)+N(L31),IF(AND(N(M31)>0,OR(O31="A1",O31="A2")),M31,0))) -> 180 | T31: =IF(N(H31)>0,"SLDC",IF(N(K31)+N(L31)>0,"CTUIL",IF(S31>0,"Other official",IF(N(P31)>0,"Unverified","No MW")))) -> SLDC | U31: =IF(S31>0,S31,N(P31)) -> 180 | V31: 2 Grid sanctioned / approved - not yet live | W31: https://mahasldc.in/assets/public-ui/files/Data_Centre.pdf#page=25 | Y31: SLDC MMR #26. Not in our data; connectivity still at feasibility (TFR awaited) | Z31: Blackstone / AirTrunk
A32: MH28 | B32: SLDC | C32: CtrlS | D32: M/s. CTRLS New | E32: TTC MIDC, Mahape | F32: Navi Mumbai - TTC | G32: 220 kV Mahape-CtrlS GIS D/C UG cable (1 km) | H32: 290 | S32: =IF(N(H32)>0,H32,IF(N(K32)+N(L32)>0,N(K32)+N(L32),IF(AND(N(M32)>0,OR(O32="A1",O32="A2")),M32,0))) -> 290 | T32: =IF(N(H32)>0,"SLDC",IF(N(K32)+N(L32)>0,"CTUIL",IF(S32>0,"Other official",IF(N(P32)>0,"Unverified","No MW")))) -> SLDC | U32: =IF(S32>0,S32,N(P32)) -> 290 | V32: 2 Grid sanctioned / approved - not yet live | W32: https://mahasldc.in/assets/public-ui/files/Data_Centre.pdf#page=25 | Y32: SLDC MMR #24. Second CtrlS GIS substation, +290 MW | Z32: CtrlS
A33: MH29 | B33: SLDC | C33: Digital Edge | D33: M/s. Digital Edge | E33: Dighe, Thane Belapur Road | F33: Navi Mumbai - TTC | G33: LILO of 220 kV DCHI-Colourchem | H33: 190 | P33: 350 | Q33: IT MW - tier C | R33: MPCB Consent to Establish - Approved (M019); SEIAA EC - Granted (M021) | S33: =IF(N(H33)>0,H33,IF(N(K33)+N(L33)>0,N(K33)+N(L33),IF(AND(N(M33)>0,OR(O33="A1",O33="A2")),M33,0))) -> 190 | T33: =IF(N(H33)>0,"SLDC",IF(N(K33)+N(L33)>0,"CTUIL",IF(S33>0,"Other official",IF(N(P33)>0,"Unverified","No MW")))) -> SLDC | U33: =IF(S33>0,S33,N(P33)) -> 190 | V33: 2 Grid sanctioned / approved - not yet live | W33: https://mahasldc.in/assets/public-ui/files/Data_Centre.pdf#page=26 | X33: https://www.digitaledgedc.com/products-services/data-centers/india/ | Y33: SLDC MMR #28. | Z33: Digital Edge
A34: MH30 | B34: SLDC | C34: Google | D34: M/s Amantin (Greenscape) | E34: TTC, Turbhe | F34: Navi Mumbai - TTC | G34: LILO on 220 kV Kalwa-Tiffil at proposed 220 kV S/s | H34: 130 | M34: 103.367 | N34: EC / Form-1A connected load | O34: A1 | P34: 103.4 | Q34: Connected MW - tier A1 | R34: SEAC-II EC application - n/a (M001) | S34: =IF(N(H34)>0,H34,IF(N(K34)+N(L34)>0,N(K34)+N(L34),IF(AND(N(M34)>0,OR(O34="A1",O34="A2")),M34,0))) -> 130 | T34: =IF(N(H34)>0,"SLDC",IF(N(K34)+N(L34)>0,"CTUIL",IF(S34>0,"Other official",IF(N(P34)>0,"Unverified","No MW")))) -> SLDC | U34: =IF(S34>0,S34,N(P34)) -> 130 | V34: 2 Grid sanctioned / approved - not yet live | W34: https://mahasldc.in/assets/public-ui/files/Data_Centre.pdf#page=23 | X34: https://environmentclearance.nic.in/DownloadPfdFile.aspx?FileName=Kwy+a1Xl%2FGHp2kMbJYBd8GPrFSz%2FNzzr1mrm87hA6RfsBvasy5U%2FhwjR4PRxBwwupD8Lw8MExL5FqtSFZLEOTQ%3D%3D&FilePath=93ZZBm8LWEXfg+HAlQix2fE2t8z%2FpgnoBhDlYdZCxzXTbTpOQqzWjBW0IF63rxBVcDlG0LKdfbGNs0Ou%2FTEvAA%3D%3D | Y34: SLDC MMR #10. SLDC 130 MW grid vs 103.4 MW connected load in EC filing | Z34: Google
A35: MH31 | B35: SLDC | C35: Google | D35: M/s. Raiden InfoTech India (P) Ltd | E35: Turbhe MIDC, TTC | F35: Navi Mumbai - TTC | G35: LILO on 220 kV Kharghar-Sonkhar | H35: 190 | Q35: n/a - tier A1 | R35: MPCB Consent to Establish - Approved (M002); SEIAA EC application - On agenda (M003) | S35: =IF(N(H35)>0,H35,IF(N(K35)+N(L35)>0,N(K35)+N(L35),IF(AND(N(M35)>0,OR(O35="A1",O35="A2")),M35,0))) -> 190 | T35: =IF(N(H35)>0,"SLDC",IF(N(K35)+N(L35)>0,"CTUIL",IF(S35>0,"Other official",IF(N(P35)>0,"Unverified","No MW")))) -> SLDC | U35: =IF(S35>0,S35,N(P35)) -> 190 | V35: 2 Grid sanctioned / approved - not yet live | W35: https://mahasldc.in/assets/public-ui/files/Data_Centre.pdf#page=25 | X35: https://mpcb.gov.in/sites/default/files/inline-files/Action_Taken_report_of_5th_CAC_Booklet_no_5_0.pdf | Y35: SLDC MMR #21. First MW figure for Google's own Navi Mumbai site: 190 MW, May-2026 to May-2031 | Z35: Google
A36: MH32 | B36: SLDC | C36: Iron Mountain (Web Werks) | D36: M/s. Web Werks | E36: TTC, Rabale | F36: Navi Mumbai - TTC | G36: LILO on 220 kV Kalwa-Siemens at proposed 220 kV GIS | H36: 120 | M36: 140 | N36: EC / Form-1A connected load | O36: A1 | P36: 140 | Q36: Connected MW - tier A1 | R36: SEIAA EC (new DC buildings) - Discussed (M008); MPCB Consent to Establish - Approved (M009) | S36: =IF(N(H36)>0,H36,IF(N(K36)+N(L36)>0,N(K36)+N(L36),IF(AND(N(M36)>0,OR(O36="A1",O36="A2")),M36,0))) -> 120 | T36: =IF(N(H36)>0,"SLDC",IF(N(K36)+N(L36)>0,"CTUIL",IF(S36>0,"Other official",IF(N(P36)>0,"Unverified","No MW")))) -> SLDC | U36: =IF(S36>0,S36,N(P36)) -> 120 | V36: 2 Grid sanctioned / approved - not yet live | W36: https://mahasldc.in/assets/public-ui/files/Data_Centre.pdf#page=24 | X36: https://environmentclearance.nic.in/writereaddata/FormB/agenda/1509202585756580%28740114%29MINUTESOF301DAY-4TABLEITEM-Copy.pdf | Y36: SLDC MMR #15. | Z36: Iron Mountain (Web Werks)
A37: MH33 | B37: SLDC | C37: STT GDC | D37: M/s. ST Telemedia | E37: Thane Belapur Road | F37: Navi Mumbai - TTC | G37: LILO on 220 kV Mahape-Tiffil line | H37: 40 | S37: =IF(N(H37)>0,H37,IF(N(K37)+N(L37)>0,N(K37)+N(L37),IF(AND(N(M37)>0,OR(O37="A1",O37="A2")),M37,0))) -> 40 | T37: =IF(N(H37)>0,"SLDC",IF(N(K37)+N(L37)>0,"CTUIL",IF(S37>0,"Other official",IF(N(P37)>0,"Unverified","No MW")))) -> SLDC | U37: =IF(S37>0,S37,N(P37)) -> 40 | V37: 2 Grid sanctioned / approved - not yet live | W37: https://mahasldc.in/assets/public-ui/files/Data_Centre.pdf#page=22 | Y37: SLDC MMR #1. SLDC grid sanction for the two STT Navi Mumbai sites = 120 MW | Z37: STT GDC
A38: MH34 | B38: SLDC | C38: Unidentified ('IMCC') | D38: M/s IMCC | E38: TTC MIDC Zone-A, Ghansoli | F38: Navi Mumbai - TTC | G38: LILO on ckt-I of 220 kV Kharghar-Borivali D/C | H38: 106 | S38: =IF(N(H38)>0,H38,IF(N(K38)+N(L38)>0,N(K38)+N(L38),IF(AND(N(M38)>0,OR(O38="A1",O38="A2")),M38,0))) -> 106 | T38: =IF(N(H38)>0,"SLDC",IF(N(K38)+N(L38)>0,"CTUIL",IF(S38>0,"Other official",IF(N(P38)>0,"Unverified","No MW")))) -> SLDC | U38: =IF(S38>0,S38,N(P38)) -> 106 | V38: 2 Grid sanctioned / approved - not yet live | W38: https://mahasldc.in/assets/public-ui/files/Data_Centre.pdf#page=23 | Y38: SLDC MMR #7. Not in our data; sponsor to be identified | Z38: Unidentified ('IMCC')
A39: MH35 | B39: SLDC | C39: Unidentified ('Innovative') | D39: M/s. Innovative | E39: Khairane MIDC, Navi Mumbai | F39: Navi Mumbai - TTC | G39: LILO on 220 kV Mahape-Tiffil ckt of Kalwa-Siemens-Mahape-Tiffil line | H39: 50 | S39: =IF(N(H39)>0,H39,IF(N(K39)+N(L39)>0,N(K39)+N(L39),IF(AND(N(M39)>0,OR(O39="A1",O39="A2")),M39,0))) -> 50 | T39: =IF(N(H39)>0,"SLDC",IF(N(K39)+N(L39)>0,"CTUIL",IF(S39>0,"Other official",IF(N(P39)>0,"Unverified","No MW")))) -> SLDC | U39: =IF(S39>0,S39,N(P39)) -> 50 | V39: 2 Grid sanctioned / approved - not yet live | W39: https://mahasldc.in/assets/public-ui/files/Data_Centre.pdf#page=22 | Y39: SLDC MMR #2. Not in our data; sponsor to be identified | Z39: Unidentified ('Innovative')
A40: MH36 | B40: SLDC | C40: Yotta (Hiranandani) | D40: Yotta Data Services | E40: Hiranandani Fortune City, Panvel | F40: Panvel / Raigad | G40: - | H40: 52 | P40: 52 | Q40: IT MW - tier C | R40: MPCB Renewal of consent - Approved (M041) | S40: =IF(N(H40)>0,H40,IF(N(K40)+N(L40)>0,N(K40)+N(L40),IF(AND(N(M40)>0,OR(O40="A1",O40="A2")),M40,0))) -> 52 | T40: =IF(N(H40)>0,"SLDC",IF(N(K40)+N(L40)>0,"CTUIL",IF(S40>0,"Other official",IF(N(P40)>0,"Unverified","No MW")))) -> SLDC | U40: =IF(S40>0,S40,N(P40)) -> 52 | V40: 2 Grid sanctioned / approved - not yet live | W40: https://mahasldc.in/assets/public-ui/files/Data_Centre.pdf#page=26 | X40: https://colocation.yotta.com/data-center/nm1-datacenter-mumbai-region-maharashtra/ | Y40: SLDC MMR #31. Exact match | Z40: Yotta (Hiranandani)
A41: MH37 | B41: SLDC | C41: Adani Group (ex-Microsoft site) | D41: M/s Microsoft Corporation India Ltd (Bhosari) | E41: Bhosari, Pimpri Industrial Area, Pune | F41: Pune | G41: 220 kV D/C UG cable from 220 kV Century Enka S/s (2 km) | H41: 74 | M41: 75.4 | N41: EC / Form-1A connected load | O41: A1 | P41: 75.4 | Q41: Connected MW - tier A1 | R41: SEIAA EC (expansion) - Referred back to SEAC-III (M015); MPCB Consent to Establish - Approved (M016) | S41: =IF(N(H41)>0,H41,IF(N(K41)+N(L41)>0,N(K41)+N(L41),IF(AND(N(M41)>0,OR(O41="A1",O41="A2")),M41,0))) -> 74 | T41: =IF(N(H41)>0,"SLDC",IF(N(K41)+N(L41)>0,"CTUIL",IF(S41>0,"Other official",IF(N(P41)>0,"Unverified","No MW")))) -> SLDC | U41: =IF(S41>0,S41,N(P41)) -> 74 | V41: 2 Grid sanctioned / approved - not yet live | W41: https://mahasldc.in/assets/public-ui/files/Data_Centre.pdf#page=26 | X41: https://environmentclearance.nic.in/writereaddata/FormB/agenda/2302202697285484%28921161%29MINUTESOF319DAY-5PART-B.pdf | Y41: SLDC PMR #1. 74 MW grid = 75.4 MW EC. Schedule in report is cumulative (16.1 -> 74); converted to annual increments | Z41: Adani Group
...

Sheet Summary
A1: Maharashtra - what the SLDC data-centre report (Dec-2025) adds to our dataset
A2: https://mahasldc.in/assets/public-ui/files/Data_Centre.pdf
A4: Headline numbers (official, STU / SLDC) | B4: MW | C4: % / note | D4: Comment
A5: Data-centre projects with STU grid connectivity (MMR + PMR) | B5: 36 | D5: 31 in MMR, 5 in PMR
A6: Total load sanctioned by STU | B6: =SLDC_Projects!G43 -> 6000 | D6: Report: 6,000 MW (MMR 5,385 + PMR 615)
A7: Load realised (final connectivity granted) | B7: =SLDC_Projects!H43 -> 685 | C7: =B7/B6 -> 0.11416667 | D7: Report: 685 MW (~11% of sanctioned)
A8: Average metered load, last 3 months (18 commissioned DCs) | B8: 204.52 | C8: =B8/615 -> 0.33255285 | D8: 33% of the 615 MW granted to these 18 DCs
A9: Maximum metered load, last 3 months | B9: 274.46 | C9: =B9/615 -> 0.44627642 | D9: 44% of granted - DCs draw far below sanction today
A10: Sanctioned load scheduled for 2025-2028 | B10: =SUM(SLDC_Projects!R43:'SLDC_Projects'!U43) -> 3130 | C10: =B10/B6 -> 0.52166667 | D10: Bulk of the ramp is 2025-28, per report
A11: Sanctioned load scheduled for 2029-2036 | B11: =SUM(SLDC_Projects!V43:'SLDC_Projects'!AC43) -> 1776 | C11: =B11/B6 -> 0.296 | D11: Long tail to 2036 (Ambernath, Newfound)
A13: Comparison with our Maharashtra data | B13: Projects | C13: SLDC sanctioned MW | D13: What it means
A14: NEW - in SLDC, not in our state data | B14: =COUNTIFS(SLDC_Projects!$K$5:$K$40,"NEW") -> 11 | C14: =SUMIFS(SLDC_Projects!$G$5:$G$40,SLDC_Projects!$K$5:$K$40,"NEW") -> 1804 | D14: Add ~2 GW of grid-sanctioned DC load: K Raheja Newfound (250) & Gigaplex (285), Gramercy Infopark (480) & Gramercy Infra Realty (180), STT Pune (200), Airtel Nxtra Mahape + Pune (221), IMCC (106), Innovative (50), Bridge DC (32)
A15: Matched - SLDC gives a bigger / first official MW | B15: =COUNTIFS(SLDC_Projects!$K$5:$K$40,"*bigger*") -> 5 | C15: =SUMIFS(SLDC_Projects!$G$5:$G$40,SLDC_Projects!$K$5:$K$40,"*bigger*") -> 890 | D15: AWS Powai 225 vs 77; CtrlS 295 + 290 vs 214 IT; Amanthin 130 vs 103; Gramercy Techpark 90 vs 62; Gramercy Business Hub 150 vs 120
A16: Matched - SLDC adds MW where we had none | B16: =COUNTIFS(SLDC_Projects!$K$5:$K$40,"*adds*") -> 3 | C16: =SUMIFS(SLDC_Projects!$G$5:$G$40,SLDC_Projects!$K$5:$K$40,"*adds*") -> 635 | D16: Google/Raiden Turbhe 190 MW; Microsoft (now Adani SPV) Pimpri 155 MW; CtrlS New 290 MW
A17: Matched - SLDC smaller than our (company) figure | B17: =COUNTIFS(SLDC_Projects!$K$5:$K$40,"*smaller*") -> 4 | C17: =SUMIFS(SLDC_Projects!$G$5:$G$40,SLDC_Projects!$K$5:$K$40,"*smaller*") -> 375 | D17: Sify 160 grid vs 377 campus; Colt DCS-RMZ 60 vs 148; Digital Edge 225 vs 350
A18: Corrects our row | B18: =COUNTIFS(SLDC_Projects!$K$5:$K$40,"CORRECTS*") -> 1 | C18: =SUMIFS(SLDC_Projects!$G$5:$G$40,SLDC_Projects!$K$5:$K$40,"CORRECTS*") -> 150 | D18: AWS Thane (Balkum-Majiwada): 150 MW official vs 272 MW tier-D figure
A19: Matched - consistent | B19: =COUNTIFS(SLDC_Projects!$K$5:$K$40,"Matched") -> 12 | C19: =SUMIFS(SLDC_Projects!$G$5:$G$40,SLDC_Projects!$K$5:$K$40,"Matched") -> 2146 | D19: STT Navi Mumbai, NTT, Web Werks, Datascape, Yotta (52 = 52), Microsoft Bhosari (74 vs 75.4), Lodha/Ambernath
A21: Key takeaways
A22: 1) Official confirmation of the pipeline: STU has sanctioned ~6 GW of DC load in MMR + Pune (Dec-2025) - vs only ~0.7 GW realised and ~0.2 GW actually drawn on average. The client's 'much bigger than the press' view is supported on sanctions; actual draw lags badly.
A23: 2) Utilisation is low: 18 commissioned DCs draw 33% (avg) / 44% (peak) of the 615 MW granted to them - phased IT fit-out, not grid constraints (SLDC's own conclusion).
A24: 3) Navi Mumbai (TTC-Mahape-Airoli-Kalwa) is the stress point: almost all MMR projects hang off a handful of 220 kV LILOs (Kalwa-Tiffil, Kharghar-Borivali, Kalwa-Bapgaon, Kalwa-Colourchem, Mahape-Tiffil); NTT and Gramercy Infopark need 400 kV LILOs.
A25: 4) This report EXCLUDES ISTS (CTUIL) connections - Support Properties / AdaniConneX 1,468 MW at PG Navi Mumbai and Adani Infra 500 MW at Padghe-Kharghar are on top of the 6 GW.
A26: 5) Later events: MERC Case 88/2026 (Jun-2026) raised the Lodha Ambernath park to ~1,450 MW granted + 1,500 MW under consideration (vs 925 MW here), so the 6 GW is already stale on the upside.
A27: 6) Projects in our data but not here (no STU sanction by Dec-2025, served by a discom, or announced only): AdaniConneX Taloja (CoreWeave), PDG MU1/MU2, Chandivali, L&T Vyoma, AirTrunk Pen, ReNew, Trentar, Zerra, ESR, MAHAPREIT - see Ours_not_in_SLDC.
A29: Sanctioned DC load by scheduled year (MW)
A30: Ph-I / undated | B30: =SLDC_Projects!P43 -> 1004
A31: 2024 | B31: =SLDC_Projects!Q43 -> 65
A32: 2025 | B32: =SLDC_Projects!R43 -> 705
A33: 2026 | B33: =SLDC_Projects!S43 -> 779
A34: 2027 | B34: =SLDC_Projects!T43 -> 758.5
A35: 2028 | B35: =SLDC_Projects!U43 -> 887.5
A36: 2029 | B36: =SLDC_Projects!V43 -> 429
A37: 2030 | B37: =SLDC_Projects!W43 -> 558
A38: 2031 | B38: =SLDC_Projects!X43 -> 304
A39: 2032 | B39: =SLDC_Projects!Y43 -> 176
A40: 2033 | B40: =SLDC_Projects!Z43 -> 84
A41: 2034 | B41: =SLDC_Projects!AA43 -> 125
A42: 2035 | B42: =SLDC_Projects!AB43 -> 50
A43: 2036 | B43: =SLDC_Projects!AC43 -> 50

Sheet By_Group
A1: SLDC sanctioned / realised load by group (MW)
A3: Group (mapped) | B3: Sanctioned (MW) | C3: Realised (MW) | D3: Avg load 3 m (MW) | E3: Projects
A4: Blackstone / AirTrunk (Gramercy SPVs) | B4: =SUMIFS(SLDC_Projects!$G$5:$G$40,SLDC_Projects!$AE$5:$AE$40,A4) -> 900 | C4: =SUMIFS(SLDC_Projects!$H$5:$H$40,SLDC_Projects!$AE$5:$AE$40,A4) -> 35 | D4: =SUMIFS(SLDC_Projects!$I$5:$I$40,SLDC_Projects!$AE$5:$AE$40,A4) -> 5 | E4: =COUNTIFS(SLDC_Projects!$AE$5:$AE$40,A4) -> 4
A5: AWS (Amazon) | B5: =SUMIFS(SLDC_Projects!$G$5:$G$40,SLDC_Projects!$AE$5:$AE$40,A5) -> 850 | C5: =SUMIFS(SLDC_Projects!$H$5:$H$40,SLDC_Projects!$AE$5:$AE$40,A5) -> 0 | D5: =SUMIFS(SLDC_Projects!$I$5:$I$40,SLDC_Projects!$AE$5:$AE$40,A5) -> 0 | E5: =COUNTIFS(SLDC_Projects!$AE$5:$AE$40,A5) -> 3
A6: STT GDC | B6: =SUMIFS(SLDC_Projects!$G$5:$G$40,SLDC_Projects!$AE$5:$AE$40,A6) -> 770 | C6: =SUMIFS(SLDC_Projects!$H$5:$H$40,SLDC_Projects!$AE$5:$AE$40,A6) -> 97 | D6: =SUMIFS(SLDC_Projects!$I$5:$I$40,SLDC_Projects!$AE$5:$AE$40,A6) -> 46.63 | E6: =COUNTIFS(SLDC_Projects!$AE$5:$AE$40,A6) -> 4
A7: NTT | B7: =SUMIFS(SLDC_Projects!$G$5:$G$40,SLDC_Projects!$AE$5:$AE$40,A7) -> 665 | C7: =SUMIFS(SLDC_Projects!$H$5:$H$40,SLDC_Projects!$AE$5:$AE$40,A7) -> 90 | D7: =SUMIFS(SLDC_Projects!$I$5:$I$40,SLDC_Projects!$AE$5:$AE$40,A7) -> 42.19 | E7: =COUNTIFS(SLDC_Projects!$AE$5:$AE$40,A7) -> 3
A8: CtrlS | B8: =SUMIFS(SLDC_Projects!$G$5:$G$40,SLDC_Projects!$AE$5:$AE$40,A8) -> 585 | C8: =SUMIFS(SLDC_Projects!$H$5:$H$40,SLDC_Projects!$AE$5:$AE$40,A8) -> 70 | D8: =SUMIFS(SLDC_Projects!$I$5:$I$40,SLDC_Projects!$AE$5:$AE$40,A8) -> 43 | E8: =COUNTIFS(SLDC_Projects!$AE$5:$AE$40,A8) -> 2
A9: K Raheja Corp / Mindspace | B9: =SUMIFS(SLDC_Projects!$G$5:$G$40,SLDC_Projects!$AE$5:$AE$40,A9) -> 535 | C9: =SUMIFS(SLDC_Projects!$H$5:$H$40,SLDC_Projects!$AE$5:$AE$40,A9) -> 71 | D9: =SUMIFS(SLDC_Projects!$I$5:$I$40,SLDC_Projects!$AE$5:$AE$40,A9) -> 7.42 | E9: =COUNTIFS(SLDC_Projects!$AE$5:$AE$40,A9) -> 2
A10: Google | B10: =SUMIFS(SLDC_Projects!$G$5:$G$40,SLDC_Projects!$AE$5:$AE$40,A10) -> 320 | C10: =SUMIFS(SLDC_Projects!$H$5:$H$40,SLDC_Projects!$AE$5:$AE$40,A10) -> 0 | D10: =SUMIFS(SLDC_Projects!$I$5:$I$40,SLDC_Projects!$AE$5:$AE$40,A10) -> 0 | E10: =COUNTIFS(SLDC_Projects!$AE$5:$AE$40,A10) -> 2
A11: Microsoft site -> Adani SPVs | B11: =SUMIFS(SLDC_Projects!$G$5:$G$40,SLDC_Projects!$AE$5:$AE$40,A11) -> 229 | C11: =SUMIFS(SLDC_Projects!$H$5:$H$40,SLDC_Projects!$AE$5:$AE$40,A11) -> 16 | D11: =SUMIFS(SLDC_Projects!$I$5:$I$40,SLDC_Projects!$AE$5:$AE$40,A11) -> 0 | E11: =COUNTIFS(SLDC_Projects!$AE$5:$AE$40,A11) -> 2
A12: Digital Edge | B12: =SUMIFS(SLDC_Projects!$G$5:$G$40,SLDC_Projects!$AE$5:$AE$40,A12) -> 225 | C12: =SUMIFS(SLDC_Projects!$H$5:$H$40,SLDC_Projects!$AE$5:$AE$40,A12) -> 25 | D12: =SUMIFS(SLDC_Projects!$I$5:$I$40,SLDC_Projects!$AE$5:$AE$40,A12) -> 0.97 | E12: =COUNTIFS(SLDC_Projects!$AE$5:$AE$40,A12) -> 2
A13: Bharti Airtel (Nxtra) | B13: =SUMIFS(SLDC_Projects!$G$5:$G$40,SLDC_Projects!$AE$5:$AE$40,A13) -> 221 | C13: =SUMIFS(SLDC_Projects!$H$5:$H$40,SLDC_Projects!$AE$5:$AE$40,A13) -> 121 | D13: =SUMIFS(SLDC_Projects!$I$5:$I$40,SLDC_Projects!$AE$5:$AE$40,A13) -> 24.18 | E13: =COUNTIFS(SLDC_Projects!$AE$5:$AE$40,A13) -> 3
A14: Sify | B14: =SUMIFS(SLDC_Projects!$G$5:$G$40,SLDC_Projects!$AE$5:$AE$40,A14) -> 160 | C14: =SUMIFS(SLDC_Projects!$H$5:$H$40,SLDC_Projects!$AE$5:$AE$40,A14) -> 100 | D14: =SUMIFS(SLDC_Projects!$I$5:$I$40,SLDC_Projects!$AE$5:$AE$40,A14) -> 14 | E14: =COUNTIFS(SLDC_Projects!$AE$5:$AE$40,A14) -> 2
A15: Iron Mountain (Web Werks) | B15: =SUMIFS(SLDC_Projects!$G$5:$G$40,SLDC_Projects!$AE$5:$AE$40,A15) -> 120 | C15: =SUMIFS(SLDC_Projects!$H$5:$H$40,SLDC_Projects!$AE$5:$AE$40,A15) -> 0 | D15: =SUMIFS(SLDC_Projects!$I$5:$I$40,SLDC_Projects!$AE$5:$AE$40,A15) -> 0 | E15: =COUNTIFS(SLDC_Projects!$AE$5:$AE$40,A15) -> 1
... A21: Bridge Data Centres (BDC) | B21: =SUMIFS(SLDC_Projects!$G$5:$G$40,SLDC_Projects!$AE$5:$AE$40,A21) -> 32 | C21: =SUMIFS(SLDC_Projects!$H$5:$H$40,SLDC_Projects!$AE$5:$AE$40,A21) -> 32 | D21: =SUMIFS(SLDC_Projects!$I$5:$I$40,SLDC_Projects!$AE$5:$AE$40,A21) -> 10.93 | E21: =COUNTIFS(SLDC_Projects!$AE$5:$AE$40,A21) -> 1
A22: Total | B22: =SUM(B4:B21) -> 6000 | C22: =SUM(C4:C21) -> 685 | D22: =SUM(D4:D21) -> 204.52

Sheet SLDC_Projects
A1: Maharashtra SLDC (MahaTransco) - data-centre grid connectivity sanctioned by STU, MMR & PMR (report dated Dec-2025)
A2: Source: 'Preliminary Assessment of Data Centre Load Patterns in the Maharashtra Power System', Maharashtra State Load Despatch Centre, Dec-2025, Tables 1-4 (pp.21-29). Sanctioned = STU-sanctioned load (grid MW). Realised = final grid connectivity granted / load realised. Avg/Max = metered load, last 3 months (Table 4). Covers only STU (state 100-220-400 kV) connections - CTUIL / ISTS connections (e.g. Support Properties 1,468 MW, Adani Infra 500 MW) are NOT in this report.
A4: Region | B4: Sr | C4: Consumer (as in report) | D4: Group (mapped) | E4: Address | F4: Grid connectivity | G4: Sanctioned (MW) | H4: Realised (MW) | I4: Avg load, last 3 m (MW) | J4: Max load, last 3 m (MW) | K4: Match vs our dataset | L4: Our row / project | M4: Our MW & basis | N4: Comment | O4: Report page | P4: Ph-I / undated | Q4: 2024 | R4: 2025 | S4: 2026 | T4: 2027 | U4: 2028 | V4: 2029 | W4: 2030 | X4: 2031 | Y4: 2032 | Z4: 2033 | AA4: 2034 | AB4: 2035 | AC4: 2036 | AD4: Schedule total | AE4: Group key
A5: MMR | B5: 1 | C5: M/s. ST Telemedia | D5: STT GDC | E5: Thane Belapur Road | F5: LILO on 220 kV Mahape-Tiffil line | G5: 40 | K5: Matched | L5: Row 20 STT GDC TTC Khairane/Mahape | M5: 133 IT MW (with SLDC #14) | N5: SLDC grid sanction for the two STT Navi Mumbai sites = 120 MW | O5: 21 | P5: 40 | AD5: =SUM(P5:AC5) -> 40 | AE5: STT GDC
A6: MMR | B6: 2 | C6: M/s. Innovative | D6: Unidentified ('Innovative') | E6: Khairane MIDC, Navi Mumbai | F6: LILO on 220 kV Mahape-Tiffil ckt of Kalwa-Siemens-Mahape-Tiffil line | G6: 50 | K6: NEW | L6: - | M6: - | N6: Not in our data; sponsor to be identified | O6: 21 | P6: 50 | AD6: =SUM(P6:AC6) -> 50 | AE6: Unidentified ('Innovative')
A7: MMR | B7: 3 | C7: M/s CTRLS | D7: CtrlS | E7: TTC MIDC, Mahape | F7: LILO on ckt-I of 220 kV Kharghar-Borivali D/C | G7: 295 | H7: 70 | I7: 43 | J7: 45 | K7: Matched - bigger | L7: Row 19 CtrlS Mahape DC1-DC7 | M7: 214 IT MW | N7: SLDC: 295 MW sanctioned + 290 MW 'CtrlS New' (#24) = 585 MW grid vs our 214 IT MW. Site visit: 70 MW live, avg 42-45 MW | O7: 21 | P7: 70 | R7: 50 | S7: 30 | W7: 145 | AD7: =SUM(P7:AC7) -> 295 | AE7: CtrlS
A8: MMR | B8: 4 | C8: M/s Newfound | D8: K Raheja Corp (Newfound Properties) - inferred | E8: TTC Industrial Area, Thane, Navi Mumbai | F8: LILO on 220 kV Kharghar-Sonkhar line | G8: 250 | H8: 36 | I8: 0.42 | J8: 4.25 | K8: NEW | L8: v3 MH_Permits only (no MW) | M8: - | N8: Not in state data; 250 MW sanctioned to 2034 | O8: 21 | P8: 36 | R8: 19 | S8: 15 | T8: 16 | U8: 32 | V8: 13 | W8: 14 | X8: 10 | Y8: 11 | Z8: 9 | AA8: 75 | AD8: =SUM(P8:AC8) -> 250 | AE8: K Raheja Corp / Mindspace
A9: MMR | B9: 5 | C9: M/s Gigaplex | D9: K Raheja Corp / Mindspace REIT (Gigaplex) - inferred | E9: Airoli Knowledge Park, Airoli | F9: LILO on 220 kV Kalwa-Bapgaon | G9: 285 | H9: 35 | I9: 7 | J9: 27 | K9: NEW | L9: v3 MH_Permits only (no MW) | M9: - | N9: Not in state data; 285 MW sanctioned to 2031 | O9: 21 | P9: 35 | R9: 40 | S9: 50 | T9: 35 | U9: 25 | V9: 35 | W9: 30 | X9: 35 | AD9: =SUM(P9:AC9) -> 285 | AE9: K Raheja Corp / Mindspace
A10: MMR | B10: 6 | C10: M/s Netmagic | D10: NTT | E10: TTC, Mahape | F10: LILO on ckt-1 of 220 kV Kharghar-Borivali D/C | G10: 90 | H10: 25 | I10: 23.19 | J10: 24.68 | K10: Matched | L10: Row 21 NTT NAV1A + NAV2 | M10: 366 IT MW (with #9, #18) | N10: SLDC: NTT sites #6 + #9 + #18 = 665 MW grid | O10: 22 | P10: 35 | R10: 15 | S10: 10 | T10: 10 | U10: 10 | V10: 10 | AD10: =SUM(P10:AC10) -> 90 | AE10: NTT
A11: MMR | B11: 7 | C11: M/s IMCC | D11: Unidentified ('IMCC') | E11: TTC MIDC Zone-A, Ghansoli | F11: LILO on ckt-I of 220 kV Kharghar-Borivali D/C | G11: 106 | K11: NEW | L11: - | M11: - | N11: Not in our data; sponsor to be identified | O11: 22 | P11: 20 | R11: 20 | S11: 20 | T11: 20 | U11: 26 | AD11: =SUM(P11:AC11) -> 106 | AE11: Unidentified ('IMCC')
A12: MMR | B12: 8 | C12: M/s. Nxtra | D12: Bharti Airtel (Nxtra) | E12: TTC, Mahape | F12: LILO on 220 kV Kalwa-Tiffil line | G12: 35 | H12: 35 | I12: 2.28 | J12: 3.5 | K12: NEW | L12: - | M12: - | N12: Not in our MH state data (Airtel Nxtra) | O12: 22 | P12: 35 | AD12: =SUM(P12:AC12) -> 35 | AE12: Bharti Airtel (Nxtra)
A13: MMR | B13: 9 | C13: M/s. Estela Mukund (NTT Global) | D13: NTT | E13: Bhola Nagar, Kalwa | F13: Interim LILO on 220 kV Kalwa-Bapgaon; final LILO on 400 kV Kalwa-Padghe | G13: 500 | H13: 50 | I13: 14 | J13: 15 | K13: Matched | L13: Row 21 NTT NAV2 | M13: 366 IT MW (with #6, #18) | N13: NAV2 = 500 MW facility; our IT figure is consistent | O13: 22 | P13: 120 | R13: 80 | S13: 150 | T13: 150 | AD13: =SUM(P13:AC13) -> 500 | AE13: NTT
A14: MMR | B14: 10 | C14: M/s Amantin (Greenscape) | D14: Google (Amanthin / EverYondr lease) | E14: TTC, Turbhe | F14: LILO on 220 kV Kalwa-Tiffil at proposed 220 kV S/s | G14: 130 | K14: Matched - bigger | L14: Row 11 Amanthin D-31/32 TTC Turbhe | M14: 103.4 connected MW (Form-1A) | N14: SLDC 130 MW grid vs 103.4 MW connected load in EC filing | O14: 22 | R14: 23 | S14: 21 | T14: 21 | U14: 23 | V14: 22 | W14: 20 | AD14: =SUM(P14:AC14) -> 130 | AE14: Google
A15: MMR | B15: 11 | C15: M/s Estela Coromandal (Gramercy Infopark Pvt Ltd) | D15: Blackstone / AirTrunk (Gramercy SPV) - inferred | E15: TTC, Mavli, Ghansoli | F15: Interim LILO on 220 kV Kharghar-Borivali; final LILO on 400 kV Kalwa-Kharghar | G15: 480 | K15: NEW | L15: - | M15: - | N15: Largest new item: 480 MW (Mar-2028 to Nov-2031); needs a 400 kV LILO | O15: 22 | U15: 150 | V15: 100 | W15: 100 | X15: 130 | AD15: =SUM(P15:AC15) -> 480 | AE15: Blackstone / AirTrunk (Gramercy SPVs)
A16: MMR | B16: 12 | C16: M/s Print House (Sify Infinit Spaces) | D16: Sify | E16: TTC, Rabale | F16: LILO on 220 kV Apta-Kalwa | G16: 90 | H16: 30 | I16: 14 | J16: 19 | K16: Matched - smaller | L16: Row 17 Sify Rabale campus | M16: 377 IT MW (company) | N16: SLDC: Sify #12 + #30 = 160 MW grid vs 377 MW company campus figure | O16: 22 | P16: 30 | R16: 40 | T16: 10 | U16: 10 | AD16: =SUM(P16:AC16) -> 90 | AE16: Sify
A17: MMR | B17: 13 | C17: M/s Estela Hindustan Unilever (Gramercy Techpark) | D17: Blackstone / AirTrunk (Gramercy Techpark) | E17: TTC MIDC, Airoli | F17: LILO on 220 kV Kalwa-Taloja-Panchanand | G17: 90 | H17: 35 | I17: 5 | J17: 10 | K17: Matched - bigger | L17: Row 4 AirTrunk BOM1 (Gramercy Techpark) | M17: 62 IT MW (tier D) | N17: Official grid figure (90 MW) replaces directory-sourced 62 MW | O17: 23 | P17: 35 | R17: 25 | S17: 30 | AD17: =SUM(P17:AC17) -> 90 | AE17: Blackstone / AirTrunk (Gramercy SPVs)
A18: MMR | B18: 14 | C18: M/s. STT Global | D18: STT GDC | E18: TTC MIDC, Khairane | F18: LILO on 220 kV Mahape-Tiffil | G18: 80 | H18: 40 | I18: 5 | J18: 5 | K18: Matched | L18: Row 20 STT GDC | M18: 133 IT MW (with #1) | O18: 23 | P18: 40 | S18: 20 | T18: 20 | AD18: =SUM(P18:AC18) -> 80 | AE18: STT GDC
A19: MMR | B19: 15 | C19: M/s. Web Werks | D19: Iron Mountain (Web Werks) | E19: TTC, Rabale | F19: LILO on 220 kV Kalwa-Siemens at proposed 220 kV GIS | G19: 120 | K19: Matched | L19: Row 14 Web Werks MUM-3 | M19: 140 connected MW (SEIAA) | O19: 23 | P19: 25 | R19: 15 | S19: 25 | T19: 55 | AD19: =SUM(P19:AC19) -> 120 | AE19: Iron Mountain (Web Werks)
A20: MMR | B20: 16 | C20: M/s. Data Centre Holding | D20: Colt DCS - RMZ | E20: Kalwa Industrial Area, Dighe, Airoli | F20: LILO on 220 kV Kalwa-Colourchem | G20: 60 | H20: 10 | I20: 1.2 | J20: 1.75 | K20: Matched - smaller | L20: Row 23 Colt DCS-RMZ Kalwa | M20: 148 IT MW (potential) | N20: SLDC sanction only 60 MW so far vs 148 MW campus potential | O20: 23 | P20: 10 | S20: 15 | U20: 10 | V20: 25 | AD20: =SUM(P20:AC20) -> 60 | AE20: Colt DCS - RMZ
A21: MMR | B21: 17 | C21: M/s. Datascape | D21: CapitaLand | E21: TTC, Dighe | F21: LILO on 220 kV Kalwa-Bapgaon | G21: 120 | H21: 18 | I21: 9 | J21: 10 | K21: Matched | L21: Row 13 CapitaLand Digha | M21: 135 connected MW (SEIAA) | O21: 23 | P21: 18 | R21: 28 | S21: 22 | T21: 22 | U21: 30 | AD21: =SUM(P21:AC21) -> 120 | AE21: CapitaLand
