Workbook

Sheet Summary
A1: State-level DC power evidence (non-CTUIL) - summary (MW)
A2: Block B on each state sheet excludes projects already in the CTUIL register, so it can be added to the CTUIL numbers without double counting.
A4: State | B4: Under process | C4: Approved | D4: Total | E4: Of which overlaps CTUIL (Yes/Possible) | F4: Total excl. CTUIL overlap
A5: Maharashtra | B5: =Maharashtra!B30 -> 7108.8 | C5: =Maharashtra!C30 -> 4005.4 | D5: =B5+C5 -> 11114.2 | E5: =SUMIFS(Backup_All_States!$E$2:$E$70,Backup_All_States!$A$2:$A$70,$A5,Backup_All_States!$L$2:$L$70,"Y",Backup_All_States!$J$2:$J$70,"<>No")+SUMIFS(Backup_All_States!$F$2:$F$70,Backup_All_States!$A$2:$A$70,$A5,Backup_All_States!$L$2:$L$70,"Y",Backup_All_States!$J$2:$J$70,"<>No") -> 240 | F5: =D5-E5 -> 10874.2
A6: Andhra Pradesh | B6: ='Andhra Pradesh'!B13 -> 0 | C6: ='Andhra Pradesh'!C13 -> 6486 | D6: =B6+C6 -> 6486 | E6: =SUMIFS(Backup_All_States!$E$2:$E$70,Backup_All_States!$A$2:$A$70,$A6,Backup_All_States!$L$2:$L$70,"Y",Backup_All_States!$J$2:$J$70,"<>No")+SUMIFS(Backup_All_States!$F$2:$F$70,Backup_All_States!$A$2:$A$70,$A6,Backup_All_States!$L$2:$L$70,"Y",Backup_All_States!$J$2:$J$70,"<>No") -> 2138 | F6: =D6-E6 -> 4348
A7: Telangana | B7: =Telangana!B14 -> 2386.8 | C7: =Telangana!C14 -> 2297.2 | D7: =B7+C7 -> 4684 | E7: =SUMIFS(Backup_All_States!$E$2:$E$70,Backup_All_States!$A$2:$A$70,$A7,Backup_All_States!$L$2:$L$70,"Y",Backup_All_States!$J$2:$J$70,"<>No")+SUMIFS(Backup_All_States!$F$2:$F$70,Backup_All_States!$A$2:$A$70,$A7,Backup_All_States!$L$2:$L$70,"Y",Backup_All_States!$J$2:$J$70,"<>No") -> 1406 | F7: =D7-E7 -> 3278
A8: Tamil Nadu | B8: ='Tamil Nadu'!B12 -> 157.9 | C8: ='Tamil Nadu'!C12 -> 239.1 | D8: =B8+C8 -> 397 | E8: =SUMIFS(Backup_All_States!$E$2:$E$70,Backup_All_States!$A$2:$A$70,$A8,Backup_All_States!$L$2:$L$70,"Y",Backup_All_States!$J$2:$J$70,"<>No")+SUMIFS(Backup_All_States!$F$2:$F$70,Backup_All_States!$A$2:$A$70,$A8,Backup_All_States!$L$2:$L$70,"Y",Backup_All_States!$J$2:$J$70,"<>No") -> 0 | F8: =D8-E8 -> 397
A9: Uttar Pradesh | B9: ='Uttar Pradesh'!B12 -> 434.8 | C9: ='Uttar Pradesh'!C12 -> 133 | D9: =B9+C9 -> 567.8 | E9: =SUMIFS(Backup_All_States!$E$2:$E$70,Backup_All_States!$A$2:$A$70,$A9,Backup_All_States!$L$2:$L$70,"Y",Backup_All_States!$J$2:$J$70,"<>No")+SUMIFS(Backup_All_States!$F$2:$F$70,Backup_All_States!$A$2:$A$70,$A9,Backup_All_States!$L$2:$L$70,"Y",Backup_All_States!$J$2:$J$70,"<>No") -> 0 | F9: =D9-E9 -> 567.8
A10: Odisha | B10: =Odisha!B8 -> 0 | C10: =Odisha!C8 -> 1120 | D10: =B10+C10 -> 1120 | E10: =SUMIFS(Backup_All_States!$E$2:$E$70,Backup_All_States!$A$2:$A$70,$A10,Backup_All_States!$L$2:$L$70,"Y",Backup_All_States!$J$2:$J$70,"<>No")+SUMIFS(Backup_All_States!$F$2:$F$70,Backup_All_States!$A$2:$A$70,$A10,Backup_All_States!$L$2:$L$70,"Y",Backup_All_States!$J$2:$J$70,"<>No") -> 0 | F10: =D10-E10 -> 1120
A11: Karnataka | B11: =Karnataka!B7 -> 500 | C11: =Karnataka!C7 -> 0 | D11: =B11+C11 -> 500 | E11: =SUMIFS(Backup_All_States!$E$2:$E$70,Backup_All_States!$A$2:$A$70,$A11,Backup_All_States!$L$2:$L$70,"Y",Backup_All_States!$J$2:$J$70,"<>No")+SUMIFS(Backup_All_States!$F$2:$F$70,Backup_All_States!$A$2:$A$70,$A11,Backup_All_States!$L$2:$L$70,"Y",Backup_All_States!$J$2:$J$70,"<>No") -> 0 | F11: =D11-E11 -> 500
A12: Gujarat | B12: =Gujarat!B7 -> 168 | C12: =Gujarat!C7 -> 0 | D12: =B12+C12 -> 168 | E12: =SUMIFS(Backup_All_States!$E$2:$E$70,Backup_All_States!$A$2:$A$70,$A12,Backup_All_States!$L$2:$L$70,"Y",Backup_All_States!$J$2:$J$70,"<>No")+SUMIFS(Backup_All_States!$F$2:$F$70,Backup_All_States!$A$2:$A$70,$A12,Backup_All_States!$L$2:$L$70,"Y",Backup_All_States!$J$2:$J$70,"<>No") -> 168 | F12: =D12-E12 -> 0
A13: Haryana | B13: =Haryana!B7 -> 279 | C13: =Haryana!C7 -> 28 | D13: =B13+C13 -> 307 | E13: =SUMIFS(Backup_All_States!$E$2:$E$70,Backup_All_States!$A$2:$A$70,$A13,Backup_All_States!$L$2:$L$70,"Y",Backup_All_States!$J$2:$J$70,"<>No")+SUMIFS(Backup_All_States!$F$2:$F$70,Backup_All_States!$A$2:$A$70,$A13,Backup_All_States!$L$2:$L$70,"Y",Backup_All_States!$J$2:$J$70,"<>No") -> 0 | F13: =D13-E13 -> 307
A14: West Bengal | B14: ='West Bengal'!B8 -> 275 | C14: ='West Bengal'!C8 -> 0 | D14: =B14+C14 -> 275 | E14: =SUMIFS(Backup_All_States!$E$2:$E$70,Backup_All_States!$A$2:$A$70,$A14,Backup_All_States!$L$2:$L$70,"Y",Backup_All_States!$J$2:$J$70,"<>No")+SUMIFS(Backup_All_States!$F$2:$F$70,Backup_All_States!$A$2:$A$70,$A14,Backup_All_States!$L$2:$L$70,"Y",Backup_All_States!$J$2:$J$70,"<>No") -> 0 | F14: =D14-E14 -> 275
A15: Total | B15: =SUM(B5:B14) -> 11310.3 | C15: =SUM(C5:C14) -> 14308.7 | D15: =SUM(D5:D14) -> 25619 | E15: =SUM(E5:E14) -> 3952 | F15: =SUM(F5:F14) -> 21667

Sheet MH_Reconciliation
A1: Why Maharashtra state-level data is ~5x the CTUIL data-centre filings
A2: Blue numbers are inputs from the CTUIL workbook (CTUIL_Bulk_Applications_by_State.xlsx, DC groups per your mapping: Adani, TCS, SITAC). All other numbers are formulas on Backup_All_States.
A4: Bridge item (Maharashtra) | B4: Approved (MW) | C4: Under process (MW) | D4: Total (MW) | E4: Share of state total | F4: Comparable to a CTUIL GNA filing?
A5: Lodha/Ambernath via state STU (MERC 88/2026) | B5: =SUMIFS(Backup_All_States!$E$2:$E$70,Backup_All_States!$A$2:$A$70,"Maharashtra",Backup_All_States!$O$2:$O$70,"1 Grid connection granted / sanctioned",Backup_All_States!$L$2:$L$70,"Y") -> 1450 | C5: =SUMIFS(Backup_All_States!$F$2:$F$70,Backup_All_States!$A$2:$A$70,"Maharashtra",Backup_All_States!$O$2:$O$70,"1 Grid connection granted / sanctioned",Backup_All_States!$L$2:$L$70,"Y") -> 1500 | D5: =B5+C5 -> 2950 | E5: =IF($D$10=0,0,D5/$D$10) -> 0.26542621 | F5: Yes in kind - but via STATE grid, so never in CTUIL
A6: Campus permits - mostly existing TTC-belt campuses on MSETCL/MSEDCL 220 kV | B6: =SUMIFS(Backup_All_States!$E$2:$E$70,Backup_All_States!$A$2:$A$70,"Maharashtra",Backup_All_States!$O$2:$O$70,"2 Permit (EC / pollution consent)",Backup_All_States!$L$2:$L$70,"Y") -> 2551.4 | C6: =SUMIFS(Backup_All_States!$F$2:$F$70,Backup_All_States!$A$2:$A$70,"Maharashtra",Backup_All_States!$O$2:$O$70,"2 Permit (EC / pollution consent)",Backup_All_States!$L$2:$L$70,"Y") -> 437.3 | D6: =B6+C6 -> 2988.7 | E6: =IF($D$10=0,0,D6/$D$10) -> 0.26890824 | F6: No - permits, often IT MW, state-grid connected
A7: Government approvals (GO / land) | B7: =SUMIFS(Backup_All_States!$E$2:$E$70,Backup_All_States!$A$2:$A$70,"Maharashtra",Backup_All_States!$O$2:$O$70,"3 Govt approval (GO / land)",Backup_All_States!$L$2:$L$70,"Y") -> 0 | C7: =SUMIFS(Backup_All_States!$F$2:$F$70,Backup_All_States!$A$2:$A$70,"Maharashtra",Backup_All_States!$O$2:$O$70,"3 Govt approval (GO / land)",Backup_All_States!$L$2:$L$70,"Y") -> 0 | D7: =B7+C7 -> 0 | E7: =IF($D$10=0,0,D7/$D$10) -> 0 | F7: No
A8: MoUs / LoIs / announcements (AirTrunk Raigad 3 GW, ReNew, Trentar, MAHAPREIT...) | B8: =SUMIFS(Backup_All_States!$E$2:$E$70,Backup_All_States!$A$2:$A$70,"Maharashtra",Backup_All_States!$O$2:$O$70,"4 MoU / LoI / announced",Backup_All_States!$L$2:$L$70,"Y") -> 4 | C8: =SUMIFS(Backup_All_States!$F$2:$F$70,Backup_All_States!$A$2:$A$70,"Maharashtra",Backup_All_States!$O$2:$O$70,"4 MoU / LoI / announced",Backup_All_States!$L$2:$L$70,"Y") -> 5051.5 | D8: =B8+C8 -> 5055.5 | E8: =IF($D$10=0,0,D8/$D$10) -> 0.45486855 | F8: No - intent only, no grid application yet
A9: Operating / company filings | B9: =SUMIFS(Backup_All_States!$E$2:$E$70,Backup_All_States!$A$2:$A$70,"Maharashtra",Backup_All_States!$O$2:$O$70,"5 Operating / company filing",Backup_All_States!$L$2:$L$70,"Y") -> 0 | C9: =SUMIFS(Backup_All_States!$F$2:$F$70,Backup_All_States!$A$2:$A$70,"Maharashtra",Backup_All_States!$O$2:$O$70,"5 Operating / company filing",Backup_All_States!$L$2:$L$70,"Y") -> 120 | D9: =B9+C9 -> 120 | E9: =IF($D$10=0,0,D9/$D$10) -> 0.010796998 | F9: No
A10: Maharashtra state-level total | B10: =SUM(B5:B9) -> 4005.4 | C10: =SUM(C5:C9) -> 7108.8 | D10: =SUM(D5:D9) -> 11114.2 | E10: =SUM(E5:E9) -> 1
A12: Like-for-like: grid-connection evidence only (MW)
A13: State | B13: CTUIL DC filings (ISTS) | C13: State-grid connection / sanction | D13: Total grid evidence | E13: State-grid share | F13: Main state-grid item
A14: Maharashtra | B14: 2068 | C14: =SUMIFS(Backup_All_States!$E$2:$E$70,Backup_All_States!$A$2:$A$70,$A14,Backup_All_States!$O$2:$O$70,"1 Grid*",Backup_All_States!$L$2:$L$70,"Y")+SUMIFS(Backup_All_States!$F$2:$F$70,Backup_All_States!$A$2:$A$70,$A14,Backup_All_States!$O$2:$O$70,"1 Grid*",Backup_All_States!$L$2:$L$70,"Y") -> 2950 | D14: =B14+C14 -> 5018 | E14: =IF(D14=0,0,C14/D14) -> 0.58788362 | F14: Lodha/Ambernath 1,450 granted + 1,500 under consideration (STU)
A15: Andhra Pradesh | B15: 2573 | C15: =SUMIFS(Backup_All_States!$E$2:$E$70,Backup_All_States!$A$2:$A$70,$A15,Backup_All_States!$O$2:$O$70,"1 Grid*",Backup_All_States!$L$2:$L$70,"Y")+SUMIFS(Backup_All_States!$F$2:$F$70,Backup_All_States!$A$2:$A$70,$A15,Backup_All_States!$O$2:$O$70,"1 Grid*",Backup_All_States!$L$2:$L$70,"Y") -> 0 | D15: =B15+C15 -> 2573 | E15: =IF(D15=0,0,C15/D15) -> 0 | F15: None found - Vizag DCs filed directly with CTUIL
A16: Telangana | B16: 4102 | C16: =SUMIFS(Backup_All_States!$E$2:$E$70,Backup_All_States!$A$2:$A$70,$A16,Backup_All_States!$O$2:$O$70,"1 Grid*",Backup_All_States!$L$2:$L$70,"Y")+SUMIFS(Backup_All_States!$F$2:$F$70,Backup_All_States!$A$2:$A$70,$A16,Backup_All_States!$O$2:$O$70,"1 Grid*",Backup_All_States!$L$2:$L$70,"Y") -> 2000 | D16: =B16+C16 -> 6102 | E16: =IF(D16=0,0,C16/D16) -> 0.32776139 | F16: Fortune 2,000 MVA (TGTRANSCO, per developer)
A18: 1. Different instruments: ~44% of the Maharashtra state number is MoU/LoI/announced capacity (AirTrunk's 3 GW Raigad LoI alone is 26%). These have no grid application yet - they cannot appear in CTUIL.
A19: 2. Different grid: Maharashtra DCs connect through the STATE network (MSETCL 220/400 kV; MSEDCL, Tata Power, AEML distribution). MERC Case 88/2026 records STU - not CTU - connectivity for AWS and STT at Ambernath; MSETCL's STU plan builds a 765/400/220 kV Mahape node 'for Datacenter Consumers' (6,000 + 2,000 MVA).
A20: 3. ISTS access is physically constrained in Navi Mumbai: CTUIL's 26th WR consultation meeting (28-02-2024) recorded 'No margins for drawal of power exist at existing 400/220kV Navi Mumbai S/s'. Only Support Properties (1,468 MW, approved) and Adani Infra (500 MW, pending) have direct ISTS filings.
A21: 4. Different units: most permit rows are IT MW or design capacity of existing campuses (Sify 377, Digital Edge 400, NTT 530), not grid MW.
A22: 5. By contrast, AP and Telangana mega-campuses are greenfield, far from strong state networks, and filed directly with CTUIL (Vizag SPVs at Gajuwaka/Pendurthi; Telangana SPVs at Maheshwaram/Doma) - so CTUIL captures a larger share there.
A23: Conclusion: the 5x is mainly a measurement artefact (instrument + grid route), not double counting. For a like-for-like national chart, use grid-connection evidence only (table above) or CTUIL + state-grid connectivity; show MoU/LoI separately as 'pipeline intent'.
A24: Residual risk: AWS Thane (Balkum, 272 MW IT) and STT's Navi Mumbai rows could partly draw on the Ambernath STU connectivity - not confirmed; kept separate.

Sheet Audit_Log
A1: Row-by-row audit of every MW figure (21-Oct-2026)
A2: Method: each row's linked source was re-fetched (or the local copy / OCR of the scanned minutes used) and the MW figure, company and site searched in it; every match was then read in context.
A4: Backup row | B4: State | C4: Group | D4: Project / site | E4: Approved MW (now) | F4: Under process MW (now) | G4: Tier (now) | H4: Verdict | I4: What was checked / changed
A5: 2 | B5: Maharashtra | C5: Lodha Group (park; tenants AWS, STT) | D5: Palava-Ambernath Green DC Park | E5: 1450 | F5: 1500 | G5: A1 | H5: Verified - primary doc | I5: 1,450 + 1,500 MW quoted in MERC order para 7.15
A6: 3 | B6: Maharashtra | C6: AirTrunk (Blackstone) | D6: Raigad-Pen Growth Centre | F6: 3000 | G6: A2 | H6: Verified - press / reported govt action | I6: 3 GW quoted (CM statement via ANI)
A7: 4 | B7: Maharashtra | C7: AirTrunk (Blackstone) | D7: BOM1, Plot 7 & 7A TTC Airoli | E7: 62 | G7: D | H7: Downgraded | I7: Was 182 MW combined with BOM2; consent verified, 62 MW only from a directory listing
A8: 5 | B8: Maharashtra | C8: AirTrunk (Blackstone) | D8: BOM2, Mahape (5.4 ha) | F8: 120 | G8: C | H8: Corrected | I8: Split out; 120+ MW company figure; moved to under process (no BOM2 permit found)
A9: 6 | B9: Maharashtra | C9: Adani Group | D9: Taloja campus | F9: 240 | G9: C | H9: Verified - company / rating / exchange | I9: 240 MW in CoreWeave release
A10: 7 | B10: Maharashtra | C10: Adani Group | D10: A-GEN-4 TTC Rabale/Ghansoli | G10: A1 | H10: No MW (reference only) | I10: Power captured in CTUIL (Support Properties)
A11: 8 | B11: Maharashtra | C11: Adani Group | D11: ACXPNQ26 / PNQ04, Bhosari, Pune (Microsoft site) | E11: 75.4 | G11: A1 | H11: Verified - primary doc | I11: 75.4 MW connected load in 319th SEIAA minutes (OCR)
A12: 9 | B12: Maharashtra | C12: AWS (Amazon) | D12: Balkum-Majiwada, Thane | E12: 272 | G12: D | H12: Downgraded | I12: CTE + Rs 7,203 cr verified; 272 MW only in a social-media summary of the EC filing
A13: 10 | B13: Maharashtra | C13: AWS (Amazon) | D13: Powai | E13: 77 | G13: A1 | H13: Verified - primary doc | I13: 77,000 kW connected / 75,000 kW demand in 301st SEIAA minutes (OCR)
A14: 11 | B14: Maharashtra | C14: Google | D14: D-31/32 TTC Turbhe | F14: 103.4 | G14: A1 | H14: Verified - primary doc | I14: 1,03,367 kW connected load in Form-1A
A15: 12 | B15: Maharashtra | C15: Google | D15: GEN-2/1/A/1 TTC Turbhe | G15: A1 | H15: No MW (reference only) | I15: CTE verified; no MW disclosed
A16: 13 | B16: Maharashtra | C16: CapitaLand | D16: Digha (DC Navi Mumbai 1) | E16: 135 | G16: A1 | H16: Verified - primary doc | I16: 135 MW connected / 120 MVA in 301st SEIAA minutes (OCR)
A17: 14 | B17: Maharashtra | C17: Iron Mountain | D17: MUM-3, R-50 to R-54 TTC Rabale | E17: 140 | G17: A1 | H17: Verified - primary doc | I17: 140 MW connected / 131 MW demand in 301st SEIAA minutes (OCR)
A18: 15 | B18: Maharashtra | C18: Unidentified (Chandivali) | D18: Saki Vihar-Chandivali, Mumbai | F18: 113.9 | G18: A1 | H18: Verified - primary doc | I18: 113,855 kW connected in 292nd/296th SEIAA minutes (OCR)
A19: 16 | B19: Maharashtra | C19: Digital Edge | D19: BOM campus, Kalwa/Dighe (47 acres) | E19: 350 | G19: C | H19: Corrected | I19: 400 -> 350 MW (company page: 350MW on 47 acres)
A20: 17 | B20: Maharashtra | C20: Sify | D20: Rabale campus | E20: 377 | G20: A1 | H20: Verified - company / rating / exchange | I20: 377+ MW in Sify Integrated Report 2024-25 (link updated in v3 dataset; company page)
A21: 18 | B21: Maharashtra | C21: Yotta (Hiranandani) | D21: NM1 Panvel | E21: 52 | G21: C | H21: Corrected | I21: 250 -> 52 MW (Yotta page); 250 was aggregator-only
A22: 19 | B22: Maharashtra | C22: CtrlS | D22: Mahape DC1-DC7 | E22: 214 | G22: A1 | H22: Verified - company / rating / exchange | I22: DC1&2 40, DC3 10, DC4 36.8, DC5 32 + DC6&7 95 MW on CtrlS homepage
A23: 20 | B23: Maharashtra | C23: STT GDC | D23: TTC Khairane/Mahape | E23: 133 | G23: A1 | H23: Verified - company / rating / exchange | I23: 133MW on STT Mumbai page
A24: 21 | B24: Maharashtra | C24: NTT | D24: NAV1A + NAV2, Airoli/Mahape | E24: 366 | G24: C | H24: Corrected | I24: 530 -> 366 MW IT (was mixing 500 MW facility power with IT)
A25: 22 | B25: Maharashtra | C25: Princeton Digital Group | D25: MU1 Airoli (50 live + 100 expansion) + MU2 (120) | E25: 150 | F25: 120 | G25: C | H25: Corrected | I25: 220 approved -> 150 approved + 120 under process (DCD)
A26: 23 | B26: Maharashtra | C26: Colt DCS - RMZ | D26: Kalwa plots 5 & 5A, Airoli | E26: 148 | G26: C | H26: Corrected | I26: Link fixed: 148 MW is in Oct-2026 article; ICRA says 142 MW
A27: 24 | B27: Maharashtra | C27: L&T | D27: Vyoma EL-200 Mahape | F27: 100 | G27: A1 | H27: Verified - company / rating / exchange | I27: 40 MW of 100 MW campus in L&T release
A28: 25 | B28: Maharashtra | C28: ReNew | D28: MMR green DC park (Panvel/Taloja/Khalapur) | F28: 750 | G28: A2 | H28: Verified - press / reported govt action | I28: 750 MW in Business Standard
A29: 26 | B29: Maharashtra | C29: Trentar (Dorf Ketal) | D29: Location not disclosed | F29: 500 | G29: A2 | H29: Verified - company / rating / exchange | I29: 500 MW in Trentar release
A30: 27 | B30: Maharashtra | C30: Zerra | D30: Navi Mumbai 29 acres | F30: 240 | G30: C | H30: Verified - company / rating / exchange | I30: 240MW on Zerra page
A31: 28 | B31: Maharashtra | C31: MAHAPREIT (state) | D31: State DC project | F31: 200 | G31: A1 | H31: Verified - primary doc | I31: 200 MW in MAHAPREIT EOI
A32: 29 | B32: Maharashtra | C32: ESR | D32: Rabale | F32: 60 | G32: D | H32: Verified - press / reported govt action | I32: 60 MW in CRN Asia
A33: 30 | B33: Maharashtra | C33: TCC Concept / NES Data | D33: Hinjewadi, Pune | E33: 4 | F33: 56 | G33: C | H33: Derived from verified figures | I33: 4 MW op + (60 - 4) under process
A34: 31 | B34: Maharashtra | C34: Avisirah | D34: Navi Mumbai | F34: 5.5 | G34: D | H34: Verified - press / reported govt action | I34: 5.5 MW in PropNewsTime
A35: 32 | B35: Andhra Pradesh | C35: Adani Group | D35: Tarluvada (for Google) | E35: 929 | G35: A2 | H35: Verified - press / reported govt action | I35: 929 MW grid demand quoted from EC (HRF); matches CTUIL 929 MW
A36: 33 | B36: Andhra Pradesh | C36: Adani Group | D36: Rambilli (for Google) | E36: 697 | G36: A2 | H36: Verified - press / reported govt action | I36: 697 MW quoted from EC (HRF); matches CTUIL 697 MW
A37: 34 | B37: Andhra Pradesh | C37: Adani Group | D37: Adavivaram-Mudasarlova (for Google) | E37: 512 | G37: A2 | H37: Verified - press / reported govt action | I37: 512 MW in SEIAA affidavit (ThePrint)
A38: 35 | B38: Andhra Pradesh | C38: ReNew | D38: Makavaripalem, Anakapalli | E38: 1000 | G38: A2 | H38: Verified - press / reported govt action | I38: 1,000 MW quoting GO (MediaNama)
A39: 36 | B39: Andhra Pradesh | C39: Reliance | D39: Bhogapuram / Vizianagaram (854.97 acres) | E39: 1500 | G39: D | H39: Downgraded | I39: Approval verified; 1.5 GW only from registry / derived total
A40: 37 | B40: Andhra Pradesh | C40: Sify | D40: Paradesipalem (53.6 + 25 acres) | E40: 550 | G40: A2 | H40: Corrected | I40: 600 -> 550 MW (GO); dropped 50 MW registry-only site
A41: 38 | B41: Andhra Pradesh | C41: AM Intelligence Labs | D41: Amanam, Bheemunipatnam | E41: 512 | G41: A2 | H41: Verified - press / reported govt action | I41: 512 MW quoting GO (PTI)
...

Sheet Maharashtra
A1: Maharashtra - data-centre power by company group (MW), state-level sources
A2: Approved = government permission granted or operating; Under process = application / MoU / LoI / announced. MW basis varies by row - see Backup_All_States column G.
A4: A. All state-level data
A5: Company / group | B5: Under process | C5: Approved | D5: Total
A6: AirTrunk (Blackstone) | B6: =SUMIFS(Backup_All_States!$F$2:$F$70,Backup_All_States!$A$2:$A$70,"Maharashtra",Backup_All_States!$B$2:$B$70,$A6,Backup_All_States!$L$2:$L$70,"Y") -> 3120 | C6: =SUMIFS(Backup_All_States!$E$2:$E$70,Backup_All_States!$A$2:$A$70,"Maharashtra",Backup_All_States!$B$2:$B$70,$A6,Backup_All_States!$L$2:$L$70,"Y") -> 62 | D6: =B6+C6 -> 3182
A7: Lodha Group (park; tenants AWS, STT) | B7: =SUMIFS(Backup_All_States!$F$2:$F$70,Backup_All_States!$A$2:$A$70,"Maharashtra",Backup_All_States!$B$2:$B$70,$A7,Backup_All_States!$L$2:$L$70,"Y") -> 1500 | C7: =SUMIFS(Backup_All_States!$E$2:$E$70,Backup_All_States!$A$2:$A$70,"Maharashtra",Backup_All_States!$B$2:$B$70,$A7,Backup_All_States!$L$2:$L$70,"Y") -> 1450 | D7: =B7+C7 -> 2950
A8: ReNew | B8: =SUMIFS(Backup_All_States!$F$2:$F$70,Backup_All_States!$A$2:$A$70,"Maharashtra",Backup_All_States!$B$2:$B$70,$A8,Backup_All_States!$L$2:$L$70,"Y") -> 750 | C8: =SUMIFS(Backup_All_States!$E$2:$E$70,Backup_All_States!$A$2:$A$70,"Maharashtra",Backup_All_States!$B$2:$B$70,$A8,Backup_All_States!$L$2:$L$70,"Y") -> 0 | D8: =B8+C8 -> 750
A9: Trentar (Dorf Ketal) | B9: =SUMIFS(Backup_All_States!$F$2:$F$70,Backup_All_States!$A$2:$A$70,"Maharashtra",Backup_All_States!$B$2:$B$70,$A9,Backup_All_States!$L$2:$L$70,"Y") -> 500 | C9: =SUMIFS(Backup_All_States!$E$2:$E$70,Backup_All_States!$A$2:$A$70,"Maharashtra",Backup_All_States!$B$2:$B$70,$A9,Backup_All_States!$L$2:$L$70,"Y") -> 0 | D9: =B9+C9 -> 500
A10: Sify | B10: =SUMIFS(Backup_All_States!$F$2:$F$70,Backup_All_States!$A$2:$A$70,"Maharashtra",Backup_All_States!$B$2:$B$70,$A10,Backup_All_States!$L$2:$L$70,"Y") -> 0 | C10: =SUMIFS(Backup_All_States!$E$2:$E$70,Backup_All_States!$A$2:$A$70,"Maharashtra",Backup_All_States!$B$2:$B$70,$A10,Backup_All_States!$L$2:$L$70,"Y") -> 377 | D10: =B10+C10 -> 377
A11: NTT | B11: =SUMIFS(Backup_All_States!$F$2:$F$70,Backup_All_States!$A$2:$A$70,"Maharashtra",Backup_All_States!$B$2:$B$70,$A11,Backup_All_States!$L$2:$L$70,"Y") -> 0 | C11: =SUMIFS(Backup_All_States!$E$2:$E$70,Backup_All_States!$A$2:$A$70,"Maharashtra",Backup_All_States!$B$2:$B$70,$A11,Backup_All_States!$L$2:$L$70,"Y") -> 366 | D11: =B11+C11 -> 366
A12: Digital Edge | B12: =SUMIFS(Backup_All_States!$F$2:$F$70,Backup_All_States!$A$2:$A$70,"Maharashtra",Backup_All_States!$B$2:$B$70,$A12,Backup_All_States!$L$2:$L$70,"Y") -> 0 | C12: =SUMIFS(Backup_All_States!$E$2:$E$70,Backup_All_States!$A$2:$A$70,"Maharashtra",Backup_All_States!$B$2:$B$70,$A12,Backup_All_States!$L$2:$L$70,"Y") -> 350 | D12: =B12+C12 -> 350
A13: AWS (Amazon) | B13: =SUMIFS(Backup_All_States!$F$2:$F$70,Backup_All_States!$A$2:$A$70,"Maharashtra",Backup_All_States!$B$2:$B$70,$A13,Backup_All_States!$L$2:$L$70,"Y") -> 0 | C13: =SUMIFS(Backup_All_States!$E$2:$E$70,Backup_All_States!$A$2:$A$70,"Maharashtra",Backup_All_States!$B$2:$B$70,$A13,Backup_All_States!$L$2:$L$70,"Y") -> 349 | D13: =B13+C13 -> 349
A14: Adani Group | B14: =SUMIFS(Backup_All_States!$F$2:$F$70,Backup_All_States!$A$2:$A$70,"Maharashtra",Backup_All_States!$B$2:$B$70,$A14,Backup_All_States!$L$2:$L$70,"Y") -> 240 | C14: =SUMIFS(Backup_All_States!$E$2:$E$70,Backup_All_States!$A$2:$A$70,"Maharashtra",Backup_All_States!$B$2:$B$70,$A14,Backup_All_States!$L$2:$L$70,"Y") -> 75.4 | D14: =B14+C14 -> 315.4
A15: Princeton Digital Group | B15: =SUMIFS(Backup_All_States!$F$2:$F$70,Backup_All_States!$A$2:$A$70,"Maharashtra",Backup_All_States!$B$2:$B$70,$A15,Backup_All_States!$L$2:$L$70,"Y") -> 120 | C15: =SUMIFS(Backup_All_States!$E$2:$E$70,Backup_All_States!$A$2:$A$70,"Maharashtra",Backup_All_States!$B$2:$B$70,$A15,Backup_All_States!$L$2:$L$70,"Y") -> 150 | D15: =B15+C15 -> 270
A16: Zerra | B16: =SUMIFS(Backup_All_States!$F$2:$F$70,Backup_All_States!$A$2:$A$70,"Maharashtra",Backup_All_States!$B$2:$B$70,$A16,Backup_All_States!$L$2:$L$70,"Y") -> 240 | C16: =SUMIFS(Backup_All_States!$E$2:$E$70,Backup_All_States!$A$2:$A$70,"Maharashtra",Backup_All_States!$B$2:$B$70,$A16,Backup_All_States!$L$2:$L$70,"Y") -> 0 | D16: =B16+C16 -> 240
A17: CtrlS | B17: =SUMIFS(Backup_All_States!$F$2:$F$70,Backup_All_States!$A$2:$A$70,"Maharashtra",Backup_All_States!$B$2:$B$70,$A17,Backup_All_States!$L$2:$L$70,"Y") -> 0 | C17: =SUMIFS(Backup_All_States!$E$2:$E$70,Backup_All_States!$A$2:$A$70,"Maharashtra",Backup_All_States!$B$2:$B$70,$A17,Backup_All_States!$L$2:$L$70,"Y") -> 214 | D17: =B17+C17 -> 214
... A29: Avisirah | B29: =SUMIFS(Backup_All_States!$F$2:$F$70,Backup_All_States!$A$2:$A$70,"Maharashtra",Backup_All_States!$B$2:$B$70,$A29,Backup_All_States!$L$2:$L$70,"Y") -> 5.5 | C29: =SUMIFS(Backup_All_States!$E$2:$E$70,Backup_All_States!$A$2:$A$70,"Maharashtra",Backup_All_States!$B$2:$B$70,$A29,Backup_All_States!$L$2:$L$70,"Y") -> 0 | D29: =B29+C29 -> 5.5
A30: Total | B30: =SUM(B6:B29) -> 7108.8 | C30: =SUM(C6:C29) -> 4005.4 | D30: =SUM(D6:D29) -> 11114.2
A33: B. Excluding rows that overlap CTUIL (use this to ADD to the CTUIL chart)
A34: Company / group | B34: Under process | C34: Approved | D34: Total
A35: AirTrunk (Blackstone) | B35: =SUMIFS(Backup_All_States!$F$2:$F$70,Backup_All_States!$A$2:$A$70,"Maharashtra",Backup_All_States!$B$2:$B$70,$A35,Backup_All_States!$L$2:$L$70,"Y",Backup_All_States!$J$2:$J$70,"No") -> 3120 | C35: =SUMIFS(Backup_All_States!$E$2:$E$70,Backup_All_States!$A$2:$A$70,"Maharashtra",Backup_All_States!$B$2:$B$70,$A35,Backup_All_States!$L$2:$L$70,"Y",Backup_All_States!$J$2:$J$70,"No") -> 62 | D35: =B35+C35 -> 3182
A36: Lodha Group (park; tenants AWS, STT) | B36: =SUMIFS(Backup_All_States!$F$2:$F$70,Backup_All_States!$A$2:$A$70,"Maharashtra",Backup_All_States!$B$2:$B$70,$A36,Backup_All_States!$L$2:$L$70,"Y",Backup_All_States!$J$2:$J$70,"No") -> 1500 | C36: =SUMIFS(Backup_All_States!$E$2:$E$70,Backup_All_States!$A$2:$A$70,"Maharashtra",Backup_All_States!$B$2:$B$70,$A36,Backup_All_States!$L$2:$L$70,"Y",Backup_All_States!$J$2:$J$70,"No") -> 1450 | D36: =B36+C36 -> 2950
A37: ReNew | B37: =SUMIFS(Backup_All_States!$F$2:$F$70,Backup_All_States!$A$2:$A$70,"Maharashtra",Backup_All_States!$B$2:$B$70,$A37,Backup_All_States!$L$2:$L$70,"Y",Backup_All_States!$J$2:$J$70,"No") -> 750 | C37: =SUMIFS(Backup_All_States!$E$2:$E$70,Backup_All_States!$A$2:$A$70,"Maharashtra",Backup_All_States!$B$2:$B$70,$A37,Backup_All_States!$L$2:$L$70,"Y",Backup_All_States!$J$2:$J$70,"No") -> 0 | D37: =B37+C37 -> 750
A38: Trentar (Dorf Ketal) | B38: =SUMIFS(Backup_All_States!$F$2:$F$70,Backup_All_States!$A$2:$A$70,"Maharashtra",Backup_All_States!$B$2:$B$70,$A38,Backup_All_States!$L$2:$L$70,"Y",Backup_All_States!$J$2:$J$70,"No") -> 500 | C38: =SUMIFS(Backup_All_States!$E$2:$E$70,Backup_All_States!$A$2:$A$70,"Maharashtra",Backup_All_States!$B$2:$B$70,$A38,Backup_All_States!$L$2:$L$70,"Y",Backup_All_States!$J$2:$J$70,"No") -> 0 | D38: =B38+C38 -> 500
A39: Sify | B39: =SUMIFS(Backup_All_States!$F$2:$F$70,Backup_All_States!$A$2:$A$70,"Maharashtra",Backup_All_States!$B$2:$B$70,$A39,Backup_All_States!$L$2:$L$70,"Y",Backup_All_States!$J$2:$J$70,"No") -> 0 | C39: =SUMIFS(Backup_All_States!$E$2:$E$70,Backup_All_States!$A$2:$A$70,"Maharashtra",Backup_All_States!$B$2:$B$70,$A39,Backup_All_States!$L$2:$L$70,"Y",Backup_All_States!$J$2:$J$70,"No") -> 377 | D39: =B39+C39 -> 377
A40: NTT | B40: =SUMIFS(Backup_All_States!$F$2:$F$70,Backup_All_States!$A$2:$A$70,"Maharashtra",Backup_All_States!$B$2:$B$70,$A40,Backup_All_States!$L$2:$L$70,"Y",Backup_All_States!$J$2:$J$70,"No") -> 0 | C40: =SUMIFS(Backup_All_States!$E$2:$E$70,Backup_All_States!$A$2:$A$70,"Maharashtra",Backup_All_States!$B$2:$B$70,$A40,Backup_All_States!$L$2:$L$70,"Y",Backup_All_States!$J$2:$J$70,"No") -> 366 | D40: =B40+C40 -> 366
A41: Digital Edge | B41: =SUMIFS(Backup_All_States!$F$2:$F$70,Backup_All_States!$A$2:$A$70,"Maharashtra",Backup_All_States!$B$2:$B$70,$A41,Backup_All_States!$L$2:$L$70,"Y",Backup_All_States!$J$2:$J$70,"No") -> 0 | C41: =SUMIFS(Backup_All_States!$E$2:$E$70,Backup_All_States!$A$2:$A$70,"Maharashtra",Backup_All_States!$B$2:$B$70,$A41,Backup_All_States!$L$2:$L$70,"Y",Backup_All_States!$J$2:$J$70,"No") -> 350 | D41: =B41+C41 -> 350
A42: AWS (Amazon) | B42: =SUMIFS(Backup_All_States!$F$2:$F$70,Backup_All_States!$A$2:$A$70,"Maharashtra",Backup_All_States!$B$2:$B$70,$A42,Backup_All_States!$L$2:$L$70,"Y",Backup_All_States!$J$2:$J$70,"No") -> 0 | C42: =SUMIFS(Backup_All_States!$E$2:$E$70,Backup_All_States!$A$2:$A$70,"Maharashtra",Backup_All_States!$B$2:$B$70,$A42,Backup_All_States!$L$2:$L$70,"Y",Backup_All_States!$J$2:$J$70,"No") -> 349 | D42: =B42+C42 -> 349
A43: Adani Group | B43: =SUMIFS(Backup_All_States!$F$2:$F$70,Backup_All_States!$A$2:$A$70,"Maharashtra",Backup_All_States!$B$2:$B$70,$A43,Backup_All_States!$L$2:$L$70,"Y",Backup_All_States!$J$2:$J$70,"No") -> 0 | C43: =SUMIFS(Backup_All_States!$E$2:$E$70,Backup_All_States!$A$2:$A$70,"Maharashtra",Backup_All_States!$B$2:$B$70,$A43,Backup_All_States!$L$2:$L$70,"Y",Backup_All_States!$J$2:$J$70,"No") -> 75.4 | D43: =B43+C43 -> 75.4
A44: Princeton Digital Group | B44: =SUMIFS(Backup_All_States!$F$2:$F$70,Backup_All_States!$A$2:$A$70,"Maharashtra",Backup_All_States!$B$2:$B$70,$A44,Backup_All_States!$L$2:$L$70,"Y",Backup_All_States!$J$2:$J$70,"No") -> 120 | C44: =SUMIFS(Backup_All_States!$E$2:$E$70,Backup_All_States!$A$2:$A$70,"Maharashtra",Backup_All_States!$B$2:$B$70,$A44,Backup_All_States!$L$2:$L$70,"Y",Backup_All_States!$J$2:$J$70,"No") -> 150 | D44: =B44+C44 -> 270
A45: Zerra | B45: =SUMIFS(Backup_All_States!$F$2:$F$70,Backup_All_States!$A$2:$A$70,"Maharashtra",Backup_All_States!$B$2:$B$70,$A45,Backup_All_States!$L$2:$L$70,"Y",Backup_All_States!$J$2:$J$70,"No") -> 240 | C45: =SUMIFS(Backup_All_States!$E$2:$E$70,Backup_All_States!$A$2:$A$70,"Maharashtra",Backup_All_States!$B$2:$B$70,$A45,Backup_All_States!$L$2:$L$70,"Y",Backup_All_States!$J$2:$J$70,"No") -> 0 | D45: =B45+C45 -> 240
A46: CtrlS | B46: =SUMIFS(Backup_All_States!$F$2:$F$70,Backup_All_States!$A$2:$A$70,"Maharashtra",Backup_All_States!$B$2:$B$70,$A46,Backup_All_States!$L$2:$L$70,"Y",Backup_All_States!$J$2:$J$70,"No") -> 0 | C46: =SUMIFS(Backup_All_States!$E$2:$E$70,Backup_All_States!$A$2:$A$70,"Maharashtra",Backup_All_States!$B$2:$B$70,$A46,Backup_All_States!$L$2:$L$70,"Y",Backup_All_States!$J$2:$J$70,"No") -> 214 | D46: =B46+C46 -> 214
... A58: Avisirah | B58: =SUMIFS(Backup_All_States!$F$2:$F$70,Backup_All_States!$A$2:$A$70,"Maharashtra",Backup_All_States!$B$2:$B$70,$A58,Backup_All_States!$L$2:$L$70,"Y",Backup_All_States!$J$2:$J$70,"No") -> 5.5 | C58: =SUMIFS(Backup_All_States!$E$2:$E$70,Backup_All_States!$A$2:$A$70,"Maharashtra",Backup_All_States!$B$2:$B$70,$A58,Backup_All_States!$L$2:$L$70,"Y",Backup_All_States!$J$2:$J$70,"No") -> 0 | D58: =B58+C58 -> 5.5
A59: Total | B59: =SUM(B35:B58) -> 6868.8 | C59: =SUM(C35:C58) -> 4005.4 | D59: =SUM(D35:D58) -> 10874.2

Sheet Andhra Pradesh
A1: Andhra Pradesh - data-centre power by company group (MW), state-level sources
A2: Approved = government permission granted or operating; Under process = application / MoU / LoI / announced. MW basis varies by row - see Backup_All_States column G.
A4: A. All state-level data
A5: Company / group | B5: Under process | C5: Approved | D5: Total
A6: Adani Group | B6: =SUMIFS(Backup_All_States!$F$2:$F$70,Backup_All_States!$A$2:$A$70,"Andhra Pradesh",Backup_All_States!$B$2:$B$70,$A6,Backup_All_States!$L$2:$L$70,"Y") -> 0 | C6: =SUMIFS(Backup_All_States!$E$2:$E$70,Backup_All_States!$A$2:$A$70,"Andhra Pradesh",Backup_All_States!$B$2:$B$70,$A6,Backup_All_States!$L$2:$L$70,"Y") -> 2338 | D6: =B6+C6 -> 2338
A7: Reliance | B7: =SUMIFS(Backup_All_States!$F$2:$F$70,Backup_All_States!$A$2:$A$70,"Andhra Pradesh",Backup_All_States!$B$2:$B$70,$A7,Backup_All_States!$L$2:$L$70,"Y") -> 0 | C7: =SUMIFS(Backup_All_States!$E$2:$E$70,Backup_All_States!$A$2:$A$70,"Andhra Pradesh",Backup_All_States!$B$2:$B$70,$A7,Backup_All_States!$L$2:$L$70,"Y") -> 1500 | D7: =B7+C7 -> 1500
A8: ReNew | B8: =SUMIFS(Backup_All_States!$F$2:$F$70,Backup_All_States!$A$2:$A$70,"Andhra Pradesh",Backup_All_States!$B$2:$B$70,$A8,Backup_All_States!$L$2:$L$70,"Y") -> 0 | C8: =SUMIFS(Backup_All_States!$E$2:$E$70,Backup_All_States!$A$2:$A$70,"Andhra Pradesh",Backup_All_States!$B$2:$B$70,$A8,Backup_All_States!$L$2:$L$70,"Y") -> 1000 | D8: =B8+C8 -> 1000
A9: Sify | B9: =SUMIFS(Backup_All_States!$F$2:$F$70,Backup_All_States!$A$2:$A$70,"Andhra Pradesh",Backup_All_States!$B$2:$B$70,$A9,Backup_All_States!$L$2:$L$70,"Y") -> 0 | C9: =SUMIFS(Backup_All_States!$E$2:$E$70,Backup_All_States!$A$2:$A$70,"Andhra Pradesh",Backup_All_States!$B$2:$B$70,$A9,Backup_All_States!$L$2:$L$70,"Y") -> 550 | D9: =B9+C9 -> 550
A10: AM Intelligence Labs | B10: =SUMIFS(Backup_All_States!$F$2:$F$70,Backup_All_States!$A$2:$A$70,"Andhra Pradesh",Backup_All_States!$B$2:$B$70,$A10,Backup_All_States!$L$2:$L$70,"Y") -> 0 | C10: =SUMIFS(Backup_All_States!$E$2:$E$70,Backup_All_States!$A$2:$A$70,"Andhra Pradesh",Backup_All_States!$B$2:$B$70,$A10,Backup_All_States!$L$2:$L$70,"Y") -> 512 | D10: =B10+C10 -> 512
A11: Colt DCS - RMZ | B11: =SUMIFS(Backup_All_States!$F$2:$F$70,Backup_All_States!$A$2:$A$70,"Andhra Pradesh",Backup_All_States!$B$2:$B$70,$A11,Backup_All_States!$L$2:$L$70,"Y") -> 0 | C11: =SUMIFS(Backup_All_States!$E$2:$E$70,Backup_All_States!$A$2:$A$70,"Andhra Pradesh",Backup_All_States!$B$2:$B$70,$A11,Backup_All_States!$L$2:$L$70,"Y") -> 486 | D11: =B11+C11 -> 486
A12: CtrlS | B12: =SUMIFS(Backup_All_States!$F$2:$F$70,Backup_All_States!$A$2:$A$70,"Andhra Pradesh",Backup_All_States!$B$2:$B$70,$A12,Backup_All_States!$L$2:$L$70,"Y") -> 0 | C12: =SUMIFS(Backup_All_States!$E$2:$E$70,Backup_All_States!$A$2:$A$70,"Andhra Pradesh",Backup_All_States!$B$2:$B$70,$A12,Backup_All_States!$L$2:$L$70,"Y") -> 100 | D12: =B12+C12 -> 100
A13: Total | B13: =SUM(B6:B12) -> 0 | C13: =SUM(C6:C12) -> 6486 | D13: =SUM(D6:D12) -> 6486
A16: B. Excluding rows that overlap CTUIL (use this to ADD to the CTUIL chart)
A17: Company / group | B17: Under process | C17: Approved | D17: Total
A18: Adani Group | B18: =SUMIFS(Backup_All_States!$F$2:$F$70,Backup_All_States!$A$2:$A$70,"Andhra Pradesh",Backup_All_States!$B$2:$B$70,$A18,Backup_All_States!$L$2:$L$70,"Y",Backup_All_States!$J$2:$J$70,"No") -> 0 | C18: =SUMIFS(Backup_All_States!$E$2:$E$70,Backup_All_States!$A$2:$A$70,"Andhra Pradesh",Backup_All_States!$B$2:$B$70,$A18,Backup_All_States!$L$2:$L$70,"Y",Backup_All_States!$J$2:$J$70,"No") -> 200 | D18: =B18+C18 -> 200
A19: Reliance | B19: =SUMIFS(Backup_All_States!$F$2:$F$70,Backup_All_States!$A$2:$A$70,"Andhra Pradesh",Backup_All_States!$B$2:$B$70,$A19,Backup_All_States!$L$2:$L$70,"Y",Backup_All_States!$J$2:$J$70,"No") -> 0 | C19: =SUMIFS(Backup_All_States!$E$2:$E$70,Backup_All_States!$A$2:$A$70,"Andhra Pradesh",Backup_All_States!$B$2:$B$70,$A19,Backup_All_States!$L$2:$L$70,"Y",Backup_All_States!$J$2:$J$70,"No") -> 1500 | D19: =B19+C19 -> 1500
A20: ReNew | B20: =SUMIFS(Backup_All_States!$F$2:$F$70,Backup_All_States!$A$2:$A$70,"Andhra Pradesh",Backup_All_States!$B$2:$B$70,$A20,Backup_All_States!$L$2:$L$70,"Y",Backup_All_States!$J$2:$J$70,"No") -> 0 | C20: =SUMIFS(Backup_All_States!$E$2:$E$70,Backup_All_States!$A$2:$A$70,"Andhra Pradesh",Backup_All_States!$B$2:$B$70,$A20,Backup_All_States!$L$2:$L$70,"Y",Backup_All_States!$J$2:$J$70,"No") -> 1000 | D20: =B20+C20 -> 1000
A21: Sify | B21: =SUMIFS(Backup_All_States!$F$2:$F$70,Backup_All_States!$A$2:$A$70,"Andhra Pradesh",Backup_All_States!$B$2:$B$70,$A21,Backup_All_States!$L$2:$L$70,"Y",Backup_All_States!$J$2:$J$70,"No") -> 0 | C21: =SUMIFS(Backup_All_States!$E$2:$E$70,Backup_All_States!$A$2:$A$70,"Andhra Pradesh",Backup_All_States!$B$2:$B$70,$A21,Backup_All_States!$L$2:$L$70,"Y",Backup_All_States!$J$2:$J$70,"No") -> 550 | D21: =B21+C21 -> 550
A22: AM Intelligence Labs | B22: =SUMIFS(Backup_All_States!$F$2:$F$70,Backup_All_States!$A$2:$A$70,"Andhra Pradesh",Backup_All_States!$B$2:$B$70,$A22,Backup_All_States!$L$2:$L$70,"Y",Backup_All_States!$J$2:$J$70,"No") -> 0 | C22: =SUMIFS(Backup_All_States!$E$2:$E$70,Backup_All_States!$A$2:$A$70,"Andhra Pradesh",Backup_All_States!$B$2:$B$70,$A22,Backup_All_States!$L$2:$L$70,"Y",Backup_All_States!$J$2:$J$70,"No") -> 512 | D22: =B22+C22 -> 512
A23: Colt DCS - RMZ | B23: =SUMIFS(Backup_All_States!$F$2:$F$70,Backup_All_States!$A$2:$A$70,"Andhra Pradesh",Backup_All_States!$B$2:$B$70,$A23,Backup_All_States!$L$2:$L$70,"Y",Backup_All_States!$J$2:$J$70,"No") -> 0 | C23: =SUMIFS(Backup_All_States!$E$2:$E$70,Backup_All_States!$A$2:$A$70,"Andhra Pradesh",Backup_All_States!$B$2:$B$70,$A23,Backup_All_States!$L$2:$L$70,"Y",Backup_All_States!$J$2:$J$70,"No") -> 486 | D23: =B23+C23 -> 486
A24: CtrlS | B24: =SUMIFS(Backup_All_States!$F$2:$F$70,Backup_All_States!$A$2:$A$70,"Andhra Pradesh",Backup_All_States!$B$2:$B$70,$A24,Backup_All_States!$L$2:$L$70,"Y",Backup_All_States!$J$2:$J$70,"No") -> 0 | C24: =SUMIFS(Backup_All_States!$E$2:$E$70,Backup_All_States!$A$2:$A$70,"Andhra Pradesh",Backup_All_States!$B$2:$B$70,$A24,Backup_All_States!$L$2:$L$70,"Y",Backup_All_States!$J$2:$J$70,"No") -> 100 | D24: =B24+C24 -> 100
A25: Total | B25: =SUM(B18:B24) -> 0 | C25: =SUM(C18:C24) -> 4348 | D25: =SUM(D18:D24) -> 4348

Sheet Telangana
A1: Telangana - data-centre power by company group (MW), state-level sources
A2: Approved = government permission granted or operating; Under process = application / MoU / LoI / announced. MW basis varies by row - see Backup_All_States column G.
A4: A. All state-level data
A5: Company / group | B5: Under process | C5: Approved | D5: Total
A6: Fortune | B6: =SUMIFS(Backup_All_States!$F$2:$F$70,Backup_All_States!$A$2:$A$70,"Telangana",Backup_All_States!$B$2:$B$70,$A6,Backup_All_States!$L$2:$L$70,"Y") -> 0 | C6: =SUMIFS(Backup_All_States!$E$2:$E$70,Backup_All_States!$A$2:$A$70,"Telangana",Backup_All_States!$B$2:$B$70,$A6,Backup_All_States!$L$2:$L$70,"Y") -> 2000 | D6: =B6+C6 -> 2000
A7: TCS | B7: =SUMIFS(Backup_All_States!$F$2:$F$70,Backup_All_States!$A$2:$A$70,"Telangana",Backup_All_States!$B$2:$B$70,$A7,Backup_All_States!$L$2:$L$70,"Y") -> 1000 | C7: =SUMIFS(Backup_All_States!$E$2:$E$70,Backup_All_States!$A$2:$A$70,"Telangana",Backup_All_States!$B$2:$B$70,$A7,Backup_All_States!$L$2:$L$70,"Y") -> 0 | D7: =B7+C7 -> 1000
A8: Adani Group | B8: =SUMIFS(Backup_All_States!$F$2:$F$70,Backup_All_States!$A$2:$A$70,"Telangana",Backup_All_States!$B$2:$B$70,$A8,Backup_All_States!$L$2:$L$70,"Y") -> 386.8 | C8: =SUMIFS(Backup_All_States!$E$2:$E$70,Backup_All_States!$A$2:$A$70,"Telangana",Backup_All_States!$B$2:$B$70,$A8,Backup_All_States!$L$2:$L$70,"Y") -> 19.2 | D8: =B8+C8 -> 406
A9: CtrlS | B9: =SUMIFS(Backup_All_States!$F$2:$F$70,Backup_All_States!$A$2:$A$70,"Telangana",Backup_All_States!$B$2:$B$70,$A9,Backup_All_States!$L$2:$L$70,"Y") -> 400 | C9: =SUMIFS(Backup_All_States!$E$2:$E$70,Backup_All_States!$A$2:$A$70,"Telangana",Backup_All_States!$B$2:$B$70,$A9,Backup_All_States!$L$2:$L$70,"Y") -> 0 | D9: =B9+C9 -> 400
A10: NTT Data - Neysa | B10: =SUMIFS(Backup_All_States!$F$2:$F$70,Backup_All_States!$A$2:$A$70,"Telangana",Backup_All_States!$B$2:$B$70,$A10,Backup_All_States!$L$2:$L$70,"Y") -> 400 | C10: =SUMIFS(Backup_All_States!$E$2:$E$70,Backup_All_States!$A$2:$A$70,"Telangana",Backup_All_States!$B$2:$B$70,$A10,Backup_All_States!$L$2:$L$70,"Y") -> 0 | D10: =B10+C10 -> 400
A11: AWS / CtrlS (unattributed) | B11: =SUMIFS(Backup_All_States!$F$2:$F$70,Backup_All_States!$A$2:$A$70,"Telangana",Backup_All_States!$B$2:$B$70,$A11,Backup_All_States!$L$2:$L$70,"Y") -> 0 | C11: =SUMIFS(Backup_All_States!$E$2:$E$70,Backup_All_States!$A$2:$A$70,"Telangana",Backup_All_States!$B$2:$B$70,$A11,Backup_All_States!$L$2:$L$70,"Y") -> 278 | D11: =B11+C11 -> 278
A12: STT GDC | B12: =SUMIFS(Backup_All_States!$F$2:$F$70,Backup_All_States!$A$2:$A$70,"Telangana",Backup_All_States!$B$2:$B$70,$A12,Backup_All_States!$L$2:$L$70,"Y") -> 100 | C12: =SUMIFS(Backup_All_States!$E$2:$E$70,Backup_All_States!$A$2:$A$70,"Telangana",Backup_All_States!$B$2:$B$70,$A12,Backup_All_States!$L$2:$L$70,"Y") -> 0 | D12: =B12+C12 -> 100
A13: UPC-Volt | B13: =SUMIFS(Backup_All_States!$F$2:$F$70,Backup_All_States!$A$2:$A$70,"Telangana",Backup_All_States!$B$2:$B$70,$A13,Backup_All_States!$L$2:$L$70,"Y") -> 100 | C13: =SUMIFS(Backup_All_States!$E$2:$E$70,Backup_All_States!$A$2:$A$70,"Telangana",Backup_All_States!$B$2:$B$70,$A13,Backup_All_States!$L$2:$L$70,"Y") -> 0 | D13: =B13+C13 -> 100
A14: Total | B14: =SUM(B6:B13) -> 2386.8 | C14: =SUM(C6:C13) -> 2297.2 | D14: =SUM(D6:D13) -> 4684
A17: B. Excluding rows that overlap CTUIL (use this to ADD to the CTUIL chart)
A18: Company / group | B18: Under process | C18: Approved | D18: Total
A19: Fortune | B19: =SUMIFS(Backup_All_States!$F$2:$F$70,Backup_All_States!$A$2:$A$70,"Telangana",Backup_All_States!$B$2:$B$70,$A19,Backup_All_States!$L$2:$L$70,"Y",Backup_All_States!$J$2:$J$70,"No") -> 0 | C19: =SUMIFS(Backup_All_States!$E$2:$E$70,Backup_All_States!$A$2:$A$70,"Telangana",Backup_All_States!$B$2:$B$70,$A19,Backup_All_States!$L$2:$L$70,"Y",Backup_All_States!$J$2:$J$70,"No") -> 2000 | D19: =B19+C19 -> 2000
A20: TCS | B20: =SUMIFS(Backup_All_States!$F$2:$F$70,Backup_All_States!$A$2:$A$70,"Telangana",Backup_All_States!$B$2:$B$70,$A20,Backup_All_States!$L$2:$L$70,"Y",Backup_All_States!$J$2:$J$70,"No") -> 0 | C20: =SUMIFS(Backup_All_States!$E$2:$E$70,Backup_All_States!$A$2:$A$70,"Telangana",Backup_All_States!$B$2:$B$70,$A20,Backup_All_States!$L$2:$L$70,"Y",Backup_All_States!$J$2:$J$70,"No") -> 0 | D20: =B20+C20 -> 0
A21: Adani Group | B21: =SUMIFS(Backup_All_States!$F$2:$F$70,Backup_All_States!$A$2:$A$70,"Telangana",Backup_All_States!$B$2:$B$70,$A21,Backup_All_States!$L$2:$L$70,"Y",Backup_All_States!$J$2:$J$70,"No") -> 0 | C21: =SUMIFS(Backup_All_States!$E$2:$E$70,Backup_All_States!$A$2:$A$70,"Telangana",Backup_All_States!$B$2:$B$70,$A21,Backup_All_States!$L$2:$L$70,"Y",Backup_All_States!$J$2:$J$70,"No") -> 0 | D21: =B21+C21 -> 0
A22: CtrlS | B22: =SUMIFS(Backup_All_States!$F$2:$F$70,Backup_All_States!$A$2:$A$70,"Telangana",Backup_All_States!$B$2:$B$70,$A22,Backup_All_States!$L$2:$L$70,"Y",Backup_All_States!$J$2:$J$70,"No") -> 400 | C22: =SUMIFS(Backup_All_States!$E$2:$E$70,Backup_All_States!$A$2:$A$70,"Telangana",Backup_All_States!$B$2:$B$70,$A22,Backup_All_States!$L$2:$L$70,"Y",Backup_All_States!$J$2:$J$70,"No") -> 0 | D22: =B22+C22 -> 400
A23: NTT Data - Neysa | B23: =SUMIFS(Backup_All_States!$F$2:$F$70,Backup_All_States!$A$2:$A$70,"Telangana",Backup_All_States!$B$2:$B$70,$A23,Backup_All_States!$L$2:$L$70,"Y",Backup_All_States!$J$2:$J$70,"No") -> 400 | C23: =SUMIFS(Backup_All_States!$E$2:$E$70,Backup_All_States!$A$2:$A$70,"Telangana",Backup_All_States!$B$2:$B$70,$A23,Backup_All_States!$L$2:$L$70,"Y",Backup_All_States!$J$2:$J$70,"No") -> 0 | D23: =B23+C23 -> 400
A24: AWS / CtrlS (unattributed) | B24: =SUMIFS(Backup_All_States!$F$2:$F$70,Backup_All_States!$A$2:$A$70,"Telangana",Backup_All_States!$B$2:$B$70,$A24,Backup_All_States!$L$2:$L$70,"Y",Backup_All_States!$J$2:$J$70,"No") -> 0 | C24: =SUMIFS(Backup_All_States!$E$2:$E$70,Backup_All_States!$A$2:$A$70,"Telangana",Backup_All_States!$B$2:$B$70,$A24,Backup_All_States!$L$2:$L$70,"Y",Backup_All_States!$J$2:$J$70,"No") -> 278 | D24: =B24+C24 -> 278
A25: STT GDC | B25: =SUMIFS(Backup_All_States!$F$2:$F$70,Backup_All_States!$A$2:$A$70,"Telangana",Backup_All_States!$B$2:$B$70,$A25,Backup_All_States!$L$2:$L$70,"Y",Backup_All_States!$J$2:$J$70,"No") -> 100 | C25: =SUMIFS(Backup_All_States!$E$2:$E$70,Backup_All_States!$A$2:$A$70,"Telangana",Backup_All_States!$B$2:$B$70,$A25,Backup_All_States!$L$2:$L$70,"Y",Backup_All_States!$J$2:$J$70,"No") -> 0 | D25: =B25+C25 -> 100
A26: UPC-Volt | B26: =SUMIFS(Backup_All_States!$F$2:$F$70,Backup_All_States!$A$2:$A$70,"Telangana",Backup_All_States!$B$2:$B$70,$A26,Backup_All_States!$L$2:$L$70,"Y",Backup_All_States!$J$2:$J$70,"No") -> 100 | C26: =SUMIFS(Backup_All_States!$E$2:$E$70,Backup_All_States!$A$2:$A$70,"Telangana",Backup_All_States!$B$2:$B$70,$A26,Backup_All_States!$L$2:$L$70,"Y",Backup_All_States!$J$2:$J$70,"No") -> 0 | D26: =B26+C26 -> 100
A27: Total | B27: =SUM(B19:B26) -> 1000 | C27: =SUM(C19:C26) -> 2278 | D27: =SUM(D19:D26) -> 3278

Sheet Tamil Nadu
A1: Tamil Nadu - data-centre power by company group (MW), state-level sources
A2: Approved = government permission granted or operating; Under process = application / MoU / LoI / announced. MW basis varies by row - see Backup_All_States column G.
A4: A. All state-level data
A5: Company / group | B5: Under process | C5: Approved | D5: Total
A6: Sify | B6: =SUMIFS(Backup_All_States!$F$2:$F$70,Backup_All_States!$A$2:$A$70,"Tamil Nadu",Backup_All_States!$B$2:$B$70,$A6,Backup_All_States!$L$2:$L$70,"Y") -> 104.1 | C6: =SUMIFS(Backup_All_States!$E$2:$E$70,Backup_All_States!$A$2:$A$70,"Tamil Nadu",Backup_All_States!$B$2:$B$70,$A6,Backup_All_States!$L$2:$L$70,"Y") -> 25.9 | D6: =B6+C6 -> 130
A7: Digital Connexion (Reliance-Brookfield-DLR) | B7: =SUMIFS(Backup_All_States!$F$2:$F$70,Backup_All_States!$A$2:$A$70,"Tamil Nadu",Backup_All_States!$B$2:$B$70,$A7,Backup_All_States!$L$2:$L$70,"Y") -> 0 | C7: =SUMIFS(Backup_All_States!$E$2:$E$70,Backup_All_States!$A$2:$A$70,"Tamil Nadu",Backup_All_States!$B$2:$B$70,$A7,Backup_All_States!$L$2:$L$70,"Y") -> 100 | D7: =B7+C7 -> 100
A8: CapitaLand | B8: =SUMIFS(Backup_All_States!$F$2:$F$70,Backup_All_States!$A$2:$A$70,"Tamil Nadu",Backup_All_States!$B$2:$B$70,$A8,Backup_All_States!$L$2:$L$70,"Y") -> 0 | C8: =SUMIFS(Backup_All_States!$E$2:$E$70,Backup_All_States!$A$2:$A$70,"Tamil Nadu",Backup_All_States!$B$2:$B$70,$A8,Backup_All_States!$L$2:$L$70,"Y") -> 53 | D8: =B8+C8 -> 53
A9: STT GDC | B9: =SUMIFS(Backup_All_States!$F$2:$F$70,Backup_All_States!$A$2:$A$70,"Tamil Nadu",Backup_All_States!$B$2:$B$70,$A9,Backup_All_States!$L$2:$L$70,"Y") -> 37.8 | C9: =SUMIFS(Backup_All_States!$E$2:$E$70,Backup_All_States!$A$2:$A$70,"Tamil Nadu",Backup_All_States!$B$2:$B$70,$A9,Backup_All_States!$L$2:$L$70,"Y") -> 7.2 | D9: =B9+C9 -> 45
A10: Techno Digital | B10: =SUMIFS(Backup_All_States!$F$2:$F$70,Backup_All_States!$A$2:$A$70,"Tamil Nadu",Backup_All_States!$B$2:$B$70,$A10,Backup_All_States!$L$2:$L$70,"Y") -> 0 | C10: =SUMIFS(Backup_All_States!$E$2:$E$70,Backup_All_States!$A$2:$A$70,"Tamil Nadu",Backup_All_States!$B$2:$B$70,$A10,Backup_All_States!$L$2:$L$70,"Y") -> 36 | D10: =B10+C10 -> 36
A11: Adani Group | B11: =SUMIFS(Backup_All_States!$F$2:$F$70,Backup_All_States!$A$2:$A$70,"Tamil Nadu",Backup_All_States!$B$2:$B$70,$A11,Backup_All_States!$L$2:$L$70,"Y") -> 16 | C11: =SUMIFS(Backup_All_States!$E$2:$E$70,Backup_All_States!$A$2:$A$70,"Tamil Nadu",Backup_All_States!$B$2:$B$70,$A11,Backup_All_States!$L$2:$L$70,"Y") -> 17 | D11: =B11+C11 -> 33
A12: Total | B12: =SUM(B6:B11) -> 157.9 | C12: =SUM(C6:C11) -> 239.1 | D12: =SUM(D6:D11) -> 397
A15: B. Excluding rows that overlap CTUIL (use this to ADD to the CTUIL chart)
A16: Company / group | B16: Under process | C16: Approved | D16: Total
A17: Sify | B17: =SUMIFS(Backup_All_States!$F$2:$F$70,Backup_All_States!$A$2:$A$70,"Tamil Nadu",Backup_All_States!$B$2:$B$70,$A17,Backup_All_States!$L$2:$L$70,"Y",Backup_All_States!$J$2:$J$70,"No") -> 104.1 | C17: =SUMIFS(Backup_All_States!$E$2:$E$70,Backup_All_States!$A$2:$A$70,"Tamil Nadu",Backup_All_States!$B$2:$B$70,$A17,Backup_All_States!$L$2:$L$70,"Y",Backup_All_States!$J$2:$J$70,"No") -> 25.9 | D17: =B17+C17 -> 130
A18: Digital Connexion (Reliance-Brookfield-DLR) | B18: =SUMIFS(Backup_All_States!$F$2:$F$70,Backup_All_States!$A$2:$A$70,"Tamil Nadu",Backup_All_States!$B$2:$B$70,$A18,Backup_All_States!$L$2:$L$70,"Y",Backup_All_States!$J$2:$J$70,"No") -> 0 | C18: =SUMIFS(Backup_All_States!$E$2:$E$70,Backup_All_States!$A$2:$A$70,"Tamil Nadu",Backup_All_States!$B$2:$B$70,$A18,Backup_All_States!$L$2:$L$70,"Y",Backup_All_States!$J$2:$J$70,"No") -> 100 | D18: =B18+C18 -> 100
A19: CapitaLand | B19: =SUMIFS(Backup_All_States!$F$2:$F$70,Backup_All_States!$A$2:$A$70,"Tamil Nadu",Backup_All_States!$B$2:$B$70,$A19,Backup_All_States!$L$2:$L$70,"Y",Backup_All_States!$J$2:$J$70,"No") -> 0 | C19: =SUMIFS(Backup_All_States!$E$2:$E$70,Backup_All_States!$A$2:$A$70,"Tamil Nadu",Backup_All_States!$B$2:$B$70,$A19,Backup_All_States!$L$2:$L$70,"Y",Backup_All_States!$J$2:$J$70,"No") -> 53 | D19: =B19+C19 -> 53
A20: STT GDC | B20: =SUMIFS(Backup_All_States!$F$2:$F$70,Backup_All_States!$A$2:$A$70,"Tamil Nadu",Backup_All_States!$B$2:$B$70,$A20,Backup_All_States!$L$2:$L$70,"Y",Backup_All_States!$J$2:$J$70,"No") -> 37.8 | C20: =SUMIFS(Backup_All_States!$E$2:$E$70,Backup_All_States!$A$2:$A$70,"Tamil Nadu",Backup_All_States!$B$2:$B$70,$A20,Backup_All_States!$L$2:$L$70,"Y",Backup_All_States!$J$2:$J$70,"No") -> 7.2 | D20: =B20+C20 -> 45
A21: Techno Digital | B21: =SUMIFS(Backup_All_States!$F$2:$F$70,Backup_All_States!$A$2:$A$70,"Tamil Nadu",Backup_All_States!$B$2:$B$70,$A21,Backup_All_States!$L$2:$L$70,"Y",Backup_All_States!$J$2:$J$70,"No") -> 0 | C21: =SUMIFS(Backup_All_States!$E$2:$E$70,Backup_All_States!$A$2:$A$70,"Tamil Nadu",Backup_All_States!$B$2:$B$70,$A21,Backup_All_States!$L$2:$L$70,"Y",Backup_All_States!$J$2:$J$70,"No") -> 36 | D21: =B21+C21 -> 36
A22: Adani Group | B22: =SUMIFS(Backup_All_States!$F$2:$F$70,Backup_All_States!$A$2:$A$70,"Tamil Nadu",Backup_All_States!$B$2:$B$70,$A22,Backup_All_States!$L$2:$L$70,"Y",Backup_All_States!$J$2:$J$70,"No") -> 16 | C22: =SUMIFS(Backup_All_States!$E$2:$E$70,Backup_All_States!$A$2:$A$70,"Tamil Nadu",Backup_All_States!$B$2:$B$70,$A22,Backup_All_States!$L$2:$L$70,"Y",Backup_All_States!$J$2:$J$70,"No") -> 17 | D22: =B22+C22 -> 33
A23: Total | B23: =SUM(B17:B22) -> 157.9 | C23: =SUM(C17:C22) -> 239.1 | D23: =SUM(D17:D22) -> 397

Sheet Uttar Pradesh
A1: Uttar Pradesh - data-centre power by company group (MW), state-level sources
A2: Approved = government permission granted or operating; Under process = application / MoU / LoI / announced. MW basis varies by row - see Backup_All_States column G.
A4: A. All state-level data
A5: Company / group | B5: Under process | C5: Approved | D5: Total
A6: Hiranandani (Yotta) | B6: =SUMIFS(Backup_All_States!$F$2:$F$70,Backup_All_States!$A$2:$A$70,"Uttar Pradesh",Backup_All_States!$B$2:$B$70,$A6,Backup_All_States!$L$2:$L$70,"Y") -> 222 | C6: =SUMIFS(Backup_All_States!$E$2:$E$70,Backup_All_States!$A$2:$A$70,"Uttar Pradesh",Backup_All_States!$B$2:$B$70,$A6,Backup_All_States!$L$2:$L$70,"Y") -> 28 | D6: =B6+C6 -> 250
A7: SKVR | B7: =SUMIFS(Backup_All_States!$F$2:$F$70,Backup_All_States!$A$2:$A$70,"Uttar Pradesh",Backup_All_States!$B$2:$B$70,$A7,Backup_All_States!$L$2:$L$70,"Y") -> 104 | C7: =SUMIFS(Backup_All_States!$E$2:$E$70,Backup_All_States!$A$2:$A$70,"Uttar Pradesh",Backup_All_States!$B$2:$B$70,$A7,Backup_All_States!$L$2:$L$70,"Y") -> 16 | D7: =B7+C7 -> 120
A8: Adani Group | B8: =SUMIFS(Backup_All_States!$F$2:$F$70,Backup_All_States!$A$2:$A$70,"Uttar Pradesh",Backup_All_States!$B$2:$B$70,$A8,Backup_All_States!$L$2:$L$70,"Y") -> 65 | C8: =SUMIFS(Backup_All_States!$E$2:$E$70,Backup_All_States!$A$2:$A$70,"Uttar Pradesh",Backup_All_States!$B$2:$B$70,$A8,Backup_All_States!$L$2:$L$70,"Y") -> 35 | D8: =B8+C8 -> 100
A9: NTT | B9: =SUMIFS(Backup_All_States!$F$2:$F$70,Backup_All_States!$A$2:$A$70,"Uttar Pradesh",Backup_All_States!$B$2:$B$70,$A9,Backup_All_States!$L$2:$L$70,"Y") -> 43.8 | C9: =SUMIFS(Backup_All_States!$E$2:$E$70,Backup_All_States!$A$2:$A$70,"Uttar Pradesh",Backup_All_States!$B$2:$B$70,$A9,Backup_All_States!$L$2:$L$70,"Y") -> 9 | D9: =B9+C9 -> 52.8
A10: STT GDC | B10: =SUMIFS(Backup_All_States!$F$2:$F$70,Backup_All_States!$A$2:$A$70,"Uttar Pradesh",Backup_All_States!$B$2:$B$70,$A10,Backup_All_States!$L$2:$L$70,"Y") -> 0 | C10: =SUMIFS(Backup_All_States!$E$2:$E$70,Backup_All_States!$A$2:$A$70,"Uttar Pradesh",Backup_All_States!$B$2:$B$70,$A10,Backup_All_States!$L$2:$L$70,"Y") -> 40 | D10: =B10+C10 -> 40
A11: Iron Mountain | B11: =SUMIFS(Backup_All_States!$F$2:$F$70,Backup_All_States!$A$2:$A$70,"Uttar Pradesh",Backup_All_States!$B$2:$B$70,$A11,Backup_All_States!$L$2:$L$70,"Y") -> 0 | C11: =SUMIFS(Backup_All_States!$E$2:$E$70,Backup_All_States!$A$2:$A$70,"Uttar Pradesh",Backup_All_States!$B$2:$B$70,$A11,Backup_All_States!$L$2:$L$70,"Y") -> 5 | D11: =B11+C11 -> 5
A12: Total | B12: =SUM(B6:B11) -> 434.8 | C12: =SUM(C6:C11) -> 133 | D12: =SUM(D6:D11) -> 567.8
A15: B. Excluding rows that overlap CTUIL (use this to ADD to the CTUIL chart)
A16: Company / group | B16: Under process | C16: Approved | D16: Total
A17: Hiranandani (Yotta) | B17: =SUMIFS(Backup_All_States!$F$2:$F$70,Backup_All_States!$A$2:$A$70,"Uttar Pradesh",Backup_All_States!$B$2:$B$70,$A17,Backup_All_States!$L$2:$L$70,"Y",Backup_All_States!$J$2:$J$70,"No") -> 222 | C17: =SUMIFS(Backup_All_States!$E$2:$E$70,Backup_All_States!$A$2:$A$70,"Uttar Pradesh",Backup_All_States!$B$2:$B$70,$A17,Backup_All_States!$L$2:$L$70,"Y",Backup_All_States!$J$2:$J$70,"No") -> 28 | D17: =B17+C17 -> 250
A18: SKVR | B18: =SUMIFS(Backup_All_States!$F$2:$F$70,Backup_All_States!$A$2:$A$70,"Uttar Pradesh",Backup_All_States!$B$2:$B$70,$A18,Backup_All_States!$L$2:$L$70,"Y",Backup_All_States!$J$2:$J$70,"No") -> 104 | C18: =SUMIFS(Backup_All_States!$E$2:$E$70,Backup_All_States!$A$2:$A$70,"Uttar Pradesh",Backup_All_States!$B$2:$B$70,$A18,Backup_All_States!$L$2:$L$70,"Y",Backup_All_States!$J$2:$J$70,"No") -> 16 | D18: =B18+C18 -> 120
A19: Adani Group | B19: =SUMIFS(Backup_All_States!$F$2:$F$70,Backup_All_States!$A$2:$A$70,"Uttar Pradesh",Backup_All_States!$B$2:$B$70,$A19,Backup_All_States!$L$2:$L$70,"Y",Backup_All_States!$J$2:$J$70,"No") -> 65 | C19: =SUMIFS(Backup_All_States!$E$2:$E$70,Backup_All_States!$A$2:$A$70,"Uttar Pradesh",Backup_All_States!$B$2:$B$70,$A19,Backup_All_States!$L$2:$L$70,"Y",Backup_All_States!$J$2:$J$70,"No") -> 35 | D19: =B19+C19 -> 100
A20: NTT | B20: =SUMIFS(Backup_All_States!$F$2:$F$70,Backup_All_States!$A$2:$A$70,"Uttar Pradesh",Backup_All_States!$B$2:$B$70,$A20,Backup_All_States!$L$2:$L$70,"Y",Backup_All_States!$J$2:$J$70,"No") -> 43.8 | C20: =SUMIFS(Backup_All_States!$E$2:$E$70,Backup_All_States!$A$2:$A$70,"Uttar Pradesh",Backup_All_States!$B$2:$B$70,$A20,Backup_All_States!$L$2:$L$70,"Y",Backup_All_States!$J$2:$J$70,"No") -> 9 | D20: =B20+C20 -> 52.8
A21: STT GDC | B21: =SUMIFS(Backup_All_States!$F$2:$F$70,Backup_All_States!$A$2:$A$70,"Uttar Pradesh",Backup_All_States!$B$2:$B$70,$A21,Backup_All_States!$L$2:$L$70,"Y",Backup_All_States!$J$2:$J$70,"No") -> 0 | C21: =SUMIFS(Backup_All_States!$E$2:$E$70,Backup_All_States!$A$2:$A$70,"Uttar Pradesh",Backup_All_States!$B$2:$B$70,$A21,Backup_All_States!$L$2:$L$70,"Y",Backup_All_States!$J$2:$J$70,"No") -> 40 | D21: =B21+C21 -> 40
A22: Iron Mountain | B22: =SUMIFS(Backup_All_States!$F$2:$F$70,Backup_All_States!$A$2:$A$70,"Uttar Pradesh",Backup_All_States!$B$2:$B$70,$A22,Backup_All_States!$L$2:$L$70,"Y",Backup_All_States!$J$2:$J$70,"No") -> 0 | C22: =SUMIFS(Backup_All_States!$E$2:$E$70,Backup_All_States!$A$2:$A$70,"Uttar Pradesh",Backup_All_States!$B$2:$B$70,$A22,Backup_All_States!$L$2:$L$70,"Y",Backup_All_States!$J$2:$J$70,"No") -> 5 | D22: =B22+C22 -> 5
A23: Total | B23: =SUM(B17:B22) -> 434.8 | C23: =SUM(C17:C22) -> 133 | D23: =SUM(D17:D22) -> 567.8

Sheet Odisha
A1: Odisha - data-centre power by company group (MW), state-level sources
A2: Approved = government permission granted or operating; Under process = application / MoU / LoI / announced. MW basis varies by row - see Backup_All_States column G.
A4: A. All state-level data
A5: Company / group | B5: Under process | C5: Approved | D5: Total
A6: Adani Group | B6: =SUMIFS(Backup_All_States!$F$2:$F$70,Backup_All_States!$A$2:$A$70,"Odisha",Backup_All_States!$B$2:$B$70,$A6,Backup_All_States!$L$2:$L$70,"Y") -> 0 | C6: =SUMIFS(Backup_All_States!$E$2:$E$70,Backup_All_States!$A$2:$A$70,"Odisha",Backup_All_States!$B$2:$B$70,$A6,Backup_All_States!$L$2:$L$70,"Y") -> 1000 | D6: =B6+C6 -> 1000
A7: Sentraforge AI | B7: =SUMIFS(Backup_All_States!$F$2:$F$70,Backup_All_States!$A$2:$A$70,"Odisha",Backup_All_States!$B$2:$B$70,$A7,Backup_All_States!$L$2:$L$70,"Y") -> 0 | C7: =SUMIFS(Backup_All_States!$E$2:$E$70,Backup_All_States!$A$2:$A$70,"Odisha",Backup_All_States!$B$2:$B$70,$A7,Backup_All_States!$L$2:$L$70,"Y") -> 120 | D7: =B7+C7 -> 120
A8: Total | B8: =SUM(B6:B7) -> 0 | C8: =SUM(C6:C7) -> 1120 | D8: =SUM(D6:D7) -> 1120
A11: B. Excluding rows that overlap CTUIL (use this to ADD to the CTUIL chart)
A12: Company / group | B12: Under process | C12: Approved | D12: Total
A13: Adani Group | B13: =SUMIFS(Backup_All_States!$F$2:$F$70,Backup_All_States!$A$2:$A$70,"Odisha",Backup_All_States!$B$2:$B$70,$A13,Backup_All_States!$L$2:$L$70,"Y",Backup_All_States!$J$2:$J$70,"No") -> 0 | C13: =SUMIFS(Backup_All_States!$E$2:$E$70,Backup_All_States!$A$2:$A$70,"Odisha",Backup_All_States!$B$2:$B$70,$A13,Backup_All_States!$L$2:$L$70,"Y",Backup_All_States!$J$2:$J$70,"No") -> 1000 | D13: =B13+C13 -> 1000
A14: Sentraforge AI | B14: =SUMIFS(Backup_All_States!$F$2:$F$70,Backup_All_States!$A$2:$A$70,"Odisha",Backup_All_States!$B$2:$B$70,$A14,Backup_All_States!$L$2:$L$70,"Y",Backup_All_States!$J$2:$J$70,"No") -> 0 | C14: =SUMIFS(Backup_All_States!$E$2:$E$70,Backup_All_States!$A$2:$A$70,"Odisha",Backup_All_States!$B$2:$B$70,$A14,Backup_All_States!$L$2:$L$70,"Y",Backup_All_States!$J$2:$J$70,"No") -> 120 | D14: =B14+C14 -> 120
A15: Total | B15: =SUM(B13:B14) -> 0 | C15: =SUM(C13:C14) -> 1120 | D15: =SUM(D13:D14) -> 1120

Sheet Karnataka
A1: Karnataka - data-centre power by company group (MW), state-level sources
A2: Approved = government permission granted or operating; Under process = application / MoU / LoI / announced. MW basis varies by row - see Backup_All_States column G.
A4: A. All state-level data
A5: Company / group | B5: Under process | C5: Approved | D5: Total
A6: Govt of Karnataka (park) | B6: =SUMIFS(Backup_All_States!$F$2:$F$70,Backup_All_States!$A$2:$A$70,"Karnataka",Backup_All_States!$B$2:$B$70,$A6,Backup_All_States!$L$2:$L$70,"Y") -> 500 | C6: =SUMIFS(Backup_All_States!$E$2:$E$70,Backup_All_States!$A$2:$A$70,"Karnataka",Backup_All_States!$B$2:$B$70,$A6,Backup_All_States!$L$2:$L$70,"Y") -> 0 | D6: =B6+C6 -> 500
A7: Total | B7: =SUM(B6:B6) -> 500 | C7: =SUM(C6:C6) -> 0 | D7: =SUM(D6:D6) -> 500
A10: B. Excluding rows that overlap CTUIL (use this to ADD to the CTUIL chart)
A11: Company / group | B11: Under process | C11: Approved | D11: Total
A12: Govt of Karnataka (park) | B12: =SUMIFS(Backup_All_States!$F$2:$F$70,Backup_All_States!$A$2:$A$70,"Karnataka",Backup_All_States!$B$2:$B$70,$A12,Backup_All_States!$L$2:$L$70,"Y",Backup_All_States!$J$2:$J$70,"No") -> 500 | C12: =SUMIFS(Backup_All_States!$E$2:$E$70,Backup_All_States!$A$2:$A$70,"Karnataka",Backup_All_States!$B$2:$B$70,$A12,Backup_All_States!$L$2:$L$70,"Y",Backup_All_States!$J$2:$J$70,"No") -> 0 | D12: =B12+C12 -> 500
A13: Total | B13: =SUM(B12:B12) -> 500 | C13: =SUM(C12:C12) -> 0 | D13: =SUM(D12:D12) -> 500

Sheet Gujarat
A1: Gujarat - data-centre power by company group (MW), state-level sources
A2: Approved = government permission granted or operating; Under process = application / MoU / LoI / announced. MW basis varies by row - see Backup_All_States column G.
A4: A. All state-level data
A5: Company / group | B5: Under process | C5: Approved | D5: Total
A6: Reliance | B6: =SUMIFS(Backup_All_States!$F$2:$F$70,Backup_All_States!$A$2:$A$70,"Gujarat",Backup_All_States!$B$2:$B$70,$A6,Backup_All_States!$L$2:$L$70,"Y") -> 168 | C6: =SUMIFS(Backup_All_States!$E$2:$E$70,Backup_All_States!$A$2:$A$70,"Gujarat",Backup_All_States!$B$2:$B$70,$A6,Backup_All_States!$L$2:$L$70,"Y") -> 0 | D6: =B6+C6 -> 168
A7: Total | B7: =SUM(B6:B6) -> 168 | C7: =SUM(C6:C6) -> 0 | D7: =SUM(D6:D6) -> 168
A10: B. Excluding rows that overlap CTUIL (use this to ADD to the CTUIL chart)
A11: Company / group | B11: Under process | C11: Approved | D11: Total
A12: Reliance | B12: =SUMIFS(Backup_All_States!$F$2:$F$70,Backup_All_States!$A$2:$A$70,"Gujarat",Backup_All_States!$B$2:$B$70,$A12,Backup_All_States!$L$2:$L$70,"Y",Backup_All_States!$J$2:$J$70,"No") -> 0 | C12: =SUMIFS(Backup_All_States!$E$2:$E$70,Backup_All_States!$A$2:$A$70,"Gujarat",Backup_All_States!$B$2:$B$70,$A12,Backup_All_States!$L$2:$L$70,"Y",Backup_All_States!$J$2:$J$70,"No") -> 0 | D12: =B12+C12 -> 0
A13: Total | B13: =SUM(B12:B12) -> 0 | C13: =SUM(C12:C12) -> 0 | D13: =SUM(D12:D12) -> 0

Sheet Haryana
A1: Haryana - data-centre power by company group (MW), state-level sources
A2: Approved = government permission granted or operating; Under process = application / MoU / LoI / announced. MW basis varies by row - see Backup_All_States column G.
A4: A. All state-level data
A5: Company / group | B5: Under process | C5: Approved | D5: Total
A6: Anant Raj | B6: =SUMIFS(Backup_All_States!$F$2:$F$70,Backup_All_States!$A$2:$A$70,"Haryana",Backup_All_States!$B$2:$B$70,$A6,Backup_All_States!$L$2:$L$70,"Y") -> 279 | C6: =SUMIFS(Backup_All_States!$E$2:$E$70,Backup_All_States!$A$2:$A$70,"Haryana",Backup_All_States!$B$2:$B$70,$A6,Backup_All_States!$L$2:$L$70,"Y") -> 28 | D6: =B6+C6 -> 307
A7: Total | B7: =SUM(B6:B6) -> 279 | C7: =SUM(C6:C6) -> 28 | D7: =SUM(D6:D6) -> 307
A10: B. Excluding rows that overlap CTUIL (use this to ADD to the CTUIL chart)
A11: Company / group | B11: Under process | C11: Approved | D11: Total
